
#######################################################################
# +-----------------------------------------------------------------+ #
# |                            BO3 object                           | #
# +-----------------------------------------------------------------+ #
#######################################################################

# This is the config file of a custom object.
# If you add this object correctly to your BiomeConfigs, it will spawn in the world.

# This is the creator of this BO3 object
Author: Unknown

# A short description of this BO3 object
Description: This BO3 was converted from a schematic using OTGEdit. The author and description information of the schematic could not be found. If you know who the author of the schematic is then please add this information.

# The BO3 version, don't change this! It can be used by external applications to do a version check.
Version: 3

# The settings mode, WriteAll, WriteWithoutComments or WriteDisable. See WorldConfig.
SettingsMode: WriteAll


#######################################################################
# +-----------------------------------------------------------------+ #
# |                          Main settings                          | #
# +-----------------------------------------------------------------+ #
#######################################################################

# This needs to be set to true to spawn the object in the Tree and Sapling resources.
Tree: true

# The frequency of the BO3 from 1 to 200. Tries this many times to spawn this BO3 when using the CustomObject(...) resource.
# Ignored by Tree(..), Sapling(..) and CustomStructure(..)
Frequency: 40

# The rarity of the BO3 from 0 to 100. Each spawn attempt has rarity% chance to succeed when using the CustomObject(...) resource.
# Ignored by Tree(..), Sapling(..) and CustomStructure(..)
Rarity: 100.0

# If you set this to true, the BO3 will be placed with a random rotation.
RotateRandomly: true

# The spawn height of the BO3: randomY, highestBlock or highestSolidBlock.
SpawnHeight: randomY

# The offset from the spawn height to spawn this BO3
# Ex. SpawnHeight = highestSolidBlock, SpawnHeightOffset = 3; This object will spawn 3 blocks above the highest solid block
SpawnHeightOffset: 0

# A random amount to offset the spawn location from the spawn offset height
# Ex. SpawnHeightOffset = 3, SpawnHeightVariance = 3; This object will spawn 3 to 6 blocks above the original spot it would have spawned
SpawnHeightVariance: 0

##############################
# Height Limits for the BO3. #
##############################

# When in randomY mode used as the minimum Y or in atMinY mode as the actual Y to spawn this BO3 at.
MinHeight: 92

# When in randomY mode used as the maximum Y to spawn this BO3 at.
MaxHeight: 256

######################
# Extrusion settings #
######################

# The style of extrusion you wish to use - BottomDown, TopUp, None (Default)
ExtrudeMode: None

# The blocks to extrude your BO3 through
ExtrudeThroughBlocks: AIR

# Objects can have other objects attacthed to it: branches. Branches can also
# have branches attached to it, which can also have branches, etc. This is the
# maximum branch depth for this objects.
MaxBranchDepth: 10

# When spawned with the UseWorld keyword, this BO3 should NOT spawn in the following biomes.
# If you write the BO3 name directly in the BiomeConfigs, this will be ignored.
ExcludedBiomes: All


#######################################################################
# +-----------------------------------------------------------------+ #
# |                      Source block settings                      | #
# +-----------------------------------------------------------------+ #
#######################################################################

# The block(s) the BO3 should spawn in.
SourceBlocks: AIR,GRASS,DIRT

# The maximum percentage of the BO3 that can be outside the SourceBlock.
# The BO3 won't be placed on a location with more blocks outside the SourceBlock than this percentage.
MaxPercentageOutsideSourceBlock: 100

# What to do when a block is about to be placed outside the SourceBlock? (dontPlace, placeAnyway)
OutsideSourceBlock: placeAnyway

# OTG+ settings #
# Legacy setting, rename this file to .BO4 instead. Set this to true to enable the advanced customstructure features of OTG+.
IsOTGPlus: false


#######################################################################
# +-----------------------------------------------------------------+ #
# |                              Blocks                             | #
# +-----------------------------------------------------------------+ #
#######################################################################

# All the blocks used in the BO3 are listed here. Possible blocks:
# Block(x,y,z,id[.data][,nbtfile.nbt)
# RandomBlock(x,y,z,id[:data][,nbtfile.nbt],chance[,id[:data][,nbtfile.nbt],chance[,...]])
#  So RandomBlock(0,0,0,CHEST,chest.nbt,50,CHEST,anotherchest.nbt,100) will spawn a chest at
#  the BO3 origin, and give it a 50% chance to have the contents of chest.nbt, or, if that
#  fails, a 100% percent chance to have the contents of anotherchest.nbt.
# *Note: Unlike Entity() and Spawner(), for Block() .txt files don't work, only .nbt files work.
# MinecraftObject(x,y,z,name) (TODO: This may not work anymore and needs to be tested.
#  Spawns an object in the Mojang NBT structure format. For example, 
#  MinecraftObject(0,0,0,minecraft:igloo/igloo_bottom)
#  spawns the bottom part of an igloo.
Block(-20,23,12,biomesoplenty:leaves_0:15)
Block(-20,23,13,biomesoplenty:leaves_0:15)
Block(-20,23,14,biomesoplenty:leaves_0:15)
Block(-19,19,13,biomesoplenty:leaves_0:15)
Block(-19,20,13,biomesoplenty:leaves_0:15)
Block(-19,21,13,biomesoplenty:leaves_0:15)
Block(-19,22,13,biomesoplenty:leaves_0:15)
Block(-19,23,11,biomesoplenty:leaves_0:15)
Block(-19,23,12,biomesoplenty:leaves_0:15)
Block(-19,23,13,biomesoplenty:log_1:5)
Block(-19,23,14,biomesoplenty:leaves_0:3)
Block(-19,24,9,biomesoplenty:leaves_0:15)
Block(-19,24,10,biomesoplenty:leaves_0:3)
Block(-19,24,11,biomesoplenty:leaves_0:3)
Block(-19,24,12,biomesoplenty:leaves_0:15)
Block(-19,24,13,biomesoplenty:leaves_0:3)
Block(-19,24,14,biomesoplenty:leaves_0:3)
Block(-19,24,15,biomesoplenty:leaves_0:3)
Block(-19,25,10,biomesoplenty:leaves_0:15)
Block(-19,25,11,biomesoplenty:leaves_0:3)
Block(-19,25,12,biomesoplenty:leaves_0:15)
Block(-19,25,13,biomesoplenty:leaves_0:3)
Block(-19,25,14,biomesoplenty:leaves_0:3)
Block(-18,21,12,biomesoplenty:leaves_0:15)
Block(-18,22,12,biomesoplenty:leaves_0:15)
Block(-18,22,14,biomesoplenty:leaves_0:3)
Block(-18,22,15,biomesoplenty:leaves_0:3)
Block(-18,23,9,biomesoplenty:leaves_0:3)
Block(-18,23,10,biomesoplenty:leaves_0:3)
Block(-18,23,11,biomesoplenty:leaves_0:15)
Block(-18,23,12,biomesoplenty:leaves_0:3)
Block(-18,23,13,biomesoplenty:leaves_0:3)
Block(-18,23,15,biomesoplenty:leaves_0:3)
Block(-18,23,16,biomesoplenty:leaves_0:3)
Block(-18,24,6,biomesoplenty:leaves_0:15)
Block(-18,24,7,biomesoplenty:leaves_0:15)
Block(-18,24,8,biomesoplenty:leaves_0:15)
Block(-18,24,9,biomesoplenty:leaves_0:15)
Block(-18,24,10,biomesoplenty:log_1:1)
Block(-18,24,11,biomesoplenty:leaves_0:15)
Block(-18,24,12,biomesoplenty:leaves_0:3)
Block(-18,24,13,biomesoplenty:leaves_0:3)
Block(-18,24,14,biomesoplenty:leaves_0:3)
Block(-18,24,15,biomesoplenty:leaves_0:3)
Block(-18,24,16,biomesoplenty:leaves_0:3)
Block(-18,25,9,biomesoplenty:leaves_0:15)
Block(-18,25,10,biomesoplenty:leaves_0:15)
Block(-18,25,11,biomesoplenty:leaves_0:3)
Block(-18,25,12,biomesoplenty:leaves_0:15)
Block(-18,25,13,biomesoplenty:leaves_0:3)
Block(-18,25,14,biomesoplenty:leaves_0:3)
Block(-18,26,8,biomesoplenty:leaves_0:3)
Block(-18,26,10,biomesoplenty:leaves_0:15)
Block(-18,26,11,biomesoplenty:leaves_0:15)
Block(-18,26,12,biomesoplenty:leaves_0:15)
Block(-18,26,14,biomesoplenty:leaves_0:3)
Block(-18,26,15,biomesoplenty:leaves_0:3)
Block(-17,19,9,biomesoplenty:leaves_0:15)
Block(-17,20,9,biomesoplenty:leaves_0:15)
Block(-17,21,9,biomesoplenty:leaves_0:15)
Block(-17,22,7,biomesoplenty:leaves_0:3)
Block(-17,22,8,biomesoplenty:leaves_0:3)
Block(-17,22,9,biomesoplenty:leaves_0:15)
Block(-17,22,14,biomesoplenty:leaves_0:3)
Block(-17,22,15,biomesoplenty:leaves_0:3)
Block(-17,23,6,biomesoplenty:leaves_0:3)
Block(-17,23,9,biomesoplenty:log_1:5)
Block(-17,23,10,biomesoplenty:leaves_0:3)
Block(-17,23,11,biomesoplenty:leaves_0:3)
Block(-17,23,12,biomesoplenty:leaves_0:3)
Block(-17,23,13,biomesoplenty:leaves_0:3)
Block(-17,23,14,biomesoplenty:leaves_0:3)
Block(-17,23,16,biomesoplenty:leaves_0:3)
Block(-17,24,5,biomesoplenty:leaves_0:3)
Block(-17,24,6,biomesoplenty:leaves_0:15)
Block(-17,24,7,biomesoplenty:leaves_0:3)
Block(-17,24,8,biomesoplenty:leaves_0:15)
Block(-17,24,9,biomesoplenty:log_1:1)
Block(-17,24,10,biomesoplenty:leaves_0:3)
Block(-17,24,11,biomesoplenty:leaves_0:3)
Block(-17,24,12,biomesoplenty:leaves_0:3)
Block(-17,24,13,biomesoplenty:leaves_0:3)
Block(-17,24,14,biomesoplenty:log_1:1)
Block(-17,24,15,biomesoplenty:leaves_0:3)
Block(-17,24,16,biomesoplenty:leaves_0:3)
Block(-17,25,7,biomesoplenty:leaves_0:3)
Block(-17,25,8,biomesoplenty:leaves_0:3)
Block(-17,25,9,biomesoplenty:leaves_0:3)
Block(-17,25,10,biomesoplenty:leaves_0:3)
Block(-17,25,11,biomesoplenty:leaves_0:3)
Block(-17,25,12,biomesoplenty:leaves_0:3)
Block(-17,25,13,biomesoplenty:leaves_0:3)
Block(-17,25,14,biomesoplenty:leaves_0:3)
Block(-17,25,15,biomesoplenty:leaves_0:3)
Block(-17,25,16,biomesoplenty:leaves_0:3)
Block(-17,26,8,biomesoplenty:leaves_0:3)
Block(-17,26,9,biomesoplenty:leaves_0:15)
Block(-17,26,10,biomesoplenty:leaves_0:3)
Block(-17,26,11,biomesoplenty:leaves_0:15)
Block(-17,26,12,biomesoplenty:leaves_0:3)
Block(-17,26,13,biomesoplenty:leaves_0:3)
Block(-17,26,14,biomesoplenty:leaves_0:3)
Block(-17,26,15,biomesoplenty:leaves_0:3)
Block(-17,27,8,biomesoplenty:leaves_0:15)
Block(-16,17,15,GLOWSTONE)
Block(-16,18,6,biomesoplenty:leaves_0:3)
Block(-16,18,15,biomesoplenty:leaves_0:3)
Block(-16,19,6,biomesoplenty:leaves_0:3)
Block(-16,19,15,biomesoplenty:leaves_0:3)
Block(-16,20,6,biomesoplenty:leaves_0:3)
Block(-16,20,15,biomesoplenty:leaves_0:3)
Block(-16,21,6,biomesoplenty:leaves_0:3)
Block(-16,21,10,biomesoplenty:leaves_0:3)
Block(-16,21,11,biomesoplenty:leaves_0:3)
Block(-16,21,15,biomesoplenty:leaves_0:3)
Block(-16,22,5,biomesoplenty:leaves_0:3)
Block(-16,22,6,biomesoplenty:log_1:5)
Block(-16,22,7,biomesoplenty:leaves_0:3)
Block(-16,22,9,biomesoplenty:leaves_0:3)
Block(-16,22,10,biomesoplenty:leaves_0:3)
Block(-16,22,11,biomesoplenty:leaves_0:3)
Block(-16,22,15,biomesoplenty:log_1:5)
Block(-16,22,16,biomesoplenty:leaves_0:3)
Block(-16,23,6,biomesoplenty:leaves_0:3)
Block(-16,23,8,biomesoplenty:leaves_0:3)
Block(-16,23,10,biomesoplenty:leaves_0:3)
Block(-16,23,12,biomesoplenty:leaves_0:3)
Block(-16,23,15,biomesoplenty:leaves_0:3)
Block(-16,23,16,biomesoplenty:leaves_0:3)
Block(-16,24,4,biomesoplenty:leaves_0:3)
Block(-16,24,5,biomesoplenty:leaves_0:3)
Block(-16,24,6,biomesoplenty:log_1:1)
Block(-16,24,7,biomesoplenty:leaves_0:3)
Block(-16,24,8,biomesoplenty:leaves_0:3)
Block(-16,24,9,biomesoplenty:leaves_0:3)
Block(-16,24,10,biomesoplenty:log_1:1)
Block(-16,24,12,biomesoplenty:leaves_0:3)
Block(-16,24,13,biomesoplenty:log_1:1)
Block(-16,24,14,biomesoplenty:log_1:9)
Block(-16,24,15,biomesoplenty:log_1:9)
Block(-16,24,16,biomesoplenty:leaves_0:3)
Block(-16,25,5,biomesoplenty:leaves_0:3)
Block(-16,25,6,biomesoplenty:leaves_0:3)
Block(-16,25,7,biomesoplenty:leaves_0:3)
Block(-16,25,8,biomesoplenty:leaves_0:3)
Block(-16,25,9,biomesoplenty:log_1:5)
Block(-16,25,10,biomesoplenty:leaves_0:3)
Block(-16,25,11,biomesoplenty:leaves_0:3)
Block(-16,25,12,biomesoplenty:leaves_0:3)
Block(-16,25,13,biomesoplenty:leaves_0:3)
Block(-16,25,15,biomesoplenty:leaves_0:3)
Block(-16,25,16,biomesoplenty:leaves_0:3)
Block(-16,25,18,biomesoplenty:leaves_0:3)
Block(-16,26,5,biomesoplenty:leaves_0:3)
Block(-16,26,6,biomesoplenty:leaves_0:3)
Block(-16,26,7,biomesoplenty:leaves_0:3)
Block(-16,26,8,biomesoplenty:leaves_0:3)
Block(-16,26,9,biomesoplenty:leaves_0:3)
Block(-16,26,10,biomesoplenty:leaves_0:3)
Block(-16,26,11,biomesoplenty:leaves_0:3)
Block(-16,26,12,biomesoplenty:leaves_0:3)
Block(-16,26,14,biomesoplenty:leaves_0:3)
Block(-16,27,11,biomesoplenty:leaves_0:3)
Block(-15,17,5,biomesoplenty:leaves_0:3)
Block(-15,17,6,biomesoplenty:leaves_0:3)
Block(-15,22,5,biomesoplenty:leaves_0:3)
Block(-15,22,6,biomesoplenty:leaves_0:3)
Block(-15,22,7,biomesoplenty:leaves_0:3)
Block(-15,22,8,biomesoplenty:leaves_0:3)
Block(-15,22,9,biomesoplenty:leaves_0:3)
Block(-15,23,5,biomesoplenty:leaves_0:3)
Block(-15,23,6,biomesoplenty:leaves_0:3)
Block(-15,23,7,biomesoplenty:leaves_0:3)
Block(-15,23,11,biomesoplenty:leaves_0:3)
Block(-15,23,14,biomesoplenty:leaves_0:3)
Block(-15,23,15,biomesoplenty:leaves_0:3)
Block(-15,23,16,biomesoplenty:leaves_0:3)
Block(-15,23,17,biomesoplenty:leaves_0:3)
Block(-15,24,3,biomesoplenty:leaves_0:3)
Block(-15,24,4,biomesoplenty:leaves_0:3)
Block(-15,24,6,biomesoplenty:log_1:9)
Block(-15,24,7,biomesoplenty:log_1:1)
Block(-15,24,8,biomesoplenty:leaves_0:3)
Block(-15,24,9,biomesoplenty:log_1:9)
Block(-15,24,10,biomesoplenty:leaves_0:3)
Block(-15,24,11,biomesoplenty:leaves_0:3)
Block(-15,24,12,biomesoplenty:log_1:9)
Block(-15,24,13,biomesoplenty:log_1:1)
Block(-15,24,14,biomesoplenty:leaves_0:3)
Block(-15,24,15,biomesoplenty:leaves_0:3)
Block(-15,24,18,biomesoplenty:leaves_0:3)
Block(-15,24,19,biomesoplenty:leaves_0:3)
Block(-15,25,4,biomesoplenty:leaves_0:3)
Block(-15,25,5,biomesoplenty:leaves_0:3)
Block(-15,25,6,biomesoplenty:leaves_0:3)
Block(-15,25,8,biomesoplenty:leaves_0:3)
Block(-15,25,9,biomesoplenty:leaves_0:3)
Block(-15,25,11,biomesoplenty:log_1:5)
Block(-15,25,12,biomesoplenty:leaves_0:3)
Block(-15,25,13,biomesoplenty:leaves_0:3)
Block(-15,25,14,biomesoplenty:leaves_0:3)
Block(-15,25,15,biomesoplenty:leaves_0:3)
Block(-15,25,16,biomesoplenty:leaves_0:3)
Block(-15,25,17,biomesoplenty:leaves_0:3)
Block(-15,25,18,biomesoplenty:leaves_0:3)
Block(-15,26,6,biomesoplenty:leaves_0:3)
Block(-15,26,7,biomesoplenty:leaves_0:3)
Block(-15,26,8,biomesoplenty:leaves_0:3)
Block(-15,26,9,biomesoplenty:leaves_0:3)
Block(-15,26,10,biomesoplenty:leaves_0:3)
Block(-15,26,11,biomesoplenty:leaves_0:3)
Block(-15,26,12,biomesoplenty:leaves_0:3)
Block(-15,26,18,biomesoplenty:leaves_0:3)
Block(-15,27,9,biomesoplenty:leaves_0:3)
Block(-15,27,10,biomesoplenty:leaves_0:3)
Block(-15,27,11,biomesoplenty:leaves_0:3)
Block(-15,27,12,biomesoplenty:leaves_0:3)
Block(-14,16,5,biomesoplenty:leaves_0:3)
Block(-14,17,4,biomesoplenty:leaves_0:3)
Block(-14,17,5,biomesoplenty:leaves_0:3)
Block(-14,17,6,biomesoplenty:leaves_0:3)
Block(-14,17,7,biomesoplenty:leaves_0:3)
Block(-14,18,5,biomesoplenty:leaves_0:3)
Block(-14,21,6,biomesoplenty:leaves_0:3)
Block(-14,21,7,biomesoplenty:leaves_0:3)
Block(-14,22,6,biomesoplenty:leaves_0:3)
Block(-14,22,7,biomesoplenty:leaves_0:3)
Block(-14,22,8,biomesoplenty:leaves_0:3)
Block(-14,22,10,biomesoplenty:leaves_0:3)
Block(-14,22,13,biomesoplenty:leaves_0:3)
Block(-14,22,15,biomesoplenty:leaves_0:3)
Block(-14,23,5,biomesoplenty:leaves_0:3)
Block(-14,23,6,biomesoplenty:leaves_0:3)
Block(-14,23,7,biomesoplenty:leaves_0:3)
Block(-14,23,8,biomesoplenty:leaves_0:3)
Block(-14,23,9,biomesoplenty:leaves_0:3)
Block(-14,23,10,biomesoplenty:leaves_0:3)
Block(-14,23,13,biomesoplenty:leaves_0:3)
Block(-14,23,14,biomesoplenty:leaves_0:3)
Block(-14,23,15,biomesoplenty:leaves_0:3)
Block(-14,23,16,biomesoplenty:leaves_0:3)
Block(-14,23,17,biomesoplenty:leaves_0:3)
Block(-14,23,18,biomesoplenty:leaves_0:3)
Block(-14,23,19,biomesoplenty:leaves_0:3)
Block(-14,24,3,biomesoplenty:leaves_0:3)
Block(-14,24,4,biomesoplenty:leaves_0:3)
Block(-14,24,5,biomesoplenty:leaves_0:3)
Block(-14,24,6,biomesoplenty:leaves_0:3)
Block(-14,24,7,biomesoplenty:log_1:9)
Block(-14,24,8,biomesoplenty:log_1:1)
Block(-14,24,9,biomesoplenty:leaves_0:3)
Block(-14,24,10,biomesoplenty:leaves_0:3)
Block(-14,24,11,biomesoplenty:log_1:9)
Block(-14,24,13,biomesoplenty:log_1:1)
Block(-14,24,14,biomesoplenty:leaves_0:3)
Block(-14,24,15,biomesoplenty:leaves_0:3)
Block(-14,24,16,biomesoplenty:leaves_0:3)
Block(-14,24,17,biomesoplenty:leaves_0:3)
Block(-14,24,18,biomesoplenty:leaves_0:3)
Block(-14,24,20,biomesoplenty:leaves_0:3)
Block(-14,25,4,biomesoplenty:leaves_0:3)
Block(-14,25,5,biomesoplenty:leaves_0:3)
Block(-14,25,6,biomesoplenty:leaves_0:3)
Block(-14,25,7,biomesoplenty:leaves_0:3)
Block(-14,25,8,biomesoplenty:leaves_0:3)
Block(-14,25,9,biomesoplenty:leaves_0:3)
Block(-14,25,10,biomesoplenty:leaves_0:3)
Block(-14,25,12,biomesoplenty:leaves_0:3)
Block(-14,25,13,biomesoplenty:log_1:5)
Block(-14,25,15,biomesoplenty:leaves_0:3)
Block(-14,25,16,biomesoplenty:leaves_0:3)
Block(-14,25,17,biomesoplenty:leaves_0:3)
Block(-14,25,18,biomesoplenty:leaves_0:3)
Block(-14,25,19,biomesoplenty:leaves_0:3)
Block(-14,25,20,biomesoplenty:leaves_0:3)
Block(-14,26,5,biomesoplenty:leaves_0:3)
Block(-14,26,6,biomesoplenty:log_1:5)
Block(-14,26,7,biomesoplenty:leaves_0:3)
Block(-14,26,8,biomesoplenty:leaves_0:3)
Block(-14,26,9,biomesoplenty:leaves_0:3)
Block(-14,26,10,biomesoplenty:leaves_0:3)
Block(-14,26,11,biomesoplenty:leaves_0:3)
Block(-14,26,12,biomesoplenty:leaves_0:3)
Block(-14,26,14,biomesoplenty:leaves_0:3)
Block(-14,26,15,biomesoplenty:leaves_0:3)
Block(-14,26,16,biomesoplenty:leaves_0:3)
Block(-14,26,18,biomesoplenty:leaves_0:3)
Block(-14,26,19,biomesoplenty:leaves_0:3)
Block(-14,27,6,biomesoplenty:leaves_0:3)
Block(-14,27,7,biomesoplenty:leaves_0:3)
Block(-14,27,8,biomesoplenty:leaves_0:3)
Block(-14,27,9,biomesoplenty:leaves_0:3)
Block(-14,27,10,biomesoplenty:leaves_0:3)
Block(-14,27,11,biomesoplenty:leaves_0:3)
Block(-14,27,12,biomesoplenty:leaves_0:3)
Block(-14,27,13,biomesoplenty:leaves_0:3)
Block(-14,27,14,biomesoplenty:leaves_0:3)
Block(-14,27,16,biomesoplenty:leaves_0:3)
Block(-14,28,9,biomesoplenty:leaves_0:3)
Block(-14,28,10,biomesoplenty:leaves_0:3)
Block(-14,28,11,biomesoplenty:leaves_0:3)
Block(-14,28,12,biomesoplenty:leaves_0:3)
Block(-14,28,13,biomesoplenty:leaves_0:3)
Block(-13,16,3,GLOWSTONE)
Block(-13,16,4,biomesoplenty:leaves_0:3)
Block(-13,16,5,biomesoplenty:leaves_0:3)
Block(-13,16,6,biomesoplenty:leaves_0:3)
Block(-13,17,3,biomesoplenty:leaves_0:3)
Block(-13,17,4,biomesoplenty:leaves_0:3)
Block(-13,17,5,biomesoplenty:log_1:9)
Block(-13,17,6,biomesoplenty:leaves_0:3)
Block(-13,17,7,biomesoplenty:leaves_0:3)
Block(-13,17,8,biomesoplenty:leaves_0:3)
Block(-13,18,4,biomesoplenty:leaves_0:3)
Block(-13,18,5,biomesoplenty:leaves_0:3)
Block(-13,18,6,biomesoplenty:leaves_0:3)
Block(-13,18,7,biomesoplenty:leaves_0:3)
Block(-13,18,8,biomesoplenty:leaves_0:3)
Block(-13,21,9,biomesoplenty:leaves_0:3)
Block(-13,22,7,biomesoplenty:leaves_0:3)
Block(-13,22,9,biomesoplenty:leaves_0:3)
Block(-13,22,10,biomesoplenty:leaves_0:3)
Block(-13,22,14,biomesoplenty:leaves_0:3)
Block(-13,22,15,biomesoplenty:leaves_0:3)
Block(-13,22,16,biomesoplenty:leaves_0:3)
Block(-13,22,18,biomesoplenty:leaves_0:3)
Block(-13,23,5,biomesoplenty:leaves_0:3)
Block(-13,23,6,biomesoplenty:leaves_0:3)
Block(-13,23,7,biomesoplenty:leaves_0:3)
Block(-13,23,9,biomesoplenty:leaves_0:3)
Block(-13,23,10,biomesoplenty:leaves_0:3)
Block(-13,23,12,biomesoplenty:leaves_0:3)
Block(-13,23,14,biomesoplenty:leaves_0:3)
Block(-13,23,15,biomesoplenty:leaves_0:3)
Block(-13,23,16,biomesoplenty:leaves_0:3)
Block(-13,23,17,biomesoplenty:leaves_0:3)
Block(-13,23,18,biomesoplenty:leaves_0:3)
Block(-13,23,19,biomesoplenty:leaves_0:3)
Block(-13,23,20,biomesoplenty:leaves_0:3)
Block(-13,24,1,biomesoplenty:leaves_0:3)
Block(-13,24,2,biomesoplenty:leaves_0:3)
Block(-13,24,3,biomesoplenty:leaves_0:3)
Block(-13,24,5,biomesoplenty:leaves_0:3)
Block(-13,24,6,biomesoplenty:leaves_0:3)
Block(-13,24,7,biomesoplenty:leaves_0:3)
Block(-13,24,8,biomesoplenty:log_1:9)
Block(-13,24,9,biomesoplenty:log_1:1)
Block(-13,24,10,biomesoplenty:leaves_0:3)
Block(-13,24,12,biomesoplenty:log_1:1)
Block(-13,24,13,biomesoplenty:log_1:9)
Block(-13,24,14,biomesoplenty:leaves_0:3)
Block(-13,24,15,biomesoplenty:log_1:9)
Block(-13,24,16,biomesoplenty:leaves_0:3)
Block(-13,24,17,biomesoplenty:leaves_0:3)
Block(-13,24,18,biomesoplenty:log_1:1)
Block(-13,24,19,biomesoplenty:leaves_0:3)
Block(-13,24,20,biomesoplenty:leaves_0:3)
Block(-13,24,21,biomesoplenty:leaves_0:3)
Block(-13,25,3,biomesoplenty:leaves_0:3)
Block(-13,25,4,biomesoplenty:leaves_0:3)
Block(-13,25,5,biomesoplenty:leaves_0:3)
Block(-13,25,6,biomesoplenty:leaves_0:3)
Block(-13,25,7,biomesoplenty:leaves_0:3)
Block(-13,25,8,biomesoplenty:leaves_0:3)
Block(-13,25,10,biomesoplenty:leaves_0:3)
Block(-13,25,11,biomesoplenty:leaves_0:3)
Block(-13,25,12,biomesoplenty:leaves_0:3)
Block(-13,25,13,biomesoplenty:leaves_0:3)
Block(-13,25,14,biomesoplenty:leaves_0:3)
Block(-13,25,15,biomesoplenty:leaves_0:3)
Block(-13,25,16,biomesoplenty:leaves_0:3)
Block(-13,25,17,biomesoplenty:leaves_0:3)
Block(-13,25,18,biomesoplenty:leaves_0:3)
Block(-13,25,19,biomesoplenty:leaves_0:3)
Block(-13,25,20,biomesoplenty:leaves_0:3)
Block(-13,25,21,biomesoplenty:leaves_0:3)
Block(-13,26,5,biomesoplenty:leaves_0:3)
Block(-13,26,6,biomesoplenty:leaves_0:3)
Block(-13,26,7,biomesoplenty:leaves_0:3)
Block(-13,26,8,biomesoplenty:leaves_0:3)
Block(-13,26,9,biomesoplenty:leaves_0:3)
Block(-13,26,10,biomesoplenty:leaves_0:3)
Block(-13,26,11,biomesoplenty:leaves_0:3)
Block(-13,26,12,biomesoplenty:leaves_0:3)
Block(-13,26,13,biomesoplenty:leaves_0:3)
Block(-13,26,14,biomesoplenty:leaves_0:3)
Block(-13,26,15,biomesoplenty:leaves_0:3)
Block(-13,26,16,biomesoplenty:leaves_0:3)
Block(-13,26,17,biomesoplenty:leaves_0:3)
Block(-13,26,18,biomesoplenty:leaves_0:3)
Block(-13,27,6,biomesoplenty:leaves_0:3)
Block(-13,27,7,biomesoplenty:leaves_0:3)
Block(-13,27,8,biomesoplenty:leaves_0:3)
Block(-13,27,9,biomesoplenty:leaves_0:3)
Block(-13,27,10,biomesoplenty:leaves_0:3)
Block(-13,27,11,biomesoplenty:leaves_0:3)
Block(-13,27,12,biomesoplenty:leaves_0:3)
Block(-13,27,13,biomesoplenty:leaves_0:3)
Block(-13,27,14,biomesoplenty:leaves_0:3)
Block(-13,27,15,biomesoplenty:leaves_0:3)
Block(-13,27,16,biomesoplenty:leaves_0:3)
Block(-13,27,17,biomesoplenty:leaves_0:3)
Block(-13,28,8,biomesoplenty:leaves_0:3)
Block(-13,28,9,biomesoplenty:leaves_0:3)
Block(-13,28,10,biomesoplenty:leaves_0:3)
Block(-13,28,11,biomesoplenty:leaves_0:3)
Block(-13,28,12,biomesoplenty:leaves_0:3)
Block(-13,28,13,biomesoplenty:leaves_0:3)
Block(-13,29,9,biomesoplenty:leaves_0:3)
Block(-13,29,10,biomesoplenty:leaves_0:3)
Block(-13,29,11,biomesoplenty:leaves_0:3)
Block(-12,10,7,biomesoplenty:leaves_0:3)
Block(-12,11,7,biomesoplenty:leaves_0:3)
Block(-12,12,7,biomesoplenty:leaves_0:3)
Block(-12,13,7,biomesoplenty:leaves_0:3)
Block(-12,14,5,biomesoplenty:leaves_0:3)
Block(-12,14,7,biomesoplenty:log_1:5)
Block(-12,15,5,biomesoplenty:leaves_0:3)
Block(-12,15,7,biomesoplenty:leaves_0:3)
Block(-12,16,5,biomesoplenty:leaves_0:3)
Block(-12,16,6,biomesoplenty:leaves_0:3)
Block(-12,16,7,biomesoplenty:leaves_0:3)
Block(-12,17,3,biomesoplenty:leaves_0:3)
Block(-12,17,4,biomesoplenty:log_1:1)
Block(-12,17,5,biomesoplenty:leaves_0:3)
Block(-12,17,6,biomesoplenty:leaves_0:3)
Block(-12,17,7,biomesoplenty:log_1:9)
Block(-12,17,8,biomesoplenty:leaves_0:3)
Block(-12,18,5,biomesoplenty:log_1:9)
Block(-12,18,6,biomesoplenty:log_1:5)
Block(-12,18,8,biomesoplenty:leaves_0:3)
Block(-12,18,16,biomesoplenty:leaves_0:3)
Block(-12,19,6,biomesoplenty:leaves_0:3)
Block(-12,19,7,biomesoplenty:log_1:5)
Block(-12,19,16,biomesoplenty:leaves_0:3)
Block(-12,20,6,biomesoplenty:leaves_0:3)
Block(-12,20,8,biomesoplenty:log_1:5)
Block(-12,20,16,biomesoplenty:leaves_0:3)
Block(-12,21,9,biomesoplenty:log_1:5)
Block(-12,21,10,biomesoplenty:log_1:5)
Block(-12,21,11,biomesoplenty:leaves_0:3)
Block(-12,21,16,biomesoplenty:leaves_0:3)
Block(-12,22,9,biomesoplenty:leaves_0:3)
Block(-12,22,10,biomesoplenty:log_1:5)
Block(-12,22,11,biomesoplenty:leaves_0:3)
Block(-12,22,12,biomesoplenty:leaves_0:3)
Block(-12,22,15,biomesoplenty:leaves_0:3)
Block(-12,22,16,biomesoplenty:log_1:5)
Block(-12,22,17,biomesoplenty:leaves_0:3)
Block(-12,22,18,biomesoplenty:leaves_0:3)
Block(-12,22,19,biomesoplenty:leaves_0:3)
Block(-12,22,20,biomesoplenty:leaves_0:3)
Block(-12,23,3,biomesoplenty:leaves_0:3)
Block(-12,23,4,biomesoplenty:leaves_0:3)
Block(-12,23,6,biomesoplenty:leaves_0:3)
Block(-12,23,7,biomesoplenty:leaves_0:3)
Block(-12,23,10,biomesoplenty:leaves_0:3)
Block(-12,23,11,biomesoplenty:leaves_0:3)
Block(-12,23,12,biomesoplenty:leaves_0:3)
Block(-12,23,15,biomesoplenty:leaves_0:3)
Block(-12,23,16,biomesoplenty:leaves_0:3)
Block(-12,23,17,biomesoplenty:leaves_0:3)
Block(-12,23,18,biomesoplenty:leaves_0:3)
Block(-12,23,19,biomesoplenty:leaves_0:3)
Block(-12,23,20,biomesoplenty:leaves_0:3)
Block(-12,23,21,biomesoplenty:leaves_0:3)
Block(-12,24,1,biomesoplenty:leaves_0:3)
Block(-12,24,2,biomesoplenty:leaves_0:3)
Block(-12,24,3,biomesoplenty:leaves_0:3)
Block(-12,24,4,biomesoplenty:log_1:9)
Block(-12,24,5,biomesoplenty:log_1:9)
Block(-12,24,6,biomesoplenty:log_1:9)
Block(-12,24,7,biomesoplenty:log_1:1)
Block(-12,24,8,biomesoplenty:log_1:9)
Block(-12,24,9,biomesoplenty:log_1:1)
Block(-12,24,10,biomesoplenty:log_1:1)
Block(-12,24,11,biomesoplenty:leaves_0:3)
Block(-12,24,12,biomesoplenty:log_1:5)
Block(-12,24,13,biomesoplenty:leaves_0:3)
Block(-12,24,14,biomesoplenty:leaves_0:3)
Block(-12,24,15,biomesoplenty:leaves_0:3)
Block(-12,24,16,biomesoplenty:log_1:1)
Block(-12,24,17,biomesoplenty:leaves_0:3)
Block(-12,24,18,biomesoplenty:log_1:1)
Block(-12,24,19,biomesoplenty:log_1:9)
Block(-12,24,20,biomesoplenty:leaves_0:3)
Block(-12,24,21,biomesoplenty:leaves_0:3)
Block(-12,25,3,biomesoplenty:leaves_0:3)
Block(-12,25,4,biomesoplenty:leaves_0:3)
Block(-12,25,5,biomesoplenty:leaves_0:3)
Block(-12,25,7,biomesoplenty:leaves_0:3)
Block(-12,25,8,biomesoplenty:leaves_0:3)
Block(-12,25,9,biomesoplenty:log_1:5)
Block(-12,25,10,biomesoplenty:leaves_0:3)
Block(-12,25,11,biomesoplenty:leaves_0:3)
Block(-12,25,12,biomesoplenty:log_1:5)
Block(-12,25,15,biomesoplenty:leaves_0:3)
Block(-12,25,16,biomesoplenty:leaves_0:3)
Block(-12,25,17,biomesoplenty:leaves_0:3)
Block(-12,25,18,biomesoplenty:leaves_0:3)
Block(-12,25,19,biomesoplenty:leaves_0:3)
Block(-12,25,20,biomesoplenty:leaves_0:3)
Block(-12,26,4,biomesoplenty:leaves_0:3)
Block(-12,26,5,biomesoplenty:leaves_0:3)
Block(-12,26,6,biomesoplenty:leaves_0:3)
Block(-12,26,7,biomesoplenty:leaves_0:3)
Block(-12,26,8,biomesoplenty:leaves_0:3)
Block(-12,26,9,biomesoplenty:log_1:5)
Block(-12,26,10,biomesoplenty:log_1:9)
Block(-12,26,11,biomesoplenty:leaves_0:3)
Block(-12,26,12,biomesoplenty:log_1:5)
Block(-12,26,13,biomesoplenty:log_1:9)
Block(-12,26,14,biomesoplenty:leaves_0:3)
Block(-12,26,15,biomesoplenty:leaves_0:3)
Block(-12,26,16,biomesoplenty:log_1:5)
Block(-12,26,17,biomesoplenty:leaves_0:3)
Block(-12,26,18,biomesoplenty:leaves_0:3)
Block(-12,27,6,biomesoplenty:leaves_0:3)
Block(-12,27,7,biomesoplenty:leaves_0:3)
Block(-12,27,8,biomesoplenty:log_1:5)
Block(-12,27,9,biomesoplenty:leaves_0:3)
Block(-12,27,10,biomesoplenty:leaves_0:3)
Block(-12,27,11,biomesoplenty:leaves_0:3)
Block(-12,27,12,biomesoplenty:leaves_0:3)
Block(-12,27,13,biomesoplenty:leaves_0:3)
Block(-12,27,14,biomesoplenty:leaves_0:3)
Block(-12,27,15,biomesoplenty:leaves_0:3)
Block(-12,27,16,biomesoplenty:leaves_0:3)
Block(-12,27,17,biomesoplenty:leaves_0:3)
Block(-12,28,7,biomesoplenty:leaves_0:3)
Block(-12,28,8,biomesoplenty:leaves_0:3)
Block(-12,28,9,biomesoplenty:leaves_0:3)
Block(-12,28,10,biomesoplenty:leaves_0:3)
Block(-12,28,11,biomesoplenty:leaves_0:3)
Block(-12,28,13,biomesoplenty:leaves_0:3)
Block(-12,28,14,biomesoplenty:leaves_0:3)
Block(-12,29,9,biomesoplenty:leaves_0:3)
Block(-12,29,10,biomesoplenty:leaves_0:3)
Block(-12,29,11,biomesoplenty:leaves_0:3)
Block(-12,29,12,biomesoplenty:leaves_0:3)
Block(-12,29,13,biomesoplenty:leaves_0:3)
Block(-12,30,11,biomesoplenty:leaves_0:3)
Block(-11,15,3,biomesoplenty:leaves_0:3)
Block(-11,15,4,biomesoplenty:leaves_0:3)
Block(-11,16,2,biomesoplenty:leaves_0:3)
Block(-11,16,3,biomesoplenty:log_1:9)
Block(-11,16,4,biomesoplenty:log_1:5)
Block(-11,16,6,biomesoplenty:leaves_0:3)
Block(-11,17,4,biomesoplenty:log_1:5)
Block(-11,17,5,biomesoplenty:log_1:5)
Block(-11,17,6,biomesoplenty:log_1:5)
Block(-11,17,7,biomesoplenty:leaves_0:3)
Block(-11,18,5,biomesoplenty:log_1:5)
Block(-11,18,6,biomesoplenty:log_1:5)
Block(-11,18,7,biomesoplenty:log_1:5)
Block(-11,18,18,biomesoplenty:leaves_0:3)
Block(-11,19,6,biomesoplenty:log_1:5)
Block(-11,19,7,biomesoplenty:log_1:5)
Block(-11,19,8,biomesoplenty:log_1:5)
Block(-11,19,9,biomesoplenty:leaves_0:3)
Block(-11,19,18,biomesoplenty:leaves_0:3)
Block(-11,20,6,biomesoplenty:leaves_0:3)
Block(-11,20,7,biomesoplenty:log_1:5)
Block(-11,20,8,biomesoplenty:log_1:5)
Block(-11,20,9,biomesoplenty:log_1:5)
Block(-11,20,10,biomesoplenty:log_1:5)
Block(-11,20,18,biomesoplenty:leaves_0:3)
Block(-11,21,7,biomesoplenty:leaves_0:3)
Block(-11,21,8,biomesoplenty:log_1:5)
Block(-11,21,9,biomesoplenty:log_1:5)
Block(-11,21,10,biomesoplenty:log_1:5)
Block(-11,21,11,biomesoplenty:log_1:5)
Block(-11,21,18,biomesoplenty:leaves_0:3)
Block(-11,22,8,GLOWSTONE)
Block(-11,22,9,biomesoplenty:log_1:5)
Block(-11,22,10,biomesoplenty:log_1:5)
Block(-11,22,11,biomesoplenty:log_1:5)
Block(-11,22,12,biomesoplenty:leaves_0:3)
Block(-11,22,13,biomesoplenty:leaves_0:3)
Block(-11,22,17,biomesoplenty:leaves_0:3)
Block(-11,22,18,biomesoplenty:log_1:5)
Block(-11,22,19,biomesoplenty:leaves_0:3)
Block(-11,22,20,biomesoplenty:leaves_0:3)
Block(-11,23,2,biomesoplenty:leaves_0:3)
Block(-11,23,3,biomesoplenty:leaves_0:3)
Block(-11,23,5,biomesoplenty:leaves_0:3)
Block(-11,23,6,biomesoplenty:leaves_0:3)
Block(-11,23,9,biomesoplenty:leaves_0:3)
Block(-11,23,10,biomesoplenty:log_1:5)
Block(-11,23,11,biomesoplenty:leaves_0:3)
Block(-11,23,12,biomesoplenty:log_1:1)
Block(-11,23,13,biomesoplenty:leaves_0:3)
Block(-11,23,14,biomesoplenty:leaves_0:3)
Block(-11,23,15,biomesoplenty:leaves_0:3)
Block(-11,23,16,biomesoplenty:leaves_0:3)
Block(-11,23,17,biomesoplenty:leaves_0:3)
Block(-11,23,18,biomesoplenty:leaves_0:3)
Block(-11,23,19,biomesoplenty:leaves_0:3)
Block(-11,23,20,biomesoplenty:leaves_0:3)
Block(-11,24,2,biomesoplenty:leaves_0:3)
Block(-11,24,3,biomesoplenty:leaves_0:3)
Block(-11,24,5,biomesoplenty:leaves_0:3)
Block(-11,24,6,biomesoplenty:log_1:1)
Block(-11,24,9,biomesoplenty:log_1:9)
Block(-11,24,10,biomesoplenty:log_1:1)
Block(-11,24,13,biomesoplenty:leaves_0:3)
Block(-11,24,14,biomesoplenty:leaves_0:3)
Block(-11,24,15,biomesoplenty:leaves_0:3)
Block(-11,24,16,biomesoplenty:log_1:1)
Block(-11,24,17,biomesoplenty:log_1:9)
Block(-11,24,18,biomesoplenty:log_1:9)
Block(-11,24,19,biomesoplenty:leaves_0:3)
Block(-11,24,20,biomesoplenty:leaves_0:3)
Block(-11,24,21,biomesoplenty:leaves_0:3)
Block(-11,24,22,biomesoplenty:leaves_0:3)
Block(-11,25,3,biomesoplenty:leaves_0:3)
Block(-11,25,4,biomesoplenty:leaves_0:3)
Block(-11,25,7,biomesoplenty:leaves_0:3)
Block(-11,25,8,biomesoplenty:leaves_0:3)
Block(-11,25,9,biomesoplenty:leaves_0:3)
Block(-11,25,10,biomesoplenty:leaves_0:3)
Block(-11,25,11,biomesoplenty:leaves_0:3)
Block(-11,25,13,biomesoplenty:leaves_0:3)
Block(-11,25,14,biomesoplenty:leaves_0:3)
Block(-11,25,15,biomesoplenty:leaves_0:3)
Block(-11,25,16,biomesoplenty:leaves_0:3)
Block(-11,25,17,biomesoplenty:leaves_0:3)
Block(-11,25,18,biomesoplenty:leaves_0:3)
Block(-11,25,19,biomesoplenty:leaves_0:3)
Block(-11,25,20,biomesoplenty:leaves_0:3)
Block(-11,25,21,biomesoplenty:leaves_0:3)
Block(-11,26,5,biomesoplenty:leaves_0:3)
Block(-11,26,6,biomesoplenty:leaves_0:3)
Block(-11,26,7,biomesoplenty:leaves_0:3)
Block(-11,26,8,biomesoplenty:leaves_0:3)
Block(-11,26,9,biomesoplenty:leaves_0:3)
Block(-11,26,10,biomesoplenty:leaves_0:3)
Block(-11,26,12,biomesoplenty:leaves_0:3)
Block(-11,26,13,biomesoplenty:leaves_0:3)
Block(-11,26,14,biomesoplenty:leaves_0:3)
Block(-11,26,16,biomesoplenty:leaves_0:3)
Block(-11,26,17,biomesoplenty:log_1:5)
Block(-11,26,18,biomesoplenty:leaves_0:3)
Block(-11,26,19,biomesoplenty:leaves_0:3)
Block(-11,26,20,biomesoplenty:leaves_0:3)
Block(-11,27,6,biomesoplenty:leaves_0:3)
Block(-11,27,7,biomesoplenty:leaves_0:3)
Block(-11,27,8,biomesoplenty:leaves_0:3)
Block(-11,27,9,biomesoplenty:leaves_0:3)
Block(-11,27,10,biomesoplenty:leaves_0:3)
Block(-11,27,11,biomesoplenty:leaves_0:3)
Block(-11,27,12,biomesoplenty:leaves_0:3)
Block(-11,27,13,biomesoplenty:leaves_0:3)
Block(-11,27,14,biomesoplenty:leaves_0:3)
Block(-11,27,16,biomesoplenty:leaves_0:3)
Block(-11,27,17,biomesoplenty:leaves_0:3)
Block(-11,28,7,biomesoplenty:leaves_0:3)
Block(-11,28,8,biomesoplenty:leaves_0:3)
Block(-11,28,9,biomesoplenty:leaves_0:3)
Block(-11,28,10,biomesoplenty:leaves_0:3)
Block(-11,28,11,biomesoplenty:leaves_0:3)
Block(-11,28,12,biomesoplenty:leaves_0:3)
Block(-11,28,13,biomesoplenty:leaves_0:3)
Block(-11,28,14,biomesoplenty:leaves_0:3)
Block(-11,28,15,biomesoplenty:leaves_0:3)
Block(-11,29,9,biomesoplenty:leaves_0:3)
Block(-11,29,10,biomesoplenty:leaves_0:3)
Block(-11,29,11,biomesoplenty:leaves_0:3)
Block(-11,29,12,biomesoplenty:leaves_0:3)
Block(-11,29,13,biomesoplenty:leaves_0:3)
Block(-11,29,14,biomesoplenty:leaves_0:3)
Block(-11,30,11,biomesoplenty:leaves_0:3)
Block(-11,30,12,biomesoplenty:leaves_0:3)
Block(-10,11,3,biomesoplenty:leaves_0:3)
Block(-10,12,3,biomesoplenty:leaves_0:3)
Block(-10,13,0,biomesoplenty:leaves_0:3)
Block(-10,13,1,biomesoplenty:leaves_0:3)
Block(-10,13,3,biomesoplenty:leaves_0:3)
Block(-10,14,3,biomesoplenty:leaves_0:3)
Block(-10,15,3,biomesoplenty:log_1:5)
Block(-10,15,4,biomesoplenty:log_1:5)
Block(-10,16,1,biomesoplenty:leaves_0:3)
Block(-10,16,2,biomesoplenty:log_1:9)
Block(-10,16,3,biomesoplenty:log_1:5)
Block(-10,16,4,biomesoplenty:log_1:5)
Block(-10,16,5,biomesoplenty:log_1:5)
Block(-10,16,6,biomesoplenty:log_1:5)
Block(-10,17,2,biomesoplenty:leaves_0:3)
Block(-10,17,3,biomesoplenty:log_1:5)
Block(-10,17,4,biomesoplenty:log_1:5)
Block(-10,17,5,biomesoplenty:log_1:5)
Block(-10,17,6,biomesoplenty:log_1:5)
Block(-10,17,7,biomesoplenty:log_1:5)
Block(-10,17,8,biomesoplenty:leaves_0:3)
Block(-10,18,3,biomesoplenty:leaves_0:3)
Block(-10,18,4,biomesoplenty:log_1:5)
Block(-10,18,5,biomesoplenty:log_1:5)
Block(-10,18,6,biomesoplenty:log_1:5)
Block(-10,18,7,biomesoplenty:log_1:5)
Block(-10,19,4,GLOWSTONE)
Block(-10,19,5,biomesoplenty:leaves_0:3)
Block(-10,19,6,biomesoplenty:log_1:5)
Block(-10,19,7,biomesoplenty:log_1:5)
Block(-10,19,8,biomesoplenty:leaves_0:3)
Block(-10,20,6,biomesoplenty:leaves_0:3)
Block(-10,20,7,biomesoplenty:leaves_0:3)
Block(-10,20,8,biomesoplenty:log_1:5)
Block(-10,20,9,biomesoplenty:log_1:1)
Block(-10,20,10,biomesoplenty:leaves_0:3)
Block(-10,20,11,GLOWSTONE)
Block(-10,21,7,biomesoplenty:leaves_0:3)
Block(-10,21,8,biomesoplenty:leaves_0:3)
Block(-10,21,9,biomesoplenty:log_1:5)
Block(-10,21,10,biomesoplenty:log_1:5)
Block(-10,21,11,biomesoplenty:log_1:5)
Block(-10,22,6,biomesoplenty:leaves_0:3)
Block(-10,22,7,biomesoplenty:leaves_0:3)
Block(-10,22,8,biomesoplenty:leaves_0:3)
Block(-10,22,9,biomesoplenty:log_1:5)
Block(-10,22,10,biomesoplenty:log_1:5)
Block(-10,22,11,biomesoplenty:log_1:5)
Block(-10,22,12,biomesoplenty:log_1:5)
Block(-10,22,13,biomesoplenty:leaves_0:3)
Block(-10,22,16,biomesoplenty:leaves_0:3)
Block(-10,22,17,biomesoplenty:leaves_0:3)
Block(-10,22,18,biomesoplenty:leaves_0:3)
Block(-10,22,19,biomesoplenty:leaves_0:3)
Block(-10,22,20,biomesoplenty:leaves_0:3)
Block(-10,23,4,biomesoplenty:leaves_0:3)
Block(-10,23,5,biomesoplenty:leaves_0:3)
Block(-10,23,6,biomesoplenty:leaves_0:3)
Block(-10,23,9,biomesoplenty:leaves_0:3)
Block(-10,23,10,biomesoplenty:log_1:5)
Block(-10,23,11,biomesoplenty:log_1:5)
Block(-10,23,12,biomesoplenty:log_1:5)
Block(-10,23,13,biomesoplenty:leaves_0:3)
Block(-10,23,14,biomesoplenty:log_1:1)
Block(-10,23,15,biomesoplenty:log_1:9)
Block(-10,23,16,biomesoplenty:leaves_0:3)
Block(-10,23,17,biomesoplenty:leaves_0:3)
Block(-10,23,19,biomesoplenty:leaves_0:3)
Block(-10,24,1,biomesoplenty:leaves_0:3)
Block(-10,24,2,biomesoplenty:leaves_0:3)
Block(-10,24,3,biomesoplenty:leaves_0:3)
Block(-10,24,4,biomesoplenty:leaves_0:3)
Block(-10,24,5,biomesoplenty:leaves_0:3)
Block(-10,24,6,biomesoplenty:leaves_0:3)
Block(-10,24,8,biomesoplenty:leaves_0:3)
Block(-10,24,9,biomesoplenty:leaves_0:3)
Block(-10,24,10,biomesoplenty:leaves_0:3)
Block(-10,24,11,biomesoplenty:leaves_0:3)
Block(-10,24,12,biomesoplenty:leaves_0:3)
Block(-10,24,13,biomesoplenty:leaves_0:3)
Block(-10,24,15,biomesoplenty:log_1:5)
Block(-10,24,16,biomesoplenty:log_1:9)
Block(-10,24,17,biomesoplenty:leaves_0:3)
Block(-10,24,18,biomesoplenty:leaves_0:3)
Block(-10,24,19,biomesoplenty:leaves_0:3)
Block(-10,24,20,biomesoplenty:leaves_0:3)
Block(-10,24,21,biomesoplenty:leaves_0:3)
Block(-10,24,22,biomesoplenty:leaves_0:3)
Block(-10,25,3,biomesoplenty:leaves_0:3)
Block(-10,25,4,biomesoplenty:leaves_0:3)
Block(-10,25,5,biomesoplenty:leaves_0:3)
Block(-10,25,8,biomesoplenty:leaves_0:3)
Block(-10,25,9,biomesoplenty:leaves_0:3)
Block(-10,25,10,biomesoplenty:leaves_0:3)
Block(-10,25,11,biomesoplenty:log_1:5)
Block(-10,25,12,biomesoplenty:leaves_0:3)
Block(-10,25,13,biomesoplenty:leaves_0:3)
Block(-10,25,14,biomesoplenty:leaves_0:3)
Block(-10,25,15,biomesoplenty:log_1:5)
Block(-10,25,16,biomesoplenty:leaves_0:3)
Block(-10,25,17,biomesoplenty:leaves_0:3)
Block(-10,25,18,biomesoplenty:log_1:5)
Block(-10,25,19,biomesoplenty:log_1:5)
Block(-10,25,20,biomesoplenty:leaves_0:3)
Block(-10,26,4,biomesoplenty:leaves_0:3)
Block(-10,26,5,biomesoplenty:leaves_0:3)
Block(-10,26,6,biomesoplenty:leaves_0:3)
Block(-10,26,7,biomesoplenty:leaves_0:3)
Block(-10,26,8,biomesoplenty:leaves_0:3)
Block(-10,26,9,biomesoplenty:leaves_0:3)
Block(-10,26,10,biomesoplenty:leaves_0:3)
Block(-10,26,11,biomesoplenty:log_1:5)
Block(-10,26,12,biomesoplenty:log_1:9)
Block(-10,26,13,biomesoplenty:leaves_0:3)
Block(-10,26,14,biomesoplenty:log_1:9)
Block(-10,26,15,biomesoplenty:log_1:5)
Block(-10,26,16,biomesoplenty:leaves_0:3)
Block(-10,26,17,biomesoplenty:leaves_0:3)
Block(-10,26,18,biomesoplenty:leaves_0:3)
Block(-10,26,19,biomesoplenty:leaves_0:3)
Block(-10,27,6,biomesoplenty:leaves_0:3)
Block(-10,27,7,biomesoplenty:log_1:5)
Block(-10,27,8,biomesoplenty:leaves_0:3)
Block(-10,27,9,biomesoplenty:leaves_0:3)
Block(-10,27,10,biomesoplenty:leaves_0:3)
Block(-10,27,11,biomesoplenty:log_1:5)
Block(-10,27,12,biomesoplenty:leaves_0:3)
Block(-10,27,14,biomesoplenty:log_1:5)
Block(-10,27,15,biomesoplenty:leaves_0:3)
Block(-10,27,16,biomesoplenty:leaves_0:3)
Block(-10,27,17,biomesoplenty:leaves_0:3)
Block(-10,28,6,biomesoplenty:leaves_0:3)
Block(-10,28,7,biomesoplenty:leaves_0:3)
Block(-10,28,8,biomesoplenty:leaves_0:3)
Block(-10,28,9,biomesoplenty:leaves_0:3)
Block(-10,28,10,biomesoplenty:leaves_0:3)
Block(-10,28,11,biomesoplenty:log_1:5)
Block(-10,28,12,biomesoplenty:leaves_0:3)
Block(-10,28,13,biomesoplenty:leaves_0:3)
Block(-10,28,14,biomesoplenty:leaves_0:3)
Block(-10,28,15,biomesoplenty:leaves_0:3)
Block(-10,28,16,biomesoplenty:leaves_0:3)
Block(-10,29,9,biomesoplenty:leaves_0:3)
Block(-10,29,10,biomesoplenty:leaves_0:3)
Block(-10,29,11,biomesoplenty:leaves_0:3)
Block(-10,29,12,biomesoplenty:leaves_0:3)
Block(-10,29,13,biomesoplenty:leaves_0:3)
Block(-10,29,14,biomesoplenty:leaves_0:3)
Block(-10,29,15,biomesoplenty:leaves_0:3)
Block(-10,30,11,biomesoplenty:leaves_0:3)
Block(-10,30,12,biomesoplenty:leaves_0:3)
Block(-10,30,13,biomesoplenty:leaves_0:3)
Block(-9,12,-1,biomesoplenty:leaves_0:3)
Block(-9,13,-2,biomesoplenty:leaves_0:3)
Block(-9,13,-1,biomesoplenty:leaves_0:3)
Block(-9,13,0,biomesoplenty:leaves_0:3)
Block(-9,13,1,biomesoplenty:leaves_0:3)
Block(-9,14,-1,biomesoplenty:leaves_0:3)
Block(-9,14,0,biomesoplenty:leaves_0:3)
Block(-9,14,3,biomesoplenty:log_1:5)
Block(-9,14,4,biomesoplenty:leaves_0:3)
Block(-9,15,0,biomesoplenty:leaves_0:3)
Block(-9,15,1,biomesoplenty:log_1:9)
Block(-9,15,2,biomesoplenty:log_1:5)
Block(-9,15,3,biomesoplenty:log_1:5)
Block(-9,15,4,biomesoplenty:log_1:5)
Block(-9,15,5,biomesoplenty:leaves_0:3)
Block(-9,15,6,biomesoplenty:leaves_0:3)
Block(-9,16,2,biomesoplenty:log_1:5)
Block(-9,16,3,biomesoplenty:log_1:5)
Block(-9,16,4,biomesoplenty:log_1:5)
Block(-9,16,5,biomesoplenty:log_1:5)
Block(-9,17,2,biomesoplenty:leaves_0:3)
Block(-9,17,3,biomesoplenty:log_1:5)
Block(-9,17,4,biomesoplenty:log_1:5)
Block(-9,17,5,biomesoplenty:log_1:5)
Block(-9,17,6,biomesoplenty:log_1:5)
Block(-9,18,3,biomesoplenty:leaves_0:3)
Block(-9,18,4,biomesoplenty:leaves_0:3)
Block(-9,18,6,biomesoplenty:log_1:5)
Block(-9,19,7,biomesoplenty:leaves_0:3)
Block(-9,19,9,biomesoplenty:leaves_0:3)
Block(-9,20,6,biomesoplenty:leaves_0:3)
Block(-9,20,7,biomesoplenty:leaves_0:3)
Block(-9,20,8,biomesoplenty:leaves_0:3)
Block(-9,20,9,biomesoplenty:log_1:1)
Block(-9,20,10,biomesoplenty:leaves_0:3)
Block(-9,20,11,biomesoplenty:log_1:5)
Block(-9,21,7,biomesoplenty:leaves_0:3)
Block(-9,21,8,biomesoplenty:leaves_0:3)
Block(-9,21,9,biomesoplenty:leaves_0:3)
Block(-9,21,10,biomesoplenty:leaves_0:3)
Block(-9,21,11,biomesoplenty:log_1:5)
Block(-9,21,15,biomesoplenty:leaves_0:3)
Block(-9,22,8,biomesoplenty:leaves_0:3)
Block(-9,22,9,biomesoplenty:leaves_0:3)
Block(-9,22,10,biomesoplenty:log_1:5)
Block(-9,22,11,biomesoplenty:log_1:5)
Block(-9,22,12,biomesoplenty:log_1:5)
Block(-9,22,13,biomesoplenty:leaves_0:3)
Block(-9,22,14,biomesoplenty:leaves_0:3)
Block(-9,22,15,biomesoplenty:leaves_0:3)
Block(-9,22,16,biomesoplenty:leaves_0:3)
Block(-9,22,17,biomesoplenty:leaves_0:3)
Block(-9,23,2,biomesoplenty:leaves_0:3)
Block(-9,23,3,biomesoplenty:leaves_0:3)
Block(-9,23,4,biomesoplenty:leaves_0:3)
Block(-9,23,9,biomesoplenty:leaves_0:3)
Block(-9,23,10,biomesoplenty:log_1:5)
Block(-9,23,11,biomesoplenty:log_1:5)
Block(-9,23,12,biomesoplenty:log_1:5)
Block(-9,23,13,biomesoplenty:log_1:5)
Block(-9,23,14,biomesoplenty:log_1:9)
Block(-9,23,16,biomesoplenty:leaves_0:3)
Block(-9,23,17,biomesoplenty:leaves_0:3)
Block(-9,23,18,biomesoplenty:leaves_0:3)
Block(-9,23,19,biomesoplenty:leaves_0:3)
Block(-9,23,20,biomesoplenty:leaves_0:3)
Block(-9,24,2,biomesoplenty:leaves_0:3)
Block(-9,24,3,biomesoplenty:leaves_0:3)
Block(-9,24,4,biomesoplenty:log_1:9)
Block(-9,24,5,biomesoplenty:log_1:1)
Block(-9,24,7,biomesoplenty:leaves_0:3)
Block(-9,24,8,biomesoplenty:leaves_0:3)
Block(-9,24,9,biomesoplenty:log_1:9)
Block(-9,24,10,biomesoplenty:log_1:9)
Block(-9,24,11,biomesoplenty:log_1:5)
Block(-9,24,12,biomesoplenty:log_1:5)
Block(-9,24,13,biomesoplenty:leaves_0:3)
Block(-9,24,14,biomesoplenty:leaves_0:3)
Block(-9,24,15,biomesoplenty:leaves_0:3)
Block(-9,24,16,biomesoplenty:leaves_0:3)
Block(-9,24,17,biomesoplenty:leaves_0:3)
Block(-9,24,18,biomesoplenty:leaves_0:3)
Block(-9,24,19,biomesoplenty:leaves_0:3)
Block(-9,24,20,biomesoplenty:leaves_0:3)
Block(-9,24,21,biomesoplenty:leaves_0:3)
Block(-9,24,22,biomesoplenty:leaves_0:3)
Block(-9,25,2,biomesoplenty:leaves_0:3)
Block(-9,25,3,biomesoplenty:leaves_0:3)
Block(-9,25,4,biomesoplenty:leaves_0:3)
Block(-9,25,5,biomesoplenty:log_1:9)
Block(-9,25,6,biomesoplenty:leaves_0:3)
Block(-9,25,7,biomesoplenty:leaves_0:3)
Block(-9,25,9,biomesoplenty:leaves_0:3)
Block(-9,25,11,biomesoplenty:leaves_0:3)
Block(-9,25,12,biomesoplenty:leaves_0:3)
Block(-9,25,13,biomesoplenty:leaves_0:3)
Block(-9,25,14,biomesoplenty:leaves_0:3)
Block(-9,25,15,biomesoplenty:leaves_0:3)
Block(-9,25,16,biomesoplenty:leaves_0:3)
Block(-9,25,17,biomesoplenty:leaves_0:3)
Block(-9,25,18,biomesoplenty:leaves_0:3)
Block(-9,25,19,biomesoplenty:leaves_0:3)
Block(-9,25,20,biomesoplenty:leaves_0:3)
Block(-9,26,5,biomesoplenty:leaves_0:3)
Block(-9,26,6,biomesoplenty:leaves_0:3)
Block(-9,26,7,biomesoplenty:leaves_0:3)
Block(-9,26,8,biomesoplenty:log_1:1)
Block(-9,26,9,biomesoplenty:log_1:9)
Block(-9,26,10,biomesoplenty:leaves_0:3)
Block(-9,26,11,biomesoplenty:leaves_0:3)
Block(-9,26,12,biomesoplenty:leaves_0:3)
Block(-9,26,13,biomesoplenty:leaves_0:3)
Block(-9,26,14,biomesoplenty:leaves_0:3)
Block(-9,26,15,biomesoplenty:leaves_0:3)
Block(-9,26,16,biomesoplenty:leaves_0:3)
Block(-9,26,17,biomesoplenty:leaves_0:3)
Block(-9,26,18,biomesoplenty:leaves_0:3)
Block(-9,26,19,biomesoplenty:leaves_0:3)
Block(-9,27,6,biomesoplenty:leaves_0:3)
Block(-9,27,7,biomesoplenty:log_1:5)
Block(-9,27,8,biomesoplenty:leaves_0:3)
Block(-9,27,10,biomesoplenty:leaves_0:3)
Block(-9,27,11,biomesoplenty:leaves_0:3)
Block(-9,27,12,biomesoplenty:leaves_0:3)
Block(-9,27,13,biomesoplenty:leaves_0:3)
Block(-9,27,14,biomesoplenty:leaves_0:3)
Block(-9,27,15,biomesoplenty:leaves_0:3)
Block(-9,27,16,biomesoplenty:leaves_0:3)
Block(-9,27,17,biomesoplenty:leaves_0:3)
Block(-9,28,7,biomesoplenty:leaves_0:3)
Block(-9,28,8,biomesoplenty:leaves_0:3)
Block(-9,28,9,biomesoplenty:leaves_0:3)
Block(-9,28,10,biomesoplenty:leaves_0:3)
Block(-9,28,11,biomesoplenty:leaves_0:3)
Block(-9,28,13,biomesoplenty:leaves_0:3)
Block(-9,28,14,biomesoplenty:leaves_0:3)
Block(-9,28,15,biomesoplenty:leaves_0:3)
Block(-9,28,16,biomesoplenty:leaves_0:3)
Block(-9,29,10,biomesoplenty:leaves_0:3)
Block(-9,29,11,biomesoplenty:leaves_0:3)
Block(-9,29,12,biomesoplenty:leaves_0:3)
Block(-9,29,13,biomesoplenty:leaves_0:3)
Block(-9,29,14,biomesoplenty:leaves_0:3)
Block(-9,29,15,biomesoplenty:leaves_0:3)
Block(-9,30,12,biomesoplenty:leaves_0:3)
Block(-8,8,-1,biomesoplenty:leaves_0:3)
Block(-8,9,-1,biomesoplenty:leaves_0:3)
Block(-8,10,-1,biomesoplenty:leaves_0:3)
Block(-8,11,-1,biomesoplenty:leaves_0:3)
Block(-8,12,-4,biomesoplenty:leaves_0:3)
Block(-8,12,-3,biomesoplenty:leaves_0:3)
Block(-8,12,-2,biomesoplenty:leaves_0:3)
Block(-8,12,-1,biomesoplenty:log_1:1)
Block(-8,12,0,biomesoplenty:leaves_0:3)
Block(-8,13,-3,biomesoplenty:leaves_0:3)
Block(-8,13,-2,biomesoplenty:leaves_0:3)
Block(-8,13,-1,biomesoplenty:leaves_0:3)
Block(-8,13,0,biomesoplenty:leaves_0:3)
Block(-8,13,1,biomesoplenty:leaves_0:3)
Block(-8,14,-1,biomesoplenty:leaves_0:3)
Block(-8,14,0,biomesoplenty:log_1:1)
Block(-8,14,1,biomesoplenty:log_1:5)
Block(-8,14,2,biomesoplenty:log_1:5)
Block(-8,14,3,biomesoplenty:log_1:5)
Block(-8,14,4,biomesoplenty:leaves_0:3)
Block(-8,14,5,biomesoplenty:leaves_0:3)
Block(-8,15,0,biomesoplenty:leaves_0:3)
Block(-8,15,1,biomesoplenty:log_1:5)
Block(-8,15,2,biomesoplenty:log_1:5)
Block(-8,15,3,biomesoplenty:log_1:5)
Block(-8,15,4,biomesoplenty:log_1:5)
Block(-8,15,5,biomesoplenty:log_1:9)
Block(-8,15,6,biomesoplenty:log_1:9)
Block(-8,15,7,biomesoplenty:leaves_0:3)
Block(-8,16,1,biomesoplenty:log_1:5)
Block(-8,16,2,biomesoplenty:log_1:5)
Block(-8,16,3,biomesoplenty:log_1:5)
Block(-8,16,4,biomesoplenty:log_1:5)
Block(-8,16,5,biomesoplenty:leaves_0:3)
Block(-8,16,6,biomesoplenty:leaves_0:3)
Block(-8,16,8,biomesoplenty:leaves_0:3)
Block(-8,17,3,biomesoplenty:leaves_0:3)
Block(-8,17,4,biomesoplenty:leaves_0:3)
Block(-8,17,5,biomesoplenty:leaves_0:3)
Block(-8,17,8,biomesoplenty:leaves_0:3)
Block(-8,17,14,biomesoplenty:leaves_0:3)
Block(-8,18,4,biomesoplenty:leaves_0:3)
Block(-8,18,8,biomesoplenty:leaves_0:3)
Block(-8,18,11,biomesoplenty:log_1:5)
Block(-8,18,14,biomesoplenty:leaves_0:3)
Block(-8,19,8,biomesoplenty:leaves_0:3)
Block(-8,19,10,biomesoplenty:leaves_0:3)
Block(-8,19,11,biomesoplenty:log_1:5)
Block(-8,19,14,biomesoplenty:leaves_0:3)
Block(-8,20,6,biomesoplenty:leaves_0:3)
Block(-8,20,7,biomesoplenty:leaves_0:3)
Block(-8,20,8,biomesoplenty:log_1:9)
Block(-8,20,9,biomesoplenty:leaves_0:3)
Block(-8,20,10,biomesoplenty:leaves_0:3)
Block(-8,20,11,biomesoplenty:log_1:1)
Block(-8,20,14,biomesoplenty:leaves_0:3)
Block(-8,21,4,biomesoplenty:leaves_0:3)
Block(-8,21,8,biomesoplenty:leaves_0:3)
Block(-8,21,9,biomesoplenty:leaves_0:3)
Block(-8,21,10,biomesoplenty:log_1:5)
Block(-8,21,11,biomesoplenty:leaves_0:3)
Block(-8,21,12,biomesoplenty:leaves_0:3)
Block(-8,21,14,biomesoplenty:log_1:5)
Block(-8,21,15,biomesoplenty:leaves_0:3)
Block(-8,22,4,biomesoplenty:leaves_0:3)
Block(-8,22,5,biomesoplenty:leaves_0:3)
Block(-8,22,8,biomesoplenty:leaves_0:3)
Block(-8,22,11,biomesoplenty:log_1:5)
Block(-8,22,12,biomesoplenty:log_1:5)
Block(-8,22,14,biomesoplenty:leaves_0:3)
Block(-8,22,15,biomesoplenty:leaves_0:3)
Block(-8,22,16,biomesoplenty:leaves_0:3)
Block(-8,22,17,biomesoplenty:leaves_0:3)
Block(-8,23,4,biomesoplenty:leaves_0:3)
Block(-8,23,5,biomesoplenty:leaves_0:3)
Block(-8,23,10,biomesoplenty:leaves_0:3)
Block(-8,23,11,biomesoplenty:log_1:5)
Block(-8,23,12,biomesoplenty:log_1:5)
Block(-8,23,13,biomesoplenty:log_1:5)
Block(-8,23,14,biomesoplenty:leaves_0:3)
Block(-8,23,15,biomesoplenty:leaves_0:3)
Block(-8,23,16,biomesoplenty:leaves_0:3)
Block(-8,23,18,biomesoplenty:leaves_0:3)
Block(-8,23,19,biomesoplenty:leaves_0:3)
Block(-8,24,1,biomesoplenty:leaves_0:3)
Block(-8,24,2,biomesoplenty:leaves_0:3)
Block(-8,24,3,biomesoplenty:leaves_0:3)
Block(-8,24,4,biomesoplenty:leaves_0:3)
Block(-8,24,5,biomesoplenty:log_1:9)
Block(-8,24,6,biomesoplenty:log_1:1)
Block(-8,24,8,biomesoplenty:log_1:9)
Block(-8,24,9,biomesoplenty:log_1:1)
Block(-8,24,11,biomesoplenty:log_1:1)
Block(-8,24,12,biomesoplenty:log_1:5)
Block(-8,24,13,biomesoplenty:leaves_0:3)
Block(-8,24,14,biomesoplenty:leaves_0:3)
Block(-8,24,15,biomesoplenty:leaves_0:3)
Block(-8,24,16,biomesoplenty:leaves_0:3)
Block(-8,24,17,biomesoplenty:leaves_0:3)
Block(-8,24,18,biomesoplenty:leaves_0:3)
Block(-8,24,19,biomesoplenty:log_1:9)
Block(-8,24,20,biomesoplenty:leaves_0:3)
Block(-8,24,21,biomesoplenty:leaves_0:3)
Block(-8,24,22,biomesoplenty:leaves_0:3)
Block(-8,25,2,biomesoplenty:leaves_0:3)
Block(-8,25,4,biomesoplenty:leaves_0:3)
Block(-8,25,5,biomesoplenty:leaves_0:3)
Block(-8,25,7,biomesoplenty:leaves_0:3)
Block(-8,25,8,biomesoplenty:log_1:5)
Block(-8,25,11,biomesoplenty:leaves_0:3)
Block(-8,25,12,biomesoplenty:leaves_0:3)
Block(-8,25,13,biomesoplenty:leaves_0:3)
Block(-8,25,14,biomesoplenty:leaves_0:3)
Block(-8,25,15,biomesoplenty:leaves_0:3)
Block(-8,25,16,biomesoplenty:leaves_0:3)
Block(-8,25,17,biomesoplenty:leaves_0:3)
Block(-8,25,18,biomesoplenty:leaves_0:3)
Block(-8,25,19,biomesoplenty:leaves_0:3)
Block(-8,25,20,biomesoplenty:leaves_0:3)
Block(-8,26,4,biomesoplenty:leaves_0:3)
Block(-8,26,5,biomesoplenty:leaves_0:3)
Block(-8,26,6,biomesoplenty:leaves_0:3)
Block(-8,26,8,biomesoplenty:log_1:5)
Block(-8,26,10,biomesoplenty:leaves_0:3)
Block(-8,26,11,biomesoplenty:leaves_0:3)
Block(-8,26,12,biomesoplenty:leaves_0:3)
Block(-8,26,13,biomesoplenty:leaves_0:3)
Block(-8,26,14,biomesoplenty:leaves_0:3)
Block(-8,26,15,biomesoplenty:log_1:5)
Block(-8,26,16,biomesoplenty:leaves_0:3)
Block(-8,26,17,biomesoplenty:leaves_0:3)
Block(-8,26,18,biomesoplenty:leaves_0:3)
Block(-8,26,19,biomesoplenty:leaves_0:3)
Block(-8,27,7,biomesoplenty:leaves_0:3)
Block(-8,27,8,biomesoplenty:leaves_0:3)
Block(-8,27,9,biomesoplenty:leaves_0:3)
Block(-8,27,10,biomesoplenty:leaves_0:3)
Block(-8,27,11,biomesoplenty:log_1:1)
Block(-8,27,12,biomesoplenty:leaves_0:3)
Block(-8,27,13,biomesoplenty:leaves_0:3)
Block(-8,27,14,biomesoplenty:leaves_0:3)
Block(-8,27,15,biomesoplenty:leaves_0:3)
Block(-8,27,16,biomesoplenty:leaves_0:3)
Block(-8,28,7,biomesoplenty:leaves_0:3)
Block(-8,28,8,biomesoplenty:leaves_0:3)
Block(-8,28,9,biomesoplenty:leaves_0:3)
Block(-8,28,10,biomesoplenty:leaves_0:3)
Block(-8,28,11,biomesoplenty:leaves_0:3)
Block(-8,28,12,biomesoplenty:leaves_0:3)
Block(-8,28,14,biomesoplenty:leaves_0:3)
Block(-8,28,15,biomesoplenty:leaves_0:3)
Block(-8,28,16,biomesoplenty:leaves_0:3)
Block(-8,29,10,biomesoplenty:leaves_0:3)
Block(-8,29,11,biomesoplenty:leaves_0:3)
Block(-8,29,12,biomesoplenty:leaves_0:3)
Block(-8,29,13,biomesoplenty:leaves_0:3)
Block(-8,29,14,biomesoplenty:leaves_0:3)
Block(-7,8,-3,biomesoplenty:leaves_0:3)
Block(-7,8,1,biomesoplenty:leaves_0:3)
Block(-7,9,-3,biomesoplenty:leaves_0:3)
Block(-7,9,0,biomesoplenty:leaves_0:3)
Block(-7,9,1,biomesoplenty:leaves_0:3)
Block(-7,9,2,biomesoplenty:leaves_0:3)
Block(-7,10,-3,biomesoplenty:leaves_0:3)
Block(-7,10,5,biomesoplenty:leaves_0:3)
Block(-7,11,-3,biomesoplenty:leaves_0:3)
Block(-7,11,-2,biomesoplenty:leaves_0:3)
Block(-7,11,5,biomesoplenty:leaves_0:3)
Block(-7,12,-4,biomesoplenty:leaves_0:3)
Block(-7,12,-3,biomesoplenty:log_1:9)
Block(-7,12,-2,biomesoplenty:log_1:9)
Block(-7,12,-1,biomesoplenty:leaves_0:3)
Block(-7,12,0,biomesoplenty:leaves_0:3)
Block(-7,12,1,biomesoplenty:leaves_0:3)
Block(-7,12,5,biomesoplenty:leaves_0:3)
Block(-7,13,-4,biomesoplenty:leaves_0:3)
Block(-7,13,-3,biomesoplenty:leaves_0:3)
Block(-7,13,-2,biomesoplenty:leaves_0:3)
Block(-7,13,-1,biomesoplenty:log_1:1)
Block(-7,13,0,biomesoplenty:log_1:5)
Block(-7,13,1,biomesoplenty:log_1:5)
Block(-7,13,5,biomesoplenty:leaves_0:3)
Block(-7,14,-2,biomesoplenty:leaves_0:3)
Block(-7,14,-1,biomesoplenty:leaves_0:3)
Block(-7,14,0,biomesoplenty:log_1:5)
Block(-7,14,1,biomesoplenty:log_1:5)
Block(-7,14,2,biomesoplenty:log_1:5)
Block(-7,14,3,biomesoplenty:leaves_0:3)
Block(-7,14,4,biomesoplenty:leaves_0:3)
Block(-7,14,5,biomesoplenty:log_1:5)
Block(-7,14,6,biomesoplenty:leaves_0:3)
Block(-7,15,0,biomesoplenty:leaves_0:3)
Block(-7,15,1,biomesoplenty:log_1:5)
Block(-7,15,2,biomesoplenty:log_1:5)
Block(-7,15,3,biomesoplenty:log_1:5)
Block(-7,15,4,biomesoplenty:leaves_0:3)
Block(-7,15,5,biomesoplenty:log_1:1)
Block(-7,15,6,biomesoplenty:leaves_0:3)
Block(-7,15,7,biomesoplenty:leaves_0:3)
Block(-7,16,1,biomesoplenty:log_1:5)
Block(-7,16,2,GLOWSTONE)
Block(-7,16,3,biomesoplenty:leaves_0:3)
Block(-7,16,4,biomesoplenty:leaves_0:3)
Block(-7,16,5,biomesoplenty:leaves_0:3)
Block(-7,16,6,biomesoplenty:leaves_0:3)
Block(-7,17,10,biomesoplenty:log_1:9)
Block(-7,17,11,biomesoplenty:log_1:5)
Block(-7,18,11,biomesoplenty:log_1:1)
Block(-7,18,12,biomesoplenty:leaves_0:3)
Block(-7,19,10,biomesoplenty:leaves_0:3)
Block(-7,19,12,biomesoplenty:leaves_0:3)
Block(-7,20,7,biomesoplenty:leaves_0:3)
Block(-7,20,8,biomesoplenty:leaves_0:3)
Block(-7,20,9,biomesoplenty:leaves_0:3)
Block(-7,20,10,biomesoplenty:leaves_0:3)
Block(-7,21,8,biomesoplenty:leaves_0:3)
Block(-7,21,9,biomesoplenty:log_1:5)
Block(-7,21,13,biomesoplenty:leaves_0:3)
Block(-7,22,13,biomesoplenty:leaves_0:3)
Block(-7,22,16,biomesoplenty:leaves_0:3)
Block(-7,22,17,biomesoplenty:leaves_0:3)
Block(-7,22,18,biomesoplenty:leaves_0:3)
Block(-7,23,4,biomesoplenty:leaves_0:3)
Block(-7,23,6,biomesoplenty:log_1:5)
Block(-7,23,11,biomesoplenty:leaves_0:3)
Block(-7,23,12,biomesoplenty:log_1:5)
Block(-7,23,13,biomesoplenty:log_1:1)
Block(-7,23,14,biomesoplenty:log_1:9)
Block(-7,23,15,biomesoplenty:leaves_0:3)
Block(-7,23,16,biomesoplenty:leaves_0:3)
Block(-7,23,17,biomesoplenty:leaves_0:3)
Block(-7,23,18,biomesoplenty:leaves_0:3)
Block(-7,23,19,biomesoplenty:leaves_0:3)
Block(-7,24,2,biomesoplenty:leaves_0:3)
Block(-7,24,3,biomesoplenty:leaves_0:3)
Block(-7,24,4,biomesoplenty:leaves_0:3)
Block(-7,24,5,biomesoplenty:leaves_0:3)
Block(-7,24,6,biomesoplenty:log_1:9)
Block(-7,24,7,biomesoplenty:log_1:9)
Block(-7,24,8,biomesoplenty:log_1:1)
Block(-7,24,11,biomesoplenty:log_1:1)
Block(-7,24,12,biomesoplenty:leaves_0:3)
Block(-7,24,13,biomesoplenty:leaves_0:3)
Block(-7,24,14,biomesoplenty:leaves_0:3)
Block(-7,24,15,biomesoplenty:leaves_0:3)
Block(-7,24,16,biomesoplenty:leaves_0:3)
Block(-7,24,18,biomesoplenty:leaves_0:3)
Block(-7,24,19,biomesoplenty:leaves_0:3)
Block(-7,24,20,biomesoplenty:leaves_0:3)
Block(-7,24,21,biomesoplenty:leaves_0:3)
Block(-7,24,22,biomesoplenty:leaves_0:3)
Block(-7,25,3,biomesoplenty:leaves_0:3)
Block(-7,25,4,biomesoplenty:leaves_0:3)
Block(-7,25,5,biomesoplenty:leaves_0:3)
Block(-7,25,6,biomesoplenty:leaves_0:3)
Block(-7,25,7,biomesoplenty:log_1:5)
Block(-7,25,8,biomesoplenty:leaves_0:3)
Block(-7,25,10,biomesoplenty:leaves_0:3)
Block(-7,25,11,biomesoplenty:log_1:5)
Block(-7,25,12,biomesoplenty:leaves_0:3)
Block(-7,25,13,biomesoplenty:leaves_0:3)
Block(-7,25,14,biomesoplenty:leaves_0:3)
Block(-7,25,15,biomesoplenty:leaves_0:3)
Block(-7,25,16,biomesoplenty:leaves_0:3)
Block(-7,25,17,biomesoplenty:leaves_0:3)
Block(-7,25,18,biomesoplenty:leaves_0:3)
Block(-7,25,19,biomesoplenty:leaves_0:3)
Block(-7,25,20,biomesoplenty:leaves_0:3)
Block(-7,26,6,biomesoplenty:leaves_0:3)
Block(-7,26,7,biomesoplenty:leaves_0:3)
Block(-7,26,8,biomesoplenty:leaves_0:3)
Block(-7,26,9,biomesoplenty:log_1:9)
Block(-7,26,10,biomesoplenty:leaves_0:3)
Block(-7,26,11,biomesoplenty:log_1:5)
Block(-7,26,12,biomesoplenty:leaves_0:3)
Block(-7,26,14,biomesoplenty:log_1:5)
Block(-7,26,15,biomesoplenty:leaves_0:3)
Block(-7,26,16,biomesoplenty:log_1:5)
Block(-7,26,17,biomesoplenty:leaves_0:3)
Block(-7,26,18,biomesoplenty:leaves_0:3)
Block(-7,26,19,biomesoplenty:leaves_0:3)
Block(-7,27,6,biomesoplenty:leaves_0:3)
Block(-7,27,7,biomesoplenty:leaves_0:3)
Block(-7,27,8,biomesoplenty:log_1:1)
Block(-7,27,9,biomesoplenty:log_1:5)
Block(-7,27,11,biomesoplenty:log_1:5)
Block(-7,27,12,biomesoplenty:leaves_0:3)
Block(-7,27,13,biomesoplenty:leaves_0:3)
Block(-7,27,14,biomesoplenty:leaves_0:3)
Block(-7,27,15,biomesoplenty:leaves_0:3)
Block(-7,27,16,biomesoplenty:leaves_0:3)
Block(-7,28,8,biomesoplenty:leaves_0:3)
Block(-7,28,9,biomesoplenty:leaves_0:3)
Block(-7,28,10,biomesoplenty:leaves_0:3)
Block(-7,28,11,biomesoplenty:leaves_0:3)
Block(-7,28,12,biomesoplenty:leaves_0:3)
Block(-7,28,13,biomesoplenty:leaves_0:3)
Block(-7,28,14,biomesoplenty:leaves_0:3)
Block(-7,28,15,biomesoplenty:leaves_0:3)
Block(-7,29,10,biomesoplenty:leaves_0:3)
Block(-7,29,11,biomesoplenty:leaves_0:3)
Block(-7,29,12,biomesoplenty:leaves_0:3)
Block(-7,29,14,biomesoplenty:leaves_0:3)
Block(-6,5,1,biomesoplenty:leaves_0:3)
Block(-6,6,1,biomesoplenty:leaves_0:3)
Block(-6,7,1,biomesoplenty:leaves_0:3)
Block(-6,8,0,biomesoplenty:leaves_0:3)
Block(-6,8,1,biomesoplenty:log_1:5)
Block(-6,8,2,biomesoplenty:leaves_0:3)
Block(-6,9,0,biomesoplenty:leaves_0:3)
Block(-6,9,1,biomesoplenty:log_1:1)
Block(-6,9,2,biomesoplenty:leaves_0:3)
Block(-6,9,3,biomesoplenty:leaves_0:3)
Block(-6,10,1,biomesoplenty:leaves_0:3)
Block(-6,10,2,biomesoplenty:leaves_0:3)
Block(-6,11,-2,biomesoplenty:leaves_0:3)
Block(-6,11,-1,biomesoplenty:leaves_0:3)
Block(-6,11,0,biomesoplenty:leaves_0:3)
Block(-6,12,-4,biomesoplenty:leaves_0:3)
Block(-6,12,-3,biomesoplenty:leaves_0:3)
Block(-6,12,-2,biomesoplenty:leaves_0:3)
Block(-6,12,-1,biomesoplenty:log_1:5)
Block(-6,12,0,biomesoplenty:log_1:5)
Block(-6,12,1,biomesoplenty:log_1:5)
Block(-6,13,-2,biomesoplenty:leaves_0:3)
Block(-6,13,-1,biomesoplenty:log_1:5)
Block(-6,13,0,biomesoplenty:log_1:5)
Block(-6,13,1,biomesoplenty:log_1:5)
Block(-6,13,2,biomesoplenty:log_1:5)
Block(-6,14,-2,biomesoplenty:leaves_0:3)
Block(-6,14,-1,biomesoplenty:leaves_0:3)
Block(-6,14,0,biomesoplenty:log_1:5)
Block(-6,14,1,biomesoplenty:log_1:5)
Block(-6,14,3,biomesoplenty:leaves_0:3)
Block(-6,14,4,biomesoplenty:leaves_0:3)
Block(-6,14,5,biomesoplenty:leaves_0:3)
Block(-6,15,0,biomesoplenty:leaves_0:3)
Block(-6,15,1,biomesoplenty:log_1:1)
Block(-6,15,3,biomesoplenty:leaves_0:3)
Block(-6,15,4,biomesoplenty:leaves_0:3)
Block(-6,15,5,biomesoplenty:log_1:1)
Block(-6,15,6,biomesoplenty:leaves_0:3)
Block(-6,15,7,biomesoplenty:leaves_0:3)
Block(-6,16,3,biomesoplenty:leaves_0:3)
Block(-6,16,4,biomesoplenty:leaves_0:3)
Block(-6,16,5,biomesoplenty:leaves_0:3)
Block(-6,16,10,biomesoplenty:log_1:5)
Block(-6,17,10,biomesoplenty:log_1:9)
Block(-6,17,11,biomesoplenty:log_1:1)
Block(-6,21,5,biomesoplenty:leaves_0:3)
Block(-6,21,8,biomesoplenty:leaves_0:3)
Block(-6,21,9,biomesoplenty:leaves_0:3)
Block(-6,21,12,biomesoplenty:leaves_0:3)
Block(-6,21,13,biomesoplenty:leaves_0:3)
Block(-6,22,5,biomesoplenty:leaves_0:3)
Block(-6,22,6,biomesoplenty:log_1:5)
Block(-6,22,12,biomesoplenty:leaves_0:3)
Block(-6,22,13,biomesoplenty:leaves_0:3)
Block(-6,22,15,biomesoplenty:leaves_0:3)
Block(-6,23,4,biomesoplenty:log_1:9)
Block(-6,23,5,biomesoplenty:leaves_0:3)
Block(-6,23,6,biomesoplenty:log_1:1)
Block(-6,23,8,biomesoplenty:leaves_0:3)
Block(-6,23,11,biomesoplenty:leaves_0:3)
Block(-6,23,12,biomesoplenty:leaves_0:3)
Block(-6,23,13,biomesoplenty:leaves_0:3)
Block(-6,23,14,biomesoplenty:log_1:1)
Block(-6,23,15,biomesoplenty:leaves_0:3)
Block(-6,23,16,biomesoplenty:leaves_0:3)
Block(-6,23,17,biomesoplenty:leaves_0:3)
Block(-6,23,18,biomesoplenty:leaves_0:3)
Block(-6,23,19,biomesoplenty:leaves_0:3)
Block(-6,24,2,biomesoplenty:leaves_0:3)
Block(-6,24,3,biomesoplenty:leaves_0:3)
Block(-6,24,4,biomesoplenty:leaves_0:3)
Block(-6,24,5,biomesoplenty:log_1:9)
Block(-6,24,6,biomesoplenty:leaves_0:3)
Block(-6,24,7,biomesoplenty:log_1:1)
Block(-6,24,10,biomesoplenty:leaves_0:3)
Block(-6,24,13,biomesoplenty:leaves_0:3)
Block(-6,24,14,biomesoplenty:log_1:5)
Block(-6,24,15,biomesoplenty:log_1:9)
Block(-6,24,16,biomesoplenty:leaves_0:3)
Block(-6,24,17,biomesoplenty:log_1:9)
Block(-6,24,18,biomesoplenty:log_1:9)
Block(-6,24,19,biomesoplenty:log_1:9)
Block(-6,24,20,biomesoplenty:leaves_0:3)
Block(-6,24,21,biomesoplenty:leaves_0:3)
Block(-6,25,4,biomesoplenty:leaves_0:3)
Block(-6,25,5,biomesoplenty:leaves_0:3)
Block(-6,25,6,biomesoplenty:leaves_0:3)
Block(-6,25,8,biomesoplenty:leaves_0:3)
Block(-6,25,9,biomesoplenty:leaves_0:3)
Block(-6,25,10,biomesoplenty:leaves_0:3)
Block(-6,25,11,biomesoplenty:log_1:1)
Block(-6,25,12,biomesoplenty:leaves_0:3)
Block(-6,25,13,biomesoplenty:leaves_0:3)
Block(-6,25,14,biomesoplenty:leaves_0:3)
Block(-6,25,15,biomesoplenty:leaves_0:3)
Block(-6,25,16,biomesoplenty:leaves_0:3)
Block(-6,25,17,biomesoplenty:leaves_0:3)
Block(-6,25,18,biomesoplenty:leaves_0:3)
Block(-6,25,19,biomesoplenty:leaves_0:3)
Block(-6,25,20,biomesoplenty:leaves_0:3)
Block(-6,26,6,biomesoplenty:leaves_0:3)
Block(-6,26,7,biomesoplenty:leaves_0:3)
Block(-6,26,9,biomesoplenty:leaves_0:3)
Block(-6,26,10,biomesoplenty:leaves_0:3)
Block(-6,26,11,biomesoplenty:leaves_0:3)
Block(-6,26,12,biomesoplenty:leaves_0:3)
Block(-6,26,13,biomesoplenty:leaves_0:3)
Block(-6,26,14,biomesoplenty:leaves_0:3)
Block(-6,26,15,biomesoplenty:leaves_0:3)
Block(-6,26,16,biomesoplenty:leaves_0:3)
Block(-6,26,17,biomesoplenty:leaves_0:3)
Block(-6,26,18,biomesoplenty:leaves_0:3)
Block(-6,26,19,biomesoplenty:leaves_0:3)
Block(-6,27,7,biomesoplenty:leaves_0:3)
Block(-6,27,8,biomesoplenty:leaves_0:3)
Block(-6,27,9,biomesoplenty:log_1:5)
Block(-6,27,10,biomesoplenty:leaves_0:3)
Block(-6,27,11,biomesoplenty:log_1:5)
Block(-6,27,12,biomesoplenty:leaves_0:3)
Block(-6,27,13,biomesoplenty:leaves_0:3)
Block(-6,27,14,biomesoplenty:leaves_0:3)
Block(-6,27,15,biomesoplenty:leaves_0:3)
Block(-6,28,8,biomesoplenty:leaves_0:3)
Block(-6,28,9,biomesoplenty:leaves_0:3)
Block(-6,28,10,biomesoplenty:leaves_0:3)
Block(-6,28,11,biomesoplenty:leaves_0:3)
Block(-6,28,12,biomesoplenty:leaves_0:3)
Block(-6,28,13,biomesoplenty:leaves_0:3)
Block(-6,28,14,biomesoplenty:leaves_0:3)
Block(-5,4,2,biomesoplenty:leaves_0:3)
Block(-5,5,2,biomesoplenty:leaves_0:3)
Block(-5,6,2,biomesoplenty:leaves_0:3)
Block(-5,7,2,biomesoplenty:leaves_0:3)
Block(-5,8,1,biomesoplenty:leaves_0:3)
Block(-5,8,2,biomesoplenty:log_1:5)
Block(-5,8,3,biomesoplenty:leaves_0:3)
Block(-5,9,0,biomesoplenty:leaves_0:3)
Block(-5,9,1,biomesoplenty:log_1:1)
Block(-5,9,2,biomesoplenty:log_1:1)
Block(-5,9,3,biomesoplenty:leaves_0:3)
Block(-5,9,4,biomesoplenty:leaves_0:3)
Block(-5,10,1,biomesoplenty:leaves_0:3)
Block(-5,10,2,biomesoplenty:leaves_0:3)
Block(-5,10,3,biomesoplenty:leaves_0:3)
Block(-5,11,-3,GLOWSTONE)
Block(-5,11,-2,biomesoplenty:leaves_0:3)
Block(-5,11,-1,biomesoplenty:log_1:5)
Block(-5,11,0,biomesoplenty:log_1:5)
Block(-5,11,1,biomesoplenty:leaves_0:3)
Block(-5,12,-3,biomesoplenty:leaves_0:3)
Block(-5,12,-2,biomesoplenty:log_1:5)
Block(-5,12,-1,biomesoplenty:log_1:5)
Block(-5,12,0,biomesoplenty:log_1:5)
Block(-5,12,1,biomesoplenty:log_1:5)
Block(-5,13,-2,biomesoplenty:leaves_0:3)
Block(-5,13,-1,biomesoplenty:log_1:5)
Block(-5,13,0,biomesoplenty:log_1:5)
Block(-5,13,1,biomesoplenty:log_1:5)
Block(-5,14,-1,biomesoplenty:leaves_0:3)
Block(-5,14,3,biomesoplenty:leaves_0:3)
Block(-5,15,1,biomesoplenty:log_1:1)
Block(-5,15,4,biomesoplenty:leaves_0:3)
Block(-5,15,5,biomesoplenty:leaves_0:3)
Block(-5,15,6,biomesoplenty:leaves_0:3)
Block(-5,15,9,biomesoplenty:log_1:5)
Block(-5,16,9,biomesoplenty:log_1:9)
Block(-5,16,10,biomesoplenty:log_1:1)
Block(-5,17,9,biomesoplenty:leaves_0:3)
Block(-5,20,7,biomesoplenty:leaves_0:3)
Block(-5,21,6,biomesoplenty:log_1:5)
Block(-5,21,7,biomesoplenty:leaves_0:3)
Block(-5,21,9,biomesoplenty:leaves_0:3)
Block(-5,21,13,biomesoplenty:leaves_0:3)
Block(-5,22,5,biomesoplenty:leaves_0:3)
Block(-5,22,6,biomesoplenty:log_1:1)
Block(-5,22,7,biomesoplenty:leaves_0:3)
Block(-5,22,8,biomesoplenty:leaves_0:3)
Block(-5,22,12,biomesoplenty:leaves_0:3)
Block(-5,23,4,biomesoplenty:leaves_0:3)
Block(-5,23,5,biomesoplenty:leaves_0:3)
Block(-5,23,6,biomesoplenty:leaves_0:3)
Block(-5,23,7,biomesoplenty:log_1:5)
Block(-5,23,8,biomesoplenty:leaves_0:3)
Block(-5,23,10,biomesoplenty:leaves_0:3)
Block(-5,23,13,biomesoplenty:leaves_0:3)
Block(-5,23,14,biomesoplenty:leaves_0:3)
Block(-5,23,15,biomesoplenty:log_1:5)
Block(-5,23,16,biomesoplenty:leaves_0:3)
Block(-5,23,17,biomesoplenty:leaves_0:3)
Block(-5,23,18,biomesoplenty:leaves_0:3)
Block(-5,24,3,biomesoplenty:leaves_0:3)
Block(-5,24,4,biomesoplenty:leaves_0:3)
Block(-5,24,5,biomesoplenty:leaves_0:3)
Block(-5,24,6,biomesoplenty:log_1:9)
Block(-5,24,7,biomesoplenty:log_1:1)
Block(-5,24,8,biomesoplenty:leaves_0:3)
Block(-5,24,9,biomesoplenty:leaves_0:3)
Block(-5,24,11,biomesoplenty:leaves_0:3)
Block(-5,24,12,biomesoplenty:leaves_0:3)
Block(-5,24,13,biomesoplenty:leaves_0:3)
Block(-5,24,14,biomesoplenty:leaves_0:3)
Block(-5,24,15,biomesoplenty:log_1:1)
Block(-5,24,16,biomesoplenty:leaves_0:3)
Block(-5,24,17,biomesoplenty:leaves_0:3)
Block(-5,24,18,biomesoplenty:leaves_0:3)
Block(-5,24,19,biomesoplenty:leaves_0:3)
Block(-5,24,20,biomesoplenty:leaves_0:3)
Block(-5,25,3,biomesoplenty:leaves_0:3)
Block(-5,25,4,biomesoplenty:leaves_0:3)
Block(-5,25,5,biomesoplenty:leaves_0:3)
Block(-5,25,6,biomesoplenty:leaves_0:3)
Block(-5,25,7,biomesoplenty:leaves_0:3)
Block(-5,25,8,biomesoplenty:log_1:5)
Block(-5,25,10,biomesoplenty:leaves_0:3)
Block(-5,25,11,biomesoplenty:log_1:1)
Block(-5,25,12,biomesoplenty:leaves_0:3)
Block(-5,25,13,biomesoplenty:leaves_0:3)
Block(-5,25,14,biomesoplenty:leaves_0:3)
Block(-5,25,15,biomesoplenty:log_1:5)
Block(-5,25,17,biomesoplenty:leaves_0:3)
Block(-5,25,18,biomesoplenty:leaves_0:3)
Block(-5,25,19,biomesoplenty:leaves_0:3)
Block(-5,26,6,biomesoplenty:leaves_0:3)
Block(-5,26,7,biomesoplenty:leaves_0:3)
Block(-5,26,8,biomesoplenty:leaves_0:3)
Block(-5,26,9,biomesoplenty:leaves_0:3)
Block(-5,26,11,biomesoplenty:leaves_0:3)
Block(-5,26,12,biomesoplenty:log_1:5)
Block(-5,26,13,biomesoplenty:leaves_0:3)
Block(-5,26,14,biomesoplenty:log_1:5)
Block(-5,26,15,biomesoplenty:leaves_0:3)
Block(-5,26,16,biomesoplenty:leaves_0:3)
Block(-5,26,17,biomesoplenty:log_1:5)
Block(-5,26,18,biomesoplenty:leaves_0:3)
Block(-5,27,7,biomesoplenty:leaves_0:3)
Block(-5,27,8,biomesoplenty:log_1:5)
Block(-5,27,9,biomesoplenty:leaves_0:3)
Block(-5,27,10,biomesoplenty:leaves_0:3)
Block(-5,27,11,biomesoplenty:leaves_0:3)
Block(-5,27,12,biomesoplenty:leaves_0:3)
Block(-5,27,13,biomesoplenty:leaves_0:3)
Block(-5,27,14,biomesoplenty:leaves_0:3)
Block(-5,27,15,biomesoplenty:leaves_0:3)
Block(-5,27,16,biomesoplenty:leaves_0:3)
Block(-5,27,17,biomesoplenty:leaves_0:3)
Block(-5,28,8,biomesoplenty:leaves_0:3)
Block(-5,28,9,biomesoplenty:leaves_0:3)
Block(-5,28,10,biomesoplenty:leaves_0:3)
Block(-5,28,11,biomesoplenty:leaves_0:3)
Block(-5,28,12,biomesoplenty:leaves_0:3)
Block(-5,28,13,biomesoplenty:leaves_0:3)
Block(-4,8,0,biomesoplenty:leaves_0:3)
Block(-4,8,1,biomesoplenty:leaves_0:3)
Block(-4,8,2,biomesoplenty:leaves_0:3)
Block(-4,9,-1,biomesoplenty:leaves_0:3)
Block(-4,9,0,biomesoplenty:log_1:1)
Block(-4,9,1,biomesoplenty:log_1:9)
Block(-4,9,2,biomesoplenty:log_1:9)
Block(-4,9,3,biomesoplenty:leaves_0:3)
Block(-4,9,4,biomesoplenty:leaves_0:3)
Block(-4,10,-1,biomesoplenty:log_1:5)
Block(-4,10,1,biomesoplenty:leaves_0:3)
Block(-4,10,2,biomesoplenty:leaves_0:3)
Block(-4,10,3,biomesoplenty:leaves_0:3)
Block(-4,10,4,biomesoplenty:leaves_0:3)
Block(-4,11,-2,biomesoplenty:log_1:5)
Block(-4,11,-1,biomesoplenty:log_1:5)
Block(-4,11,0,biomesoplenty:log_1:5)
Block(-4,11,1,biomesoplenty:leaves_0:3)
Block(-4,11,2,biomesoplenty:leaves_0:3)
Block(-4,12,-2,biomesoplenty:leaves_0:3)
Block(-4,12,-1,biomesoplenty:log_1:5)
Block(-4,12,0,biomesoplenty:log_1:5)
Block(-4,14,1,biomesoplenty:log_1:1)
Block(-4,15,1,biomesoplenty:log_1:5)
Block(-4,15,2,biomesoplenty:leaves_0:3)
Block(-4,15,8,biomesoplenty:log_1:9)
Block(-4,15,9,biomesoplenty:log_1:1)
Block(-4,21,5,biomesoplenty:log_1:9)
Block(-4,21,6,biomesoplenty:log_1:1)
Block(-4,21,7,biomesoplenty:log_1:9)
Block(-4,21,9,biomesoplenty:leaves_0:3)
Block(-4,22,5,biomesoplenty:leaves_0:3)
Block(-4,22,7,biomesoplenty:leaves_0:3)
Block(-4,22,8,biomesoplenty:leaves_0:3)
Block(-4,22,14,biomesoplenty:leaves_0:3)
Block(-4,23,5,biomesoplenty:leaves_0:3)
Block(-4,23,6,biomesoplenty:leaves_0:3)
Block(-4,23,7,biomesoplenty:leaves_0:3)
Block(-4,23,10,biomesoplenty:leaves_0:3)
Block(-4,23,11,biomesoplenty:leaves_0:3)
Block(-4,23,12,biomesoplenty:leaves_0:3)
Block(-4,23,13,biomesoplenty:leaves_0:3)
Block(-4,23,14,biomesoplenty:leaves_0:3)
Block(-4,23,15,biomesoplenty:log_1:1)
Block(-4,23,16,biomesoplenty:leaves_0:3)
Block(-4,23,17,biomesoplenty:leaves_0:3)
Block(-4,24,5,biomesoplenty:leaves_0:3)
Block(-4,24,6,biomesoplenty:log_1:1)
Block(-4,24,7,biomesoplenty:leaves_0:3)
Block(-4,24,10,biomesoplenty:leaves_0:3)
Block(-4,24,11,biomesoplenty:leaves_0:3)
Block(-4,24,12,biomesoplenty:leaves_0:3)
Block(-4,24,13,biomesoplenty:leaves_0:3)
Block(-4,24,15,biomesoplenty:leaves_0:3)
Block(-4,24,17,biomesoplenty:leaves_0:3)
Block(-4,24,18,biomesoplenty:leaves_0:3)
Block(-4,24,19,biomesoplenty:leaves_0:3)
Block(-4,24,20,biomesoplenty:leaves_0:3)
Block(-4,25,6,biomesoplenty:leaves_0:3)
Block(-4,25,7,biomesoplenty:leaves_0:3)
Block(-4,25,8,biomesoplenty:leaves_0:3)
Block(-4,25,9,biomesoplenty:leaves_0:3)
Block(-4,25,10,biomesoplenty:log_1:9)
Block(-4,25,11,biomesoplenty:log_1:1)
Block(-4,25,12,biomesoplenty:leaves_0:3)
Block(-4,25,13,biomesoplenty:leaves_0:3)
Block(-4,25,14,biomesoplenty:leaves_0:3)
Block(-4,25,15,biomesoplenty:log_1:1)
Block(-4,25,16,biomesoplenty:log_1:9)
Block(-4,25,17,biomesoplenty:leaves_0:3)
Block(-4,25,18,biomesoplenty:leaves_0:3)
Block(-4,25,19,biomesoplenty:leaves_0:3)
Block(-4,26,5,biomesoplenty:leaves_0:3)
Block(-4,26,6,biomesoplenty:leaves_0:3)
Block(-4,26,8,biomesoplenty:leaves_0:3)
Block(-4,26,9,biomesoplenty:leaves_0:3)
Block(-4,26,10,biomesoplenty:leaves_0:3)
Block(-4,26,11,biomesoplenty:log_1:5)
Block(-4,26,12,biomesoplenty:leaves_0:3)
Block(-4,26,13,biomesoplenty:leaves_0:3)
Block(-4,26,14,biomesoplenty:leaves_0:3)
Block(-4,26,15,biomesoplenty:leaves_0:3)
Block(-4,26,16,biomesoplenty:leaves_0:3)
Block(-4,26,17,biomesoplenty:leaves_0:3)
Block(-4,26,18,biomesoplenty:leaves_0:3)
Block(-4,26,19,biomesoplenty:leaves_0:3)
Block(-4,27,7,biomesoplenty:leaves_0:3)
Block(-4,27,9,biomesoplenty:leaves_0:3)
Block(-4,27,10,biomesoplenty:leaves_0:3)
Block(-4,27,11,biomesoplenty:leaves_0:3)
Block(-4,27,12,biomesoplenty:leaves_0:3)
Block(-4,27,13,biomesoplenty:leaves_0:3)
Block(-4,27,14,biomesoplenty:leaves_0:3)
Block(-4,27,15,biomesoplenty:leaves_0:3)
Block(-4,27,16,biomesoplenty:leaves_0:3)
Block(-4,27,17,biomesoplenty:leaves_0:3)
Block(-4,28,9,biomesoplenty:leaves_0:3)
Block(-3,4,3,GLOWSTONE)
Block(-3,4,10,biomesoplenty:leaves_0:3)
Block(-3,5,3,biomesoplenty:leaves_0:3)
Block(-3,6,3,biomesoplenty:leaves_0:3)
Block(-3,7,3,biomesoplenty:leaves_0:3)
Block(-3,8,0,biomesoplenty:leaves_0:3)
Block(-3,8,1,biomesoplenty:leaves_0:3)
Block(-3,8,2,biomesoplenty:leaves_0:3)
Block(-3,8,3,biomesoplenty:leaves_0:3)
Block(-3,9,-2,biomesoplenty:leaves_0:3)
Block(-3,9,-1,biomesoplenty:log_1:5)
Block(-3,9,0,biomesoplenty:log_1:5)
Block(-3,9,1,biomesoplenty:log_1:9)
Block(-3,9,2,biomesoplenty:log_1:9)
Block(-3,9,3,biomesoplenty:log_1:9)
Block(-3,9,4,biomesoplenty:leaves_0:3)
Block(-3,10,-2,biomesoplenty:log_1:5)
Block(-3,10,-1,biomesoplenty:log_1:5)
Block(-3,10,0,biomesoplenty:log_1:5)
Block(-3,10,1,biomesoplenty:leaves_0:3)
Block(-3,10,2,biomesoplenty:leaves_0:3)
Block(-3,10,3,biomesoplenty:leaves_0:3)
Block(-3,11,-2,biomesoplenty:leaves_0:3)
Block(-3,11,-1,biomesoplenty:log_1:5)
Block(-3,11,0,biomesoplenty:leaves_0:3)
Block(-3,11,1,biomesoplenty:leaves_0:3)
Block(-3,11,2,biomesoplenty:leaves_0:3)
Block(-3,11,8,biomesoplenty:leaves_0:3)
Block(-3,12,8,biomesoplenty:leaves_0:3)
Block(-3,13,8,biomesoplenty:leaves_0:3)
Block(-3,14,0,biomesoplenty:leaves_0:3)
Block(-3,14,1,biomesoplenty:log_1:9)
Block(-3,14,2,biomesoplenty:log_1:1)
Block(-3,14,7,biomesoplenty:log_1:9)
Block(-3,14,8,biomesoplenty:log_1:5)
Block(-3,14,9,biomesoplenty:leaves_0:3)
Block(-3,15,8,biomesoplenty:log_1:1)
Block(-3,15,9,biomesoplenty:leaves_0:3)
Block(-3,17,5,GLOWSTONE)
Block(-3,18,5,biomesoplenty:leaves_0:3)
Block(-3,19,5,biomesoplenty:leaves_0:3)
Block(-3,20,5,biomesoplenty:leaves_0:3)
Block(-3,21,4,biomesoplenty:log_1:9)
Block(-3,21,5,biomesoplenty:log_1:1)
Block(-3,21,6,biomesoplenty:leaves_0:3)
Block(-3,21,7,biomesoplenty:log_1:9)
Block(-3,21,8,biomesoplenty:leaves_0:3)
Block(-3,22,15,biomesoplenty:leaves_0:3)
Block(-3,22,16,biomesoplenty:leaves_0:3)
Block(-3,23,10,biomesoplenty:leaves_0:3)
Block(-3,23,11,biomesoplenty:leaves_0:3)
Block(-3,23,14,biomesoplenty:leaves_0:3)
Block(-3,23,15,biomesoplenty:log_1:1)
Block(-3,23,16,biomesoplenty:log_1:5)
Block(-3,23,17,biomesoplenty:leaves_0:3)
Block(-3,24,4,biomesoplenty:leaves_0:3)
Block(-3,24,5,biomesoplenty:leaves_0:3)
Block(-3,24,6,biomesoplenty:leaves_0:3)
Block(-3,24,12,biomesoplenty:leaves_0:3)
Block(-3,24,13,biomesoplenty:leaves_0:3)
Block(-3,24,14,biomesoplenty:leaves_0:3)
Block(-3,24,15,biomesoplenty:leaves_0:3)
Block(-3,24,16,biomesoplenty:leaves_0:3)
Block(-3,24,17,biomesoplenty:leaves_0:3)
Block(-3,24,18,biomesoplenty:leaves_0:3)
Block(-3,24,19,biomesoplenty:leaves_0:3)
Block(-3,25,5,biomesoplenty:leaves_0:3)
Block(-3,25,6,biomesoplenty:leaves_0:3)
Block(-3,25,7,biomesoplenty:leaves_0:3)
Block(-3,25,8,biomesoplenty:leaves_0:3)
Block(-3,25,10,biomesoplenty:leaves_0:3)
Block(-3,25,11,biomesoplenty:log_1:1)
Block(-3,25,12,biomesoplenty:leaves_0:3)
Block(-3,25,13,biomesoplenty:leaves_0:3)
Block(-3,25,14,biomesoplenty:leaves_0:3)
Block(-3,25,15,biomesoplenty:log_1:1)
Block(-3,25,16,biomesoplenty:log_1:5)
Block(-3,25,17,biomesoplenty:leaves_0:3)
Block(-3,25,18,biomesoplenty:leaves_0:3)
Block(-3,26,8,biomesoplenty:leaves_0:3)
Block(-3,26,9,biomesoplenty:leaves_0:3)
Block(-3,26,10,biomesoplenty:leaves_0:3)
Block(-3,26,11,biomesoplenty:leaves_0:3)
Block(-3,26,12,biomesoplenty:leaves_0:3)
Block(-3,26,13,biomesoplenty:leaves_0:3)
Block(-3,26,14,biomesoplenty:leaves_0:3)
Block(-3,26,15,biomesoplenty:leaves_0:3)
Block(-3,26,16,biomesoplenty:leaves_0:3)
Block(-3,26,17,biomesoplenty:leaves_0:3)
Block(-3,26,18,biomesoplenty:leaves_0:3)
Block(-3,27,9,biomesoplenty:leaves_0:3)
Block(-3,27,10,biomesoplenty:leaves_0:3)
Block(-3,27,11,biomesoplenty:leaves_0:3)
Block(-3,27,12,biomesoplenty:leaves_0:3)
Block(-3,28,9,biomesoplenty:leaves_0:3)
Block(-2,4,-1,biomesoplenty:leaves_0:3)
Block(-2,4,8,biomesoplenty:leaves_0:3)
Block(-2,4,9,biomesoplenty:leaves_0:3)
Block(-2,4,10,biomesoplenty:leaves_0:3)
Block(-2,4,11,biomesoplenty:leaves_0:3)
Block(-2,4,12,biomesoplenty:leaves_0:3)
Block(-2,5,-1,biomesoplenty:leaves_0:3)
Block(-2,6,-1,biomesoplenty:leaves_0:3)
Block(-2,7,-1,biomesoplenty:leaves_0:3)
Block(-2,8,-1,biomesoplenty:log_1:5)
Block(-2,8,0,biomesoplenty:log_1:5)
Block(-2,8,1,biomesoplenty:leaves_0:3)
Block(-2,9,-2,biomesoplenty:log_1:5)
Block(-2,9,-1,biomesoplenty:log_1:5)
Block(-2,9,0,biomesoplenty:log_1:5)
Block(-2,9,1,biomesoplenty:log_1:5)
Block(-2,9,2,biomesoplenty:leaves_0:3)
Block(-2,9,3,biomesoplenty:leaves_0:3)
Block(-2,10,-2,biomesoplenty:log_1:5)
Block(-2,10,-1,biomesoplenty:log_1:5)
Block(-2,10,0,biomesoplenty:log_1:5)
Block(-2,10,1,biomesoplenty:leaves_0:3)
Block(-2,10,2,biomesoplenty:leaves_0:3)
Block(-2,11,-1,biomesoplenty:log_1:5)
Block(-2,11,0,biomesoplenty:leaves_0:3)
Block(-2,11,1,biomesoplenty:leaves_0:3)
Block(-2,13,2,biomesoplenty:log_1:9)
Block(-2,13,3,biomesoplenty:log_1:1)
Block(-2,13,5,biomesoplenty:log_1:1)
Block(-2,14,2,biomesoplenty:log_1:5)
Block(-2,14,5,biomesoplenty:leaves_0:3)
Block(-2,14,6,biomesoplenty:log_1:9)
Block(-2,14,7,biomesoplenty:log_1:1)
Block(-2,14,8,biomesoplenty:leaves_0:3)
Block(-2,19,11,biomesoplenty:leaves_0:3)
Block(-2,20,11,biomesoplenty:leaves_0:3)
Block(-2,21,3,biomesoplenty:log_1:9)
Block(-2,21,4,biomesoplenty:log_1:1)
Block(-2,21,5,biomesoplenty:leaves_0:3)
Block(-2,21,11,biomesoplenty:leaves_0:3)
Block(-2,22,11,biomesoplenty:leaves_0:3)
Block(-2,23,11,biomesoplenty:log_1:5)
Block(-2,23,12,biomesoplenty:leaves_0:3)
Block(-2,23,15,biomesoplenty:leaves_0:3)
Block(-2,23,16,biomesoplenty:leaves_0:3)
Block(-2,24,11,biomesoplenty:leaves_0:3)
Block(-2,24,12,biomesoplenty:leaves_0:3)
Block(-2,24,13,biomesoplenty:leaves_0:3)
Block(-2,24,14,biomesoplenty:leaves_0:3)
Block(-2,24,15,biomesoplenty:leaves_0:3)
Block(-2,24,16,biomesoplenty:leaves_0:3)
Block(-2,24,17,biomesoplenty:leaves_0:3)
Block(-2,24,18,biomesoplenty:leaves_0:3)
Block(-2,25,-3,biomesoplenty:leaves_0:3)
Block(-2,25,-2,biomesoplenty:leaves_0:3)
Block(-2,25,0,biomesoplenty:leaves_0:3)
Block(-2,25,1,biomesoplenty:leaves_0:3)
Block(-2,25,3,biomesoplenty:leaves_0:3)
Block(-2,25,9,biomesoplenty:leaves_0:3)
Block(-2,25,10,biomesoplenty:leaves_0:3)
Block(-2,25,11,biomesoplenty:leaves_0:3)
Block(-2,25,12,biomesoplenty:leaves_0:3)
Block(-2,25,13,biomesoplenty:leaves_0:3)
Block(-2,25,14,biomesoplenty:leaves_0:3)
Block(-2,25,15,biomesoplenty:leaves_0:3)
Block(-2,25,16,biomesoplenty:leaves_0:3)
Block(-2,25,17,biomesoplenty:leaves_0:3)
Block(-2,26,9,biomesoplenty:leaves_0:3)
Block(-2,26,10,biomesoplenty:leaves_0:3)
Block(-2,26,11,biomesoplenty:leaves_0:3)
Block(-2,26,16,biomesoplenty:leaves_0:3)
Block(-2,26,17,biomesoplenty:leaves_0:3)
Block(-1,0,6,biomesoplenty:log_1:1)
Block(-1,0,10,biomesoplenty:leaves_0:3)
Block(-1,1,10,biomesoplenty:leaves_0:3)
Block(-1,2,10,biomesoplenty:leaves_0:3)
Block(-1,3,10,biomesoplenty:leaves_0:3)
Block(-1,4,8,biomesoplenty:leaves_0:3)
Block(-1,4,9,biomesoplenty:leaves_0:3)
Block(-1,4,10,biomesoplenty:log_1:1)
Block(-1,4,11,biomesoplenty:leaves_0:3)
Block(-1,4,12,biomesoplenty:leaves_0:3)
Block(-1,5,9,biomesoplenty:leaves_0:3)
Block(-1,5,10,biomesoplenty:leaves_0:3)
Block(-1,5,11,biomesoplenty:leaves_0:3)
Block(-1,6,1,biomesoplenty:log_1:5)
Block(-1,6,2,biomesoplenty:log_1:5)
Block(-1,6,3,biomesoplenty:leaves_0:3)
Block(-1,7,0,biomesoplenty:log_1:5)
Block(-1,7,1,biomesoplenty:log_1:5)
Block(-1,7,2,biomesoplenty:leaves_0:3)
Block(-1,8,-1,biomesoplenty:log_1:5)
Block(-1,8,0,biomesoplenty:log_1:5)
Block(-1,8,1,biomesoplenty:log_1:5)
Block(-1,9,-2,biomesoplenty:leaves_0:3)
Block(-1,9,-1,biomesoplenty:log_1:5)
Block(-1,9,0,biomesoplenty:log_1:5)
Block(-1,9,1,biomesoplenty:log_1:5)
Block(-1,9,2,biomesoplenty:leaves_0:3)
Block(-1,10,-1,biomesoplenty:log_1:5)
Block(-1,10,0,biomesoplenty:log_1:5)
Block(-1,10,1,biomesoplenty:leaves_0:3)
Block(-1,13,2,biomesoplenty:leaves_0:3)
Block(-1,13,3,biomesoplenty:log_1:1)
Block(-1,13,4,biomesoplenty:log_1:9)
Block(-1,13,5,biomesoplenty:log_1:9)
Block(-1,14,6,biomesoplenty:leaves_0:3)
Block(-1,22,3,biomesoplenty:log_1:1)
Block(-1,23,0,biomesoplenty:leaves_0:3)
Block(-1,23,10,biomesoplenty:leaves_0:3)
Block(-1,23,11,biomesoplenty:leaves_0:3)
Block(-1,24,10,biomesoplenty:leaves_0:3)
Block(-1,24,15,biomesoplenty:leaves_0:3)
Block(-1,24,16,biomesoplenty:leaves_0:3)
Block(-1,24,17,biomesoplenty:leaves_0:3)
Block(-1,25,-4,biomesoplenty:leaves_0:3)
Block(-1,25,-3,biomesoplenty:leaves_0:3)
Block(-1,25,-2,biomesoplenty:leaves_0:3)
Block(-1,25,-1,biomesoplenty:leaves_0:3)
Block(-1,25,0,biomesoplenty:leaves_0:3)
Block(-1,25,1,biomesoplenty:leaves_0:3)
Block(-1,25,2,biomesoplenty:leaves_0:3)
Block(-1,25,3,biomesoplenty:leaves_0:3)
Block(-1,25,4,biomesoplenty:leaves_0:3)
Block(-1,25,10,biomesoplenty:leaves_0:3)
Block(-1,25,11,biomesoplenty:leaves_0:3)
Block(-1,25,13,biomesoplenty:leaves_0:3)
Block(-1,25,14,biomesoplenty:leaves_0:3)
Block(-1,25,15,biomesoplenty:leaves_0:3)
Block(-1,26,-3,biomesoplenty:leaves_0:3)
Block(-1,26,-2,biomesoplenty:leaves_0:3)
Block(-1,26,-1,biomesoplenty:leaves_0:3)
Block(-1,26,0,biomesoplenty:leaves_0:3)
Block(-1,26,1,biomesoplenty:leaves_0:3)
Block(-1,26,2,biomesoplenty:leaves_0:3)
Block(0,0,5,biomesoplenty:log_1:5)
Block(0,0,6,biomesoplenty:log_1:5)
Block(0,0,7,biomesoplenty:log_1:5)
Block(0,0,8,biomesoplenty:log_1:1)
Block(0,1,5,biomesoplenty:log_1:5)
Block(0,1,6,biomesoplenty:log_1:5)
Block(0,1,7,biomesoplenty:log_1:5)
Block(0,2,6,biomesoplenty:log_1:5)
Block(0,3,4,biomesoplenty:log_1:5)
Block(0,3,8,biomesoplenty:log_1:5)
Block(0,3,9,GLOWSTONE)
Block(0,4,3,biomesoplenty:log_1:5)
Block(0,4,4,biomesoplenty:log_1:5)
Block(0,4,7,biomesoplenty:leaves_0:3)
Block(0,4,8,biomesoplenty:leaves_0:3)
Block(0,4,9,biomesoplenty:log_1:5)
Block(0,4,10,biomesoplenty:log_1:5)
Block(0,4,11,biomesoplenty:leaves_0:3)
Block(0,4,12,biomesoplenty:leaves_0:3)
Block(0,5,1,biomesoplenty:log_1:5)
Block(0,5,2,biomesoplenty:log_1:5)
Block(0,5,3,biomesoplenty:log_1:5)
Block(0,5,4,biomesoplenty:leaves_0:3)
Block(0,5,9,biomesoplenty:leaves_0:3)
Block(0,5,10,biomesoplenty:log_1:5)
Block(0,5,11,biomesoplenty:leaves_0:3)
Block(0,5,12,biomesoplenty:leaves_0:3)
Block(0,6,-2,biomesoplenty:leaves_0:3)
Block(0,6,-1,biomesoplenty:leaves_0:3)
Block(0,6,0,biomesoplenty:log_1:5)
Block(0,6,1,biomesoplenty:log_1:5)
Block(0,6,2,biomesoplenty:log_1:5)
Block(0,6,3,biomesoplenty:log_1:5)
Block(0,6,4,biomesoplenty:leaves_0:3)
Block(0,6,10,biomesoplenty:leaves_0:3)
Block(0,7,-1,biomesoplenty:leaves_0:3)
Block(0,7,0,biomesoplenty:log_1:5)
Block(0,7,1,biomesoplenty:log_1:5)
Block(0,7,2,biomesoplenty:log_1:5)
Block(0,7,3,biomesoplenty:leaves_0:3)
Block(0,7,15,biomesoplenty:leaves_0:3)
Block(0,8,-1,biomesoplenty:log_1:5)
Block(0,8,0,biomesoplenty:log_1:5)
Block(0,8,1,biomesoplenty:log_1:5)
Block(0,8,2,biomesoplenty:log_1:5)
Block(0,8,13,biomesoplenty:leaves_0:3)
Block(0,8,14,biomesoplenty:leaves_0:3)
Block(0,8,15,biomesoplenty:leaves_0:3)
Block(0,9,0,biomesoplenty:log_1:5)
Block(0,9,1,biomesoplenty:log_1:5)
Block(0,11,3,GLOWSTONE)
Block(0,12,3,biomesoplenty:leaves_0:3)
Block(0,13,3,biomesoplenty:log_1:1)
Block(0,13,4,biomesoplenty:log_1:1)
Block(0,19,2,biomesoplenty:leaves_0:3)
Block(0,20,2,biomesoplenty:leaves_0:3)
Block(0,21,2,biomesoplenty:leaves_0:3)
Block(0,22,2,biomesoplenty:log_1:5)
Block(0,22,3,biomesoplenty:log_1:9)
Block(0,22,4,biomesoplenty:leaves_0:3)
Block(0,23,-4,biomesoplenty:leaves_0:3)
Block(0,23,-3,biomesoplenty:leaves_0:3)
Block(0,23,0,biomesoplenty:leaves_0:3)
Block(0,23,2,biomesoplenty:log_1:1)
Block(0,24,-3,biomesoplenty:leaves_0:3)
Block(0,24,-1,biomesoplenty:leaves_0:3)
Block(0,24,0,biomesoplenty:leaves_0:3)
Block(0,24,1,biomesoplenty:leaves_0:3)
Block(0,24,2,biomesoplenty:leaves_0:3)
Block(0,25,-5,biomesoplenty:leaves_0:3)
Block(0,25,-4,biomesoplenty:leaves_0:3)
Block(0,25,-3,biomesoplenty:leaves_0:3)
Block(0,25,-2,biomesoplenty:leaves_0:3)
Block(0,25,-1,biomesoplenty:leaves_0:3)
Block(0,25,0,biomesoplenty:leaves_0:3)
Block(0,25,1,biomesoplenty:leaves_0:3)
Block(0,25,2,biomesoplenty:leaves_0:3)
Block(0,25,3,biomesoplenty:leaves_0:3)
Block(0,25,4,biomesoplenty:leaves_0:3)
Block(0,25,5,biomesoplenty:leaves_0:3)
Block(0,25,6,biomesoplenty:leaves_0:3)
Block(0,26,-4,biomesoplenty:leaves_0:3)
Block(0,26,-3,biomesoplenty:leaves_0:3)
Block(0,26,-2,biomesoplenty:leaves_0:3)
Block(0,26,-1,biomesoplenty:leaves_0:3)
Block(0,26,1,biomesoplenty:leaves_0:3)
Block(0,26,2,biomesoplenty:leaves_0:3)
Block(0,26,3,biomesoplenty:leaves_0:3)
Block(0,26,4,biomesoplenty:leaves_0:3)
Block(0,27,-2,biomesoplenty:leaves_0:3)
Block(0,27,-1,biomesoplenty:leaves_0:3)
Block(0,27,0,biomesoplenty:leaves_0:3)
Block(0,27,1,biomesoplenty:leaves_0:3)
Block(0,28,-1,biomesoplenty:leaves_0:3)
Block(0,28,0,biomesoplenty:leaves_0:3)
Block(1,0,4,biomesoplenty:log_1:9)
Block(1,0,5,biomesoplenty:log_1:5)
Block(1,0,6,biomesoplenty:log_1:5)
Block(1,0,7,biomesoplenty:log_1:5)
Block(1,0,8,biomesoplenty:log_1:5)
Block(1,0,11,biomesoplenty:leaves_0:3)
Block(1,1,5,biomesoplenty:log_1:5)
Block(1,1,6,biomesoplenty:log_1:5)
Block(1,1,7,biomesoplenty:log_1:5)
Block(1,1,8,biomesoplenty:log_1:9)
Block(1,1,11,biomesoplenty:leaves_0:3)
Block(1,2,1,biomesoplenty:leaves_0:3)
Block(1,2,4,biomesoplenty:log_1:5)
Block(1,2,5,biomesoplenty:log_1:5)
Block(1,2,6,biomesoplenty:log_1:5)
Block(1,2,7,biomesoplenty:log_1:5)
Block(1,2,8,biomesoplenty:log_1:5)
Block(1,2,11,biomesoplenty:leaves_0:3)
Block(1,3,1,biomesoplenty:leaves_0:3)
Block(1,3,3,biomesoplenty:log_1:5)
Block(1,3,4,biomesoplenty:log_1:5)
Block(1,3,5,biomesoplenty:log_1:5)
Block(1,3,7,biomesoplenty:log_1:5)
Block(1,3,8,biomesoplenty:log_1:5)
Block(1,3,9,biomesoplenty:log_1:5)
Block(1,3,10,biomesoplenty:log_1:5)
Block(1,3,11,biomesoplenty:leaves_0:3)
Block(1,4,1,biomesoplenty:leaves_0:3)
Block(1,4,2,biomesoplenty:log_1:5)
Block(1,4,3,biomesoplenty:log_1:5)
Block(1,4,4,biomesoplenty:log_1:5)
Block(1,4,5,biomesoplenty:log_1:5)
Block(1,4,8,biomesoplenty:log_1:5)
Block(1,4,9,biomesoplenty:log_1:5)
Block(1,4,10,biomesoplenty:log_1:5)
Block(1,4,11,biomesoplenty:log_1:5)
Block(1,4,12,biomesoplenty:leaves_0:3)
Block(1,5,-3,biomesoplenty:leaves_0:3)
Block(1,5,0,biomesoplenty:leaves_0:3)
Block(1,5,1,biomesoplenty:log_1:5)
Block(1,5,2,biomesoplenty:log_1:5)
Block(1,5,3,biomesoplenty:log_1:5)
Block(1,5,4,biomesoplenty:log_1:5)
Block(1,5,8,biomesoplenty:leaves_0:3)
Block(1,5,9,biomesoplenty:log_1:5)
Block(1,5,10,biomesoplenty:log_1:5)
Block(1,5,11,biomesoplenty:log_1:5)
Block(1,6,-3,biomesoplenty:leaves_0:3)
Block(1,6,-2,biomesoplenty:leaves_0:3)
Block(1,6,-1,biomesoplenty:leaves_0:3)
Block(1,6,0,biomesoplenty:log_1:9)
Block(1,6,1,biomesoplenty:log_1:5)
Block(1,6,2,biomesoplenty:log_1:5)
Block(1,6,3,biomesoplenty:log_1:5)
Block(1,6,4,biomesoplenty:leaves_0:3)
Block(1,6,9,biomesoplenty:leaves_0:3)
Block(1,6,10,biomesoplenty:log_1:5)
Block(1,6,11,biomesoplenty:log_1:5)
Block(1,7,-2,biomesoplenty:leaves_0:3)
Block(1,7,-1,biomesoplenty:leaves_0:3)
Block(1,7,0,biomesoplenty:leaves_0:3)
Block(1,7,1,biomesoplenty:log_1:5)
Block(1,7,2,biomesoplenty:log_1:5)
Block(1,7,11,biomesoplenty:log_1:5)
Block(1,7,12,biomesoplenty:log_1:5)
Block(1,7,13,biomesoplenty:leaves_0:3)
Block(1,8,-1,biomesoplenty:leaves_0:3)
Block(1,8,0,biomesoplenty:log_1:5)
Block(1,8,1,biomesoplenty:log_1:5)
Block(1,8,12,biomesoplenty:leaves_0:3)
Block(1,8,13,biomesoplenty:leaves_0:3)
Block(1,8,14,biomesoplenty:leaves_0:3)
Block(1,8,15,biomesoplenty:leaves_0:3)
Block(1,8,16,biomesoplenty:leaves_0:3)
Block(1,9,14,biomesoplenty:leaves_0:3)
Block(1,9,15,biomesoplenty:leaves_0:3)
Block(1,10,4,biomesoplenty:leaves_0:3)
Block(1,11,4,biomesoplenty:leaves_0:3)
Block(1,12,4,biomesoplenty:leaves_0:3)
Block(1,13,3,biomesoplenty:log_1:9)
Block(1,13,4,biomesoplenty:log_1:1)
Block(1,13,5,biomesoplenty:leaves_0:3)
Block(1,23,-3,biomesoplenty:leaves_0:3)
Block(1,23,0,biomesoplenty:leaves_0:3)
Block(1,23,1,biomesoplenty:leaves_0:3)
Block(1,23,2,biomesoplenty:log_1:1)
Block(1,23,3,biomesoplenty:leaves_0:3)
Block(1,24,-5,biomesoplenty:leaves_0:3)
Block(1,24,-4,biomesoplenty:leaves_0:3)
Block(1,24,-1,biomesoplenty:leaves_0:3)
Block(1,24,0,biomesoplenty:leaves_0:3)
Block(1,24,1,biomesoplenty:leaves_0:3)
Block(1,24,2,biomesoplenty:log_1:9)
Block(1,25,-7,biomesoplenty:leaves_0:3)
Block(1,25,-6,biomesoplenty:leaves_0:3)
Block(1,25,-5,biomesoplenty:leaves_0:3)
Block(1,25,-4,biomesoplenty:leaves_0:3)
Block(1,25,-3,biomesoplenty:log_1:1)
Block(1,25,-2,biomesoplenty:leaves_0:3)
Block(1,25,-1,biomesoplenty:log_1:1)
Block(1,25,0,biomesoplenty:leaves_0:3)
Block(1,25,2,biomesoplenty:log_1:1)
Block(1,25,3,biomesoplenty:leaves_0:3)
Block(1,25,4,biomesoplenty:leaves_0:3)
Block(1,25,5,biomesoplenty:leaves_0:3)
Block(1,25,6,biomesoplenty:leaves_0:3)
Block(1,25,7,biomesoplenty:leaves_0:3)
Block(1,25,8,biomesoplenty:leaves_0:3)
Block(1,26,-5,biomesoplenty:leaves_0:3)
Block(1,26,-4,biomesoplenty:leaves_0:3)
Block(1,26,-3,biomesoplenty:leaves_0:3)
Block(1,26,-2,biomesoplenty:leaves_0:3)
Block(1,26,-1,biomesoplenty:leaves_0:3)
Block(1,26,1,biomesoplenty:leaves_0:3)
Block(1,26,2,biomesoplenty:leaves_0:3)
Block(1,26,4,biomesoplenty:leaves_0:3)
Block(1,26,6,biomesoplenty:leaves_0:3)
Block(1,26,7,biomesoplenty:leaves_0:3)
Block(1,27,-4,biomesoplenty:leaves_0:3)
Block(1,27,-3,biomesoplenty:leaves_0:3)
Block(1,27,-2,biomesoplenty:leaves_0:3)
Block(1,27,-1,biomesoplenty:leaves_0:3)
Block(1,27,0,biomesoplenty:leaves_0:3)
Block(1,27,1,biomesoplenty:leaves_0:3)
Block(1,27,2,biomesoplenty:leaves_0:3)
Block(1,27,3,biomesoplenty:leaves_0:3)
Block(1,27,4,biomesoplenty:leaves_0:3)
Block(1,27,6,biomesoplenty:leaves_0:3)
Block(1,28,0,biomesoplenty:leaves_0:3)
Block(1,28,1,biomesoplenty:leaves_0:3)
Block(1,28,2,biomesoplenty:leaves_0:3)
Block(1,28,3,biomesoplenty:leaves_0:3)
Block(1,28,4,biomesoplenty:leaves_0:3)
Block(1,28,5,biomesoplenty:leaves_0:3)
Block(2,0,5,biomesoplenty:log_1:5)
Block(2,0,6,biomesoplenty:log_1:5)
Block(2,0,7,biomesoplenty:log_1:5)
Block(2,1,3,biomesoplenty:leaves_0:3)
Block(2,1,5,biomesoplenty:log_1:5)
Block(2,1,6,biomesoplenty:log_1:5)
Block(2,1,7,biomesoplenty:log_1:5)
Block(2,2,3,biomesoplenty:leaves_0:3)
Block(2,2,5,biomesoplenty:log_1:5)
Block(2,3,3,biomesoplenty:leaves_0:3)
Block(2,3,4,biomesoplenty:log_1:5)
Block(2,3,7,biomesoplenty:leaves_0:3)
Block(2,3,8,biomesoplenty:log_1:5)
Block(2,3,9,biomesoplenty:leaves_0:3)
Block(2,3,12,biomesoplenty:leaves_0:3)
Block(2,4,3,biomesoplenty:log_1:5)
Block(2,4,4,biomesoplenty:log_1:5)
Block(2,4,5,biomesoplenty:leaves_0:3)
Block(2,4,8,biomesoplenty:leaves_0:3)
Block(2,4,9,biomesoplenty:log_1:5)
Block(2,4,10,biomesoplenty:log_1:5)
Block(2,4,12,biomesoplenty:leaves_0:3)
Block(2,5,0,biomesoplenty:leaves_0:3)
Block(2,5,1,biomesoplenty:leaves_0:3)
Block(2,5,2,biomesoplenty:log_1:5)
Block(2,5,3,biomesoplenty:log_1:5)
Block(2,5,4,biomesoplenty:leaves_0:3)
Block(2,5,9,biomesoplenty:log_1:5)
Block(2,5,10,biomesoplenty:log_1:5)
Block(2,5,11,biomesoplenty:log_1:5)
Block(2,5,12,biomesoplenty:leaves_0:3)
Block(2,5,15,biomesoplenty:leaves_0:3)
Block(2,6,-3,biomesoplenty:leaves_0:3)
Block(2,6,-2,biomesoplenty:leaves_0:3)
Block(2,6,-1,biomesoplenty:leaves_0:3)
Block(2,6,0,biomesoplenty:log_1:1)
Block(2,6,1,biomesoplenty:leaves_0:3)
Block(2,6,2,biomesoplenty:log_1:5)
Block(2,6,3,biomesoplenty:leaves_0:3)
Block(2,6,10,biomesoplenty:log_1:5)
Block(2,6,11,biomesoplenty:log_1:5)
Block(2,6,12,biomesoplenty:log_1:5)
Block(2,6,15,biomesoplenty:leaves_0:3)
Block(2,7,-2,biomesoplenty:leaves_0:3)
Block(2,7,-1,biomesoplenty:leaves_0:3)
Block(2,7,0,biomesoplenty:leaves_0:3)
Block(2,7,1,biomesoplenty:leaves_0:3)
Block(2,7,2,biomesoplenty:leaves_0:3)
Block(2,7,9,biomesoplenty:leaves_0:3)
Block(2,7,10,biomesoplenty:log_1:5)
Block(2,7,11,biomesoplenty:log_1:5)
Block(2,7,12,biomesoplenty:log_1:5)
Block(2,7,13,biomesoplenty:log_1:5)
Block(2,7,14,GLOWSTONE)
Block(2,7,15,biomesoplenty:leaves_0:3)
Block(2,8,-1,biomesoplenty:leaves_0:3)
Block(2,8,0,biomesoplenty:leaves_0:3)
Block(2,8,9,biomesoplenty:leaves_0:3)
Block(2,8,10,biomesoplenty:leaves_0:3)
Block(2,8,11,biomesoplenty:log_1:5)
Block(2,8,12,biomesoplenty:log_1:5)
Block(2,8,13,biomesoplenty:log_1:5)
Block(2,8,14,biomesoplenty:log_1:1)
Block(2,8,15,biomesoplenty:leaves_0:3)
Block(2,8,16,biomesoplenty:leaves_0:3)
Block(2,9,12,biomesoplenty:leaves_0:3)
Block(2,9,13,biomesoplenty:leaves_0:3)
Block(2,9,14,biomesoplenty:leaves_0:3)
Block(2,9,15,biomesoplenty:leaves_0:3)
Block(2,9,16,biomesoplenty:leaves_0:3)
Block(2,9,17,biomesoplenty:leaves_0:3)
Block(2,13,3,GLOWSTONE)
Block(2,13,4,biomesoplenty:log_1:1)
Block(2,14,4,biomesoplenty:leaves_0:3)
Block(2,19,1,biomesoplenty:leaves_0:3)
Block(2,20,1,biomesoplenty:leaves_0:3)
Block(2,21,1,biomesoplenty:leaves_0:3)
Block(2,22,1,biomesoplenty:leaves_0:3)
Block(2,22,2,biomesoplenty:leaves_0:3)
Block(2,23,-4,biomesoplenty:leaves_0:3)
Block(2,23,-1,biomesoplenty:leaves_0:3)
Block(2,23,0,biomesoplenty:leaves_0:3)
Block(2,23,1,biomesoplenty:log_1:9)
Block(2,23,2,biomesoplenty:leaves_0:3)
Block(2,24,-6,biomesoplenty:leaves_0:3)
Block(2,24,-5,biomesoplenty:leaves_0:3)
Block(2,24,-4,biomesoplenty:leaves_0:3)
Block(2,24,-3,biomesoplenty:leaves_0:3)
Block(2,24,-1,biomesoplenty:leaves_0:3)
Block(2,24,1,biomesoplenty:leaves_0:3)
Block(2,24,2,biomesoplenty:leaves_0:3)
Block(2,25,-8,biomesoplenty:leaves_0:3)
Block(2,25,-7,biomesoplenty:leaves_0:3)
Block(2,25,-6,biomesoplenty:leaves_0:3)
Block(2,25,-5,biomesoplenty:leaves_0:3)
Block(2,25,-4,biomesoplenty:leaves_0:3)
Block(2,25,-3,biomesoplenty:leaves_0:3)
Block(2,25,-2,biomesoplenty:leaves_0:3)
Block(2,25,-1,biomesoplenty:leaves_0:3)
Block(2,25,0,biomesoplenty:leaves_0:3)
Block(2,25,2,biomesoplenty:log_1:9)
Block(2,25,3,biomesoplenty:log_1:1)
Block(2,25,4,biomesoplenty:leaves_0:3)
Block(2,25,5,biomesoplenty:leaves_0:3)
Block(2,25,6,biomesoplenty:leaves_0:3)
Block(2,25,7,biomesoplenty:leaves_0:3)
Block(2,25,8,biomesoplenty:leaves_0:3)
Block(2,25,9,biomesoplenty:leaves_0:3)
Block(2,25,10,biomesoplenty:leaves_0:3)
Block(2,26,-7,biomesoplenty:leaves_0:3)
Block(2,26,-6,biomesoplenty:leaves_0:3)
Block(2,26,-5,biomesoplenty:leaves_0:3)
Block(2,26,-4,biomesoplenty:leaves_0:3)
Block(2,26,-3,biomesoplenty:leaves_0:3)
Block(2,26,-2,biomesoplenty:leaves_0:3)
Block(2,26,-1,biomesoplenty:log_1:9)
Block(2,26,0,biomesoplenty:leaves_0:3)
Block(2,26,1,biomesoplenty:log_1:5)
Block(2,26,2,biomesoplenty:leaves_0:3)
Block(2,26,3,biomesoplenty:leaves_0:3)
Block(2,26,4,biomesoplenty:leaves_0:3)
Block(2,26,7,biomesoplenty:leaves_0:3)
Block(2,26,8,biomesoplenty:leaves_0:3)
Block(2,27,-4,biomesoplenty:leaves_0:3)
Block(2,27,-3,biomesoplenty:leaves_0:3)
Block(2,27,-2,biomesoplenty:leaves_0:3)
Block(2,27,-1,biomesoplenty:leaves_0:3)
Block(2,27,1,biomesoplenty:log_1:1)
Block(2,27,2,biomesoplenty:leaves_0:3)
Block(2,27,3,biomesoplenty:leaves_0:3)
Block(2,27,4,biomesoplenty:leaves_0:3)
Block(2,27,5,biomesoplenty:leaves_0:3)
Block(2,27,6,biomesoplenty:leaves_0:3)
Block(2,27,7,biomesoplenty:leaves_0:3)
Block(2,28,-1,biomesoplenty:leaves_0:3)
Block(2,28,0,biomesoplenty:leaves_0:3)
Block(2,28,2,biomesoplenty:leaves_0:3)
Block(2,28,3,biomesoplenty:leaves_0:3)
Block(2,28,4,biomesoplenty:leaves_0:3)
Block(2,28,5,biomesoplenty:leaves_0:3)
Block(2,28,6,biomesoplenty:leaves_0:3)
Block(2,29,0,biomesoplenty:leaves_0:3)
Block(2,29,1,biomesoplenty:leaves_0:3)
Block(2,29,2,biomesoplenty:leaves_0:3)
Block(2,29,3,biomesoplenty:leaves_0:3)
Block(2,29,4,biomesoplenty:leaves_0:3)
Block(2,29,5,biomesoplenty:leaves_0:3)
Block(2,30,4,biomesoplenty:leaves_0:3)
Block(3,0,5,biomesoplenty:log_1:1)
Block(3,0,6,biomesoplenty:log_1:1)
Block(3,2,0,biomesoplenty:leaves_0:3)
Block(3,3,0,biomesoplenty:leaves_0:3)
Block(3,3,4,biomesoplenty:leaves_0:3)
Block(3,3,8,biomesoplenty:leaves_0:3)
Block(3,4,0,biomesoplenty:leaves_0:3)
Block(3,4,9,biomesoplenty:leaves_0:3)
Block(3,5,0,biomesoplenty:leaves_0:3)
Block(3,5,1,biomesoplenty:leaves_0:3)
Block(3,5,10,biomesoplenty:log_1:5)
Block(3,6,-2,biomesoplenty:leaves_0:3)
Block(3,6,-1,biomesoplenty:log_1:9)
Block(3,6,0,biomesoplenty:log_1:1)
Block(3,6,1,biomesoplenty:leaves_0:3)
Block(3,6,2,biomesoplenty:leaves_0:3)
Block(3,6,3,biomesoplenty:leaves_0:3)
Block(3,6,10,biomesoplenty:leaves_0:3)
Block(3,6,11,biomesoplenty:log_1:5)
Block(3,6,12,biomesoplenty:log_1:5)
Block(3,7,-1,biomesoplenty:leaves_0:3)
Block(3,7,0,biomesoplenty:leaves_0:3)
Block(3,7,1,biomesoplenty:leaves_0:3)
Block(3,7,9,biomesoplenty:leaves_0:3)
Block(3,7,10,biomesoplenty:log_1:9)
Block(3,7,11,biomesoplenty:log_1:5)
Block(3,7,12,biomesoplenty:log_1:5)
Block(3,7,13,biomesoplenty:log_1:5)
Block(3,8,10,biomesoplenty:leaves_0:3)
Block(3,8,11,biomesoplenty:log_1:5)
Block(3,8,12,biomesoplenty:log_1:5)
Block(3,8,13,biomesoplenty:log_1:5)
Block(3,8,14,biomesoplenty:log_1:5)
Block(3,8,15,biomesoplenty:leaves_0:3)
Block(3,8,16,biomesoplenty:leaves_0:3)
Block(3,9,10,biomesoplenty:leaves_0:3)
Block(3,9,12,biomesoplenty:log_1:5)
Block(3,9,13,biomesoplenty:log_1:5)
Block(3,9,14,biomesoplenty:leaves_0:3)
Block(3,9,15,biomesoplenty:leaves_0:3)
Block(3,9,16,biomesoplenty:leaves_0:3)
Block(3,10,13,biomesoplenty:leaves_0:3)
Block(3,10,14,biomesoplenty:leaves_0:3)
Block(3,12,10,biomesoplenty:leaves_0:3)
Block(3,13,2,biomesoplenty:log_1:9)
Block(3,13,3,biomesoplenty:log_1:9)
Block(3,13,4,biomesoplenty:log_1:1)
Block(3,14,1,biomesoplenty:leaves_0:3)
Block(3,21,6,biomesoplenty:leaves_0:3)
Block(3,22,-3,biomesoplenty:leaves_0:3)
Block(3,22,1,biomesoplenty:leaves_0:3)
Block(3,22,6,biomesoplenty:leaves_0:3)
Block(3,23,-7,biomesoplenty:leaves_0:3)
Block(3,23,-6,biomesoplenty:leaves_0:3)
Block(3,23,-5,biomesoplenty:leaves_0:3)
Block(3,23,-4,biomesoplenty:leaves_0:3)
Block(3,23,-3,biomesoplenty:leaves_0:3)
Block(3,23,-2,biomesoplenty:log_1:9)
Block(3,23,-1,biomesoplenty:log_1:9)
Block(3,23,0,biomesoplenty:log_1:1)
Block(3,23,2,biomesoplenty:leaves_0:3)
Block(3,23,3,biomesoplenty:leaves_0:3)
Block(3,23,6,biomesoplenty:leaves_0:3)
Block(3,24,-7,biomesoplenty:leaves_0:3)
Block(3,24,-6,biomesoplenty:leaves_0:3)
Block(3,24,-5,biomesoplenty:leaves_0:3)
Block(3,24,-3,biomesoplenty:leaves_0:3)
Block(3,24,-1,biomesoplenty:leaves_0:3)
Block(3,24,1,biomesoplenty:leaves_0:3)
Block(3,24,2,biomesoplenty:leaves_0:3)
Block(3,24,4,biomesoplenty:leaves_0:3)
Block(3,24,5,biomesoplenty:leaves_0:3)
Block(3,24,6,biomesoplenty:leaves_0:3)
Block(3,25,-7,biomesoplenty:log_1:1)
Block(3,25,-6,biomesoplenty:leaves_0:3)
Block(3,25,-5,biomesoplenty:leaves_0:3)
Block(3,25,-4,biomesoplenty:log_1:9)
Block(3,25,-3,biomesoplenty:log_1:1)
Block(3,25,-2,biomesoplenty:leaves_0:3)
Block(3,25,-1,biomesoplenty:leaves_0:3)
Block(3,25,0,biomesoplenty:leaves_0:3)
Block(3,25,1,biomesoplenty:leaves_0:3)
Block(3,25,2,biomesoplenty:leaves_0:3)
Block(3,25,3,biomesoplenty:log_1:1)
