
#######################################################################
# +-----------------------------------------------------------------+ #
# |                            BO3 object                           | #
# +-----------------------------------------------------------------+ #
#######################################################################

# This is the config file of a custom object.
# If you add this object correctly to your BiomeConfigs, it will spawn in the world.

# This is the creator of this BO3 object
Author: BO3 BulkEdit (by LanToaster)

# A short description of this BO3 object
Description: This Object was Created with BO3_BulkEdit

# The BO3 version, don't change this! It can be used by external applications to do a version check.
Version: 3

# The settings mode, WriteAll, WriteWithoutComments or WriteDisable. See WorldConfig.
SettingsMode: WriteAll


#######################################################################
# +-----------------------------------------------------------------+ #
# |                          Main settings                          | #
# +-----------------------------------------------------------------+ #
#######################################################################

# This needs to be set to true to spawn the object in the Tree and Sapling resources.
Tree: true

# The frequency of the BO3 from 1 to 200. Tries this many times to spawn this BO3 when using the CustomObject(...) resource.
# Ignored by Tree(..), Sapling(..) and CustomStructure(..)
Frequency: 1

# The rarity of the BO3 from 0 to 100. Each spawn attempt has rarity% chance to succeed when using the CustomObject(...) resource.
# Ignored by Tree(..), Sapling(..) and CustomStructure(..)
Rarity: 100.0

# If you set this to true, the BO3 will be placed with a random rotation.
RotateRandomly: true

# The spawn height of the BO3: randomY, highestBlock or highestSolidBlock.
SpawnHeight: randomY

# The offset from the spawn height to spawn this BO3
# Ex. SpawnHeight = highestSolidBlock, SpawnHeightOffset = 3; This object will spawn 3 blocks above the highest solid block
SpawnHeightOffset: 0

# A random amount to offset the spawn location from the spawn offset height
# Ex. SpawnHeightOffset = 3, SpawnHeightVariance = 3; This object will spawn 3 to 6 blocks above the original spot it would have spawned
SpawnHeightVariance: 0

##############################
# Height Limits for the BO3. #
##############################

# When in randomY mode used as the minimum Y or in atMinY mode as the actual Y to spawn this BO3 at.
MinHeight: 92

# When in randomY mode used as the maximum Y to spawn this BO3 at.
MaxHeight: 256

######################
# Extrusion settings #
######################

# The style of extrusion you wish to use - BottomDown, TopUp, None (Default)
ExtrudeMode: None

# The blocks to extrude your BO3 through
ExtrudeThroughBlocks: AIR

# Objects can have other objects attacthed to it: branches. Branches can also
# have branches attached to it, which can also have branches, etc. This is the
# maximum branch depth for this objects.
MaxBranchDepth: 10

# When spawned with the UseWorld keyword, this BO3 should NOT spawn in the following biomes.
# If you write the BO3 name directly in the BiomeConfigs, this will be ignored.
ExcludedBiomes: All


#######################################################################
# +-----------------------------------------------------------------+ #
# |                      Source block settings                      | #
# +-----------------------------------------------------------------+ #
#######################################################################

# The block(s) the BO3 should spawn in.
SourceBlocks: AIR,GRASS,DIRT

# The maximum percentage of the BO3 that can be outside the SourceBlock.
# The BO3 won't be placed on a location with more blocks outside the SourceBlock than this percentage.
MaxPercentageOutsideSourceBlock: 100

# What to do when a block is about to be placed outside the SourceBlock? (dontPlace, placeAnyway)
OutsideSourceBlock: placeAnyway

# OTG+ settings #
# Legacy setting, rename this file to .BO4 instead. Set this to true to enable the advanced customstructure features of OTG+.
IsOTGPlus: false


#######################################################################
# +-----------------------------------------------------------------+ #
# |                              Blocks                             | #
# +-----------------------------------------------------------------+ #
#######################################################################

# All the blocks used in the BO3 are listed here. Possible blocks:
# Block(x,y,z,id[.data][,nbtfile.nbt)
# RandomBlock(x,y,z,id[:data][,nbtfile.nbt],chance[,id[:data][,nbtfile.nbt],chance[,...]])
#  So RandomBlock(0,0,0,CHEST,chest.nbt,50,CHEST,anotherchest.nbt,100) will spawn a chest at
#  the BO3 origin, and give it a 50% chance to have the contents of chest.nbt, or, if that
#  fails, a 100% percent chance to have the contents of anotherchest.nbt.
# *Note: Unlike Entity() and Spawner(), for Block() .txt files don't work, only .nbt files work.
# MinecraftObject(x,y,z,name) (TODO: This may not work anymore and needs to be tested.
#  Spawns an object in the Mojang NBT structure format. For example, 
#  MinecraftObject(0,0,0,minecraft:igloo/igloo_bottom)
#  spawns the bottom part of an igloo.
Block(-1,0,-4,biomesoplenty:log_0:7)
Block(0,0,-4,biomesoplenty:log_0:7)
Block(-2,0,-3,biomesoplenty:log_0:7)
Block(-1,0,-3,biomesoplenty:log_0:7)
Block(0,0,-3,biomesoplenty:log_0:7)
Block(1,0,-3,biomesoplenty:log_0:7)
Block(2,0,-3,biomesoplenty:log_0:7)
Block(-3,0,-2,biomesoplenty:log_0:7)
Block(-2,0,-2,biomesoplenty:log_0:7)
Block(-1,0,-2,biomesoplenty:log_0:7)
Block(0,0,-2,biomesoplenty:log_0:7)
Block(1,0,-2,biomesoplenty:log_0:7)
Block(2,0,-2,biomesoplenty:log_0:7)
Block(3,0,-2,biomesoplenty:log_0:7)
Block(-3,0,-1,biomesoplenty:log_0:7)
Block(-2,0,-1,biomesoplenty:log_0:7)
Block(-1,0,-1,biomesoplenty:log_0:7)
Block(0,0,-1,biomesoplenty:log_0:7)
Block(1,0,-1,biomesoplenty:log_0:7)
Block(2,0,-1,biomesoplenty:log_0:7)
Block(3,0,-1,biomesoplenty:log_0:7)
Block(4,0,-1,biomesoplenty:log_0:7)
Block(-3,0,0,biomesoplenty:log_0:7)
Block(-2,0,0,biomesoplenty:log_0:7)
Block(-1,0,0,biomesoplenty:log_0:7)
Block(0,0,0,biomesoplenty:log_0:7)
Block(1,0,0,biomesoplenty:log_0:7)
Block(2,0,0,biomesoplenty:log_0:7)
Block(3,0,0,biomesoplenty:log_0:7)
Block(-2,0,1,biomesoplenty:log_0:7)
Block(-1,0,1,biomesoplenty:log_0:7)
Block(0,0,1,biomesoplenty:log_0:7)
Block(1,0,1,biomesoplenty:log_0:7)
Block(2,0,1,biomesoplenty:log_0:7)
Block(3,0,1,biomesoplenty:log_0:7)
Block(-1,0,2,biomesoplenty:log_0:7)
Block(0,0,2,biomesoplenty:log_0:7)
Block(1,0,2,biomesoplenty:log_0:7)
Block(-1,1,-3,biomesoplenty:log_0:7)
Block(0,1,-3,biomesoplenty:log_0:7)
Block(-1,1,-2,biomesoplenty:log_0:7)
Block(0,1,-2,biomesoplenty:log_0:7)
Block(1,1,-2,biomesoplenty:log_0:7)
Block(2,1,-2,biomesoplenty:log_0:7)
Block(-3,1,-1,biomesoplenty:log_0:7)
Block(-2,1,-1,biomesoplenty:log_0:7)
Block(-1,1,-1,biomesoplenty:log_0:7)
Block(0,1,-1,biomesoplenty:log_0:7)
Block(1,1,-1,biomesoplenty:log_0:7)
Block(2,1,-1,biomesoplenty:log_0:7)
Block(3,1,-1,biomesoplenty:log_0:7)
Block(-2,1,0,biomesoplenty:log_0:7)
Block(-1,1,0,biomesoplenty:log_0:7)
Block(0,1,0,biomesoplenty:log_0:7)
Block(1,1,0,biomesoplenty:log_0:7)
Block(2,1,0,biomesoplenty:log_0:7)
Block(-1,1,1,biomesoplenty:log_0:7)
Block(0,1,1,biomesoplenty:log_0:7)
Block(1,1,1,biomesoplenty:log_0:7)
Block(0,2,-3,biomesoplenty:log_0:7)
Block(-1,2,-2,biomesoplenty:log_0:7)
Block(0,2,-2,biomesoplenty:log_0:7)
Block(1,2,-2,biomesoplenty:log_0:7)
Block(-2,2,-1,biomesoplenty:log_0:7)
Block(-1,2,-1,biomesoplenty:log_0:7)
Block(0,2,-1,biomesoplenty:log_0:7)
Block(1,2,-1,biomesoplenty:log_0:7)
Block(2,2,-1,biomesoplenty:log_0:7)
Block(-2,2,0,biomesoplenty:log_0:7)
Block(-1,2,0,biomesoplenty:log_0:7)
Block(0,2,0,biomesoplenty:log_0:7)
Block(1,2,0,biomesoplenty:log_0:7)
Block(2,2,0,biomesoplenty:log_0:7)
Block(-1,2,1,biomesoplenty:log_0:7)
Block(0,2,1,biomesoplenty:log_0:7)
Block(-1,3,-2,biomesoplenty:log_0:7)
Block(0,3,-2,biomesoplenty:log_0:7)
Block(1,3,-2,biomesoplenty:log_0:7)
Block(-2,3,-1,biomesoplenty:log_0:7)
Block(-1,3,-1,biomesoplenty:log_0:7)
Block(0,3,-1,biomesoplenty:log_0:7)
Block(1,3,-1,biomesoplenty:log_0:7)
Block(2,3,-1,biomesoplenty:log_0:7)
Block(-1,3,0,biomesoplenty:log_0:7)
Block(0,3,0,biomesoplenty:log_0:7)
Block(1,3,0,biomesoplenty:log_0:7)
Block(0,3,1,biomesoplenty:log_0:7)
Block(-1,4,-2,biomesoplenty:log_0:7)
Block(0,4,-2,biomesoplenty:log_0:7)
Block(1,4,-2,biomesoplenty:log_0:7)
Block(-2,4,-1,biomesoplenty:log_0:7)
Block(-1,4,-1,biomesoplenty:log_0:7)
Block(0,4,-1,biomesoplenty:log_0:7)
Block(1,4,-1,biomesoplenty:log_0:7)
Block(2,4,-1,biomesoplenty:log_0:7)
Block(-1,4,0,biomesoplenty:log_0:7)
Block(0,4,0,biomesoplenty:log_0:7)
Block(1,4,0,biomesoplenty:log_0:7)
Block(0,4,1,biomesoplenty:log_0:7)
Block(-1,5,-3,biomesoplenty:leaves_1:10)
Block(-2,5,-2,biomesoplenty:leaves_1:10)
Block(-1,5,-2,biomesoplenty:log_0:7)
Block(0,5,-2,biomesoplenty:log_0:7)
Block(1,5,-2,biomesoplenty:log_0:7)
Block(-2,5,-1,biomesoplenty:log_0:7)
Block(-1,5,-1,biomesoplenty:log_0:7)
Block(0,5,-1,biomesoplenty:log_0:7)
Block(1,5,-1,biomesoplenty:log_0:7)
Block(2,5,-1,biomesoplenty:log_0:7)
Block(-1,5,0,biomesoplenty:log_0:7)
Block(0,5,0,biomesoplenty:log_0:7)
Block(1,5,0,biomesoplenty:log_0:7)
Block(0,5,1,biomesoplenty:log_0:7)
Block(3,6,-9,biomesoplenty:leaves_1:10)
Block(-6,6,-4,biomesoplenty:leaves_1:10)
Block(-4,6,-4,biomesoplenty:leaves_1:10)
Block(-5,6,-3,biomesoplenty:leaves_1:10)
Block(-4,6,-3,biomesoplenty:leaves_1:10)
Block(-3,6,-3,biomesoplenty:leaves_1:10)
Block(-1,6,-3,biomesoplenty:leaves_1:10)
Block(0,6,-3,biomesoplenty:leaves_1:10)
Block(-4,6,-2,biomesoplenty:leaves_1:10)
Block(-3,6,-2,biomesoplenty:leaves_1:10)
Block(-1,6,-2,biomesoplenty:log_0:7)
Block(0,6,-2,biomesoplenty:log_0:7)
Block(1,6,-2,biomesoplenty:log_0:7)
Block(9,6,-2,biomesoplenty:leaves_1:10)
Block(10,6,-2,biomesoplenty:leaves_1:10)
Block(-2,6,-1,biomesoplenty:log_0:7)
Block(-1,6,-1,biomesoplenty:log_0:7)
Block(0,6,-1,biomesoplenty:log_0:7)
Block(1,6,-1,biomesoplenty:log_0:7)
Block(2,6,-1,biomesoplenty:log_0:7)
Block(4,6,-1,biomesoplenty:leaves_1:10)
Block(5,6,-1,biomesoplenty:leaves_1:10)
Block(8,6,-1,biomesoplenty:leaves_1:10)
Block(9,6,-1,biomesoplenty:leaves_1:10)
Block(-1,6,0,biomesoplenty:log_0:7)
Block(0,6,0,biomesoplenty:log_0:7)
Block(1,6,0,biomesoplenty:log_0:7)
Block(-1,6,1,biomesoplenty:log_0:7)
Block(0,6,1,biomesoplenty:log_0:7)
Block(-1,6,2,biomesoplenty:leaves_1:10)
Block(8,6,2,biomesoplenty:leaves_1:10)
Block(9,6,2,biomesoplenty:leaves_1:10)
Block(-1,6,3,biomesoplenty:leaves_1:10)
Block(0,6,3,biomesoplenty:leaves_1:10)
Block(-3,6,4,biomesoplenty:leaves_1:10)
Block(-2,6,4,biomesoplenty:leaves_1:10)
Block(-1,6,4,biomesoplenty:leaves_1:10)
Block(-2,6,5,biomesoplenty:leaves_1:10)
Block(-6,7,-10,biomesoplenty:leaves_1:10)
Block(0,7,-10,biomesoplenty:leaves_1:10)
Block(5,7,-10,biomesoplenty:leaves_1:10)
Block(-6,7,-9,biomesoplenty:leaves_1:10)
Block(0,7,-9,biomesoplenty:leaves_1:10)
Block(1,7,-9,biomesoplenty:leaves_1:10)
Block(5,7,-9,biomesoplenty:leaves_1:10)
Block(-7,7,-8,biomesoplenty:leaves_1:10)
Block(1,7,-8,biomesoplenty:leaves_1:10)
Block(3,7,-8,biomesoplenty:leaves_1:10)
Block(-8,7,-7,biomesoplenty:leaves_1:10)
Block(-7,7,-7,biomesoplenty:leaves_1:10)
Block(-6,7,-7,biomesoplenty:leaves_1:10)
Block(1,7,-7,biomesoplenty:leaves_1:10)
Block(-7,7,-6,biomesoplenty:leaves_1:10)
Block(-6,7,-6,biomesoplenty:leaves_1:10)
Block(-5,7,-6,biomesoplenty:leaves_1:10)
Block(2,7,-6,biomesoplenty:leaves_1:10)
Block(-6,7,-5,biomesoplenty:leaves_1:10)
Block(-5,7,-5,biomesoplenty:leaves_1:10)
Block(-4,7,-5,biomesoplenty:leaves_1:10)
Block(0,7,-5,biomesoplenty:leaves_1:10)
Block(1,7,-5,biomesoplenty:leaves_1:10)
Block(2,7,-5,biomesoplenty:leaves_1:10)
Block(3,7,-5,biomesoplenty:leaves_1:10)
Block(-5,7,-4,biomesoplenty:log_0:7)
Block(-4,7,-4,biomesoplenty:log_0:7)
Block(-3,7,-4,biomesoplenty:leaves_1:10)
Block(-1,7,-4,biomesoplenty:leaves_1:10)
Block(0,7,-4,biomesoplenty:leaves_1:10)
Block(1,7,-4,biomesoplenty:leaves_1:10)
Block(2,7,-4,biomesoplenty:leaves_1:10)
Block(-5,7,-3,biomesoplenty:leaves_1:10)
Block(-4,7,-3,biomesoplenty:log_0:7)
Block(-3,7,-3,biomesoplenty:leaves_1:10)
Block(0,7,-3,biomesoplenty:leaves_1:10)
Block(-5,7,-2,biomesoplenty:leaves_1:10)
Block(-4,7,-2,biomesoplenty:log_0:7)
Block(-3,7,-2,biomesoplenty:log_0:7)
Block(-2,7,-2,biomesoplenty:leaves_1:10)
Block(-1,7,-2,biomesoplenty:log_0:7)
Block(0,7,-2,biomesoplenty:log_0:7)
Block(1,7,-2,biomesoplenty:leaves_1:10)
Block(-6,7,-1,biomesoplenty:leaves_1:10)
Block(-5,7,-1,biomesoplenty:leaves_1:10)
Block(-3,7,-1,biomesoplenty:log_0:7)
Block(-2,7,-1,biomesoplenty:log_0:7)
Block(-1,7,-1,biomesoplenty:log_0:7)
Block(0,7,-1,biomesoplenty:log_0:7)
Block(1,7,-1,biomesoplenty:log_0:7)
Block(2,7,-1,biomesoplenty:log_0:7)
Block(3,7,-1,biomesoplenty:leaves_1:10)
Block(-2,7,0,biomesoplenty:log_0:7)
Block(-1,7,0,biomesoplenty:log_0:7)
Block(0,7,0,biomesoplenty:log_0:7)
Block(1,7,0,biomesoplenty:log_0:7)
Block(2,7,0,biomesoplenty:log_0:7)
Block(3,7,0,biomesoplenty:leaves_1:10)
Block(4,7,0,biomesoplenty:leaves_1:10)
Block(7,7,0,biomesoplenty:leaves_1:10)
Block(8,7,0,biomesoplenty:leaves_1:10)
Block(9,7,0,biomesoplenty:leaves_1:10)
Block(-8,7,1,biomesoplenty:leaves_1:10)
Block(-1,7,1,biomesoplenty:log_0:7)
Block(0,7,1,biomesoplenty:log_0:7)
Block(1,7,1,biomesoplenty:leaves_1:10)
Block(6,7,1,biomesoplenty:leaves_1:10)
Block(7,7,1,biomesoplenty:leaves_1:10)
Block(8,7,1,biomesoplenty:leaves_1:10)
Block(-12,7,2,biomesoplenty:leaves_1:10)
Block(-11,7,2,biomesoplenty:leaves_1:10)
Block(-9,7,2,biomesoplenty:leaves_1:10)
Block(-8,7,2,biomesoplenty:leaves_1:10)
Block(-7,7,2,biomesoplenty:leaves_1:10)
Block(-1,7,2,biomesoplenty:log_0:7)
Block(0,7,2,biomesoplenty:leaves_1:10)
Block(7,7,2,biomesoplenty:leaves_1:10)
Block(-8,7,3,biomesoplenty:leaves_1:10)
Block(-2,7,3,biomesoplenty:leaves_1:10)
Block(-1,7,3,biomesoplenty:log_0:7)
Block(0,7,3,biomesoplenty:leaves_1:10)
Block(6,7,3,biomesoplenty:leaves_1:10)
Block(-3,7,4,biomesoplenty:leaves_1:10)
Block(-2,7,4,biomesoplenty:log_0:7)
Block(-1,7,4,biomesoplenty:log_0:7)
Block(0,7,4,biomesoplenty:leaves_1:10)
Block(6,7,4,biomesoplenty:leaves_1:10)
Block(7,7,4,biomesoplenty:leaves_1:10)
Block(-10,7,5,biomesoplenty:leaves_1:10)
Block(-9,7,5,biomesoplenty:leaves_1:10)
Block(-5,7,5,biomesoplenty:leaves_1:10)
Block(-4,7,5,biomesoplenty:leaves_1:10)
Block(-3,7,5,biomesoplenty:leaves_1:10)
Block(-2,7,5,biomesoplenty:log_0:7)
Block(-1,7,5,biomesoplenty:leaves_1:10)
Block(-10,7,6,biomesoplenty:leaves_1:10)
Block(-6,7,6,biomesoplenty:leaves_1:10)
Block(-5,7,6,biomesoplenty:leaves_1:10)
Block(-3,7,6,biomesoplenty:leaves_1:10)
Block(-2,7,6,biomesoplenty:log_0:7)
Block(-1,7,6,biomesoplenty:leaves_1:10)
Block(-6,7,7,biomesoplenty:leaves_1:10)
Block(-3,7,7,biomesoplenty:leaves_1:10)
Block(-2,7,7,biomesoplenty:leaves_1:10)
Block(-4,7,8,biomesoplenty:leaves_1:10)
Block(-3,7,8,biomesoplenty:leaves_1:10)
Block(-2,7,8,biomesoplenty:leaves_1:10)
Block(-1,7,8,biomesoplenty:leaves_1:10)
Block(-5,7,9,biomesoplenty:leaves_1:10)
Block(-3,7,9,biomesoplenty:leaves_1:10)
Block(-1,7,9,biomesoplenty:leaves_1:10)
Block(0,7,9,biomesoplenty:leaves_1:10)
Block(7,7,9,biomesoplenty:leaves_1:10)
Block(-5,7,10,biomesoplenty:leaves_1:10)
Block(-3,7,10,biomesoplenty:leaves_1:10)
Block(0,7,10,biomesoplenty:leaves_1:10)
Block(7,7,10,biomesoplenty:leaves_1:10)
Block(3,8,-12,biomesoplenty:leaves_1:10)
Block(-9,8,-10,biomesoplenty:leaves_1:10)
Block(-3,8,-10,biomesoplenty:leaves_1:10)
Block(3,8,-10,biomesoplenty:leaves_1:10)
Block(-9,8,-9,biomesoplenty:leaves_1:10)
Block(-7,8,-9,biomesoplenty:leaves_1:10)
Block(-4,8,-9,biomesoplenty:leaves_1:10)
Block(2,8,-9,biomesoplenty:leaves_1:10)
Block(3,8,-9,biomesoplenty:leaves_1:10)
Block(4,8,-9,biomesoplenty:leaves_1:10)
Block(-8,8,-8,biomesoplenty:leaves_1:10)
Block(-7,8,-8,biomesoplenty:leaves_1:10)
Block(-6,8,-8,biomesoplenty:leaves_1:10)
Block(-4,8,-8,biomesoplenty:leaves_1:10)
Block(-2,8,-8,biomesoplenty:leaves_1:10)
Block(1,8,-8,biomesoplenty:leaves_1:10)
Block(2,8,-8,biomesoplenty:leaves_1:10)
Block(3,8,-8,biomesoplenty:leaves_1:10)
Block(4,8,-8,biomesoplenty:leaves_1:10)
Block(-11,8,-7,biomesoplenty:leaves_1:10)
Block(-8,8,-7,biomesoplenty:leaves_1:10)
Block(-7,8,-7,biomesoplenty:log_0:7)
Block(-6,8,-7,biomesoplenty:log_0:7)
Block(-5,8,-7,biomesoplenty:leaves_1:10)
Block(-2,8,-7,biomesoplenty:leaves_1:10)
Block(1,8,-7,biomesoplenty:leaves_1:10)
Block(2,8,-7,biomesoplenty:log_0:7)
Block(3,8,-7,biomesoplenty:leaves_1:10)
Block(-10,8,-6,biomesoplenty:leaves_1:10)
Block(-9,8,-6,biomesoplenty:leaves_1:10)
Block(-8,8,-6,biomesoplenty:leaves_1:10)
Block(-7,8,-6,biomesoplenty:leaves_1:10)
Block(-6,8,-6,biomesoplenty:log_0:7)
Block(-5,8,-6,biomesoplenty:log_0:7)
Block(-4,8,-6,biomesoplenty:leaves_1:10)
Block(-1,8,-6,biomesoplenty:leaves_1:10)
Block(1,8,-6,biomesoplenty:leaves_1:10)
Block(2,8,-6,biomesoplenty:log_0:7)
Block(3,8,-6,biomesoplenty:leaves_1:10)
Block(6,8,-6,biomesoplenty:leaves_1:10)
Block(-7,8,-5,biomesoplenty:leaves_1:10)
Block(-6,8,-5,biomesoplenty:leaves_1:10)
Block(-5,8,-5,biomesoplenty:log_0:7)
Block(-1,8,-5,biomesoplenty:leaves_1:10)
Block(0,8,-5,biomesoplenty:leaves_1:10)
Block(1,8,-5,biomesoplenty:log_0:7)
Block(2,8,-5,biomesoplenty:log_0:7)
Block(3,8,-5,biomesoplenty:leaves_1:10)
Block(4,8,-5,biomesoplenty:leaves_1:10)
Block(5,8,-5,biomesoplenty:leaves_1:10)
Block(-9,8,-4,biomesoplenty:leaves_1:10)
Block(-6,8,-4,biomesoplenty:leaves_1:10)
Block(-5,8,-4,biomesoplenty:log_0:7)
Block(-4,8,-4,biomesoplenty:leaves_1:10)
Block(-1,8,-4,biomesoplenty:leaves_1:10)
Block(0,8,-4,biomesoplenty:log_0:7)
Block(1,8,-4,biomesoplenty:log_0:7)
Block(2,8,-4,biomesoplenty:leaves_1:10)
Block(3,8,-4,biomesoplenty:leaves_1:10)
Block(-8,8,-3,biomesoplenty:leaves_1:10)
Block(-7,8,-3,biomesoplenty:leaves_1:10)
Block(-6,8,-3,biomesoplenty:leaves_1:10)
Block(-5,8,-3,biomesoplenty:leaves_1:10)
Block(-4,8,-3,biomesoplenty:leaves_1:10)
Block(-3,8,-3,biomesoplenty:leaves_1:10)
Block(-1,8,-3,biomesoplenty:leaves_1:10)
Block(0,8,-3,biomesoplenty:log_0:7)
Block(1,8,-3,biomesoplenty:leaves_1:10)
Block(2,8,-3,biomesoplenty:leaves_1:10)
Block(6,8,-3,biomesoplenty:leaves_1:10)
Block(12,8,-3,biomesoplenty:leaves_1:10)
Block(-5,8,-2,biomesoplenty:leaves_1:10)
Block(-4,8,-2,biomesoplenty:leaves_1:10)
Block(-3,8,-2,biomesoplenty:leaves_1:10)
Block(-1,8,-2,biomesoplenty:log_0:7)
Block(0,8,-2,biomesoplenty:log_0:7)
Block(6,8,-2,biomesoplenty:leaves_1:10)
Block(10,8,-2,biomesoplenty:leaves_1:10)
Block(11,8,-2,biomesoplenty:leaves_1:10)
Block(-11,8,-1,biomesoplenty:leaves_1:10)
Block(-4,8,-1,biomesoplenty:leaves_1:10)
Block(-2,8,-1,biomesoplenty:log_0:7)
Block(-1,8,-1,biomesoplenty:log_0:7)
Block(0,8,-1,biomesoplenty:log_0:7)
Block(1,8,-1,biomesoplenty:log_0:7)
Block(8,8,-1,biomesoplenty:leaves_1:10)
Block(9,8,-1,biomesoplenty:leaves_1:10)
Block(-10,8,0,biomesoplenty:leaves_1:10)
Block(-9,8,0,biomesoplenty:leaves_1:10)
Block(-2,8,0,biomesoplenty:log_0:7)
Block(-1,8,0,biomesoplenty:log_0:7)
Block(0,8,0,biomesoplenty:log_0:7)
Block(1,8,0,biomesoplenty:log_0:7)
Block(2,8,0,biomesoplenty:log_0:7)
Block(3,8,0,biomesoplenty:leaves_1:10)
Block(4,8,0,biomesoplenty:leaves_1:10)
Block(5,8,0,biomesoplenty:leaves_1:10)
Block(6,8,0,biomesoplenty:leaves_1:10)
Block(7,8,0,biomesoplenty:leaves_1:10)
Block(8,8,0,biomesoplenty:log_0:7)
Block(9,8,0,biomesoplenty:log_0:7)
Block(10,8,0,biomesoplenty:leaves_1:10)
Block(-9,8,1,biomesoplenty:leaves_1:10)
Block(-8,8,1,biomesoplenty:leaves_1:10)
Block(-7,8,1,biomesoplenty:leaves_1:10)
Block(-1,8,1,biomesoplenty:log_0:7)
Block(0,8,1,biomesoplenty:log_0:7)
Block(1,8,1,biomesoplenty:log_0:7)
Block(3,8,1,biomesoplenty:leaves_1:10)
Block(4,8,1,biomesoplenty:leaves_1:10)
Block(5,8,1,biomesoplenty:log_0:7)
Block(6,8,1,biomesoplenty:log_0:7)
Block(7,8,1,biomesoplenty:log_0:7)
Block(8,8,1,biomesoplenty:log_0:7)
Block(9,8,1,biomesoplenty:leaves_1:10)
Block(-9,8,2,biomesoplenty:leaves_1:10)
Block(-8,8,2,biomesoplenty:log_0:7)
Block(-7,8,2,biomesoplenty:log_0:7)
Block(1,8,2,biomesoplenty:leaves_1:10)
Block(5,8,2,biomesoplenty:leaves_1:10)
Block(7,8,2,biomesoplenty:leaves_1:10)
Block(8,8,2,biomesoplenty:leaves_1:10)
Block(-11,8,3,biomesoplenty:leaves_1:10)
Block(-10,8,3,biomesoplenty:leaves_1:10)
Block(-9,8,3,biomesoplenty:log_0:7)
Block(-8,8,3,biomesoplenty:log_0:7)
Block(-7,8,3,biomesoplenty:leaves_1:10)
Block(-4,8,3,biomesoplenty:leaves_1:10)
Block(-3,8,3,biomesoplenty:leaves_1:10)
Block(-2,8,3,biomesoplenty:leaves_1:10)
Block(0,8,3,biomesoplenty:leaves_1:10)
Block(5,8,3,biomesoplenty:leaves_1:10)
Block(-9,8,4,biomesoplenty:leaves_1:10)
Block(-8,8,4,biomesoplenty:leaves_1:10)
Block(-5,8,4,biomesoplenty:leaves_1:10)
Block(-2,8,4,biomesoplenty:leaves_1:10)
Block(-1,8,4,biomesoplenty:leaves_1:10)
Block(-3,8,5,biomesoplenty:leaves_1:10)
Block(-2,8,5,biomesoplenty:leaves_1:10)
Block(-4,8,6,biomesoplenty:leaves_1:10)
Block(-3,8,6,biomesoplenty:log_0:7)
Block(-2,8,6,biomesoplenty:log_0:7)
Block(-1,8,6,biomesoplenty:leaves_1:10)
Block(2,8,6,biomesoplenty:leaves_1:10)
Block(-4,8,7,biomesoplenty:leaves_1:10)
Block(-3,8,7,biomesoplenty:log_0:7)
Block(-2,8,7,biomesoplenty:leaves_1:10)
Block(3,8,7,biomesoplenty:leaves_1:10)
Block(4,8,7,biomesoplenty:leaves_1:10)
Block(-4,8,8,biomesoplenty:leaves_1:10)
Block(-3,8,8,biomesoplenty:log_0:7)
Block(-2,8,8,biomesoplenty:leaves_1:10)
Block(4,8,8,biomesoplenty:leaves_1:10)
Block(5,8,8,biomesoplenty:leaves_1:10)
Block(6,8,8,biomesoplenty:leaves_1:10)
Block(-4,8,9,biomesoplenty:leaves_1:10)
Block(-3,8,9,biomesoplenty:leaves_1:10)
Block(-2,8,9,biomesoplenty:leaves_1:10)
Block(2,8,9,biomesoplenty:leaves_1:10)
Block(3,8,9,biomesoplenty:leaves_1:10)
Block(4,8,9,biomesoplenty:leaves_1:10)
Block(6,8,9,biomesoplenty:leaves_1:10)
Block(-3,8,10,biomesoplenty:leaves_1:10)
Block(3,8,10,biomesoplenty:leaves_1:10)
Block(-3,8,11,biomesoplenty:leaves_1:10)
Block(4,8,11,biomesoplenty:leaves_1:10)
Block(-3,8,12,biomesoplenty:leaves_1:10)
Block(4,8,12,biomesoplenty:leaves_1:10)
Block(4,9,-13,biomesoplenty:leaves_1:10)
Block(4,9,-12,biomesoplenty:leaves_1:10)
Block(3,9,-11,biomesoplenty:leaves_1:10)
Block(2,9,-10,biomesoplenty:leaves_1:10)
Block(3,9,-10,biomesoplenty:leaves_1:10)
Block(8,9,-10,biomesoplenty:leaves_1:10)
Block(2,9,-9,biomesoplenty:leaves_1:10)
Block(3,9,-9,biomesoplenty:log_0:7)
Block(4,9,-9,biomesoplenty:leaves_1:10)
Block(6,9,-9,biomesoplenty:leaves_1:10)
Block(7,9,-9,biomesoplenty:leaves_1:10)
Block(-7,9,-8,biomesoplenty:leaves_1:10)
Block(0,9,-8,biomesoplenty:leaves_1:10)
Block(2,9,-8,biomesoplenty:leaves_1:10)
Block(3,9,-8,biomesoplenty:log_0:7)
Block(4,9,-8,biomesoplenty:leaves_1:10)
Block(5,9,-8,biomesoplenty:leaves_1:10)
Block(-8,9,-7,biomesoplenty:leaves_1:10)
Block(-7,9,-7,biomesoplenty:leaves_1:10)
Block(-6,9,-7,biomesoplenty:leaves_1:10)
Block(1,9,-7,biomesoplenty:leaves_1:10)
Block(2,9,-7,biomesoplenty:log_0:7)
Block(3,9,-7,biomesoplenty:log_0:7)
Block(4,9,-7,biomesoplenty:leaves_1:10)
Block(-7,9,-6,biomesoplenty:leaves_1:10)
Block(-6,9,-6,biomesoplenty:leaves_1:10)
Block(-5,9,-6,biomesoplenty:leaves_1:10)
Block(2,9,-6,biomesoplenty:leaves_1:10)
Block(3,9,-6,biomesoplenty:leaves_1:10)
Block(-6,9,-5,biomesoplenty:leaves_1:10)
Block(-5,9,-5,biomesoplenty:leaves_1:10)
Block(-4,9,-5,biomesoplenty:leaves_1:10)
Block(1,9,-5,biomesoplenty:leaves_1:10)
Block(2,9,-5,biomesoplenty:leaves_1:10)
Block(3,9,-5,biomesoplenty:leaves_1:10)
Block(-6,9,-4,biomesoplenty:leaves_1:10)
Block(-5,9,-4,biomesoplenty:leaves_1:10)
Block(-4,9,-4,biomesoplenty:leaves_1:10)
Block(-2,9,-4,biomesoplenty:leaves_1:10)
Block(0,9,-4,biomesoplenty:leaves_1:10)
Block(1,9,-4,biomesoplenty:leaves_1:10)
Block(2,9,-4,biomesoplenty:leaves_1:10)
Block(7,9,-4,biomesoplenty:leaves_1:10)
Block(8,9,-4,biomesoplenty:leaves_1:10)
Block(-5,9,-3,biomesoplenty:leaves_1:10)
Block(-4,9,-3,biomesoplenty:leaves_1:10)
Block(-2,9,-3,biomesoplenty:leaves_1:10)
Block(0,9,-3,biomesoplenty:leaves_1:10)
Block(7,9,-3,biomesoplenty:leaves_1:10)
Block(-4,9,-2,biomesoplenty:leaves_1:10)
Block(-2,9,-2,biomesoplenty:leaves_1:10)
Block(0,9,-2,biomesoplenty:log_0:7)
Block(1,9,-2,biomesoplenty:leaves_1:10)
Block(6,9,-2,biomesoplenty:leaves_1:10)
Block(9,9,-2,biomesoplenty:leaves_1:10)
Block(-3,9,-1,biomesoplenty:leaves_1:10)
Block(-1,9,-1,biomesoplenty:log_0:7)
Block(0,9,-1,biomesoplenty:log_0:7)
Block(1,9,-1,biomesoplenty:log_0:7)
Block(2,9,-1,biomesoplenty:leaves_1:10)
Block(4,9,-1,biomesoplenty:leaves_1:10)
Block(6,9,-1,biomesoplenty:leaves_1:10)
Block(8,9,-1,biomesoplenty:leaves_1:10)
Block(9,9,-1,biomesoplenty:leaves_1:10)
Block(10,9,-1,biomesoplenty:leaves_1:10)
Block(-7,9,0,biomesoplenty:leaves_1:10)
Block(-5,9,0,biomesoplenty:leaves_1:10)
Block(-4,9,0,biomesoplenty:leaves_1:10)
Block(-3,9,0,biomesoplenty:leaves_1:10)
Block(-2,9,0,biomesoplenty:log_0:7)
Block(-1,9,0,biomesoplenty:log_0:7)
Block(0,9,0,biomesoplenty:log_0:7)
Block(1,9,0,biomesoplenty:log_0:7)
Block(2,9,0,biomesoplenty:log_0:7)
Block(3,9,0,biomesoplenty:log_0:7)
Block(4,9,0,biomesoplenty:log_0:7)
Block(5,9,0,biomesoplenty:leaves_1:10)
Block(6,9,0,biomesoplenty:leaves_1:10)
Block(8,9,0,biomesoplenty:leaves_1:10)
Block(9,9,0,biomesoplenty:log_0:7)
Block(10,9,0,biomesoplenty:log_0:7)
Block(11,9,0,biomesoplenty:leaves_1:10)
Block(12,9,0,biomesoplenty:leaves_1:10)
Block(-6,9,1,biomesoplenty:leaves_1:10)
Block(-5,9,1,biomesoplenty:leaves_1:10)
Block(-4,9,1,biomesoplenty:leaves_1:10)
Block(-3,9,1,biomesoplenty:leaves_1:10)
Block(-2,9,1,biomesoplenty:log_0:7)
Block(-1,9,1,biomesoplenty:log_0:7)
Block(0,9,1,biomesoplenty:log_0:7)
Block(1,9,1,biomesoplenty:log_0:7)
Block(2,9,1,biomesoplenty:leaves_1:10)
Block(3,9,1,biomesoplenty:leaves_1:10)
Block(4,9,1,biomesoplenty:log_0:7)
Block(5,9,1,biomesoplenty:log_0:7)
Block(6,9,1,biomesoplenty:leaves_1:10)
Block(7,9,1,biomesoplenty:leaves_1:10)
Block(8,9,1,biomesoplenty:leaves_1:10)
Block(9,9,1,biomesoplenty:leaves_1:10)
Block(10,9,1,biomesoplenty:leaves_1:10)
Block(-9,9,2,biomesoplenty:leaves_1:10)
Block(-8,9,2,biomesoplenty:leaves_1:10)
Block(-7,9,2,biomesoplenty:log_0:7)
Block(-6,9,2,biomesoplenty:log_0:7)
Block(-5,9,2,biomesoplenty:leaves_1:10)
Block(-1,9,2,biomesoplenty:leaves_1:10)
Block(4,9,2,biomesoplenty:leaves_1:10)
Block(5,9,2,biomesoplenty:leaves_1:10)
Block(6,9,2,biomesoplenty:leaves_1:10)
Block(7,9,2,biomesoplenty:leaves_1:10)
Block(-10,9,3,biomesoplenty:leaves_1:10)
Block(-9,9,3,biomesoplenty:leaves_1:10)
Block(-8,9,3,biomesoplenty:leaves_1:10)
Block(-2,9,3,biomesoplenty:leaves_1:10)
Block(8,9,3,biomesoplenty:leaves_1:10)
Block(9,9,3,biomesoplenty:leaves_1:10)
Block(-9,9,4,biomesoplenty:leaves_1:10)
Block(-3,9,4,biomesoplenty:leaves_1:10)
Block(-2,9,4,biomesoplenty:leaves_1:10)
Block(9,9,4,biomesoplenty:leaves_1:10)
Block(10,9,4,biomesoplenty:leaves_1:10)
Block(-3,9,5,biomesoplenty:leaves_1:10)
Block(-4,9,6,biomesoplenty:leaves_1:10)
Block(-3,9,6,biomesoplenty:leaves_1:10)
Block(2,9,6,biomesoplenty:leaves_1:10)
Block(-4,9,7,biomesoplenty:leaves_1:10)
Block(-3,9,7,biomesoplenty:leaves_1:10)
Block(-2,9,7,biomesoplenty:leaves_1:10)
Block(-1,9,7,biomesoplenty:leaves_1:10)
Block(2,9,7,biomesoplenty:leaves_1:10)
Block(3,9,7,biomesoplenty:log_0:7)
Block(-3,9,8,biomesoplenty:leaves_1:10)
Block(-2,9,8,biomesoplenty:leaves_1:10)
Block(2,9,8,biomesoplenty:leaves_1:10)
Block(3,9,8,biomesoplenty:log_0:7)
Block(4,9,8,biomesoplenty:leaves_1:10)
Block(2,9,9,biomesoplenty:leaves_1:10)
Block(3,9,9,biomesoplenty:log_0:7)
Block(4,9,9,biomesoplenty:leaves_1:10)
Block(2,9,10,biomesoplenty:leaves_1:10)
Block(3,9,10,biomesoplenty:leaves_1:10)
Block(4,9,10,biomesoplenty:leaves_1:10)
Block(1,9,11,biomesoplenty:leaves_1:10)
Block(2,9,11,biomesoplenty:leaves_1:10)
Block(1,9,12,biomesoplenty:leaves_1:10)
Block(-3,10,-9,biomesoplenty:leaves_1:10)
Block(3,10,-9,biomesoplenty:leaves_1:10)
Block(-3,10,-8,biomesoplenty:leaves_1:10)
Block(2,10,-8,biomesoplenty:leaves_1:10)
Block(3,10,-8,biomesoplenty:leaves_1:10)
Block(-7,10,-7,biomesoplenty:leaves_1:10)
Block(-4,10,-7,biomesoplenty:leaves_1:10)
Block(2,10,-7,biomesoplenty:leaves_1:10)
Block(3,10,-7,biomesoplenty:leaves_1:10)
Block(-6,10,-6,biomesoplenty:leaves_1:10)
Block(-4,10,-6,biomesoplenty:leaves_1:10)
Block(3,10,-6,biomesoplenty:leaves_1:10)
Block(0,10,-5,biomesoplenty:leaves_1:10)
Block(2,10,-5,biomesoplenty:leaves_1:10)
Block(-7,10,-4,biomesoplenty:leaves_1:10)
Block(-6,10,-4,biomesoplenty:leaves_1:10)
Block(0,10,-4,biomesoplenty:leaves_1:10)
Block(-5,10,-3,biomesoplenty:leaves_1:10)
Block(-1,10,-3,biomesoplenty:leaves_1:10)
Block(1,10,-3,biomesoplenty:leaves_1:10)
Block(-1,10,-2,biomesoplenty:leaves_1:10)
Block(0,10,-2,biomesoplenty:log_0:7)
Block(4,10,-2,biomesoplenty:leaves_1:10)
Block(-4,10,-1,biomesoplenty:leaves_1:10)
Block(-3,10,-1,biomesoplenty:leaves_1:10)
Block(-2,10,-1,biomesoplenty:leaves_1:10)
Block(-1,10,-1,biomesoplenty:log_0:7)
Block(0,10,-1,biomesoplenty:log_0:7)
Block(1,10,-1,biomesoplenty:log_0:7)
Block(3,10,-1,biomesoplenty:leaves_1:10)
Block(9,10,-1,biomesoplenty:leaves_1:10)
Block(-6,10,0,biomesoplenty:leaves_1:10)
Block(-5,10,0,biomesoplenty:leaves_1:10)
Block(-4,10,0,biomesoplenty:leaves_1:10)
Block(-3,10,0,biomesoplenty:log_0:7)
Block(-2,10,0,biomesoplenty:log_0:7)
Block(-1,10,0,biomesoplenty:log_0:7)
Block(0,10,0,biomesoplenty:log_0:7)
Block(1,10,0,biomesoplenty:log_0:7)
Block(2,10,0,biomesoplenty:log_0:7)
Block(3,10,0,biomesoplenty:leaves_1:10)
Block(4,10,0,biomesoplenty:leaves_1:10)
Block(5,10,0,biomesoplenty:leaves_1:10)
Block(8,10,0,biomesoplenty:leaves_1:10)
Block(9,10,0,biomesoplenty:leaves_1:10)
Block(10,10,0,biomesoplenty:leaves_1:10)
Block(-6,10,1,biomesoplenty:leaves_1:10)
Block(-5,10,1,biomesoplenty:log_0:7)
Block(-4,10,1,biomesoplenty:log_0:7)
Block(-3,10,1,biomesoplenty:log_0:7)
Block(-2,10,1,biomesoplenty:leaves_1:10)
Block(-1,10,1,biomesoplenty:log_0:7)
Block(0,10,1,biomesoplenty:log_0:7)
Block(1,10,1,biomesoplenty:log_0:7)
Block(3,10,1,biomesoplenty:leaves_1:10)
Block(5,10,1,biomesoplenty:leaves_1:10)
Block(6,10,1,biomesoplenty:leaves_1:10)
Block(7,10,1,biomesoplenty:leaves_1:10)
Block(8,10,1,biomesoplenty:leaves_1:10)
Block(-7,10,2,biomesoplenty:leaves_1:10)
Block(-6,10,2,biomesoplenty:log_0:7)
Block(-5,10,2,biomesoplenty:log_0:7)
Block(-4,10,2,biomesoplenty:leaves_1:10)
Block(0,10,2,biomesoplenty:leaves_1:10)
Block(3,10,2,biomesoplenty:leaves_1:10)
Block(4,10,2,biomesoplenty:leaves_1:10)
Block(5,10,2,biomesoplenty:leaves_1:10)
Block(6,10,2,biomesoplenty:leaves_1:10)
Block(7,10,2,biomesoplenty:leaves_1:10)
Block(-8,10,3,biomesoplenty:leaves_1:10)
Block(-7,10,3,biomesoplenty:leaves_1:10)
Block(-6,10,3,biomesoplenty:leaves_1:10)
Block(-5,10,3,biomesoplenty:leaves_1:10)
Block(-1,10,3,biomesoplenty:leaves_1:10)
Block(0,10,3,biomesoplenty:leaves_1:10)
Block(5,10,3,biomesoplenty:leaves_1:10)
Block(-2,10,4,biomesoplenty:leaves_1:10)
Block(0,10,4,biomesoplenty:leaves_1:10)
Block(1,10,4,biomesoplenty:leaves_1:10)
Block(6,10,4,biomesoplenty:leaves_1:10)
Block(7,10,4,biomesoplenty:leaves_1:10)
Block(-4,10,5,biomesoplenty:leaves_1:10)
Block(-3,10,5,biomesoplenty:leaves_1:10)
Block(-2,10,5,biomesoplenty:leaves_1:10)
Block(0,10,5,biomesoplenty:leaves_1:10)
Block(1,10,5,biomesoplenty:leaves_1:10)
Block(-6,10,6,biomesoplenty:leaves_1:10)
Block(-5,10,6,biomesoplenty:leaves_1:10)
Block(-3,10,6,biomesoplenty:leaves_1:10)
Block(-2,10,6,biomesoplenty:leaves_1:10)
Block(1,10,6,biomesoplenty:leaves_1:10)
Block(2,10,6,biomesoplenty:log_0:7)
Block(3,10,6,biomesoplenty:leaves_1:10)
Block(-7,10,7,biomesoplenty:leaves_1:10)
Block(-4,10,7,biomesoplenty:leaves_1:10)
Block(-3,10,7,biomesoplenty:leaves_1:10)
Block(1,10,7,biomesoplenty:leaves_1:10)
Block(2,10,7,biomesoplenty:log_0:7)
Block(3,10,7,biomesoplenty:log_0:7)
Block(4,10,7,biomesoplenty:leaves_1:10)
Block(-5,10,8,biomesoplenty:leaves_1:10)
Block(-4,10,8,biomesoplenty:leaves_1:10)
Block(-1,10,8,biomesoplenty:leaves_1:10)
Block(1,10,8,biomesoplenty:leaves_1:10)
Block(2,10,8,biomesoplenty:leaves_1:10)
Block(3,10,8,biomesoplenty:leaves_1:10)
Block(4,10,8,biomesoplenty:leaves_1:10)
Block(-5,10,9,biomesoplenty:leaves_1:10)
Block(-1,10,9,biomesoplenty:leaves_1:10)
Block(2,10,9,biomesoplenty:leaves_1:10)
Block(4,10,9,biomesoplenty:leaves_1:10)
Block(5,10,9,biomesoplenty:leaves_1:10)
Block(3,10,10,biomesoplenty:leaves_1:10)
Block(5,10,10,biomesoplenty:leaves_1:10)
Block(6,10,10,biomesoplenty:leaves_1:10)
Block(6,10,11,biomesoplenty:leaves_1:10)
Block(-5,11,-8,biomesoplenty:leaves_1:10)
Block(-5,11,-7,biomesoplenty:leaves_1:10)
Block(0,11,-6,biomesoplenty:leaves_1:10)
Block(5,11,-5,biomesoplenty:leaves_1:10)
Block(6,11,-5,biomesoplenty:leaves_1:10)
Block(-8,11,-4,biomesoplenty:leaves_1:10)
Block(-7,11,-4,biomesoplenty:leaves_1:10)
Block(4,11,-4,biomesoplenty:leaves_1:10)
Block(5,11,-4,biomesoplenty:leaves_1:10)
Block(-9,11,-3,biomesoplenty:leaves_1:10)
Block(-8,11,-3,biomesoplenty:leaves_1:10)
Block(3,11,-3,biomesoplenty:leaves_1:10)
Block(4,11,-3,biomesoplenty:leaves_1:10)
Block(1,11,-2,biomesoplenty:leaves_1:10)
Block(2,11,-2,biomesoplenty:leaves_1:10)
Block(-3,11,-1,biomesoplenty:leaves_1:10)
Block(-1,11,-1,biomesoplenty:log_0:7)
Block(0,11,-1,biomesoplenty:log_0:7)
Block(1,11,-1,biomesoplenty:log_0:7)
Block(5,11,-1,biomesoplenty:leaves_1:10)
Block(6,11,-1,biomesoplenty:leaves_1:10)
Block(7,11,-1,biomesoplenty:leaves_1:10)
Block(-7,11,0,biomesoplenty:leaves_1:10)
Block(-5,11,0,biomesoplenty:leaves_1:10)
Block(-4,11,0,biomesoplenty:leaves_1:10)
Block(-3,11,0,biomesoplenty:leaves_1:10)
Block(-2,11,0,biomesoplenty:log_0:7)
Block(-1,11,0,biomesoplenty:log_0:7)
Block(0,11,0,biomesoplenty:log_0:7)
Block(1,11,0,biomesoplenty:log_0:7)
Block(3,11,0,biomesoplenty:leaves_1:10)
Block(4,11,0,biomesoplenty:leaves_1:10)
Block(5,11,0,biomesoplenty:leaves_1:10)
Block(-10,11,1,biomesoplenty:leaves_1:10)
Block(-9,11,1,biomesoplenty:leaves_1:10)
Block(-6,11,1,biomesoplenty:leaves_1:10)
Block(-5,11,1,biomesoplenty:leaves_1:10)
Block(-4,11,1,biomesoplenty:leaves_1:10)
Block(-1,11,1,biomesoplenty:log_0:7)
Block(0,11,1,biomesoplenty:log_0:7)
Block(1,11,1,biomesoplenty:log_0:7)
Block(2,11,1,biomesoplenty:leaves_1:10)
Block(3,11,1,biomesoplenty:leaves_1:10)
Block(4,11,1,biomesoplenty:leaves_1:10)
Block(6,11,1,biomesoplenty:leaves_1:10)
Block(-8,11,2,biomesoplenty:leaves_1:10)
Block(-7,11,2,biomesoplenty:leaves_1:10)
Block(-6,11,2,biomesoplenty:leaves_1:10)
Block(-5,11,2,biomesoplenty:leaves_1:10)
Block(-4,11,2,biomesoplenty:leaves_1:10)
Block(-3,11,2,biomesoplenty:leaves_1:10)
Block(-1,11,2,biomesoplenty:leaves_1:10)
Block(0,11,2,biomesoplenty:log_0:7)
Block(1,11,2,biomesoplenty:leaves_1:10)
Block(3,11,2,biomesoplenty:leaves_1:10)
Block(-6,11,3,biomesoplenty:leaves_1:10)
Block(-5,11,3,biomesoplenty:leaves_1:10)
Block(-1,11,3,biomesoplenty:leaves_1:10)
Block(0,11,3,biomesoplenty:log_0:7)
Block(1,11,3,biomesoplenty:leaves_1:10)
Block(-7,11,4,biomesoplenty:leaves_1:10)
Block(-6,11,4,biomesoplenty:leaves_1:10)
Block(-1,11,4,biomesoplenty:leaves_1:10)
Block(0,11,4,biomesoplenty:log_0:7)
Block(1,11,4,biomesoplenty:log_0:7)
Block(2,11,4,biomesoplenty:leaves_1:10)
Block(-8,11,5,biomesoplenty:leaves_1:10)
Block(-2,11,5,biomesoplenty:leaves_1:10)
Block(0,11,5,biomesoplenty:leaves_1:10)
Block(1,11,5,biomesoplenty:log_0:7)
Block(2,11,5,biomesoplenty:leaves_1:10)
Block(3,11,5,biomesoplenty:leaves_1:10)
Block(0,11,6,biomesoplenty:leaves_1:10)
Block(1,11,6,biomesoplenty:log_0:7)
Block(2,11,6,biomesoplenty:log_0:7)
Block(3,11,6,biomesoplenty:leaves_1:10)
Block(4,11,6,biomesoplenty:leaves_1:10)
Block(1,11,7,biomesoplenty:leaves_1:10)
Block(2,11,7,biomesoplenty:leaves_1:10)
Block(3,11,7,biomesoplenty:leaves_1:10)
Block(4,11,7,biomesoplenty:leaves_1:10)
Block(5,11,7,biomesoplenty:leaves_1:10)
Block(2,11,8,biomesoplenty:leaves_1:10)
Block(3,11,8,biomesoplenty:leaves_1:10)
Block(6,11,8,biomesoplenty:leaves_1:10)
Block(3,11,9,biomesoplenty:leaves_1:10)
Block(-7,12,-8,biomesoplenty:leaves_1:10)
Block(-2,12,-8,biomesoplenty:leaves_1:10)
Block(0,12,-5,biomesoplenty:leaves_1:10)
Block(3,12,-5,biomesoplenty:leaves_1:10)
Block(0,12,-4,biomesoplenty:leaves_1:10)
Block(3,12,-4,biomesoplenty:leaves_1:10)
Block(-4,12,-3,biomesoplenty:leaves_1:10)
Block(-3,12,-3,biomesoplenty:leaves_1:10)
Block(1,12,-3,biomesoplenty:leaves_1:10)
Block(2,12,-3,biomesoplenty:leaves_1:10)
Block(3,12,-3,biomesoplenty:log_0:7)
Block(4,12,-3,biomesoplenty:leaves_1:10)
Block(5,12,-3,biomesoplenty:leaves_1:10)
Block(0,12,-2,biomesoplenty:leaves_1:10)
Block(1,12,-2,biomesoplenty:log_0:7)
Block(2,12,-2,biomesoplenty:log_0:7)
Block(3,12,-2,biomesoplenty:log_0:7)
Block(4,12,-2,biomesoplenty:leaves_1:10)
Block(-2,12,-1,biomesoplenty:log_0:7)
Block(-1,12,-1,biomesoplenty:log_0:7)
Block(0,12,-1,biomesoplenty:log_0:7)
Block(1,12,-1,biomesoplenty:log_0:7)
Block(2,12,-1,biomesoplenty:leaves_1:10)
Block(3,12,-1,biomesoplenty:leaves_1:10)
Block(-9,12,0,biomesoplenty:leaves_1:10)
Block(-3,12,0,biomesoplenty:leaves_1:10)
Block(-2,12,0,biomesoplenty:log_0:7)
Block(-1,12,0,biomesoplenty:log_0:7)
Block(0,12,0,biomesoplenty:log_0:7)
Block(1,12,0,biomesoplenty:log_0:7)
Block(-4,12,1,biomesoplenty:leaves_1:10)
Block(-3,12,1,biomesoplenty:leaves_1:10)
Block(-1,12,1,biomesoplenty:log_0:7)
Block(0,12,1,biomesoplenty:log_0:7)
Block(1,12,1,biomesoplenty:log_0:7)
Block(2,12,1,biomesoplenty:leaves_1:10)
Block(-5,12,2,biomesoplenty:leaves_1:10)
Block(-2,12,2,biomesoplenty:leaves_1:10)
Block(0,12,2,biomesoplenty:leaves_1:10)
Block(0,12,3,biomesoplenty:leaves_1:10)
Block(1,12,3,biomesoplenty:leaves_1:10)
Block(2,12,3,biomesoplenty:leaves_1:10)
Block(0,12,4,biomesoplenty:leaves_1:10)
Block(1,12,4,biomesoplenty:leaves_1:10)
Block(1,12,5,biomesoplenty:leaves_1:10)
Block(2,12,5,biomesoplenty:leaves_1:10)
Block(4,12,5,biomesoplenty:leaves_1:10)
Block(5,12,5,biomesoplenty:leaves_1:10)
Block(1,12,6,biomesoplenty:leaves_1:10)
Block(2,12,6,biomesoplenty:leaves_1:10)
Block(-3,12,7,biomesoplenty:leaves_1:10)
Block(2,12,7,biomesoplenty:leaves_1:10)
Block(3,12,7,biomesoplenty:leaves_1:10)
Block(-3,12,8,biomesoplenty:leaves_1:10)
Block(0,12,8,biomesoplenty:leaves_1:10)
Block(2,12,8,biomesoplenty:leaves_1:10)
Block(3,12,8,biomesoplenty:leaves_1:10)
Block(1,12,9,biomesoplenty:leaves_1:10)
Block(2,12,9,biomesoplenty:leaves_1:10)
Block(4,12,9,biomesoplenty:leaves_1:10)
Block(1,12,10,biomesoplenty:leaves_1:10)
Block(5,12,10,biomesoplenty:leaves_1:10)
Block(-9,13,-10,biomesoplenty:leaves_1:10)
Block(-8,13,-9,biomesoplenty:leaves_1:10)
Block(-5,13,-9,biomesoplenty:leaves_1:10)
Block(-8,13,-8,biomesoplenty:leaves_1:10)
Block(-6,13,-8,biomesoplenty:leaves_1:10)
Block(-7,13,-7,biomesoplenty:leaves_1:10)
Block(-6,13,-7,biomesoplenty:leaves_1:10)
Block(-2,13,-7,biomesoplenty:leaves_1:10)
Block(-10,13,-6,biomesoplenty:leaves_1:10)
Block(-9,13,-6,biomesoplenty:leaves_1:10)
Block(-6,13,-6,biomesoplenty:leaves_1:10)
Block(-2,13,-6,biomesoplenty:leaves_1:10)
Block(2,13,-6,biomesoplenty:leaves_1:10)
Block(-3,13,-5,biomesoplenty:leaves_1:10)
Block(2,13,-5,biomesoplenty:leaves_1:10)
Block(-6,13,-4,biomesoplenty:leaves_1:10)
Block(-3,13,-4,biomesoplenty:leaves_1:10)
Block(-1,13,-4,biomesoplenty:leaves_1:10)
Block(0,13,-3,biomesoplenty:leaves_1:10)
Block(2,13,-3,biomesoplenty:leaves_1:10)
Block(3,13,-3,biomesoplenty:leaves_1:10)
Block(-3,13,-2,biomesoplenty:leaves_1:10)
Block(-2,13,-2,biomesoplenty:leaves_1:10)
Block(0,13,-2,biomesoplenty:log_0:7)
Block(1,13,-2,biomesoplenty:leaves_1:10)
Block(2,13,-2,biomesoplenty:leaves_1:10)
Block(3,13,-2,biomesoplenty:leaves_1:10)
Block(8,13,-2,biomesoplenty:leaves_1:10)
Block(9,13,-2,biomesoplenty:leaves_1:10)
Block(-2,13,-1,biomesoplenty:log_0:7)
Block(-1,13,-1,biomesoplenty:log_0:7)
Block(0,13,-1,biomesoplenty:log_0:7)
Block(1,13,-1,biomesoplenty:log_0:7)
Block(3,13,-1,biomesoplenty:leaves_1:10)
Block(-2,13,0,biomesoplenty:log_0:7)
Block(-1,13,0,biomesoplenty:log_0:7)
Block(0,13,0,biomesoplenty:log_0:7)
Block(1,13,0,biomesoplenty:log_0:7)
Block(4,13,0,biomesoplenty:leaves_1:10)
Block(-2,13,1,biomesoplenty:leaves_1:10)
Block(-1,13,1,biomesoplenty:log_0:7)
Block(0,13,1,biomesoplenty:log_0:7)
Block(1,13,1,biomesoplenty:log_0:7)
Block(3,13,1,biomesoplenty:leaves_1:10)
Block(4,13,1,biomesoplenty:leaves_1:10)
Block(5,13,1,biomesoplenty:leaves_1:10)
Block(6,13,1,biomesoplenty:leaves_1:10)
Block(6,13,2,biomesoplenty:leaves_1:10)
Block(7,13,2,biomesoplenty:leaves_1:10)
Block(3,13,3,biomesoplenty:leaves_1:10)
Block(4,13,3,biomesoplenty:leaves_1:10)
Block(-3,13,4,biomesoplenty:leaves_1:10)
Block(-4,13,5,biomesoplenty:leaves_1:10)
Block(-3,13,5,biomesoplenty:leaves_1:10)
Block(-5,13,6,biomesoplenty:leaves_1:10)
Block(-4,13,6,biomesoplenty:leaves_1:10)
Block(-2,13,6,biomesoplenty:leaves_1:10)
Block(-4,13,7,biomesoplenty:leaves_1:10)
Block(-2,13,7,biomesoplenty:leaves_1:10)
Block(-1,13,8,biomesoplenty:leaves_1:10)
Block(-7,14,-12,biomesoplenty:leaves_1:10)
Block(-7,14,-11,biomesoplenty:leaves_1:10)
Block(-6,14,-10,biomesoplenty:leaves_1:10)
Block(-6,14,-9,biomesoplenty:leaves_1:10)
Block(4,14,-9,biomesoplenty:leaves_1:10)
Block(5,14,-9,biomesoplenty:leaves_1:10)
Block(8,14,-9,biomesoplenty:leaves_1:10)
Block(9,14,-9,biomesoplenty:leaves_1:10)
Block(-7,14,-8,biomesoplenty:leaves_1:10)
Block(-6,14,-8,biomesoplenty:leaves_1:10)
Block(-5,14,-8,biomesoplenty:leaves_1:10)
Block(4,14,-8,biomesoplenty:leaves_1:10)
Block(7,14,-8,biomesoplenty:leaves_1:10)
Block(8,14,-8,biomesoplenty:leaves_1:10)
Block(-7,14,-7,biomesoplenty:leaves_1:10)
Block(-6,14,-7,biomesoplenty:log_0:7)
Block(-5,14,-7,biomesoplenty:log_0:7)
Block(-4,14,-7,biomesoplenty:leaves_1:10)
Block(7,14,-7,biomesoplenty:leaves_1:10)
Block(-6,14,-6,biomesoplenty:leaves_1:10)
Block(-5,14,-6,biomesoplenty:leaves_1:10)
Block(6,14,-6,biomesoplenty:leaves_1:10)
Block(7,14,-6,biomesoplenty:leaves_1:10)
Block(8,14,-6,biomesoplenty:leaves_1:10)
Block(-8,14,-5,biomesoplenty:leaves_1:10)
Block(-7,14,-5,biomesoplenty:leaves_1:10)
Block(-6,14,-5,biomesoplenty:leaves_1:10)
Block(-5,14,-5,biomesoplenty:leaves_1:10)
Block(-4,14,-5,biomesoplenty:leaves_1:10)
Block(4,14,-5,biomesoplenty:leaves_1:10)
Block(5,14,-5,biomesoplenty:leaves_1:10)
Block(6,14,-5,biomesoplenty:leaves_1:10)
Block(10,14,-5,biomesoplenty:leaves_1:10)
Block(11,14,-5,biomesoplenty:leaves_1:10)
Block(-5,14,-4,biomesoplenty:leaves_1:10)
Block(-4,14,-4,biomesoplenty:leaves_1:10)
Block(-4,14,-3,biomesoplenty:leaves_1:10)
Block(-3,14,-3,biomesoplenty:leaves_1:10)
Block(7,14,-3,biomesoplenty:leaves_1:10)
Block(8,14,-3,biomesoplenty:leaves_1:10)
Block(-1,14,-2,biomesoplenty:leaves_1:10)
Block(0,14,-2,biomesoplenty:log_0:7)
Block(5,14,-2,biomesoplenty:leaves_1:10)
Block(-7,14,-1,biomesoplenty:leaves_1:10)
Block(-6,14,-1,biomesoplenty:leaves_1:10)
Block(-2,14,-1,biomesoplenty:log_0:7)
Block(-1,14,-1,biomesoplenty:log_0:7)
Block(0,14,-1,biomesoplenty:log_0:7)
Block(1,14,-1,biomesoplenty:log_0:7)
Block(2,14,-1,biomesoplenty:leaves_1:10)
Block(3,14,-1,biomesoplenty:leaves_1:10)
Block(5,14,-1,biomesoplenty:leaves_1:10)
Block(6,14,-1,biomesoplenty:leaves_1:10)
Block(-2,14,0,biomesoplenty:leaves_1:10)
Block(-1,14,0,biomesoplenty:log_0:7)
Block(0,14,0,biomesoplenty:log_0:7)
Block(1,14,0,biomesoplenty:log_0:7)
Block(3,14,0,biomesoplenty:log_0:7)
Block(4,14,0,biomesoplenty:leaves_1:10)
Block(-5,14,1,biomesoplenty:leaves_1:10)
Block(-1,14,1,biomesoplenty:log_0:7)
Block(0,14,1,biomesoplenty:log_0:7)
Block(3,14,1,biomesoplenty:log_0:7)
Block(4,14,1,biomesoplenty:log_0:7)
Block(5,14,1,biomesoplenty:leaves_1:10)
Block(0,14,2,biomesoplenty:leaves_1:10)
Block(3,14,2,biomesoplenty:leaves_1:10)
Block(-3,14,3,biomesoplenty:leaves_1:10)
Block(-1,14,3,biomesoplenty:leaves_1:10)
Block(0,14,3,biomesoplenty:leaves_1:10)
Block(-4,14,4,biomesoplenty:leaves_1:10)
Block(-3,14,4,biomesoplenty:log_0:7)
Block(-2,14,4,biomesoplenty:log_0:7)
Block(-1,14,4,biomesoplenty:log_0:7)
Block(0,14,4,biomesoplenty:leaves_1:10)
Block(-5,14,5,biomesoplenty:leaves_1:10)
Block(-4,14,5,biomesoplenty:log_0:7)
Block(-3,14,5,biomesoplenty:log_0:7)
Block(-2,14,5,biomesoplenty:leaves_1:10)
Block(1,14,5,biomesoplenty:leaves_1:10)
Block(-7,14,6,biomesoplenty:leaves_1:10)
Block(-6,14,6,biomesoplenty:leaves_1:10)
Block(-5,14,6,biomesoplenty:leaves_1:10)
Block(-4,14,6,biomesoplenty:log_0:7)
Block(-3,14,6,biomesoplenty:leaves_1:10)
Block(1,14,6,biomesoplenty:leaves_1:10)
Block(-8,14,7,biomesoplenty:leaves_1:10)
Block(-5,14,7,biomesoplenty:leaves_1:10)
Block(-4,14,7,biomesoplenty:leaves_1:10)
Block(2,14,7,biomesoplenty:leaves_1:10)
Block(-4,14,8,biomesoplenty:leaves_1:10)
Block(-5,14,9,biomesoplenty:leaves_1:10)
Block(-5,14,10,biomesoplenty:leaves_1:10)
Block(-5,15,-9,biomesoplenty:leaves_1:10)
Block(-6,15,-8,biomesoplenty:leaves_1:10)
Block(-5,15,-8,biomesoplenty:leaves_1:10)
Block(-4,15,-8,biomesoplenty:leaves_1:10)
Block(-1,15,-8,biomesoplenty:leaves_1:10)
Block(3,15,-8,biomesoplenty:leaves_1:10)
Block(-6,15,-7,biomesoplenty:leaves_1:10)
Block(-5,15,-7,biomesoplenty:log_0:7)
Block(-4,15,-7,biomesoplenty:leaves_1:10)
Block(-1,15,-7,biomesoplenty:leaves_1:10)
Block(3,15,-7,biomesoplenty:leaves_1:10)
Block(6,15,-7,biomesoplenty:leaves_1:10)
Block(7,15,-7,biomesoplenty:leaves_1:10)
Block(-6,15,-6,biomesoplenty:leaves_1:10)
Block(-5,15,-6,biomesoplenty:log_0:7)
Block(-4,15,-6,biomesoplenty:leaves_1:10)
Block(-2,15,-6,biomesoplenty:leaves_1:10)
Block(4,15,-6,biomesoplenty:leaves_1:10)
Block(5,15,-6,biomesoplenty:leaves_1:10)
Block(6,15,-6,biomesoplenty:log_0:7)
Block(7,15,-6,biomesoplenty:leaves_1:10)
Block(8,15,-6,biomesoplenty:leaves_1:10)
Block(9,15,-6,biomesoplenty:leaves_1:10)
Block(10,15,-6,biomesoplenty:leaves_1:10)
Block(-6,15,-5,biomesoplenty:leaves_1:10)
Block(-5,15,-5,biomesoplenty:log_0:7)
Block(-4,15,-5,biomesoplenty:log_0:7)
Block(-3,15,-5,biomesoplenty:leaves_1:10)
Block(0,15,-5,biomesoplenty:leaves_1:10)
Block(3,15,-5,biomesoplenty:leaves_1:10)
Block(4,15,-5,biomesoplenty:log_0:7)
Block(5,15,-5,biomesoplenty:log_0:7)
Block(6,15,-5,biomesoplenty:log_0:7)
Block(7,15,-5,biomesoplenty:leaves_1:10)
Block(8,15,-5,biomesoplenty:leaves_1:10)
Block(-6,15,-4,biomesoplenty:leaves_1:10)
Block(-5,15,-4,biomesoplenty:leaves_1:10)
Block(-4,15,-4,biomesoplenty:log_0:7)
Block(-3,15,-4,biomesoplenty:leaves_1:10)
Block(-1,15,-4,biomesoplenty:leaves_1:10)
Block(0,15,-4,biomesoplenty:leaves_1:10)
Block(2,15,-4,biomesoplenty:leaves_1:10)
Block(3,15,-4,biomesoplenty:leaves_1:10)
Block(4,15,-4,biomesoplenty:leaves_1:10)
Block(5,15,-4,biomesoplenty:leaves_1:10)
Block(6,15,-4,biomesoplenty:leaves_1:10)
Block(7,15,-4,biomesoplenty:leaves_1:10)
Block(-5,15,-3,biomesoplenty:leaves_1:10)
Block(-4,15,-3,biomesoplenty:log_0:7)
Block(-3,15,-3,biomesoplenty:leaves_1:10)
Block(-2,15,-3,biomesoplenty:leaves_1:10)
Block(1,15,-3,biomesoplenty:leaves_1:10)
Block(2,15,-3,biomesoplenty:leaves_1:10)
Block(4,15,-3,biomesoplenty:leaves_1:10)
Block(-6,15,-2,biomesoplenty:leaves_1:10)
Block(-5,15,-2,biomesoplenty:leaves_1:10)
Block(-4,15,-2,biomesoplenty:leaves_1:10)
Block(-3,15,-2,biomesoplenty:leaves_1:10)
Block(-2,15,-2,biomesoplenty:leaves_1:10)
Block(-1,15,-2,biomesoplenty:log_0:7)
Block(0,15,-2,biomesoplenty:log_0:7)
Block(1,15,-2,biomesoplenty:log_0:7)
Block(2,15,-2,biomesoplenty:leaves_1:10)
Block(4,15,-2,biomesoplenty:leaves_1:10)
Block(-4,15,-1,biomesoplenty:leaves_1:10)
Block(-2,15,-1,biomesoplenty:log_0:7)
Block(-1,15,-1,biomesoplenty:log_0:7)
Block(0,15,-1,biomesoplenty:log_0:7)
Block(1,15,-1,biomesoplenty:log_0:7)
Block(2,15,-1,biomesoplenty:leaves_1:10)
Block(3,15,-1,biomesoplenty:leaves_1:10)
Block(6,15,-1,biomesoplenty:leaves_1:10)
Block(7,15,-1,biomesoplenty:leaves_1:10)
Block(-4,15,0,biomesoplenty:leaves_1:10)
Block(-2,15,0,biomesoplenty:leaves_1:10)
Block(-1,15,0,biomesoplenty:log_0:7)
Block(0,15,0,biomesoplenty:log_0:7)
Block(1,15,0,biomesoplenty:log_0:7)
Block(2,15,0,biomesoplenty:log_0:7)
Block(3,15,0,biomesoplenty:log_0:7)
Block(4,15,0,biomesoplenty:leaves_1:10)
Block(5,15,0,biomesoplenty:leaves_1:10)
Block(7,15,0,biomesoplenty:leaves_1:10)
Block(8,15,0,biomesoplenty:leaves_1:10)
Block(-1,15,1,biomesoplenty:leaves_1:10)
Block(0,15,1,biomesoplenty:log_0:7)
Block(3,15,1,biomesoplenty:leaves_1:10)
Block(4,15,1,biomesoplenty:leaves_1:10)
Block(-1,15,2,biomesoplenty:leaves_1:10)
Block(0,15,2,biomesoplenty:log_0:7)
Block(1,15,2,biomesoplenty:leaves_1:10)
Block(-4,15,3,biomesoplenty:leaves_1:10)
Block(-2,15,3,biomesoplenty:leaves_1:10)
Block(-1,15,3,biomesoplenty:log_0:7)
Block(0,15,3,biomesoplenty:log_0:7)
Block(1,15,3,biomesoplenty:leaves_1:10)
Block(2,15,3,biomesoplenty:leaves_1:10)
Block(7,15,3,biomesoplenty:leaves_1:10)
Block(-4,15,4,biomesoplenty:leaves_1:10)
Block(-3,15,4,biomesoplenty:leaves_1:10)
Block(-2,15,4,biomesoplenty:leaves_1:10)
Block(-1,15,4,biomesoplenty:log_0:7)
Block(0,15,4,biomesoplenty:leaves_1:10)
Block(1,15,4,biomesoplenty:leaves_1:10)
Block(3,15,4,biomesoplenty:leaves_1:10)
Block(-4,15,5,biomesoplenty:leaves_1:10)
Block(-3,15,5,biomesoplenty:leaves_1:10)
Block(-2,15,5,biomesoplenty:leaves_1:10)
Block(-1,15,5,biomesoplenty:leaves_1:10)
Block(0,15,5,biomesoplenty:leaves_1:10)
Block(-5,15,6,biomesoplenty:leaves_1:10)
Block(-4,15,6,biomesoplenty:leaves_1:10)
Block(-3,15,6,biomesoplenty:leaves_1:10)
Block(-2,15,6,biomesoplenty:leaves_1:10)
Block(-4,15,7,biomesoplenty:leaves_1:10)
Block(-2,15,7,biomesoplenty:leaves_1:10)
Block(-2,16,-10,biomesoplenty:leaves_1:10)
Block(-3,16,-9,biomesoplenty:leaves_1:10)
Block(-2,16,-9,biomesoplenty:leaves_1:10)
Block(-5,16,-8,biomesoplenty:leaves_1:10)
Block(-3,16,-8,biomesoplenty:leaves_1:10)
Block(-9,16,-7,biomesoplenty:leaves_1:10)
Block(-5,16,-7,biomesoplenty:leaves_1:10)
Block(-4,16,-7,biomesoplenty:leaves_1:10)
Block(-8,16,-6,biomesoplenty:leaves_1:10)
Block(-7,16,-6,biomesoplenty:leaves_1:10)
Block(-6,16,-6,biomesoplenty:leaves_1:10)
Block(-5,16,-6,biomesoplenty:leaves_1:10)
Block(2,16,-6,biomesoplenty:leaves_1:10)
Block(4,16,-6,biomesoplenty:leaves_1:10)
Block(6,16,-6,biomesoplenty:leaves_1:10)
Block(7,16,-6,biomesoplenty:leaves_1:10)
Block(8,16,-6,biomesoplenty:leaves_1:10)
Block(-7,16,-5,biomesoplenty:leaves_1:10)
Block(-6,16,-5,biomesoplenty:leaves_1:10)
Block(-5,16,-5,biomesoplenty:leaves_1:10)
Block(-4,16,-5,biomesoplenty:leaves_1:10)
Block(2,16,-5,biomesoplenty:leaves_1:10)
Block(3,16,-5,biomesoplenty:leaves_1:10)
Block(4,16,-5,biomesoplenty:log_0:7)
Block(5,16,-5,biomesoplenty:leaves_1:10)
Block(6,16,-5,biomesoplenty:leaves_1:10)
Block(7,16,-5,biomesoplenty:leaves_1:10)
Block(-5,16,-4,biomesoplenty:leaves_1:10)
Block(-4,16,-4,biomesoplenty:leaves_1:10)
Block(-3,16,-4,biomesoplenty:leaves_1:10)
Block(-2,16,-4,biomesoplenty:leaves_1:10)
Block(1,16,-4,biomesoplenty:leaves_1:10)
Block(2,16,-4,biomesoplenty:log_0:7)
Block(3,16,-4,biomesoplenty:log_0:7)
Block(4,16,-4,biomesoplenty:log_0:7)
Block(5,16,-4,biomesoplenty:leaves_1:10)
Block(6,16,-4,biomesoplenty:leaves_1:10)
Block(-6,16,-3,biomesoplenty:leaves_1:10)
Block(-5,16,-3,biomesoplenty:leaves_1:10)
Block(-4,16,-3,biomesoplenty:log_0:7)
Block(-3,16,-3,biomesoplenty:log_0:7)
Block(-2,16,-3,biomesoplenty:log_0:7)
Block(0,16,-3,biomesoplenty:leaves_1:10)
Block(1,16,-3,biomesoplenty:log_0:7)
Block(2,16,-3,biomesoplenty:log_0:7)
Block(3,16,-3,biomesoplenty:leaves_1:10)
Block(4,16,-3,biomesoplenty:leaves_1:10)
Block(5,16,-3,biomesoplenty:leaves_1:10)
Block(-8,16,-2,biomesoplenty:leaves_1:10)
Block(-7,16,-2,biomesoplenty:leaves_1:10)
Block(-4,16,-2,biomesoplenty:leaves_1:10)
Block(-3,16,-2,biomesoplenty:leaves_1:10)
Block(-2,16,-2,biomesoplenty:log_0:7)
Block(-1,16,-2,biomesoplenty:log_0:7)
Block(0,16,-2,biomesoplenty:log_0:7)
Block(1,16,-2,biomesoplenty:log_0:7)
Block(2,16,-2,biomesoplenty:leaves_1:10)
Block(3,16,-2,biomesoplenty:leaves_1:10)
Block(-9,16,-1,biomesoplenty:leaves_1:10)
Block(-5,16,-1,biomesoplenty:leaves_1:10)
Block(-2,16,-1,biomesoplenty:log_0:7)
Block(-1,16,-1,biomesoplenty:log_0:7)
Block(0,16,-1,biomesoplenty:log_0:7)
Block(1,16,-1,biomesoplenty:log_0:7)
Block(-1,16,0,biomesoplenty:log_0:7)
Block(0,16,0,biomesoplenty:log_0:7)
Block(2,16,0,biomesoplenty:leaves_1:10)
Block(3,16,0,biomesoplenty:leaves_1:10)
Block(-1,16,1,biomesoplenty:leaves_1:10)
Block(0,16,1,biomesoplenty:log_0:7)
Block(0,16,2,biomesoplenty:leaves_1:10)
Block(6,16,2,biomesoplenty:leaves_1:10)
Block(-6,16,3,biomesoplenty:leaves_1:10)
Block(-5,16,3,biomesoplenty:leaves_1:10)
Block(-1,16,3,biomesoplenty:leaves_1:10)
Block(0,16,3,biomesoplenty:leaves_1:10)
Block(1,16,3,biomesoplenty:leaves_1:10)
Block(5,16,3,biomesoplenty:leaves_1:10)
Block(6,16,3,biomesoplenty:leaves_1:10)
Block(-4,16,4,biomesoplenty:leaves_1:10)
Block(-2,16,4,biomesoplenty:leaves_1:10)
Block(-1,16,4,biomesoplenty:leaves_1:10)
Block(0,16,4,biomesoplenty:leaves_1:10)
Block(6,16,4,biomesoplenty:leaves_1:10)
Block(9,16,4,biomesoplenty:leaves_1:10)
Block(10,16,4,biomesoplenty:leaves_1:10)
Block(-5,16,5,biomesoplenty:leaves_1:10)
Block(-4,16,5,biomesoplenty:leaves_1:10)
Block(-3,16,5,biomesoplenty:leaves_1:10)
Block(-1,16,5,biomesoplenty:leaves_1:10)
Block(0,16,5,biomesoplenty:leaves_1:10)
Block(-6,16,6,biomesoplenty:leaves_1:10)
Block(-5,16,6,biomesoplenty:leaves_1:10)
Block(-2,16,6,biomesoplenty:leaves_1:10)
Block(-1,16,6,biomesoplenty:leaves_1:10)
Block(-6,16,7,biomesoplenty:leaves_1:10)
Block(-3,16,7,biomesoplenty:leaves_1:10)
Block(-1,16,7,biomesoplenty:leaves_1:10)
Block(0,16,7,biomesoplenty:leaves_1:10)
Block(-7,16,8,biomesoplenty:leaves_1:10)
Block(-3,16,8,biomesoplenty:leaves_1:10)
Block(0,16,8,biomesoplenty:leaves_1:10)
Block(-7,17,-8,biomesoplenty:leaves_1:10)
Block(-6,17,-7,biomesoplenty:leaves_1:10)
Block(-3,17,-7,biomesoplenty:leaves_1:10)
Block(7,17,-7,biomesoplenty:leaves_1:10)
Block(-6,17,-6,biomesoplenty:leaves_1:10)
Block(-4,17,-6,biomesoplenty:leaves_1:10)
Block(-8,17,-5,biomesoplenty:leaves_1:10)
Block(-5,17,-5,biomesoplenty:leaves_1:10)
Block(-4,17,-5,biomesoplenty:leaves_1:10)
Block(3,17,-5,biomesoplenty:leaves_1:10)
Block(4,17,-5,biomesoplenty:leaves_1:10)
Block(-9,17,-4,biomesoplenty:leaves_1:10)
Block(-8,17,-4,biomesoplenty:leaves_1:10)
Block(-4,17,-4,biomesoplenty:leaves_1:10)
Block(-3,17,-4,biomesoplenty:leaves_1:10)
Block(0,17,-4,biomesoplenty:leaves_1:10)
Block(2,17,-4,biomesoplenty:leaves_1:10)
Block(3,17,-4,biomesoplenty:leaves_1:10)
Block(4,17,-4,biomesoplenty:leaves_1:10)
Block(5,17,-4,biomesoplenty:leaves_1:10)
Block(-4,17,-3,biomesoplenty:leaves_1:10)
Block(-3,17,-3,biomesoplenty:leaves_1:10)
Block(-2,17,-3,biomesoplenty:leaves_1:10)
Block(-1,17,-3,biomesoplenty:leaves_1:10)
Block(0,17,-3,biomesoplenty:leaves_1:10)
Block(1,17,-3,biomesoplenty:leaves_1:10)
Block(2,17,-3,biomesoplenty:leaves_1:10)
Block(3,17,-3,biomesoplenty:leaves_1:10)
Block(-3,17,-2,biomesoplenty:leaves_1:10)
Block(-1,17,-2,biomesoplenty:log_0:7)
Block(0,17,-2,biomesoplenty:log_0:7)
Block(1,17,-2,biomesoplenty:log_0:7)
Block(5,17,-2,biomesoplenty:leaves_1:10)
Block(6,17,-2,biomesoplenty:leaves_1:10)
Block(-2,17,-1,biomesoplenty:log_0:7)
Block(-1,17,-1,biomesoplenty:log_0:7)
Block(0,17,-1,biomesoplenty:log_0:7)
Block(1,17,-1,biomesoplenty:log_0:7)
Block(8,17,-1,biomesoplenty:leaves_1:10)
Block(-5,17,0,biomesoplenty:leaves_1:10)
Block(-4,17,0,biomesoplenty:leaves_1:10)
Block(-2,17,0,biomesoplenty:log_0:7)
Block(-1,17,0,biomesoplenty:log_0:7)
Block(0,17,0,biomesoplenty:log_0:7)
Block(2,17,0,biomesoplenty:leaves_1:10)
Block(7,17,0,biomesoplenty:leaves_1:10)
Block(-7,17,1,biomesoplenty:leaves_1:10)
Block(-6,17,1,biomesoplenty:leaves_1:10)
Block(-2,17,1,biomesoplenty:leaves_1:10)
Block(-1,17,1,biomesoplenty:log_0:7)
Block(0,17,1,biomesoplenty:log_0:7)
Block(1,17,1,biomesoplenty:leaves_1:10)
Block(2,17,1,biomesoplenty:leaves_1:10)
Block(3,17,1,biomesoplenty:leaves_1:10)
Block(4,17,1,biomesoplenty:leaves_1:10)
Block(5,17,1,biomesoplenty:leaves_1:10)
Block(6,17,1,biomesoplenty:leaves_1:10)
Block(-1,17,2,biomesoplenty:leaves_1:10)
Block(3,17,2,biomesoplenty:leaves_1:10)
Block(4,17,2,biomesoplenty:log_0:7)
Block(5,17,2,biomesoplenty:log_0:7)
Block(6,17,2,biomesoplenty:log_0:7)
Block(7,17,2,biomesoplenty:leaves_1:10)
Block(4,17,3,biomesoplenty:leaves_1:10)
Block(5,17,3,biomesoplenty:leaves_1:10)
Block(6,17,3,biomesoplenty:log_0:7)
Block(7,17,3,biomesoplenty:leaves_1:10)
Block(8,17,3,biomesoplenty:leaves_1:10)
Block(9,17,3,biomesoplenty:leaves_1:10)
Block(1,17,4,biomesoplenty:leaves_1:10)
Block(5,17,4,biomesoplenty:leaves_1:10)
Block(6,17,4,biomesoplenty:leaves_1:10)
Block(7,17,4,biomesoplenty:leaves_1:10)
Block(1,17,5,biomesoplenty:leaves_1:10)
Block(2,17,5,biomesoplenty:leaves_1:10)
Block(2,17,6,biomesoplenty:leaves_1:10)
Block(-2,17,7,biomesoplenty:leaves_1:10)
Block(3,18,-13,biomesoplenty:leaves_1:10)
Block(2,18,-12,biomesoplenty:leaves_1:10)
Block(0,18,-11,biomesoplenty:leaves_1:10)
Block(2,18,-11,biomesoplenty:leaves_1:10)
Block(-1,18,-10,biomesoplenty:leaves_1:10)
Block(0,18,-10,biomesoplenty:leaves_1:10)
Block(1,18,-10,biomesoplenty:leaves_1:10)
Block(-1,18,-9,biomesoplenty:leaves_1:10)
Block(0,18,-9,biomesoplenty:leaves_1:10)
Block(-1,18,-8,biomesoplenty:leaves_1:10)
Block(-3,18,-3,biomesoplenty:leaves_1:10)
Block(-1,18,-3,biomesoplenty:log_0:7)
Block(0,18,-3,biomesoplenty:leaves_1:10)
Block(-8,18,-2,biomesoplenty:leaves_1:10)
Block(-7,18,-2,biomesoplenty:leaves_1:10)
Block(-4,18,-2,biomesoplenty:leaves_1:10)
Block(-3,18,-2,biomesoplenty:leaves_1:10)
Block(-2,18,-2,biomesoplenty:leaves_1:10)
Block(-1,18,-2,biomesoplenty:log_0:7)
Block(0,18,-2,biomesoplenty:log_0:7)
Block(1,18,-2,biomesoplenty:log_0:7)
Block(-7,18,-1,biomesoplenty:leaves_1:10)
Block(-6,18,-1,biomesoplenty:leaves_1:10)
Block(-5,18,-1,biomesoplenty:leaves_1:10)
Block(-4,18,-1,biomesoplenty:log_0:7)
Block(-3,18,-1,biomesoplenty:log_0:7)
Block(-2,18,-1,biomesoplenty:log_0:7)
Block(-1,18,-1,biomesoplenty:log_0:7)
Block(0,18,-1,biomesoplenty:log_0:7)
Block(1,18,-1,biomesoplenty:log_0:7)
Block(2,18,-1,biomesoplenty:leaves_1:10)
Block(-6,18,0,biomesoplenty:leaves_1:10)
Block(-5,18,0,biomesoplenty:log_0:7)
Block(-4,18,0,biomesoplenty:log_0:7)
Block(-2,18,0,biomesoplenty:log_0:7)
Block(-1,18,0,biomesoplenty:log_0:7)
Block(0,18,0,biomesoplenty:log_0:7)
Block(1,18,0,biomesoplenty:log_0:7)
Block(2,18,0,biomesoplenty:log_0:7)
Block(3,18,0,biomesoplenty:leaves_1:10)
Block(4,18,0,biomesoplenty:leaves_1:10)
Block(-5,18,1,biomesoplenty:leaves_1:10)
Block(-4,18,1,biomesoplenty:leaves_1:10)
Block(-1,18,1,biomesoplenty:log_0:7)
Block(0,18,1,biomesoplenty:leaves_1:10)
Block(1,18,1,biomesoplenty:leaves_1:10)
Block(2,18,1,biomesoplenty:log_0:7)
Block(3,18,1,biomesoplenty:log_0:7)
Block(4,18,1,biomesoplenty:log_0:7)
Block(5,18,1,biomesoplenty:leaves_1:10)
Block(7,18,1,biomesoplenty:leaves_1:10)
Block(8,18,1,biomesoplenty:leaves_1:10)
Block(-9,18,2,biomesoplenty:leaves_1:10)
Block(-8,18,2,biomesoplenty:leaves_1:10)
Block(2,18,2,biomesoplenty:leaves_1:10)
Block(3,18,2,biomesoplenty:leaves_1:10)
Block(4,18,2,biomesoplenty:log_0:7)
Block(5,18,2,biomesoplenty:leaves_1:10)
Block(6,18,2,biomesoplenty:leaves_1:10)
Block(3,18,3,biomesoplenty:leaves_1:10)
Block(4,18,3,biomesoplenty:leaves_1:10)
Block(5,18,3,biomesoplenty:leaves_1:10)
Block(6,18,3,biomesoplenty:leaves_1:10)
Block(7,18,3,biomesoplenty:leaves_1:10)
Block(-6,18,4,biomesoplenty:leaves_1:10)
Block(-5,18,4,biomesoplenty:leaves_1:10)
Block(6,18,4,biomesoplenty:leaves_1:10)
Block(-7,18,5,biomesoplenty:leaves_1:10)
Block(-6,18,5,biomesoplenty:leaves_1:10)
Block(-5,18,5,biomesoplenty:leaves_1:10)
Block(7,18,5,biomesoplenty:leaves_1:10)
Block(-8,18,6,biomesoplenty:leaves_1:10)
Block(-6,18,6,biomesoplenty:leaves_1:10)
Block(-10,18,7,biomesoplenty:leaves_1:10)
Block(-9,18,7,biomesoplenty:leaves_1:10)
Block(0,19,-13,biomesoplenty:leaves_1:10)
Block(-4,19,-12,biomesoplenty:leaves_1:10)
Block(0,19,-12,biomesoplenty:leaves_1:10)
Block(-4,19,-11,biomesoplenty:leaves_1:10)
Block(-3,19,-11,biomesoplenty:leaves_1:10)
Block(-1,19,-11,biomesoplenty:leaves_1:10)
Block(0,19,-11,biomesoplenty:leaves_1:10)
Block(1,19,-11,biomesoplenty:leaves_1:10)
Block(-3,19,-10,biomesoplenty:leaves_1:10)
Block(-1,19,-10,biomesoplenty:leaves_1:10)
Block(0,19,-10,biomesoplenty:log_0:7)
Block(1,19,-10,biomesoplenty:leaves_1:10)
Block(2,19,-10,biomesoplenty:leaves_1:10)
Block(-2,19,-9,biomesoplenty:leaves_1:10)
Block(-1,19,-9,biomesoplenty:leaves_1:10)
Block(0,19,-9,biomesoplenty:log_0:7)
Block(1,19,-9,biomesoplenty:leaves_1:10)
Block(-2,19,-8,biomesoplenty:leaves_1:10)
Block(-1,19,-8,biomesoplenty:leaves_1:10)
Block(0,19,-8,biomesoplenty:leaves_1:10)
Block(3,19,-8,biomesoplenty:leaves_1:10)
Block(-3,19,-7,biomesoplenty:leaves_1:10)
Block(-2,19,-7,biomesoplenty:leaves_1:10)
Block(-1,19,-7,biomesoplenty:leaves_1:10)
Block(2,19,-7,biomesoplenty:leaves_1:10)
Block(6,19,-7,biomesoplenty:leaves_1:10)
Block(-2,19,-6,biomesoplenty:leaves_1:10)
Block(1,19,-6,biomesoplenty:leaves_1:10)
Block(5,19,-6,biomesoplenty:leaves_1:10)
Block(6,19,-6,biomesoplenty:leaves_1:10)
Block(7,19,-6,biomesoplenty:leaves_1:10)
Block(-11,19,-5,biomesoplenty:leaves_1:10)
Block(-10,19,-5,biomesoplenty:leaves_1:10)
Block(4,19,-5,biomesoplenty:leaves_1:10)
Block(5,19,-5,biomesoplenty:leaves_1:10)
Block(6,19,-5,biomesoplenty:leaves_1:10)
Block(-9,19,-4,biomesoplenty:leaves_1:10)
Block(-1,19,-4,biomesoplenty:leaves_1:10)
Block(5,19,-4,biomesoplenty:leaves_1:10)
Block(-10,19,-3,biomesoplenty:leaves_1:10)
Block(-9,19,-3,biomesoplenty:leaves_1:10)
Block(-5,19,-3,biomesoplenty:leaves_1:10)
Block(-2,19,-3,biomesoplenty:leaves_1:10)
Block(-1,19,-3,biomesoplenty:log_0:7)
Block(5,19,-3,biomesoplenty:leaves_1:10)
Block(6,19,-3,biomesoplenty:leaves_1:10)
Block(7,19,-3,biomesoplenty:leaves_1:10)
Block(-9,19,-2,biomesoplenty:leaves_1:10)
Block(-4,19,-2,biomesoplenty:leaves_1:10)
Block(-1,19,-2,biomesoplenty:log_0:7)
Block(0,19,-2,biomesoplenty:log_0:7)
Block(7,19,-2,biomesoplenty:leaves_1:10)
Block(8,19,-2,biomesoplenty:leaves_1:10)
Block(-10,19,-1,biomesoplenty:leaves_1:10)
Block(-4,19,-1,biomesoplenty:leaves_1:10)
Block(-3,19,-1,biomesoplenty:leaves_1:10)
Block(-2,19,-1,biomesoplenty:log_0:7)
Block(-1,19,-1,biomesoplenty:log_0:7)
Block(0,19,-1,biomesoplenty:log_0:7)
Block(1,19,-1,biomesoplenty:log_0:7)
Block(5,19,-1,biomesoplenty:leaves_1:10)
Block(-5,19,0,biomesoplenty:leaves_1:10)
Block(-4,19,0,biomesoplenty:leaves_1:10)
Block(-2,19,0,biomesoplenty:log_0:7)
Block(-1,19,0,biomesoplenty:log_0:7)
Block(0,19,0,biomesoplenty:log_0:7)
Block(2,19,0,biomesoplenty:leaves_1:10)
Block(3,19,0,biomesoplenty:leaves_1:10)
Block(5,19,0,biomesoplenty:leaves_1:10)
Block(-2,19,1,biomesoplenty:leaves_1:10)
Block(-1,19,1,biomesoplenty:leaves_1:10)
Block(2,19,1,biomesoplenty:leaves_1:10)
Block(3,19,1,biomesoplenty:leaves_1:10)
Block(4,19,1,biomesoplenty:leaves_1:10)
Block(-4,19,2,biomesoplenty:leaves_1:10)
Block(-2,19,2,biomesoplenty:leaves_1:10)
Block(3,19,2,biomesoplenty:leaves_1:10)
Block(4,19,2,biomesoplenty:leaves_1:10)
Block(5,19,2,biomesoplenty:leaves_1:10)
Block(-8,19,3,biomesoplenty:leaves_1:10)
Block(-7,19,3,biomesoplenty:leaves_1:10)
Block(-5,19,3,biomesoplenty:leaves_1:10)
Block(-4,19,3,biomesoplenty:leaves_1:10)
Block(-1,19,3,biomesoplenty:leaves_1:10)
Block(4,19,3,biomesoplenty:leaves_1:10)
Block(-7,19,4,biomesoplenty:leaves_1:10)
Block(-6,19,4,biomesoplenty:log_0:7)
Block(-5,19,4,biomesoplenty:log_0:7)
Block(0,19,4,biomesoplenty:leaves_1:10)
Block(4,19,4,biomesoplenty:leaves_1:10)
Block(-9,19,5,biomesoplenty:leaves_1:10)
Block(-8,19,5,biomesoplenty:leaves_1:10)
Block(-7,19,5,biomesoplenty:leaves_1:10)
Block(-6,19,5,biomesoplenty:log_0:7)
Block(-5,19,5,biomesoplenty:leaves_1:10)
Block(-3,19,5,biomesoplenty:leaves_1:10)
Block(5,19,5,biomesoplenty:leaves_1:10)
Block(-7,19,6,biomesoplenty:leaves_1:10)
Block(-6,19,6,biomesoplenty:leaves_1:10)
Block(-5,19,6,biomesoplenty:leaves_1:10)
Block(-3,19,6,biomesoplenty:leaves_1:10)
Block(-2,19,6,biomesoplenty:leaves_1:10)
Block(-6,19,7,biomesoplenty:leaves_1:10)
Block(-5,19,7,biomesoplenty:leaves_1:10)
Block(-2,19,7,biomesoplenty:leaves_1:10)
Block(-7,19,8,biomesoplenty:leaves_1:10)
Block(-6,19,8,biomesoplenty:leaves_1:10)
Block(0,20,-11,biomesoplenty:leaves_1:10)
Block(-2,20,-10,biomesoplenty:leaves_1:10)
Block(-1,20,-10,biomesoplenty:leaves_1:10)
Block(0,20,-10,biomesoplenty:leaves_1:10)
Block(1,20,-10,biomesoplenty:leaves_1:10)
Block(-2,20,-9,biomesoplenty:leaves_1:10)
Block(-1,20,-9,biomesoplenty:log_0:7)
Block(0,20,-9,biomesoplenty:log_0:7)
Block(6,20,-9,biomesoplenty:leaves_1:10)
Block(-5,20,-8,biomesoplenty:leaves_1:10)
Block(-3,20,-8,biomesoplenty:leaves_1:10)
Block(-2,20,-8,biomesoplenty:log_0:7)
Block(-1,20,-8,biomesoplenty:log_0:7)
Block(0,20,-8,biomesoplenty:leaves_1:10)
Block(6,20,-8,biomesoplenty:leaves_1:10)
Block(-10,20,-7,biomesoplenty:leaves_1:10)
Block(-4,20,-7,biomesoplenty:leaves_1:10)
Block(-3,20,-7,biomesoplenty:leaves_1:10)
Block(-2,20,-7,biomesoplenty:log_0:7)
Block(-1,20,-7,biomesoplenty:leaves_1:10)
Block(0,20,-7,biomesoplenty:leaves_1:10)
Block(5,20,-7,biomesoplenty:leaves_1:10)
Block(6,20,-7,biomesoplenty:leaves_1:10)
Block(7,20,-7,biomesoplenty:leaves_1:10)
Block(-9,20,-6,biomesoplenty:leaves_1:10)
Block(-4,20,-6,biomesoplenty:leaves_1:10)
Block(-3,20,-6,biomesoplenty:leaves_1:10)
Block(-2,20,-6,biomesoplenty:log_0:7)
Block(-1,20,-6,biomesoplenty:leaves_1:10)
Block(0,20,-6,biomesoplenty:leaves_1:10)
Block(1,20,-6,biomesoplenty:leaves_1:10)
Block(4,20,-6,biomesoplenty:leaves_1:10)
Block(5,20,-6,biomesoplenty:leaves_1:10)
Block(6,20,-6,biomesoplenty:log_0:7)
Block(7,20,-6,biomesoplenty:leaves_1:10)
Block(8,20,-6,biomesoplenty:leaves_1:10)
Block(-8,20,-5,biomesoplenty:leaves_1:10)
Block(-3,20,-5,biomesoplenty:leaves_1:10)
Block(-2,20,-5,biomesoplenty:log_0:7)
Block(-1,20,-5,biomesoplenty:log_0:7)
Block(0,20,-5,biomesoplenty:leaves_1:10)
Block(4,20,-5,biomesoplenty:log_0:7)
Block(5,20,-5,biomesoplenty:log_0:7)
Block(6,20,-5,biomesoplenty:log_0:7)
Block(-10,20,-4,biomesoplenty:leaves_1:10)
Block(-9,20,-4,biomesoplenty:leaves_1:10)
Block(-8,20,-4,biomesoplenty:leaves_1:10)
Block(-7,20,-4,biomesoplenty:leaves_1:10)
Block(3,20,-4,biomesoplenty:leaves_1:10)
Block(4,20,-4,biomesoplenty:log_0:7)
Block(5,20,-4,biomesoplenty:leaves_1:10)
Block(6,20,-4,biomesoplenty:leaves_1:10)
Block(-11,20,-3,biomesoplenty:leaves_1:10)
Block(-10,20,-3,biomesoplenty:leaves_1:10)
Block(-9,20,-3,biomesoplenty:log_0:7)
Block(-8,20,-3,biomesoplenty:log_0:7)
Block(-7,20,-3,biomesoplenty:log_0:7)
Block(-6,20,-3,biomesoplenty:leaves_1:10)
Block(-1,20,-3,biomesoplenty:log_0:7)
Block(0,20,-3,biomesoplenty:log_0:7)
Block(2,20,-3,biomesoplenty:leaves_1:10)
Block(3,20,-3,biomesoplenty:log_0:7)
Block(4,20,-3,biomesoplenty:log_0:7)
Block(-10,20,-2,biomesoplenty:leaves_1:10)
Block(-9,20,-2,biomesoplenty:leaves_1:10)
Block(-8,20,-2,biomesoplenty:leaves_1:10)
Block(-7,20,-2,biomesoplenty:leaves_1:10)
Block(-2,20,-2,biomesoplenty:log_0:7)
Block(-1,20,-2,biomesoplenty:log_0:7)
Block(0,20,-2,biomesoplenty:log_0:7)
Block(3,20,-2,biomesoplenty:leaves_1:10)
Block(-2,20,-1,biomesoplenty:log_0:7)
Block(-1,20,-1,biomesoplenty:log_0:7)
Block(0,20,-1,biomesoplenty:log_0:7)
Block(-3,20,0,biomesoplenty:leaves_1:10)
Block(-2,20,0,biomesoplenty:log_0:7)
Block(-1,20,0,biomesoplenty:log_0:7)
Block(0,20,0,biomesoplenty:log_0:7)
Block(-5,20,1,biomesoplenty:leaves_1:10)
Block(-4,20,1,biomesoplenty:log_0:7)
Block(-3,20,1,biomesoplenty:log_0:7)
Block(-2,20,1,biomesoplenty:log_0:7)
Block(-1,20,1,biomesoplenty:leaves_1:10)
Block(0,20,1,biomesoplenty:leaves_1:10)
Block(3,20,1,biomesoplenty:leaves_1:10)
Block(-5,20,2,biomesoplenty:log_0:7)
Block(-4,20,2,biomesoplenty:log_0:7)
Block(-3,20,2,biomesoplenty:leaves_1:10)
Block(-2,20,2,biomesoplenty:leaves_1:10)
Block(-1,20,2,biomesoplenty:leaves_1:10)
Block(-7,20,3,biomesoplenty:leaves_1:10)
Block(-6,20,3,biomesoplenty:leaves_1:10)
Block(-5,20,3,biomesoplenty:log_0:7)
Block(-4,20,3,biomesoplenty:leaves_1:10)
Block(-3,20,3,biomesoplenty:leaves_1:10)
Block(-6,20,4,biomesoplenty:leaves_1:10)
Block(-5,20,4,biomesoplenty:log_0:7)
Block(-4,20,4,biomesoplenty:leaves_1:10)
Block(-3,20,4,biomesoplenty:leaves_1:10)
Block(-7,20,5,biomesoplenty:leaves_1:10)
Block(-6,20,5,biomesoplenty:leaves_1:10)
Block(-5,20,5,biomesoplenty:leaves_1:10)
Block(-4,20,5,biomesoplenty:leaves_1:10)
Block(-6,20,6,biomesoplenty:leaves_1:10)
Block(-1,21,-10,biomesoplenty:leaves_1:10)
Block(5,21,-10,biomesoplenty:leaves_1:10)
Block(-1,21,-9,biomesoplenty:leaves_1:10)
Block(0,21,-9,biomesoplenty:leaves_1:10)
Block(5,21,-9,biomesoplenty:leaves_1:10)
Block(-2,21,-8,biomesoplenty:leaves_1:10)
Block(-1,21,-8,biomesoplenty:leaves_1:10)
Block(-3,21,-7,biomesoplenty:leaves_1:10)
Block(-2,21,-7,biomesoplenty:leaves_1:10)
Block(-1,21,-7,biomesoplenty:leaves_1:10)
Block(0,21,-7,biomesoplenty:leaves_1:10)
Block(6,21,-7,biomesoplenty:leaves_1:10)
Block(-6,21,-6,biomesoplenty:leaves_1:10)
Block(-5,21,-6,biomesoplenty:leaves_1:10)
Block(-3,21,-6,biomesoplenty:leaves_1:10)
Block(-2,21,-6,biomesoplenty:leaves_1:10)
Block(0,21,-6,biomesoplenty:leaves_1:10)
Block(5,21,-6,biomesoplenty:leaves_1:10)
Block(6,21,-6,biomesoplenty:leaves_1:10)
Block(7,21,-6,biomesoplenty:leaves_1:10)
Block(-2,21,-5,biomesoplenty:leaves_1:10)
Block(-1,21,-5,biomesoplenty:log_0:7)
Block(0,21,-5,biomesoplenty:leaves_1:10)
Block(4,21,-5,biomesoplenty:leaves_1:10)
Block(5,21,-5,biomesoplenty:leaves_1:10)
Block(6,21,-5,biomesoplenty:leaves_1:10)
Block(-8,21,-4,biomesoplenty:leaves_1:10)
Block(-7,21,-4,biomesoplenty:leaves_1:10)
Block(-6,21,-4,biomesoplenty:leaves_1:10)
Block(-2,21,-4,biomesoplenty:leaves_1:10)
Block(-1,21,-4,biomesoplenty:log_0:7)
Block(0,21,-4,biomesoplenty:leaves_1:10)
Block(2,21,-4,biomesoplenty:leaves_1:10)
Block(3,21,-4,biomesoplenty:leaves_1:10)
Block(4,21,-4,biomesoplenty:leaves_1:10)
Block(5,21,-4,biomesoplenty:leaves_1:10)
Block(7,21,-4,biomesoplenty:leaves_1:10)
Block(-9,21,-3,biomesoplenty:leaves_1:10)
Block(-8,21,-3,biomesoplenty:leaves_1:10)
Block(-7,21,-3,biomesoplenty:log_0:7)
Block(-6,21,-3,biomesoplenty:log_0:7)
Block(-5,21,-3,biomesoplenty:log_0:7)
Block(-3,21,-3,biomesoplenty:leaves_1:10)
Block(-1,21,-3,biomesoplenty:log_0:7)
Block(0,21,-3,biomesoplenty:log_0:7)
Block(2,21,-3,biomesoplenty:leaves_1:10)
Block(3,21,-3,biomesoplenty:log_0:7)
Block(4,21,-3,biomesoplenty:leaves_1:10)
Block(7,21,-3,biomesoplenty:leaves_1:10)
Block(-9,21,-2,biomesoplenty:leaves_1:10)
Block(-8,21,-2,biomesoplenty:leaves_1:10)
Block(-7,21,-2,biomesoplenty:leaves_1:10)
Block(-6,21,-2,biomesoplenty:leaves_1:10)
Block(-5,21,-2,biomesoplenty:log_0:7)
Block(-4,21,-2,biomesoplenty:leaves_1:10)
Block(-3,21,-2,biomesoplenty:leaves_1:10)
Block(-2,21,-2,biomesoplenty:log_0:7)
Block(-1,21,-2,biomesoplenty:log_0:7)
Block(0,21,-2,biomesoplenty:log_0:7)
Block(1,21,-2,biomesoplenty:log_0:7)
Block(2,21,-2,biomesoplenty:log_0:7)
Block(3,21,-2,biomesoplenty:log_0:7)
Block(4,21,-2,biomesoplenty:leaves_1:10)
Block(8,21,-2,biomesoplenty:leaves_1:10)
Block(-8,21,-1,biomesoplenty:leaves_1:10)
Block(-7,21,-1,biomesoplenty:leaves_1:10)
Block(-5,21,-1,biomesoplenty:leaves_1:10)
Block(-3,21,-1,biomesoplenty:leaves_1:10)
Block(-2,21,-1,biomesoplenty:log_0:7)
Block(-1,21,-1,biomesoplenty:log_0:7)
Block(0,21,-1,biomesoplenty:log_0:7)
Block(1,21,-1,biomesoplenty:leaves_1:10)
Block(4,21,-1,biomesoplenty:leaves_1:10)
Block(5,21,-1,biomesoplenty:leaves_1:10)
Block(-9,21,0,biomesoplenty:leaves_1:10)
Block(-8,21,0,biomesoplenty:leaves_1:10)
Block(-2,21,0,biomesoplenty:leaves_1:10)
Block(-1,21,0,biomesoplenty:log_0:7)
Block(0,21,0,biomesoplenty:log_0:7)
Block(-4,21,1,biomesoplenty:leaves_1:10)
Block(-3,21,1,biomesoplenty:leaves_1:10)
Block(-2,21,1,biomesoplenty:leaves_1:10)
Block(-1,21,1,biomesoplenty:leaves_1:10)
Block(-5,21,2,biomesoplenty:leaves_1:10)
Block(-4,21,2,biomesoplenty:leaves_1:10)
Block(-3,21,2,biomesoplenty:leaves_1:10)
Block(-2,21,2,biomesoplenty:leaves_1:10)
Block(-5,21,3,biomesoplenty:leaves_1:10)
Block(-4,21,3,biomesoplenty:leaves_1:10)
Block(-3,21,3,biomesoplenty:leaves_1:10)
Block(-6,21,4,biomesoplenty:leaves_1:10)
Block(-5,21,4,biomesoplenty:leaves_1:10)
Block(-4,21,4,biomesoplenty:leaves_1:10)
Block(-5,21,5,biomesoplenty:leaves_1:10)
Block(-4,22,-10,biomesoplenty:leaves_1:10)
Block(2,22,-10,biomesoplenty:leaves_1:10)
Block(-3,22,-9,biomesoplenty:leaves_1:10)
Block(2,22,-9,biomesoplenty:leaves_1:10)
Block(-3,22,-8,biomesoplenty:leaves_1:10)
Block(1,22,-8,biomesoplenty:leaves_1:10)
Block(-2,22,-7,biomesoplenty:leaves_1:10)
Block(0,22,-7,biomesoplenty:leaves_1:10)
Block(1,22,-7,biomesoplenty:leaves_1:10)
Block(-2,22,-6,biomesoplenty:leaves_1:10)
Block(-1,22,-6,biomesoplenty:leaves_1:10)
Block(5,22,-6,biomesoplenty:leaves_1:10)
Block(-9,22,-5,biomesoplenty:leaves_1:10)
Block(-8,22,-5,biomesoplenty:leaves_1:10)
Block(-2,22,-5,biomesoplenty:leaves_1:10)
Block(-1,22,-5,biomesoplenty:leaves_1:10)
Block(0,22,-5,biomesoplenty:leaves_1:10)
Block(2,22,-5,biomesoplenty:leaves_1:10)
Block(-7,22,-4,biomesoplenty:leaves_1:10)
Block(-1,22,-4,biomesoplenty:leaves_1:10)
Block(3,22,-4,biomesoplenty:leaves_1:10)
Block(-8,22,-3,biomesoplenty:leaves_1:10)
Block(-7,22,-3,biomesoplenty:leaves_1:10)
Block(-6,22,-3,biomesoplenty:leaves_1:10)
Block(-5,22,-3,biomesoplenty:leaves_1:10)
Block(-4,22,-3,biomesoplenty:leaves_1:10)
Block(-3,22,-3,biomesoplenty:leaves_1:10)
Block(-2,22,-3,biomesoplenty:leaves_1:10)
Block(0,22,-3,biomesoplenty:log_0:7)
Block(3,22,-3,biomesoplenty:leaves_1:10)
Block(4,22,-3,biomesoplenty:leaves_1:10)
Block(-7,22,-2,biomesoplenty:leaves_1:10)
Block(-6,22,-2,biomesoplenty:leaves_1:10)
Block(-5,22,-2,biomesoplenty:log_0:7)
Block(-4,22,-2,biomesoplenty:log_0:7)
Block(-3,22,-2,biomesoplenty:log_0:7)
Block(-2,22,-2,biomesoplenty:log_0:7)
Block(-1,22,-2,biomesoplenty:log_0:7)
Block(0,22,-2,biomesoplenty:log_0:7)
Block(1,22,-2,biomesoplenty:log_0:7)
Block(3,22,-2,biomesoplenty:leaves_1:10)
Block(-6,22,-1,biomesoplenty:leaves_1:10)
Block(-5,22,-1,biomesoplenty:leaves_1:10)
Block(-4,22,-1,biomesoplenty:leaves_1:10)
Block(-3,22,-1,biomesoplenty:leaves_1:10)
Block(-2,22,-1,biomesoplenty:log_0:7)
Block(-1,22,-1,biomesoplenty:log_0:7)
Block(0,22,-1,biomesoplenty:log_0:7)
Block(-6,22,0,biomesoplenty:leaves_1:10)
Block(-2,22,0,biomesoplenty:leaves_1:10)
Block(-1,22,0,biomesoplenty:log_0:7)
Block(0,22,0,biomesoplenty:leaves_1:10)
Block(1,22,0,biomesoplenty:leaves_1:10)
Block(2,22,0,biomesoplenty:leaves_1:10)
Block(-7,22,1,biomesoplenty:leaves_1:10)
Block(1,22,1,biomesoplenty:leaves_1:10)
Block(2,22,1,biomesoplenty:leaves_1:10)
Block(3,22,1,biomesoplenty:leaves_1:10)
Block(-3,22,2,biomesoplenty:leaves_1:10)
Block(0,22,2,biomesoplenty:leaves_1:10)
Block(2,22,2,biomesoplenty:leaves_1:10)
Block(0,22,3,biomesoplenty:leaves_1:10)
Block(-1,22,4,biomesoplenty:leaves_1:10)
Block(2,22,4,biomesoplenty:leaves_1:10)
Block(-6,22,5,biomesoplenty:leaves_1:10)
Block(2,22,5,biomesoplenty:leaves_1:10)
Block(-7,22,6,biomesoplenty:leaves_1:10)
Block(-5,23,-5,biomesoplenty:leaves_1:10)
Block(-4,23,-4,biomesoplenty:leaves_1:10)
Block(0,23,-4,biomesoplenty:leaves_1:10)
Block(-4,23,-3,biomesoplenty:leaves_1:10)
Block(-3,23,-3,biomesoplenty:leaves_1:10)
Block(-2,23,-3,biomesoplenty:leaves_1:10)
Block(0,23,-3,biomesoplenty:log_0:7)
Block(2,23,-3,biomesoplenty:leaves_1:10)
Block(-6,23,-2,biomesoplenty:leaves_1:10)
Block(-5,23,-2,biomesoplenty:leaves_1:10)
Block(-4,23,-2,biomesoplenty:leaves_1:10)
Block(-3,23,-2,biomesoplenty:leaves_1:10)
Block(-2,23,-2,biomesoplenty:log_0:7)
Block(-1,23,-2,biomesoplenty:log_0:7)
Block(0,23,-2,biomesoplenty:log_0:7)
Block(1,23,-2,biomesoplenty:log_0:7)
Block(-5,23,-1,biomesoplenty:leaves_1:10)
Block(-4,23,-1,biomesoplenty:leaves_1:10)
Block(-3,23,-1,biomesoplenty:leaves_1:10)
Block(-2,23,-1,biomesoplenty:log_0:7)
Block(-1,23,-1,biomesoplenty:log_0:7)
Block(0,23,-1,biomesoplenty:log_0:7)
Block(1,23,-1,biomesoplenty:log_0:7)
Block(2,23,-1,biomesoplenty:leaves_1:10)
Block(-1,23,0,biomesoplenty:log_0:7)
Block(0,23,0,biomesoplenty:leaves_1:10)
Block(1,23,0,biomesoplenty:log_0:7)
Block(3,23,0,biomesoplenty:leaves_1:10)
Block(4,23,0,biomesoplenty:leaves_1:10)
Block(-1,23,1,biomesoplenty:leaves_1:10)
Block(0,23,1,biomesoplenty:leaves_1:10)
Block(1,23,1,biomesoplenty:log_0:7)
Block(2,23,1,biomesoplenty:log_0:7)
Block(3,23,1,biomesoplenty:leaves_1:10)
Block(1,23,2,biomesoplenty:leaves_1:10)
Block(2,23,2,biomesoplenty:leaves_1:10)
Block(3,23,2,biomesoplenty:leaves_1:10)
Block(4,23,2,biomesoplenty:leaves_1:10)
Block(3,23,3,biomesoplenty:leaves_1:10)
Block(3,23,4,biomesoplenty:leaves_1:10)
Block(-5,24,-3,biomesoplenty:leaves_1:10)
Block(-1,24,-3,biomesoplenty:leaves_1:10)
Block(0,24,-3,biomesoplenty:log_0:7)
Block(-4,24,-2,biomesoplenty:leaves_1:10)
Block(-3,24,-2,biomesoplenty:leaves_1:10)
Block(-2,24,-2,biomesoplenty:log_0:7)
Block(-1,24,-2,biomesoplenty:log_0:7)
Block(0,24,-2,biomesoplenty:log_0:7)
Block(1,24,-2,biomesoplenty:log_0:7)
Block(-1,24,-1,biomesoplenty:log_0:7)
Block(0,24,-1,biomesoplenty:log_0:7)
Block(4,24,-1,biomesoplenty:leaves_1:10)
Block(5,24,-1,biomesoplenty:leaves_1:10)
Block(-5,24,0,biomesoplenty:leaves_1:10)
Block(-4,24,0,biomesoplenty:leaves_1:10)
Block(-1,24,0,biomesoplenty:log_0:7)
Block(1,24,0,biomesoplenty:leaves_1:10)
Block(2,24,0,biomesoplenty:leaves_1:10)
Block(-6,24,1,biomesoplenty:leaves_1:10)
Block(-5,24,1,biomesoplenty:leaves_1:10)
Block(2,24,1,biomesoplenty:leaves_1:10)
Block(3,24,1,biomesoplenty:leaves_1:10)
Block(4,24,2,biomesoplenty:leaves_1:10)
Block(5,24,3,biomesoplenty:leaves_1:10)
Block(-5,24,4,biomesoplenty:leaves_1:10)
Block(-4,24,4,biomesoplenty:leaves_1:10)
Block(4,25,-7,biomesoplenty:leaves_1:10)
Block(2,25,-6,biomesoplenty:leaves_1:10)
Block(4,25,-6,biomesoplenty:leaves_1:10)
Block(-3,25,-5,biomesoplenty:leaves_1:10)
Block(1,25,-5,biomesoplenty:leaves_1:10)
Block(2,25,-5,biomesoplenty:leaves_1:10)
Block(3,25,-5,biomesoplenty:leaves_1:10)
Block(-3,25,-4,biomesoplenty:leaves_1:10)
Block(-2,25,-4,biomesoplenty:leaves_1:10)
Block(1,25,-4,biomesoplenty:leaves_1:10)
Block(2,25,-4,biomesoplenty:leaves_1:10)
Block(3,25,-4,biomesoplenty:leaves_1:10)
Block(4,25,-4,biomesoplenty:leaves_1:10)
Block(5,25,-4,biomesoplenty:leaves_1:10)
Block(-2,25,-3,biomesoplenty:leaves_1:10)
Block(0,25,-3,biomesoplenty:log_0:7)
Block(2,25,-3,biomesoplenty:leaves_1:10)
Block(-2,25,-2,biomesoplenty:log_0:7)
Block(-1,25,-2,biomesoplenty:log_0:7)
Block(0,25,-2,biomesoplenty:log_0:7)
Block(1,25,-2,biomesoplenty:log_0:7)
Block(-2,25,-1,biomesoplenty:leaves_1:10)
Block(-1,25,-1,biomesoplenty:log_0:7)
Block(0,25,-1,biomesoplenty:log_0:7)
Block(-3,25,0,biomesoplenty:leaves_1:10)
Block(-1,25,0,biomesoplenty:leaves_1:10)
Block(0,25,0,biomesoplenty:leaves_1:10)
Block(-4,25,1,biomesoplenty:leaves_1:10)
Block(-2,25,1,biomesoplenty:leaves_1:10)
Block(-3,25,2,biomesoplenty:leaves_1:10)
Block(-1,25,2,biomesoplenty:leaves_1:10)
Block(2,25,2,biomesoplenty:leaves_1:10)
Block(-4,25,3,biomesoplenty:leaves_1:10)
Block(-3,25,3,biomesoplenty:leaves_1:10)
Block(-1,25,3,biomesoplenty:leaves_1:10)
Block(2,26,-8,biomesoplenty:leaves_1:10)
Block(2,26,-7,biomesoplenty:leaves_1:10)
Block(1,26,-6,biomesoplenty:leaves_1:10)
Block(2,26,-6,biomesoplenty:leaves_1:10)
Block(3,26,-6,biomesoplenty:leaves_1:10)
Block(-1,26,-5,biomesoplenty:leaves_1:10)
Block(1,26,-5,biomesoplenty:leaves_1:10)
Block(2,26,-5,biomesoplenty:log_0:7)
Block(0,26,-4,biomesoplenty:leaves_1:10)
Block(1,26,-4,biomesoplenty:log_0:7)
Block(2,26,-4,biomesoplenty:log_0:7)
Block(3,26,-4,biomesoplenty:leaves_1:10)
Block(-2,26,-3,biomesoplenty:leaves_1:10)
Block(1,26,-3,biomesoplenty:log_0:7)
Block(2,26,-3,biomesoplenty:leaves_1:10)
Block(3,26,-3,biomesoplenty:leaves_1:10)
Block(4,26,-3,biomesoplenty:leaves_1:10)
Block(-2,26,-2,biomesoplenty:log_0:7)
Block(-1,26,-2,biomesoplenty:log_0:7)
Block(0,26,-2,biomesoplenty:log_0:7)
Block(1,26,-2,biomesoplenty:log_0:7)
Block(3,26,-2,biomesoplenty:leaves_1:10)
Block(-3,26,-1,biomesoplenty:leaves_1:10)
Block(-2,26,-1,biomesoplenty:leaves_1:10)
Block(-1,26,-1,biomesoplenty:log_0:7)
Block(0,26,-1,biomesoplenty:log_0:7)
Block(1,26,-1,biomesoplenty:leaves_1:10)
Block(4,26,-1,biomesoplenty:leaves_1:10)
Block(-4,26,0,biomesoplenty:leaves_1:10)
Block(-3,26,0,biomesoplenty:leaves_1:10)
Block(-2,26,0,biomesoplenty:log_0:7)
Block(-1,26,0,biomesoplenty:log_0:7)
Block(0,26,0,biomesoplenty:leaves_1:10)
Block(1,26,0,biomesoplenty:leaves_1:10)
Block(2,26,0,biomesoplenty:leaves_1:10)
Block(-5,26,1,biomesoplenty:leaves_1:10)
Block(-4,26,1,biomesoplenty:leaves_1:10)
Block(-3,26,1,biomesoplenty:log_0:7)
Block(-2,26,1,biomesoplenty:log_0:7)
Block(-1,26,1,biomesoplenty:leaves_1:10)
Block(3,26,1,biomesoplenty:leaves_1:10)
Block(-4,26,2,biomesoplenty:leaves_1:10)
Block(-3,26,2,biomesoplenty:leaves_1:10)
Block(-2,26,2,biomesoplenty:leaves_1:10)
Block(2,27,-6,biomesoplenty:leaves_1:10)
Block(1,27,-5,biomesoplenty:leaves_1:10)
Block(2,27,-5,biomesoplenty:leaves_1:10)
Block(1,27,-4,biomesoplenty:leaves_1:10)
Block(2,27,-4,biomesoplenty:leaves_1:10)
Block(3,27,-4,biomesoplenty:leaves_1:10)
Block(-5,27,-3,biomesoplenty:leaves_1:10)
Block(-4,27,-3,biomesoplenty:leaves_1:10)
Block(-1,27,-3,biomesoplenty:leaves_1:10)
Block(2,27,-3,biomesoplenty:leaves_1:10)
Block(-4,27,-2,biomesoplenty:leaves_1:10)
Block(-2,27,-2,biomesoplenty:leaves_1:10)
Block(-1,27,-2,biomesoplenty:log_0:7)
Block(0,27,-2,biomesoplenty:log_0:7)
Block(1,27,-2,biomesoplenty:log_0:7)
Block(-3,27,-1,biomesoplenty:leaves_1:10)
Block(-1,27,-1,biomesoplenty:log_0:7)
Block(1,27,-1,biomesoplenty:leaves_1:10)
Block(-6,27,0,biomesoplenty:leaves_1:10)
Block(-5,27,0,biomesoplenty:leaves_1:10)
Block(-3,27,0,biomesoplenty:leaves_1:10)
Block(-2,27,0,biomesoplenty:leaves_1:10)
Block(-1,27,0,biomesoplenty:leaves_1:10)
Block(-4,27,1,biomesoplenty:leaves_1:10)
Block(-3,27,1,biomesoplenty:leaves_1:10)
Block(-2,27,1,biomesoplenty:leaves_1:10)
Block(1,27,1,biomesoplenty:leaves_1:10)
Block(-3,27,2,biomesoplenty:leaves_1:10)
Block(4,28,-7,biomesoplenty:leaves_1:10)
Block(-1,28,-6,biomesoplenty:leaves_1:10)
Block(3,28,-6,biomesoplenty:leaves_1:10)
Block(4,28,-6,biomesoplenty:leaves_1:10)
Block(-1,28,-5,biomesoplenty:leaves_1:10)
Block(3,28,-5,biomesoplenty:leaves_1:10)
Block(2,28,-4,biomesoplenty:leaves_1:10)
Block(-1,28,-3,biomesoplenty:leaves_1:10)
Block(0,28,-3,biomesoplenty:leaves_1:10)
Block(-1,28,-2,biomesoplenty:log_0:7)
Block(0,28,-2,biomesoplenty:log_0:7)
Block(1,28,-2,biomesoplenty:leaves_1:10)
Block(2,28,-2,biomesoplenty:leaves_1:10)
Block(3,28,-2,biomesoplenty:leaves_1:10)
Block(-2,28,-1,biomesoplenty:leaves_1:10)
Block(-1,28,-1,biomesoplenty:log_0:7)
Block(0,28,-1,biomesoplenty:leaves_1:10)
Block(3,28,-1,biomesoplenty:leaves_1:10)
Block(4,28,-1,biomesoplenty:leaves_1:10)
Block(-3,28,0,biomesoplenty:leaves_1:10)
Block(-1,28,0,biomesoplenty:leaves_1:10)
Block(-4,28,1,biomesoplenty:leaves_1:10)
Block(-2,28,2,biomesoplenty:leaves_1:10)
Block(0,29,-5,biomesoplenty:leaves_1:10)
Block(-5,29,-4,biomesoplenty:leaves_1:10)
Block(-4,29,-4,biomesoplenty:leaves_1:10)
Block(0,29,-4,biomesoplenty:leaves_1:10)
Block(-4,29,-3,biomesoplenty:leaves_1:10)
Block(-1,29,-3,biomesoplenty:leaves_1:10)
Block(0,29,-3,biomesoplenty:log_0:7)
Block(1,29,-3,biomesoplenty:leaves_1:10)
Block(-2,29,-2,biomesoplenty:leaves_1:10)
Block(-1,29,-2,biomesoplenty:log_0:7)
Block(0,29,-2,biomesoplenty:log_0:7)
Block(0,29,-1,biomesoplenty:leaves_1:10)
Block(-2,29,0,biomesoplenty:leaves_1:10)
Block(-1,29,0,biomesoplenty:leaves_1:10)
Block(0,29,0,biomesoplenty:leaves_1:10)
Block(1,29,0,biomesoplenty:leaves_1:10)
Block(-2,29,1,biomesoplenty:leaves_1:10)
Block(2,29,1,biomesoplenty:leaves_1:10)
Block(3,29,1,biomesoplenty:leaves_1:10)
Block(3,29,2,biomesoplenty:leaves_1:10)
Block(4,29,2,biomesoplenty:leaves_1:10)
Block(0,29,3,biomesoplenty:leaves_1:10)
Block(0,29,4,biomesoplenty:leaves_1:10)
Block(2,30,-5,biomesoplenty:leaves_1:10)
Block(1,30,-4,biomesoplenty:leaves_1:10)
Block(2,30,-4,biomesoplenty:leaves_1:10)
Block(-4,30,-3,biomesoplenty:leaves_1:10)
Block(-3,30,-3,biomesoplenty:leaves_1:10)
Block(0,30,-3,biomesoplenty:leaves_1:10)
Block(-3,30,-2,biomesoplenty:leaves_1:10)
Block(-2,30,-2,biomesoplenty:leaves_1:10)
Block(-1,30,-2,biomesoplenty:log_0:7)
Block(0,30,-2,biomesoplenty:log_0:7)
Block(1,30,-2,biomesoplenty:leaves_1:10)
Block(-1,30,-1,biomesoplenty:leaves_1:10)
Block(0,30,-1,biomesoplenty:log_0:7)
Block(1,30,-1,biomesoplenty:leaves_1:10)
Block(-1,30,0,biomesoplenty:leaves_1:10)
Block(0,30,0,biomesoplenty:log_0:7)
Block(1,30,0,biomesoplenty:log_0:7)
Block(2,30,0,biomesoplenty:leaves_1:10)
Block(0,30,1,biomesoplenty:leaves_1:10)
Block(1,30,1,biomesoplenty:leaves_1:10)
Block(2,30,1,biomesoplenty:leaves_1:10)
Block(1,30,2,biomesoplenty:leaves_1:10)
Block(1,30,3,biomesoplenty:leaves_1:10)
Block(-1,31,-3,biomesoplenty:leaves_1:10)
Block(-1,31,-2,biomesoplenty:leaves_1:10)
Block(0,31,-2,biomesoplenty:log_0:7)
Block(-4,31,-1,biomesoplenty:leaves_1:10)
Block(-3,31,-1,biomesoplenty:leaves_1:10)
Block(-1,31,-1,biomesoplenty:leaves_1:10)
Block(0,31,-1,biomesoplenty:leaves_1:10)
Block(0,31,0,biomesoplenty:leaves_1:10)
Block(1,31,0,biomesoplenty:leaves_1:10)
Block(-2,31,1,biomesoplenty:leaves_1:10)
Block(-1,31,1,biomesoplenty:leaves_1:10)
Block(-1,31,2,biomesoplenty:leaves_1:10)
Block(-1,32,-5,biomesoplenty:leaves_1:10)
Block(-1,32,-4,biomesoplenty:leaves_1:10)
Block(0,32,-4,biomesoplenty:leaves_1:10)
Block(-2,32,-3,biomesoplenty:leaves_1:10)
Block(0,32,-3,biomesoplenty:leaves_1:10)
Block(2,32,-3,biomesoplenty:leaves_1:10)
Block(0,32,-2,biomesoplenty:log_0:7)
Block(1,32,-2,biomesoplenty:leaves_1:10)
Block(-4,32,-1,biomesoplenty:leaves_1:10)
Block(-2,32,-1,biomesoplenty:leaves_1:10)
Block(0,32,-1,biomesoplenty:leaves_1:10)
Block(-2,32,0,biomesoplenty:leaves_1:10)
Block(1,32,1,biomesoplenty:leaves_1:10)
Block(-2,33,-4,biomesoplenty:leaves_1:10)
Block(-3,33,-3,biomesoplenty:leaves_1:10)
Block(-2,33,-3,biomesoplenty:leaves_1:10)
Block(0,33,-3,biomesoplenty:leaves_1:10)
Block(-1,33,-2,biomesoplenty:log_0:7)
Block(0,33,-2,biomesoplenty:log_0:7)
Block(1,33,-2,biomesoplenty:leaves_1:10)
Block(-1,33,-1,biomesoplenty:leaves_1:10)
Block(1,33,-1,biomesoplenty:leaves_1:10)
Block(0,33,0,biomesoplenty:leaves_1:10)
Block(-1,34,-3,biomesoplenty:leaves_1:10)
Block(-2,34,-2,biomesoplenty:leaves_1:10)
Block(-1,34,-2,biomesoplenty:log_0:7)
Block(0,34,-2,biomesoplenty:leaves_1:10)
Block(-1,34,-1,biomesoplenty:leaves_1:10)
Block(0,35,-4,biomesoplenty:leaves_1:10)
Block(-2,35,-3,biomesoplenty:leaves_1:10)
Block(-1,35,-3,biomesoplenty:leaves_1:10)
Block(-2,35,-2,biomesoplenty:leaves_1:10)
Block(-1,35,-2,biomesoplenty:log_0:7)
Block(0,35,-2,biomesoplenty:leaves_1:10)
Block(1,35,-2,biomesoplenty:leaves_1:10)
Block(-3,35,-1,biomesoplenty:leaves_1:10)
Block(0,35,-1,biomesoplenty:leaves_1:10)
Block(-2,35,0,biomesoplenty:leaves_1:10)
Block(-1,35,0,biomesoplenty:leaves_1:10)
Block(-1,36,-4,biomesoplenty:leaves_1:10)
Block(0,36,-3,biomesoplenty:leaves_1:10)
Block(-2,36,-2,biomesoplenty:leaves_1:10)
Block(-1,36,-2,biomesoplenty:log_0:7)
Block(0,36,-2,biomesoplenty:leaves_1:10)
Block(-1,36,-1,biomesoplenty:leaves_1:10)
Block(-1,37,-4,biomesoplenty:leaves_1:10)
Block(-2,37,-3,biomesoplenty:leaves_1:10)
Block(-1,37,-3,biomesoplenty:leaves_1:10)
Block(-1,37,-2,biomesoplenty:leaves_1:10)
Block(0,37,-2,biomesoplenty:leaves_1:10)
Block(-1,38,-3,biomesoplenty:leaves_1:10)
Block(-1,38,-2,biomesoplenty:leaves_1:10)
Block(-1,38,-1,biomesoplenty:leaves_1:10)
Block(-2,39,-2,biomesoplenty:leaves_1:10)
Block(-1,39,-2,biomesoplenty:leaves_1:10)
Block(0,39,-2,biomesoplenty:leaves_1:10)
Block(0,40,-3,biomesoplenty:leaves_1:10)
Block(-1,40,-2,biomesoplenty:leaves_1:10)
Block(0,40,-2,biomesoplenty:leaves_1:10)
Block(-1,41,-3,biomesoplenty:leaves_1:10)
Block(0,41,-2,biomesoplenty:leaves_1:10)
Block(0,41,-1,biomesoplenty:leaves_1:10)
Block(-1,42,-2,biomesoplenty:leaves_1:10)
Block(0,42,-2,biomesoplenty:leaves_1:10)
Block(0,43,-2,biomesoplenty:leaves_1:10)
Block(0,44,-2,biomesoplenty:leaves_1:10)
Block(0,45,-2,biomesoplenty:leaves_1:10)

#######################################################################
# +-----------------------------------------------------------------+ #
# |                            BO3 checks                           | #
# +-----------------------------------------------------------------+ #
#######################################################################

# Require a condition at a certain location in order for the BO3 to be spawned.
# BlockCheck(x,y,z,BlockName[,BlockName[,...]]) - one of the blocks must be at the location
# BlockCheckNot(x,y,z,BlockName[,BlockName[,...]]) - all the blocks must not be at the location
# LightCheck(x,y,z,minLightLevel,maxLightLevel) - light must be between min and max (inclusive)

# You can use "Solid" as a BlockName for matching all solid blocks or "All" to match all blocks that aren't air.

# Examples:
#   BlockCheck(0,-1,0,GRASS,DIRT)  Require grass or dirt just below the object
#   BlockCheck(0,-1,0,Solid)       Require any solid block just below the object
#   BlockCheck(0,-1,0,WOOL)        Require any type of wool just below the object
#   BlockCheck(0,-1,0,WOOL:0)      Require white wool just below the object
#   BlockCheckNot(0,-1,0,WOOL:0)   Require that there is no white wool below the object
#   LightCheck(0,0,0,0,1)          Require almost complete darkness just below the object
BlockCheck(0,2,0,AIR)
BlockCheck(2,2,0,AIR)
BlockCheck(-2,2,0,AIR)
BlockCheck(0,2,2,AIR)
BlockCheck(0,2,-2,AIR)
BlockCheck(5,2,0,AIR)
BlockCheck(-5,2,0,AIR)
BlockCheck(0,2,5,AIR)
BlockCheck(0,2,-5,AIR)
BlockCheck(-4,0,-4,Solid)
BlockCheck(-3,0,-4,Solid)
BlockCheck(-2,0,-4,Solid)
BlockCheck(-1,0,-4,Solid)
BlockCheck(0,0,-4,Solid)
BlockCheck(1,0,-4,Solid)
BlockCheck(2,0,-4,Solid)
BlockCheck(3,0,-4,Solid)
BlockCheck(4,0,-4,Solid)
BlockCheck(-4,0,-3,Solid)
BlockCheck(-3,0,-3,Solid)
BlockCheck(-2,0,-3,Solid)
BlockCheck(-1,0,-3,Solid)
BlockCheck(0,0,-3,Solid)
BlockCheck(1,0,-3,Solid)
BlockCheck(2,0,-3,Solid)
BlockCheck(3,0,-3,Solid)
BlockCheck(4,0,-3,Solid)
BlockCheck(-4,0,-2,Solid)
BlockCheck(-3,0,-2,Solid)
BlockCheck(-2,0,-2,Solid)
BlockCheck(-1,0,-2,Solid)
BlockCheck(0,0,-2,Solid)
BlockCheck(1,0,-2,Solid)
BlockCheck(2,0,-2,Solid)
BlockCheck(3,0,-2,Solid)
BlockCheck(4,0,-2,Solid)
BlockCheck(-4,0,-1,Solid)
BlockCheck(-3,0,-1,Solid)
BlockCheck(-2,0,-1,Solid)
BlockCheck(-1,0,-1,Solid)
BlockCheck(0,0,-1,Solid)
BlockCheck(1,0,-1,Solid)
BlockCheck(2,0,-1,Solid)
BlockCheck(3,0,-1,Solid)
BlockCheck(4,0,-1,Solid)
BlockCheck(-4,0,0,Solid)
BlockCheck(-3,0,0,Solid)
BlockCheck(-2,0,0,Solid)
BlockCheck(-1,0,0,Solid)
BlockCheck(0,0,0,Solid)
BlockCheck(1,0,0,Solid)
BlockCheck(2,0,0,Solid)
BlockCheck(3,0,0,Solid)
BlockCheck(4,0,0,Solid)
BlockCheck(-4,0,1,Solid)
BlockCheck(-3,0,1,Solid)
BlockCheck(-2,0,1,Solid)
BlockCheck(-1,0,1,Solid)
BlockCheck(0,0,1,Solid)
BlockCheck(1,0,1,Solid)
BlockCheck(2,0,1,Solid)
BlockCheck(3,0,1,Solid)
BlockCheck(4,0,1,Solid)
BlockCheck(-4,0,2,Solid)
BlockCheck(-3,0,2,Solid)
BlockCheck(-2,0,2,Solid)
BlockCheck(-1,0,2,Solid)
BlockCheck(0,0,2,Solid)
BlockCheck(1,0,2,Solid)
BlockCheck(2,0,2,Solid)
BlockCheck(3,0,2,Solid)
BlockCheck(4,0,2,Solid)
BlockCheck(-4,0,3,Solid)
BlockCheck(-3,0,3,Solid)
BlockCheck(-2,0,3,Solid)
BlockCheck(-1,0,3,Solid)
BlockCheck(0,0,3,Solid)
BlockCheck(1,0,3,Solid)
BlockCheck(2,0,3,Solid)
BlockCheck(3,0,3,Solid)
BlockCheck(4,0,3,Solid)
BlockCheck(-4,0,4,Solid)
BlockCheck(-3,0,4,Solid)
BlockCheck(-2,0,4,Solid)
BlockCheck(-1,0,4,Solid)
BlockCheck(0,0,4,Solid)
BlockCheck(1,0,4,Solid)
BlockCheck(2,0,4,Solid)
BlockCheck(3,0,4,Solid)
BlockCheck(4,0,4,Solid)

#######################################################################
# +-----------------------------------------------------------------+ #
# |                             Branches                            | #
# +-----------------------------------------------------------------+ #
#######################################################################

# Branches are child-BO3's that spawn if this BO3 is configured to spawn as a
# CustomStructure resource in a biome config. Branches can have branches,
# making complex structures possible. See the wiki for more details.

# Regular Branches spawn each branch with an independent chance of spawning.
# Branch(x,y,z,branchName,rotation,chance[,anotherBranchName,rotation,chance[,...]][IndividualChance])
# branchName - name of the object to spawn.
# rotation - NORTH, SOUTH, EAST or WEST.
# IndividualChance - The chance each branch has to spawn, assumed to be 100 when left blank
# isRequiredBranch - If this is set to true then at least one of the branches in this BO3 must spawn at these x,y,z coordinates. If no branch can spawn there then this BO3 fails to spawn and its branch is rolled back.
# isRequiredBranch:true branches must spawn or the current branch is rolled back entirely. This is useful for grouping BO3's that must spawn together, for instance a single room made of multiple BO3's/branches.
# If all parts of the room are connected together via isRequiredBranch:true branches then either the entire room will spawns or no part of it will spawn.
# *Note: When isRequiredBranch:true only one BO3 can be added per Branch() and it will automatically have a rarity of 100.0.
# isRequiredBranch:false branches are used to make optional parts of structures, for instance the middle section of a tunnel that has a beginning, middle and end BO3/branch and can have a variable length by repeating the middle BO3/branch.
# By making the start and end branches isRequiredBranch:true and the middle branch isRequiredbranch:false you can make it so that either:
# A. A tunnel spawns with at least a beginning and end branch
# B. A tunnel spawns with a beginning and end branch and as many middle branches as will fit in the available space.
# C. No tunnel spawns at all because there wasn't enough space to spawn at least a beginning and end branch.
# branchDepth - When creating a chain of branches that contains optional (isRequiredBranch:false) branches branch depth is configured for the first BO3 in the chain to determine the maximum length of the chain.
# branchDepth - 1 is inherited by each isRequiredBranch:false branch in the chain. When branchDepth is zero isRequiredBranch:false branches cannot spawn and the chain ends. In the case of the tunnel this means the last middle branch would be
# rolled back and an IsRequiredBranch:true end branch could be spawned in its place to make sure the tunnel has a proper ending.
# Instead of inheriting branchDepth - 1 from the parent branchDepth can be overridden by child branches if it is set higher than 0 (the default value).
# isRequiredBranch:true branches do inherit branchDepth and pass it on to their own branches, however they cannot be prevented from spawning by it and also don't subtract 1 from branchDepth when inheriting it.

# Weighted Branches spawn branches with a dependent chance of spawning.
# WeightedBranch(x,y,z,branchName,rotation,chance[,anotherBranchName,rotation,chance[,...]][MaxChanceOutOf])
# *Note: isRequiredBranch must be set to false. It is not possible to use isRequiredBranch:true with WeightedBranch() since isRequired:true branches must spawn and automatically have a rarity of 100.0.
# MaxChanceOutOf - The chance all branches have to spawn out of, assumed to be 100 when left blank

#######################################################################
# +-----------------------------------------------------------------+ #
# |                             Entities                            | #
# +-----------------------------------------------------------------+ #
#######################################################################

# Forge only (this may have changed, check for updates).
# An EntityFunction spawns an entity instead of a block. The entity is spawned only once when the BO3 is spawned.
# Entities are persistent by default so they don't de-spawn when no player is near, they are only unloaded.
# Usage: Entity(x,y,z,entityName,groupSize,NameTagOrNBTFileName) or Entity(x,y,z,mobName,groupSize)
# Use /otg entities to get a list of entities that can be used as entityName, this includes entities added by other mods and non-living entities.
# NameTagOrNBTFileName can be either a nametag for the mob or an .txt file with nbt data (such as myentityinfo.txt).
# In the text file you can use the same mob spawning parameters used with the /summon command to equip the
# entity and give it custom attributes etc. You can copy the DATA part of a summon command including surrounding 
# curly braces to a .txt file, for instance for: "/summon Skeleton x y z {DATA}"
# *Note: Unlike Block(), for Entity() .nbt files don't work, only .txt files work.

#######################################################################
# +-----------------------------------------------------------------+ #
# |                            Particles                            | #
# +-----------------------------------------------------------------+ #
#######################################################################

# Forge only (this may have changed, check for updates).
# Creates an invisible particle spawner at the given location that spawns particles every x milliseconds.
# Usage: Particle(x,y,z,particleName,interval,velocityX,velocityY,velocityZ)
# velocityX, velocityY and velocityZ are optional.
# Only vanilla particle names can be used, for 1.11.2 these are;
# explode, largeexplode, hugeexplosion, fireworksSpark, bubble, splash, wake, suspended
# depthsuspend, crit, magicCrit, smoke, largesmoke, spell, instantSpell, mobSpell
# mobSpellAmbient, witchMagic, dripWater, dripLava, angryVillager, happyVillager
# townaura, note, portal, enchantmenttable, flame, lava, footstep, cloud, reddust
# snowballpoof,  snowshovel, slime, heart, barrier, iconcrack, blockcrack, blockdust
# droplet, take, mobappearance, dragonbreath, endRod, damageIndicator, sweepAttack
# fallingdust, totem, spit.
# velocityX,velocityY,velocityZ - Spawn the enemy with the given velocity. If this is not filled in then a small random velocity is applied.

#######################################################################
