
#######################################################################
# +-----------------------------------------------------------------+ #
# |                            BO3 object                           | #
# +-----------------------------------------------------------------+ #
#######################################################################

# This is the config file of a custom object.
# If you add this object correctly to your BiomeConfigs, it will spawn in the world.

# This is the creator of this BO3 object
Author: Unknown

# A short description of this BO3 object
Description: This BO3 was converted from a schematic using OTGEdit. The author and description information of the schematic could not be found. If you know who the author of the schematic is then please add this information.

# The BO3 version, don't change this! It can be used by external applications to do a version check.
Version: 3

# The settings mode, WriteAll, WriteWithoutComments or WriteDisable. See WorldConfig.
SettingsMode: WriteAll


#######################################################################
# +-----------------------------------------------------------------+ #
# |                          Main settings                          | #
# +-----------------------------------------------------------------+ #
#######################################################################

# This needs to be set to true to spawn the object in the Tree and Sapling resources.
Tree: true

# The frequency of the BO3 from 1 to 200. Tries this many times to spawn this BO3 when using the CustomObject(...) resource.
# Ignored by Tree(..), Sapling(..) and CustomStructure(..)
Frequency: 40

# The rarity of the BO3 from 0 to 100. Each spawn attempt has rarity% chance to succeed when using the CustomObject(...) resource.
# Ignored by Tree(..), Sapling(..) and CustomStructure(..)
Rarity: 100.0

# If you set this to true, the BO3 will be placed with a random rotation.
RotateRandomly: true

# The spawn height of the BO3: randomY, highestBlock or highestSolidBlock.
SpawnHeight: randomY

# The offset from the spawn height to spawn this BO3
# Ex. SpawnHeight = highestSolidBlock, SpawnHeightOffset = 3; This object will spawn 3 blocks above the highest solid block
SpawnHeightOffset: 0

# A random amount to offset the spawn location from the spawn offset height
# Ex. SpawnHeightOffset = 3, SpawnHeightVariance = 3; This object will spawn 3 to 6 blocks above the original spot it would have spawned
SpawnHeightVariance: 0

##############################
# Height Limits for the BO3. #
##############################

# When in randomY mode used as the minimum Y or in atMinY mode as the actual Y to spawn this BO3 at.
MinHeight: 92

# When in randomY mode used as the maximum Y to spawn this BO3 at.
MaxHeight: 256

######################
# Extrusion settings #
######################

# The style of extrusion you wish to use - BottomDown, TopUp, None (Default)
ExtrudeMode: None

# The blocks to extrude your BO3 through
ExtrudeThroughBlocks: AIR

# Objects can have other objects attacthed to it: branches. Branches can also
# have branches attached to it, which can also have branches, etc. This is the
# maximum branch depth for this objects.
MaxBranchDepth: 10

# When spawned with the UseWorld keyword, this BO3 should NOT spawn in the following biomes.
# If you write the BO3 name directly in the BiomeConfigs, this will be ignored.
ExcludedBiomes: All


#######################################################################
# +-----------------------------------------------------------------+ #
# |                      Source block settings                      | #
# +-----------------------------------------------------------------+ #
#######################################################################

# The block(s) the BO3 should spawn in.
SourceBlocks: AIR,GRASS,DIRT

# The maximum percentage of the BO3 that can be outside the SourceBlock.
# The BO3 won't be placed on a location with more blocks outside the SourceBlock than this percentage.
MaxPercentageOutsideSourceBlock: 100

# What to do when a block is about to be placed outside the SourceBlock? (dontPlace, placeAnyway)
OutsideSourceBlock: placeAnyway

# OTG+ settings #
# Legacy setting, rename this file to .BO4 instead. Set this to true to enable the advanced customstructure features of OTG+.
IsOTGPlus: false


#######################################################################
# +-----------------------------------------------------------------+ #
# |                              Blocks                             | #
# +-----------------------------------------------------------------+ #
#######################################################################

# All the blocks used in the BO3 are listed here. Possible blocks:
# Block(x,y,z,id[.data][,nbtfile.nbt)
# RandomBlock(x,y,z,id[:data][,nbtfile.nbt],chance[,id[:data][,nbtfile.nbt],chance[,...]])
#  So RandomBlock(0,0,0,CHEST,chest.nbt,50,CHEST,anotherchest.nbt,100) will spawn a chest at
#  the BO3 origin, and give it a 50% chance to have the contents of chest.nbt, or, if that
#  fails, a 100% percent chance to have the contents of anotherchest.nbt.
# *Note: Unlike Entity() and Spawner(), for Block() .txt files don't work, only .nbt files work.
# MinecraftObject(x,y,z,name) (TODO: This may not work anymore and needs to be tested.
#  Spawns an object in the Mojang NBT structure format. For example, 
#  MinecraftObject(0,0,0,minecraft:igloo/igloo_bottom)
#  spawns the bottom part of an igloo.
Block(-7,24,4,LEAVES_2:1)
Block(-7,25,4,LEAVES_2:1)
Block(-7,25,5,LEAVES_2:1)
Block(-7,26,4,LEAVES_2:1)
Block(-7,26,5,LEAVES_2:1)
Block(-7,26,6,LEAVES_2:1)
Block(-6,23,4,LEAVES_2:1)
Block(-6,23,5,LEAVES_2:1)
Block(-6,24,0,LEAVES_2:1)
Block(-6,24,4,LEAVES_2:1)
Block(-6,24,5,LEAVES_2:1)
Block(-6,24,6,LEAVES_2:1)
Block(-6,24,9,LEAVES_2:1)
Block(-6,25,0,LEAVES_2:1)
Block(-6,25,1,LEAVES_2:1)
Block(-6,25,3,LEAVES_2:1)
Block(-6,25,4,LEAVES_2:1)
Block(-6,25,5,LOG_2:1)
Block(-6,25,6,LEAVES_2:1)
Block(-6,25,9,LEAVES_2:1)
Block(-6,25,10,LEAVES_2:1)
Block(-6,26,-1,LEAVES_2:1)
Block(-6,26,0,LEAVES_2:1)
Block(-6,26,3,LEAVES_2:1)
Block(-6,26,4,LEAVES_2:1)
Block(-6,26,5,LEAVES_2:1)
Block(-6,26,8,LEAVES_2:1)
Block(-6,26,9,LEAVES_2:1)
Block(-6,27,5,LEAVES_2:1)
Block(-6,27,6,LEAVES_2:1)
Block(-6,28,4,LEAVES_2:1)
Block(-5,23,-2,LEAVES_2:1)
Block(-5,23,0,LEAVES_2:1)
Block(-5,23,4,LEAVES_2:1)
Block(-5,23,5,LEAVES_2:1)
Block(-5,23,6,LEAVES_2:1)
Block(-5,23,8,LEAVES_2:1)
Block(-5,23,9,LEAVES_2:1)
Block(-5,24,-3,LEAVES_2:1)
Block(-5,24,-2,LEAVES_2:1)
Block(-5,24,-1,LEAVES_2:1)
Block(-5,24,1,LEAVES_2:1)
Block(-5,24,2,LEAVES_2:1)
Block(-5,24,3,LEAVES_2:1)
Block(-5,24,4,LEAVES_2:1)
Block(-5,24,5,LEAVES_2:1)
Block(-5,24,7,LEAVES_2:1)
Block(-5,24,9,LEAVES_2:1)
Block(-5,25,-2,LEAVES_2:1)
Block(-5,25,-1,LEAVES_2:1)
Block(-5,25,0,LEAVES_2:1)
Block(-5,25,2,LEAVES_2:1)
Block(-5,25,3,LEAVES_2:1)
Block(-5,25,4,LOG_2:1)
Block(-5,25,5,LOG_2:1)
Block(-5,25,6,LEAVES_2:1)
Block(-5,25,7,LEAVES_2:1)
Block(-5,25,9,LEAVES_2:1)
Block(-5,25,10,LEAVES_2:1)
Block(-5,25,11,LEAVES_2:1)
Block(-5,26,-2,LEAVES_2:1)
Block(-5,26,-1,LEAVES_2:1)
Block(-5,26,0,LEAVES_2:1)
Block(-5,26,1,LEAVES_2:1)
Block(-5,26,2,LEAVES_2:1)
Block(-5,26,3,LEAVES_2:1)
Block(-5,26,4,LEAVES_2:1)
Block(-5,26,5,LEAVES_2:1)
Block(-5,26,6,LEAVES_2:1)
Block(-5,26,7,LEAVES_2:1)
Block(-5,26,9,LEAVES_2:1)
Block(-5,27,0,LEAVES_2:1)
Block(-5,27,1,LEAVES_2:1)
Block(-5,27,3,LEAVES_2:1)
Block(-5,27,4,LEAVES_2:1)
Block(-5,27,5,LEAVES_2:1)
Block(-5,27,6,LEAVES_2:1)
Block(-5,27,7,LEAVES_2:1)
Block(-5,27,8,LEAVES_2:1)
Block(-5,28,4,LEAVES_2:1)
Block(-5,28,5,LEAVES_2:1)
Block(-5,28,7,LEAVES_2:1)
Block(-5,28,8,LEAVES_2:1)
Block(-5,28,9,LEAVES_2:1)
Block(-5,29,6,LEAVES_2:1)
Block(-5,29,8,LEAVES_2:1)
Block(-5,29,9,LEAVES_2:1)
Block(-5,31,6,LEAVES_2:1)
Block(-5,32,4,LEAVES_2:1)
Block(-5,32,5,LEAVES_2:1)
Block(-5,32,6,LEAVES_2:1)
Block(-5,33,5,LEAVES_2:1)
Block(-5,33,6,LEAVES_2:1)
Block(-4,23,-3,LEAVES_2:1)
Block(-4,23,-2,LEAVES_2:1)
Block(-4,23,-1,LEAVES_2:1)
Block(-4,23,0,LEAVES_2:1)
Block(-4,23,1,LEAVES_2:1)
Block(-4,23,2,LEAVES_2:1)
Block(-4,23,4,LEAVES_2:1)
Block(-4,23,6,LEAVES_2:1)
Block(-4,23,9,LEAVES_2:1)
Block(-4,23,10,LEAVES_2:1)
Block(-4,24,-3,LOG_2:1)
Block(-4,24,-2,LEAVES_2:1)
Block(-4,24,-1,LOG_2:1)
Block(-4,24,0,LEAVES_2:1)
Block(-4,24,1,LEAVES_2:1)
Block(-4,24,2,LEAVES_2:1)
Block(-4,24,5,LEAVES_2:1)
Block(-4,24,9,LEAVES_2:1)
Block(-4,24,10,LEAVES_2:1)
Block(-4,24,11,LEAVES_2:1)
Block(-4,25,-3,LEAVES_2:1)
Block(-4,25,-2,LEAVES_2:1)
Block(-4,25,-1,LOG_2:1)
Block(-4,25,0,LOG_2:1)
Block(-4,25,1,LEAVES_2:1)
Block(-4,25,2,LEAVES_2:1)
Block(-4,25,4,LOG_2:1)
Block(-4,25,5,LEAVES_2:1)
Block(-4,25,6,LEAVES_2:1)
Block(-4,25,7,LEAVES_2:1)
Block(-4,25,8,LEAVES_2:1)
Block(-4,25,9,LOG_2:1)
Block(-4,25,10,LOG_2:1)
Block(-4,25,11,LEAVES_2:1)
Block(-4,26,-1,LEAVES_2:1)
Block(-4,26,0,LEAVES_2:1)
Block(-4,26,1,LEAVES_2:1)
Block(-4,26,2,LEAVES_2:1)
Block(-4,26,3,LEAVES_2:1)
Block(-4,26,4,LOG_2:1)
Block(-4,26,5,LEAVES_2:1)
Block(-4,26,6,LEAVES_2:1)
Block(-4,26,7,LEAVES_2:1)
Block(-4,26,8,LEAVES_2:1)
Block(-4,26,9,LEAVES_2:1)
Block(-4,26,10,LEAVES_2:1)
Block(-4,26,11,LEAVES_2:1)
Block(-4,27,-1,LEAVES_2:1)
Block(-4,27,0,LEAVES_2:1)
Block(-4,27,1,LEAVES_2:1)
Block(-4,27,2,LEAVES_2:1)
Block(-4,27,4,LEAVES_2:1)
Block(-4,27,5,LEAVES_2:1)
Block(-4,27,6,LEAVES_2:1)
Block(-4,27,7,LEAVES_2:1)
Block(-4,27,8,LOG_2:1)
Block(-4,27,9,LEAVES_2:1)
Block(-4,27,10,LEAVES_2:1)
Block(-4,28,-1,LEAVES_2:1)
Block(-4,28,0,LEAVES_2:1)
Block(-4,28,1,LEAVES_2:1)
Block(-4,28,5,LEAVES_2:1)
Block(-4,28,6,LEAVES_2:1)
Block(-4,28,7,LEAVES_2:1)
Block(-4,28,8,LOG_2:1)
Block(-4,28,9,LEAVES_2:1)
Block(-4,28,10,LEAVES_2:1)
Block(-4,29,-1,LEAVES_2:1)
Block(-4,29,0,LEAVES_2:1)
Block(-4,29,1,LEAVES_2:1)
Block(-4,29,4,LEAVES_2:1)
Block(-4,29,6,LEAVES_2:1)
Block(-4,29,8,LEAVES_2:1)
Block(-4,29,10,LEAVES_2:1)
Block(-4,30,0,LEAVES_2:1)
Block(-4,30,4,LEAVES_2:1)
Block(-4,30,5,LEAVES_2:1)
Block(-4,30,6,LEAVES_2:1)
Block(-4,30,7,LEAVES_2:1)
Block(-4,30,8,LEAVES_2:1)
Block(-4,31,5,LEAVES_2:1)
Block(-4,31,7,LEAVES_2:1)
Block(-4,32,5,LEAVES_2:1)
Block(-4,32,7,LEAVES_2:1)
Block(-4,33,3,LEAVES_2:1)
Block(-4,33,4,LEAVES_2:1)
Block(-4,33,5,LEAVES_2:1)
Block(-4,33,7,LEAVES_2:1)
Block(-4,34,4,LEAVES_2:1)
Block(-4,34,5,LEAVES_2:1)
Block(-4,36,3,LEAVES_2:1)
Block(-4,37,1,LEAVES_2:1)
Block(-4,37,2,LEAVES_2:1)
Block(-4,37,3,LEAVES_2:1)
Block(-4,37,4,LEAVES_2:1)
Block(-4,38,1,LEAVES_2:1)
Block(-4,38,2,LEAVES_2:1)
Block(-4,38,4,LEAVES_2:1)
Block(-4,39,2,LEAVES_2:1)
Block(-4,39,3,LEAVES_2:1)
Block(-4,41,2,LEAVES_2:1)
Block(-4,41,3,LEAVES_2:1)
Block(-4,42,2,LEAVES_2:1)
Block(-4,42,3,LEAVES_2:1)
Block(-4,43,2,LEAVES_2:1)
Block(-3,22,0,LEAVES_2:1)
Block(-3,22,1,LEAVES_2:1)
Block(-3,23,-5,LEAVES_2:1)
Block(-3,23,-4,LEAVES_2:1)
Block(-3,23,-2,LEAVES_2:1)
Block(-3,23,-1,LEAVES_2:1)
Block(-3,23,0,LEAVES_2:1)
Block(-3,23,1,LEAVES_2:1)
Block(-3,23,3,LEAVES_2:1)
Block(-3,23,8,LEAVES_2:1)
Block(-3,23,9,LEAVES_2:1)
Block(-3,24,-5,LEAVES_2:1)
Block(-3,24,-4,LEAVES_2:1)
Block(-3,24,-3,LEAVES_2:1)
Block(-3,24,-2,LEAVES_2:1)
Block(-3,24,-1,LEAVES_2:1)
Block(-3,24,0,LEAVES_2:1)
Block(-3,24,1,LEAVES_2:1)
Block(-3,24,2,LEAVES_2:1)
Block(-3,24,3,LEAVES_2:1)
Block(-3,24,4,LEAVES_2:1)
Block(-3,24,5,LEAVES_2:1)
Block(-3,24,6,LEAVES_2:1)
Block(-3,24,7,LEAVES_2:1)
Block(-3,24,8,LEAVES_2:1)
Block(-3,24,9,LEAVES_2:1)
Block(-3,24,10,LEAVES_2:1)
Block(-3,24,11,LEAVES_2:1)
Block(-3,25,-4,LEAVES_2:1)
Block(-3,25,-3,LEAVES_2:1)
Block(-3,25,-2,LEAVES_2:1)
Block(-3,25,-1,LEAVES_2:1)
Block(-3,25,0,LOG_2:1)
Block(-3,25,1,LEAVES_2:1)
Block(-3,25,2,LEAVES_2:1)
Block(-3,25,3,LEAVES_2:1)
Block(-3,25,4,LEAVES_2:1)
Block(-3,25,5,LEAVES_2:1)
Block(-3,25,6,LEAVES_2:1)
Block(-3,25,7,LEAVES_2:1)
Block(-3,25,8,LEAVES_2:1)
Block(-3,25,9,LOG_2:1)
Block(-3,25,10,LEAVES_2:1)
Block(-3,25,11,LEAVES_2:1)
Block(-3,26,-2,LEAVES_2:1)
Block(-3,26,-1,LEAVES_2:1)
Block(-3,26,0,LOG_2:1)
Block(-3,26,1,LEAVES_2:1)
Block(-3,26,3,LEAVES_2:1)
Block(-3,26,4,LEAVES_2:1)
Block(-3,26,5,LEAVES_2:1)
Block(-3,26,6,LEAVES_2:1)
Block(-3,26,7,LEAVES_2:1)
Block(-3,26,8,LEAVES_2:1)
Block(-3,26,9,LOG_2:1)
Block(-3,26,10,LEAVES_2:1)
Block(-3,27,-1,LEAVES_2:1)
Block(-3,27,0,LEAVES_2:1)
Block(-3,27,1,LEAVES_2:1)
Block(-3,27,2,LEAVES_2:1)
Block(-3,27,3,LEAVES_2:1)
Block(-3,27,4,LOG_2:1)
Block(-3,27,5,LOG_2:1)
Block(-3,27,6,LEAVES_2:1)
Block(-3,27,7,LEAVES_2:1)
Block(-3,27,8,LOG_2:1)
Block(-3,27,9,LOG_2:1)
Block(-3,27,10,LEAVES_2:1)
Block(-3,27,11,LEAVES_2:1)
Block(-3,28,-1,LEAVES_2:1)
Block(-3,28,0,LEAVES_2:1)
Block(-3,28,2,LEAVES_2:1)
Block(-3,28,3,LEAVES_2:1)
Block(-3,28,4,LEAVES_2:1)
Block(-3,28,5,LOG_2:1)
Block(-3,28,6,LEAVES_2:1)
Block(-3,28,7,LEAVES_2:1)
Block(-3,28,8,LOG_2:1)
Block(-3,28,9,LEAVES_2:1)
Block(-3,28,10,LEAVES_2:1)
Block(-3,29,-2,LEAVES_2:1)
Block(-3,29,-1,LEAVES_2:1)
Block(-3,29,0,LEAVES_2:1)
Block(-3,29,1,LEAVES_2:1)
Block(-3,29,4,LEAVES_2:1)
Block(-3,29,5,LOG_2:1)
Block(-3,29,6,LEAVES_2:1)
Block(-3,29,7,LEAVES_2:1)
Block(-3,29,8,LEAVES_2:1)
Block(-3,29,9,LEAVES_2:1)
Block(-3,30,-1,LEAVES_2:1)
Block(-3,30,0,LEAVES_2:1)
Block(-3,30,4,LEAVES_2:1)
Block(-3,30,5,LEAVES_2:1)
Block(-3,30,6,LEAVES_2:1)
Block(-3,30,8,LEAVES_2:1)
Block(-3,30,9,LEAVES_2:1)
Block(-3,31,-1,LEAVES_2:1)
Block(-3,31,0,LEAVES_2:1)
Block(-3,31,3,LEAVES_2:1)
Block(-3,31,4,LEAVES_2:1)
Block(-3,31,5,LEAVES_2:1)
Block(-3,31,6,LEAVES_2:1)
Block(-3,31,7,LEAVES_2:1)
Block(-3,31,8,LEAVES_2:1)
Block(-3,31,9,LEAVES_2:1)
Block(-3,32,-1,LEAVES_2:1)
Block(-3,32,3,LEAVES_2:1)
Block(-3,32,4,LEAVES_2:1)
Block(-3,32,5,LOG_2:1)
Block(-3,32,7,LEAVES_2:1)
Block(-3,32,8,LEAVES_2:1)
Block(-3,33,4,LEAVES_2:1)
Block(-3,33,5,LEAVES_2:1)
Block(-3,33,6,LEAVES_2:1)
Block(-3,33,7,LEAVES_2:1)
Block(-3,34,4,LEAVES_2:1)
Block(-3,34,5,LEAVES_2:1)
Block(-3,34,6,LEAVES_2:1)
Block(-3,34,7,LEAVES_2:1)
Block(-3,35,2,LEAVES_2:1)
Block(-3,35,4,LEAVES_2:1)
Block(-3,36,1,LEAVES_2:1)
Block(-3,36,2,LEAVES_2:1)
Block(-3,36,3,LEAVES_2:1)
Block(-3,36,7,LEAVES_2:1)
Block(-3,37,0,LEAVES_2:1)
Block(-3,37,1,LEAVES_2:1)
Block(-3,37,2,LOG_2:1)
Block(-3,37,3,LEAVES_2:1)
Block(-3,37,4,LEAVES_2:1)
Block(-3,37,5,LEAVES_2:1)
Block(-3,37,6,LEAVES_2:1)
Block(-3,38,0,LEAVES_2:1)
Block(-3,38,1,LEAVES_2:1)
Block(-3,38,2,LEAVES_2:1)
Block(-3,38,3,LEAVES_2:1)
Block(-3,38,4,LEAVES_2:1)
Block(-3,38,5,LEAVES_2:1)
Block(-3,39,0,LEAVES_2:1)
Block(-3,39,2,LEAVES_2:1)
Block(-3,39,3,LEAVES_2:1)
Block(-3,39,4,LEAVES_2:1)
Block(-3,40,-2,LEAVES_2:1)
Block(-3,40,0,LEAVES_2:1)
Block(-3,40,2,LEAVES_2:1)
Block(-3,41,-2,LEAVES_2:1)
Block(-3,41,-1,LEAVES_2:1)
Block(-3,41,3,LEAVES_2:1)
Block(-3,42,-2,LEAVES_2:1)
Block(-3,42,-1,LEAVES_2:1)
Block(-3,42,2,LEAVES_2:1)
Block(-3,42,3,LEAVES_2:1)
Block(-3,42,4,LEAVES_2:1)
Block(-3,43,1,LEAVES_2:1)
Block(-3,43,2,LEAVES_2:1)
Block(-3,43,3,LEAVES_2:1)
Block(-3,43,4,LEAVES_2:1)
Block(-3,44,2,LEAVES_2:1)
Block(-3,45,0,LEAVES_2:1)
Block(-3,46,0,LEAVES_2:1)
Block(-3,46,1,LEAVES_2:1)
Block(-3,46,4,LEAVES_2:1)
Block(-3,47,2,LEAVES_2:1)
Block(-3,47,3,LEAVES_2:1)
Block(-3,47,4,LEAVES_2:1)
Block(-3,48,2,LEAVES_2:1)
Block(-3,48,3,LEAVES_2:1)
Block(-3,49,1,LEAVES_2:1)
Block(-3,49,6,LEAVES_2:1)
Block(-3,49,7,LEAVES_2:1)
Block(-3,50,7,LEAVES_2:1)
Block(-3,51,6,LEAVES_2:1)
Block(-2,23,-6,LEAVES_2:1)
Block(-2,23,-1,LEAVES_2:1)
Block(-2,23,0,LEAVES_2:1)
Block(-2,23,1,LEAVES_2:1)
Block(-2,24,-6,LEAVES_2:1)
Block(-2,24,-5,LOG_2:1)
Block(-2,24,-4,LOG_2:1)
Block(-2,24,-3,LEAVES_2:1)
Block(-2,24,-2,LEAVES_2:1)
Block(-2,24,-1,LEAVES_2:1)
Block(-2,24,0,LEAVES_2:1)
Block(-2,24,1,LEAVES_2:1)
Block(-2,24,2,LEAVES_2:1)
Block(-2,24,3,LEAVES_2:1)
Block(-2,24,4,LEAVES_2:1)
Block(-2,24,5,LEAVES_2:1)
Block(-2,24,9,LEAVES_2:1)
Block(-2,25,-4,LEAVES_2:1)
Block(-2,25,-3,LEAVES_2:1)
Block(-2,25,-2,LEAVES_2:1)
Block(-2,25,0,LEAVES_2:1)
Block(-2,25,1,LEAVES_2:1)
Block(-2,25,2,LEAVES_2:1)
Block(-2,25,3,LEAVES_2:1)
Block(-2,25,5,LEAVES_2:1)
Block(-2,25,6,LEAVES_2:1)
Block(-2,25,7,LEAVES_2:1)
Block(-2,25,8,LEAVES_2:1)
Block(-2,25,9,LEAVES_2:1)
Block(-2,25,10,LEAVES_2:1)
Block(-2,26,-4,LEAVES_2:1)
Block(-2,26,-3,LEAVES_2:1)
Block(-2,26,-2,LEAVES_2:1)
Block(-2,26,0,LOG_2:1)
Block(-2,26,1,LOG_2:1)
Block(-2,26,2,LEAVES_2:1)
Block(-2,26,3,LEAVES_2:1)
Block(-2,26,4,LEAVES_2:1)
Block(-2,26,5,LOG_2:1)
Block(-2,26,6,LEAVES_2:1)
Block(-2,26,7,LEAVES_2:1)
Block(-2,26,8,LEAVES_2:1)
Block(-2,26,9,LOG_2:1)
Block(-2,26,10,LEAVES_2:1)
Block(-2,26,11,LEAVES_2:1)
Block(-2,27,-3,LEAVES_2:1)
Block(-2,27,-2,LEAVES_2:1)
Block(-2,27,0,LOG_2:1)
Block(-2,27,1,LEAVES_2:1)
Block(-2,27,2,LEAVES_2:1)
Block(-2,27,3,LEAVES_2:1)
Block(-2,27,4,LEAVES_2:1)
Block(-2,27,5,LOG_2:1)
Block(-2,27,6,LEAVES_2:1)
Block(-2,27,7,LEAVES_2:1)
Block(-2,27,8,LEAVES_2:1)
Block(-2,27,9,LOG_2:1)
Block(-2,27,10,LEAVES_2:1)
Block(-2,27,11,LEAVES_2:1)
Block(-2,28,-1,LEAVES_2:1)
Block(-2,28,0,LOG_2:1)
Block(-2,28,1,LEAVES_2:1)
Block(-2,28,2,LEAVES_2:1)
Block(-2,28,3,LEAVES_2:1)
Block(-2,28,4,LEAVES_2:1)
Block(-2,28,5,LEAVES_2:1)
Block(-2,28,6,LEAVES_2:1)
Block(-2,28,7,LEAVES_2:1)
Block(-2,28,8,LEAVES_2:1)
Block(-2,28,9,LEAVES_2:1)
Block(-2,28,10,LEAVES_2:1)
Block(-2,29,-3,LEAVES_2:1)
Block(-2,29,-2,LEAVES_2:1)
Block(-2,29,-1,LEAVES_2:1)
Block(-2,29,0,LOG_2:1)
Block(-2,29,1,LEAVES_2:1)
Block(-2,29,2,LEAVES_2:1)
Block(-2,29,8,LEAVES_2:1)
Block(-2,29,9,LEAVES_2:1)
Block(-2,29,10,LEAVES_2:1)
Block(-2,29,11,LEAVES_2:1)
Block(-2,30,-1,LEAVES_2:1)
Block(-2,30,0,LEAVES_2:1)
Block(-2,30,1,LEAVES_2:1)
Block(-2,30,2,LEAVES_2:1)
Block(-2,30,3,LEAVES_2:1)
Block(-2,30,4,LEAVES_2:1)
Block(-2,30,5,LEAVES_2:1)
Block(-2,30,8,LEAVES_2:1)
Block(-2,30,9,LEAVES_2:1)
Block(-2,30,10,LEAVES_2:1)
Block(-2,31,-2,LEAVES_2:1)
Block(-2,31,-1,LEAVES_2:1)
Block(-2,31,0,LEAVES_2:1)
Block(-2,31,1,LEAVES_2:1)
Block(-2,31,2,LEAVES_2:1)
Block(-2,31,5,LEAVES_2:1)
Block(-2,31,7,LEAVES_2:1)
Block(-2,31,8,LEAVES_2:1)
Block(-2,31,9,LEAVES_2:1)
Block(-2,31,10,LEAVES_2:1)
Block(-2,32,-1,LEAVES_2:1)
Block(-2,32,0,LEAVES_2:1)
Block(-2,32,1,LEAVES_2:1)
Block(-2,32,3,LEAVES_2:1)
Block(-2,32,4,LEAVES_2:1)
Block(-2,32,5,LOG_2:1)
Block(-2,32,6,LOG_2:1)
Block(-2,32,7,LEAVES_2:1)
Block(-2,33,-2,LEAVES_2:1)
Block(-2,33,-1,LEAVES_2:1)
Block(-2,33,1,LEAVES_2:1)
Block(-2,33,3,LEAVES_2:1)
Block(-2,33,5,LEAVES_2:1)
Block(-2,33,6,LEAVES_2:1)
Block(-2,34,1,LEAVES_2:1)
Block(-2,34,2,LEAVES_2:1)
Block(-2,34,5,LEAVES_2:1)
Block(-2,35,2,LEAVES_2:1)
Block(-2,35,3,LEAVES_2:1)
Block(-2,35,4,LEAVES_2:1)
Block(-2,35,7,LEAVES_2:1)
Block(-2,35,10,LEAVES_2:1)
Block(-2,36,1,LEAVES_2:1)
Block(-2,36,2,LEAVES_2:1)
Block(-2,36,3,LEAVES_2:1)
Block(-2,36,4,LEAVES_2:1)
Block(-2,36,5,LEAVES_2:1)
Block(-2,36,7,LEAVES_2:1)
Block(-2,36,9,LEAVES_2:1)
Block(-2,37,0,LEAVES_2:1)
Block(-2,37,1,LEAVES_2:1)
Block(-2,37,2,LOG_2:1)
Block(-2,37,3,LOG_2:1)
Block(-2,37,4,LEAVES_2:1)
Block(-2,37,5,LEAVES_2:1)
Block(-2,37,6,LEAVES_2:1)
Block(-2,37,7,LEAVES_2:1)
Block(-2,37,8,LEAVES_2:1)
Block(-2,38,0,LEAVES_2:1)
Block(-2,38,1,LEAVES_2:1)
Block(-2,38,2,LOG_2:1)
Block(-2,38,3,LOG_2:1)
Block(-2,38,4,LEAVES_2:1)
Block(-2,38,5,LEAVES_2:1)
Block(-2,38,6,LEAVES_2:1)
Block(-2,38,7,LEAVES_2:1)
Block(-2,39,-2,LEAVES_2:1)
Block(-2,39,-1,LEAVES_2:1)
Block(-2,39,0,LEAVES_2:1)
Block(-2,39,1,LEAVES_2:1)
Block(-2,39,2,LEAVES_2:1)
Block(-2,39,3,LEAVES_2:1)
Block(-2,39,4,LEAVES_2:1)
Block(-2,39,5,LEAVES_2:1)
Block(-2,40,-4,LEAVES_2:1)
Block(-2,40,-2,LEAVES_2:1)
Block(-2,40,-1,LEAVES_2:1)
Block(-2,40,0,LEAVES_2:1)
Block(-2,40,1,LEAVES_2:1)
Block(-2,40,2,LEAVES_2:1)
Block(-2,40,3,LEAVES_2:1)
Block(-2,40,6,LEAVES_2:1)
Block(-2,41,-3,LEAVES_2:1)
Block(-2,41,-2,LEAVES_2:1)
Block(-2,41,-1,LEAVES_2:1)
Block(-2,41,0,LEAVES_2:1)
Block(-2,41,2,LEAVES_2:1)
Block(-2,41,3,LEAVES_2:1)
Block(-2,41,6,LEAVES_2:1)
Block(-2,42,-3,LEAVES_2:1)
Block(-2,42,-2,LEAVES_2:1)
Block(-2,42,-1,LEAVES_2:1)
Block(-2,42,0,LEAVES_2:1)
Block(-2,42,1,LEAVES_2:1)
Block(-2,42,2,LOG_2:1)
Block(-2,42,3,LEAVES_2:1)
Block(-2,42,7,LEAVES_2:1)
Block(-2,43,0,LEAVES_2:1)
Block(-2,43,1,LEAVES_2:1)
Block(-2,43,2,LEAVES_2:1)
Block(-2,43,3,LEAVES_2:1)
Block(-2,43,4,LEAVES_2:1)
Block(-2,43,6,LEAVES_2:1)
Block(-2,43,7,LEAVES_2:1)
Block(-2,44,0,LEAVES_2:1)
Block(-2,44,1,LEAVES_2:1)
Block(-2,44,2,LEAVES_2:1)
Block(-2,44,3,LEAVES_2:1)
Block(-2,45,0,LEAVES_2:1)
Block(-2,45,1,LEAVES_2:1)
Block(-2,45,2,LEAVES_2:1)
Block(-2,45,3,LEAVES_2:1)
Block(-2,46,0,LEAVES_2:1)
Block(-2,46,3,LOG_2:1)
Block(-2,47,0,LEAVES_2:1)
Block(-2,47,1,LEAVES_2:1)
Block(-2,47,2,LEAVES_2:1)
Block(-2,47,3,LEAVES_2:1)
Block(-2,47,4,LEAVES_2:1)
Block(-2,48,0,LEAVES_2:1)
Block(-2,48,2,LEAVES_2:1)
Block(-2,48,3,LEAVES_2:1)
Block(-2,48,5,LEAVES_2:1)
Block(-2,48,7,LEAVES_2:1)
Block(-2,48,8,LEAVES_2:1)
Block(-2,49,0,LEAVES_2:1)
Block(-2,49,1,LEAVES_2:1)
Block(-2,49,2,LEAVES_2:1)
Block(-2,49,3,LEAVES_2:1)
Block(-2,49,5,LEAVES_2:1)
Block(-2,49,6,LEAVES_2:1)
Block(-2,49,7,LEAVES_2:1)
Block(-2,50,0,LEAVES_2:1)
Block(-2,50,1,LEAVES_2:1)
Block(-2,50,2,LEAVES_2:1)
Block(-2,50,3,LEAVES_2:1)
Block(-2,50,5,LEAVES_2:1)
Block(-2,50,6,LEAVES_2:1)
Block(-2,50,7,LOG_2:1)
Block(-2,50,9,LEAVES_2:1)
Block(-2,51,0,LEAVES_2:1)
Block(-2,51,1,LEAVES_2:1)
Block(-2,51,6,LEAVES_2:1)
Block(-2,51,7,LEAVES_2:1)
Block(-2,52,6,LEAVES_2:1)
Block(-2,52,7,LEAVES_2:1)
Block(-2,52,8,LEAVES_2:1)
Block(-1,16,6,LEAVES_2:1)
Block(-1,22,-5,LEAVES_2:1)
Block(-1,22,-4,LEAVES_2:1)
Block(-1,22,-3,LEAVES_2:1)
Block(-1,23,-6,LEAVES_2:1)
Block(-1,23,-5,LEAVES_2:1)
Block(-1,23,-4,LEAVES_2:1)
Block(-1,23,-3,LEAVES_2:1)
Block(-1,23,-2,LEAVES_2:1)
Block(-1,23,1,LEAVES_2:1)
Block(-1,24,-6,LEAVES_2:1)
Block(-1,24,-5,LEAVES_2:1)
Block(-1,24,-4,LOG_2:1)
Block(-1,24,-3,LOG_2:1)
Block(-1,24,-2,LEAVES_2:1)
Block(-1,24,-1,LEAVES_2:1)
Block(-1,24,0,LEAVES_2:1)
Block(-1,24,3,LEAVES_2:1)
Block(-1,24,4,LEAVES_2:1)
Block(-1,24,5,LEAVES_2:1)
Block(-1,25,-6,LEAVES_2:1)
Block(-1,25,-5,LEAVES_2:1)
Block(-1,25,-4,LEAVES_2:1)
Block(-1,25,-3,LEAVES_2:1)
Block(-1,25,-2,LEAVES_2:1)
Block(-1,25,1,LEAVES_2:1)
Block(-1,25,2,LEAVES_2:1)
Block(-1,25,3,LEAVES_2:1)
Block(-1,25,4,LEAVES_2:1)
Block(-1,25,5,LEAVES_2:1)
Block(-1,25,6,LEAVES_2:1)
Block(-1,25,8,LEAVES_2:1)
Block(-1,25,10,LEAVES_2:1)
Block(-1,26,-5,LEAVES_2:1)
Block(-1,26,-4,LEAVES_2:1)
Block(-1,26,-3,LEAVES_2:1)
Block(-1,26,-2,LEAVES_2:1)
Block(-1,26,0,LEAVES_2:1)
Block(-1,26,1,LOG_2:1)
Block(-1,26,2,LEAVES_2:1)
Block(-1,26,4,LEAVES_2:1)
Block(-1,26,5,LEAVES_2:1)
Block(-1,26,6,LEAVES_2:1)
Block(-1,26,7,LEAVES_2:1)
Block(-1,26,8,LEAVES_2:1)
Block(-1,26,9,LEAVES_2:1)
Block(-1,26,10,LEAVES_2:1)
Block(-1,27,-5,LEAVES_2:1)
Block(-1,27,-4,LEAVES_2:1)
Block(-1,27,-3,LEAVES_2:1)
Block(-1,27,-2,LEAVES_2:1)
Block(-1,27,-1,LEAVES_2:1)
Block(-1,27,0,LEAVES_2:1)
Block(-1,27,1,LOG_2:1)
Block(-1,27,2,LEAVES_2:1)
Block(-1,27,3,LEAVES_2:1)
Block(-1,27,4,LEAVES_2:1)
Block(-1,27,5,LOG_2:1)
Block(-1,27,6,LEAVES_2:1)
Block(-1,27,7,LEAVES_2:1)
Block(-1,27,8,LOG_2:1)
Block(-1,27,9,LOG_2:1)
Block(-1,27,10,LOG_2:1)
Block(-1,27,11,LEAVES_2:1)
Block(-1,28,-3,LEAVES_2:1)
Block(-1,28,-2,LEAVES_2:1)
Block(-1,28,-1,LEAVES_2:1)
Block(-1,28,0,LEAVES_2:1)
Block(-1,28,1,LEAVES_2:1)
Block(-1,28,2,LEAVES_2:1)
Block(-1,28,3,LEAVES_2:1)
Block(-1,28,4,LEAVES_2:1)
Block(-1,28,5,LOG_2:1)
Block(-1,28,6,LEAVES_2:1)
Block(-1,28,7,LEAVES_2:1)
Block(-1,28,8,LEAVES_2:1)
Block(-1,28,9,LOG_2:1)
Block(-1,28,10,LEAVES_2:1)
Block(-1,28,11,LEAVES_2:1)
Block(-1,29,-2,LEAVES_2:1)
Block(-1,29,-1,LEAVES_2:1)
Block(-1,29,0,LEAVES_2:1)
Block(-1,29,1,LEAVES_2:1)
Block(-1,29,2,LEAVES_2:1)
Block(-1,29,3,LEAVES_2:1)
Block(-1,29,6,LEAVES_2:1)
Block(-1,29,7,LEAVES_2:1)
Block(-1,29,8,LEAVES_2:1)
Block(-1,29,9,LOG_2:1)
Block(-1,29,10,LEAVES_2:1)
Block(-1,29,11,LEAVES_2:1)
Block(-1,30,-3,LEAVES_2:1)
Block(-1,30,-2,LEAVES_2:1)
Block(-1,30,-1,LOG_2:1)
Block(-1,30,0,LEAVES_2:1)
Block(-1,30,1,LEAVES_2:1)
Block(-1,30,2,LEAVES_2:1)
Block(-1,30,3,LEAVES_2:1)
Block(-1,30,7,LEAVES_2:1)
Block(-1,30,8,LEAVES_2:1)
Block(-1,30,9,LEAVES_2:1)
Block(-1,30,10,LEAVES_2:1)
Block(-1,30,11,LEAVES_2:1)
Block(-1,31,-2,LEAVES_2:1)
Block(-1,31,-1,LOG_2:1)
Block(-1,31,0,LEAVES_2:1)
Block(-1,31,1,LEAVES_2:1)
Block(-1,31,2,LEAVES_2:1)
Block(-1,31,4,LEAVES_2:1)
Block(-1,31,5,LEAVES_2:1)
Block(-1,31,8,LEAVES_2:1)
Block(-1,31,10,LEAVES_2:1)
Block(-1,32,-3,LEAVES_2:1)
Block(-1,32,-2,LEAVES_2:1)
Block(-1,32,-1,LEAVES_2:1)
Block(-1,32,0,LEAVES_2:1)
Block(-1,32,1,LEAVES_2:1)
Block(-1,32,2,LEAVES_2:1)
Block(-1,32,5,LOG_2:1)
Block(-1,32,6,LEAVES_2:1)
Block(-1,32,8,LEAVES_2:1)
Block(-1,32,10,LEAVES_2:1)
Block(-1,33,-2,LEAVES_2:1)
Block(-1,33,-1,LEAVES_2:1)
Block(-1,33,0,LEAVES_2:1)
Block(-1,33,1,LEAVES_2:1)
Block(-1,33,3,LEAVES_2:1)
Block(-1,33,4,LEAVES_2:1)
Block(-1,33,5,LEAVES_2:1)
Block(-1,33,6,LEAVES_2:1)
Block(-1,34,-2,LEAVES_2:1)
Block(-1,34,-1,LEAVES_2:1)
Block(-1,34,0,LEAVES_2:1)
Block(-1,34,2,LEAVES_2:1)
Block(-1,34,3,LEAVES_2:1)
Block(-1,34,10,LEAVES_2:1)
Block(-1,35,1,LEAVES_2:1)
Block(-1,35,2,LEAVES_2:1)
Block(-1,35,3,LEAVES_2:1)
Block(-1,35,10,LEAVES_2:1)
Block(-1,36,-1,LEAVES_2:1)
Block(-1,36,1,LEAVES_2:1)
Block(-1,36,3,LEAVES_2:1)
Block(-1,36,4,LEAVES_2:1)
Block(-1,36,6,LEAVES_2:1)
Block(-1,36,8,LOG_2:1)
Block(-1,36,9,LEAVES_2:1)
Block(-1,36,10,LEAVES_2:1)
Block(-1,37,0,LEAVES_2:1)
Block(-1,37,1,LEAVES_2:1)
Block(-1,37,2,LEAVES_2:1)
Block(-1,37,3,LEAVES_2:1)
Block(-1,37,4,LEAVES_2:1)
Block(-1,37,5,LEAVES_2:1)
Block(-1,37,6,LEAVES_2:1)
Block(-1,37,7,LEAVES_2:1)
Block(-1,37,8,LOG_2:1)
Block(-1,38,-1,LEAVES_2:1)
Block(-1,38,0,LEAVES_2:1)
Block(-1,38,1,LEAVES_2:1)
Block(-1,38,2,LEAVES_2:1)
Block(-1,38,3,LOG_2:1)
Block(-1,38,4,LEAVES_2:1)
Block(-1,38,5,LEAVES_2:1)
Block(-1,38,6,LEAVES_2:1)
Block(-1,38,7,LEAVES_2:1)
Block(-1,39,-3,LEAVES_2:1)
Block(-1,39,-2,LEAVES_2:1)
Block(-1,39,-1,LOG_2:1)
Block(-1,39,0,LEAVES_2:1)
Block(-1,39,1,LEAVES_2:1)
Block(-1,39,2,LEAVES_2:1)
Block(-1,39,3,LEAVES_2:1)
Block(-1,39,4,LEAVES_2:1)
Block(-1,39,5,LOG_2:1)
Block(-1,39,6,LEAVES_2:1)
Block(-1,39,7,LEAVES_2:1)
Block(-1,39,8,LEAVES_2:1)
Block(-1,40,-4,LEAVES_2:1)
Block(-1,40,-3,LEAVES_2:1)
Block(-1,40,-2,LOG_2:1)
Block(-1,40,-1,LOG_2:1)
Block(-1,40,0,LEAVES_2:1)
Block(-1,40,1,LEAVES_2:1)
Block(-1,40,2,LEAVES_2:1)
Block(-1,40,3,LEAVES_2:1)
Block(-1,40,4,LEAVES_2:1)
Block(-1,40,5,LEAVES_2:1)
Block(-1,40,6,LEAVES_2:1)
Block(-1,40,7,LEAVES_2:1)
Block(-1,41,-3,LEAVES_2:1)
Block(-1,41,-2,LEAVES_2:1)
Block(-1,41,-1,LEAVES_2:1)
Block(-1,41,0,LEAVES_2:1)
Block(-1,41,1,LEAVES_2:1)
Block(-1,41,2,LEAVES_2:1)
Block(-1,41,3,LEAVES_2:1)
Block(-1,41,4,LEAVES_2:1)
Block(-1,41,5,LEAVES_2:1)
Block(-1,41,6,LEAVES_2:1)
Block(-1,41,7,LOG_2:1)
Block(-1,41,8,LOG_2:1)
Block(-1,42,-4,LEAVES_2:1)
Block(-1,42,-3,LEAVES_2:1)
Block(-1,42,-2,LEAVES_2:1)
Block(-1,42,-1,LEAVES_2:1)
Block(-1,42,0,LEAVES_2:1)
Block(-1,42,1,LEAVES_2:1)
Block(-1,42,2,LOG_2:1)
Block(-1,42,3,LEAVES_2:1)
Block(-1,42,5,LEAVES_2:1)
Block(-1,42,6,LEAVES_2:1)
Block(-1,43,-3,LEAVES_2:1)
Block(-1,43,-2,LEAVES_2:1)
Block(-1,43,0,LEAVES_2:1)
Block(-1,43,2,LEAVES_2:1)
Block(-1,43,3,LEAVES_2:1)
Block(-1,43,4,LEAVES_2:1)
Block(-1,43,7,LEAVES_2:1)
Block(-1,43,8,LEAVES_2:1)
Block(-1,43,9,LEAVES_2:1)
Block(-1,44,-2,LEAVES_2:1)
Block(-1,44,1,LEAVES_2:1)
Block(-1,44,2,LEAVES_2:1)
Block(-1,44,3,LEAVES_2:1)
Block(-1,44,6,LEAVES_2:1)
Block(-1,45,-2,LEAVES_2:1)
Block(-1,45,-1,LOG_2:1)
Block(-1,45,0,LOG_2:1)
Block(-1,45,1,LEAVES_2:1)
Block(-1,45,2,LEAVES_2:1)
Block(-1,45,3,LEAVES_2:1)
Block(-1,45,4,LEAVES_2:1)
Block(-1,46,-1,LEAVES_2:1)
Block(-1,46,0,LOG_2:1)
Block(-1,46,1,LEAVES_2:1)
Block(-1,46,2,LEAVES_2:1)
Block(-1,46,3,LOG_2:1)
Block(-1,46,4,LEAVES_2:1)
Block(-1,47,-1,LEAVES_2:1)
Block(-1,47,0,LEAVES_2:1)
Block(-1,47,1,LEAVES_2:1)
Block(-1,47,2,LEAVES_2:1)
Block(-1,47,3,LOG_2:1)
Block(-1,47,4,LEAVES_2:1)
Block(-1,47,5,LEAVES_2:1)
Block(-1,48,0,LEAVES_2:1)
Block(-1,48,1,LEAVES_2:1)
Block(-1,48,2,LEAVES_2:1)
Block(-1,48,3,LEAVES_2:1)
Block(-1,48,5,LEAVES_2:1)
Block(-1,48,6,LEAVES_2:1)
Block(-1,48,7,LEAVES_2:1)
Block(-1,48,8,LEAVES_2:1)
Block(-1,49,1,LEAVES_2:1)
Block(-1,49,2,LEAVES_2:1)
Block(-1,49,3,LEAVES_2:1)
Block(-1,49,4,LEAVES_2:1)
Block(-1,49,5,LEAVES_2:1)
Block(-1,49,6,LEAVES_2:1)
Block(-1,49,7,LEAVES_2:1)
Block(-1,49,8,LEAVES_2:1)
Block(-1,50,1,LEAVES_2:1)
Block(-1,50,5,LEAVES_2:1)
Block(-1,50,6,LEAVES_2:1)
Block(-1,50,7,LOG_2:1)
Block(-1,50,8,LEAVES_2:1)
Block(-1,50,9,LEAVES_2:1)
Block(-1,51,0,LEAVES_2:1)
Block(-1,51,1,LEAVES_2:1)
Block(-1,51,5,LEAVES_2:1)
Block(-1,51,7,LEAVES_2:1)
Block(-1,51,9,LEAVES_2:1)
Block(-1,52,6,LEAVES_2:1)
Block(-1,52,7,LEAVES_2:1)
Block(-1,52,8,LEAVES_2:1)
Block(-1,54,2,LEAVES_2:1)
Block(-1,54,3,LEAVES_2:1)
Block(-1,54,4,LEAVES_2:1)
Block(-1,54,5,LEAVES_2:1)
Block(-1,55,1,LEAVES_2:1)
Block(-1,55,2,LEAVES_2:1)
Block(-1,55,3,LEAVES_2:1)
Block(-1,55,4,LEAVES_2:1)
Block(-1,55,5,LEAVES_2:1)
Block(-1,56,2,LEAVES_2:1)
Block(-1,56,3,LEAVES_2:1)
Block(-1,56,4,LEAVES_2:1)
Block(0,15,6,LEAVES_2:1)
Block(0,15,7,LEAVES_2:1)
Block(0,16,5,LEAVES_2:1)
Block(0,16,6,LEAVES_2:1)
Block(0,16,7,LEAVES_2:1)
Block(0,16,8,LEAVES_2:1)
Block(0,17,6,LEAVES_2:1)
Block(0,17,7,LEAVES_2:1)
Block(0,23,-6,LEAVES_2:1)
Block(0,23,-3,LEAVES_2:1)
Block(0,23,-1,LEAVES_2:1)
Block(0,23,1,LEAVES_2:1)
Block(0,24,-6,LEAVES_2:1)
Block(0,24,-5,LEAVES_2:1)
Block(0,24,-4,LOG_2:1)
Block(0,24,-3,LOG_2:1)
Block(0,24,-2,LOG_2:1)
Block(0,24,-1,LEAVES_2:1)
Block(0,24,1,LEAVES_2:1)
Block(0,25,-6,LEAVES_2:1)
Block(0,25,-5,LEAVES_2:1)
Block(0,25,-4,LEAVES_2:1)
Block(0,25,-3,LOG_2:1)
Block(0,25,-2,LEAVES_2:1)
Block(0,25,-1,LEAVES_2:1)
Block(0,25,0,LEAVES_2:1)
Block(0,25,1,LEAVES_2:1)
Block(0,25,4,LEAVES_2:1)
Block(0,25,5,LEAVES_2:1)
Block(0,25,6,LEAVES_2:1)
Block(0,25,9,LEAVES_2:1)
Block(0,26,-5,LEAVES_2:1)
Block(0,26,-4,LEAVES_2:1)
Block(0,26,-3,LOG_2:1)
Block(0,26,-2,LEAVES_2:1)
Block(0,26,-1,LEAVES_2:1)
Block(0,26,1,LOG_2:1)
Block(0,26,2,LEAVES_2:1)
Block(0,26,3,LEAVES_2:1)
Block(0,26,5,LEAVES_2:1)
Block(0,26,7,LEAVES_2:1)
Block(0,26,8,LEAVES_2:1)
Block(0,26,9,LEAVES_2:1)
Block(0,26,10,LEAVES_2:1)
Block(0,26,11,LEAVES_2:1)
Block(0,27,-3,LEAVES_2:1)
Block(0,27,-2,LEAVES_2:1)
Block(0,27,-1,LEAVES_2:1)
Block(0,27,0,LEAVES_2:1)
Block(0,27,1,LOG_2:1)
Block(0,27,2,LOG_2:1)
Block(0,27,3,LEAVES_2:1)
Block(0,27,4,LEAVES_2:1)
Block(0,27,5,LOG_2:1)
Block(0,27,6,LOG_2:1)
Block(0,27,7,LOG_2:1)
Block(0,27,8,LOG_2:1)
Block(0,27,9,LEAVES_2:1)
Block(0,27,11,LEAVES_2:1)
Block(0,27,12,LEAVES_2:1)
Block(0,27,13,LEAVES_2:1)
Block(0,28,-3,LEAVES_2:1)
Block(0,28,-2,LEAVES_2:1)
Block(0,28,-1,LEAVES_2:1)
Block(0,28,0,LEAVES_2:1)
Block(0,28,1,LEAVES_2:1)
Block(0,28,2,LOG_2:1)
Block(0,28,3,LEAVES_2:1)
Block(0,28,4,LEAVES_2:1)
Block(0,28,5,LOG_2:1)
Block(0,28,6,LEAVES_2:1)
Block(0,28,7,LEAVES_2:1)
Block(0,28,8,LEAVES_2:1)
Block(0,28,9,LEAVES_2:1)
Block(0,28,10,LEAVES_2:1)
Block(0,28,11,LEAVES_2:1)
Block(0,28,12,LEAVES_2:1)
Block(0,29,-1,LEAVES_2:1)
Block(0,29,0,LEAVES_2:1)
Block(0,29,1,LEAVES_2:1)
Block(0,29,2,LOG_2:1)
Block(0,29,3,LEAVES_2:1)
Block(0,29,4,LEAVES_2:1)
Block(0,29,5,LOG_2:1)
Block(0,29,6,LEAVES_2:1)
Block(0,29,7,LEAVES_2:1)
Block(0,29,8,LEAVES_2:1)
Block(0,29,9,LEAVES_2:1)
Block(0,29,10,LEAVES_2:1)
Block(0,29,11,LEAVES_2:1)
Block(0,30,-2,LEAVES_2:1)
Block(0,30,-1,LEAVES_2:1)
Block(0,30,0,LEAVES_2:1)
Block(0,30,1,LEAVES_2:1)
Block(0,30,2,LEAVES_2:1)
Block(0,30,3,LEAVES_2:1)
Block(0,30,6,LEAVES_2:1)
Block(0,30,7,LEAVES_2:1)
Block(0,30,8,LEAVES_2:1)
Block(0,30,9,LEAVES_2:1)
Block(0,30,10,LEAVES_2:1)
Block(0,31,-3,LEAVES_2:1)
Block(0,31,-2,LEAVES_2:1)
Block(0,31,-1,LOG_2:1)
Block(0,31,0,LOG_2:1)
Block(0,31,1,LEAVES_2:1)
Block(0,31,3,LEAVES_2:1)
Block(0,31,4,LEAVES_2:1)
Block(0,31,6,LEAVES_2:1)
Block(0,31,8,LEAVES_2:1)
Block(0,31,9,LEAVES_2:1)
Block(0,31,10,LEAVES_2:1)
Block(0,32,-3,LEAVES_2:1)
Block(0,32,-2,LEAVES_2:1)
Block(0,32,-1,LEAVES_2:1)
Block(0,32,0,LEAVES_2:1)
Block(0,32,1,LEAVES_2:1)
Block(0,32,2,LEAVES_2:1)
Block(0,32,3,LEAVES_2:1)
Block(0,32,4,LOG_2:1)
Block(0,32,5,LOG_2:1)
Block(0,32,7,LEAVES_2:1)
Block(0,32,8,LEAVES_2:1)
Block(0,32,9,LEAVES_2:1)
Block(0,32,10,LEAVES_2:1)
Block(0,33,-2,LEAVES_2:1)
Block(0,33,-1,LEAVES_2:1)
Block(0,33,0,LEAVES_2:1)
Block(0,33,1,LEAVES_2:1)
Block(0,33,2,LEAVES_2:1)
Block(0,33,3,LEAVES_2:1)
Block(0,33,4,LOG_2:1)
Block(0,33,5,LOG_2:1)
Block(0,34,-1,LEAVES_2:1)
Block(0,34,0,LEAVES_2:1)
Block(0,34,1,LEAVES_2:1)
Block(0,34,2,LEAVES_2:1)
Block(0,34,4,LEAVES_2:1)
Block(0,35,-4,LEAVES_2:1)
Block(0,35,-1,LEAVES_2:1)
Block(0,35,0,LEAVES_2:1)
Block(0,35,1,LEAVES_2:1)
Block(0,35,2,LEAVES_2:1)
Block(0,35,3,LEAVES_2:1)
Block(0,36,-3,LEAVES_2:1)
Block(0,36,-1,LEAVES_2:1)
Block(0,36,0,LEAVES_2:1)
Block(0,36,2,LEAVES_2:1)
Block(0,36,3,LEAVES_2:1)
Block(0,36,4,LEAVES_2:1)
Block(0,36,7,LEAVES_2:1)
Block(0,36,8,LEAVES_2:1)
Block(0,36,9,LOG_2:1)
Block(0,36,10,LEAVES_2:1)
Block(0,37,-4,LEAVES_2:1)
Block(0,37,-3,LEAVES_2:1)
Block(0,37,-2,LEAVES_2:1)
Block(0,37,2,LEAVES_2:1)
Block(0,37,3,LEAVES_2:1)
Block(0,37,4,LEAVES_2:1)
Block(0,37,5,LEAVES_2:1)
Block(0,37,6,LEAVES_2:1)
Block(0,37,7,LEAVES_2:1)
Block(0,37,8,LOG_2:1)
Block(0,37,10,LEAVES_2:1)
Block(0,38,-2,LEAVES_2:1)
Block(0,38,0,LEAVES_2:1)
Block(0,38,1,LEAVES_2:1)
Block(0,38,2,LEAVES_2:1)
Block(0,38,3,LOG_2:1)
Block(0,38,5,LEAVES_2:1)
Block(0,38,6,LEAVES_2:1)
Block(0,38,7,LOG_2:1)
Block(0,38,8,LOG_2:1)
Block(0,38,10,LEAVES_2:1)
Block(0,39,-3,LEAVES_2:1)
Block(0,39,-2,LEAVES_2:1)
Block(0,39,-1,LOG_2:1)
Block(0,39,0,LEAVES_2:1)
Block(0,39,1,LEAVES_2:1)
Block(0,39,2,LEAVES_2:1)
Block(0,39,3,LOG_2:1)
Block(0,39,4,LEAVES_2:1)
Block(0,39,5,LEAVES_2:1)
Block(0,39,6,LEAVES_2:1)
Block(0,39,7,LEAVES_2:1)
Block(0,39,8,LEAVES_2:1)
Block(0,39,9,LEAVES_2:1)
Block(0,39,10,LEAVES_2:1)
Block(0,40,-5,LEAVES_2:1)
Block(0,40,-4,LEAVES_2:1)
Block(0,40,-2,LEAVES_2:1)
Block(0,40,-1,LOG_2:1)
Block(0,40,0,LOG_2:1)
Block(0,40,1,LEAVES_2:1)
Block(0,40,2,LEAVES_2:1)
Block(0,40,4,LEAVES_2:1)
Block(0,40,5,LEAVES_2:1)
Block(0,40,6,LEAVES_2:1)
Block(0,40,7,LEAVES_2:1)
Block(0,40,8,LEAVES_2:1)
Block(0,40,9,LEAVES_2:1)
Block(0,41,-3,LEAVES_2:1)
Block(0,41,-2,LEAVES_2:1)
Block(0,41,-1,LEAVES_2:1)
Block(0,41,0,LEAVES_2:1)
Block(0,41,1,LEAVES_2:1)
Block(0,41,2,LEAVES_2:1)
Block(0,41,3,LEAVES_2:1)
Block(0,41,4,LEAVES_2:1)
Block(0,41,5,LEAVES_2:1)
Block(0,41,6,LEAVES_2:1)
Block(0,41,7,LOG_2:1)
Block(0,42,-2,LEAVES_2:1)
Block(0,42,-1,LEAVES_2:1)
Block(0,42,0,LEAVES_2:1)
Block(0,42,1,LEAVES_2:1)
Block(0,42,2,LOG_2:1)
Block(0,42,3,LEAVES_2:1)
Block(0,42,4,LEAVES_2:1)
Block(0,42,5,LEAVES_2:1)
Block(0,42,6,LOG_2:1)
Block(0,42,7,LOG_2:1)
Block(0,42,8,LEAVES_2:1)
Block(0,43,-3,LEAVES_2:1)
Block(0,43,-2,LEAVES_2:1)
Block(0,43,-1,LEAVES_2:1)
Block(0,43,2,LEAVES_2:1)
Block(0,43,3,LEAVES_2:1)
Block(0,43,4,LEAVES_2:1)
Block(0,43,5,LEAVES_2:1)
Block(0,43,6,LEAVES_2:1)
Block(0,43,7,LEAVES_2:1)
Block(0,44,-4,LEAVES_2:1)
Block(0,44,-3,LEAVES_2:1)
Block(0,44,-2,LEAVES_2:1)
Block(0,44,-1,LEAVES_2:1)
Block(0,44,4,LEAVES_2:1)
Block(0,44,5,LEAVES_2:1)
Block(0,44,6,LEAVES_2:1)
Block(0,44,7,LEAVES_2:1)
Block(0,45,-1,LEAVES_2:1)
Block(0,45,0,LOG_2:1)
Block(0,45,1,LEAVES_2:1)
Block(0,45,2,LEAVES_2:1)
Block(0,45,3,LEAVES_2:1)
Block(0,45,5,LEAVES_2:1)
Block(0,45,6,LEAVES_2:1)
Block(0,45,7,LEAVES_2:1)
Block(0,45,8,LEAVES_2:1)
Block(0,46,-2,LEAVES_2:1)
Block(0,46,-1,LEAVES_2:1)
Block(0,46,0,LOG_2:1)
Block(0,46,1,LOG_2:1)
Block(0,46,2,LEAVES_2:1)
Block(0,46,5,LEAVES_2:1)
Block(0,46,8,LEAVES_2:1)
Block(0,46,9,LEAVES_2:1)
Block(0,47,-1,LEAVES_2:1)
Block(0,47,0,LEAVES_2:1)
Block(0,47,1,LEAVES_2:1)
Block(0,47,2,LEAVES_2:1)
Block(0,47,3,LOG_2:1)
Block(0,47,4,LOG_2:1)
Block(0,47,8,LEAVES_2:1)
Block(0,47,9,LEAVES_2:1)
Block(0,48,-2,LEAVES_2:1)
Block(0,48,-1,LEAVES_2:1)
Block(0,48,0,LEAVES_2:1)
Block(0,48,1,LEAVES_2:1)
Block(0,48,2,LEAVES_2:1)
Block(0,48,3,LEAVES_2:1)
Block(0,48,5,LEAVES_2:1)
Block(0,48,7,LEAVES_2:1)
Block(0,48,8,LEAVES_2:1)
Block(0,49,-1,LEAVES_2:1)
Block(0,49,0,LEAVES_2:1)
Block(0,49,1,LEAVES_2:1)
Block(0,49,2,LEAVES_2:1)
Block(0,49,3,LEAVES_2:1)
Block(0,49,5,LEAVES_2:1)
Block(0,49,7,LEAVES_2:1)
Block(0,49,8,LEAVES_2:1)
Block(0,49,9,LEAVES_2:1)
Block(0,50,-2,LEAVES_2:1)
Block(0,50,-1,LEAVES_2:1)
Block(0,50,0,LOG_2:1)
Block(0,50,1,LOG_2:1)
Block(0,50,2,LEAVES_2:1)
Block(0,50,3,LEAVES_2:1)
Block(0,50,5,LOG_2:1)
Block(0,50,6,LOG_2:1)
Block(0,50,7,LOG_2:1)
Block(0,50,9,LEAVES_2:1)
Block(0,51,-2,LEAVES_2:1)
Block(0,51,-1,LEAVES_2:1)
Block(0,51,0,LOG_2:1)
Block(0,51,1,LEAVES_2:1)
Block(0,51,2,LEAVES_2:1)
Block(0,51,6,LEAVES_2:1)
Block(0,51,7,LOG_2:1)
Block(0,51,8,LEAVES_2:1)
Block(0,52,-1,LEAVES_2:1)
Block(0,52,1,LEAVES_2:1)
Block(0,52,7,LOG_2:1)
Block(0,52,8,LEAVES_2:1)
Block(0,53,1,LEAVES_2:1)
Block(0,53,2,LEAVES_2:1)
Block(0,53,3,LEAVES_2:1)
Block(0,53,4,LEAVES_2:1)
Block(0,53,5,LEAVES_2:1)
Block(0,53,7,LEAVES_2:1)
Block(0,54,-1,LEAVES_2:1)
Block(0,54,0,LEAVES_2:1)
Block(0,54,1,LEAVES_2:1)
Block(0,54,2,LEAVES_2:1)
Block(0,54,3,LEAVES_2:1)
Block(0,54,4,LEAVES_2:1)
Block(0,54,5,LEAVES_2:1)
Block(0,54,6,LEAVES_2:1)
Block(0,55,0,LEAVES_2:1)
Block(0,55,1,LEAVES_2:1)
Block(0,55,2,LOG_2:1)
Block(0,55,3,LEAVES_2:1)
Block(0,55,4,LEAVES_2:1)
Block(0,55,5,LEAVES_2:1)
Block(0,56,0,LEAVES_2:1)
Block(0,56,1,LEAVES_2:1)
Block(0,56,2,LEAVES_2:1)
Block(0,56,3,LEAVES_2:1)
Block(0,56,5,LEAVES_2:1)
Block(0,57,2,LEAVES_2:1)
Block(0,57,3,LEAVES_2:1)
Block(0,57,4,LEAVES_2:1)
Block(0,57,5,LEAVES_2:1)
Block(0,58,3,LEAVES_2:1)
Block(0,58,4,LEAVES_2:1)
Block(0,58,5,LOG_2:1)
Block(0,59,4,LEAVES_2:1)
Block(0,59,5,LEAVES_2:1)
Block(0,63,2,LEAVES_2:1)
Block(0,63,3,LEAVES_2:1)
Block(1,0,2,LOG_2:1)
Block(1,0,3,LOG_2:1)
Block(1,0,4,HUGE_MUSHROOM_1)
Block(1,0,5,HUGE_MUSHROOM_1)
Block(1,1,2,LOG_2:1)
Block(1,1,3,LOG_2:1)
Block(1,2,3,LOG_2:1)
Block(1,4,1,HUGE_MUSHROOM_1)
Block(1,4,2,HUGE_MUSHROOM_1)
Block(1,11,2,HUGE_MUSHROOM_1)
Block(1,15,5,LEAVES_2:1)
Block(1,15,6,LEAVES_2:1)
Block(1,15,7,LEAVES_2:1)
Block(1,16,4,LEAVES_2:1)
Block(1,16,5,LOG_2:1)
Block(1,16,6,LOG_2:1)
Block(1,16,7,LEAVES_2:1)
Block(1,16,8,LEAVES_2:1)
Block(1,17,-1,LEAVES_2:1)
Block(1,17,1,LEAVES_2:1)
Block(1,17,2,LEAVES_2:1)
Block(1,17,4,LEAVES_2:1)
Block(1,17,5,LOG_2:1)
Block(1,17,6,LEAVES_2:1)
Block(1,17,7,LEAVES_2:1)
Block(1,18,0,LEAVES_2:1)
Block(1,18,2,LEAVES_2:1)
Block(1,18,3,LEAVES_2:1)
Block(1,18,4,LEAVES_2:1)
Block(1,18,5,LEAVES_2:1)
Block(1,18,6,LEAVES_2:1)
Block(1,19,2,LEAVES_2:1)
Block(1,22,-2,LEAVES_2:1)
Block(1,22,-1,LEAVES_2:1)
Block(1,23,-3,LEAVES_2:1)
Block(1,23,-2,LEAVES_2:1)
Block(1,23,-1,LEAVES_2:1)
Block(1,23,0,LEAVES_2:1)
Block(1,24,-7,LEAVES_2:1)
Block(1,24,-6,LEAVES_2:1)
Block(1,24,-5,LEAVES_2:1)
Block(1,24,-4,LEAVES_2:1)
Block(1,24,-3,LEAVES_2:1)
Block(1,24,-2,LOG_2:1)
Block(1,24,-1,LEAVES_2:1)
Block(1,24,0,LEAVES_2:1)
Block(1,24,10,LEAVES_2:1)
Block(1,25,-8,LEAVES_2:1)
Block(1,25,-7,LEAVES_2:1)
Block(1,25,-6,LEAVES_2:1)
Block(1,25,-5,LOG_2:1)
Block(1,25,-4,LEAVES_2:1)
Block(1,25,-3,LEAVES_2:1)
Block(1,25,-1,LEAVES_2:1)
Block(1,25,5,LEAVES_2:1)
Block(1,25,9,LEAVES_2:1)
Block(1,26,-7,LEAVES_2:1)
Block(1,26,-6,LEAVES_2:1)
Block(1,26,-5,LEAVES_2:1)
Block(1,26,-4,LEAVES_2:1)
Block(1,26,-3,LEAVES_2:1)
Block(1,26,-2,LEAVES_2:1)
Block(1,26,-1,LEAVES_2:1)
Block(1,26,0,LEAVES_2:1)
Block(1,26,2,LEAVES_2:1)
Block(1,26,5,LEAVES_2:1)
Block(1,26,6,LEAVES_2:1)
Block(1,26,7,LOG_2:1)
Block(1,26,8,LEAVES_2:1)
Block(1,26,9,LEAVES_2:1)
Block(1,26,11,LEAVES_2:1)
Block(1,26,12,LEAVES_2:1)
Block(1,27,-5,LEAVES_2:1)
Block(1,27,-4,LEAVES_2:1)
Block(1,27,-3,LEAVES_2:1)
Block(1,27,-2,LEAVES_2:1)
Block(1,27,-1,LEAVES_2:1)
Block(1,27,0,LEAVES_2:1)
Block(1,27,1,LEAVES_2:1)
Block(1,27,2,LOG_2:1)
Block(1,27,3,LEAVES_2:1)
Block(1,27,4,LEAVES_2:1)
Block(1,27,5,LEAVES_2:1)
Block(1,27,6,LOG_2:1)
Block(1,27,7,LOG_2:1)
Block(1,27,8,LOG_2:1)
Block(1,27,9,LOG_2:1)
Block(1,27,10,LEAVES_2:1)
Block(1,27,11,LEAVES_2:1)
Block(1,27,12,LEAVES_2:1)
Block(1,28,-6,LEAVES_2:1)
Block(1,28,-5,LEAVES_2:1)
Block(1,28,-3,LEAVES_2:1)
Block(1,28,-2,LEAVES_2:1)
Block(1,28,-1,LEAVES_2:1)
Block(1,28,0,LEAVES_2:1)
Block(1,28,1,LEAVES_2:1)
Block(1,28,2,LOG_2:1)
Block(1,28,3,LEAVES_2:1)
Block(1,28,4,LEAVES_2:1)
Block(1,28,5,LOG_2:1)
Block(1,28,6,LOG_2:1)
Block(1,28,7,LOG_2:1)
Block(1,28,8,LEAVES_2:1)
Block(1,28,9,LEAVES_2:1)
Block(1,28,10,LEAVES_2:1)
Block(1,28,11,LEAVES_2:1)
Block(1,28,12,LEAVES_2:1)
Block(1,29,-3,LEAVES_2:1)
Block(1,29,-2,LEAVES_2:1)
Block(1,29,-1,LEAVES_2:1)
Block(1,29,2,LEAVES_2:1)
Block(1,29,4,LEAVES_2:1)
Block(1,29,5,LEAVES_2:1)
Block(1,29,7,LEAVES_2:1)
Block(1,29,8,LEAVES_2:1)
Block(1,29,9,LEAVES_2:1)
Block(1,29,10,LEAVES_2:1)
Block(1,29,11,LEAVES_2:1)
Block(1,29,12,LEAVES_2:1)
Block(1,30,-3,LEAVES_2:1)
Block(1,30,-2,LEAVES_2:1)
Block(1,30,-1,LEAVES_2:1)
Block(1,30,0,LEAVES_2:1)
Block(1,30,1,LEAVES_2:1)
Block(1,30,2,LEAVES_2:1)
Block(1,30,7,LEAVES_2:1)
Block(1,30,8,LEAVES_2:1)
Block(1,30,9,LOG_2:1)
Block(1,30,11,LEAVES_2:1)
Block(1,30,12,LEAVES_2:1)
Block(1,30,13,LEAVES_2:1)
Block(1,31,-3,LEAVES_2:1)
Block(1,31,-2,LEAVES_2:1)
Block(1,31,-1,LEAVES_2:1)
Block(1,31,0,LOG_2:1)
Block(1,31,1,LOG_2:1)
Block(1,31,2,LEAVES_2:1)
Block(1,31,3,LEAVES_2:1)
Block(1,31,4,LEAVES_2:1)
Block(1,31,8,LEAVES_2:1)
Block(1,31,10,LEAVES_2:1)
Block(1,31,12,LEAVES_2:1)
Block(1,32,-2,LEAVES_2:1)
Block(1,32,-1,LEAVES_2:1)
Block(1,32,0,LEAVES_2:1)
Block(1,32,1,LOG_2:1)
Block(1,32,2,LEAVES_2:1)
Block(1,32,3,LEAVES_2:1)
Block(1,32,4,LOG_2:1)
Block(1,32,5,LEAVES_2:1)
Block(1,32,7,LEAVES_2:1)
Block(1,32,8,LEAVES_2:1)
Block(1,33,-1,LEAVES_2:1)
Block(1,33,0,LEAVES_2:1)
Block(1,33,1,LEAVES_2:1)
Block(1,33,2,LEAVES_2:1)
Block(1,33,3,LOG_2:1)
Block(1,33,4,LOG_2:1)
Block(1,33,5,LEAVES_2:1)
Block(1,34,-4,LEAVES_2:1)
Block(1,34,0,LEAVES_2:1)
Block(1,34,1,LEAVES_2:1)
Block(1,34,2,LEAVES_2:1)
Block(1,34,3,LOG_2:1)
Block(1,34,4,LEAVES_2:1)
Block(1,34,5,LEAVES_2:1)
Block(1,35,-5,LEAVES_2:1)
Block(1,35,-4,LEAVES_2:1)
Block(1,35,-3,LEAVES_2:1)
Block(1,35,-2,LEAVES_2:1)
Block(1,35,-1,LEAVES_2:1)
Block(1,35,0,LEAVES_2:1)
Block(1,35,1,LEAVES_2:1)
Block(1,35,2,LEAVES_2:1)
Block(1,35,4,LEAVES_2:1)
Block(1,35,5,LEAVES_2:1)
Block(1,36,-3,LEAVES_2:1)
Block(1,36,-2,LOG_2:1)
Block(1,36,-1,LEAVES_2:1)
Block(1,36,0,LEAVES_2:1)
Block(1,36,1,LEAVES_2:1)
Block(1,36,8,LEAVES_2:1)
Block(1,37,-5,LEAVES_2:1)
Block(1,37,-4,LEAVES_2:1)
Block(1,37,-3,LEAVES_2:1)
Block(1,37,-2,LEAVES_2:1)
Block(1,37,-1,LEAVES_2:1)
Block(1,37,4,LEAVES_2:1)
Block(1,37,5,LEAVES_2:1)
Block(1,37,6,LEAVES_2:1)
Block(1,37,8,LEAVES_2:1)
Block(1,37,9,LEAVES_2:1)
Block(1,37,10,LEAVES_2:1)
Block(1,38,-4,LEAVES_2:1)
Block(1,38,-3,LEAVES_2:1)
Block(1,38,-2,LEAVES_2:1)
Block(1,38,-1,LEAVES_2:1)
Block(1,38,0,LEAVES_2:1)
Block(1,38,1,LEAVES_2:1)
Block(1,38,3,LOG_2:1)
Block(1,38,4,LEAVES_2:1)
Block(1,38,5,LEAVES_2:1)
Block(1,38,6,LOG_2:1)
Block(1,38,7,LOG_2:1)
Block(1,38,8,LOG_2:1)
Block(1,39,-3,LEAVES_2:1)
Block(1,39,-2,LEAVES_2:1)
Block(1,39,-1,LEAVES_2:1)
Block(1,39,0,LOG_2:1)
Block(1,39,1,LEAVES_2:1)
Block(1,39,2,LEAVES_2:1)
Block(1,39,3,LEAVES_2:1)
Block(1,39,4,LEAVES_2:1)
Block(1,39,5,LEAVES_2:1)
Block(1,39,6,LOG_2:1)
Block(1,39,7,LEAVES_2:1)
Block(1,39,8,LEAVES_2:1)
Block(1,40,-3,LEAVES_2:1)
Block(1,40,-2,LEAVES_2:1)
Block(1,40,-1,LOG_2:1)
Block(1,40,0,LOG_2:1)
Block(1,40,1,LEAVES_2:1)
Block(1,40,2,LEAVES_2:1)
Block(1,40,3,LEAVES_2:1)
Block(1,40,4,LEAVES_2:1)
Block(1,40,5,LEAVES_2:1)
Block(1,40,6,LEAVES_2:1)
Block(1,40,7,LEAVES_2:1)
Block(1,40,8,LEAVES_2:1)
Block(1,41,-3,LEAVES_2:1)
Block(1,41,-2,LEAVES_2:1)
Block(1,41,-1,LEAVES_2:1)
Block(1,41,0,LOG_2:1)
Block(1,41,1,LOG_2:1)
Block(1,41,3,LEAVES_2:1)
Block(1,41,4,LEAVES_2:1)
Block(1,41,5,LEAVES_2:1)
Block(1,41,6,LOG_2:1)
Block(1,41,7,LOG_2:1)
Block(1,41,8,LOG_2:1)
Block(1,41,9,LEAVES_2:1)
Block(1,42,-3,LEAVES_2:1)
Block(1,42,-2,LEAVES_2:1)
Block(1,42,-1,LEAVES_2:1)
Block(1,42,0,LEAVES_2:1)
Block(1,42,2,LOG_2:1)
Block(1,42,3,LEAVES_2:1)
Block(1,42,5,LEAVES_2:1)
Block(1,42,6,LOG_2:1)
Block(1,42,7,LOG_2:1)
Block(1,42,8,LEAVES_2:1)
Block(1,43,-4,LEAVES_2:1)
Block(1,43,-3,LEAVES_2:1)
Block(1,43,-2,LEAVES_2:1)
Block(1,43,-1,LEAVES_2:1)
Block(1,43,2,LEAVES_2:1)
Block(1,43,3,LEAVES_2:1)
Block(1,43,4,LEAVES_2:1)
Block(1,43,5,LOG_2:1)
Block(1,43,6,LEAVES_2:1)
Block(1,44,-4,LEAVES_2:1)
Block(1,44,-3,LEAVES_2:1)
Block(1,44,-2,LEAVES_2:1)
Block(1,44,0,LEAVES_2:1)
Block(1,44,2,LEAVES_2:1)
Block(1,44,3,LEAVES_2:1)
Block(1,44,4,LEAVES_2:1)
Block(1,44,5,LEAVES_2:1)
Block(1,44,6,LEAVES_2:1)
Block(1,44,7,LEAVES_2:1)
Block(1,45,-4,LEAVES_2:1)
Block(1,45,-2,LEAVES_2:1)
Block(1,45,-1,LEAVES_2:1)
Block(1,45,1,LEAVES_2:1)
Block(1,45,3,LEAVES_2:1)
Block(1,45,4,LEAVES_2:1)
Block(1,45,5,LEAVES_2:1)
Block(1,45,6,LEAVES_2:1)
Block(1,45,7,LEAVES_2:1)
Block(1,45,8,LEAVES_2:1)
Block(1,45,10,LEAVES_2:1)
Block(1,46,-3,LEAVES_2:1)
Block(1,46,-2,LEAVES_2:1)
Block(1,46,-1,LEAVES_2:1)
Block(1,46,0,LEAVES_2:1)
Block(1,46,1,LOG_2:1)
Block(1,46,2,LOG_2:1)
Block(1,46,3,LEAVES_2:1)
Block(1,46,4,LEAVES_2:1)
Block(1,46,5,LEAVES_2:1)
Block(1,46,6,LEAVES_2:1)
Block(1,46,8,LOG_2:1)
Block(1,46,9,LOG_2:1)
Block(1,46,10,LEAVES_2:1)
Block(1,47,-1,LEAVES_2:1)
Block(1,47,0,LEAVES_2:1)
Block(1,47,1,LEAVES_2:1)
Block(1,47,2,LEAVES_2:1)
Block(1,47,3,LOG_2:1)
Block(1,47,4,LEAVES_2:1)
Block(1,47,5,LOG_2:1)
Block(1,47,6,LEAVES_2:1)
Block(1,47,7,LEAVES_2:1)
Block(1,47,10,LEAVES_2:1)
Block(1,48,-2,LEAVES_2:1)
Block(1,48,-1,LEAVES_2:1)
Block(1,48,0,LEAVES_2:1)
Block(1,48,1,LEAVES_2:1)
Block(1,48,2,LEAVES_2:1)
Block(1,48,3,LEAVES_2:1)
Block(1,48,4,LEAVES_2:1)
Block(1,48,6,LEAVES_2:1)
Block(1,48,9,LEAVES_2:1)
Block(1,49,-1,LEAVES_2:1)
Block(1,49,0,LEAVES_2:1)
Block(1,49,1,LOG_2:1)
Block(1,49,2,LEAVES_2:1)
Block(1,49,3,LEAVES_2:1)
Block(1,49,4,LEAVES_2:1)
Block(1,49,5,LEAVES_2:1)
Block(1,49,6,LEAVES_2:1)
Block(1,49,7,LEAVES_2:1)
Block(1,49,8,LEAVES_2:1)
Block(1,50,-2,LEAVES_2:1)
Block(1,50,-1,LOG_2:1)
Block(1,50,0,LOG_2:1)
Block(1,50,1,LOG_2:1)
Block(1,50,2,LEAVES_2:1)
Block(1,50,4,LEAVES_2:1)
Block(1,50,5,LEAVES_2:1)
Block(1,50,6,LOG_2:1)
Block(1,50,7,LEAVES_2:1)
Block(1,50,8,LEAVES_2:1)
Block(1,51,-1,LEAVES_2:1)
Block(1,51,0,LOG_2:1)
Block(1,51,1,LOG_2:1)
Block(1,51,2,LOG_2:1)
Block(1,51,3,LEAVES_2:1)
Block(1,51,4,LEAVES_2:1)
Block(1,51,5,LEAVES_2:1)
Block(1,51,6,LOG_2:1)
Block(1,51,7,LEAVES_2:1)
Block(1,51,8,LEAVES_2:1)
Block(1,51,9,LEAVES_2:1)
Block(1,52,-2,LEAVES_2:1)
Block(1,52,-1,LEAVES_2:1)
Block(1,52,0,LEAVES_2:1)
Block(1,52,1,LEAVES_2:1)
Block(1,52,2,LEAVES_2:1)
Block(1,52,6,LEAVES_2:1)
Block(1,52,7,LEAVES_2:1)
Block(1,52,8,LEAVES_2:1)
Block(1,52,9,LEAVES_2:1)
Block(1,53,0,LEAVES_2:1)
Block(1,53,1,LEAVES_2:1)
Block(1,53,2,LEAVES_2:1)
Block(1,53,3,LEAVES_2:1)
Block(1,53,4,LEAVES_2:1)
Block(1,53,5,LEAVES_2:1)
Block(1,53,8,LEAVES_2:1)
Block(1,53,9,LEAVES_2:1)
Block(1,54,1,LEAVES_2:1)
Block(1,54,2,LEAVES_2:1)
Block(1,54,3,LEAVES_2:1)
Block(1,54,4,LEAVES_2:1)
Block(1,54,5,LEAVES_2:1)
Block(1,54,6,LEAVES_2:1)
Block(1,54,7,LEAVES_2:1)
Block(1,54,8,LEAVES_2:1)
Block(1,55,0,LEAVES_2:1)
Block(1,55,1,LEAVES_2:1)
Block(1,55,2,LOG_2:1)
Block(1,55,3,LEAVES_2:1)
Block(1,55,4,LEAVES_2:1)
Block(1,55,5,LEAVES_2:1)
Block(1,55,6,LEAVES_2:1)
Block(1,56,0,LEAVES_2:1)
Block(1,56,1,LEAVES_2:1)
Block(1,56,2,LEAVES_2:1)
Block(1,56,3,LEAVES_2:1)
Block(1,56,4,LEAVES_2:1)
Block(1,56,5,LEAVES_2:1)
Block(1,56,6,LEAVES_2:1)
Block(1,57,-1,LEAVES_2:1)
Block(1,57,0,LEAVES_2:1)
Block(1,57,1,LEAVES_2:1)
Block(1,57,2,LEAVES_2:1)
Block(1,57,3,LEAVES_2:1)
Block(1,57,4,LEAVES_2:1)
Block(1,57,5,LEAVES_2:1)
Block(1,58,1,LEAVES_2:1)
Block(1,58,3,LEAVES_2:1)
Block(1,58,4,LEAVES_2:1)
Block(1,58,5,LOG_2:1)
Block(1,58,6,LOG_2:1)
Block(1,59,0,LEAVES_2:1)
Block(1,59,1,LOG_2:1)
Block(1,59,2,LEAVES_2:1)
Block(1,59,3,LEAVES_2:1)
Block(1,59,4,LEAVES_2:1)
Block(1,59,5,LEAVES_2:1)
Block(1,60,0,LEAVES_2:1)
Block(1,60,1,LEAVES_2:1)
Block(1,60,2,LEAVES_2:1)
Block(1,60,4,LEAVES_2:1)
Block(1,60,5,LEAVES_2:1)
Block(1,61,1,LEAVES_2:1)
Block(1,61,3,LEAVES_2:1)
Block(1,61,4,LEAVES_2:1)
Block(1,62,1,LEAVES_2:1)
Block(1,62,2,LEAVES_2:1)
Block(1,62,3,LEAVES_2:1)
Block(1,63,1,LEAVES_2:1)
Block(1,63,2,LEAVES_2:1)
Block(1,63,3,LEAVES_2:1)
Block(1,64,1,LEAVES_2:1)
Block(1,64,2,LEAVES_2:1)
Block(1,64,3,LEAVES_2:1)
Block(1,65,2,LEAVES_2:1)
Block(1,66,3,LEAVES_2:1)
Block(1,67,2,LEAVES_2:1)
Block(1,68,2,LEAVES_2:1)
Block(1,68,3,LEAVES_2:1)
Block(2,0,1,LOG_2:1)
Block(2,0,2,LOG_2:1)
Block(2,0,3,LOG_2:1)
Block(2,0,4,LOG_2:1)
Block(2,0,5,LOG_2:1)
Block(2,1,1,LOG_2:1)
Block(2,1,2,LOG_2:1)
Block(2,1,3,LOG_2:1)
Block(2,1,4,LOG_2:1)
Block(2,1,5,HUGE_MUSHROOM_1)
Block(2,2,1,LOG_2:1)
Block(2,2,2,LOG_2:1)
Block(2,2,3,LOG_2:1)
Block(2,2,4,LOG_2:1)
Block(2,3,2,LOG_2:1)
Block(2,3,3,LOG_2:1)
Block(2,3,4,LOG_2:1)
Block(2,4,0,HUGE_MUSHROOM_1)
Block(2,4,1,HUGE_MUSHROOM_1)
Block(2,4,2,LOG_2:1)
Block(2,4,3,LOG_2:1)
Block(2,4,4,LOG_2:1)
Block(2,5,1,HUGE_MUSHROOM_1)
Block(2,5,2,LOG_2:1)
Block(2,5,3,LOG_2:1)
Block(2,5,4,LOG_2:1)
Block(2,6,2,LOG_2:1)
Block(2,6,3,LOG_2:1)
Block(2,6,4,LOG_2:1)
Block(2,7,2,LOG_2:1)
Block(2,7,3,LOG_2:1)
Block(2,7,4,LOG_2:1)
Block(2,7,5,LOG_2:1)
Block(2,8,2,LOG_2:1)
Block(2,8,3,LOG_2:1)
Block(2,8,4,LOG_2:1)
Block(2,9,2,LOG_2:1)
Block(2,9,3,LOG_2:1)
Block(2,9,4,LOG_2:1)
Block(2,10,1,HUGE_MUSHROOM_1)
Block(2,10,2,LOG_2:1)
Block(2,10,3,LOG_2:1)
Block(2,11,1,HUGE_MUSHROOM_1)
Block(2,11,2,LOG_2:1)
Block(2,11,3,LOG_2:1)
Block(2,12,2,HUGE_MUSHROOM_1)
Block(2,12,3,LOG_2:1)
Block(2,13,3,LOG_2:1)
Block(2,14,3,LOG_2:1)
Block(2,15,3,LOG_2:1)
Block(2,15,6,LEAVES_2:1)
Block(2,16,-1,LEAVES_2:1)
Block(2,16,0,LEAVES_2:1)
Block(2,16,1,LEAVES_2:1)
Block(2,16,3,LOG_2:1)
Block(2,16,4,LEAVES_2:1)
Block(2,16,5,LEAVES_2:1)
Block(2,16,6,LEAVES_2:1)
Block(2,16,7,LEAVES_2:1)
Block(2,17,-1,LEAVES_2:1)
Block(2,17,0,LOG_2:1)
Block(2,17,1,LOG_2:1)
Block(2,17,2,LEAVES_2:1)
Block(2,17,3,LOG_2:1)
Block(2,17,4,LOG_2:1)
Block(2,17,5,LOG_2:1)
Block(2,17,6,LEAVES_2:1)
Block(2,18,0,LEAVES_2:1)
Block(2,18,1,LOG_2:1)
Block(2,18,2,LEAVES_2:1)
Block(2,18,3,LOG_2:1)
Block(2,18,4,LEAVES_2:1)
Block(2,18,5,LEAVES_2:1)
Block(2,18,6,LEAVES_2:1)
Block(2,19,1,LEAVES_2:1)
Block(2,19,3,LOG_2:1)
Block(2,20,3,LOG_2:1)
Block(2,22,-2,LEAVES_2:1)
Block(2,22,-1,LEAVES_2:1)
Block(2,23,-4,LEAVES_2:1)
Block(2,23,-3,LEAVES_2:1)
Block(2,23,-2,LEAVES_2:1)
Block(2,23,-1,LEAVES_2:1)
Block(2,24,-7,LEAVES_2:1)
Block(2,24,-6,LEAVES_2:1)
Block(2,24,-5,LEAVES_2:1)
Block(2,24,-4,LEAVES_2:1)
Block(2,24,-3,LEAVES_2:1)
Block(2,24,-2,LOG_2:1)
Block(2,24,-1,LEAVES_2:1)
Block(2,24,0,LEAVES_2:1)
Block(2,24,10,LEAVES_2:1)
Block(2,25,-7,LEAVES_2:1)
Block(2,25,-6,LEAVES_2:1)
Block(2,25,-5,LEAVES_2:1)
Block(2,25,-4,LEAVES_2:1)
Block(2,25,-3,LEAVES_2:1)
Block(2,25,-2,LEAVES_2:1)
Block(2,25,-1,LEAVES_2:1)
Block(2,25,0,LOG_2:1)
Block(2,25,1,LOG_2:1)
Block(2,25,7,LEAVES_2:1)
Block(2,25,9,LOG_2:1)
Block(2,25,10,LOG_2:1)
Block(2,25,11,LEAVES_2:1)
Block(2,26,-7,LEAVES_2:1)
Block(2,26,-6,LEAVES_2:1)
Block(2,26,-5,LEAVES_2:1)
Block(2,26,-4,LEAVES_2:1)
Block(2,26,-3,LEAVES_2:1)
Block(2,26,-2,LEAVES_2:1)
Block(2,26,-1,LEAVES_2:1)
Block(2,26,0,LEAVES_2:1)
Block(2,26,1,LEAVES_2:1)
Block(2,26,2,LEAVES_2:1)
Block(2,26,5,LEAVES_2:1)
Block(2,26,6,LEAVES_2:1)
Block(2,26,7,LEAVES_2:1)
Block(2,26,8,LEAVES_2:1)
Block(2,26,9,LOG_2:1)
Block(2,26,10,LOG_2:1)
Block(2,26,11,LEAVES_2:1)
Block(2,26,12,LEAVES_2:1)
Block(2,27,-5,LEAVES_2:1)
Block(2,27,-4,LEAVES_2:1)
Block(2,27,-3,LEAVES_2:1)
Block(2,27,-2,LEAVES_2:1)
Block(2,27,-1,LEAVES_2:1)
Block(2,27,0,LEAVES_2:1)
Block(2,27,1,LEAVES_2:1)
Block(2,27,2,LOG_2:1)
Block(2,27,3,LEAVES_2:1)
Block(2,27,5,LOG_2:1)
Block(2,27,6,LOG_2:1)
Block(2,27,7,LEAVES_2:1)
Block(2,27,8,LEAVES_2:1)
Block(2,27,9,LOG_2:1)
Block(2,27,10,LEAVES_2:1)
Block(2,27,11,LEAVES_2:1)
Block(2,27,12,LEAVES_2:1)
Block(2,27,13,LEAVES_2:1)
Block(2,28,-5,LEAVES_2:1)
Block(2,28,-4,LEAVES_2:1)
Block(2,28,-3,LEAVES_2:1)
Block(2,28,-2,LEAVES_2:1)
Block(2,28,0,LEAVES_2:1)
Block(2,28,1,LEAVES_2:1)
Block(2,28,2,LOG_2:1)
Block(2,28,4,LOG_2:1)
Block(2,28,5,LOG_2:1)
Block(2,28,6,LOG_2:1)
Block(2,28,7,LEAVES_2:1)
Block(2,28,8,LEAVES_2:1)
Block(2,28,9,LOG_2:1)
Block(2,28,10,LEAVES_2:1)
Block(2,28,11,LEAVES_2:1)
Block(2,28,12,LEAVES_2:1)
Block(2,29,-4,LEAVES_2:1)
Block(2,29,-3,LEAVES_2:1)
Block(2,29,-2,LEAVES_2:1)
Block(2,29,-1,LEAVES_2:1)
Block(2,29,0,LEAVES_2:1)
Block(2,29,1,LEAVES_2:1)
Block(2,29,4,LOG_2:1)
Block(2,29,5,LOG_2:1)
Block(2,29,7,LEAVES_2:1)
Block(2,29,8,LEAVES_2:1)
Block(2,29,9,LOG_2:1)
Block(2,29,10,LEAVES_2:1)
Block(2,29,11,LEAVES_2:1)
Block(2,29,12,LEAVES_2:1)
Block(2,29,13,LEAVES_2:1)
Block(2,30,-4,LEAVES_2:1)
Block(2,30,-3,LEAVES_2:1)
Block(2,30,-2,LEAVES_2:1)
Block(2,30,-1,LEAVES_2:1)
Block(2,30,0,LEAVES_2:1)
Block(2,30,1,LEAVES_2:1)
Block(2,30,7,LEAVES_2:1)
Block(2,30,8,LEAVES_2:1)
Block(2,30,9,LEAVES_2:1)
Block(2,30,10,LEAVES_2:1)
Block(2,30,11,LEAVES_2:1)
Block(2,30,12,LEAVES_2:1)
Block(2,30,13,LEAVES_2:1)
Block(2,31,-3,LEAVES_2:1)
Block(2,31,-2,LEAVES_2:1)
Block(2,31,-1,LOG_2:1)
Block(2,31,0,LOG_2:1)
Block(2,31,1,LEAVES_2:1)
Block(2,31,2,LEAVES_2:1)
Block(2,31,3,LEAVES_2:1)
Block(2,31,7,LEAVES_2:1)
Block(2,31,8,LEAVES_2:1)
Block(2,31,9,LEAVES_2:1)
Block(2,31,10,LEAVES_2:1)
Block(2,31,11,LOG_2:1)
Block(2,31,13,LEAVES_2:1)
Block(2,32,-4,LEAVES_2:1)
Block(2,32,-3,LEAVES_2:1)
Block(2,32,-2,LEAVES_2:1)
Block(2,32,-1,LEAVES_2:1)
Block(2,32,0,LOG_2:1)
Block(2,32,1,LOG_2:1)
Block(2,32,2,LOG_2:1)
Block(2,32,3,LOG_2:1)
Block(2,32,4,LOG_2:1)
Block(2,32,7,LEAVES_2:1)
Block(2,32,8,LEAVES_2:1)
Block(2,33,-3,LEAVES_2:1)
Block(2,33,-2,LEAVES_2:1)
Block(2,33,-1,LEAVES_2:1)
Block(2,33,0,LEAVES_2:1)
Block(2,33,1,LEAVES_2:1)
Block(2,33,2,LEAVES_2:1)
Block(2,33,3,LOG_2:1)
Block(2,33,4,LEAVES_2:1)
Block(2,33,5,LEAVES_2:1)
Block(2,33,8,LEAVES_2:1)
Block(2,33,9,LEAVES_2:1)
Block(2,34,-4,LEAVES_2:1)
Block(2,34,-3,LEAVES_2:1)
Block(2,34,-2,LEAVES_2:1)
Block(2,34,0,LEAVES_2:1)
Block(2,34,1,LEAVES_2:1)
Block(2,34,2,LEAVES_2:1)
Block(2,34,3,LOG_2:1)
Block(2,34,4,LEAVES_2:1)
Block(2,34,8,LEAVES_2:1)
Block(2,35,-5,LEAVES_2:1)
Block(2,35,-4,LEAVES_2:1)
Block(2,35,-3,LEAVES_2:1)
Block(2,35,-1,LEAVES_2:1)
Block(2,35,3,LEAVES_2:1)
Block(2,35,4,LEAVES_2:1)
Block(2,36,-4,LEAVES_2:1)
Block(2,36,-3,LOG_2:1)
Block(2,36,-2,LOG_2:1)
Block(2,36,-1,LOG_2:1)
Block(2,36,1,LEAVES_2:1)
Block(2,36,2,LEAVES_2:1)
Block(2,37,-5,LEAVES_2:1)
Block(2,37,-4,LEAVES_2:1)
Block(2,37,-3,LEAVES_2:1)
Block(2,37,-2,LEAVES_2:1)
Block(2,37,-1,LOG_2:1)
Block(2,37,4,LEAVES_2:1)
Block(2,37,5,LEAVES_2:1)
Block(2,37,6,LEAVES_2:1)
Block(2,37,7,LEAVES_2:1)
Block(2,37,9,LEAVES_2:1)
Block(2,38,-4,LEAVES_2:1)
Block(2,38,-3,LEAVES_2:1)
Block(2,38,-2,LEAVES_2:1)
Block(2,38,3,LOG_2:1)
Block(2,38,4,LEAVES_2:1)
Block(2,38,5,LEAVES_2:1)
Block(2,38,6,LEAVES_2:1)
Block(2,38,7,LEAVES_2:1)
Block(2,38,8,LEAVES_2:1)
Block(2,38,9,LEAVES_2:1)
Block(2,39,-4,LEAVES_2:1)
Block(2,39,-3,LEAVES_2:1)
Block(2,39,-2,LEAVES_2:1)
Block(2,39,0,LEAVES_2:1)
Block(2,39,1,LEAVES_2:1)
Block(2,39,2,LOG_2:1)
Block(2,39,3,LOG_2:1)
Block(2,39,4,LOG_2:1)
Block(2,39,5,LOG_2:1)
Block(2,39,6,LOG_2:1)
Block(2,39,7,LEAVES_2:1)
Block(2,39,8,LEAVES_2:1)
Block(2,40,-4,LEAVES_2:1)
Block(2,40,-3,LEAVES_2:1)
Block(2,40,0,LEAVES_2:1)
Block(2,40,1,LEAVES_2:1)
Block(2,40,2,LOG_2:1)
Block(2,40,3,LEAVES_2:1)
Block(2,40,4,LOG_2:1)
Block(2,40,5,LOG_2:1)
Block(2,40,6,LEAVES_2:1)
Block(2,40,7,LEAVES_2:1)
Block(2,41,-5,LEAVES_2:1)
Block(2,41,-3,LEAVES_2:1)
Block(2,41,-2,LEAVES_2:1)
Block(2,41,0,LEAVES_2:1)
Block(2,41,1,LOG_2:1)
Block(2,41,2,LEAVES_2:1)
Block(2,41,3,LEAVES_2:1)
Block(2,41,4,LEAVES_2:1)
Block(2,41,5,LEAVES_2:1)
Block(2,41,6,LEAVES_2:1)
Block(2,41,7,LEAVES_2:1)
Block(2,41,9,LEAVES_2:1)
Block(2,42,-3,LEAVES_2:1)
Block(2,42,-2,LEAVES_2:1)
Block(2,42,1,LEAVES_2:1)
Block(2,42,2,LOG_2:1)
Block(2,42,3,LEAVES_2:1)
Block(2,42,4,LEAVES_2:1)
Block(2,42,5,LEAVES_2:1)
Block(2,42,6,LOG_2:1)
Block(2,42,7,LEAVES_2:1)
Block(2,42,8,LEAVES_2:1)
Block(2,43,-4,LEAVES_2:1)
Block(2,43,-3,LEAVES_2:1)
Block(2,43,-2,LEAVES_2:1)
Block(2,43,-1,LEAVES_2:1)
Block(2,43,1,LEAVES_2:1)
Block(2,43,2,LEAVES_2:1)
Block(2,43,3,LEAVES_2:1)
Block(2,43,4,LOG_2:1)
Block(2,43,5,LOG_2:1)
Block(2,43,6,LOG_2:1)
Block(2,43,7,LEAVES_2:1)
Block(2,43,8,LEAVES_2:1)
Block(2,44,-5,LEAVES_2:1)
Block(2,44,-4,LEAVES_2:1)
Block(2,44,-3,LEAVES_2:1)
Block(2,44,-2,LOG_2:1)
Block(2,44,-1,LEAVES_2:1)
Block(2,44,0,LEAVES_2:1)
Block(2,44,1,LEAVES_2:1)
Block(2,44,3,LEAVES_2:1)
Block(2,44,4,LEAVES_2:1)
Block(2,44,5,LEAVES_2:1)
Block(2,44,6,LEAVES_2:1)
Block(2,44,7,LEAVES_2:1)
Block(2,45,-3,LEAVES_2:1)
Block(2,45,-2,LEAVES_2:1)
Block(2,45,-1,LEAVES_2:1)
Block(2,45,0,LEAVES_2:1)
Block(2,45,1,LEAVES_2:1)
Block(2,45,2,LEAVES_2:1)
Block(2,45,3,LEAVES_2:1)
Block(2,45,4,LEAVES_2:1)
Block(2,45,5,LEAVES_2:1)
Block(2,45,6,LEAVES_2:1)
Block(2,45,7,LEAVES_2:1)
Block(2,46,-4,LEAVES_2:1)
Block(2,46,-3,LEAVES_2:1)
Block(2,46,-2,LEAVES_2:1)
Block(2,46,-1,LEAVES_2:1)
Block(2,46,0,LEAVES_2:1)
Block(2,46,1,LOG_2:1)
Block(2,46,2,LOG_2:1)
Block(2,46,5,LEAVES_2:1)
Block(2,46,6,LOG_2:1)
Block(2,46,7,LOG_2:1)
Block(2,46,8,LOG_2:1)
Block(2,46,9,LEAVES_2:1)
Block(2,46,10,LEAVES_2:1)
Block(2,47,-3,LEAVES_2:1)
Block(2,47,-1,LEAVES_2:1)
Block(2,47,0,LEAVES_2:1)
Block(2,47,1,LOG_2:1)
Block(2,47,2,LOG_2:1)
Block(2,47,3,LOG_2:1)
Block(2,47,5,LOG_2:1)
Block(2,47,6,LOG_2:1)
Block(2,47,7,LOG_2:1)
Block(2,47,8,LEAVES_2:1)
Block(2,47,9,LEAVES_2:1)
Block(2,47,10,LEAVES_2:1)
Block(2,48,-2,LEAVES_2:1)
Block(2,48,0,LEAVES_2:1)
Block(2,48,1,LEAVES_2:1)
Block(2,48,2,LOG_2:1)
Block(2,48,3,LEAVES_2:1)
Block(2,48,4,LOG_2:1)
Block(2,48,5,LEAVES_2:1)
Block(2,48,6,LEAVES_2:1)
Block(2,48,7,LEAVES_2:1)
Block(2,48,8,LEAVES_2:1)
Block(2,48,9,LEAVES_2:1)
Block(2,49,-2,LEAVES_2:1)
Block(2,49,-1,LEAVES_2:1)
Block(2,49,0,LEAVES_2:1)
Block(2,49,1,LEAVES_2:1)
Block(2,49,2,LEAVES_2:1)
Block(2,49,3,LEAVES_2:1)
Block(2,49,4,LEAVES_2:1)
Block(2,49,5,LEAVES_2:1)
Block(2,49,6,LEAVES_2:1)
Block(2,49,7,LEAVES_2:1)
Block(2,49,8,LEAVES_2:1)
Block(2,50,-2,LEAVES_2:1)
Block(2,50,-1,LEAVES_2:1)
Block(2,50,0,LEAVES_2:1)
Block(2,50,1,LEAVES_2:1)
Block(2,50,2,LEAVES_2:1)
Block(2,50,3,LOG_2:1)
Block(2,50,4,LEAVES_2:1)
Block(2,50,5,LEAVES_2:1)
Block(2,50,6,LEAVES_2:1)
Block(2,50,7,LEAVES_2:1)
Block(2,50,8,LEAVES_2:1)
Block(2,51,-1,LEAVES_2:1)
Block(2,51,0,LEAVES_2:1)
Block(2,51,1,LOG_2:1)
Block(2,51,2,LOG_2:1)
Block(2,51,3,LOG_2:1)
Block(2,51,4,LEAVES_2:1)
Block(2,51,5,LOG_2:1)
Block(2,51,6,LOG_2:1)
Block(2,51,7,LEAVES_2:1)
Block(2,52,-1,LEAVES_2:1)
Block(2,52,0,LOG_2:1)
Block(2,52,1,LOG_2:1)
Block(2,52,2,LEAVES_2:1)
Block(2,52,3,LEAVES_2:1)
Block(2,52,4,LOG_2:1)
Block(2,52,5,LEAVES_2:1)
Block(2,52,6,LEAVES_2:1)
Block(2,52,7,LEAVES_2:1)
Block(2,52,8,LEAVES_2:1)
Block(2,52,9,LEAVES_2:1)
Block(2,53,-1,LEAVES_2:1)
Block(2,53,0,LEAVES_2:1)
Block(2,53,1,LEAVES_2:1)
Block(2,53,2,LOG_2:1)
Block(2,53,3,LEAVES_2:1)
Block(2,53,4,LEAVES_2:1)
Block(2,53,5,LEAVES_2:1)
Block(2,53,7,LEAVES_2:1)
Block(2,53,8,LEAVES_2:1)
Block(2,53,9,LEAVES_2:1)
Block(2,54,0,LEAVES_2:1)
Block(2,54,1,LEAVES_2:1)
Block(2,54,2,LOG_2:1)
Block(2,54,3,LEAVES_2:1)
Block(2,54,4,LEAVES_2:1)
Block(2,54,5,LEAVES_2:1)
Block(2,54,6,LEAVES_2:1)
Block(2,54,7,LEAVES_2:1)
Block(2,55,-1,LEAVES_2:1)
Block(2,55,0,LEAVES_2:1)
Block(2,55,1,LOG_2:1)
Block(2,55,2,LOG_2:1)
Block(2,55,3,LOG_2:1)
Block(2,55,4,LEAVES_2:1)
Block(2,55,5,LOG_2:1)
Block(2,55,6,LEAVES_2:1)
Block(2,56,-1,LEAVES_2:1)
Block(2,56,0,LEAVES_2:1)
Block(2,56,1,LEAVES_2:1)
Block(2,56,2,LEAVES_2:1)
Block(2,56,4,LEAVES_2:1)
Block(2,56,5,LEAVES_2:1)
Block(2,56,6,LEAVES_2:1)
Block(2,56,7,LEAVES_2:1)
Block(2,57,-1,LEAVES_2:1)
Block(2,57,0,LEAVES_2:1)
Block(2,57,1,LEAVES_2:1)
Block(2,57,2,LEAVES_2:1)
Block(2,57,3,LEAVES_2:1)
Block(2,57,4,LEAVES_2:1)
Block(2,57,5,LEAVES_2:1)
Block(2,57,6,LEAVES_2:1)
Block(2,58,0,LEAVES_2:1)
Block(2,58,1,LEAVES_2:1)
Block(2,58,2,LEAVES_2:1)
Block(2,58,3,LEAVES_2:1)
Block(2,58,4,LOG_2:1)
Block(2,58,5,LOG_2:1)
Block(2,59,-1,LEAVES_2:1)
Block(2,59,0,LOG_2:1)
Block(2,59,1,LOG_2:1)
Block(2,59,2,LOG_2:1)
Block(2,59,3,LEAVES_2:1)
Block(2,59,4,LEAVES_2:1)
Block(2,59,5,LEAVES_2:1)
Block(2,60,0,LEAVES_2:1)
Block(2,60,1,LEAVES_2:1)
Block(2,60,2,LEAVES_2:1)
Block(2,60,3,LEAVES_2:1)
Block(2,60,4,LEAVES_2:1)
Block(2,60,5,LEAVES_2:1)
Block(2,60,6,LEAVES_2:1)
Block(2,61,1,LEAVES_2:1)
Block(2,61,2,LEAVES_2:1)
Block(2,61,4,LEAVES_2:1)
Block(2,61,5,LEAVES_2:1)
Block(2,61,6,LEAVES_2:1)
Block(2,62,0,LEAVES_2:1)
Block(2,62,1,LEAVES_2:1)
Block(2,62,2,LEAVES_2:1)
Block(2,62,3,LEAVES_2:1)
Block(2,62,5,LEAVES_2:1)
Block(2,63,0,LEAVES_2:1)
Block(2,63,1,LEAVES_2:1)
Block(2,63,2,LEAVES_2:1)
Block(2,63,3,LEAVES_2:1)
Block(2,63,4,LEAVES_2:1)
Block(2,64,0,LEAVES_2:1)
Block(2,64,1,LEAVES_2:1)
Block(2,64,2,LEAVES_2:1)
Block(2,64,3,LEAVES_2:1)
Block(2,64,4,LEAVES_2:1)
Block(2,65,0,LEAVES_2:1)
Block(2,65,2,LEAVES_2:1)
Block(2,65,3,LEAVES_2:1)
Block(2,65,4,LEAVES_2:1)
Block(2,66,1,LEAVES_2:1)
Block(2,66,2,LEAVES_2:1)
Block(2,66,3,LEAVES_2:1)
Block(2,66,4,LEAVES_2:1)
Block(2,67,2,LEAVES_2:1)
Block(2,67,3,LEAVES_2:1)
Block(2,67,4,LEAVES_2:1)
Block(2,68,2,LEAVES_2:1)
Block(2,68,3,LEAVES_2:1)
Block(2,68,4,LEAVES_2:1)
Block(2,68,5,LEAVES_2:1)
Block(2,69,2,LEAVES_2:1)
Block(2,69,3,LEAVES_2:1)
Block(3,0,0,LOG_2:1)
Block(3,0,1,LOG_2:1)
Block(3,0,2,LOG_2:1)
Block(3,0,3,LOG_2:1)
Block(3,0,4,LOG_2:1)
Block(3,0,5,LOG_2:1)
Block(3,0,6,LOG_2:1)
Block(3,1,0,LOG_2:1)
Block(3,1,1,LOG_2:1)
Block(3,1,2,LOG_2:1)
Block(3,1,3,LOG_2:1)
Block(3,1,4,LOG_2:1)
Block(3,1,5,LOG_2:1)
Block(3,2,1,LOG_2:1)
Block(3,2,2,LOG_2:1)
Block(3,2,3,LOG_2:1)
Block(3,2,4,LOG_2:1)
Block(3,2,5,LOG_2:1)
Block(3,3,1,LOG_2:1)
Block(3,3,2,LOG_2:1)
Block(3,3,3,LOG_2:1)
Block(3,3,4,LOG_2:1)
Block(3,3,5,LOG_2:1)
Block(3,4,0,HUGE_MUSHROOM_1)
Block(3,4,1,LOG_2:1)
Block(3,4,2,LOG_2:1)
Block(3,4,3,LOG_2:1)
Block(3,4,4,LOG_2:1)
Block(3,4,5,LOG_2:1)
Block(3,5,1,LOG_2:1)
Block(3,5,2,LOG_2:1)
Block(3,5,3,LOG_2:1)
Block(3,5,4,LOG_2:1)
Block(3,5,5,LOG_2:1)
Block(3,6,1,LOG_2:1)
Block(3,6,2,LOG_2:1)
Block(3,6,3,LOG_2:1)
Block(3,6,4,LOG_2:1)
Block(3,6,5,LOG_2:1)
Block(3,7,1,LOG_2:1)
Block(3,7,2,LOG_2:1)
Block(3,7,3,LOG_2:1)
Block(3,7,4,LOG_2:1)
Block(3,7,5,LOG_2:1)
Block(3,8,1,LOG_2:1)
Block(3,8,2,LOG_2:1)
Block(3,8,3,LOG_2:1)
Block(3,8,4,LOG_2:1)
Block(3,8,5,LOG_2:1)
Block(3,9,1,LOG_2:1)
Block(3,9,2,LOG_2:1)
Block(3,9,3,LOG_2:1)
Block(3,9,4,LOG_2:1)
Block(3,9,5,LOG_2:1)
Block(3,10,1,LOG_2:1)
Block(3,10,2,LOG_2:1)
Block(3,10,3,LOG_2:1)
Block(3,10,4,LOG_2:1)
Block(3,10,5,LOG_2:1)
Block(3,11,1,LOG_2:1)
Block(3,11,2,LOG_2:1)
Block(3,11,3,LOG_2:1)
Block(3,11,4,LOG_2:1)
Block(3,12,1,LOG_2:1)
Block(3,12,2,LOG_2:1)
Block(3,12,3,LOG_2:1)
Block(3,12,4,LOG_2:1)
Block(3,13,2,LOG_2:1)
Block(3,13,3,LOG_2:1)
Block(3,13,4,LOG_2:1)
Block(3,14,2,LOG_2:1)
Block(3,14,3,LOG_2:1)
Block(3,14,4,LOG_2:1)
Block(3,15,2,LOG_2:1)
Block(3,15,3,LOG_2:1)
Block(3,15,4,LOG_2:1)
Block(3,16,2,LOG_2:1)
Block(3,16,3,LOG_2:1)
Block(3,16,4,LOG_2:1)
Block(3,17,0,LEAVES_2:1)
Block(3,17,1,LEAVES_2:1)
Block(3,17,2,LOG_2:1)
Block(3,17,3,LOG_2:1)
Block(3,17,4,LOG_2:1)
Block(3,17,5,LEAVES_2:1)
Block(3,18,0,LEAVES_2:1)
Block(3,18,1,LOG_2:1)
Block(3,18,2,LOG_2:1)
Block(3,18,3,LOG_2:1)
Block(3,18,4,LOG_2:1)
Block(3,18,5,LEAVES_2:1)
Block(3,19,1,LEAVES_2:1)
Block(3,19,2,LOG_2:1)
Block(3,19,3,LOG_2:1)
Block(3,19,4,LOG_2:1)
Block(3,20,2,LOG_2:1)
Block(3,20,3,LOG_2:1)
Block(3,20,4,LOG_2:1)
Block(3,21,2,LOG_2:1)
Block(3,21,3,LOG_2:1)
Block(3,21,4,LOG_2:1)
Block(3,22,2,LOG_2:1)
Block(3,22,3,LOG_2:1)
Block(3,22,4,LOG_2:1)
Block(3,23,-5,LEAVES_2:1)
Block(3,23,-4,LEAVES_2:1)
Block(3,23,-3,LEAVES_2:1)
Block(3,23,-2,LEAVES_2:1)
Block(3,23,-1,LEAVES_2:1)
Block(3,23,0,LEAVES_2:1)
Block(3,23,2,LOG_2:1)
Block(3,23,3,LOG_2:1)
Block(3,23,4,LOG_2:1)
Block(3,24,-7,LEAVES_2:1)
Block(3,24,-6,LEAVES_2:1)
Block(3,24,-5,LEAVES_2:1)
Block(3,24,-4,LOG_2:1)
Block(3,24,-3,LOG_2:1)
Block(3,24,-2,LOG_2:1)
Block(3,24,-1,LOG_2:1)
Block(3,24,0,LOG_2:1)
Block(3,24,2,LOG_2:1)
Block(3,24,3,LOG_2:1)
Block(3,24,4,LOG_2:1)
Block(3,24,9,LEAVES_2:1)
Block(3,24,10,LEAVES_2:1)
Block(3,25,-8,LEAVES_2:1)
Block(3,25,-7,LEAVES_2:1)
Block(3,25,-6,LEAVES_2:1)
Block(3,25,-5,LEAVES_2:1)
Block(3,25,-4,LOG_2:1)
Block(3,25,-3,LOG_2:1)
Block(3,25,-2,LEAVES_2:1)
Block(3,25,-1,LOG_2:1)
Block(3,25,0,LOG_2:1)
Block(3,25,1,LOG_2:1)
Block(3,25,2,LOG_2:1)
Block(3,25,3,LOG_2:1)
Block(3,25,4,LOG_2:1)
Block(3,25,7,LEAVES_2:1)
Block(3,25,8,LEAVES_2:1)
Block(3,25,9,LEAVES_2:1)
Block(3,26,-7,LEAVES_2:1)
Block(3,26,-6,LEAVES_2:1)
Block(3,26,-5,LEAVES_2:1)
Block(3,26,-4,LOG_2:1)
Block(3,26,-3,LOG_2:1)
Block(3,26,-2,LEAVES_2:1)
Block(3,26,-1,LEAVES_2:1)
Block(3,26,0,LOG_2:1)
Block(3,26,1,LOG_2:1)
Block(3,26,2,LOG_2:1)
Block(3,26,3,LOG_2:1)
Block(3,26,4,LOG_2:1)
Block(3,26,9,LEAVES_2:1)
Block(3,26,10,LOG_2:1)
Block(3,26,11,LEAVES_2:1)
Block(3,27,-6,LEAVES_2:1)
Block(3,27,-5,LEAVES_2:1)
Block(3,27,-4,LEAVES_2:1)
Block(3,27,-3,LEAVES_2:1)
Block(3,27,-2,LEAVES_2:1)
Block(3,27,-1,LEAVES_2:1)
Block(3,27,0,LOG_2:1)
Block(3,27,2,LOG_2:1)
Block(3,27,3,LOG_2:1)
Block(3,27,4,LOG_2:1)
Block(3,27,5,LOG_2:1)
Block(3,27,7,LEAVES_2:1)
Block(3,27,8,LEAVES_2:1)
Block(3,27,9,LEAVES_2:1)
Block(3,27,10,LEAVES_2:1)
Block(3,27,11,LEAVES_2:1)
Block(3,28,-5,LEAVES_2:1)
Block(3,28,-4,LEAVES_2:1)
Block(3,28,-3,LEAVES_2:1)
Block(3,28,-2,LEAVES_2:1)
Block(3,28,-1,LEAVES_2:1)
Block(3,28,0,LEAVES_2:1)
Block(3,28,1,LEAVES_2:1)
Block(3,28,2,LOG_2:1)
Block(3,28,3,LOG_2:1)
Block(3,28,4,LOG_2:1)
Block(3,28,5,LOG_2:1)
Block(3,28,7,LEAVES_2:1)
Block(3,28,8,LEAVES_2:1)
Block(3,28,9,LEAVES_2:1)
Block(3,28,10,LEAVES_2:1)
Block(3,28,11,LEAVES_2:1)
Block(3,29,-5,LEAVES_2:1)
Block(3,29,-4,LEAVES_2:1)
Block(3,29,-3,LEAVES_2:1)
Block(3,29,-1,LEAVES_2:1)
Block(3,29,0,LEAVES_2:1)
Block(3,29,1,LEAVES_2:1)
Block(3,29,2,LOG_2:1)
Block(3,29,3,LOG_2:1)
Block(3,29,4,LOG_2:1)
Block(3,29,5,LOG_2:1)
Block(3,29,7,LEAVES_2:1)
Block(3,29,8,LEAVES_2:1)
Block(3,29,9,LEAVES_2:1)
Block(3,29,10,LEAVES_2:1)
Block(3,29,11,LEAVES_2:1)
Block(3,29,12,LEAVES_2:1)
Block(3,30,-4,LEAVES_2:1)
Block(3,30,-3,LEAVES_2:1)
Block(3,30,-2,LEAVES_2:1)
Block(3,30,-1,LEAVES_2:1)
Block(3,30,0,LEAVES_2:1)
Block(3,30,1,LEAVES_2:1)
Block(3,30,2,LOG_2:1)
Block(3,30,3,LOG_2:1)
Block(3,30,4,LOG_2:1)
Block(3,30,8,LEAVES_2:1)
Block(3,30,9,LEAVES_2:1)
Block(3,30,10,LEAVES_2:1)
Block(3,30,11,LEAVES_2:1)
Block(3,30,12,LEAVES_2:1)
Block(3,30,13,LEAVES_2:1)
Block(3,31,-5,LEAVES_2:1)
Block(3,31,-4,LEAVES_2:1)
Block(3,31,-3,LEAVES_2:1)
Block(3,31,-2,LOG_2:1)
Block(3,31,-1,LOG_2:1)
Block(3,31,0,LEAVES_2:1)
Block(3,31,1,LEAVES_2:1)
Block(3,31,2,LOG_2:1)
Block(3,31,3,LOG_2:1)
Block(3,31,4,LOG_2:1)
Block(3,31,7,LEAVES_2:1)
Block(3,31,8,LEAVES_2:1)
Block(3,31,9,LEAVES_2:1)
Block(3,32,-4,LEAVES_2:1)
Block(3,32,-2,LEAVES_2:1)
Block(3,32,-1,LEAVES_2:1)
Block(3,32,0,LEAVES_2:1)
Block(3,32,1,LEAVES_2:1)
Block(3,32,2,LOG_2:1)
Block(3,32,3,LOG_2:1)
Block(3,32,4,LOG_2:1)
Block(3,32,7,LEAVES_2:1)
Block(3,32,8,LEAVES_2:1)
Block(3,32,9,LEAVES_2:1)
Block(3,33,-4,LEAVES_2:1)
Block(3,33,-3,LEAVES_2:1)
Block(3,33,-2,LEAVES_2:1)
Block(3,33,-1,LEAVES_2:1)
Block(3,33,0,LEAVES_2:1)
Block(3,33,1,LEAVES_2:1)
Block(3,33,2,LOG_2:1)
Block(3,33,3,LOG_2:1)
Block(3,33,4,LOG_2:1)
Block(3,33,5,LOG_2:1)
Block(3,33,6,LOG_2:1)
Block(3,33,7,LEAVES_2:1)
Block(3,33,9,LEAVES_2:1)
Block(3,34,-3,LEAVES_2:1)
Block(3,34,2,LOG_2:1)
Block(3,34,3,LOG_2:1)
Block(3,34,4,LOG_2:1)
Block(3,34,5,LOG_2:1)
Block(3,34,6,LOG_2:1)
Block(3,34,8,LEAVES_2:1)
Block(3,34,9,LEAVES_2:1)
Block(3,35,-4,LEAVES_2:1)
Block(3,35,-2,LEAVES_2:1)
Block(3,35,-1,LOG_2:1)
Block(3,35,2,LOG_2:1)
Block(3,35,3,LOG_2:1)
Block(3,35,4,LOG_2:1)
Block(3,35,7,LEAVES_2:1)
Block(3,35,8,LEAVES_2:1)
Block(3,35,9,LEAVES_2:1)
Block(3,36,-5,LEAVES_2:1)
Block(3,36,-4,LEAVES_2:1)
Block(3,36,-3,LEAVES_2:1)
Block(3,36,-2,LEAVES_2:1)
Block(3,36,-1,LOG_2:1)
Block(3,36,2,LOG_2:1)
Block(3,36,3,LOG_2:1)
Block(3,36,4,LOG_2:1)
Block(3,37,-5,LEAVES_2:1)
Block(3,37,-4,LEAVES_2:1)
Block(3,37,-3,LEAVES_2:1)
Block(3,37,-2,LEAVES_2:1)
Block(3,37,-1,LOG_2:1)
Block(3,37,0,LOG_2:1)
Block(3,37,1,LOG_2:1)
Block(3,37,2,LOG_2:1)
Block(3,37,3,LOG_2:1)
Block(3,37,4,LOG_2:1)
Block(3,38,-4,LEAVES_2:1)
Block(3,38,-3,LEAVES_2:1)
Block(3,38,2,LOG_2:1)
Block(3,38,3,LOG_2:1)
Block(3,38,4,LOG_2:1)
Block(3,38,5,LEAVES_2:1)
Block(3,38,7,LEAVES_2:1)
Block(3,39,-4,LEAVES_2:1)
Block(3,39,-3,LEAVES_2:1)
Block(3,39,2,LOG_2:1)
Block(3,39,3,LOG_2:1)
Block(3,39,4,LOG_2:1)
Block(3,39,5,LOG_2:1)
Block(3,39,6,LEAVES_2:1)
Block(3,39,8,LEAVES_2:1)
Block(3,39,9,LEAVES_2:1)
Block(3,40,-4,LEAVES_2:1)
Block(3,40,2,LOG_2:1)
Block(3,40,3,LOG_2:1)
Block(3,40,4,LOG_2:1)
Block(3,40,5,LEAVES_2:1)
Block(3,40,7,LEAVES_2:1)
Block(3,40,8,LEAVES_2:1)
Block(3,40,9,LEAVES_2:1)
Block(3,41,-5,LEAVES_2:1)
Block(3,41,-4,LEAVES_2:1)
Block(3,41,-3,LEAVES_2:1)
Block(3,41,-2,LEAVES_2:1)
Block(3,41,-1,LEAVES_2:1)
Block(3,41,1,LOG_2:1)
Block(3,41,2,LOG_2:1)
Block(3,41,3,LOG_2:1)
Block(3,41,4,LOG_2:1)
Block(3,41,5,LEAVES_2:1)
Block(3,41,6,LEAVES_2:1)
Block(3,41,7,LEAVES_2:1)
Block(3,41,8,LEAVES_2:1)
Block(3,42,-5,LEAVES_2:1)
Block(3,42,-3,LEAVES_2:1)
Block(3,42,-2,LEAVES_2:1)
Block(3,42,-1,LEAVES_2:1)
Block(3,42,1,LOG_2:1)
Block(3,42,2,LOG_2:1)
Block(3,42,3,LOG_2:1)
Block(3,42,4,LOG_2:1)
Block(3,42,5,LEAVES_2:1)
Block(3,42,6,LEAVES_2:1)
Block(3,42,7,LEAVES_2:1)
Block(3,42,8,LEAVES_2:1)
Block(3,43,-2,LEAVES_2:1)
Block(3,43,-1,LEAVES_2:1)
Block(3,43,0,LEAVES_2:1)
Block(3,43,1,LEAVES_2:1)
Block(3,43,2,LOG_2:1)
Block(3,43,3,LOG_2:1)
Block(3,43,4,LOG_2:1)
Block(3,43,5,LOG_2:1)
Block(3,43,6,LEAVES_2:1)
Block(3,43,7,LEAVES_2:1)
Block(3,43,8,LEAVES_2:1)
Block(3,44,-4,LEAVES_2:1)
Block(3,44,-3,LEAVES_2:1)
Block(3,44,-2,LOG_2:1)
Block(3,44,-1,LOG_2:1)
Block(3,44,0,LEAVES_2:1)
Block(3,44,1,LEAVES_2:1)
Block(3,44,2,LOG_2:1)
Block(3,44,3,LOG_2:1)
Block(3,44,4,LOG_2:1)
Block(3,44,5,LEAVES_2:1)
Block(3,44,6,LEAVES_2:1)
Block(3,44,7,LEAVES_2:1)
Block(3,44,8,LEAVES_2:1)
Block(3,45,-5,LEAVES_2:1)
Block(3,45,-4,LEAVES_2:1)
Block(3,45,-3,LEAVES_2:1)
Block(3,45,-2,LEAVES_2:1)
Block(3,45,0,LEAVES_2:1)
Block(3,45,1,LEAVES_2:1)
Block(3,45,2,LOG_2:1)
Block(3,45,3,LOG_2:1)
Block(3,45,4,LOG_2:1)
Block(3,45,5,LEAVES_2:1)
Block(3,45,6,LEAVES_2:1)
Block(3,45,7,LEAVES_2:1)
Block(3,46,-4,LEAVES_2:1)
Block(3,46,-3,LEAVES_2:1)
Block(3,46,-2,LEAVES_2:1)
Block(3,46,-1,LEAVES_2:1)
Block(3,46,0,LEAVES_2:1)
Block(3,46,1,LEAVES_2:1)
Block(3,46,2,LOG_2:1)
Block(3,46,3,LOG_2:1)
Block(3,46,4,LOG_2:1)
Block(3,46,5,LEAVES_2:1)
Block(3,46,6,LEAVES_2:1)
Block(3,46,7,LEAVES_2:1)
Block(3,46,8,LOG_2:1)
Block(3,46,9,LEAVES_2:1)
Block(3,46,10,LEAVES_2:1)
Block(3,47,-2,LEAVES_2:1)
Block(3,47,-1,LEAVES_2:1)
Block(3,47,0,LOG_2:1)
Block(3,47,1,LOG_2:1)
Block(3,47,2,LOG_2:1)
Block(3,47,3,LOG_2:1)
Block(3,47,4,LOG_2:1)
Block(3,47,5,LOG_2:1)
Block(3,47,6,LEAVES_2:1)
Block(3,47,7,LEAVES_2:1)
Block(3,47,8,LEAVES_2:1)
Block(3,47,9,LEAVES_2:1)
Block(3,48,-1,LEAVES_2:1)
Block(3,48,0,LEAVES_2:1)
Block(3,48,1,LEAVES_2:1)
Block(3,48,2,LOG_2:1)
Block(3,48,3,LOG_2:1)
Block(3,48,4,LOG_2:1)
Block(3,48,5,LOG_2:1)
Block(3,48,6,LOG_2:1)
Block(3,48,7,LEAVES_2:1)
Block(3,48,8,LEAVES_2:1)
Block(3,48,9,LEAVES_2:1)
Block(3,49,-3,LEAVES_2:1)
Block(3,49,-2,LEAVES_2:1)
Block(3,49,-1,LEAVES_2:1)
Block(3,49,0,LEAVES_2:1)
Block(3,49,1,LOG_2:1)
Block(3,49,2,LOG_2:1)
Block(3,49,3,LOG_2:1)
Block(3,49,4,LOG_2:1)
Block(3,49,5,LEAVES_2:1)
Block(3,49,6,LEAVES_2:1)
Block(3,49,7,LEAVES_2:1)
Block(3,49,8,LEAVES_2:1)
Block(3,50,-2,LEAVES_2:1)
Block(3,50,-1,LEAVES_2:1)
Block(3,50,0,LEAVES_2:1)
Block(3,50,1,LEAVES_2:1)
Block(3,50,2,LOG_2:1)
Block(3,50,3,LOG_2:1)
Block(3,50,4,LOG_2:1)
Block(3,50,5,LEAVES_2:1)
Block(3,50,6,LEAVES_2:1)
Block(3,50,7,LEAVES_2:1)
Block(3,50,8,LEAVES_2:1)
Block(3,51,-2,LEAVES_2:1)
Block(3,51,-1,LEAVES_2:1)
Block(3,51,0,LEAVES_2:1)
Block(3,51,1,LEAVES_2:1)
Block(3,51,2,LOG_2:1)
Block(3,51,3,LOG_2:1)
Block(3,51,4,LOG_2:1)
Block(3,51,5,LOG_2:1)
Block(3,51,6,LEAVES_2:1)
Block(3,51,7,LEAVES_2:1)
Block(3,51,8,LEAVES_2:1)
Block(3,52,-2,LEAVES_2:1)
Block(3,52,-1,LEAVES_2:1)
Block(3,52,0,LEAVES_2:1)
Block(3,52,1,LOG_2:1)
Block(3,52,2,LOG_2:1)
Block(3,52,3,LOG_2:1)
Block(3,52,4,LOG_2:1)
Block(3,52,5,LOG_2:1)
Block(3,52,6,LEAVES_2:1)
Block(3,52,7,LEAVES_2:1)
Block(3,52,8,LOG_2:1)
Block(3,52,9,LEAVES_2:1)
Block(3,53,-1,LEAVES_2:1)
Block(3,53,0,LEAVES_2:1)
Block(3,53,1,LEAVES_2:1)
Block(3,53,2,LOG_2:1)
Block(3,53,3,LOG_2:1)
Block(3,53,4,LOG_2:1)
Block(3,53,5,LEAVES_2:1)
Block(3,53,6,LEAVES_2:1)
Block(3,53,7,LEAVES_2:1)
Block(3,53,8,LOG_2:1)
Block(3,54,0,LEAVES_2:1)
Block(3,54,1,LEAVES_2:1)
Block(3,54,2,LOG_2:1)
Block(3,54,3,LOG_2:1)
Block(3,54,4,LOG_2:1)
Block(3,54,5,LEAVES_2:1)
Block(3,54,6,LEAVES_2:1)
Block(3,54,7,LEAVES_2:1)
Block(3,54,8,LEAVES_2:1)
Block(3,55,-1,LEAVES_2:1)
Block(3,55,0,LEAVES_2:1)
Block(3,55,1,LEAVES_2:1)
Block(3,55,2,LOG_2:1)
Block(3,55,3,LOG_2:1)
Block(3,55,4,LOG_2:1)
Block(3,55,5,LOG_2:1)
Block(3,55,6,LOG_2:1)
Block(3,55,7,LEAVES_2:1)
Block(3,56,-1,LEAVES_2:1)
Block(3,56,0,LEAVES_2:1)
Block(3,56,1,LOG_2:1)
Block(3,56,2,LOG_2:1)
Block(3,56,3,LOG_2:1)
Block(3,56,4,LOG_2:1)
Block(3,56,5,LOG_2:1)
Block(3,56,6,LEAVES_2:1)
Block(3,57,-2,LEAVES_2:1)
Block(3,57,-1,LEAVES_2:1)
Block(3,57,0,LEAVES_2:1)
Block(3,57,1,LEAVES_2:1)
Block(3,57,2,LOG_2:1)
Block(3,57,3,LOG_2:1)
Block(3,57,4,LOG_2:1)
Block(3,57,5,LEAVES_2:1)
Block(3,57,6,LEAVES_2:1)
Block(3,58,-1,LEAVES_2:1)
Block(3,58,0,LEAVES_2:1)
Block(3,58,1,LEAVES_2:1)
Block(3,58,2,LOG_2:1)
Block(3,58,3,LOG_2:1)
Block(3,58,4,LOG_2:1)
Block(3,58,5,LEAVES_2:1)
Block(3,58,6,LEAVES_2:1)
Block(3,59,-2,LEAVES_2:1)
Block(3,59,0,LEAVES_2:1)
Block(3,59,1,LEAVES_2:1)
Block(3,59,2,LOG_2:1)
Block(3,59,3,LOG_2:1)
Block(3,59,4,LOG_2:1)
Block(3,59,5,LEAVES_2:1)
Block(3,59,6,LEAVES_2:1)
Block(3,59,7,LEAVES_2:1)
Block(3,60,-1,LEAVES_2:1)
Block(3,60,0,LEAVES_2:1)
Block(3,60,1,LEAVES_2:1)
Block(3,60,2,LOG_2:1)
Block(3,60,3,LOG_2:1)
Block(3,60,4,LEAVES_2:1)
Block(3,60,5,LEAVES_2:1)
Block(3,60,7,LEAVES_2:1)
Block(3,61,0,LEAVES_2:1)
Block(3,61,1,LEAVES_2:1)
Block(3,61,2,LEAVES_2:1)
Block(3,61,3,LOG_2:1)
Block(3,61,4,LEAVES_2:1)
Block(3,61,5,LEAVES_2:1)
Block(3,61,7,LEAVES_2:1)
Block(3,62,1,LEAVES_2:1)
Block(3,62,2,LEAVES_2:1)
Block(3,62,3,LOG_2:1)
Block(3,62,4,LEAVES_2:1)
Block(3,62,5,LEAVES_2:1)
Block(3,63,1,LEAVES_2:1)
Block(3,63,2,LEAVES_2:1)
Block(3,63,3,LEAVES_2:1)
Block(3,63,4,LEAVES_2:1)
Block(3,64,1,LEAVES_2:1)
Block(3,64,2,LEAVES_2:1)
Block(3,64,3,LEAVES_2:1)
Block(3,64,4,LEAVES_2:1)
Block(3,65,0,LEAVES_2:1)
Block(3,65,1,LEAVES_2:1)
Block(3,65,2,LEAVES_2:1)
Block(3,65,3,LOG_2:1)
Block(3,65,4,LEAVES_2:1)
Block(3,66,0,LEAVES_2:1)
Block(3,66,1,LEAVES_2:1)
Block(3,66,2,LEAVES_2:1)
Block(3,66,3,LEAVES_2:1)
Block(3,66,4,LEAVES_2:1)
Block(3,66,5,LEAVES_2:1)
Block(3,67,1,LEAVES_2:1)
Block(3,67,2,LEAVES_2:1)
Block(3,67,3,LOG_2:1)
Block(3,67,4,LEAVES_2:1)
Block(3,67,5,LEAVES_2:1)
Block(3,68,1,LEAVES_2:1)
Block(3,68,2,LEAVES_2:1)
Block(3,68,3,LEAVES_2:1)
Block(3,68,4,LEAVES_2:1)
Block(3,68,5,LEAVES_2:1)
Block(3,69,1,LEAVES_2:1)
Block(3,69,2,LEAVES_2:1)
Block(3,69,3,LEAVES_2:1)
Block(3,69,4,LEAVES_2:1)
Block(3,70,1,LEAVES_2:1)
Block(3,70,2,LEAVES_2:1)
Block(3,70,3,LEAVES_2:1)
Block(3,71,2,LEAVES_2:1)
Block(4,0,0,LOG_2:1)
Block(4,0,1,LOG_2:1)
Block(4,0,2,LOG_2:1)
Block(4,1,0,LOG_2:1)
Block(4,1,1,LOG_2:1)
Block(4,1,2,LOG_2:1)
Block(4,2,0,LOG_2:1)
Block(4,2,1,LOG_2:1)
Block(4,2,2,LOG_2:1)
Block(4,2,3,LOG_2:1)
Block(4,2,4,LOG_2:1)
Block(4,2,5,LOG_2:1)
Block(4,2,6,LOG_2:1)
Block(4,3,1,LOG_2:1)
Block(4,3,2,LOG_2:1)
Block(4,3,3,LOG_2:1)
Block(4,3,4,LOG_2:1)
Block(4,3,5,LOG_2:1)
Block(4,4,1,LOG_2:1)
Block(4,4,2,LOG_2:1)
Block(4,4,3,LOG_2:1)
Block(4,4,4,LOG_2:1)
Block(4,4,5,LOG_2:1)
Block(4,5,1,LOG_2:1)
Block(4,5,2,LOG_2:1)
Block(4,5,3,LOG_2:1)
Block(4,5,4,LOG_2:1)
Block(4,5,5,LOG_2:1)
Block(4,5,6,HUGE_MUSHROOM_1)
Block(4,6,1,LOG_2:1)
Block(4,6,2,LOG_2:1)
Block(4,6,3,LOG_2:1)
Block(4,6,4,LOG_2:1)
Block(4,6,5,LOG_2:1)
Block(4,7,1,LOG_2:1)
Block(4,7,2,LOG_2:1)
Block(4,7,3,LOG_2:1)
Block(4,7,4,LOG_2:1)
Block(4,7,5,LOG_2:1)
Block(4,8,1,LOG_2:1)
Block(4,8,2,LOG_2:1)
Block(4,8,3,LOG_2:1)
Block(4,8,4,LOG_2:1)
Block(4,8,5,LOG_2:1)
Block(4,9,1,LOG_2:1)
Block(4,9,2,LOG_2:1)
Block(4,9,3,LOG_2:1)
Block(4,9,4,LOG_2:1)
Block(4,9,5,LOG_2:1)
Block(4,10,1,LOG_2:1)
Block(4,10,2,LOG_2:1)
Block(4,10,3,LOG_2:1)
Block(4,10,4,LOG_2:1)
Block(4,10,5,LOG_2:1)
Block(4,11,1,LOG_2:1)
Block(4,11,2,LOG_2:1)
Block(4,11,3,LOG_2:1)
Block(4,11,4,LOG_2:1)
Block(4,11,5,LOG_2:1)
Block(4,12,1,LOG_2:1)
Block(4,12,2,LOG_2:1)
Block(4,12,3,LOG_2:1)
Block(4,12,4,LOG_2:1)
Block(4,12,5,LOG_2:1)
Block(4,13,1,LOG_2:1)
Block(4,13,2,LOG_2:1)
Block(4,13,3,LOG_2:1)
Block(4,13,4,LOG_2:1)
Block(4,13,5,LOG_2:1)
Block(4,14,1,LOG_2:1)
Block(4,14,2,LOG_2:1)
Block(4,14,3,LOG_2:1)
Block(4,14,4,LOG_2:1)
Block(4,14,5,LOG_2:1)
Block(4,15,2,LOG_2:1)
Block(4,15,3,LOG_2:1)
Block(4,15,4,LOG_2:1)
Block(4,15,5,LOG_2:1)
Block(4,16,2,LOG_2:1)
Block(4,16,3,LOG_2:1)
Block(4,16,4,LOG_2:1)
Block(4,16,5,LOG_2:1)
Block(4,17,1,LEAVES_2:1)
Block(4,17,2,LOG_2:1)
Block(4,17,3,LOG_2:1)
Block(4,17,4,LOG_2:1)
Block(4,17,5,LOG_2:1)
Block(4,18,0,LEAVES_2:1)
Block(4,18,1,LEAVES_2:1)
Block(4,18,2,LOG_2:1)
Block(4,18,3,LOG_2:1)
Block(4,18,4,LOG_2:1)
Block(4,18,5,LOG_2:1)
Block(4,19,1,LEAVES_2:1)
Block(4,19,2,LOG_2:1)
Block(4,19,3,LOG_2:1)
Block(4,19,4,LOG_2:1)
Block(4,20,2,LOG_2:1)
Block(4,20,3,LOG_2:1)
Block(4,20,4,LOG_2:1)
Block(4,21,2,LOG_2:1)
Block(4,21,3,LOG_2:1)
Block(4,21,4,LOG_2:1)
Block(4,21,5,LEAVES_2:1)
Block(4,22,2,LOG_2:1)
Block(4,22,3,LOG_2:1)
Block(4,22,4,LOG_2:1)
Block(4,23,-6,LEAVES_2:1)
Block(4,23,-5,LEAVES_2:1)
Block(4,23,-4,LEAVES_2:1)
Block(4,23,2,LOG_2:1)
Block(4,23,3,LOG_2:1)
Block(4,23,4,LOG_2:1)
Block(4,24,-7,LEAVES_2:1)
Block(4,24,-6,LEAVES_2:1)
Block(4,24,-5,LOG_2:1)
Block(4,24,-4,LOG_2:1)
Block(4,24,-3,LOG_2:1)
Block(4,24,-2,LEAVES_2:1)
Block(4,24,-1,LEAVES_2:1)
Block(4,24,2,LOG_2:1)
Block(4,24,3,LOG_2:1)
Block(4,24,4,LOG_2:1)
Block(4,25,-7,LEAVES_2:1)
Block(4,25,-6,LEAVES_2:1)
Block(4,25,-5,LEAVES_2:1)
Block(4,25,-4,LOG_2:1)
Block(4,25,-3,LEAVES_2:1)
Block(4,25,-2,LEAVES_2:1)
Block(4,25,-1,LEAVES_2:1)
Block(4,25,0,LEAVES_2:1)
Block(4,25,1,LOG_2:1)
Block(4,25,2,LOG_2:1)
Block(4,25,3,LOG_2:1)
Block(4,25,4,LOG_2:1)
Block(4,25,8,LEAVES_2:1)
Block(4,25,9,LEAVES_2:1)
Block(4,25,10,LEAVES_2:1)
Block(4,26,-6,LEAVES_2:1)
Block(4,26,-5,LEAVES_2:1)
Block(4,26,-4,LEAVES_2:1)
Block(4,26,-3,LEAVES_2:1)
Block(4,26,-2,LEAVES_2:1)
Block(4,26,-1,LEAVES_2:1)
Block(4,26,0,LOG_2:1)
Block(4,26,1,LOG_2:1)
Block(4,26,2,LOG_2:1)
Block(4,26,3,LOG_2:1)
Block(4,26,4,LOG_2:1)
Block(4,26,8,LEAVES_2:1)
Block(4,26,9,LEAVES_2:1)
Block(4,26,10,LEAVES_2:1)
Block(4,27,-6,LEAVES_2:1)
Block(4,27,-5,LEAVES_2:1)
Block(4,27,-4,LEAVES_2:1)
Block(4,27,-3,LEAVES_2:1)
Block(4,27,-2,LEAVES_2:1)
Block(4,27,1,LOG_2:1)
Block(4,27,2,LOG_2:1)
Block(4,27,3,LOG_2:1)
Block(4,27,4,LOG_2:1)
Block(4,27,8,LEAVES_2:1)
Block(4,27,9,LEAVES_2:1)
Block(4,27,10,LEAVES_2:1)
Block(4,27,11,LEAVES_2:1)
Block(4,28,-4,LEAVES_2:1)
Block(4,28,-3,LEAVES_2:1)
Block(4,28,0,LEAVES_2:1)
Block(4,28,1,LOG_2:1)
Block(4,28,2,LOG_2:1)
Block(4,28,3,LOG_2:1)
Block(4,28,4,LOG_2:1)
Block(4,28,5,LOG_2:1)
Block(4,28,8,LEAVES_2:1)
Block(4,28,9,LEAVES_2:1)
Block(4,28,10,LEAVES_2:1)
Block(4,28,11,LEAVES_2:1)
Block(4,29,-5,LEAVES_2:1)
Block(4,29,-4,LEAVES_2:1)
Block(4,29,-3,LEAVES_2:1)
Block(4,29,1,LOG_2:1)
Block(4,29,2,LOG_2:1)
Block(4,29,3,LOG_2:1)
Block(4,29,4,LOG_2:1)
Block(4,29,8,LEAVES_2:1)
Block(4,29,9,LEAVES_2:1)
Block(4,29,10,LEAVES_2:1)
Block(4,29,11,LEAVES_2:1)
Block(4,30,-5,LEAVES_2:1)
Block(4,30,-4,LEAVES_2:1)
Block(4,30,-3,LEAVES_2:1)
Block(4,30,-2,LEAVES_2:1)
Block(4,30,-1,LEAVES_2:1)
Block(4,30,0,LEAVES_2:1)
Block(4,30,1,LEAVES_2:1)
Block(4,30,2,LOG_2:1)
Block(4,30,3,LOG_2:1)
Block(4,30,4,LOG_2:1)
Block(4,30,8,LEAVES_2:1)
Block(4,30,9,LEAVES_2:1)
Block(4,30,10,LEAVES_2:1)
Block(4,31,-4,LEAVES_2:1)
Block(4,31,-3,LEAVES_2:1)
Block(4,31,-2,LEAVES_2:1)
Block(4,31,-1,LEAVES_2:1)
Block(4,31,0,LEAVES_2:1)
Block(4,31,2,LOG_2:1)
Block(4,31,3,LOG_2:1)
Block(4,31,4,LOG_2:1)
Block(4,31,7,LEAVES_2:1)
Block(4,31,8,LEAVES_2:1)
Block(4,31,9,LEAVES_2:1)
Block(4,31,10,LEAVES_2:1)
Block(4,32,-4,LEAVES_2:1)
Block(4,32,-3,LEAVES_2:1)
Block(4,32,-2,LEAVES_2:1)
Block(4,32,-1,LEAVES_2:1)
Block(4,32,0,LEAVES_2:1)
Block(4,32,2,LOG_2:1)
Block(4,32,3,LOG_2:1)
Block(4,32,4,LOG_2:1)
Block(4,32,6,LEAVES_2:1)
Block(4,32,7,LOG_2:1)
Block(4,32,9,LEAVES_2:1)
Block(4,32,10,LEAVES_2:1)
Block(4,33,-3,LEAVES_2:1)
Block(4,33,-2,LEAVES_2:1)
Block(4,33,1,LOG_2:1)
Block(4,33,2,LOG_2:1)
Block(4,33,3,LOG_2:1)
Block(4,33,4,LOG_2:1)
Block(4,33,6,LOG_2:1)
Block(4,33,7,LOG_2:1)
Block(4,33,8,LOG_2:1)
Block(4,33,9,LOG_2:1)
Block(4,33,10,LEAVES_2:1)
Block(4,34,-4,LEAVES_2:1)
Block(4,34,-3,LEAVES_2:1)
Block(4,34,-2,LEAVES_2:1)
Block(4,34,-1,LEAVES_2:1)
Block(4,34,2,LOG_2:1)
Block(4,34,3,LOG_2:1)
Block(4,34,4,LOG_2:1)
Block(4,34,5,LOG_2:1)
Block(4,34,6,LEAVES_2:1)
Block(4,34,7,LEAVES_2:1)
Block(4,34,8,LEAVES_2:1)
Block(4,34,9,LEAVES_2:1)
Block(4,34,10,LEAVES_2:1)
Block(4,35,-3,LEAVES_2:1)
Block(4,35,-2,LEAVES_2:1)
Block(4,35,2,LOG_2:1)
Block(4,35,3,LOG_2:1)
Block(4,35,4,LOG_2:1)
Block(4,35,7,LEAVES_2:1)
Block(4,35,8,LEAVES_2:1)
Block(4,35,9,LEAVES_2:1)
Block(4,35,10,LEAVES_2:1)
Block(4,36,-3,LEAVES_2:1)
Block(4,36,-2,LEAVES_2:1)
Block(4,36,-1,LEAVES_2:1)
Block(4,36,0,LOG_2:1)
Block(4,36,1,LEAVES_2:1)
Block(4,36,2,LOG_2:1)
Block(4,36,3,LOG_2:1)
Block(4,36,4,LOG_2:1)
Block(4,36,10,LEAVES_2:1)
Block(4,37,-4,LEAVES_2:1)
Block(4,37,-3,LEAVES_2:1)
Block(4,37,-2,LEAVES_2:1)
Block(4,37,-1,LEAVES_2:1)
Block(4,37,1,LOG_2:1)
Block(4,37,2,LOG_2:1)
Block(4,37,3,LOG_2:1)
Block(4,37,4,LOG_2:1)
Block(4,37,6,LEAVES_2:1)
Block(4,37,8,LEAVES_2:1)
Block(4,38,-4,LEAVES_2:1)
Block(4,38,-3,LEAVES_2:1)
Block(4,38,2,LOG_2:1)
Block(4,38,3,LOG_2:1)
Block(4,38,4,LOG_2:1)
Block(4,38,5,LEAVES_2:1)
Block(4,38,6,LEAVES_2:1)
Block(4,38,7,LEAVES_2:1)
Block(4,38,8,LEAVES_2:1)
Block(4,38,9,LEAVES_2:1)
Block(4,39,-5,LEAVES_2:1)
Block(4,39,-4,LEAVES_2:1)
Block(4,39,-3,LEAVES_2:1)
Block(4,39,-2,LEAVES_2:1)
Block(4,39,2,LOG_2:1)
Block(4,39,3,LOG_2:1)
Block(4,39,4,LOG_2:1)
Block(4,39,5,LOG_2:1)
Block(4,39,6,LEAVES_2:1)
Block(4,39,8,LEAVES_2:1)
Block(4,39,9,LEAVES_2:1)
Block(4,40,-4,LEAVES_2:1)
Block(4,40,-2,LEAVES_2:1)
Block(4,40,2,LOG_2:1)
Block(4,40,3,LOG_2:1)
Block(4,40,4,LOG_2:1)
Block(4,40,5,LOG_2:1)
Block(4,40,6,LEAVES_2:1)
Block(4,40,7,LEAVES_2:1)
Block(4,40,8,LEAVES_2:1)
Block(4,40,9,LEAVES_2:1)
Block(4,41,-5,LEAVES_2:1)
Block(4,41,-4,LEAVES_2:1)
Block(4,41,-3,LOG_2:1)
Block(4,41,-2,LOG_2:1)
Block(4,41,-1,LOG_2:1)
Block(4,41,0,LOG_2:1)
Block(4,41,1,LOG_2:1)
Block(4,41,2,LOG_2:1)
Block(4,41,3,LOG_2:1)
Block(4,41,4,LOG_2:1)
Block(4,41,5,LOG_2:1)
Block(4,41,6,LEAVES_2:1)
Block(4,41,7,LEAVES_2:1)
Block(4,41,8,LEAVES_2:1)
Block(4,42,-5,LEAVES_2:1)
Block(4,42,-4,LEAVES_2:1)
Block(4,42,-3,LEAVES_2:1)
Block(4,42,-1,LEAVES_2:1)
Block(4,42,2,LOG_2:1)
Block(4,42,3,LOG_2:1)
Block(4,42,4,LOG_2:1)
Block(4,42,5,LEAVES_2:1)
Block(4,42,6,LEAVES_2:1)
Block(4,42,7,LEAVES_2:1)
Block(4,42,8,LEAVES_2:1)
Block(4,42,9,LEAVES_2:1)
Block(4,43,-4,LEAVES_2:1)
Block(4,43,-3,LEAVES_2:1)
Block(4,43,-2,LEAVES_2:1)
Block(4,43,-1,LEAVES_2:1)
Block(4,43,2,LOG_2:1)
Block(4,43,3,LOG_2:1)
Block(4,43,4,LOG_2:1)
Block(4,43,5,LOG_2:1)
Block(4,43,6,LOG_2:1)
Block(4,43,7,LEAVES_2:1)
Block(4,44,-3,LEAVES_2:1)
Block(4,44,-2,LEAVES_2:1)
Block(4,44,-1,LOG_2:1)
Block(4,44,0,LOG_2:1)
Block(4,44,1,LOG_2:1)
Block(4,44,2,LOG_2:1)
Block(4,44,3,LOG_2:1)
Block(4,44,4,LOG_2:1)
Block(4,44,5,LEAVES_2:1)
Block(4,44,6,LEAVES_2:1)
Block(4,44,7,LEAVES_2:1)
Block(4,44,8,LEAVES_2:1)
Block(4,45,-2,LEAVES_2:1)
Block(4,45,0,LOG_2:1)
Block(4,45,1,LOG_2:1)
Block(4,45,2,LOG_2:1)
Block(4,45,3,LOG_2:1)
Block(4,45,4,LOG_2:1)
Block(4,45,5,LOG_2:1)
Block(4,45,6,LEAVES_2:1)
Block(4,45,7,LEAVES_2:1)
Block(4,45,8,LEAVES_2:1)
Block(4,45,9,LEAVES_2:1)
Block(4,46,-1,LEAVES_2:1)
Block(4,46,0,LEAVES_2:1)
Block(4,46,1,LEAVES_2:1)
Block(4,46,2,LOG_2:1)
Block(4,46,3,LOG_2:1)
Block(4,46,4,LOG_2:1)
Block(4,46,6,LEAVES_2:1)
Block(4,46,7,LEAVES_2:1)
Block(4,46,8,LEAVES_2:1)
Block(4,46,9,LEAVES_2:1)
Block(4,46,10,LEAVES_2:1)
Block(4,47,-1,LEAVES_2:1)
Block(4,47,0,LEAVES_2:1)
Block(4,47,2,LOG_2:1)
Block(4,47,3,LOG_2:1)
Block(4,47,4,LOG_2:1)
Block(4,47,5,LEAVES_2:1)
Block(4,47,6,LEAVES_2:1)
Block(4,47,8,LEAVES_2:1)
Block(4,47,10,LEAVES_2:1)
Block(4,48,-2,LEAVES_2:1)
Block(4,48,-1,LEAVES_2:1)
Block(4,48,0,LEAVES_2:1)
Block(4,48,2,LOG_2:1)
Block(4,48,3,LOG_2:1)
Block(4,48,4,LOG_2:1)
Block(4,48,5,LEAVES_2:1)
Block(4,48,6,LEAVES_2:1)
Block(4,48,7,LEAVES_2:1)
Block(4,48,8,LEAVES_2:1)
Block(4,48,9,LEAVES_2:1)
Block(4,49,-3,LEAVES_2:1)
Block(4,49,-2,LEAVES_2:1)
Block(4,49,-1,LEAVES_2:1)
Block(4,49,0,LEAVES_2:1)
Block(4,49,1,LEAVES_2:1)
Block(4,49,2,LOG_2:1)
Block(4,49,3,LOG_2:1)
Block(4,49,4,LOG_2:1)
Block(4,49,5,LEAVES_2:1)
Block(4,50,-1,LEAVES_2:1)
Block(4,50,0,LOG_2:1)
Block(4,50,1,LOG_2:1)
Block(4,50,2,LOG_2:1)
Block(4,50,3,LOG_2:1)
Block(4,50,4,LOG_2:1)
Block(4,50,5,LEAVES_2:1)
Block(4,50,6,LEAVES_2:1)
Block(4,50,7,LEAVES_2:1)
Block(4,51,-2,LEAVES_2:1)
Block(4,51,-1,LEAVES_2:1)
Block(4,51,0,LEAVES_2:1)
Block(4,51,1,LEAVES_2:1)
Block(4,51,2,LOG_2:1)
Block(4,51,3,LOG_2:1)
Block(4,51,4,LOG_2:1)
Block(4,51,6,LEAVES_2:1)
Block(4,51,7,LEAVES_2:1)
Block(4,51,8,LEAVES_2:1)
Block(4,51,9,LEAVES_2:1)
Block(4,52,-2,LEAVES_2:1)
Block(4,52,-1,LEAVES_2:1)
Block(4,52,0,LEAVES_2:1)
Block(4,52,1,LEAVES_2:1)
Block(4,52,2,LOG_2:1)
Block(4,52,3,LOG_2:1)
Block(4,52,4,LOG_2:1)
Block(4,52,5,LEAVES_2:1)
Block(4,52,7,LEAVES_2:1)
Block(4,52,8,LOG_2:1)
Block(4,53,0,LEAVES_2:1)
Block(4,53,1,LOG_2:1)
Block(4,53,2,LOG_2:1)
Block(4,53,3,LOG_2:1)
Block(4,53,4,LOG_2:1)
Block(4,53,5,LOG_2:1)
Block(4,53,6,LEAVES_2:1)
Block(4,53,7,LEAVES_2:1)
Block(4,53,8,LEAVES_2:1)
Block(4,54,1,LEAVES_2:1)
Block(4,54,2,LOG_2:1)
Block(4,54,3,LOG_2:1)
Block(4,54,4,LOG_2:1)
Block(4,54,5,LEAVES_2:1)
Block(4,54,6,LEAVES_2:1)
Block(4,54,7,LEAVES_2:1)
Block(4,54,9,LEAVES_2:1)
Block(4,55,1,LOG_2:1)
Block(4,55,2,LOG_2:1)
Block(4,55,3,LOG_2:1)
Block(4,55,4,LOG_2:1)
Block(4,55,5,LEAVES_2:1)
Block(4,55,6,LEAVES_2:1)
Block(4,55,7,LEAVES_2:1)
Block(4,55,8,LEAVES_2:1)
Block(4,56,-1,LEAVES_2:1)
Block(4,56,0,LEAVES_2:1)
Block(4,56,1,LEAVES_2:1)
Block(4,56,2,LOG_2:1)
Block(4,56,3,LOG_2:1)
Block(4,56,4,LOG_2:1)
Block(4,56,5,LEAVES_2:1)
Block(4,56,6,LEAVES_2:1)
Block(4,56,7,LEAVES_2:1)
Block(4,57,-2,LEAVES_2:1)
Block(4,57,-1,LEAVES_2:1)
Block(4,57,0,LEAVES_2:1)
Block(4,57,1,LEAVES_2:1)
Block(4,57,2,LOG_2:1)
Block(4,57,3,LOG_2:1)
Block(4,57,4,LOG_2:1)
Block(4,57,5,LOG_2:1)
Block(4,57,6,LEAVES_2:1)
Block(4,58,-2,LEAVES_2:1)
Block(4,58,-1,LEAVES_2:1)
Block(4,58,0,LEAVES_2:1)
Block(4,58,1,LEAVES_2:1)
Block(4,58,2,LOG_2:1)
Block(4,58,3,LOG_2:1)
Block(4,58,4,LOG_2:1)
Block(4,58,5,LEAVES_2:1)
Block(4,59,-2,LEAVES_2:1)
Block(4,59,-1,LEAVES_2:1)
Block(4,59,0,LOG_2:1)
Block(4,59,1,LOG_2:1)
Block(4,59,2,LOG_2:1)
Block(4,59,3,LOG_2:1)
Block(4,59,4,LOG_2:1)
Block(4,59,5,LEAVES_2:1)
Block(4,59,7,LEAVES_2:1)
Block(4,60,-1,LEAVES_2:1)
Block(4,60,0,LEAVES_2:1)
Block(4,60,1,LEAVES_2:1)
Block(4,60,2,LOG_2:1)
Block(4,60,3,LOG_2:1)
Block(4,60,4,LOG_2:1)
Block(4,60,5,LOG_2:1)
Block(4,60,6,LEAVES_2:1)
Block(4,60,7,LEAVES_2:1)
Block(4,61,-1,LEAVES_2:1)
Block(4,61,0,LEAVES_2:1)
Block(4,61,1,LEAVES_2:1)
Block(4,61,2,LOG_2:1)
Block(4,61,3,LOG_2:1)
Block(4,61,4,LOG_2:1)
Block(4,61,5,LEAVES_2:1)
Block(4,61,6,LEAVES_2:1)
Block(4,62,-1,LEAVES_2:1)
Block(4,62,0,LEAVES_2:1)
Block(4,62,1,LEAVES_2:1)
Block(4,62,2,LOG_2:1)
Block(4,62,3,LOG_2:1)
Block(4,62,4,LOG_2:1)
Block(4,62,5,LEAVES_2:1)
Block(4,62,6,LEAVES_2:1)
Block(4,63,0,LEAVES_2:1)
Block(4,63,1,LEAVES_2:1)
Block(4,63,2,LOG_2:1)
Block(4,63,3,LOG_2:1)
Block(4,63,4,LOG_2:1)
Block(4,64,0,LEAVES_2:1)
Block(4,64,1,LEAVES_2:1)
Block(4,64,2,LOG_2:1)
Block(4,64,3,LOG_2:1)
Block(4,64,4,LEAVES_2:1)
Block(4,65,1,LEAVES_2:1)
Block(4,65,2,LEAVES_2:1)
Block(4,65,3,LOG_2:1)
Block(4,65,4,LEAVES_2:1)
Block(4,66,1,LEAVES_2:1)
Block(4,66,2,LEAVES_2:1)
Block(4,66,3,LOG_2:1)
Block(4,66,4,LEAVES_2:1)
Block(4,67,1,LEAVES_2:1)
Block(4,67,2,LEAVES_2:1)
Block(4,67,3,LOG_2:1)
Block(4,67,4,LEAVES_2:1)
Block(4,67,5,LEAVES_2:1)
Block(4,68,1,LEAVES_2:1)
Block(4,68,2,LOG_2:1)
Block(4,68,3,LOG_2:1)
Block(4,68,4,LOG_2:1)
Block(4,68,5,LEAVES_2:1)
Block(4,69,1,LEAVES_2:1)
Block(4,69,2,LEAVES_2:1)
Block(4,69,3,LOG_2:1)
Block(4,69,4,LEAVES_2:1)
Block(4,70,2,LEAVES_2:1)
Block(4,70,3,LOG_2:1)
Block(4,71,2,LEAVES_2:1)
Block(4,71,3,LEAVES_2:1)
Block(4,72,2,LEAVES_2:1)
Block(4,72,3,LEAVES_2:1)
Block(4,73,3,LEAVES_2:1)
Block(4,74,3,LEAVES_2:1)
Block(5,0,0,LOG_2:1)
Block(5,0,1,LOG_2:1)
Block(5,0,2,LOG_2:1)
Block(5,0,3,LOG_2:1)
Block(5,0,4,LOG_2:1)
Block(5,0,5,LOG_2:1)
Block(5,0,6,LOG_2:1)
Block(5,1,0,LOG_2:1)
Block(5,1,1,LOG_2:1)
Block(5,1,2,LOG_2:1)
Block(5,1,3,LOG_2:1)
Block(5,1,4,LOG_2:1)
Block(5,1,5,LOG_2:1)
Block(5,2,0,HUGE_MUSHROOM_1)
Block(5,2,1,LOG_2:1)
Block(5,2,2,LOG_2:1)
Block(5,2,3,LOG_2:1)
Block(5,2,4,LOG_2:1)
Block(5,2,5,LOG_2:1)
Block(5,3,1,LOG_2:1)
Block(5,3,2,LOG_2:1)
Block(5,3,3,LOG_2:1)
Block(5,3,4,LOG_2:1)
Block(5,3,5,LOG_2:1)
Block(5,4,1,LOG_2:1)
Block(5,4,2,LOG_2:1)
Block(5,4,3,LOG_2:1)
Block(5,4,4,LOG_2:1)
Block(5,4,5,LOG_2:1)
Block(5,5,1,LOG_2:1)
Block(5,5,2,LOG_2:1)
Block(5,5,3,LOG_2:1)
Block(5,5,4,LOG_2:1)
Block(5,5,5,LOG_2:1)
Block(5,5,6,HUGE_MUSHROOM_1)
Block(5,5,7,HUGE_MUSHROOM_1)
Block(5,6,1,LOG_2:1)
Block(5,6,2,LOG_2:1)
Block(5,6,3,LOG_2:1)
Block(5,6,4,LOG_2:1)
Block(5,6,5,LOG_2:1)
Block(5,6,6,HUGE_MUSHROOM_1)
Block(5,7,1,LOG_2:1)
Block(5,7,2,LOG_2:1)
Block(5,7,3,LOG_2:1)
Block(5,7,4,LOG_2:1)
Block(5,7,5,LOG_2:1)
Block(5,8,1,LOG_2:1)
Block(5,8,2,LOG_2:1)
Block(5,8,3,LOG_2:1)
Block(5,8,4,LOG_2:1)
Block(5,8,5,LOG_2:1)
Block(5,9,1,LOG_2:1)
Block(5,9,2,LOG_2:1)
Block(5,9,3,LOG_2:1)
Block(5,9,4,LOG_2:1)
Block(5,9,5,LOG_2:1)
Block(5,10,0,HUGE_MUSHROOM_1)
Block(5,10,1,LOG_2:1)
Block(5,10,2,LOG_2:1)
Block(5,10,3,LOG_2:1)
Block(5,10,4,LOG_2:1)
Block(5,10,5,LOG_2:1)
Block(5,11,1,LOG_2:1)
Block(5,11,2,LOG_2:1)
Block(5,11,3,LOG_2:1)
Block(5,11,4,LOG_2:1)
Block(5,11,5,LOG_2:1)
Block(5,12,1,LOG_2:1)
Block(5,12,2,LOG_2:1)
Block(5,12,3,LOG_2:1)
Block(5,12,4,LOG_2:1)
Block(5,12,5,LOG_2:1)
Block(5,13,1,LOG_2:1)
Block(5,13,2,LOG_2:1)
Block(5,13,3,LOG_2:1)
Block(5,13,4,LOG_2:1)
Block(5,14,1,LOG_2:1)
Block(5,14,2,LOG_2:1)
Block(5,14,3,LOG_2:1)
Block(5,14,4,LOG_2:1)
Block(5,14,5,LOG_2:1)
Block(5,14,6,LEAVES_2:1)
Block(5,15,1,LOG_2:1)
Block(5,15,2,LOG_2:1)
Block(5,15,3,LOG_2:1)
Block(5,15,4,LOG_2:1)
Block(5,15,5,LEAVES_2:1)
Block(5,16,1,LEAVES_2:1)
Block(5,16,2,LOG_2:1)
Block(5,16,3,LOG_2:1)
Block(5,16,4,LOG_2:1)
Block(5,17,2,LOG_2:1)
Block(5,17,3,LOG_2:1)
Block(5,17,4,LOG_2:1)
Block(5,18,2,LOG_2:1)
Block(5,18,3,LOG_2:1)
Block(5,18,4,LOG_2:1)
Block(5,19,2,LOG_2:1)
Block(5,19,3,LOG_2:1)
Block(5,19,4,LOG_2:1)
Block(5,20,2,LOG_2:1)
Block(5,20,3,LOG_2:1)
Block(5,20,4,LOG_2:1)
Block(5,20,5,LEAVES_2:1)
Block(5,21,2,LOG_2:1)
Block(5,21,3,LOG_2:1)
Block(5,21,4,LOG_2:1)
Block(5,21,5,LEAVES_2:1)
Block(5,22,-7,LEAVES_2:1)
Block(5,22,-6,LEAVES_2:1)
Block(5,22,-5,LEAVES_2:1)
Block(5,22,2,LOG_2:1)
Block(5,22,3,LOG_2:1)
Block(5,22,4,LOG_2:1)
Block(5,22,5,LEAVES_2:1)
Block(5,23,-7,LEAVES_2:1)
Block(5,23,-6,LEAVES_2:1)
Block(5,23,-5,LEAVES_2:1)
Block(5,23,-4,LEAVES_2:1)
Block(5,23,2,LOG_2:1)
Block(5,23,3,LOG_2:1)
Block(5,23,4,LOG_2:1)
Block(5,24,-8,LEAVES_2:1)
Block(5,24,-6,LEAVES_2:1)
Block(5,24,-5,LOG_2:1)
Block(5,24,-4,LEAVES_2:1)
Block(5,24,-3,LEAVES_2:1)
Block(5,24,0,LEAVES_2:1)
Block(5,24,1,LEAVES_2:1)
Block(5,24,2,LOG_2:1)
Block(5,24,3,LOG_2:1)
Block(5,24,4,LOG_2:1)
Block(5,24,9,LEAVES_2:1)
Block(5,24,10,LEAVES_2:1)
Block(5,25,-8,LEAVES_2:1)
Block(5,25,-7,LEAVES_2:1)
Block(5,25,-6,LEAVES_2:1)
Block(5,25,-5,LEAVES_2:1)
Block(5,25,-4,LEAVES_2:1)
Block(5,25,-3,LEAVES_2:1)
Block(5,25,-2,LEAVES_2:1)
Block(5,25,0,LEAVES_2:1)
Block(5,25,1,LEAVES_2:1)
Block(5,25,2,LOG_2:1)
Block(5,25,3,LOG_2:1)
Block(5,25,4,LOG_2:1)
Block(5,25,9,LEAVES_2:1)
Block(5,25,11,LEAVES_2:1)
Block(5,26,-7,LEAVES_2:1)
Block(5,26,-6,LEAVES_2:1)
Block(5,26,-5,LEAVES_2:1)
Block(5,26,-4,LEAVES_2:1)
Block(5,26,-3,LEAVES_2:1)
Block(5,26,-2,LEAVES_2:1)
Block(5,26,-1,LEAVES_2:1)
Block(5,26,0,LEAVES_2:1)
Block(5,26,1,LEAVES_2:1)
Block(5,26,2,LOG_2:1)
Block(5,26,3,LOG_2:1)
Block(5,26,5,LEAVES_2:1)
Block(5,26,7,LEAVES_2:1)
Block(5,26,8,LEAVES_2:1)
Block(5,26,9,LEAVES_2:1)
Block(5,26,11,LEAVES_2:1)
Block(5,27,-6,LEAVES_2:1)
Block(5,27,-5,LEAVES_2:1)
Block(5,27,-4,LEAVES_2:1)
Block(5,27,-3,LEAVES_2:1)
Block(5,27,-2,LEAVES_2:1)
Block(5,27,-1,LEAVES_2:1)
Block(5,27,0,LEAVES_2:1)
Block(5,27,1,LOG_2:1)
Block(5,27,2,LOG_2:1)
Block(5,27,3,LOG_2:1)
Block(5,27,4,LOG_2:1)
Block(5,27,5,LEAVES_2:1)
Block(5,27,6,LEAVES_2:1)
Block(5,27,8,LEAVES_2:1)
Block(5,27,9,LEAVES_2:1)
Block(5,27,10,LEAVES_2:1)
Block(5,28,-5,LEAVES_2:1)
Block(5,28,-4,LEAVES_2:1)
Block(5,28,-1,LEAVES_2:1)
Block(5,28,0,LEAVES_2:1)
Block(5,28,1,LEAVES_2:1)
Block(5,28,2,LOG_2:1)
Block(5,28,3,LOG_2:1)
Block(5,28,9,LEAVES_2:1)
Block(5,28,10,LEAVES_2:1)
Block(5,29,-3,LEAVES_2:1)
Block(5,29,-1,LEAVES_2:1)
Block(5,29,0,LEAVES_2:1)
Block(5,29,1,LEAVES_2:1)
Block(5,29,2,LOG_2:1)
Block(5,29,3,LOG_2:1)
Block(5,29,4,LEAVES_2:1)
Block(5,29,5,LEAVES_2:1)
Block(5,29,10,LEAVES_2:1)
Block(5,30,-5,LEAVES_2:1)
Block(5,30,-4,LEAVES_2:1)
Block(5,30,-3,LEAVES_2:1)
Block(5,30,-2,LEAVES_2:1)
Block(5,30,0,LEAVES_2:1)
Block(5,30,1,LEAVES_2:1)
Block(5,30,2,LOG_2:1)
Block(5,30,3,LOG_2:1)
Block(5,30,4,LEAVES_2:1)
Block(5,30,5,LEAVES_2:1)
Block(5,30,7,LEAVES_2:1)
Block(5,30,8,LEAVES_2:1)
Block(5,30,9,LEAVES_2:1)
Block(5,31,-5,LEAVES_2:1)
Block(5,31,-4,LEAVES_2:1)
Block(5,31,-3,LOG_2:1)
Block(5,31,-2,LOG_2:1)
Block(5,31,-1,LEAVES_2:1)
Block(5,31,0,LOG_2:1)
Block(5,31,2,LOG_2:1)
Block(5,31,3,LOG_2:1)
Block(5,31,4,LOG_2:1)
Block(5,31,6,LEAVES_2:1)
Block(5,31,7,LEAVES_2:1)
Block(5,31,8,LEAVES_2:1)
Block(5,31,9,LEAVES_2:1)
Block(5,32,-4,LEAVES_2:1)
Block(5,32,-3,LOG_2:1)
Block(5,32,-2,LOG_2:1)
Block(5,32,-1,LOG_2:1)
Block(5,32,0,LOG_2:1)
Block(5,32,1,LOG_2:1)
Block(5,32,2,LOG_2:1)
Block(5,32,3,LOG_2:1)
Block(5,32,4,LOG_2:1)
Block(5,32,6,LEAVES_2:1)
Block(5,32,7,LEAVES_2:1)
Block(5,32,8,LEAVES_2:1)
Block(5,32,9,LOG_2:1)
Block(5,33,-4,LEAVES_2:1)
Block(5,33,-3,LEAVES_2:1)
Block(5,33,-2,LEAVES_2:1)
Block(5,33,-1,LEAVES_2:1)
Block(5,33,0,LEAVES_2:1)
Block(5,33,1,LOG_2:1)
Block(5,33,2,LOG_2:1)
Block(5,33,3,LOG_2:1)
Block(5,33,4,LEAVES_2:1)
Block(5,33,6,LEAVES_2:1)
Block(5,33,7,LEAVES_2:1)
Block(5,33,9,LOG_2:1)
Block(5,33,10,LEAVES_2:1)
Block(5,34,-3,LEAVES_2:1)
Block(5,34,-2,LEAVES_2:1)
Block(5,34,-1,LEAVES_2:1)
Block(5,34,1,LEAVES_2:1)
Block(5,34,2,LOG_2:1)
Block(5,34,3,LOG_2:1)
Block(5,34,5,LEAVES_2:1)
Block(5,34,6,LEAVES_2:1)
Block(5,34,7,LEAVES_2:1)
Block(5,35,-3,LEAVES_2:1)
Block(5,35,-2,LEAVES_2:1)
Block(5,35,0,LEAVES_2:1)
Block(5,35,1,LEAVES_2:1)
Block(5,35,2,LOG_2:1)
Block(5,35,3,LOG_2:1)
Block(5,35,4,LOG_2:1)
Block(5,35,5,LEAVES_2:1)
Block(5,35,6,LEAVES_2:1)
Block(5,35,7,LEAVES_2:1)
Block(5,35,8,LEAVES_2:1)
Block(5,35,9,LEAVES_2:1)
Block(5,36,-3,LEAVES_2:1)
Block(5,36,-2,LOG_2:1)
Block(5,36,-1,LOG_2:1)
Block(5,36,0,LOG_2:1)
Block(5,36,1,LEAVES_2:1)
Block(5,36,2,LOG_2:1)
Block(5,36,3,LOG_2:1)
Block(5,36,4,LOG_2:1)
Block(5,36,5,LOG_2:1)
Block(5,36,6,LEAVES_2:1)
Block(5,36,8,LEAVES_2:1)
Block(5,36,9,LEAVES_2:1)
Block(5,37,-4,LEAVES_2:1)
Block(5,37,-1,LEAVES_2:1)
Block(5,37,0,LEAVES_2:1)
Block(5,37,1,LEAVES_2:1)
Block(5,37,2,LOG_2:1)
Block(5,37,3,LOG_2:1)
Block(5,37,4,LEAVES_2:1)
Block(5,37,7,LEAVES_2:1)
Block(5,37,9,LEAVES_2:1)
Block(5,38,-3,LEAVES_2:1)
Block(5,38,-2,LEAVES_2:1)
Block(5,38,2,LOG_2:1)
Block(5,38,3,LOG_2:1)
Block(5,38,5,LEAVES_2:1)
Block(5,38,6,LOG_2:1)
Block(5,38,7,LEAVES_2:1)
Block(5,38,8,LEAVES_2:1)
Block(5,38,9,LEAVES_2:1)
Block(5,39,-4,LEAVES_2:1)
Block(5,39,-3,LEAVES_2:1)
Block(5,39,-2,LEAVES_2:1)
Block(5,39,0,LEAVES_2:1)
Block(5,39,1,LEAVES_2:1)
Block(5,39,2,LOG_2:1)
Block(5,39,3,LOG_2:1)
Block(5,39,4,LOG_2:1)
Block(5,39,5,LOG_2:1)
Block(5,39,6,LOG_2:1)
Block(5,39,7,LOG_2:1)
Block(5,39,8,LEAVES_2:1)
Block(5,39,9,LEAVES_2:1)
Block(5,40,-3,LEAVES_2:1)
Block(5,40,-2,LEAVES_2:1)
Block(5,40,-1,LEAVES_2:1)
Block(5,40,0,LEAVES_2:1)
Block(5,40,1,LOG_2:1)
Block(5,40,2,LOG_2:1)
Block(5,40,3,LOG_2:1)
Block(5,40,4,LOG_2:1)
Block(5,40,5,LEAVES_2:1)
Block(5,40,6,LEAVES_2:1)
Block(5,40,7,LOG_2:1)
Block(5,40,8,LEAVES_2:1)
Block(5,41,-5,LEAVES_2:1)
Block(5,41,-4,LEAVES_2:1)
Block(5,41,-3,LEAVES_2:1)
Block(5,41,-2,LEAVES_2:1)
Block(5,41,-1,LEAVES_2:1)
Block(5,41,0,LEAVES_2:1)
Block(5,41,1,LOG_2:1)
Block(5,41,2,LOG_2:1)
Block(5,41,3,LOG_2:1)
Block(5,41,5,LEAVES_2:1)
Block(5,41,6,LEAVES_2:1)
Block(5,41,7,LEAVES_2:1)
Block(5,41,8,LEAVES_2:1)
Block(5,42,-4,LEAVES_2:1)
Block(5,42,-2,LEAVES_2:1)
Block(5,42,-1,LEAVES_2:1)
Block(5,42,1,LEAVES_2:1)
Block(5,42,2,LOG_2:1)
Block(5,42,3,LOG_2:1)
Block(5,42,4,LEAVES_2:1)
Block(5,42,5,LEAVES_2:1)
Block(5,42,6,LEAVES_2:1)
Block(5,42,7,LEAVES_2:1)
Block(5,43,-2,LEAVES_2:1)
Block(5,43,-1,LEAVES_2:1)
Block(5,43,1,LEAVES_2:1)
Block(5,43,2,LOG_2:1)
Block(5,43,3,LOG_2:1)
Block(5,43,4,LEAVES_2:1)
Block(5,43,5,LEAVES_2:1)
Block(5,43,6,LEAVES_2:1)
Block(5,43,7,LEAVES_2:1)
Block(5,44,-2,LEAVES_2:1)
Block(5,44,-1,LEAVES_2:1)
Block(5,44,0,LEAVES_2:1)
Block(5,44,1,LEAVES_2:1)
Block(5,44,2,LOG_2:1)
Block(5,44,3,LOG_2:1)
Block(5,44,4,LOG_2:1)
Block(5,44,5,LOG_2:1)
Block(5,44,6,LEAVES_2:1)
Block(5,44,7,LEAVES_2:1)
Block(5,44,8,LEAVES_2:1)
Block(5,45,-2,LEAVES_2:1)
