
#######################################################################
# +-----------------------------------------------------------------+ #
# |                            BO3 object                           | #
# +-----------------------------------------------------------------+ #
#######################################################################

# This is the config file of a custom object.
# If you add this object correctly to your BiomeConfigs, it will spawn in the world.

# This is the creator of this BO3 object
Author: Unknown

# A short description of this BO3 object
Description: This BO3 was converted from a schematic using OTGEdit. The author and description information of the schematic could not be found. If you know who the author of the schematic is then please add this information.

# The BO3 version, don't change this! It can be used by external applications to do a version check.
Version: 3

# The settings mode, WriteAll, WriteWithoutComments or WriteDisable. See WorldConfig.
SettingsMode: WriteAll


#######################################################################
# +-----------------------------------------------------------------+ #
# |                          Main settings                          | #
# +-----------------------------------------------------------------+ #
#######################################################################

# This needs to be set to true to spawn the object in the Tree and Sapling resources.
Tree: true

# The frequency of the BO3 from 1 to 200. Tries this many times to spawn this BO3 when using the CustomObject(...) resource.
# Ignored by Tree(..), Sapling(..) and CustomStructure(..)
Frequency: 40

# The rarity of the BO3 from 0 to 100. Each spawn attempt has rarity% chance to succeed when using the CustomObject(...) resource.
# Ignored by Tree(..), Sapling(..) and CustomStructure(..)
Rarity: 100.0

# If you set this to true, the BO3 will be placed with a random rotation.
RotateRandomly: true

# The spawn height of the BO3: randomY, highestBlock or highestSolidBlock.
SpawnHeight: randomY

# The offset from the spawn height to spawn this BO3
# Ex. SpawnHeight = highestSolidBlock, SpawnHeightOffset = 3; This object will spawn 3 blocks above the highest solid block
SpawnHeightOffset: 0

# A random amount to offset the spawn location from the spawn offset height
# Ex. SpawnHeightOffset = 3, SpawnHeightVariance = 3; This object will spawn 3 to 6 blocks above the original spot it would have spawned
SpawnHeightVariance: 0

##############################
# Height Limits for the BO3. #
##############################

# When in randomY mode used as the minimum Y or in atMinY mode as the actual Y to spawn this BO3 at.
MinHeight: 92

# When in randomY mode used as the maximum Y to spawn this BO3 at.
MaxHeight: 256

######################
# Extrusion settings #
######################

# The style of extrusion you wish to use - BottomDown, TopUp, None (Default)
ExtrudeMode: None

# The blocks to extrude your BO3 through
ExtrudeThroughBlocks: AIR

# Objects can have other objects attacthed to it: branches. Branches can also
# have branches attached to it, which can also have branches, etc. This is the
# maximum branch depth for this objects.
MaxBranchDepth: 10

# When spawned with the UseWorld keyword, this BO3 should NOT spawn in the following biomes.
# If you write the BO3 name directly in the BiomeConfigs, this will be ignored.
ExcludedBiomes: All


#######################################################################
# +-----------------------------------------------------------------+ #
# |                      Source block settings                      | #
# +-----------------------------------------------------------------+ #
#######################################################################

# The block(s) the BO3 should spawn in.
SourceBlocks: AIR,GRASS,DIRT

# The maximum percentage of the BO3 that can be outside the SourceBlock.
# The BO3 won't be placed on a location with more blocks outside the SourceBlock than this percentage.
MaxPercentageOutsideSourceBlock: 100

# What to do when a block is about to be placed outside the SourceBlock? (dontPlace, placeAnyway)
OutsideSourceBlock: placeAnyway

# OTG+ settings #
# Legacy setting, rename this file to .BO4 instead. Set this to true to enable the advanced customstructure features of OTG+.
IsOTGPlus: false


#######################################################################
# +-----------------------------------------------------------------+ #
# |                              Blocks                             | #
# +-----------------------------------------------------------------+ #
#######################################################################

# All the blocks used in the BO3 are listed here. Possible blocks:
# Block(x,y,z,id[.data][,nbtfile.nbt)
# RandomBlock(x,y,z,id[:data][,nbtfile.nbt],chance[,id[:data][,nbtfile.nbt],chance[,...]])
#  So RandomBlock(0,0,0,CHEST,chest.nbt,50,CHEST,anotherchest.nbt,100) will spawn a chest at
#  the BO3 origin, and give it a 50% chance to have the contents of chest.nbt, or, if that
#  fails, a 100% percent chance to have the contents of anotherchest.nbt.
# *Note: Unlike Entity() and Spawner(), for Block() .txt files don't work, only .nbt files work.
# MinecraftObject(x,y,z,name) (TODO: This may not work anymore and needs to be tested.
#  Spawns an object in the Mojang NBT structure format. For example, 
#  MinecraftObject(0,0,0,minecraft:igloo/igloo_bottom)
#  spawns the bottom part of an igloo.
Block(-8,22,4,LEAVES_2:1)
Block(-8,22,8,LEAVES_2:1)
Block(-8,23,8,LEAVES_2:1)
Block(-8,23,9,LEAVES_2:1)
Block(-8,24,5,LEAVES_2:1)
Block(-8,24,8,LEAVES_2:1)
Block(-7,20,4,LEAVES_2:1)
Block(-7,21,3,LEAVES_2:1)
Block(-7,21,4,LEAVES_2:1)
Block(-7,22,3,LEAVES_2:1)
Block(-7,22,4,LOG_2:1)
Block(-7,22,5,LEAVES_2:1)
Block(-7,22,8,LEAVES_2:1)
Block(-7,23,3,LEAVES_2:1)
Block(-7,23,4,LEAVES_2:1)
Block(-7,23,5,LEAVES_2:1)
Block(-7,23,8,LEAVES_2:1)
Block(-7,23,9,LEAVES_2:1)
Block(-7,23,10,LEAVES_2:1)
Block(-7,24,4,LEAVES_2:1)
Block(-7,24,7,LEAVES_2:1)
Block(-7,24,8,LEAVES_2:1)
Block(-7,25,5,LEAVES_2:1)
Block(-7,26,8,LEAVES_2:1)
Block(-6,20,3,LEAVES_2:1)
Block(-6,20,5,LEAVES_2:1)
Block(-6,21,3,LEAVES_2:1)
Block(-6,21,5,LEAVES_2:1)
Block(-6,21,6,LEAVES_2:1)
Block(-6,21,8,LEAVES_2:1)
Block(-6,21,9,LEAVES_2:1)
Block(-6,21,10,LEAVES_2:1)
Block(-6,22,0,LEAVES_2:1)
Block(-6,22,2,LEAVES_2:1)
Block(-6,22,3,LEAVES_2:1)
Block(-6,22,4,LOG_2:1)
Block(-6,22,6,LEAVES_2:1)
Block(-6,22,9,LEAVES_2:1)
Block(-6,22,10,LEAVES_2:1)
Block(-6,22,11,LEAVES_2:1)
Block(-6,23,2,LEAVES_2:1)
Block(-6,23,3,LEAVES_2:1)
Block(-6,23,4,LEAVES_2:1)
Block(-6,23,5,LEAVES_2:1)
Block(-6,23,6,LEAVES_2:1)
Block(-6,23,9,LOG_2:1)
Block(-6,23,10,LEAVES_2:1)
Block(-6,24,4,LEAVES_2:1)
Block(-6,24,5,LEAVES_2:1)
Block(-6,24,6,LEAVES_2:1)
Block(-6,24,8,LEAVES_2:1)
Block(-6,24,9,LEAVES_2:1)
Block(-6,24,10,LEAVES_2:1)
Block(-6,25,3,LEAVES_2:1)
Block(-6,25,4,LEAVES_2:1)
Block(-6,25,5,LEAVES_2:1)
Block(-6,25,6,LEAVES_2:1)
Block(-6,25,7,LEAVES_2:1)
Block(-6,25,8,LEAVES_2:1)
Block(-6,25,9,LEAVES_2:1)
Block(-6,26,6,LEAVES_2:1)
Block(-6,26,7,LEAVES_2:1)
Block(-6,26,8,LEAVES_2:1)
Block(-6,26,9,LEAVES_2:1)
Block(-6,27,7,LEAVES_2:1)
Block(-6,27,9,LEAVES_2:1)
Block(-6,28,5,LEAVES_2:1)
Block(-6,29,5,LEAVES_2:1)
Block(-6,30,4,LEAVES_2:1)
Block(-5,20,4,LEAVES_2:1)
Block(-5,21,0,LEAVES_2:1)
Block(-5,21,1,LEAVES_2:1)
Block(-5,21,2,LEAVES_2:1)
Block(-5,21,3,LEAVES_2:1)
Block(-5,21,4,LEAVES_2:1)
Block(-5,21,5,LEAVES_2:1)
Block(-5,21,6,LEAVES_2:1)
Block(-5,21,8,LEAVES_2:1)
Block(-5,21,9,LEAVES_2:1)
Block(-5,22,-1,LEAVES_2:1)
Block(-5,22,2,LEAVES_2:1)
Block(-5,22,3,LOG_2:1)
Block(-5,22,5,LEAVES_2:1)
Block(-5,22,9,LEAVES_2:1)
Block(-5,22,10,LEAVES_2:1)
Block(-5,22,11,LEAVES_2:1)
Block(-5,23,-2,LEAVES_2:1)
Block(-5,23,-1,LEAVES_2:1)
Block(-5,23,0,LEAVES_2:1)
Block(-5,23,1,LEAVES_2:1)
Block(-5,23,2,LEAVES_2:1)
Block(-5,23,3,LEAVES_2:1)
Block(-5,23,5,LEAVES_2:1)
Block(-5,23,6,LEAVES_2:1)
Block(-5,23,7,LEAVES_2:1)
Block(-5,23,8,LEAVES_2:1)
Block(-5,23,9,LOG_2:1)
Block(-5,23,10,LEAVES_2:1)
Block(-5,23,11,LEAVES_2:1)
Block(-5,24,2,LEAVES_2:1)
Block(-5,24,3,LEAVES_2:1)
Block(-5,24,4,LEAVES_2:1)
Block(-5,24,6,LEAVES_2:1)
Block(-5,24,7,LEAVES_2:1)
Block(-5,24,9,LOG_2:1)
Block(-5,24,10,LEAVES_2:1)
Block(-5,25,3,LEAVES_2:1)
Block(-5,25,4,LEAVES_2:1)
Block(-5,25,5,LEAVES_2:1)
Block(-5,25,6,LEAVES_2:1)
Block(-5,25,7,LOG_2:1)
Block(-5,25,9,LOG_2:1)
Block(-5,25,10,LEAVES_2:1)
Block(-5,26,5,LEAVES_2:1)
Block(-5,26,6,LEAVES_2:1)
Block(-5,26,7,LOG_2:1)
Block(-5,26,8,LEAVES_2:1)
Block(-5,26,9,LEAVES_2:1)
Block(-5,27,5,LEAVES_2:1)
Block(-5,27,7,LEAVES_2:1)
Block(-5,27,8,LEAVES_2:1)
Block(-5,28,6,LEAVES_2:1)
Block(-5,28,7,LEAVES_2:1)
Block(-5,28,8,LEAVES_2:1)
Block(-5,29,3,LEAVES_2:1)
Block(-5,29,4,LEAVES_2:1)
Block(-5,29,6,LEAVES_2:1)
Block(-5,30,3,LEAVES_2:1)
Block(-5,30,6,LEAVES_2:1)
Block(-5,31,5,LEAVES_2:1)
Block(-5,31,6,LEAVES_2:1)
Block(-4,20,-3,LEAVES_2:1)
Block(-4,20,-2,LEAVES_2:1)
Block(-4,20,0,LEAVES_2:1)
Block(-4,20,1,LEAVES_2:1)
Block(-4,20,2,LEAVES_2:1)
Block(-4,20,4,LEAVES_2:1)
Block(-4,21,-2,LEAVES_2:1)
Block(-4,21,-1,LEAVES_2:1)
Block(-4,21,1,LEAVES_2:1)
Block(-4,21,2,LEAVES_2:1)
Block(-4,21,5,LEAVES_2:1)
Block(-4,22,-2,LEAVES_2:1)
Block(-4,22,-1,LEAVES_2:1)
Block(-4,22,0,LEAVES_2:1)
Block(-4,22,1,LEAVES_2:1)
Block(-4,22,2,LEAVES_2:1)
Block(-4,22,4,LOG_2:1)
Block(-4,22,5,LEAVES_2:1)
Block(-4,22,6,LEAVES_2:1)
Block(-4,22,7,LEAVES_2:1)
Block(-4,22,9,LEAVES_2:1)
Block(-4,23,-2,LEAVES_2:1)
Block(-4,23,-1,LEAVES_2:1)
Block(-4,23,0,LEAVES_2:1)
Block(-4,23,1,LEAVES_2:1)
Block(-4,23,2,LEAVES_2:1)
Block(-4,23,3,LEAVES_2:1)
Block(-4,23,4,LOG_2:1)
Block(-4,23,5,LEAVES_2:1)
Block(-4,23,6,LEAVES_2:1)
Block(-4,23,7,LEAVES_2:1)
Block(-4,23,8,LEAVES_2:1)
Block(-4,23,9,LEAVES_2:1)
Block(-4,23,10,LEAVES_2:1)
Block(-4,24,-2,LEAVES_2:1)
Block(-4,24,-1,LEAVES_2:1)
Block(-4,24,1,LEAVES_2:1)
Block(-4,24,5,LOG_2:1)
Block(-4,24,6,LEAVES_2:1)
Block(-4,24,7,LEAVES_2:1)
Block(-4,24,8,LEAVES_2:1)
Block(-4,24,9,LOG_2:1)
Block(-4,24,10,LEAVES_2:1)
Block(-4,24,11,LEAVES_2:1)
Block(-4,25,5,LOG_2:1)
Block(-4,25,6,LEAVES_2:1)
Block(-4,25,7,LEAVES_2:1)
Block(-4,25,8,LOG_2:1)
Block(-4,25,9,LOG_2:1)
Block(-4,25,10,LEAVES_2:1)
Block(-4,25,11,LEAVES_2:1)
Block(-4,26,3,LEAVES_2:1)
Block(-4,26,4,LOG_2:1)
Block(-4,26,6,LEAVES_2:1)
Block(-4,26,7,LOG_2:1)
Block(-4,26,9,LEAVES_2:1)
Block(-4,26,10,LEAVES_2:1)
Block(-4,27,3,LEAVES_2:1)
Block(-4,27,4,LEAVES_2:1)
Block(-4,27,5,LEAVES_2:1)
Block(-4,27,6,LEAVES_2:1)
Block(-4,27,7,LEAVES_2:1)
Block(-4,27,9,LEAVES_2:1)
Block(-4,27,10,LEAVES_2:1)
Block(-4,28,4,LEAVES_2:1)
Block(-4,28,7,LEAVES_2:1)
Block(-4,28,8,LEAVES_2:1)
Block(-4,28,9,LEAVES_2:1)
Block(-4,29,4,LEAVES_2:1)
Block(-4,29,6,LEAVES_2:1)
Block(-4,29,8,LEAVES_2:1)
Block(-4,30,2,LEAVES_2:1)
Block(-4,30,3,LEAVES_2:1)
Block(-4,30,4,LEAVES_2:1)
Block(-4,30,5,LEAVES_2:1)
Block(-4,30,6,LEAVES_2:1)
Block(-4,31,3,LEAVES_2:1)
Block(-4,31,4,LEAVES_2:1)
Block(-4,31,5,LEAVES_2:1)
Block(-4,31,6,LEAVES_2:1)
Block(-4,33,1,LEAVES_2:1)
Block(-4,34,1,LEAVES_2:1)
Block(-4,34,2,LEAVES_2:1)
Block(-4,35,2,LEAVES_2:1)
Block(-4,36,1,LEAVES_2:1)
Block(-4,38,1,LEAVES_2:1)
Block(-4,39,1,LEAVES_2:1)
Block(-4,49,5,LEAVES_2:1)
Block(-3,19,-3,LEAVES_2:1)
Block(-3,19,1,LEAVES_2:1)
Block(-3,20,-3,LOG_2:1)
Block(-3,20,-2,LEAVES_2:1)
Block(-3,20,-1,LEAVES_2:1)
Block(-3,20,0,LEAVES_2:1)
Block(-3,20,1,LEAVES_2:1)
Block(-3,20,3,LEAVES_2:1)
Block(-3,21,-3,LEAVES_2:1)
Block(-3,21,-2,LEAVES_2:1)
Block(-3,21,-1,LOG_2:1)
Block(-3,21,0,LEAVES_2:1)
Block(-3,21,1,LEAVES_2:1)
Block(-3,21,2,LEAVES_2:1)
Block(-3,21,3,LEAVES_2:1)
Block(-3,21,4,LEAVES_2:1)
Block(-3,21,5,LEAVES_2:1)
Block(-3,22,-2,LEAVES_2:1)
Block(-3,22,-1,LOG_2:1)
Block(-3,22,0,LOG_2:1)
Block(-3,22,1,LEAVES_2:1)
Block(-3,22,2,LEAVES_2:1)
Block(-3,22,3,LEAVES_2:1)
Block(-3,22,4,LEAVES_2:1)
Block(-3,22,5,LEAVES_2:1)
Block(-3,23,-2,LEAVES_2:1)
Block(-3,23,-1,LEAVES_2:1)
Block(-3,23,0,LEAVES_2:1)
Block(-3,23,1,LEAVES_2:1)
Block(-3,23,3,LEAVES_2:1)
Block(-3,23,4,LEAVES_2:1)
Block(-3,23,5,LOG_2:1)
Block(-3,23,6,LEAVES_2:1)
Block(-3,23,7,LEAVES_2:1)
Block(-3,23,8,LEAVES_2:1)
Block(-3,23,10,LEAVES_2:1)
Block(-3,24,-1,LEAVES_2:1)
Block(-3,24,0,LEAVES_2:1)
Block(-3,24,1,LEAVES_2:1)
Block(-3,24,4,LOG_2:1)
Block(-3,24,5,LOG_2:1)
Block(-3,24,6,LEAVES_2:1)
Block(-3,24,7,LEAVES_2:1)
Block(-3,24,8,LEAVES_2:1)
Block(-3,24,9,LEAVES_2:1)
Block(-3,24,10,LEAVES_2:1)
Block(-3,25,5,LEAVES_2:1)
Block(-3,25,6,LEAVES_2:1)
Block(-3,25,7,LEAVES_2:1)
Block(-3,25,8,LEAVES_2:1)
Block(-3,25,9,LOG_2:1)
Block(-3,25,10,LOG_2:1)
Block(-3,25,11,LEAVES_2:1)
Block(-3,25,12,LEAVES_2:1)
Block(-3,25,13,LEAVES_2:1)
Block(-3,26,-2,LEAVES_2:1)
Block(-3,26,-1,LEAVES_2:1)
Block(-3,26,0,LEAVES_2:1)
Block(-3,26,1,LEAVES_2:1)
Block(-3,26,4,LEAVES_2:1)
Block(-3,26,6,LEAVES_2:1)
Block(-3,26,7,LEAVES_2:1)
Block(-3,26,8,LEAVES_2:1)
Block(-3,26,9,LOG_2:1)
Block(-3,26,10,LEAVES_2:1)
Block(-3,26,11,LEAVES_2:1)
Block(-3,27,-2,LEAVES_2:1)
Block(-3,27,-1,LEAVES_2:1)
Block(-3,27,1,LEAVES_2:1)
Block(-3,27,3,LEAVES_2:1)
Block(-3,27,5,LEAVES_2:1)
Block(-3,27,8,LEAVES_2:1)
Block(-3,27,9,LOG_2:1)
Block(-3,27,10,LEAVES_2:1)
Block(-3,27,11,LEAVES_2:1)
Block(-3,28,2,LEAVES_2:1)
Block(-3,28,3,LEAVES_2:1)
Block(-3,28,4,LEAVES_2:1)
Block(-3,28,8,LEAVES_2:1)
Block(-3,28,9,LEAVES_2:1)
Block(-3,28,10,LEAVES_2:1)
Block(-3,28,11,LEAVES_2:1)
Block(-3,29,2,LEAVES_2:1)
Block(-3,29,3,LEAVES_2:1)
Block(-3,29,4,LOG_2:1)
Block(-3,29,5,LOG_2:1)
Block(-3,29,6,LEAVES_2:1)
Block(-3,29,7,LEAVES_2:1)
Block(-3,29,10,LEAVES_2:1)
Block(-3,30,3,LEAVES_2:1)
Block(-3,30,4,LEAVES_2:1)
Block(-3,30,5,LEAVES_2:1)
Block(-3,30,6,LEAVES_2:1)
Block(-3,31,3,LEAVES_2:1)
Block(-3,31,4,LEAVES_2:1)
Block(-3,32,1,LEAVES_2:1)
Block(-3,32,3,LEAVES_2:1)
Block(-3,33,1,LEAVES_2:1)
Block(-3,33,2,LEAVES_2:1)
Block(-3,34,-1,LEAVES_2:1)
Block(-3,34,0,LEAVES_2:1)
Block(-3,34,1,LOG_2:1)
Block(-3,34,2,LEAVES_2:1)
Block(-3,34,3,LEAVES_2:1)
Block(-3,34,4,LEAVES_2:1)
Block(-3,35,-1,LEAVES_2:1)
Block(-3,35,0,LEAVES_2:1)
Block(-3,35,2,LEAVES_2:1)
Block(-3,35,3,LEAVES_2:1)
Block(-3,35,6,LEAVES_2:1)
Block(-3,35,7,LEAVES_2:1)
Block(-3,35,8,LEAVES_2:1)
Block(-3,36,0,LEAVES_2:1)
Block(-3,36,1,LEAVES_2:1)
Block(-3,36,2,LEAVES_2:1)
Block(-3,36,5,LEAVES_2:1)
Block(-3,36,6,LEAVES_2:1)
Block(-3,36,7,LEAVES_2:1)
Block(-3,36,8,LEAVES_2:1)
Block(-3,36,9,LEAVES_2:1)
Block(-3,37,5,LEAVES_2:1)
Block(-3,38,0,LEAVES_2:1)
Block(-3,38,1,LEAVES_2:1)
Block(-3,39,0,LEAVES_2:1)
Block(-3,39,1,LEAVES_2:1)
Block(-3,39,2,LEAVES_2:1)
Block(-3,40,0,LEAVES_2:1)
Block(-3,40,1,LEAVES_2:1)
Block(-3,40,2,LEAVES_2:1)
Block(-3,46,3,LEAVES_2:1)
Block(-3,46,4,LEAVES_2:1)
Block(-3,46,5,LEAVES_2:1)
Block(-3,47,3,LEAVES_2:1)
Block(-3,47,4,LEAVES_2:1)
Block(-3,48,3,LEAVES_2:1)
Block(-3,48,4,LEAVES_2:1)
Block(-3,48,5,LEAVES_2:1)
Block(-3,48,6,LEAVES_2:1)
Block(-3,49,6,LEAVES_2:1)
Block(-3,50,5,LEAVES_2:1)
Block(-2,20,-3,LEAVES_2:1)
Block(-2,20,-2,LEAVES_2:1)
Block(-2,20,-1,LEAVES_2:1)
Block(-2,20,0,LEAVES_2:1)
Block(-2,20,2,LEAVES_2:1)
Block(-2,20,4,LEAVES_2:1)
Block(-2,21,-3,LEAVES_2:1)
Block(-2,21,-2,LEAVES_2:1)
Block(-2,21,-1,LEAVES_2:1)
Block(-2,21,0,LEAVES_2:1)
Block(-2,21,1,LEAVES_2:1)
Block(-2,21,2,LEAVES_2:1)
Block(-2,21,3,LEAVES_2:1)
Block(-2,21,4,LEAVES_2:1)
Block(-2,21,5,LEAVES_2:1)
Block(-2,21,6,LEAVES_2:1)
Block(-2,22,-2,LEAVES_2:1)
Block(-2,22,-1,LEAVES_2:1)
Block(-2,22,0,LOG_2:1)
Block(-2,22,1,LEAVES_2:1)
Block(-2,22,2,LEAVES_2:1)
Block(-2,22,3,LEAVES_2:1)
Block(-2,22,5,LEAVES_2:1)
Block(-2,23,-1,LEAVES_2:1)
Block(-2,23,0,LOG_2:1)
Block(-2,23,1,LOG_2:1)
Block(-2,23,2,LEAVES_2:1)
Block(-2,23,3,LEAVES_2:1)
Block(-2,23,4,LEAVES_2:1)
Block(-2,23,5,LEAVES_2:1)
Block(-2,23,6,LEAVES_2:1)
Block(-2,23,10,LEAVES_2:1)
Block(-2,24,-1,LEAVES_2:1)
Block(-2,24,0,LEAVES_2:1)
Block(-2,24,1,LEAVES_2:1)
Block(-2,24,2,LEAVES_2:1)
Block(-2,24,3,LEAVES_2:1)
Block(-2,24,4,LEAVES_2:1)
Block(-2,24,5,LOG_2:1)
Block(-2,24,6,LEAVES_2:1)
Block(-2,24,7,LEAVES_2:1)
Block(-2,24,8,LEAVES_2:1)
Block(-2,24,9,LEAVES_2:1)
Block(-2,24,10,LEAVES_2:1)
Block(-2,24,11,LEAVES_2:1)
Block(-2,24,13,LEAVES_2:1)
Block(-2,25,-1,LEAVES_2:1)
Block(-2,25,0,LEAVES_2:1)
Block(-2,25,1,LEAVES_2:1)
Block(-2,25,2,LEAVES_2:1)
Block(-2,25,3,LEAVES_2:1)
Block(-2,25,4,LEAVES_2:1)
Block(-2,25,5,LOG_2:1)
Block(-2,25,6,LEAVES_2:1)
Block(-2,25,7,LEAVES_2:1)
Block(-2,25,8,LOG_2:1)
Block(-2,25,9,LEAVES_2:1)
Block(-2,25,11,LEAVES_2:1)
Block(-2,25,12,LEAVES_2:1)
Block(-2,26,-2,LEAVES_2:1)
Block(-2,26,-1,LEAVES_2:1)
Block(-2,26,0,LEAVES_2:1)
Block(-2,26,1,LEAVES_2:1)
Block(-2,26,2,LEAVES_2:1)
Block(-2,26,6,LEAVES_2:1)
Block(-2,26,7,LEAVES_2:1)
Block(-2,26,8,LEAVES_2:1)
Block(-2,26,9,LEAVES_2:1)
Block(-2,26,10,LEAVES_2:1)
Block(-2,26,11,LEAVES_2:1)
Block(-2,26,12,LEAVES_2:1)
Block(-2,27,-2,LEAVES_2:1)
Block(-2,27,-1,LEAVES_2:1)
Block(-2,27,0,LEAVES_2:1)
Block(-2,27,1,LEAVES_2:1)
Block(-2,27,7,LEAVES_2:1)
Block(-2,27,8,LEAVES_2:1)
Block(-2,27,9,LEAVES_2:1)
Block(-2,27,10,LEAVES_2:1)
Block(-2,27,11,LEAVES_2:1)
Block(-2,28,-2,LEAVES_2:1)
Block(-2,28,-1,LEAVES_2:1)
Block(-2,28,5,LEAVES_2:1)
Block(-2,28,7,LEAVES_2:1)
Block(-2,28,8,LEAVES_2:1)
Block(-2,28,9,LEAVES_2:1)
Block(-2,28,10,LEAVES_2:1)
Block(-2,28,13,LEAVES_2:1)
Block(-2,29,-2,LEAVES_2:1)
Block(-2,29,2,LEAVES_2:1)
Block(-2,29,3,LEAVES_2:1)
Block(-2,29,4,LOG_2:1)
Block(-2,29,5,LOG_2:1)
Block(-2,29,6,LEAVES_2:1)
Block(-2,29,8,LEAVES_2:1)
Block(-2,29,9,LEAVES_2:1)
Block(-2,29,10,LEAVES_2:1)
Block(-2,30,2,LEAVES_2:1)
Block(-2,30,4,LEAVES_2:1)
Block(-2,30,5,LEAVES_2:1)
Block(-2,30,8,LEAVES_2:1)
Block(-2,30,9,LEAVES_2:1)
Block(-2,31,4,LEAVES_2:1)
Block(-2,32,1,LEAVES_2:1)
Block(-2,32,2,LEAVES_2:1)
Block(-2,32,3,LEAVES_2:1)
Block(-2,33,0,LEAVES_2:1)
Block(-2,33,1,LEAVES_2:1)
Block(-2,33,2,LEAVES_2:1)
Block(-2,33,3,LEAVES_2:1)
Block(-2,33,4,LEAVES_2:1)
Block(-2,34,-1,LEAVES_2:1)
Block(-2,34,0,LEAVES_2:1)
Block(-2,34,1,LOG_2:1)
Block(-2,34,2,LOG_2:1)
Block(-2,34,3,LEAVES_2:1)
Block(-2,34,4,LEAVES_2:1)
Block(-2,34,5,LEAVES_2:1)
Block(-2,34,8,LEAVES_2:1)
Block(-2,35,-1,LEAVES_2:1)
Block(-2,35,0,LEAVES_2:1)
Block(-2,35,1,LOG_2:1)
Block(-2,35,2,LOG_2:1)
Block(-2,35,3,LEAVES_2:1)
Block(-2,35,4,LEAVES_2:1)
Block(-2,35,5,LEAVES_2:1)
Block(-2,35,7,LOG_2:1)
Block(-2,35,9,LEAVES_2:1)
Block(-2,36,0,LEAVES_2:1)
Block(-2,36,2,LEAVES_2:1)
Block(-2,36,3,LEAVES_2:1)
Block(-2,36,4,LEAVES_2:1)
Block(-2,36,5,LEAVES_2:1)
Block(-2,36,6,LEAVES_2:1)
Block(-2,36,7,LEAVES_2:1)
Block(-2,36,8,LEAVES_2:1)
Block(-2,36,9,LEAVES_2:1)
Block(-2,37,0,LEAVES_2:1)
Block(-2,37,4,LEAVES_2:1)
Block(-2,37,5,LEAVES_2:1)
Block(-2,37,6,LEAVES_2:1)
Block(-2,37,7,LEAVES_2:1)
Block(-2,37,8,LEAVES_2:1)
Block(-2,37,9,LEAVES_2:1)
Block(-2,38,-3,LEAVES_2:1)
Block(-2,38,1,LEAVES_2:1)
Block(-2,38,4,LEAVES_2:1)
Block(-2,38,6,LEAVES_2:1)
Block(-2,38,7,LEAVES_2:1)
Block(-2,39,-3,LEAVES_2:1)
Block(-2,39,0,LEAVES_2:1)
Block(-2,39,1,LEAVES_2:1)
Block(-2,39,6,LOG_2:1)
Block(-2,39,7,LEAVES_2:1)
Block(-2,40,-4,LEAVES_2:1)
Block(-2,40,-3,LEAVES_2:1)
Block(-2,40,-1,LEAVES_2:1)
Block(-2,40,0,LEAVES_2:1)
Block(-2,40,1,LEAVES_2:1)
Block(-2,40,2,LEAVES_2:1)
Block(-2,40,7,LEAVES_2:1)
Block(-2,41,-2,LEAVES_2:1)
Block(-2,41,0,LEAVES_2:1)
Block(-2,41,1,LEAVES_2:1)
Block(-2,41,6,LEAVES_2:1)
Block(-2,41,7,LEAVES_2:1)
Block(-2,42,-3,LEAVES_2:1)
Block(-2,42,-2,LEAVES_2:1)
Block(-2,42,1,LEAVES_2:1)
Block(-2,43,-2,LEAVES_2:1)
Block(-2,43,-1,LEAVES_2:1)
Block(-2,43,1,LOG_2:1)
Block(-2,44,-1,LEAVES_2:1)
Block(-2,44,0,LEAVES_2:1)
Block(-2,44,2,LEAVES_2:1)
Block(-2,45,-3,LEAVES_2:1)
Block(-2,45,-2,LEAVES_2:1)
Block(-2,45,-1,LEAVES_2:1)
Block(-2,45,0,LEAVES_2:1)
Block(-2,45,4,LEAVES_2:1)
Block(-2,45,5,LEAVES_2:1)
Block(-2,46,-2,LEAVES_2:1)
Block(-2,46,-1,LEAVES_2:1)
Block(-2,46,2,LEAVES_2:1)
Block(-2,46,3,LEAVES_2:1)
Block(-2,46,4,LEAVES_2:1)
Block(-2,46,6,LEAVES_2:1)
Block(-2,47,-2,LEAVES_2:1)
Block(-2,47,2,LEAVES_2:1)
Block(-2,47,3,LEAVES_2:1)
Block(-2,47,4,LOG_2:1)
Block(-2,47,6,LEAVES_2:1)
Block(-2,48,3,LEAVES_2:1)
Block(-2,48,4,LEAVES_2:1)
Block(-2,48,5,LEAVES_2:1)
Block(-2,48,6,LEAVES_2:1)
Block(-2,49,3,LEAVES_2:1)
Block(-2,49,4,LEAVES_2:1)
Block(-2,49,6,LEAVES_2:1)
Block(-2,50,5,LEAVES_2:1)
Block(-1,15,3,LEAVES_2:1)
Block(-1,16,3,LEAVES_2:1)
Block(-1,16,4,LEAVES_2:1)
Block(-1,17,3,LEAVES_2:1)
Block(-1,19,-4,LEAVES_2:1)
Block(-1,19,-3,LEAVES_2:1)
Block(-1,20,-5,LEAVES_2:1)
Block(-1,20,-4,LEAVES_2:1)
Block(-1,20,-2,LEAVES_2:1)
Block(-1,20,0,LEAVES_2:1)
Block(-1,20,2,LEAVES_2:1)
Block(-1,21,-4,LEAVES_2:1)
Block(-1,21,-2,LEAVES_2:1)
Block(-1,21,-1,LEAVES_2:1)
Block(-1,21,0,LEAVES_2:1)
Block(-1,21,1,LEAVES_2:1)
Block(-1,21,4,LEAVES_2:1)
Block(-1,22,-3,LEAVES_2:1)
Block(-1,22,0,LEAVES_2:1)
Block(-1,22,2,LEAVES_2:1)
Block(-1,22,3,LEAVES_2:1)
Block(-1,22,4,LEAVES_2:1)
Block(-1,22,5,LEAVES_2:1)
Block(-1,22,6,LEAVES_2:1)
Block(-1,22,11,LEAVES_2:1)
Block(-1,23,-3,LEAVES_2:1)
Block(-1,23,-2,LEAVES_2:1)
Block(-1,23,0,LOG_2:1)
Block(-1,23,2,LEAVES_2:1)
Block(-1,23,4,LEAVES_2:1)
Block(-1,23,6,LEAVES_2:1)
Block(-1,23,7,LEAVES_2:1)
Block(-1,23,10,LEAVES_2:1)
Block(-1,24,0,LOG_2:1)
Block(-1,24,1,LOG_2:1)
Block(-1,24,2,LEAVES_2:1)
Block(-1,24,3,LEAVES_2:1)
Block(-1,24,4,LEAVES_2:1)
Block(-1,24,5,LOG_2:1)
Block(-1,24,8,LEAVES_2:1)
Block(-1,24,9,LEAVES_2:1)
Block(-1,24,10,LEAVES_2:1)
Block(-1,24,12,LEAVES_2:1)
Block(-1,24,13,LEAVES_2:1)
Block(-1,25,-2,LEAVES_2:1)
Block(-1,25,-1,LEAVES_2:1)
Block(-1,25,0,LOG_2:1)
Block(-1,25,1,LEAVES_2:1)
Block(-1,25,2,LEAVES_2:1)
Block(-1,25,3,LEAVES_2:1)
Block(-1,25,4,LEAVES_2:1)
Block(-1,25,5,LOG_2:1)
Block(-1,25,6,LOG_2:1)
Block(-1,25,7,LOG_2:1)
Block(-1,25,8,LOG_2:1)
Block(-1,25,9,LOG_2:1)
Block(-1,25,10,LOG_2:1)
Block(-1,25,11,LEAVES_2:1)
Block(-1,25,12,LEAVES_2:1)
Block(-1,25,13,LEAVES_2:1)
Block(-1,25,14,LEAVES_2:1)
Block(-1,26,-2,LEAVES_2:1)
Block(-1,26,-1,LEAVES_2:1)
Block(-1,26,0,LOG_2:1)
Block(-1,26,1,LEAVES_2:1)
Block(-1,26,2,LEAVES_2:1)
Block(-1,26,3,LEAVES_2:1)
Block(-1,26,5,LOG_2:1)
Block(-1,26,6,LEAVES_2:1)
Block(-1,26,7,LEAVES_2:1)
Block(-1,26,8,LEAVES_2:1)
Block(-1,26,9,LEAVES_2:1)
Block(-1,26,10,LEAVES_2:1)
Block(-1,26,11,LEAVES_2:1)
Block(-1,26,13,LEAVES_2:1)
Block(-1,27,-1,LEAVES_2:1)
Block(-1,27,0,LEAVES_2:1)
Block(-1,27,1,LEAVES_2:1)
Block(-1,27,2,LEAVES_2:1)
Block(-1,27,3,LEAVES_2:1)
Block(-1,27,6,LEAVES_2:1)
Block(-1,27,7,LEAVES_2:1)
Block(-1,27,8,LEAVES_2:1)
Block(-1,27,9,LEAVES_2:1)
Block(-1,27,10,LEAVES_2:1)
Block(-1,27,11,LEAVES_2:1)
Block(-1,27,12,LEAVES_2:1)
Block(-1,27,13,LEAVES_2:1)
Block(-1,28,-2,LEAVES_2:1)
Block(-1,28,-1,LEAVES_2:1)
Block(-1,28,0,LEAVES_2:1)
Block(-1,28,1,LEAVES_2:1)
Block(-1,28,4,LEAVES_2:1)
Block(-1,28,6,LEAVES_2:1)
Block(-1,28,7,LEAVES_2:1)
Block(-1,28,8,LEAVES_2:1)
Block(-1,28,9,LOG_2:1)
Block(-1,28,11,LEAVES_2:1)
Block(-1,28,12,LEAVES_2:1)
Block(-1,28,13,LEAVES_2:1)
Block(-1,29,-2,LEAVES_2:1)
Block(-1,29,-1,LEAVES_2:1)
Block(-1,29,2,LEAVES_2:1)
Block(-1,29,5,LOG_2:1)
Block(-1,29,8,LEAVES_2:1)
Block(-1,29,10,LEAVES_2:1)
Block(-1,29,12,LEAVES_2:1)
Block(-1,29,13,LEAVES_2:1)
Block(-1,30,3,LEAVES_2:1)
Block(-1,30,4,LEAVES_2:1)
Block(-1,30,5,LOG_2:1)
Block(-1,30,7,LEAVES_2:1)
Block(-1,30,8,LEAVES_2:1)
Block(-1,31,2,LEAVES_2:1)
Block(-1,32,1,LEAVES_2:1)
Block(-1,32,2,LEAVES_2:1)
Block(-1,33,0,LEAVES_2:1)
Block(-1,33,2,LEAVES_2:1)
Block(-1,33,3,LEAVES_2:1)
Block(-1,34,-1,LEAVES_2:1)
Block(-1,34,0,LEAVES_2:1)
Block(-1,34,1,LEAVES_2:1)
Block(-1,34,2,LEAVES_2:1)
Block(-1,34,3,LEAVES_2:1)
Block(-1,34,4,LEAVES_2:1)
Block(-1,34,5,LEAVES_2:1)
Block(-1,34,6,LEAVES_2:1)
Block(-1,34,7,LEAVES_2:1)
Block(-1,35,-1,LEAVES_2:1)
Block(-1,35,0,LEAVES_2:1)
Block(-1,35,1,LEAVES_2:1)
Block(-1,35,2,LOG_2:1)
Block(-1,35,3,LEAVES_2:1)
Block(-1,35,4,LEAVES_2:1)
Block(-1,35,5,LEAVES_2:1)
Block(-1,35,6,LEAVES_2:1)
Block(-1,35,7,LOG_2:1)
Block(-1,35,8,LOG_2:1)
Block(-1,35,9,LEAVES_2:1)
Block(-1,36,-4,LEAVES_2:1)
Block(-1,36,-2,LEAVES_2:1)
Block(-1,36,-1,LEAVES_2:1)
Block(-1,36,0,LEAVES_2:1)
Block(-1,36,1,LEAVES_2:1)
Block(-1,36,2,LEAVES_2:1)
Block(-1,36,3,LEAVES_2:1)
Block(-1,36,4,LOG_2:1)
Block(-1,36,5,LEAVES_2:1)
Block(-1,36,6,LOG_2:1)
Block(-1,36,7,LOG_2:1)
Block(-1,36,8,LEAVES_2:1)
Block(-1,37,-5,LEAVES_2:1)
Block(-1,37,-4,LEAVES_2:1)
Block(-1,37,-2,LEAVES_2:1)
Block(-1,37,-1,LEAVES_2:1)
Block(-1,37,0,LEAVES_2:1)
Block(-1,37,1,LEAVES_2:1)
Block(-1,37,2,LEAVES_2:1)
Block(-1,37,3,LEAVES_2:1)
Block(-1,37,4,LEAVES_2:1)
Block(-1,37,5,LEAVES_2:1)
Block(-1,37,6,LEAVES_2:1)
Block(-1,37,7,LEAVES_2:1)
Block(-1,38,-5,LEAVES_2:1)
Block(-1,38,-4,LEAVES_2:1)
Block(-1,38,-2,LEAVES_2:1)
Block(-1,38,0,LEAVES_2:1)
Block(-1,38,2,LEAVES_2:1)
Block(-1,38,3,LEAVES_2:1)
Block(-1,38,4,LEAVES_2:1)
Block(-1,38,5,LEAVES_2:1)
Block(-1,38,6,LEAVES_2:1)
Block(-1,38,7,LEAVES_2:1)
Block(-1,38,8,LEAVES_2:1)
Block(-1,39,-4,LEAVES_2:1)
Block(-1,39,-3,LEAVES_2:1)
Block(-1,39,-2,LEAVES_2:1)
Block(-1,39,-1,LEAVES_2:1)
Block(-1,39,0,LOG_2:1)
Block(-1,39,2,LEAVES_2:1)
Block(-1,39,3,LEAVES_2:1)
Block(-1,39,4,LEAVES_2:1)
Block(-1,39,6,LOG_2:1)
Block(-1,39,8,LEAVES_2:1)
Block(-1,40,-4,LEAVES_2:1)
Block(-1,40,-3,LEAVES_2:1)
Block(-1,40,-2,LEAVES_2:1)
Block(-1,40,-1,LEAVES_2:1)
Block(-1,40,0,LEAVES_2:1)
Block(-1,40,1,LEAVES_2:1)
Block(-1,40,2,LEAVES_2:1)
Block(-1,40,6,LOG_2:1)
Block(-1,40,7,LEAVES_2:1)
Block(-1,40,8,LEAVES_2:1)
Block(-1,41,-3,LEAVES_2:1)
Block(-1,41,-1,LEAVES_2:1)
Block(-1,41,0,LEAVES_2:1)
Block(-1,41,1,LEAVES_2:1)
Block(-1,41,4,LEAVES_2:1)
Block(-1,41,7,LEAVES_2:1)
Block(-1,42,-5,LEAVES_2:1)
Block(-1,42,-4,LEAVES_2:1)
Block(-1,42,-3,LOG_2:1)
Block(-1,42,-2,LEAVES_2:1)
Block(-1,42,-1,LEAVES_2:1)
Block(-1,42,0,LEAVES_2:1)
Block(-1,42,1,LEAVES_2:1)
Block(-1,42,2,LEAVES_2:1)
Block(-1,42,5,LEAVES_2:1)
Block(-1,42,6,LEAVES_2:1)
Block(-1,43,-3,LEAVES_2:1)
Block(-1,43,-2,LEAVES_2:1)
Block(-1,43,1,LOG_2:1)
Block(-1,43,2,LEAVES_2:1)
Block(-1,43,6,LEAVES_2:1)
Block(-1,44,-3,LEAVES_2:1)
Block(-1,44,-2,LEAVES_2:1)
Block(-1,44,-1,LEAVES_2:1)
Block(-1,44,0,LEAVES_2:1)
Block(-1,44,1,LOG_2:1)
Block(-1,44,2,LEAVES_2:1)
Block(-1,44,3,LEAVES_2:1)
Block(-1,44,6,LEAVES_2:1)
Block(-1,44,7,LEAVES_2:1)
Block(-1,45,0,LEAVES_2:1)
Block(-1,45,1,LEAVES_2:1)
Block(-1,45,3,LEAVES_2:1)
Block(-1,45,4,LEAVES_2:1)
Block(-1,45,5,LEAVES_2:1)
Block(-1,45,6,LEAVES_2:1)
Block(-1,45,7,LEAVES_2:1)
Block(-1,46,-2,LEAVES_2:1)
Block(-1,46,-1,LEAVES_2:1)
Block(-1,46,0,LEAVES_2:1)
Block(-1,46,2,LEAVES_2:1)
Block(-1,46,3,LEAVES_2:1)
Block(-1,46,4,LEAVES_2:1)
Block(-1,46,5,LEAVES_2:1)
Block(-1,46,6,LEAVES_2:1)
Block(-1,47,-3,LEAVES_2:1)
Block(-1,47,-2,LEAVES_2:1)
Block(-1,47,-1,LEAVES_2:1)
Block(-1,47,0,LEAVES_2:1)
Block(-1,47,3,LEAVES_2:1)
Block(-1,47,4,LOG_2:1)
Block(-1,47,6,LEAVES_2:1)
Block(-1,47,7,LEAVES_2:1)
Block(-1,48,-2,LEAVES_2:1)
Block(-1,48,4,LEAVES_2:1)
Block(-1,48,7,LEAVES_2:1)
Block(-1,49,3,LEAVES_2:1)
Block(-1,49,4,LEAVES_2:1)
Block(-1,49,6,LEAVES_2:1)
Block(-1,50,5,LEAVES_2:1)
Block(-1,51,2,LEAVES_2:1)
Block(-1,52,1,LEAVES_2:1)
Block(-1,52,2,LEAVES_2:1)
Block(-1,53,1,LEAVES_2:1)
Block(0,15,3,LEAVES_2:1)
Block(0,15,4,LEAVES_2:1)
Block(0,16,2,LEAVES_2:1)
Block(0,16,3,LEAVES_2:1)
Block(0,16,4,LEAVES_2:1)
Block(0,16,5,LEAVES_2:1)
Block(0,17,3,LEAVES_2:1)
Block(0,17,4,LEAVES_2:1)
Block(0,18,-3,LEAVES_2:1)
Block(0,18,-2,LEAVES_2:1)
Block(0,19,-5,LEAVES_2:1)
Block(0,19,-2,LEAVES_2:1)
Block(0,20,-5,LEAVES_2:1)
Block(0,20,-4,LOG_2:1)
Block(0,20,-3,LOG_2:1)
Block(0,20,-2,LOG_2:1)
Block(0,20,-1,LEAVES_2:1)
Block(0,20,2,LEAVES_2:1)
Block(0,21,-3,LEAVES_2:1)
Block(0,21,-2,LEAVES_2:1)
Block(0,21,-1,LEAVES_2:1)
Block(0,21,0,LEAVES_2:1)
Block(0,21,2,LEAVES_2:1)
Block(0,22,-4,LEAVES_2:1)
Block(0,22,-2,LEAVES_2:1)
Block(0,22,-1,LEAVES_2:1)
Block(0,22,2,LEAVES_2:1)
Block(0,22,6,LEAVES_2:1)
Block(0,22,11,LEAVES_2:1)
Block(0,23,-4,LEAVES_2:1)
Block(0,23,-2,LEAVES_2:1)
Block(0,23,-1,LEAVES_2:1)
Block(0,23,1,LEAVES_2:1)
Block(0,23,2,LOG_2:1)
Block(0,23,3,LEAVES_2:1)
Block(0,23,4,LEAVES_2:1)
Block(0,23,6,LEAVES_2:1)
Block(0,23,10,LOG_2:1)
Block(0,23,11,LOG_2:1)
Block(0,23,12,LEAVES_2:1)
Block(0,24,-3,LEAVES_2:1)
Block(0,24,-1,LEAVES_2:1)
Block(0,24,0,LEAVES_2:1)
Block(0,24,2,LOG_2:1)
Block(0,24,3,LOG_2:1)
Block(0,24,4,LEAVES_2:1)
Block(0,24,5,LEAVES_2:1)
Block(0,24,6,LEAVES_2:1)
Block(0,24,7,LEAVES_2:1)
Block(0,24,8,LOG_2:1)
Block(0,24,9,LEAVES_2:1)
Block(0,24,10,LOG_2:1)
Block(0,24,11,LOG_2:1)
Block(0,24,12,LEAVES_2:1)
Block(0,25,-2,LEAVES_2:1)
Block(0,25,-1,LEAVES_2:1)
Block(0,25,0,LEAVES_2:1)
Block(0,25,2,LEAVES_2:1)
Block(0,25,3,LEAVES_2:1)
Block(0,25,4,LEAVES_2:1)
Block(0,25,6,LOG_2:1)
Block(0,25,7,LOG_2:1)
Block(0,25,8,LOG_2:1)
Block(0,25,9,LEAVES_2:1)
Block(0,25,10,LOG_2:1)
Block(0,25,11,LEAVES_2:1)
Block(0,25,12,LEAVES_2:1)
Block(0,26,-3,LEAVES_2:1)
Block(0,26,-2,LEAVES_2:1)
Block(0,26,-1,LEAVES_2:1)
Block(0,26,0,LEAVES_2:1)
Block(0,26,1,LEAVES_2:1)
Block(0,26,2,LOG_2:1)
Block(0,26,3,LEAVES_2:1)
Block(0,26,4,LEAVES_2:1)
Block(0,26,6,LEAVES_2:1)
Block(0,26,7,LOG_2:1)
Block(0,26,8,LOG_2:1)
Block(0,26,9,LEAVES_2:1)
Block(0,26,10,LOG_2:1)
Block(0,26,11,LEAVES_2:1)
Block(0,26,12,LEAVES_2:1)
Block(0,27,-1,LOG_2:1)
Block(0,27,0,LEAVES_2:1)
Block(0,27,1,LEAVES_2:1)
Block(0,27,2,LEAVES_2:1)
Block(0,27,3,LEAVES_2:1)
Block(0,27,7,LEAVES_2:1)
Block(0,27,8,LEAVES_2:1)
Block(0,27,10,LOG_2:1)
Block(0,27,11,LEAVES_2:1)
Block(0,27,12,LEAVES_2:1)
Block(0,27,13,LEAVES_2:1)
Block(0,28,-2,LEAVES_2:1)
Block(0,28,-1,LOG_2:1)
Block(0,28,0,LEAVES_2:1)
Block(0,28,1,LEAVES_2:1)
Block(0,28,3,LEAVES_2:1)
Block(0,28,4,LEAVES_2:1)
Block(0,28,7,LEAVES_2:1)
Block(0,28,8,LEAVES_2:1)
Block(0,28,9,LEAVES_2:1)
Block(0,28,10,LEAVES_2:1)
Block(0,28,11,LEAVES_2:1)
Block(0,28,12,LEAVES_2:1)
Block(0,28,13,LEAVES_2:1)
Block(0,28,14,LEAVES_2:1)
Block(0,29,-2,LEAVES_2:1)
Block(0,29,-1,LEAVES_2:1)
Block(0,29,0,LEAVES_2:1)
Block(0,29,1,LEAVES_2:1)
Block(0,29,2,LEAVES_2:1)
Block(0,29,3,LEAVES_2:1)
Block(0,29,4,LOG_2:1)
Block(0,29,5,LEAVES_2:1)
Block(0,29,8,LEAVES_2:1)
Block(0,29,9,LEAVES_2:1)
Block(0,29,10,LEAVES_2:1)
Block(0,29,11,LOG_2:1)
Block(0,29,12,LEAVES_2:1)
Block(0,30,-1,LEAVES_2:1)
Block(0,30,0,LEAVES_2:1)
Block(0,30,1,LEAVES_2:1)
Block(0,30,2,LEAVES_2:1)
Block(0,30,3,LEAVES_2:1)
Block(0,30,4,LOG_2:1)
Block(0,30,7,LEAVES_2:1)
Block(0,30,8,LEAVES_2:1)
Block(0,31,2,LEAVES_2:1)
Block(0,31,4,LEAVES_2:1)
Block(0,31,5,LEAVES_2:1)
Block(0,32,2,LEAVES_2:1)
Block(0,32,3,LEAVES_2:1)
Block(0,33,0,LEAVES_2:1)
Block(0,33,2,LEAVES_2:1)
Block(0,33,3,LEAVES_2:1)
Block(0,34,-1,LEAVES_2:1)
Block(0,34,0,LEAVES_2:1)
Block(0,34,1,LEAVES_2:1)
Block(0,34,2,LEAVES_2:1)
Block(0,34,3,LEAVES_2:1)
Block(0,34,4,LEAVES_2:1)
Block(0,34,6,LEAVES_2:1)
Block(0,34,8,LEAVES_2:1)
Block(0,35,-3,LEAVES_2:1)
Block(0,35,-1,LEAVES_2:1)
Block(0,35,0,LEAVES_2:1)
Block(0,35,1,LEAVES_2:1)
Block(0,35,2,LOG_2:1)
Block(0,35,4,LEAVES_2:1)
Block(0,35,5,LOG_2:1)
Block(0,35,7,LEAVES_2:1)
Block(0,35,8,LEAVES_2:1)
Block(0,36,-5,LEAVES_2:1)
Block(0,36,-3,LEAVES_2:1)
Block(0,36,-2,LOG_2:1)
Block(0,36,-1,LEAVES_2:1)
Block(0,36,0,LEAVES_2:1)
Block(0,36,1,LEAVES_2:1)
Block(0,36,2,LOG_2:1)
Block(0,36,3,LEAVES_2:1)
Block(0,36,4,LEAVES_2:1)
Block(0,36,5,LOG_2:1)
Block(0,36,6,LOG_2:1)
Block(0,36,7,LOG_2:1)
Block(0,37,-4,LEAVES_2:1)
Block(0,37,-3,LEAVES_2:1)
Block(0,37,-2,LOG_2:1)
Block(0,37,-1,LEAVES_2:1)
Block(0,37,0,LEAVES_2:1)
Block(0,37,1,LEAVES_2:1)
Block(0,37,3,LEAVES_2:1)
Block(0,37,4,LEAVES_2:1)
Block(0,37,5,LEAVES_2:1)
Block(0,37,6,LEAVES_2:1)
Block(0,37,7,LEAVES_2:1)
Block(0,37,8,LEAVES_2:1)
Block(0,38,-4,LEAVES_2:1)
Block(0,38,-3,LEAVES_2:1)
Block(0,38,-2,LEAVES_2:1)
Block(0,38,-1,LEAVES_2:1)
Block(0,38,0,LEAVES_2:1)
Block(0,38,1,LEAVES_2:1)
Block(0,38,2,LEAVES_2:1)
Block(0,38,3,LEAVES_2:1)
Block(0,38,4,LEAVES_2:1)
Block(0,38,5,LOG_2:1)
Block(0,38,6,LEAVES_2:1)
Block(0,38,7,LEAVES_2:1)
Block(0,38,8,LEAVES_2:1)
Block(0,39,-4,LEAVES_2:1)
Block(0,39,-2,LEAVES_2:1)
Block(0,39,-1,LEAVES_2:1)
Block(0,39,0,LEAVES_2:1)
Block(0,39,1,LOG_2:1)
Block(0,39,2,LEAVES_2:1)
Block(0,39,3,LEAVES_2:1)
Block(0,39,4,LEAVES_2:1)
Block(0,39,5,LOG_2:1)
Block(0,39,6,LOG_2:1)
Block(0,39,7,LOG_2:1)
Block(0,39,8,LEAVES_2:1)
Block(0,40,-1,LEAVES_2:1)
Block(0,40,0,LEAVES_2:1)
Block(0,40,2,LEAVES_2:1)
Block(0,40,3,LEAVES_2:1)
Block(0,40,4,LEAVES_2:1)
Block(0,40,5,LEAVES_2:1)
Block(0,40,6,LOG_2:1)
Block(0,40,7,LEAVES_2:1)
Block(0,40,8,LEAVES_2:1)
Block(0,41,-5,LEAVES_2:1)
Block(0,41,-4,LEAVES_2:1)
Block(0,41,-1,LEAVES_2:1)
Block(0,41,0,LEAVES_2:1)
Block(0,41,3,LEAVES_2:1)
Block(0,41,4,LEAVES_2:1)
Block(0,41,7,LEAVES_2:1)
Block(0,41,8,LEAVES_2:1)
Block(0,42,-5,LEAVES_2:1)
Block(0,42,-4,LEAVES_2:1)
Block(0,42,-3,LOG_2:1)
Block(0,42,-2,LOG_2:1)
Block(0,42,-1,LEAVES_2:1)
Block(0,42,0,LEAVES_2:1)
Block(0,42,1,LEAVES_2:1)
Block(0,42,3,LEAVES_2:1)
Block(0,42,4,LEAVES_2:1)
Block(0,42,6,LEAVES_2:1)
Block(0,42,7,LEAVES_2:1)
Block(0,43,-2,LOG_2:1)
Block(0,43,-1,LEAVES_2:1)
Block(0,43,0,LEAVES_2:1)
Block(0,43,3,LEAVES_2:1)
Block(0,43,6,LEAVES_2:1)
Block(0,43,8,LEAVES_2:1)
Block(0,44,-3,LEAVES_2:1)
Block(0,44,-2,LEAVES_2:1)
Block(0,44,-1,LEAVES_2:1)
Block(0,44,0,LEAVES_2:1)
Block(0,44,1,LOG_2:1)
Block(0,44,2,LOG_2:1)
Block(0,44,5,LEAVES_2:1)
Block(0,44,6,LOG_2:1)
Block(0,44,7,LOG_2:1)
Block(0,44,8,LEAVES_2:1)
Block(0,45,-3,LEAVES_2:1)
Block(0,45,-2,LEAVES_2:1)
Block(0,45,-1,LEAVES_2:1)
Block(0,45,0,LEAVES_2:1)
Block(0,45,1,LEAVES_2:1)
Block(0,45,3,LEAVES_2:1)
Block(0,45,8,LEAVES_2:1)
Block(0,46,-4,LEAVES_2:1)
Block(0,46,-3,LEAVES_2:1)
Block(0,46,-2,LEAVES_2:1)
Block(0,46,-1,LEAVES_2:1)
Block(0,46,0,LEAVES_2:1)
Block(0,46,1,LEAVES_2:1)
Block(0,46,3,LEAVES_2:1)
Block(0,46,5,LEAVES_2:1)
Block(0,46,7,LEAVES_2:1)
Block(0,47,-5,LEAVES_2:1)
Block(0,47,-4,LEAVES_2:1)
Block(0,47,-2,LOG_2:1)
Block(0,47,-1,LEAVES_2:1)
Block(0,47,3,LOG_2:1)
Block(0,47,4,LOG_2:1)
Block(0,47,5,LEAVES_2:1)
Block(0,47,6,LEAVES_2:1)
Block(0,48,-2,LEAVES_2:1)
Block(0,48,-1,LEAVES_2:1)
Block(0,48,4,LEAVES_2:1)
Block(0,48,5,LOG_2:1)
Block(0,48,6,LEAVES_2:1)
Block(0,49,4,LOG_2:1)
Block(0,49,6,LEAVES_2:1)
Block(0,49,7,LEAVES_2:1)
Block(0,50,1,LEAVES_2:1)
Block(0,50,2,LEAVES_2:1)
Block(0,50,4,LEAVES_2:1)
Block(0,50,6,LEAVES_2:1)
Block(0,50,7,LEAVES_2:1)
Block(0,51,-1,LEAVES_2:1)
Block(0,51,0,LEAVES_2:1)
Block(0,51,1,LEAVES_2:1)
Block(0,51,2,LEAVES_2:1)
Block(0,51,3,LEAVES_2:1)
Block(0,51,6,LEAVES_2:1)
Block(0,52,-2,LEAVES_2:1)
Block(0,52,-1,LEAVES_2:1)
Block(0,52,0,LEAVES_2:1)
Block(0,52,1,LEAVES_2:1)
Block(0,52,2,LEAVES_2:1)
Block(0,52,5,LEAVES_2:1)
Block(0,53,-1,LEAVES_2:1)
Block(0,53,0,LEAVES_2:1)
Block(0,53,2,LEAVES_2:1)
Block(0,54,1,LEAVES_2:1)
Block(0,54,2,LEAVES_2:1)
Block(0,55,2,LOG_2:1)
Block(0,56,2,LEAVES_2:1)
Block(1,0,3,HUGE_MUSHROOM_1)
Block(1,0,4,LOG_2:1)
Block(1,1,4,HUGE_MUSHROOM_1)
Block(1,5,8,HUGE_MUSHROOM_1)
Block(1,15,3,LEAVES_2:1)
Block(1,15,4,LEAVES_2:1)
Block(1,16,2,LEAVES_2:1)
Block(1,16,3,LOG_2:1)
Block(1,16,4,LEAVES_2:1)
Block(1,17,3,LEAVES_2:1)
Block(1,17,4,LEAVES_2:1)
Block(1,18,-4,LEAVES_2:1)
Block(1,18,3,LEAVES_2:1)
Block(1,18,4,LEAVES_2:1)
Block(1,19,-5,LEAVES_2:1)
Block(1,19,-4,LEAVES_2:1)
Block(1,19,-2,LEAVES_2:1)
Block(1,20,-5,LEAVES_2:1)
Block(1,20,-4,LEAVES_2:1)
Block(1,20,-3,LOG_2:1)
Block(1,20,-2,LOG_2:1)
Block(1,20,0,LEAVES_2:1)
Block(1,20,1,LEAVES_2:1)
Block(1,21,-5,LEAVES_2:1)
Block(1,21,-4,LEAVES_2:1)
Block(1,21,-3,LEAVES_2:1)
Block(1,21,-2,LOG_2:1)
Block(1,21,-1,LOG_2:1)
Block(1,21,0,LEAVES_2:1)
Block(1,21,1,LEAVES_2:1)
Block(1,22,-4,LEAVES_2:1)
Block(1,22,-3,LEAVES_2:1)
Block(1,22,-2,LOG_2:1)
Block(1,22,-1,LEAVES_2:1)
Block(1,22,0,LEAVES_2:1)
Block(1,22,10,LEAVES_2:1)
Block(1,22,11,LEAVES_2:1)
Block(1,23,-4,LEAVES_2:1)
Block(1,23,-3,LEAVES_2:1)
Block(1,23,-2,LEAVES_2:1)
Block(1,23,-1,LEAVES_2:1)
Block(1,23,0,LEAVES_2:1)
Block(1,23,3,LEAVES_2:1)
Block(1,23,6,LEAVES_2:1)
Block(1,23,8,LEAVES_2:1)
Block(1,23,9,LEAVES_2:1)
Block(1,23,10,LEAVES_2:1)
Block(1,24,-2,LEAVES_2:1)
Block(1,24,-1,LEAVES_2:1)
Block(1,24,0,LEAVES_2:1)
Block(1,24,1,LEAVES_2:1)
Block(1,24,2,LEAVES_2:1)
Block(1,24,3,LOG_2:1)
Block(1,24,4,LEAVES_2:1)
Block(1,24,6,LOG_2:1)
Block(1,24,7,LEAVES_2:1)
Block(1,24,8,LEAVES_2:1)
Block(1,24,10,LEAVES_2:1)
Block(1,24,11,LOG_2:1)
Block(1,24,12,LEAVES_2:1)
Block(1,25,-1,LEAVES_2:1)
Block(1,25,0,LEAVES_2:1)
Block(1,25,1,LEAVES_2:1)
Block(1,25,2,LEAVES_2:1)
Block(1,25,3,LOG_2:1)
Block(1,25,4,LEAVES_2:1)
Block(1,25,5,LEAVES_2:1)
Block(1,25,6,LOG_2:1)
Block(1,25,7,LOG_2:1)
Block(1,25,8,LEAVES_2:1)
Block(1,25,9,LEAVES_2:1)
Block(1,25,10,LEAVES_2:1)
Block(1,25,11,LEAVES_2:1)
Block(1,25,12,LEAVES_2:1)
Block(1,26,0,LEAVES_2:1)
Block(1,26,3,LEAVES_2:1)
Block(1,26,5,LEAVES_2:1)
Block(1,26,6,LOG_2:1)
Block(1,26,7,LOG_2:1)
Block(1,26,8,LEAVES_2:1)
Block(1,26,9,LEAVES_2:1)
Block(1,26,10,LEAVES_2:1)
Block(1,26,11,LEAVES_2:1)
Block(1,26,12,LEAVES_2:1)
Block(1,27,-3,LEAVES_2:1)
Block(1,27,-2,LEAVES_2:1)
Block(1,27,-1,LEAVES_2:1)
Block(1,27,0,LEAVES_2:1)
Block(1,27,2,LEAVES_2:1)
Block(1,27,8,LEAVES_2:1)
Block(1,27,9,LEAVES_2:1)
Block(1,27,10,LEAVES_2:1)
Block(1,27,11,LEAVES_2:1)
Block(1,27,12,LEAVES_2:1)
Block(1,28,-3,LEAVES_2:1)
Block(1,28,-2,LEAVES_2:1)
Block(1,28,-1,LOG_2:1)
Block(1,28,0,LOG_2:1)
Block(1,28,1,LOG_2:1)
Block(1,28,2,LEAVES_2:1)
Block(1,28,3,LEAVES_2:1)
Block(1,28,4,LEAVES_2:1)
Block(1,28,8,LEAVES_2:1)
Block(1,28,9,LEAVES_2:1)
Block(1,28,10,LEAVES_2:1)
Block(1,28,11,LEAVES_2:1)
Block(1,28,12,LEAVES_2:1)
Block(1,29,-2,LEAVES_2:1)
Block(1,29,-1,LEAVES_2:1)
Block(1,29,0,LEAVES_2:1)
Block(1,29,1,LOG_2:1)
Block(1,29,2,LEAVES_2:1)
Block(1,29,3,LEAVES_2:1)
Block(1,29,4,LOG_2:1)
Block(1,29,7,LEAVES_2:1)
Block(1,29,8,LEAVES_2:1)
Block(1,29,10,LEAVES_2:1)
Block(1,30,-1,LEAVES_2:1)
Block(1,30,0,LEAVES_2:1)
Block(1,30,1,LEAVES_2:1)
Block(1,30,2,LEAVES_2:1)
Block(1,30,3,LOG_2:1)
Block(1,30,4,LOG_2:1)
Block(1,30,5,LEAVES_2:1)
Block(1,30,7,LEAVES_2:1)
Block(1,30,8,LEAVES_2:1)
Block(1,31,0,LEAVES_2:1)
Block(1,31,1,LEAVES_2:1)
Block(1,31,2,LEAVES_2:1)
Block(1,31,3,LOG_2:1)
Block(1,31,4,LEAVES_2:1)
Block(1,31,8,LEAVES_2:1)
Block(1,31,9,LEAVES_2:1)
Block(1,32,2,LEAVES_2:1)
Block(1,32,4,LEAVES_2:1)
Block(1,32,8,LEAVES_2:1)
Block(1,33,-2,LEAVES_2:1)
Block(1,33,9,LEAVES_2:1)
Block(1,34,4,LEAVES_2:1)
Block(1,34,5,LEAVES_2:1)
Block(1,34,6,LEAVES_2:1)
Block(1,35,-4,LEAVES_2:1)
Block(1,35,-3,LEAVES_2:1)
Block(1,35,-1,LEAVES_2:1)
Block(1,35,0,LEAVES_2:1)
Block(1,35,3,LOG_2:1)
Block(1,35,4,LEAVES_2:1)
Block(1,35,6,LEAVES_2:1)
Block(1,35,7,LEAVES_2:1)
Block(1,36,-5,LEAVES_2:1)
Block(1,36,-4,LEAVES_2:1)
Block(1,36,-3,LOG_2:1)
Block(1,36,-2,LOG_2:1)
Block(1,36,-1,LEAVES_2:1)
Block(1,36,0,LEAVES_2:1)
Block(1,36,1,LEAVES_2:1)
Block(1,36,2,LEAVES_2:1)
Block(1,36,3,LEAVES_2:1)
Block(1,36,4,LEAVES_2:1)
Block(1,36,6,LOG_2:1)
Block(1,36,7,LEAVES_2:1)
Block(1,36,8,LEAVES_2:1)
Block(1,36,9,LEAVES_2:1)
Block(1,37,-4,LEAVES_2:1)
Block(1,37,-3,LEAVES_2:1)
Block(1,37,-2,LOG_2:1)
Block(1,37,-1,LOG_2:1)
Block(1,37,0,LEAVES_2:1)
Block(1,37,1,LEAVES_2:1)
Block(1,37,2,LEAVES_2:1)
Block(1,37,3,LEAVES_2:1)
Block(1,37,4,LEAVES_2:1)
Block(1,37,5,LEAVES_2:1)
Block(1,37,7,LEAVES_2:1)
Block(1,37,8,LEAVES_2:1)
Block(1,38,-5,LEAVES_2:1)
Block(1,38,-4,LEAVES_2:1)
Block(1,38,-3,LEAVES_2:1)
Block(1,38,-2,LEAVES_2:1)
Block(1,38,-1,LEAVES_2:1)
Block(1,38,0,LEAVES_2:1)
Block(1,38,2,LEAVES_2:1)
Block(1,38,3,LEAVES_2:1)
Block(1,38,4,LEAVES_2:1)
Block(1,38,5,LEAVES_2:1)
Block(1,38,6,LEAVES_2:1)
Block(1,39,-4,LEAVES_2:1)
Block(1,39,-3,LEAVES_2:1)
Block(1,39,-2,LEAVES_2:1)
Block(1,39,-1,LEAVES_2:1)
Block(1,39,0,LEAVES_2:1)
Block(1,39,1,LOG_2:1)
Block(1,39,2,LEAVES_2:1)
Block(1,39,4,LEAVES_2:1)
Block(1,39,5,LOG_2:1)
Block(1,39,6,LEAVES_2:1)
Block(1,39,8,LEAVES_2:1)
Block(1,40,-2,LEAVES_2:1)
Block(1,40,1,LEAVES_2:1)
Block(1,40,2,LEAVES_2:1)
Block(1,40,3,LEAVES_2:1)
Block(1,40,4,LOG_2:1)
Block(1,40,5,LOG_2:1)
Block(1,40,6,LEAVES_2:1)
Block(1,40,7,LEAVES_2:1)
Block(1,41,-5,LEAVES_2:1)
Block(1,41,-4,LEAVES_2:1)
Block(1,41,-2,LEAVES_2:1)
Block(1,41,2,LEAVES_2:1)
Block(1,41,3,LEAVES_2:1)
Block(1,41,4,LEAVES_2:1)
Block(1,41,5,LEAVES_2:1)
Block(1,41,6,LEAVES_2:1)
Block(1,41,7,LEAVES_2:1)
Block(1,41,8,LEAVES_2:1)
Block(1,42,-5,LEAVES_2:1)
Block(1,42,-4,LEAVES_2:1)
Block(1,42,-2,LEAVES_2:1)
Block(1,42,-1,LOG_2:1)
Block(1,42,0,LEAVES_2:1)
Block(1,42,1,LEAVES_2:1)
Block(1,42,2,LEAVES_2:1)
Block(1,42,3,LEAVES_2:1)
Block(1,42,6,LEAVES_2:1)
Block(1,42,7,LEAVES_2:1)
Block(1,43,-4,LEAVES_2:1)
Block(1,43,-2,LOG_2:1)
Block(1,43,-1,LOG_2:1)
Block(1,43,0,LEAVES_2:1)
Block(1,43,2,LEAVES_2:1)
Block(1,43,3,LEAVES_2:1)
Block(1,43,4,LEAVES_2:1)
Block(1,43,6,LOG_2:1)
Block(1,43,7,LOG_2:1)
Block(1,44,-2,LEAVES_2:1)
Block(1,44,-1,LEAVES_2:1)
Block(1,44,0,LEAVES_2:1)
Block(1,44,1,LOG_2:1)
Block(1,44,2,LEAVES_2:1)
Block(1,44,3,LOG_2:1)
Block(1,44,4,LEAVES_2:1)
Block(1,44,6,LOG_2:1)
Block(1,44,7,LOG_2:1)
Block(1,44,8,LEAVES_2:1)
Block(1,44,9,LEAVES_2:1)
Block(1,45,-5,LEAVES_2:1)
Block(1,45,-4,LEAVES_2:1)
Block(1,45,-3,LEAVES_2:1)
Block(1,45,-2,LEAVES_2:1)
Block(1,45,-1,LEAVES_2:1)
Block(1,45,0,LEAVES_2:1)
Block(1,45,1,LEAVES_2:1)
Block(1,45,2,LEAVES_2:1)
Block(1,45,4,LEAVES_2:1)
Block(1,45,5,LEAVES_2:1)
Block(1,45,7,LEAVES_2:1)
Block(1,45,8,LEAVES_2:1)
Block(1,46,-5,LEAVES_2:1)
Block(1,46,-3,LEAVES_2:1)
Block(1,46,-2,LEAVES_2:1)
Block(1,46,-1,LEAVES_2:1)
Block(1,46,0,LEAVES_2:1)
Block(1,46,1,LEAVES_2:1)
Block(1,46,2,LEAVES_2:1)
Block(1,46,3,LEAVES_2:1)
Block(1,46,4,LEAVES_2:1)
Block(1,46,5,LEAVES_2:1)
Block(1,46,6,LEAVES_2:1)
Block(1,46,7,LEAVES_2:1)
Block(1,47,-3,LEAVES_2:1)
Block(1,47,-2,LOG_2:1)
Block(1,47,-1,LOG_2:1)
Block(1,47,0,LEAVES_2:1)
Block(1,47,2,LEAVES_2:1)
Block(1,47,3,LEAVES_2:1)
Block(1,47,4,LOG_2:1)
Block(1,47,5,LEAVES_2:1)
Block(1,47,6,LEAVES_2:1)
Block(1,48,-3,LEAVES_2:1)
Block(1,48,-2,LOG_2:1)
Block(1,48,-1,LEAVES_2:1)
Block(1,48,0,LEAVES_2:1)
Block(1,48,2,LEAVES_2:1)
Block(1,48,3,LEAVES_2:1)
Block(1,48,4,LOG_2:1)
Block(1,48,5,LEAVES_2:1)
Block(1,48,6,LEAVES_2:1)
Block(1,49,-1,LEAVES_2:1)
Block(1,49,4,LEAVES_2:1)
Block(1,49,5,LEAVES_2:1)
Block(1,50,-1,LEAVES_2:1)
Block(1,50,0,LEAVES_2:1)
Block(1,50,1,LEAVES_2:1)
Block(1,50,2,LEAVES_2:1)
Block(1,50,3,LEAVES_2:1)
Block(1,50,6,LEAVES_2:1)
Block(1,50,7,LEAVES_2:1)
Block(1,51,-2,LEAVES_2:1)
Block(1,51,-1,LEAVES_2:1)
Block(1,51,0,LEAVES_2:1)
Block(1,51,2,LEAVES_2:1)
Block(1,51,3,LEAVES_2:1)
Block(1,51,4,LEAVES_2:1)
Block(1,51,6,LEAVES_2:1)
Block(1,51,7,LEAVES_2:1)
Block(1,52,-3,LEAVES_2:1)
Block(1,52,-2,LEAVES_2:1)
Block(1,52,-1,LOG_2:1)
Block(1,52,0,LEAVES_2:1)
Block(1,52,2,LEAVES_2:1)
Block(1,52,3,LEAVES_2:1)
Block(1,53,-3,LEAVES_2:1)
Block(1,53,-2,LEAVES_2:1)
Block(1,53,-1,LEAVES_2:1)
Block(1,53,0,LEAVES_2:1)
Block(1,53,1,LEAVES_2:1)
Block(1,53,2,LEAVES_2:1)
Block(1,53,3,LEAVES_2:1)
Block(1,54,-1,LEAVES_2:1)
Block(1,54,0,LEAVES_2:1)
Block(1,54,1,LEAVES_2:1)
Block(1,54,2,LEAVES_2:1)
Block(1,55,0,LEAVES_2:1)
Block(1,55,1,LEAVES_2:1)
Block(1,55,2,LOG_2:1)
Block(1,55,3,LOG_2:1)
Block(1,56,1,LEAVES_2:1)
Block(1,56,2,LEAVES_2:1)
Block(1,57,2,LEAVES_2:1)
Block(1,60,-2,LEAVES_2:1)
Block(1,60,-1,LEAVES_2:1)
Block(2,0,3,HUGE_MUSHROOM_1)
Block(2,0,4,LOG_2:1)
Block(2,0,5,LOG_2:1)
Block(2,0,6,LOG_2:1)
Block(2,0,7,LOG_2:1)
Block(2,1,4,LOG_2:1)
Block(2,1,5,LOG_2:1)
Block(2,1,6,LOG_2:1)
Block(2,2,4,LOG_2:1)
Block(2,2,5,LOG_2:1)
Block(2,2,6,LOG_2:1)
Block(2,3,4,LOG_2:1)
Block(2,3,5,LOG_2:1)
Block(2,4,4,LOG_2:1)
Block(2,4,5,LOG_2:1)
Block(2,5,4,LOG_2:1)
Block(2,5,5,LOG_2:1)
Block(2,5,6,HUGE_MUSHROOM_1)
Block(2,5,7,HUGE_MUSHROOM_1)
Block(2,5,9,HUGE_MUSHROOM_1)
Block(2,6,5,LOG_2:1)
Block(2,6,7,HUGE_MUSHROOM_1)
Block(2,7,4,LOG_2:1)
Block(2,7,5,LOG_2:1)
Block(2,8,5,LOG_2:1)
Block(2,9,5,LOG_2:1)
Block(2,11,8,LEAVES_2:1)
Block(2,11,10,LEAVES_2:1)
Block(2,12,8,LEAVES_2:1)
Block(2,12,10,LEAVES_2:1)
Block(2,13,8,LEAVES_2:1)
Block(2,13,10,LEAVES_2:1)
Block(2,16,2,LEAVES_2:1)
Block(2,16,4,LEAVES_2:1)
Block(2,17,2,LEAVES_2:1)
Block(2,17,3,LOG_2:1)
Block(2,17,4,LOG_2:1)
Block(2,18,2,LEAVES_2:1)
Block(2,18,3,LEAVES_2:1)
Block(2,18,4,LEAVES_2:1)
Block(2,19,-5,LEAVES_2:1)
Block(2,19,-1,LEAVES_2:1)
Block(2,19,0,LEAVES_2:1)
Block(2,19,1,LEAVES_2:1)
Block(2,20,-5,LEAVES_2:1)
Block(2,20,-4,LEAVES_2:1)
Block(2,20,-3,LEAVES_2:1)
Block(2,20,-2,LEAVES_2:1)
Block(2,20,0,LEAVES_2:1)
Block(2,20,6,LOG_2:1)
Block(2,21,-5,LEAVES_2:1)
Block(2,21,-4,LEAVES_2:1)
Block(2,21,-3,LEAVES_2:1)
Block(2,21,-2,LEAVES_2:1)
Block(2,21,-1,LOG_2:1)
Block(2,21,0,LEAVES_2:1)
Block(2,21,2,LEAVES_2:1)
Block(2,21,6,LOG_2:1)
Block(2,22,-4,LEAVES_2:1)
Block(2,22,-3,LEAVES_2:1)
Block(2,22,-2,LEAVES_2:1)
Block(2,22,0,LEAVES_2:1)
Block(2,22,1,LOG_2:1)
Block(2,22,2,LOG_2:1)
Block(2,22,6,LOG_2:1)
Block(2,23,-2,LEAVES_2:1)
Block(2,23,-1,LEAVES_2:1)
Block(2,23,0,LEAVES_2:1)
Block(2,23,1,LEAVES_2:1)
Block(2,23,2,LEAVES_2:1)
Block(2,23,3,LEAVES_2:1)
Block(2,23,5,LOG_2:1)
Block(2,23,8,LEAVES_2:1)
Block(2,23,10,LEAVES_2:1)
Block(2,23,11,LEAVES_2:1)
Block(2,23,12,LEAVES_2:1)
Block(2,24,-1,LEAVES_2:1)
Block(2,24,0,LEAVES_2:1)
Block(2,24,1,LEAVES_2:1)
Block(2,24,2,LEAVES_2:1)
Block(2,24,3,LOG_2:1)
Block(2,24,4,LEAVES_2:1)
Block(2,24,5,LOG_2:1)
Block(2,24,6,LOG_2:1)
Block(2,24,10,LEAVES_2:1)
Block(2,24,11,LEAVES_2:1)
Block(2,25,-1,LEAVES_2:1)
Block(2,25,0,LEAVES_2:1)
Block(2,25,1,LEAVES_2:1)
Block(2,25,2,LEAVES_2:1)
Block(2,25,3,LOG_2:1)
Block(2,25,5,LOG_2:1)
Block(2,25,6,LOG_2:1)
Block(2,25,8,LEAVES_2:1)
Block(2,25,9,LEAVES_2:1)
Block(2,25,10,LEAVES_2:1)
Block(2,25,11,LEAVES_2:1)
Block(2,25,12,LEAVES_2:1)
Block(2,26,-2,LEAVES_2:1)
Block(2,26,-1,LEAVES_2:1)
Block(2,26,0,LEAVES_2:1)
Block(2,26,2,LEAVES_2:1)
Block(2,26,5,LOG_2:1)
Block(2,26,6,LOG_2:1)
Block(2,26,8,LEAVES_2:1)
Block(2,26,9,LEAVES_2:1)
Block(2,26,10,LEAVES_2:1)
Block(2,26,11,LEAVES_2:1)
Block(2,26,12,LEAVES_2:1)
Block(2,27,-2,LEAVES_2:1)
Block(2,27,-1,LEAVES_2:1)
Block(2,27,0,LEAVES_2:1)
Block(2,27,1,LEAVES_2:1)
Block(2,27,2,LEAVES_2:1)
Block(2,27,8,LEAVES_2:1)
Block(2,27,9,LEAVES_2:1)
Block(2,27,10,LEAVES_2:1)
Block(2,27,11,LEAVES_2:1)
Block(2,27,12,LEAVES_2:1)
Block(2,28,-1,LEAVES_2:1)
Block(2,28,0,LOG_2:1)
Block(2,28,2,LEAVES_2:1)
Block(2,28,3,LEAVES_2:1)
Block(2,28,4,LEAVES_2:1)
Block(2,28,9,LEAVES_2:1)
Block(2,28,10,LEAVES_2:1)
Block(2,28,11,LEAVES_2:1)
Block(2,29,-1,LEAVES_2:1)
Block(2,29,0,LEAVES_2:1)
Block(2,29,2,LOG_2:1)
Block(2,29,3,LOG_2:1)
Block(2,29,4,LOG_2:1)
Block(2,29,8,LEAVES_2:1)
Block(2,29,9,LEAVES_2:1)
Block(2,29,10,LEAVES_2:1)
Block(2,29,11,LEAVES_2:1)
Block(2,30,-1,LEAVES_2:1)
Block(2,30,0,LEAVES_2:1)
Block(2,30,1,LEAVES_2:1)
Block(2,30,2,LEAVES_2:1)
Block(2,30,3,LOG_2:1)
Block(2,30,4,LEAVES_2:1)
Block(2,30,6,LOG_2:1)
Block(2,30,7,LOG_2:1)
Block(2,30,8,LEAVES_2:1)
Block(2,30,9,LEAVES_2:1)
Block(2,30,10,LEAVES_2:1)
Block(2,30,11,LEAVES_2:1)
Block(2,31,-4,LEAVES_2:1)
Block(2,31,0,LEAVES_2:1)
Block(2,31,1,LEAVES_2:1)
Block(2,31,2,LEAVES_2:1)
Block(2,31,3,LOG_2:1)
Block(2,31,4,LEAVES_2:1)
Block(2,31,5,LOG_2:1)
Block(2,31,6,LOG_2:1)
Block(2,31,7,LEAVES_2:1)
Block(2,31,10,LOG_2:1)
Block(2,31,11,LEAVES_2:1)
Block(2,32,-3,LEAVES_2:1)
Block(2,32,-2,LOG_2:1)
Block(2,32,3,LEAVES_2:1)
Block(2,32,4,LEAVES_2:1)
Block(2,32,8,LEAVES_2:1)
Block(2,32,10,LEAVES_2:1)
Block(2,33,-4,LEAVES_2:1)
Block(2,33,-3,LEAVES_2:1)
Block(2,33,-2,LEAVES_2:1)
Block(2,33,-1,LEAVES_2:1)
Block(2,33,7,LEAVES_2:1)
Block(2,33,8,LEAVES_2:1)
Block(2,33,9,LEAVES_2:1)
Block(2,34,-2,LEAVES_2:1)
Block(2,34,-1,LEAVES_2:1)
Block(2,34,4,LEAVES_2:1)
Block(2,34,5,LEAVES_2:1)
Block(2,35,-4,LEAVES_2:1)
Block(2,35,-2,LEAVES_2:1)
Block(2,35,0,LEAVES_2:1)
Block(2,35,1,LEAVES_2:1)
Block(2,35,3,LOG_2:1)
Block(2,35,4,LEAVES_2:1)
Block(2,35,5,LEAVES_2:1)
Block(2,36,-6,LEAVES_2:1)
Block(2,36,-5,LEAVES_2:1)
Block(2,36,-3,LEAVES_2:1)
Block(2,36,-2,LEAVES_2:1)
Block(2,36,-1,LEAVES_2:1)
Block(2,36,0,LOG_2:1)
Block(2,36,1,LEAVES_2:1)
Block(2,36,2,LOG_2:1)
Block(2,36,3,LOG_2:1)
Block(2,36,4,LOG_2:1)
Block(2,36,5,LOG_2:1)
Block(2,36,6,LEAVES_2:1)
Block(2,36,7,LEAVES_2:1)
Block(2,37,-4,LEAVES_2:1)
Block(2,37,-3,LEAVES_2:1)
Block(2,37,-2,LOG_2:1)
Block(2,37,-1,LOG_2:1)
Block(2,37,0,LEAVES_2:1)
Block(2,37,2,LOG_2:1)
Block(2,37,3,LEAVES_2:1)
Block(2,37,4,LOG_2:1)
Block(2,38,-2,LEAVES_2:1)
Block(2,38,-1,LOG_2:1)
Block(2,38,0,LOG_2:1)
Block(2,38,1,LEAVES_2:1)
Block(2,38,2,LEAVES_2:1)
Block(2,38,3,LEAVES_2:1)
Block(2,38,4,LEAVES_2:1)
Block(2,38,6,LEAVES_2:1)
Block(2,38,7,LEAVES_2:1)
Block(2,38,8,LEAVES_2:1)
Block(2,39,-4,LEAVES_2:1)
Block(2,39,-3,LEAVES_2:1)
Block(2,39,-2,LEAVES_2:1)
Block(2,39,-1,LEAVES_2:1)
Block(2,39,1,LOG_2:1)
Block(2,39,2,LEAVES_2:1)
Block(2,39,3,LEAVES_2:1)
Block(2,39,4,LEAVES_2:1)
Block(2,39,5,LEAVES_2:1)
Block(2,39,7,LEAVES_2:1)
Block(2,40,-5,LEAVES_2:1)
Block(2,40,-4,LEAVES_2:1)
Block(2,40,-3,LEAVES_2:1)
Block(2,40,1,LEAVES_2:1)
Block(2,40,2,LEAVES_2:1)
Block(2,40,3,LOG_2:1)
Block(2,40,4,LOG_2:1)
Block(2,40,5,LEAVES_2:1)
Block(2,40,6,LEAVES_2:1)
Block(2,40,7,LEAVES_2:1)
Block(2,40,8,LEAVES_2:1)
Block(2,41,-4,LEAVES_2:1)
Block(2,41,-3,LEAVES_2:1)
Block(2,41,-1,LEAVES_2:1)
Block(2,41,1,LEAVES_2:1)
Block(2,41,2,LEAVES_2:1)
Block(2,41,3,LEAVES_2:1)
Block(2,41,4,LEAVES_2:1)
Block(2,41,5,LEAVES_2:1)
Block(2,41,6,LEAVES_2:1)
Block(2,42,-2,LEAVES_2:1)
Block(2,42,0,LEAVES_2:1)
Block(2,42,2,LEAVES_2:1)
Block(2,42,3,LEAVES_2:1)
Block(2,42,4,LEAVES_2:1)
Block(2,42,5,LEAVES_2:1)
Block(2,42,6,LEAVES_2:1)
Block(2,42,7,LEAVES_2:1)
Block(2,43,-2,LEAVES_2:1)
Block(2,43,-1,LEAVES_2:1)
Block(2,43,0,LOG_2:1)
Block(2,43,1,LOG_2:1)
Block(2,43,4,LEAVES_2:1)
Block(2,43,5,LOG_2:1)
Block(2,43,6,LEAVES_2:1)
Block(2,43,7,LEAVES_2:1)
Block(2,43,8,LEAVES_2:1)
Block(2,44,-4,LEAVES_2:1)
Block(2,44,-1,LEAVES_2:1)
Block(2,44,0,LEAVES_2:1)
Block(2,44,1,LEAVES_2:1)
Block(2,44,2,LOG_2:1)
Block(2,44,4,LOG_2:1)
Block(2,44,5,LOG_2:1)
Block(2,44,6,LEAVES_2:1)
Block(2,44,7,LOG_2:1)
Block(2,44,8,LEAVES_2:1)
Block(2,44,9,LEAVES_2:1)
Block(2,45,-5,LEAVES_2:1)
Block(2,45,-4,LEAVES_2:1)
Block(2,45,-2,LEAVES_2:1)
Block(2,45,-1,LEAVES_2:1)
Block(2,45,0,LEAVES_2:1)
Block(2,45,2,LEAVES_2:1)
Block(2,45,3,LOG_2:1)
Block(2,45,4,LEAVES_2:1)
Block(2,45,5,LEAVES_2:1)
Block(2,45,6,LEAVES_2:1)
Block(2,45,7,LEAVES_2:1)
Block(2,45,8,LEAVES_2:1)
Block(2,46,-5,LEAVES_2:1)
Block(2,46,-4,LOG_2:1)
Block(2,46,-3,LOG_2:1)
Block(2,46,-2,LEAVES_2:1)
Block(2,46,-1,LOG_2:1)
Block(2,46,0,LEAVES_2:1)
Block(2,46,2,LEAVES_2:1)
Block(2,46,3,LEAVES_2:1)
Block(2,46,4,LEAVES_2:1)
Block(2,46,6,LEAVES_2:1)
Block(2,46,7,LEAVES_2:1)
Block(2,46,8,LEAVES_2:1)
Block(2,47,-5,LEAVES_2:1)
Block(2,47,-3,LEAVES_2:1)
Block(2,47,-2,LOG_2:1)
Block(2,47,-1,LOG_2:1)
Block(2,47,0,LEAVES_2:1)
Block(2,47,1,LOG_2:1)
Block(2,47,2,LEAVES_2:1)
Block(2,47,3,LEAVES_2:1)
Block(2,47,4,LEAVES_2:1)
Block(2,47,5,LEAVES_2:1)
Block(2,47,7,LEAVES_2:1)
Block(2,48,-4,LEAVES_2:1)
Block(2,48,-3,LEAVES_2:1)
Block(2,48,-2,LOG_2:1)
Block(2,48,-1,LOG_2:1)
Block(2,48,0,LOG_2:1)
Block(2,48,1,LOG_2:1)
Block(2,48,2,LEAVES_2:1)
Block(2,48,3,LOG_2:1)
Block(2,48,4,LOG_2:1)
Block(2,48,5,LEAVES_2:1)
Block(2,48,6,LEAVES_2:1)
Block(2,49,-2,LEAVES_2:1)
Block(2,49,-1,LEAVES_2:1)
Block(2,49,0,LEAVES_2:1)
Block(2,49,2,LOG_2:1)
Block(2,49,3,LEAVES_2:1)
Block(2,49,4,LEAVES_2:1)
Block(2,49,5,LEAVES_2:1)
Block(2,49,6,LEAVES_2:1)
Block(2,50,-2,LEAVES_2:1)
Block(2,50,-1,LEAVES_2:1)
Block(2,50,0,LEAVES_2:1)
Block(2,50,1,LEAVES_2:1)
Block(2,50,2,LEAVES_2:1)
Block(2,50,3,LEAVES_2:1)
Block(2,50,5,LEAVES_2:1)
Block(2,50,6,LOG_2:1)
Block(2,50,7,LEAVES_2:1)
Block(2,51,-1,LEAVES_2:1)
Block(2,51,0,LEAVES_2:1)
Block(2,51,1,LEAVES_2:1)
Block(2,51,2,LEAVES_2:1)
Block(2,51,3,LEAVES_2:1)
Block(2,51,4,LEAVES_2:1)
Block(2,51,5,LEAVES_2:1)
Block(2,51,6,LOG_2:1)
Block(2,52,-2,LEAVES_2:1)
Block(2,52,-1,LEAVES_2:1)
Block(2,52,0,LOG_2:1)
Block(2,52,1,LEAVES_2:1)
Block(2,52,2,LEAVES_2:1)
Block(2,52,3,LOG_2:1)
Block(2,52,4,LEAVES_2:1)
Block(2,52,6,LEAVES_2:1)
Block(2,53,-2,LEAVES_2:1)
Block(2,53,-1,LEAVES_2:1)
Block(2,53,0,LEAVES_2:1)
Block(2,53,2,LEAVES_2:1)
Block(2,53,3,LEAVES_2:1)
Block(2,53,4,LEAVES_2:1)
Block(2,53,5,LEAVES_2:1)
Block(2,54,-3,LEAVES_2:1)
Block(2,54,-2,LEAVES_2:1)
Block(2,54,-1,LEAVES_2:1)
Block(2,54,0,LEAVES_2:1)
Block(2,54,2,LEAVES_2:1)
Block(2,54,3,LEAVES_2:1)
Block(2,55,0,LEAVES_2:1)
Block(2,55,1,LOG_2:1)
Block(2,55,2,LOG_2:1)
Block(2,56,-2,LOG_2:1)
Block(2,56,-1,LEAVES_2:1)
Block(2,56,0,LEAVES_2:1)
Block(2,56,1,LEAVES_2:1)
Block(2,56,2,LEAVES_2:1)
Block(2,57,-2,LEAVES_2:1)
Block(2,57,-1,LEAVES_2:1)
Block(2,57,1,LEAVES_2:1)
Block(2,57,2,LEAVES_2:1)
Block(2,57,3,LEAVES_2:1)
Block(2,58,-2,LEAVES_2:1)
Block(2,58,0,LEAVES_2:1)
Block(2,58,1,LEAVES_2:1)
Block(2,58,2,LEAVES_2:1)
Block(2,58,3,LEAVES_2:1)
Block(2,59,-1,LEAVES_2:1)
Block(2,59,0,LEAVES_2:1)
Block(2,59,2,LEAVES_2:1)
Block(2,60,-2,LEAVES_2:1)
Block(2,60,-1,LEAVES_2:1)
Block(2,60,0,LEAVES_2:1)
Block(2,61,-2,LEAVES_2:1)
Block(2,61,-1,LEAVES_2:1)
Block(2,63,-1,LEAVES_2:1)
Block(2,64,-2,LEAVES_2:1)
Block(2,65,-2,LEAVES_2:1)
Block(2,65,-1,LEAVES_2:1)
Block(3,0,2,LOG_2:1)
Block(3,0,3,LOG_2:1)
Block(3,0,5,LOG_2:1)
Block(3,0,6,LOG_2:1)
Block(3,0,7,LOG_2:1)
Block(3,0,8,LOG_2:1)
Block(3,1,2,LOG_2:1)
Block(3,1,3,LOG_2:1)
Block(3,1,5,LOG_2:1)
Block(3,1,6,LOG_2:1)
Block(3,1,7,LOG_2:1)
Block(3,2,2,LOG_2:1)
Block(3,2,3,LOG_2:1)
Block(3,2,5,LOG_2:1)
Block(3,2,6,LOG_2:1)
Block(3,2,7,LOG_2:1)
Block(3,3,3,LOG_2:1)
Block(3,3,5,LOG_2:1)
Block(3,3,6,LOG_2:1)
Block(3,3,7,LOG_2:1)
Block(3,4,3,LOG_2:1)
Block(3,4,5,LOG_2:1)
Block(3,4,7,LOG_2:1)
Block(3,5,3,LOG_2:1)
Block(3,5,5,LOG_2:1)
Block(3,5,7,LOG_2:1)
Block(3,5,8,HUGE_MUSHROOM_1)
Block(3,5,9,HUGE_MUSHROOM_1)
Block(3,6,4,LOG_2:1)
Block(3,6,5,LOG_2:1)
Block(3,6,6,LOG_2:1)
Block(3,6,7,LOG_2:1)
Block(3,7,4,LOG_2:1)
Block(3,7,5,LOG_2:1)
Block(3,7,6,LOG_2:1)
Block(3,7,7,LOG_2:1)
Block(3,8,4,LOG_2:1)
Block(3,8,5,LOG_2:1)
Block(3,8,6,LOG_2:1)
Block(3,8,7,LOG_2:1)
Block(3,9,5,LOG_2:1)
Block(3,9,6,LOG_2:1)
Block(3,10,4,LOG_2:1)
Block(3,10,5,LOG_2:1)
Block(3,10,6,LOG_2:1)
Block(3,11,4,LOG_2:1)
Block(3,11,5,LOG_2:1)
Block(3,11,6,LOG_2:1)
Block(3,11,9,LEAVES_2:1)
Block(3,12,4,LOG_2:1)
Block(3,12,6,LOG_2:1)
Block(3,12,7,LOG_2:1)
Block(3,12,8,LOG_2:1)
Block(3,12,9,LOG_2:1)
Block(3,12,10,LEAVES_2:1)
Block(3,13,4,LOG_2:1)
Block(3,13,6,LOG_2:1)
Block(3,13,8,LOG_2:1)
Block(3,13,9,LEAVES_2:1)
Block(3,14,4,LOG_2:1)
Block(3,14,7,LEAVES_2:1)
Block(3,14,8,LEAVES_2:1)
Block(3,15,4,LOG_2:1)
Block(3,15,6,LEAVES_2:1)
Block(3,15,8,LEAVES_2:1)
Block(3,16,3,LEAVES_2:1)
Block(3,16,4,LOG_2:1)
Block(3,17,3,LOG_2:1)
Block(3,17,4,LOG_2:1)
Block(3,17,5,LEAVES_2:1)
Block(3,17,6,LOG_2:1)
Block(3,18,2,LEAVES_2:1)
Block(3,18,3,LEAVES_2:1)
Block(3,18,4,LOG_2:1)
Block(3,18,5,LEAVES_2:1)
Block(3,18,6,LOG_2:1)
Block(3,19,-2,LEAVES_2:1)
Block(3,19,-1,LEAVES_2:1)
Block(3,19,0,LEAVES_2:1)
Block(3,19,1,LEAVES_2:1)
Block(3,19,4,LOG_2:1)
Block(3,20,-5,LEAVES_2:1)
Block(3,20,-4,LEAVES_2:1)
Block(3,20,-3,LEAVES_2:1)
Block(3,20,-2,LEAVES_2:1)
Block(3,20,-1,LEAVES_2:1)
Block(3,20,0,LEAVES_2:1)
Block(3,20,1,LEAVES_2:1)
Block(3,20,2,LEAVES_2:1)
Block(3,20,4,LOG_2:1)
Block(3,20,5,LOG_2:1)
Block(3,20,6,LOG_2:1)
Block(3,21,-6,LEAVES_2:1)
Block(3,21,-5,LEAVES_2:1)
Block(3,21,-4,LOG_2:1)
Block(3,21,-3,LEAVES_2:1)
Block(3,21,-2,LEAVES_2:1)
Block(3,21,-1,LEAVES_2:1)
Block(3,21,0,LOG_2:1)
Block(3,21,1,LEAVES_2:1)
Block(3,21,2,LOG_2:1)
Block(3,21,4,LOG_2:1)
Block(3,21,5,LOG_2:1)
Block(3,21,6,LOG_2:1)
Block(3,22,-6,LEAVES_2:1)
Block(3,22,-5,LEAVES_2:1)
Block(3,22,-4,LEAVES_2:1)
Block(3,22,-3,LEAVES_2:1)
Block(3,22,-2,LEAVES_2:1)
Block(3,22,0,LEAVES_2:1)
Block(3,22,2,LOG_2:1)
Block(3,22,3,LOG_2:1)
Block(3,22,4,LOG_2:1)
Block(3,22,5,LOG_2:1)
Block(3,22,6,LOG_2:1)
Block(3,22,11,LEAVES_2:1)
Block(3,22,12,LEAVES_2:1)
Block(3,23,-3,LEAVES_2:1)
Block(3,23,-2,LEAVES_2:1)
Block(3,23,-1,LEAVES_2:1)
Block(3,23,0,LEAVES_2:1)
Block(3,23,2,LOG_2:1)
Block(3,23,3,LOG_2:1)
Block(3,23,4,LOG_2:1)
Block(3,23,6,LOG_2:1)
Block(3,23,11,LEAVES_2:1)
Block(3,23,13,LEAVES_2:1)
Block(3,24,-1,LEAVES_2:1)
Block(3,24,0,LEAVES_2:1)
Block(3,24,1,LOG_2:1)
Block(3,24,3,LOG_2:1)
Block(3,24,4,LOG_2:1)
Block(3,24,6,LOG_2:1)
Block(3,24,10,LEAVES_2:1)
Block(3,24,11,LEAVES_2:1)
Block(3,24,13,LEAVES_2:1)
Block(3,25,1,LEAVES_2:1)
Block(3,25,2,LEAVES_2:1)
Block(3,25,3,LOG_2:1)
Block(3,25,4,LOG_2:1)
Block(3,25,5,LOG_2:1)
Block(3,25,6,LOG_2:1)
Block(3,25,10,LEAVES_2:1)
Block(3,25,11,LEAVES_2:1)
Block(3,25,12,LEAVES_2:1)
Block(3,26,-2,LEAVES_2:1)
Block(3,26,-1,LEAVES_2:1)
Block(3,26,0,LEAVES_2:1)
Block(3,26,1,LEAVES_2:1)
Block(3,26,2,LEAVES_2:1)
Block(3,26,3,LOG_2:1)
Block(3,26,4,LOG_2:1)
Block(3,26,5,LOG_2:1)
Block(3,26,11,LEAVES_2:1)
Block(3,27,-2,LEAVES_2:1)
Block(3,27,-1,LEAVES_2:1)
Block(3,27,0,LEAVES_2:1)
Block(3,27,1,LEAVES_2:1)
Block(3,27,2,LEAVES_2:1)
Block(3,27,3,LOG_2:1)
Block(3,27,4,LOG_2:1)
Block(3,27,5,LOG_2:1)
Block(3,27,11,LEAVES_2:1)
Block(3,28,-2,LEAVES_2:1)
Block(3,28,-1,LEAVES_2:1)
Block(3,28,0,LOG_2:1)
Block(3,28,1,LOG_2:1)
Block(3,28,2,LEAVES_2:1)
Block(3,28,3,LOG_2:1)
Block(3,28,4,LOG_2:1)
Block(3,28,5,LOG_2:1)
Block(3,28,9,LEAVES_2:1)
Block(3,28,10,LEAVES_2:1)
Block(3,29,-1,LEAVES_2:1)
Block(3,29,0,LEAVES_2:1)
Block(3,29,1,LOG_2:1)
Block(3,29,2,LEAVES_2:1)
Block(3,29,3,LOG_2:1)
Block(3,29,4,LOG_2:1)
Block(3,29,5,LOG_2:1)
Block(3,29,7,LEAVES_2:1)
Block(3,29,8,LEAVES_2:1)
Block(3,29,9,LEAVES_2:1)
Block(3,29,10,LEAVES_2:1)
Block(3,30,-4,LEAVES_2:1)
Block(3,30,-2,LEAVES_2:1)
Block(3,30,0,LEAVES_2:1)
Block(3,30,1,LEAVES_2:1)
Block(3,30,2,LEAVES_2:1)
Block(3,30,3,LOG_2:1)
Block(3,30,4,LOG_2:1)
Block(3,30,5,LOG_2:1)
Block(3,30,7,LOG_2:1)
Block(3,30,8,LOG_2:1)
Block(3,30,10,LOG_2:1)
Block(3,31,-5,LEAVES_2:1)
Block(3,31,-4,LEAVES_2:1)
Block(3,31,-3,LEAVES_2:1)
Block(3,31,0,LEAVES_2:1)
Block(3,31,3,LOG_2:1)
Block(3,31,4,LOG_2:1)
Block(3,31,6,LOG_2:1)
Block(3,31,7,LEAVES_2:1)
Block(3,31,8,LOG_2:1)
Block(3,31,9,LOG_2:1)
Block(3,31,10,LOG_2:1)
Block(3,31,11,LEAVES_2:1)
Block(3,32,-3,LEAVES_2:1)
Block(3,32,-2,LOG_2:1)
Block(3,32,-1,LEAVES_2:1)
Block(3,32,2,LOG_2:1)
Block(3,32,3,LOG_2:1)
Block(3,32,4,LOG_2:1)
Block(3,32,8,LEAVES_2:1)
Block(3,32,9,LEAVES_2:1)
Block(3,33,-5,LEAVES_2:1)
Block(3,33,-4,LEAVES_2:1)
Block(3,33,-3,LEAVES_2:1)
Block(3,33,-2,LEAVES_2:1)
Block(3,33,-1,LOG_2:1)
Block(3,33,2,LOG_2:1)
Block(3,33,3,LOG_2:1)
Block(3,33,4,LOG_2:1)
Block(3,33,8,LEAVES_2:1)
Block(3,34,-4,LEAVES_2:1)
Block(3,34,-3,LEAVES_2:1)
Block(3,34,-2,LEAVES_2:1)
Block(3,34,-1,LOG_2:1)
Block(3,34,2,LOG_2:1)
Block(3,34,3,LOG_2:1)
Block(3,34,4,LOG_2:1)
Block(3,34,6,LEAVES_2:1)
Block(3,35,-2,LEAVES_2:1)
Block(3,35,2,LOG_2:1)
Block(3,35,3,LOG_2:1)
Block(3,35,4,LOG_2:1)
Block(3,35,5,LEAVES_2:1)
Block(3,35,6,LEAVES_2:1)
Block(3,35,8,LEAVES_2:1)
Block(3,35,9,LEAVES_2:1)
Block(3,36,-3,LEAVES_2:1)
Block(3,36,0,LEAVES_2:1)
Block(3,36,1,LEAVES_2:1)
Block(3,36,2,LOG_2:1)
Block(3,36,3,LOG_2:1)
Block(3,36,4,LOG_2:1)
Block(3,36,5,LOG_2:1)
Block(3,36,6,LEAVES_2:1)
Block(3,36,7,LEAVES_2:1)
Block(3,36,8,LEAVES_2:1)
Block(3,36,9,LEAVES_2:1)
Block(3,37,-2,LEAVES_2:1)
Block(3,37,0,LEAVES_2:1)
Block(3,37,1,LEAVES_2:1)
Block(3,37,2,LOG_2:1)
Block(3,37,3,LOG_2:1)
Block(3,37,4,LOG_2:1)
Block(3,37,5,LEAVES_2:1)
Block(3,37,6,LEAVES_2:1)
Block(3,37,8,LEAVES_2:1)
Block(3,38,-4,LEAVES_2:1)
Block(3,38,-3,LEAVES_2:1)
Block(3,38,-2,LEAVES_2:1)
Block(3,38,0,LEAVES_2:1)
Block(3,38,1,LOG_2:1)
Block(3,38,2,LOG_2:1)
Block(3,38,3,LOG_2:1)
Block(3,38,4,LOG_2:1)
Block(3,38,5,LEAVES_2:1)
Block(3,38,6,LEAVES_2:1)
Block(3,38,7,LEAVES_2:1)
Block(3,38,8,LEAVES_2:1)
Block(3,38,10,LEAVES_2:1)
Block(3,39,-5,LEAVES_2:1)
Block(3,39,-4,LEAVES_2:1)
Block(3,39,0,LEAVES_2:1)
Block(3,39,2,LOG_2:1)
Block(3,39,3,LOG_2:1)
Block(3,39,4,LOG_2:1)
Block(3,39,5,LEAVES_2:1)
Block(3,39,6,LEAVES_2:1)
Block(3,39,7,LEAVES_2:1)
Block(3,39,8,LEAVES_2:1)
Block(3,39,9,LEAVES_2:1)
Block(3,39,10,LEAVES_2:1)
Block(3,40,-5,LEAVES_2:1)
Block(3,40,-4,LEAVES_2:1)
Block(3,40,-3,LEAVES_2:1)
Block(3,40,-2,LEAVES_2:1)
Block(3,40,1,LEAVES_2:1)
Block(3,40,2,LOG_2:1)
Block(3,40,3,LOG_2:1)
Block(3,40,4,LOG_2:1)
Block(3,40,6,LOG_2:1)
Block(3,40,7,LEAVES_2:1)
Block(3,40,8,LEAVES_2:1)
Block(3,40,9,LEAVES_2:1)
Block(3,40,10,LEAVES_2:1)
Block(3,40,11,LEAVES_2:1)
Block(3,41,-5,LEAVES_2:1)
Block(3,41,-4,LEAVES_2:1)
Block(3,41,-3,LEAVES_2:1)
Block(3,41,-2,LEAVES_2:1)
Block(3,41,-1,LEAVES_2:1)
Block(3,41,0,LEAVES_2:1)
Block(3,41,1,LOG_2:1)
Block(3,41,2,LOG_2:1)
Block(3,41,3,LOG_2:1)
Block(3,41,4,LEAVES_2:1)
Block(3,41,5,LEAVES_2:1)
Block(3,41,7,LEAVES_2:1)
Block(3,41,8,LEAVES_2:1)
Block(3,42,-4,LEAVES_2:1)
Block(3,42,-3,LEAVES_2:1)
Block(3,42,-2,LEAVES_2:1)
Block(3,42,-1,LEAVES_2:1)
Block(3,42,0,LEAVES_2:1)
Block(3,42,1,LEAVES_2:1)
Block(3,42,2,LOG_2:1)
Block(3,42,3,LOG_2:1)
Block(3,42,4,LEAVES_2:1)
Block(3,42,5,LEAVES_2:1)
Block(3,42,6,LEAVES_2:1)
Block(3,43,-2,LEAVES_2:1)
Block(3,43,-1,LEAVES_2:1)
Block(3,43,0,LOG_2:1)
Block(3,43,1,LOG_2:1)
Block(3,43,2,LOG_2:1)
Block(3,43,3,LOG_2:1)
Block(3,43,4,LEAVES_2:1)
Block(3,43,5,LEAVES_2:1)
Block(3,43,6,LEAVES_2:1)
Block(3,43,7,LEAVES_2:1)
Block(3,43,8,LEAVES_2:1)
Block(3,43,9,LEAVES_2:1)
Block(3,44,-2,LEAVES_2:1)
Block(3,44,-1,LEAVES_2:1)
Block(3,44,0,LOG_2:1)
Block(3,44,1,LOG_2:1)
Block(3,44,2,LOG_2:1)
Block(3,44,3,LOG_2:1)
Block(3,44,4,LOG_2:1)
Block(3,44,5,LEAVES_2:1)
Block(3,44,7,LEAVES_2:1)
Block(3,44,8,LEAVES_2:1)
Block(3,44,9,LEAVES_2:1)
Block(3,45,-2,LEAVES_2:1)
Block(3,45,-1,LEAVES_2:1)
Block(3,45,0,LEAVES_2:1)
Block(3,45,1,LOG_2:1)
Block(3,45,2,LOG_2:1)
Block(3,45,3,LOG_2:1)
Block(3,45,4,LOG_2:1)
Block(3,45,5,LOG_2:1)
Block(3,45,6,LEAVES_2:1)
Block(3,45,7,LEAVES_2:1)
Block(3,45,9,LEAVES_2:1)
Block(3,46,-5,LEAVES_2:1)
Block(3,46,-4,LEAVES_2:1)
Block(3,46,-3,LOG_2:1)
Block(3,46,-2,LEAVES_2:1)
Block(3,46,-1,LEAVES_2:1)
Block(3,46,1,LEAVES_2:1)
Block(3,46,2,LOG_2:1)
Block(3,46,3,LOG_2:1)
Block(3,46,4,LEAVES_2:1)
Block(3,46,5,LEAVES_2:1)
Block(3,46,7,LEAVES_2:1)
Block(3,46,8,LEAVES_2:1)
Block(3,47,-4,LEAVES_2:1)
Block(3,47,-3,LEAVES_2:1)
Block(3,47,-1,LEAVES_2:1)
Block(3,47,0,LEAVES_2:1)
Block(3,47,2,LOG_2:1)
Block(3,47,3,LOG_2:1)
Block(3,47,4,LEAVES_2:1)
Block(3,47,5,LEAVES_2:1)
Block(3,47,6,LEAVES_2:1)
Block(3,48,-4,LEAVES_2:1)
Block(3,48,-3,LEAVES_2:1)
Block(3,48,-2,LEAVES_2:1)
Block(3,48,-1,LOG_2:1)
Block(3,48,0,LOG_2:1)
Block(3,48,2,LOG_2:1)
Block(3,48,3,LOG_2:1)
Block(3,48,4,LEAVES_2:1)
Block(3,48,6,LEAVES_2:1)
Block(3,49,-2,LOG_2:1)
Block(3,49,-1,LOG_2:1)
Block(3,49,0,LEAVES_2:1)
Block(3,49,1,LOG_2:1)
Block(3,49,2,LOG_2:1)
Block(3,49,3,LOG_2:1)
Block(3,49,4,LEAVES_2:1)
Block(3,49,6,LEAVES_2:1)
Block(3,49,7,LEAVES_2:1)
Block(3,50,-2,LEAVES_2:1)
Block(3,50,-1,LEAVES_2:1)
Block(3,50,0,LOG_2:1)
Block(3,50,1,LEAVES_2:1)
Block(3,50,2,LOG_2:1)
Block(3,50,3,LEAVES_2:1)
Block(3,50,4,LEAVES_2:1)
Block(3,50,5,LEAVES_2:1)
Block(3,50,6,LOG_2:1)
Block(3,51,-2,LEAVES_2:1)
Block(3,51,-1,LEAVES_2:1)
Block(3,51,0,LOG_2:1)
Block(3,51,1,LEAVES_2:1)
Block(3,51,2,LOG_2:1)
Block(3,51,3,LEAVES_2:1)
Block(3,51,4,LEAVES_2:1)
Block(3,51,5,LEAVES_2:1)
Block(3,51,6,LEAVES_2:1)
Block(3,52,-2,LEAVES_2:1)
Block(3,52,-1,LOG_2:1)
Block(3,52,0,LOG_2:1)
Block(3,52,1,LOG_2:1)
Block(3,52,2,LOG_2:1)
Block(3,52,3,LOG_2:1)
Block(3,52,4,LOG_2:1)
Block(3,52,5,LEAVES_2:1)
Block(3,52,7,LEAVES_2:1)
Block(3,53,-2,LEAVES_2:1)
Block(3,53,-1,LEAVES_2:1)
Block(3,53,0,LEAVES_2:1)
Block(3,53,2,LOG_2:1)
Block(3,53,3,LOG_2:1)
Block(3,53,4,LEAVES_2:1)
Block(3,53,6,LEAVES_2:1)
Block(3,54,-2,LEAVES_2:1)
Block(3,54,-1,LEAVES_2:1)
Block(3,54,0,LEAVES_2:1)
Block(3,54,1,LEAVES_2:1)
Block(3,54,2,LOG_2:1)
Block(3,54,3,LEAVES_2:1)
Block(3,54,4,LEAVES_2:1)
Block(3,55,-2,LEAVES_2:1)
Block(3,55,-1,LEAVES_2:1)
Block(3,55,0,LEAVES_2:1)
Block(3,55,2,LOG_2:1)
Block(3,55,3,LEAVES_2:1)
Block(3,55,4,LEAVES_2:1)
Block(3,56,-2,LOG_2:1)
Block(3,56,-1,LOG_2:1)
Block(3,56,0,LEAVES_2:1)
Block(3,56,2,LOG_2:1)
Block(3,56,3,LEAVES_2:1)
Block(3,56,4,LEAVES_2:1)
Block(3,57,-2,LEAVES_2:1)
Block(3,57,-1,LEAVES_2:1)
Block(3,57,0,LEAVES_2:1)
Block(3,57,1,LEAVES_2:1)
Block(3,57,2,LEAVES_2:1)
Block(3,57,4,LEAVES_2:1)
Block(3,58,-2,LEAVES_2:1)
Block(3,58,-1,LEAVES_2:1)
Block(3,58,1,LEAVES_2:1)
Block(3,58,2,LEAVES_2:1)
Block(3,58,4,LEAVES_2:1)
Block(3,59,-2,LEAVES_2:1)
Block(3,59,-1,LEAVES_2:1)
Block(3,59,0,LEAVES_2:1)
Block(3,59,2,LEAVES_2:1)
Block(3,60,-2,LEAVES_2:1)
Block(3,60,-1,LEAVES_2:1)
Block(3,60,0,LEAVES_2:1)
Block(3,60,1,LEAVES_2:1)
Block(3,61,-2,LEAVES_2:1)
Block(3,61,-1,LEAVES_2:1)
Block(3,61,0,LEAVES_2:1)
Block(3,61,1,LEAVES_2:1)
Block(3,62,-1,LEAVES_2:1)
Block(3,62,0,LEAVES_2:1)
Block(3,62,1,LEAVES_2:1)
Block(3,63,-2,LEAVES_2:1)
Block(3,63,-1,LEAVES_2:1)
Block(3,63,0,LEAVES_2:1)
Block(3,63,2,LEAVES_2:1)
Block(3,64,-2,LEAVES_2:1)
Block(3,64,-1,LEAVES_2:1)
Block(3,64,0,LEAVES_2:1)
Block(3,64,2,LEAVES_2:1)
Block(3,65,-2,LEAVES_2:1)
Block(3,65,-1,LEAVES_2:1)
Block(3,65,0,LEAVES_2:1)
Block(3,65,1,LEAVES_2:1)
Block(3,66,-2,LEAVES_2:1)
Block(3,66,-1,LEAVES_2:1)
Block(4,0,2,LOG_2:1)
Block(4,0,3,LOG_2:1)
Block(4,0,4,LOG_2:1)
Block(4,0,5,LOG_2:1)
Block(4,0,6,LOG_2:1)
Block(4,0,7,LOG_2:1)
Block(4,1,2,LOG_2:1)
Block(4,1,3,LOG_2:1)
Block(4,1,4,LOG_2:1)
Block(4,1,5,LOG_2:1)
Block(4,1,6,LOG_2:1)
Block(4,1,7,LOG_2:1)
Block(4,2,3,LOG_2:1)
Block(4,2,4,LOG_2:1)
Block(4,2,5,LOG_2:1)
Block(4,2,6,LOG_2:1)
Block(4,2,7,LOG_2:1)
Block(4,3,3,LOG_2:1)
Block(4,3,4,LOG_2:1)
Block(4,3,5,LOG_2:1)
Block(4,3,6,LOG_2:1)
Block(4,3,7,LOG_2:1)
Block(4,4,1,HUGE_MUSHROOM_1)
Block(4,4,2,HUGE_MUSHROOM_1)
Block(4,4,3,LOG_2:1)
Block(4,4,4,LOG_2:1)
Block(4,4,5,LOG_2:1)
Block(4,4,6,LOG_2:1)
Block(4,4,7,LOG_2:1)
Block(4,5,3,LOG_2:1)
Block(4,5,4,LOG_2:1)
Block(4,5,5,LOG_2:1)
Block(4,5,6,LOG_2:1)
Block(4,5,7,LOG_2:1)
Block(4,5,8,HUGE_MUSHROOM_1)
Block(4,5,9,HUGE_MUSHROOM_1)
Block(4,5,10,HUGE_MUSHROOM_1)
Block(4,6,3,LOG_2:1)
Block(4,6,4,LOG_2:1)
Block(4,6,5,LOG_2:1)
Block(4,6,6,LOG_2:1)
Block(4,6,7,LOG_2:1)
Block(4,7,3,LOG_2:1)
Block(4,7,4,LOG_2:1)
Block(4,7,5,LOG_2:1)
Block(4,7,6,LOG_2:1)
Block(4,7,7,LOG_2:1)
Block(4,8,4,LOG_2:1)
Block(4,8,5,LOG_2:1)
Block(4,8,6,LOG_2:1)
Block(4,8,7,LOG_2:1)
Block(4,9,4,LOG_2:1)
Block(4,9,5,LOG_2:1)
Block(4,9,6,LOG_2:1)
Block(4,10,3,LOG_2:1)
Block(4,10,4,LOG_2:1)
Block(4,10,5,LOG_2:1)
Block(4,10,6,LOG_2:1)
Block(4,11,2,LOG_2:1)
Block(4,11,4,LOG_2:1)
Block(4,11,5,LOG_2:1)
Block(4,11,6,LOG_2:1)
Block(4,11,8,LEAVES_2:1)
Block(4,12,2,HUGE_MUSHROOM_1)
Block(4,12,3,LOG_2:1)
Block(4,12,4,LOG_2:1)
Block(4,12,5,LOG_2:1)
Block(4,12,6,LOG_2:1)
Block(4,12,8,LEAVES_2:1)
Block(4,13,3,LOG_2:1)
Block(4,13,4,LOG_2:1)
Block(4,13,5,LOG_2:1)
Block(4,13,6,LOG_2:1)
Block(4,13,7,LOG_2:1)
Block(4,13,8,LEAVES_2:1)
Block(4,14,3,LOG_2:1)
Block(4,14,4,LOG_2:1)
Block(4,14,5,LOG_2:1)
Block(4,14,6,LOG_2:1)
Block(4,14,7,LOG_2:1)
Block(4,14,8,LEAVES_2:1)
Block(4,14,9,LEAVES_2:1)
Block(4,15,3,LOG_2:1)
Block(4,15,4,LOG_2:1)
Block(4,15,5,LOG_2:1)
Block(4,15,6,LOG_2:1)
Block(4,15,7,LEAVES_2:1)
Block(4,15,8,LEAVES_2:1)
Block(4,16,3,LOG_2:1)
Block(4,16,4,LOG_2:1)
Block(4,16,5,LOG_2:1)
Block(4,16,6,LOG_2:1)
Block(4,17,1,LEAVES_2:1)
Block(4,17,3,LOG_2:1)
Block(4,17,4,LOG_2:1)
Block(4,17,5,LOG_2:1)
Block(4,18,1,LEAVES_2:1)
Block(4,18,3,LOG_2:1)
Block(4,18,4,LOG_2:1)
Block(4,18,5,LOG_2:1)
Block(4,19,-2,LEAVES_2:1)
Block(4,19,-1,LEAVES_2:1)
Block(4,19,1,LEAVES_2:1)
Block(4,19,3,LOG_2:1)
Block(4,19,4,LOG_2:1)
Block(4,19,5,LOG_2:1)
Block(4,19,7,LEAVES_2:1)
Block(4,20,-5,LEAVES_2:1)
Block(4,20,-4,LEAVES_2:1)
Block(4,20,-3,LEAVES_2:1)
Block(4,20,-2,LOG_2:1)
Block(4,20,-1,LOG_2:1)
Block(4,20,0,LEAVES_2:1)
Block(4,20,1,LEAVES_2:1)
Block(4,20,3,LOG_2:1)
Block(4,20,4,LOG_2:1)
Block(4,20,5,LOG_2:1)
Block(4,20,6,LOG_2:1)
Block(4,20,7,LOG_2:1)
Block(4,21,-6,LEAVES_2:1)
Block(4,21,-5,LEAVES_2:1)
Block(4,21,-4,LEAVES_2:1)
Block(4,21,-3,LEAVES_2:1)
Block(4,21,-2,LOG_2:1)
Block(4,21,-1,LOG_2:1)
Block(4,21,0,LOG_2:1)
Block(4,21,1,LOG_2:1)
Block(4,21,4,LOG_2:1)
Block(4,21,5,LOG_2:1)
Block(4,21,6,LOG_2:1)
Block(4,21,7,LEAVES_2:1)
Block(4,22,-5,LEAVES_2:1)
Block(4,22,-4,LEAVES_2:1)
Block(4,22,-3,LEAVES_2:1)
Block(4,22,-2,LOG_2:1)
Block(4,22,-1,LOG_2:1)
Block(4,22,0,LEAVES_2:1)
Block(4,22,1,LOG_2:1)
Block(4,22,2,LEAVES_2:1)
Block(4,22,3,LOG_2:1)
Block(4,22,4,LOG_2:1)
Block(4,22,5,LOG_2:1)
Block(4,22,6,LOG_2:1)
Block(4,22,10,LEAVES_2:1)
Block(4,22,11,LEAVES_2:1)
Block(4,22,12,LEAVES_2:1)
Block(4,23,-4,LEAVES_2:1)
Block(4,23,-3,LEAVES_2:1)
Block(4,23,-1,LEAVES_2:1)
Block(4,23,0,LEAVES_2:1)
Block(4,23,1,LEAVES_2:1)
Block(4,23,2,LOG_2:1)
Block(4,23,3,LOG_2:1)
Block(4,23,4,LOG_2:1)
Block(4,23,5,LOG_2:1)
Block(4,23,7,LEAVES_2:1)
Block(4,23,11,LEAVES_2:1)
Block(4,23,12,LEAVES_2:1)
Block(4,23,13,LEAVES_2:1)
Block(4,24,-3,LEAVES_2:1)
Block(4,24,-2,LEAVES_2:1)
Block(4,24,0,LEAVES_2:1)
Block(4,24,1,LEAVES_2:1)
Block(4,24,3,LOG_2:1)
Block(4,24,4,LOG_2:1)
Block(4,24,5,LOG_2:1)
Block(4,24,6,LOG_2:1)
Block(4,24,7,LEAVES_2:1)
Block(4,24,9,LEAVES_2:1)
Block(4,24,10,LOG_2:1)
Block(4,24,11,LOG_2:1)
Block(4,24,12,LEAVES_2:1)
Block(4,24,13,LEAVES_2:1)
Block(4,25,0,LEAVES_2:1)
Block(4,25,1,LEAVES_2:1)
Block(4,25,2,LEAVES_2:1)
Block(4,25,3,LOG_2:1)
Block(4,25,4,LOG_2:1)
Block(4,25,8,LEAVES_2:1)
Block(4,25,10,LEAVES_2:1)
Block(4,25,11,LEAVES_2:1)
Block(4,25,12,LEAVES_2:1)
Block(4,25,13,LEAVES_2:1)
Block(4,26,0,LEAVES_2:1)
Block(4,26,1,LEAVES_2:1)
Block(4,26,2,LOG_2:1)
Block(4,26,3,LOG_2:1)
Block(4,26,4,LOG_2:1)
Block(4,26,6,LEAVES_2:1)
Block(4,26,7,LEAVES_2:1)
Block(4,26,10,LEAVES_2:1)
Block(4,26,11,LEAVES_2:1)
Block(4,26,12,LEAVES_2:1)
Block(4,26,13,LEAVES_2:1)
Block(4,27,-2,LEAVES_2:1)
Block(4,27,-1,LEAVES_2:1)
Block(4,27,0,LEAVES_2:1)
Block(4,27,1,LEAVES_2:1)
Block(4,27,2,LEAVES_2:1)
Block(4,27,3,LOG_2:1)
Block(4,27,4,LOG_2:1)
Block(4,27,5,LEAVES_2:1)
Block(4,27,6,LEAVES_2:1)
Block(4,27,10,LEAVES_2:1)
Block(4,27,12,LEAVES_2:1)
Block(4,28,-1,LOG_2:1)
Block(4,28,0,LOG_2:1)
Block(4,28,1,LEAVES_2:1)
Block(4,28,3,LOG_2:1)
Block(4,28,4,LOG_2:1)
Block(4,28,5,LOG_2:1)
Block(4,28,7,LEAVES_2:1)
Block(4,28,8,LEAVES_2:1)
Block(4,28,10,LEAVES_2:1)
Block(4,29,-1,LEAVES_2:1)
Block(4,29,0,LEAVES_2:1)
Block(4,29,1,LEAVES_2:1)
Block(4,29,3,LOG_2:1)
Block(4,29,4,LOG_2:1)
Block(4,29,5,LOG_2:1)
Block(4,29,7,LEAVES_2:1)
Block(4,29,8,LEAVES_2:1)
Block(4,29,9,LEAVES_2:1)
Block(4,29,10,LEAVES_2:1)
Block(4,30,-3,LEAVES_2:1)
Block(4,30,-2,LEAVES_2:1)
Block(4,30,0,LEAVES_2:1)
Block(4,30,1,LEAVES_2:1)
Block(4,30,2,LOG_2:1)
Block(4,30,3,LOG_2:1)
Block(4,30,4,LOG_2:1)
Block(4,30,5,LOG_2:1)
Block(4,30,7,LEAVES_2:1)
Block(4,30,8,LEAVES_2:1)
Block(4,30,9,LEAVES_2:1)
Block(4,30,10,LEAVES_2:1)
Block(4,31,-5,LEAVES_2:1)
Block(4,31,-4,LEAVES_2:1)
Block(4,31,-3,LEAVES_2:1)
Block(4,31,-1,LEAVES_2:1)
Block(4,31,3,LOG_2:1)
Block(4,31,4,LOG_2:1)
Block(4,31,5,LOG_2:1)
Block(4,31,6,LEAVES_2:1)
Block(4,31,7,LEAVES_2:1)
Block(4,31,8,LEAVES_2:1)
Block(4,31,10,LEAVES_2:1)
Block(4,32,-4,LEAVES_2:1)
Block(4,32,-3,LOG_2:1)
Block(4,32,-1,LEAVES_2:1)
Block(4,32,0,LOG_2:1)
Block(4,32,3,LOG_2:1)
Block(4,32,4,LOG_2:1)
Block(4,32,5,LOG_2:1)
Block(4,32,6,LEAVES_2:1)
Block(4,32,7,LEAVES_2:1)
Block(4,32,8,LEAVES_2:1)
Block(4,32,10,LEAVES_2:1)
Block(4,33,-5,LEAVES_2:1)
Block(4,33,-4,LEAVES_2:1)
Block(4,33,-3,LEAVES_2:1)
Block(4,33,-2,LEAVES_2:1)
Block(4,33,-1,LOG_2:1)
Block(4,33,2,LEAVES_2:1)
Block(4,33,3,LOG_2:1)
Block(4,33,4,LOG_2:1)
Block(4,33,5,LOG_2:1)
Block(4,33,6,LOG_2:1)
Block(4,33,7,LEAVES_2:1)
Block(4,33,8,LEAVES_2:1)
Block(4,33,9,LEAVES_2:1)
Block(4,34,-4,LEAVES_2:1)
Block(4,34,-3,LEAVES_2:1)
Block(4,34,-1,LOG_2:1)
Block(4,34,0,LOG_2:1)
Block(4,34,1,LOG_2:1)
Block(4,34,2,LOG_2:1)
Block(4,34,3,LOG_2:1)
Block(4,34,4,LOG_2:1)
Block(4,34,9,LEAVES_2:1)
Block(4,35,-4,LEAVES_2:1)
Block(4,35,-3,LEAVES_2:1)
Block(4,35,2,LOG_2:1)
Block(4,35,3,LOG_2:1)
Block(4,35,4,LOG_2:1)
Block(4,35,5,LEAVES_2:1)
Block(4,35,6,LOG_2:1)
Block(4,35,10,LEAVES_2:1)
Block(4,36,-4,LEAVES_2:1)
Block(4,36,-3,LEAVES_2:1)
Block(4,36,2,LOG_2:1)
Block(4,36,3,LOG_2:1)
Block(4,36,4,LOG_2:1)
Block(4,36,5,LOG_2:1)
Block(4,36,6,LOG_2:1)
Block(4,36,7,LEAVES_2:1)
Block(4,36,8,LEAVES_2:1)
Block(4,36,10,LEAVES_2:1)
Block(4,37,-5,LEAVES_2:1)
Block(4,37,-3,LEAVES_2:1)
Block(4,37,-2,LEAVES_2:1)
Block(4,37,2,LOG_2:1)
Block(4,37,3,LOG_2:1)
Block(4,37,4,LOG_2:1)
Block(4,37,5,LOG_2:1)
Block(4,37,6,LEAVES_2:1)
Block(4,37,7,LOG_2:1)
Block(4,37,8,LEAVES_2:1)
Block(4,37,9,LEAVES_2:1)
Block(4,37,10,LEAVES_2:1)
Block(4,38,-3,LEAVES_2:1)
Block(4,38,-2,LEAVES_2:1)
Block(4,38,-1,LEAVES_2:1)
Block(4,38,1,LOG_2:1)
Block(4,38,2,LOG_2:1)
Block(4,38,3,LOG_2:1)
Block(4,38,4,LOG_2:1)
Block(4,38,5,LOG_2:1)
Block(4,38,6,LEAVES_2:1)
Block(4,38,7,LOG_2:1)
Block(4,38,8,LEAVES_2:1)
Block(4,38,9,LEAVES_2:1)
Block(4,38,10,LEAVES_2:1)
Block(4,39,-3,LEAVES_2:1)
Block(4,39,-2,LEAVES_2:1)
Block(4,39,-1,LEAVES_2:1)
Block(4,39,1,LOG_2:1)
Block(4,39,2,LOG_2:1)
Block(4,39,3,LOG_2:1)
Block(4,39,4,LOG_2:1)
Block(4,39,5,LEAVES_2:1)
Block(4,39,6,LEAVES_2:1)
Block(4,39,7,LEAVES_2:1)
Block(4,39,8,LEAVES_2:1)
Block(4,39,10,LEAVES_2:1)
Block(4,40,-6,LEAVES_2:1)
Block(4,40,-5,LEAVES_2:1)
Block(4,40,-4,LEAVES_2:1)
Block(4,40,-3,LOG_2:1)
Block(4,40,-1,LEAVES_2:1)
Block(4,40,0,LEAVES_2:1)
Block(4,40,1,LEAVES_2:1)
Block(4,40,2,LOG_2:1)
Block(4,40,3,LOG_2:1)
Block(4,40,4,LOG_2:1)
Block(4,40,5,LOG_2:1)
Block(4,40,6,LEAVES_2:1)
Block(4,40,7,LEAVES_2:1)
Block(4,40,8,LEAVES_2:1)
Block(4,40,9,LEAVES_2:1)
Block(4,40,10,LEAVES_2:1)
Block(4,40,11,LEAVES_2:1)
Block(4,41,-4,LEAVES_2:1)
Block(4,41,-3,LEAVES_2:1)
Block(4,41,-1,LEAVES_2:1)
Block(4,41,0,LEAVES_2:1)
Block(4,41,2,LOG_2:1)
Block(4,41,3,LOG_2:1)
Block(4,41,4,LOG_2:1)
Block(4,41,5,LEAVES_2:1)
Block(4,41,6,LEAVES_2:1)
Block(4,41,7,LEAVES_2:1)
Block(4,41,11,LEAVES_2:1)
Block(4,42,-5,LEAVES_2:1)
Block(4,42,-4,LEAVES_2:1)
Block(4,42,-3,LEAVES_2:1)
Block(4,42,-1,LEAVES_2:1)
Block(4,42,0,LEAVES_2:1)
Block(4,42,1,LOG_2:1)
Block(4,42,2,LOG_2:1)
Block(4,42,3,LOG_2:1)
Block(4,42,4,LOG_2:1)
Block(4,42,6,LEAVES_2:1)
Block(4,42,7,LEAVES_2:1)
Block(4,42,8,LEAVES_2:1)
Block(4,42,9,LEAVES_2:1)
Block(4,42,10,LEAVES_2:1)
Block(4,43,-4,LEAVES_2:1)
Block(4,43,-2,LEAVES_2:1)
Block(4,43,-1,LEAVES_2:1)
Block(4,43,0,LEAVES_2:1)
Block(4,43,1,LOG_2:1)
Block(4,43,2,LOG_2:1)
Block(4,43,3,LOG_2:1)
Block(4,43,5,LEAVES_2:1)
Block(4,43,6,LEAVES_2:1)
Block(4,43,7,LEAVES_2:1)
Block(4,43,8,LEAVES_2:1)
Block(4,43,9,LEAVES_2:1)
Block(4,43,10,LEAVES_2:1)
Block(4,44,-2,LEAVES_2:1)
Block(4,44,-1,LOG_2:1)
Block(4,44,0,LOG_2:1)
Block(4,44,1,LOG_2:1)
Block(4,44,2,LOG_2:1)
Block(4,44,3,LOG_2:1)
Block(4,44,4,LEAVES_2:1)
Block(4,44,5,LEAVES_2:1)
Block(4,44,6,LEAVES_2:1)
Block(4,44,7,LEAVES_2:1)
Block(4,44,8,LEAVES_2:1)
Block(4,44,10,LEAVES_2:1)
Block(4,45,-3,LEAVES_2:1)
Block(4,45,-2,LEAVES_2:1)
Block(4,45,-1,LEAVES_2:1)
Block(4,45,0,LEAVES_2:1)
Block(4,45,1,LOG_2:1)
Block(4,45,2,LOG_2:1)
Block(4,45,3,LOG_2:1)
Block(4,45,4,LEAVES_2:1)
Block(4,45,5,LEAVES_2:1)
Block(4,45,7,LEAVES_2:1)
Block(4,45,8,LEAVES_2:1)
Block(4,45,9,LEAVES_2:1)
Block(4,46,-3,LEAVES_2:1)
Block(4,46,-2,LEAVES_2:1)
Block(4,46,-1,LEAVES_2:1)
Block(4,46,0,LOG_2:1)
Block(4,46,1,LOG_2:1)
Block(4,46,2,LOG_2:1)
Block(4,46,3,LOG_2:1)
Block(4,46,4,LEAVES_2:1)
Block(4,46,7,LEAVES_2:1)
Block(4,46,8,LEAVES_2:1)
Block(4,47,-3,LEAVES_2:1)
Block(4,47,-2,LEAVES_2:1)
Block(4,47,-1,LEAVES_2:1)
Block(4,47,0,LEAVES_2:1)
Block(4,47,1,LOG_2:1)
Block(4,47,2,LOG_2:1)
Block(4,47,3,LOG_2:1)
Block(4,47,4,LEAVES_2:1)
Block(4,47,5,LEAVES_2:1)
Block(4,48,-3,LEAVES_2:1)
Block(4,48,-1,LEAVES_2:1)
Block(4,48,0,LEAVES_2:1)
Block(4,48,1,LOG_2:1)
Block(4,48,2,LOG_2:1)
Block(4,48,3,LOG_2:1)
Block(4,48,5,LEAVES_2:1)
Block(4,48,6,LOG_2:1)
Block(4,48,7,LOG_2:1)
Block(4,48,8,LOG_2:1)
Block(4,49,-3,LEAVES_2:1)
Block(4,49,-1,LOG_2:1)
Block(4,49,0,LOG_2:1)
Block(4,49,2,LOG_2:1)
Block(4,49,3,LOG_2:1)
Block(4,49,4,LEAVES_2:1)
Block(4,49,6,LOG_2:1)
Block(4,49,7,LOG_2:1)
Block(4,50,-2,LEAVES_2:1)
Block(4,50,-1,LEAVES_2:1)
Block(4,50,0,LOG_2:1)
Block(4,50,1,LOG_2:1)
Block(4,50,2,LOG_2:1)
Block(4,50,3,LOG_2:1)
Block(4,50,4,LEAVES_2:1)
Block(4,50,6,LOG_2:1)
Block(4,50,7,LOG_2:1)
Block(4,50,8,LEAVES_2:1)
Block(4,51,-3,LEAVES_2:1)
Block(4,51,-2,LEAVES_2:1)
Block(4,51,-1,LEAVES_2:1)
Block(4,51,0,LOG_2:1)
Block(4,51,1,LOG_2:1)
Block(4,51,2,LOG_2:1)
Block(4,51,3,LEAVES_2:1)
Block(4,51,4,LEAVES_2:1)
Block(4,51,6,LEAVES_2:1)
Block(4,51,7,LEAVES_2:1)
Block(4,51,8,LEAVES_2:1)
Block(4,52,-3,LEAVES_2:1)
Block(4,52,-2,LEAVES_2:1)
Block(4,52,-1,LEAVES_2:1)
Block(4,52,0,LOG_2:1)
Block(4,52,1,LOG_2:1)
Block(4,52,2,LOG_2:1)
Block(4,52,3,LEAVES_2:1)
Block(4,52,4,LEAVES_2:1)
Block(4,52,5,LEAVES_2:1)
Block(4,52,6,LEAVES_2:1)
Block(4,52,7,LEAVES_2:1)
Block(4,53,-3,LEAVES_2:1)
Block(4,53,-2,LEAVES_2:1)
Block(4,53,-1,LOG_2:1)
Block(4,53,0,LOG_2:1)
Block(4,53,1,LOG_2:1)
Block(4,53,2,LOG_2:1)
Block(4,53,3,LEAVES_2:1)
Block(4,53,4,LEAVES_2:1)
Block(4,53,5,LEAVES_2:1)
Block(4,53,6,LEAVES_2:1)
Block(4,54,-2,LEAVES_2:1)
Block(4,54,-1,LEAVES_2:1)
Block(4,54,0,LOG_2:1)
Block(4,54,1,LOG_2:1)
Block(4,54,2,LOG_2:1)
Block(4,54,3,LOG_2:1)
Block(4,54,4,LEAVES_2:1)
Block(4,55,-4,LEAVES_2:1)
Block(4,55,-2,LEAVES_2:1)
Block(4,55,-1,LEAVES_2:1)
Block(4,55,0,LOG_2:1)
Block(4,55,1,LOG_2:1)
Block(4,55,2,LOG_2:1)
Block(4,55,3,LEAVES_2:1)
Block(4,56,-3,LOG_2:1)
Block(4,56,-2,LEAVES_2:1)
Block(4,56,-1,LEAVES_2:1)
Block(4,56,0,LOG_2:1)
Block(4,56,1,LOG_2:1)
Block(4,56,2,LOG_2:1)
Block(4,56,3,LEAVES_2:1)
Block(4,56,5,LEAVES_2:1)
Block(4,57,-3,LEAVES_2:1)
Block(4,57,-1,LEAVES_2:1)
Block(4,57,0,LOG_2:1)
Block(4,57,2,LOG_2:1)
Block(4,57,3,LOG_2:1)
Block(4,57,4,LEAVES_2:1)
Block(4,57,5,LEAVES_2:1)
Block(4,58,-2,LEAVES_2:1)
Block(4,58,-1,LEAVES_2:1)
Block(4,58,0,LOG_2:1)
Block(4,58,1,LEAVES_2:1)
Block(4,58,2,LOG_2:1)
Block(4,58,3,LEAVES_2:1)
Block(4,59,-2,LEAVES_2:1)
Block(4,59,-1,LEAVES_2:1)
Block(4,59,0,LOG_2:1)
Block(4,59,1,LEAVES_2:1)
Block(4,59,2,LEAVES_2:1)
Block(4,59,3,LEAVES_2:1)
Block(4,60,-3,LEAVES_2:1)
Block(4,60,-2,LEAVES_2:1)
Block(4,60,-1,LEAVES_2:1)
Block(4,60,0,LEAVES_2:1)
Block(4,60,1,LEAVES_2:1)
Block(4,61,-3,LEAVES_2:1)
Block(4,61,-2,LEAVES_2:1)
Block(4,61,-1,LEAVES_2:1)
Block(4,61,0,LEAVES_2:1)
Block(4,61,1,LEAVES_2:1)
Block(4,62,-2,LEAVES_2:1)
Block(4,62,-1,LEAVES_2:1)
Block(4,62,0,LOG_2:1)
Block(4,62,1,LEAVES_2:1)
Block(4,63,-2,LEAVES_2:1)
Block(4,63,-1,LEAVES_2:1)
Block(4,63,0,LEAVES_2:1)
Block(4,63,1,LEAVES_2:1)
Block(4,64,-2,LEAVES_2:1)
Block(4,64,-1,LEAVES_2:1)
Block(4,64,0,LOG_2:1)
Block(4,64,1,LEAVES_2:1)
Block(4,64,2,LEAVES_2:1)
Block(4,65,-1,LEAVES_2:1)
Block(4,65,0,LEAVES_2:1)
Block(4,65,2,LEAVES_2:1)
Block(4,66,-2,LEAVES_2:1)
Block(4,66,-1,LEAVES_2:1)
Block(4,66,0,LEAVES_2:1)
Block(4,67,-2,LEAVES_2:1)
Block(4,67,-1,LEAVES_2:1)
Block(4,68,-2,LEAVES_2:1)
Block(5,0,2,LOG_2:1)
Block(5,0,3,LOG_2:1)
Block(5,0,5,LOG_2:1)
Block(5,0,6,LOG_2:1)
Block(5,0,7,LOG_2:1)
Block(5,0,8,LOG_2:1)
Block(5,1,2,LOG_2:1)
Block(5,1,3,LOG_2:1)
Block(5,1,4,LOG_2:1)
Block(5,1,5,LOG_2:1)
Block(5,1,6,LOG_2:1)
Block(5,1,7,LOG_2:1)
Block(5,1,8,LOG_2:1)
Block(5,2,3,LOG_2:1)
Block(5,2,4,LOG_2:1)
Block(5,2,5,LOG_2:1)
Block(5,2,6,LOG_2:1)
Block(5,2,7,LOG_2:1)
Block(5,3,3,LOG_2:1)
Block(5,3,4,LOG_2:1)
Block(5,3,6,LOG_2:1)
Block(5,3,7,LOG_2:1)
Block(5,4,2,HUGE_MUSHROOM_1)
Block(5,4,3,LOG_2:1)
Block(5,4,4,LOG_2:1)
Block(5,4,6,LOG_2:1)
Block(5,4,7,LOG_2:1)
Block(5,5,2,HUGE_MUSHROOM_1)
Block(5,5,3,LOG_2:1)
Block(5,5,4,LOG_2:1)
Block(5,5,6,LOG_2:1)
Block(5,5,7,LOG_2:1)
Block(5,5,8,HUGE_MUSHROOM_1)
Block(5,5,9,HUGE_MUSHROOM_1)
Block(5,6,3,LOG_2:1)
Block(5,6,4,LOG_2:1)
Block(5,6,6,LOG_2:1)
Block(5,6,7,LOG_2:1)
Block(5,6,8,HUGE_MUSHROOM_1)
Block(5,7,3,LOG_2:1)
Block(5,7,4,LOG_2:1)
Block(5,7,6,LOG_2:1)
Block(5,7,7,LOG_2:1)
Block(5,8,3,LOG_2:1)
Block(5,8,4,LOG_2:1)
Block(5,8,6,LOG_2:1)
Block(5,9,3,LOG_2:1)
Block(5,9,4,LOG_2:1)
Block(5,9,6,LOG_2:1)
Block(5,10,2,HUGE_MUSHROOM_1)
Block(5,10,3,LOG_2:1)
Block(5,10,4,LOG_2:1)
Block(5,10,6,LOG_2:1)
Block(5,11,2,HUGE_MUSHROOM_1)
Block(5,11,3,LOG_2:1)
Block(5,11,4,LOG_2:1)
Block(5,11,6,LOG_2:1)
Block(5,12,3,LOG_2:1)
Block(5,12,4,LOG_2:1)
Block(5,12,5,LOG_2:1)
Block(5,13,3,LOG_2:1)
Block(5,13,4,LOG_2:1)
Block(5,13,5,LOG_2:1)
Block(5,13,6,LOG_2:1)
Block(5,14,3,LOG_2:1)
Block(5,14,4,LOG_2:1)
Block(5,14,5,LOG_2:1)
Block(5,14,7,LEAVES_2:1)
Block(5,14,8,LEAVES_2:1)
Block(5,15,3,LOG_2:1)
Block(5,15,5,LOG_2:1)
Block(5,15,7,LEAVES_2:1)
Block(5,16,3,LOG_2:1)
Block(5,16,5,LOG_2:1)
Block(5,17,1,LEAVES_2:1)
Block(5,17,2,LEAVES_2:1)
Block(5,17,3,LOG_2:1)
Block(5,17,5,LOG_2:1)
Block(5,18,2,LEAVES_2:1)
Block(5,18,3,LOG_2:1)
Block(5,18,5,LOG_2:1)
Block(5,19,-3,LEAVES_2:1)
Block(5,19,-2,LEAVES_2:1)
Block(5,19,3,LOG_2:1)
Block(5,19,5,LOG_2:1)
Block(5,19,8,LOG_2:1)
Block(5,19,9,LEAVES_2:1)
Block(5,20,-5,LEAVES_2:1)
Block(5,20,-4,LEAVES_2:1)
Block(5,20,-3,LEAVES_2:1)
Block(5,20,-2,LOG_2:1)
Block(5,20,-1,LOG_2:1)
Block(5,20,3,LOG_2:1)
Block(5,20,4,LOG_2:1)
Block(5,20,5,LOG_2:1)
Block(5,20,6,LOG_2:1)
Block(5,20,7,LOG_2:1)
Block(5,20,8,LOG_2:1)
Block(5,20,9,LEAVES_2:1)
Block(5,21,-6,LEAVES_2:1)
Block(5,21,-5,LEAVES_2:1)
Block(5,21,-4,LEAVES_2:1)
Block(5,21,-3,LEAVES_2:1)
Block(5,21,-2,LOG_2:1)
Block(5,21,-1,LEAVES_2:1)
Block(5,21,0,LEAVES_2:1)
Block(5,21,1,LEAVES_2:1)
Block(5,21,2,LEAVES_2:1)
Block(5,21,3,LEAVES_2:1)
Block(5,21,4,LOG_2:1)
Block(5,21,5,LOG_2:1)
Block(5,21,6,LOG_2:1)
Block(5,21,7,LOG_2:1)
Block(5,22,-4,LEAVES_2:1)
Block(5,22,-3,LEAVES_2:1)
Block(5,22,-2,LEAVES_2:1)
Block(5,22,-1,LEAVES_2:1)
Block(5,22,0,LEAVES_2:1)
Block(5,22,1,LEAVES_2:1)
Block(5,22,2,LEAVES_2:1)
Block(5,22,3,LEAVES_2:1)
Block(5,22,4,LOG_2:1)
Block(5,22,5,LOG_2:1)
Block(5,22,7,LEAVES_2:1)
Block(5,22,11,LEAVES_2:1)
Block(5,22,12,LEAVES_2:1)
Block(5,23,-4,LEAVES_2:1)
Block(5,23,-3,LEAVES_2:1)
Block(5,23,-2,LEAVES_2:1)
Block(5,23,-1,LEAVES_2:1)
Block(5,23,0,LEAVES_2:1)
Block(5,23,1,LEAVES_2:1)
Block(5,23,2,LEAVES_2:1)
Block(5,23,3,LEAVES_2:1)
Block(5,23,4,LOG_2:1)
Block(5,23,5,LOG_2:1)
Block(5,23,7,LEAVES_2:1)
Block(5,23,8,LEAVES_2:1)
Block(5,23,10,LEAVES_2:1)
Block(5,23,11,LEAVES_2:1)
Block(5,24,-3,LEAVES_2:1)
Block(5,24,-2,LEAVES_2:1)
Block(5,24,-1,LEAVES_2:1)
Block(5,24,0,LEAVES_2:1)
Block(5,24,2,LEAVES_2:1)
Block(5,24,3,LOG_2:1)
Block(5,24,4,LOG_2:1)
Block(5,24,5,LOG_2:1)
Block(5,24,6,LOG_2:1)
Block(5,24,7,LOG_2:1)
Block(5,24,8,LEAVES_2:1)
Block(5,24,9,LOG_2:1)
Block(5,24,10,LEAVES_2:1)
Block(5,24,11,LEAVES_2:1)
Block(5,25,2,LEAVES_2:1)
Block(5,25,3,LEAVES_2:1)
Block(5,25,4,LOG_2:1)
Block(5,25,5,LOG_2:1)
Block(5,25,6,LEAVES_2:1)
Block(5,25,7,LEAVES_2:1)
Block(5,25,8,LEAVES_2:1)
Block(5,25,9,LEAVES_2:1)
Block(5,25,10,LEAVES_2:1)
Block(5,25,11,LEAVES_2:1)
Block(5,25,12,LEAVES_2:1)
Block(5,26,-1,LEAVES_2:1)
Block(5,26,2,LEAVES_2:1)
Block(5,26,3,LEAVES_2:1)
Block(5,26,4,LOG_2:1)
Block(5,26,5,LOG_2:1)
Block(5,26,6,LEAVES_2:1)
Block(5,26,7,LEAVES_2:1)
Block(5,26,8,LEAVES_2:1)
Block(5,26,10,LEAVES_2:1)
Block(5,26,11,LEAVES_2:1)
Block(5,26,12,LEAVES_2:1)
Block(5,27,-2,LEAVES_2:1)
Block(5,27,-1,LEAVES_2:1)
Block(5,27,0,LEAVES_2:1)
Block(5,27,1,LEAVES_2:1)
Block(5,27,3,LEAVES_2:1)
Block(5,27,4,LOG_2:1)
Block(5,27,5,LOG_2:1)
Block(5,27,6,LEAVES_2:1)
Block(5,27,7,LEAVES_2:1)
Block(5,27,8,LEAVES_2:1)
Block(5,27,9,LEAVES_2:1)
Block(5,27,10,LEAVES_2:1)
Block(5,27,11,LOG_2:1)
Block(5,28,-2,LEAVES_2:1)
Block(5,28,-1,LEAVES_2:1)
Block(5,28,0,LEAVES_2:1)
Block(5,28,1,LEAVES_2:1)
Block(5,28,3,LOG_2:1)
Block(5,28,4,LOG_2:1)
Block(5,28,5,LOG_2:1)
Block(5,28,6,LOG_2:1)
Block(5,28,7,LEAVES_2:1)
Block(5,28,8,LEAVES_2:1)
Block(5,28,9,LEAVES_2:1)
Block(5,28,10,LEAVES_2:1)
Block(5,29,-2,LEAVES_2:1)
Block(5,29,-1,LEAVES_2:1)
Block(5,29,0,LEAVES_2:1)
Block(5,29,1,LEAVES_2:1)
Block(5,29,2,LOG_2:1)
Block(5,29,3,LOG_2:1)
Block(5,29,4,LOG_2:1)
Block(5,29,5,LOG_2:1)
Block(5,29,6,LEAVES_2:1)
Block(5,29,7,LEAVES_2:1)
Block(5,29,8,LEAVES_2:1)
Block(5,29,10,LEAVES_2:1)
Block(5,29,11,LEAVES_2:1)
Block(5,30,-2,LEAVES_2:1)
Block(5,30,-1,LEAVES_2:1)
Block(5,30,2,LOG_2:1)
Block(5,30,3,LOG_2:1)
Block(5,30,4,LOG_2:1)
Block(5,30,5,LEAVES_2:1)
Block(5,30,6,LEAVES_2:1)
Block(5,30,7,LEAVES_2:1)
Block(5,30,8,LEAVES_2:1)
Block(5,30,10,LEAVES_2:1)
Block(5,30,11,LEAVES_2:1)
Block(5,31,-3,LEAVES_2:1)
Block(5,31,-2,LEAVES_2:1)
Block(5,31,-1,LEAVES_2:1)
Block(5,31,0,LEAVES_2:1)
Block(5,31,2,LEAVES_2:1)
Block(5,31,3,LOG_2:1)
Block(5,31,4,LOG_2:1)
Block(5,31,6,LEAVES_2:1)
Block(5,31,7,LEAVES_2:1)
Block(5,31,8,LEAVES_2:1)
Block(5,31,9,LEAVES_2:1)
Block(5,31,10,LEAVES_2:1)
Block(5,32,-4,LEAVES_2:1)
Block(5,32,-3,LEAVES_2:1)
Block(5,32,-2,LEAVES_2:1)
Block(5,32,-1,LEAVES_2:1)
Block(5,32,2,LEAVES_2:1)
Block(5,32,3,LOG_2:1)
Block(5,32,4,LOG_2:1)
Block(5,32,5,LOG_2:1)
Block(5,32,6,LOG_2:1)
Block(5,32,7,LEAVES_2:1)
Block(5,32,8,LEAVES_2:1)
Block(5,32,9,LEAVES_2:1)
Block(5,33,-4,LEAVES_2:1)
Block(5,33,-3,LEAVES_2:1)
Block(5,33,-1,LEAVES_2:1)
Block(5,33,0,LEAVES_2:1)
Block(5,33,1,LOG_2:1)
Block(5,33,2,LEAVES_2:1)
Block(5,33,3,LOG_2:1)
Block(5,33,4,LOG_2:1)
Block(5,33,5,LOG_2:1)
Block(5,33,6,LOG_2:1)
Block(5,33,7,LEAVES_2:1)
Block(5,33,8,LEAVES_2:1)
Block(5,34,-4,LEAVES_2:1)
Block(5,34,-3,LEAVES_2:1)
Block(5,34,0,LEAVES_2:1)
Block(5,34,2,LEAVES_2:1)
Block(5,34,3,LOG_2:1)
Block(5,34,4,LOG_2:1)
Block(5,34,5,LEAVES_2:1)
Block(5,34,6,LEAVES_2:1)
Block(5,34,7,LEAVES_2:1)
Block(5,34,8,LEAVES_2:1)
Block(5,34,9,LEAVES_2:1)
Block(5,35,-4,LEAVES_2:1)
Block(5,35,-3,LEAVES_2:1)
Block(5,35,-2,LEAVES_2:1)
Block(5,35,3,LOG_2:1)
Block(5,35,4,LOG_2:1)
Block(5,35,6,LEAVES_2:1)
Block(5,35,7,LOG_2:1)
Block(5,35,8,LEAVES_2:1)
Block(5,35,9,LEAVES_2:1)
Block(5,35,10,LEAVES_2:1)
Block(5,36,-4,LEAVES_2:1)
Block(5,36,-2,LEAVES_2:1)
Block(5,36,3,LOG_2:1)
Block(5,36,4,LOG_2:1)
Block(5,36,5,LOG_2:1)
Block(5,36,6,LEAVES_2:1)
Block(5,36,7,LOG_2:1)
Block(5,36,8,LOG_2:1)
Block(5,36,9,LEAVES_2:1)
Block(5,36,10,LEAVES_2:1)
Block(5,37,-5,LEAVES_2:1)
Block(5,37,-4,LEAVES_2:1)
Block(5,37,-3,LEAVES_2:1)
Block(5,37,-2,LOG_2:1)
Block(5,37,2,LOG_2:1)
Block(5,37,3,LOG_2:1)
Block(5,37,4,LOG_2:1)
Block(5,37,5,LEAVES_2:1)
Block(5,37,6,LEAVES_2:1)
Block(5,37,8,LOG_2:1)
Block(5,37,9,LEAVES_2:1)
Block(5,37,10,LEAVES_2:1)
Block(5,37,11,LEAVES_2:1)
Block(5,38,-5,LEAVES_2:1)
Block(5,38,-3,LEAVES_2:1)
Block(5,38,-1,LOG_2:1)
Block(5,38,0,LOG_2:1)
Block(5,38,1,LOG_2:1)
Block(5,38,2,LOG_2:1)
Block(5,38,3,LOG_2:1)
Block(5,38,5,LEAVES_2:1)
Block(5,38,6,LEAVES_2:1)
Block(5,38,7,LEAVES_2:1)
Block(5,38,8,LEAVES_2:1)
Block(5,38,10,LEAVES_2:1)
Block(5,38,11,LEAVES_2:1)
Block(5,39,-2,LEAVES_2:1)
Block(5,39,-1,LEAVES_2:1)
Block(5,39,2,LOG_2:1)
Block(5,39,3,LOG_2:1)
Block(5,39,4,LEAVES_2:1)
Block(5,39,5,LEAVES_2:1)
Block(5,39,6,LEAVES_2:1)
Block(5,39,7,LEAVES_2:1)
Block(5,39,8,LEAVES_2:1)
Block(5,39,9,LEAVES_2:1)
Block(5,39,10,LEAVES_2:1)
Block(5,39,11,LEAVES_2:1)
Block(5,40,-4,LEAVES_2:1)
Block(5,40,-3,LEAVES_2:1)
Block(5,40,-2,LEAVES_2:1)
Block(5,40,-1,LEAVES_2:1)
Block(5,40,2,LOG_2:1)
Block(5,40,3,LOG_2:1)
Block(5,40,4,LEAVES_2:1)
Block(5,40,5,LEAVES_2:1)
Block(5,40,6,LEAVES_2:1)
Block(5,40,7,LEAVES_2:1)
Block(5,40,8,LEAVES_2:1)
Block(5,40,9,LEAVES_2:1)
Block(5,40,10,LEAVES_2:1)
Block(5,40,11,LEAVES_2:1)
Block(5,41,-5,LEAVES_2:1)
Block(5,41,-4,LEAVES_2:1)
Block(5,41,-3,LEAVES_2:1)
Block(5,41,-1,LOG_2:1)
Block(5,41,0,LOG_2:1)
Block(5,41,1,LOG_2:1)
Block(5,41,2,LOG_2:1)
Block(5,41,3,LOG_2:1)
Block(5,41,4,LOG_2:1)
Block(5,41,5,LOG_2:1)
Block(5,41,6,LEAVES_2:1)
Block(5,41,7,LEAVES_2:1)
Block(5,41,8,LEAVES_2:1)
Block(5,41,9,LEAVES_2:1)
Block(5,41,10,LEAVES_2:1)
Block(5,41,11,LEAVES_2:1)
Block(5,42,-4,LEAVES_2:1)
Block(5,42,-3,LEAVES_2:1)
Block(5,42,0,LOG_2:1)
Block(5,42,1,LOG_2:1)
Block(5,42,2,LOG_2:1)
Block(5,42,3,LOG_2:1)
Block(5,42,4,LEAVES_2:1)
Block(5,42,5,LEAVES_2:1)
Block(5,42,6,LEAVES_2:1)
Block(5,42,7,LEAVES_2:1)
Block(5,42,8,LEAVES_2:1)
Block(5,42,9,LEAVES_2:1)
Block(5,43,-3,LEAVES_2:1)
Block(5,43,-1,LEAVES_2:1)
Block(5,43,0,LEAVES_2:1)
Block(5,43,1,LOG_2:1)
Block(5,43,2,LOG_2:1)
Block(5,43,3,LOG_2:1)
Block(5,43,4,LEAVES_2:1)
Block(5,43,5,LEAVES_2:1)
Block(5,43,6,LEAVES_2:1)
Block(5,43,7,LEAVES_2:1)
Block(5,43,8,LEAVES_2:1)
Block(5,44,-2,LEAVES_2:1)
Block(5,44,-1,LEAVES_2:1)
Block(5,44,1,LOG_2:1)
Block(5,44,6,LEAVES_2:1)
Block(5,44,7,LEAVES_2:1)
Block(5,44,8,LEAVES_2:1)
Block(5,44,9,LEAVES_2:1)
Block(5,45,-4,LEAVES_2:1)
Block(5,45,-3,LEAVES_2:1)
Block(5,45,-2,LEAVES_2:1)
Block(5,45,-1,LEAVES_2:1)
Block(5,45,1,LOG_2:1)
Block(5,45,2,LOG_2:1)
Block(5,45,3,LOG_2:1)
Block(5,45,4,LOG_2:1)
Block(5,45,6,LEAVES_2:1)
Block(5,46,-4,LEAVES_2:1)
Block(5,46,-3,LEAVES_2:1)
Block(5,46,-2,LEAVES_2:1)
Block(5,46,-1,LEAVES_2:1)
Block(5,46,0,LEAVES_2:1)
Block(5,46,1,LOG_2:1)
Block(5,46,2,LOG_2:1)
Block(5,46,3,LOG_2:1)
Block(5,46,4,LOG_2:1)
Block(5,46,7,LEAVES_2:1)
Block(5,46,8,LEAVES_2:1)
Block(5,47,-3,LEAVES_2:1)
Block(5,47,-2,LEAVES_2:1)
Block(5,47,-1,LOG_2:1)
Block(5,47,0,LOG_2:1)
Block(5,47,1,LOG_2:1)
Block(5,47,2,LOG_2:1)
Block(5,47,3,LOG_2:1)
Block(5,48,-3,LEAVES_2:1)
Block(5,48,-2,LEAVES_2:1)
Block(5,48,-1,LEAVES_2:1)
Block(5,48,0,LEAVES_2:1)
Block(5,48,1,LOG_2:1)
Block(5,48,2,LOG_2:1)
Block(5,48,6,LEAVES_2:1)
Block(5,48,8,LOG_2:1)
Block(5,49,-3,LEAVES_2:1)
Block(5,49,-1,LEAVES_2:1)
Block(5,49,0,LEAVES_2:1)
Block(5,49,1,LOG_2:1)
Block(5,49,2,LOG_2:1)
Block(5,49,3,LOG_2:1)
Block(5,49,4,LEAVES_2:1)
Block(5,50,-1,LEAVES_2:1)
Block(5,50,0,LOG_2:1)
Block(5,50,1,LOG_2:1)
Block(5,50,2,LOG_2:1)
Block(5,50,3,LOG_2:1)
Block(5,50,4,LOG_2:1)
Block(5,50,5,LOG_2:1)
Block(5,50,6,LEAVES_2:1)
Block(5,50,7,LEAVES_2:1)
Block(5,50,8,LEAVES_2:1)
Block(5,51,-3,LEAVES_2:1)
Block(5,51,0,LOG_2:1)
Block(5,51,1,LOG_2:1)
Block(5,51,2,LOG_2:1)
Block(5,51,3,LEAVES_2:1)
Block(5,51,4,LEAVES_2:1)
Block(5,51,5,LEAVES_2:1)
Block(5,51,6,LEAVES_2:1)
Block(5,51,7,LEAVES_2:1)
Block(5,51,8,LEAVES_2:1)
Block(5,52,-3,LEAVES_2:1)
Block(5,52,-1,LOG_2:1)
Block(5,52,0,LOG_2:1)
Block(5,52,1,LOG_2:1)
Block(5,52,3,LEAVES_2:1)
Block(5,52,4,LEAVES_2:1)
Block(5,52,7,LEAVES_2:1)
Block(5,53,-4,LEAVES_2:1)
Block(5,53,-3,LEAVES_2:1)
Block(5,53,-2,LEAVES_2:1)
Block(5,53,-1,LEAVES_2:1)
Block(5,53,0,LOG_2:1)
Block(5,53,1,LOG_2:1)
Block(5,53,2,LOG_2:1)
Block(5,53,3,LOG_2:1)
Block(5,53,4,LEAVES_2:1)
Block(5,54,-3,LEAVES_2:1)
Block(5,54,-2,LEAVES_2:1)
Block(5,54,-1,LEAVES_2:1)
Block(5,54,0,LOG_2:1)
Block(5,54,1,LOG_2:1)
Block(5,54,2,LOG_2:1)
Block(5,54,4,LEAVES_2:1)
Block(5,54,5,LEAVES_2:1)
Block(5,55,-4,LEAVES_2:1)
Block(5,55,-2,LEAVES_2:1)
Block(5,55,-1,LEAVES_2:1)
Block(5,55,0,LOG_2:1)
Block(5,55,1,LOG_2:1)
Block(5,55,2,LEAVES_2:1)
Block(5,55,3,LEAVES_2:1)
Block(5,55,4,LEAVES_2:1)
Block(5,55,5,LEAVES_2:1)
Block(5,56,-3,LEAVES_2:1)
Block(5,56,-2,LOG_2:1)
Block(5,56,-1,LOG_2:1)
Block(5,56,0,LOG_2:1)
Block(5,56,1,LOG_2:1)
Block(5,56,2,LOG_2:1)
Block(5,56,3,LEAVES_2:1)
Block(5,57,-2,LEAVES_2:1)
Block(5,57,-1,LEAVES_2:1)
Block(5,57,0,LOG_2:1)
Block(5,57,1,LOG_2:1)
Block(5,57,2,LOG_2:1)
Block(5,57,3,LEAVES_2:1)
Block(5,57,4,LEAVES_2:1)
Block(5,57,5,LEAVES_2:1)
Block(5,58,-1,LEAVES_2:1)
Block(5,58,0,LOG_2:1)
Block(5,58,1,LOG_2:1)
Block(5,58,2,LOG_2:1)
Block(5,58,5,LEAVES_2:1)
Block(5,59,-1,LEAVES_2:1)
Block(5,59,0,LOG_2:1)
Block(5,59,1,LOG_2:1)
Block(5,59,2,LEAVES_2:1)
Block(5,59,3,LEAVES_2:1)
Block(5,59,4,LEAVES_2:1)
Block(5,60,-2,LEAVES_2:1)
Block(5,60,-1,LOG_2:1)
Block(5,60,0,LOG_2:1)
Block(5,60,1,LOG_2:1)
Block(5,60,3,LEAVES_2:1)
Block(5,61,-2,LEAVES_2:1)
Block(5,61,-1,LOG_2:1)
Block(5,61,0,LOG_2:1)
Block(5,61,1,LEAVES_2:1)
Block(5,61,2,LEAVES_2:1)
Block(5,62,-2,LEAVES_2:1)
Block(5,62,-1,LEAVES_2:1)
Block(5,62,0,LOG_2:1)
Block(5,62,1,LEAVES_2:1)
Block(5,62,2,LEAVES_2:1)
Block(5,63,-2,LEAVES_2:1)
Block(5,63,-1,LEAVES_2:1)
Block(5,63,0,LOG_2:1)
Block(5,63,1,LEAVES_2:1)
Block(5,64,-3,LEAVES_2:1)
Block(5,64,-2,LEAVES_2:1)
Block(5,64,-1,LEAVES_2:1)
Block(5,64,0,LOG_2:1)
Block(5,64,1,LEAVES_2:1)
Block(5,65,-2,LEAVES_2:1)
Block(5,65,-1,LOG_2:1)
Block(5,65,0,LOG_2:1)
Block(5,65,1,LOG_2:1)
Block(5,66,-1,LEAVES_2:1)
Block(5,66,0,LOG_2:1)
Block(5,66,1,LEAVES_2:1)
Block(5,67,-1,LEAVES_2:1)
Block(5,67,0,LOG_2:1)
Block(5,68,-2,LEAVES_2:1)
Block(5,68,-1,LEAVES_2:1)
Block(6,0,3,LOG_2:1)
Block(6,0,4,LOG_2:1)
Block(6,0,5,LOG_2:1)
Block(6,0,6,LOG_2:1)
Block(6,0,7,LOG_2:1)
Block(6,1,3,LOG_2:1)
Block(6,1,4,LOG_2:1)
Block(6,1,5,LOG_2:1)
Block(6,1,6,LOG_2:1)
Block(6,2,4,LOG_2:1)
Block(6,2,5,LOG_2:1)
Block(6,2,6,LOG_2:1)
Block(6,2,7,HUGE_MUSHROOM_1)
Block(6,2,8,HUGE_MUSHROOM_1)
Block(6,3,4,LOG_2:1)
Block(6,3,5,LOG_2:1)
Block(6,3,6,LOG_2:1)
Block(6,4,2,HUGE_MUSHROOM_1)
Block(6,4,3,HUGE_MUSHROOM_1)
Block(6,4,4,LOG_2:1)
Block(6,4,5,LOG_2:1)
Block(6,4,6,LOG_2:1)
Block(6,5,4,LOG_2:1)
Block(6,5,5,LOG_2:1)
Block(6,5,6,LOG_2:1)
Block(6,5,7,HUGE_MUSHROOM_1)
Block(6,6,4,LOG_2:1)
Block(6,6,5,LOG_2:1)
Block(6,6,6,LOG_2:1)
Block(6,7,4,LOG_2:1)
Block(6,7,5,LOG_2:1)
Block(6,7,6,LOG_2:1)
Block(6,8,3,LOG_2:1)
Block(6,8,4,LOG_2:1)
Block(6,8,5,LOG_2:1)
Block(6,8,6,LOG_2:1)
Block(6,9,4,LOG_2:1)
Block(6,9,5,LOG_2:1)
Block(6,9,6,LOG_2:1)
Block(6,10,4,LOG_2:1)
Block(6,10,5,LOG_2:1)
Block(6,11,4,LOG_2:1)
Block(6,11,5,LOG_2:1)
Block(6,12,4,LOG_2:1)
Block(6,12,5,LOG_2:1)
Block(6,13,4,LOG_2:1)
Block(6,13,5,LOG_2:1)
Block(6,13,6,LOG_2:1)
Block(6,14,4,LOG_2:1)
Block(6,14,5,LOG_2:1)
Block(6,14,6,LOG_2:1)
Block(6,15,4,LOG_2:1)
Block(6,15,5,LOG_2:1)
Block(6,15,6,LOG_2:1)
Block(6,16,1,LEAVES_2:1)
Block(6,16,4,LOG_2:1)
Block(6,16,5,LOG_2:1)
Block(6,17,1,LOG_2:1)
Block(6,17,2,LOG_2:1)
Block(6,17,3,LEAVES_2:1)
Block(6,17,4,LOG_2:1)
Block(6,17,5,LOG_2:1)
Block(6,18,0,LEAVES_2:1)
Block(6,18,1,LEAVES_2:1)
Block(6,18,2,LOG_2:1)
Block(6,18,3,LOG_2:1)
Block(6,18,4,LOG_2:1)
Block(6,18,5,LOG_2:1)
Block(6,19,-4,LEAVES_2:1)
Block(6,19,-3,LEAVES_2:1)
Block(6,19,-1,LEAVES_2:1)
Block(6,19,2,LEAVES_2:1)
Block(6,19,3,LEAVES_2:1)
Block(6,19,4,LOG_2:1)
Block(6,19,5,LOG_2:1)
Block(6,20,-5,LEAVES_2:1)
Block(6,20,-4,LEAVES_2:1)
Block(6,20,-3,LOG_2:1)
Block(6,20,-1,LEAVES_2:1)
Block(6,20,3,LEAVES_2:1)
Block(6,20,4,LEAVES_2:1)
Block(6,20,5,LEAVES_2:1)
Block(6,20,8,LEAVES_2:1)
Block(6,21,-4,LEAVES_2:1)
Block(6,21,-3,LEAVES_2:1)
Block(6,21,-2,LEAVES_2:1)
Block(6,21,-1,LEAVES_2:1)
Block(6,21,4,LEAVES_2:1)
Block(6,21,5,LEAVES_2:1)
Block(6,21,6,LEAVES_2:1)
Block(6,22,-4,LEAVES_2:1)
Block(6,22,-3,LEAVES_2:1)
Block(6,22,-2,LEAVES_2:1)
Block(6,22,-1,LEAVES_2:1)
Block(6,22,0,LEAVES_2:1)
Block(6,22,4,LOG_2:1)
Block(6,22,5,LEAVES_2:1)
Block(6,23,-4,LEAVES_2:1)
Block(6,23,-3,LEAVES_2:1)
Block(6,23,-2,LEAVES_2:1)
Block(6,23,-1,LEAVES_2:1)
Block(6,23,0,LEAVES_2:1)
Block(6,23,1,LEAVES_2:1)
Block(6,23,2,LEAVES_2:1)
Block(6,23,3,LEAVES_2:1)
Block(6,23,4,LOG_2:1)
Block(6,23,5,LEAVES_2:1)
Block(6,23,6,LEAVES_2:1)
Block(6,23,7,LEAVES_2:1)
Block(6,23,9,LEAVES_2:1)
Block(6,23,10,LEAVES_2:1)
Block(6,23,11,LEAVES_2:1)
Block(6,23,12,LEAVES_2:1)
Block(6,24,0,LEAVES_2:1)
Block(6,24,1,LEAVES_2:1)
Block(6,24,2,LEAVES_2:1)
Block(6,24,3,LEAVES_2:1)
Block(6,24,4,LEAVES_2:1)
Block(6,24,5,LOG_2:1)
Block(6,24,6,LOG_2:1)
Block(6,24,7,LOG_2:1)
Block(6,24,8,LOG_2:1)
Block(6,24,9,LOG_2:1)
Block(6,24,10,LOG_2:1)
Block(6,24,11,LEAVES_2:1)
Block(6,24,12,LEAVES_2:1)
Block(6,25,-1,LEAVES_2:1)
Block(6,25,1,LEAVES_2:1)
Block(6,25,2,LEAVES_2:1)
Block(6,25,3,LEAVES_2:1)
Block(6,25,4,LOG_2:1)
Block(6,25,5,LEAVES_2:1)
Block(6,25,6,LEAVES_2:1)
Block(6,25,7,LEAVES_2:1)
Block(6,25,8,LOG_2:1)
Block(6,25,9,LEAVES_2:1)
Block(6,25,10,LEAVES_2:1)
Block(6,26,-1,LEAVES_2:1)
Block(6,26,1,LEAVES_2:1)
Block(6,26,2,LEAVES_2:1)
Block(6,26,3,LEAVES_2:1)
Block(6,26,4,LOG_2:1)
Block(6,26,5,LEAVES_2:1)
Block(6,26,6,LEAVES_2:1)
Block(6,26,7,LEAVES_2:1)
Block(6,26,8,LOG_2:1)
Block(6,26,9,LEAVES_2:1)
Block(6,26,10,LEAVES_2:1)
Block(6,27,-3,LEAVES_2:1)
Block(6,27,-1,LOG_2:1)
Block(6,27,0,LEAVES_2:1)
Block(6,27,2,LEAVES_2:1)
Block(6,27,3,LEAVES_2:1)
Block(6,27,4,LEAVES_2:1)
Block(6,27,5,LEAVES_2:1)
Block(6,27,6,LEAVES_2:1)
Block(6,27,7,LEAVES_2:1)
Block(6,27,8,LEAVES_2:1)
Block(6,27,9,LEAVES_2:1)
Block(6,27,10,LEAVES_2:1)
Block(6,28,-3,LEAVES_2:1)
Block(6,28,-1,LOG_2:1)
Block(6,28,0,LOG_2:1)
Block(6,28,1,LEAVES_2:1)
Block(6,28,2,LOG_2:1)
Block(6,28,3,LOG_2:1)
Block(6,28,4,LOG_2:1)
Block(6,28,5,LOG_2:1)
Block(6,28,6,LEAVES_2:1)
Block(6,28,7,LEAVES_2:1)
Block(6,28,8,LEAVES_2:1)
Block(6,28,9,LEAVES_2:1)
Block(6,29,-2,LEAVES_2:1)
Block(6,29,-1,LEAVES_2:1)
Block(6,29,0,LOG_2:1)
Block(6,29,1,LOG_2:1)
Block(6,29,4,LOG_2:1)
Block(6,29,5,LEAVES_2:1)
Block(6,29,6,LOG_2:1)
Block(6,29,7,LOG_2:1)
Block(6,29,8,LOG_2:1)
Block(6,29,9,LEAVES_2:1)
Block(6,29,10,LEAVES_2:1)
Block(6,30,-2,LEAVES_2:1)
Block(6,30,-1,LEAVES_2:1)
Block(6,30,0,LEAVES_2:1)
Block(6,30,1,LEAVES_2:1)
Block(6,30,3,LEAVES_2:1)
Block(6,30,4,LEAVES_2:1)
Block(6,30,5,LEAVES_2:1)
Block(6,30,7,LEAVES_2:1)
Block(6,30,8,LEAVES_2:1)
Block(6,30,9,LOG_2:1)
Block(6,30,10,LEAVES_2:1)
Block(6,30,11,LEAVES_2:1)
Block(6,31,-2,LEAVES_2:1)
Block(6,31,-1,LEAVES_2:1)
Block(6,31,0,LEAVES_2:1)
Block(6,31,2,LEAVES_2:1)
Block(6,31,3,LEAVES_2:1)
Block(6,31,4,LEAVES_2:1)
Block(6,31,5,LEAVES_2:1)
Block(6,31,6,LEAVES_2:1)
Block(6,31,7,LEAVES_2:1)
Block(6,31,9,LEAVES_2:1)
Block(6,32,-2,LEAVES_2:1)
Block(6,32,-1,LOG_2:1)
Block(6,32,1,LEAVES_2:1)
Block(6,32,2,LOG_2:1)
Block(6,32,3,LOG_2:1)
Block(6,32,4,LEAVES_2:1)
Block(6,32,5,LEAVES_2:1)
Block(6,32,6,LOG_2:1)
Block(6,32,7,LOG_2:1)
Block(6,32,8,LEAVES_2:1)
Block(6,32,9,LEAVES_2:1)
Block(6,33,-3,LEAVES_2:1)
Block(6,33,0,LOG_2:1)
Block(6,33,1,LOG_2:1)
Block(6,33,2,LEAVES_2:1)
Block(6,33,3,LOG_2:1)
Block(6,33,4,LEAVES_2:1)
Block(6,33,5,LEAVES_2:1)
Block(6,33,6,LEAVES_2:1)
Block(6,33,7,LEAVES_2:1)
Block(6,34,-3,LEAVES_2:1)
Block(6,34,-2,LEAVES_2:1)
Block(6,34,-1,LEAVES_2:1)
Block(6,34,0,LEAVES_2:1)
Block(6,34,1,LEAVES_2:1)
Block(6,34,2,LEAVES_2:1)
Block(6,34,3,LEAVES_2:1)
Block(6,34,4,LEAVES_2:1)
Block(6,34,5,LEAVES_2:1)
