
#######################################################################
# +-----------------------------------------------------------------+ #
# |                            BO3 object                           | #
# +-----------------------------------------------------------------+ #
#######################################################################

# This is the config file of a custom object.
# If you add this object correctly to your BiomeConfigs, it will spawn in the world.

# This is the creator of this BO3 object
Author: Unknown

# A short description of this BO3 object
Description: This BO3 was converted from a schematic using OTGEdit. The author and description information of the schematic could not be found. If you know who the author of the schematic is then please add this information.

# The BO3 version, don't change this! It can be used by external applications to do a version check.
Version: 3

# The settings mode, WriteAll, WriteWithoutComments or WriteDisable. See WorldConfig.
SettingsMode: WriteAll


#######################################################################
# +-----------------------------------------------------------------+ #
# |                          Main settings                          | #
# +-----------------------------------------------------------------+ #
#######################################################################

# This needs to be set to true to spawn the object in the Tree and Sapling resources.
Tree: true

# The frequency of the BO3 from 1 to 200. Tries this many times to spawn this BO3 when using the CustomObject(...) resource.
# Ignored by Tree(..), Sapling(..) and CustomStructure(..)
Frequency: 40

# The rarity of the BO3 from 0 to 100. Each spawn attempt has rarity% chance to succeed when using the CustomObject(...) resource.
# Ignored by Tree(..), Sapling(..) and CustomStructure(..)
Rarity: 100.0

# If you set this to true, the BO3 will be placed with a random rotation.
RotateRandomly: true

# The spawn height of the BO3: randomY, highestBlock or highestSolidBlock.
SpawnHeight: randomY

# The offset from the spawn height to spawn this BO3
# Ex. SpawnHeight = highestSolidBlock, SpawnHeightOffset = 3; This object will spawn 3 blocks above the highest solid block
SpawnHeightOffset: 0

# A random amount to offset the spawn location from the spawn offset height
# Ex. SpawnHeightOffset = 3, SpawnHeightVariance = 3; This object will spawn 3 to 6 blocks above the original spot it would have spawned
SpawnHeightVariance: 0

##############################
# Height Limits for the BO3. #
##############################

# When in randomY mode used as the minimum Y or in atMinY mode as the actual Y to spawn this BO3 at.
MinHeight: 92

# When in randomY mode used as the maximum Y to spawn this BO3 at.
MaxHeight: 256

######################
# Extrusion settings #
######################

# The style of extrusion you wish to use - BottomDown, TopUp, None (Default)
ExtrudeMode: None

# The blocks to extrude your BO3 through
ExtrudeThroughBlocks: AIR

# Objects can have other objects attacthed to it: branches. Branches can also
# have branches attached to it, which can also have branches, etc. This is the
# maximum branch depth for this objects.
MaxBranchDepth: 10

# When spawned with the UseWorld keyword, this BO3 should NOT spawn in the following biomes.
# If you write the BO3 name directly in the BiomeConfigs, this will be ignored.
ExcludedBiomes: All


#######################################################################
# +-----------------------------------------------------------------+ #
# |                      Source block settings                      | #
# +-----------------------------------------------------------------+ #
#######################################################################

# The block(s) the BO3 should spawn in.
SourceBlocks: AIR,GRASS,DIRT

# The maximum percentage of the BO3 that can be outside the SourceBlock.
# The BO3 won't be placed on a location with more blocks outside the SourceBlock than this percentage.
MaxPercentageOutsideSourceBlock: 100

# What to do when a block is about to be placed outside the SourceBlock? (dontPlace, placeAnyway)
OutsideSourceBlock: placeAnyway

# OTG+ settings #
# Legacy setting, rename this file to .BO4 instead. Set this to true to enable the advanced customstructure features of OTG+.
IsOTGPlus: false


#######################################################################
# +-----------------------------------------------------------------+ #
# |                              Blocks                             | #
# +-----------------------------------------------------------------+ #
#######################################################################

# All the blocks used in the BO3 are listed here. Possible blocks:
# Block(x,y,z,id[.data][,nbtfile.nbt)
# RandomBlock(x,y,z,id[:data][,nbtfile.nbt],chance[,id[:data][,nbtfile.nbt],chance[,...]])
#  So RandomBlock(0,0,0,CHEST,chest.nbt,50,CHEST,anotherchest.nbt,100) will spawn a chest at
#  the BO3 origin, and give it a 50% chance to have the contents of chest.nbt, or, if that
#  fails, a 100% percent chance to have the contents of anotherchest.nbt.
# *Note: Unlike Entity() and Spawner(), for Block() .txt files don't work, only .nbt files work.
# MinecraftObject(x,y,z,name) (TODO: This may not work anymore and needs to be tested.
#  Spawns an object in the Mojang NBT structure format. For example, 
#  MinecraftObject(0,0,0,minecraft:igloo/igloo_bottom)
#  spawns the bottom part of an igloo.
Block(-10,17,4,biomesoplenty:leaves_4:15)
Block(-10,17,5,biomesoplenty:leaves_4:15)
Block(-9,13,5,biomesoplenty:leaves_4:15)
Block(-9,13,6,biomesoplenty:leaves_4:15)
Block(-9,14,5,biomesoplenty:leaves_4:15)
Block(-9,15,2,biomesoplenty:leaves_4:15)
Block(-9,15,3,biomesoplenty:leaves_4:15)
Block(-9,15,4,biomesoplenty:leaves_4:15)
Block(-9,15,5,biomesoplenty:leaves_4:15)
Block(-9,16,3,biomesoplenty:leaves_4:15)
Block(-9,16,4,biomesoplenty:leaves_4:15)
Block(-9,17,3,biomesoplenty:leaves_4:15)
Block(-9,17,4,biomesoplenty:leaves_4:15)
Block(-9,17,5,biomesoplenty:leaves_4:15)
Block(-9,18,3,biomesoplenty:leaves_4:15)
Block(-9,18,4,biomesoplenty:leaves_4:15)
Block(-9,18,5,biomesoplenty:leaves_4:15)
Block(-9,19,4,biomesoplenty:leaves_4:15)
Block(-8,12,5,biomesoplenty:leaves_4:15)
Block(-8,12,6,biomesoplenty:leaves_4:15)
Block(-8,13,2,biomesoplenty:leaves_4:15)
Block(-8,13,3,biomesoplenty:leaves_4:15)
Block(-8,13,4,biomesoplenty:leaves_4:15)
Block(-8,13,5,biomesoplenty:leaves_4:15)
Block(-8,13,6,biomesoplenty:leaves_4:15)
Block(-8,13,7,biomesoplenty:leaves_4:15)
Block(-8,14,0,biomesoplenty:leaves_4:15)
Block(-8,14,2,biomesoplenty:leaves_4:15)
Block(-8,14,3,biomesoplenty:leaves_4:15)
Block(-8,14,4,biomesoplenty:leaves_4:15)
Block(-8,14,5,biomesoplenty:leaves_4:15)
Block(-8,14,6,biomesoplenty:leaves_4:15)
Block(-8,15,1,biomesoplenty:leaves_4:15)
Block(-8,15,2,biomesoplenty:leaves_4:15)
Block(-8,15,3,biomesoplenty:leaves_4:15)
Block(-8,15,4,biomesoplenty:leaves_4:15)
Block(-8,15,5,biomesoplenty:leaves_4:15)
Block(-8,15,6,biomesoplenty:leaves_4:15)
Block(-8,16,2,biomesoplenty:leaves_4:15)
Block(-8,16,3,biomesoplenty:leaves_4:15)
Block(-8,16,4,biomesoplenty:leaves_4:15)
Block(-8,16,5,biomesoplenty:leaves_4:15)
Block(-8,17,3,biomesoplenty:leaves_4:15)
Block(-8,17,4,biomesoplenty:leaves_4:15)
Block(-8,17,5,biomesoplenty:leaves_4:15)
Block(-8,18,3,biomesoplenty:leaves_4:15)
Block(-8,18,4,biomesoplenty:leaves_4:15)
Block(-8,18,5,biomesoplenty:leaves_4:15)
Block(-8,19,3,biomesoplenty:leaves_4:15)
Block(-8,19,4,biomesoplenty:leaves_4:15)
Block(-8,19,5,biomesoplenty:leaves_4:15)
Block(-8,20,4,biomesoplenty:leaves_4:15)
Block(-7,11,5,biomesoplenty:leaves_4:15)
Block(-7,12,-3,biomesoplenty:leaves_4:15)
Block(-7,12,-2,biomesoplenty:leaves_4:15)
Block(-7,12,-1,biomesoplenty:leaves_4:15)
Block(-7,12,2,biomesoplenty:leaves_4:15)
Block(-7,12,3,biomesoplenty:leaves_4:15)
Block(-7,12,4,biomesoplenty:leaves_4:15)
Block(-7,12,5,biomesoplenty:leaves_4:15)
Block(-7,12,6,biomesoplenty:leaves_4:15)
Block(-7,13,-3,biomesoplenty:leaves_4:15)
Block(-7,13,-2,biomesoplenty:leaves_4:15)
Block(-7,13,0,biomesoplenty:leaves_4:15)
Block(-7,13,1,biomesoplenty:leaves_4:15)
Block(-7,13,2,biomesoplenty:leaves_4:15)
Block(-7,13,3,biomesoplenty:leaves_4:15)
Block(-7,13,4,biomesoplenty:leaves_4:15)
Block(-7,13,5,biomesoplenty:leaves_4:15)
Block(-7,13,6,biomesoplenty:leaves_4:15)
Block(-7,14,-2,biomesoplenty:leaves_4:15)
Block(-7,14,0,biomesoplenty:leaves_4:15)
Block(-7,14,1,biomesoplenty:leaves_4:15)
Block(-7,14,2,biomesoplenty:leaves_4:15)
Block(-7,14,3,biomesoplenty:leaves_4:15)
Block(-7,14,4,biomesoplenty:leaves_4:15)
Block(-7,14,5,biomesoplenty:leaves_4:15)
Block(-7,15,-1,biomesoplenty:leaves_4:15)
Block(-7,15,0,biomesoplenty:leaves_4:15)
Block(-7,15,1,biomesoplenty:leaves_4:15)
Block(-7,15,2,biomesoplenty:leaves_4:15)
Block(-7,15,3,biomesoplenty:leaves_4:15)
Block(-7,15,4,biomesoplenty:leaves_4:15)
Block(-7,15,5,biomesoplenty:leaves_4:15)
Block(-7,15,6,biomesoplenty:leaves_4:15)
Block(-7,15,8,biomesoplenty:leaves_4:15)
Block(-7,16,0,biomesoplenty:leaves_4:15)
Block(-7,16,1,biomesoplenty:leaves_4:15)
Block(-7,16,2,biomesoplenty:leaves_4:15)
Block(-7,16,3,biomesoplenty:leaves_4:15)
Block(-7,16,4,biomesoplenty:leaves_4:15)
Block(-7,16,7,biomesoplenty:leaves_4:15)
Block(-7,17,0,biomesoplenty:leaves_4:15)
Block(-7,17,2,biomesoplenty:leaves_4:15)
Block(-7,17,3,biomesoplenty:leaves_4:15)
Block(-7,17,4,biomesoplenty:leaves_4:15)
Block(-7,18,2,biomesoplenty:leaves_4:15)
Block(-7,18,3,biomesoplenty:leaves_4:15)
Block(-7,18,4,biomesoplenty:log_2:1)
Block(-7,18,5,biomesoplenty:leaves_4:15)
Block(-7,19,3,biomesoplenty:leaves_4:15)
Block(-7,19,4,biomesoplenty:leaves_4:15)
Block(-7,19,5,biomesoplenty:leaves_4:15)
Block(-7,20,3,biomesoplenty:leaves_4:15)
Block(-7,20,5,biomesoplenty:leaves_4:15)
Block(-6,11,-3,biomesoplenty:leaves_4:15)
Block(-6,11,-2,biomesoplenty:leaves_4:15)
Block(-6,11,-1,biomesoplenty:leaves_4:15)
Block(-6,11,5,biomesoplenty:leaves_4:15)
Block(-6,12,-4,biomesoplenty:leaves_4:15)
Block(-6,12,-3,biomesoplenty:leaves_4:15)
Block(-6,12,-2,biomesoplenty:leaves_4:15)
Block(-6,12,-1,biomesoplenty:leaves_4:15)
Block(-6,12,0,biomesoplenty:leaves_4:15)
Block(-6,12,4,biomesoplenty:leaves_4:15)
Block(-6,12,5,biomesoplenty:leaves_4:15)
Block(-6,12,6,biomesoplenty:leaves_4:15)
Block(-6,13,-4,biomesoplenty:leaves_4:15)
Block(-6,13,-3,biomesoplenty:leaves_4:15)
Block(-6,13,-2,biomesoplenty:leaves_4:15)
Block(-6,13,-1,biomesoplenty:leaves_4:15)
Block(-6,13,2,biomesoplenty:leaves_4:15)
Block(-6,13,3,biomesoplenty:leaves_4:15)
Block(-6,13,4,biomesoplenty:leaves_4:15)
Block(-6,13,5,biomesoplenty:leaves_4:15)
Block(-6,14,-3,biomesoplenty:leaves_4:15)
Block(-6,14,-2,biomesoplenty:leaves_4:15)
Block(-6,14,-1,biomesoplenty:leaves_4:15)
Block(-6,14,0,biomesoplenty:leaves_4:15)
Block(-6,14,2,biomesoplenty:leaves_4:15)
Block(-6,14,6,biomesoplenty:leaves_4:15)
Block(-6,14,7,biomesoplenty:leaves_4:15)
Block(-6,14,8,biomesoplenty:leaves_4:15)
Block(-6,15,-2,biomesoplenty:leaves_4:15)
Block(-6,15,-1,biomesoplenty:leaves_4:15)
Block(-6,15,0,biomesoplenty:leaves_4:15)
Block(-6,15,1,biomesoplenty:leaves_4:15)
Block(-6,15,2,biomesoplenty:leaves_4:15)
Block(-6,15,3,biomesoplenty:leaves_4:15)
Block(-6,15,5,biomesoplenty:leaves_4:15)
Block(-6,15,6,biomesoplenty:leaves_4:15)
Block(-6,15,7,biomesoplenty:leaves_4:15)
Block(-6,15,8,biomesoplenty:leaves_4:15)
Block(-6,15,9,biomesoplenty:leaves_4:15)
Block(-6,16,-1,biomesoplenty:leaves_4:15)
Block(-6,16,0,biomesoplenty:leaves_4:15)
Block(-6,16,1,biomesoplenty:leaves_4:15)
Block(-6,16,2,biomesoplenty:leaves_4:15)
Block(-6,16,3,biomesoplenty:leaves_4:15)
Block(-6,16,4,biomesoplenty:leaves_4:15)
Block(-6,16,6,biomesoplenty:leaves_4:15)
Block(-6,16,7,biomesoplenty:leaves_4:15)
Block(-6,16,8,biomesoplenty:leaves_4:15)
Block(-6,17,-1,biomesoplenty:leaves_4:15)
Block(-6,17,0,biomesoplenty:leaves_4:15)
Block(-6,17,1,biomesoplenty:leaves_4:15)
Block(-6,17,3,biomesoplenty:leaves_4:15)
Block(-6,17,4,biomesoplenty:leaves_4:15)
Block(-6,17,5,biomesoplenty:leaves_4:15)
Block(-6,17,6,biomesoplenty:leaves_4:15)
Block(-6,17,7,biomesoplenty:leaves_4:15)
Block(-6,17,8,biomesoplenty:leaves_4:15)
Block(-6,18,0,biomesoplenty:leaves_4:15)
Block(-6,18,3,biomesoplenty:leaves_4:15)
Block(-6,18,4,biomesoplenty:log_2:1)
Block(-6,18,5,biomesoplenty:leaves_4:15)
Block(-6,18,7,biomesoplenty:leaves_4:15)
Block(-6,18,8,biomesoplenty:leaves_4:15)
Block(-6,19,3,biomesoplenty:leaves_4:15)
Block(-6,19,4,biomesoplenty:leaves_4:15)
Block(-6,19,5,biomesoplenty:leaves_4:15)
Block(-6,19,6,biomesoplenty:leaves_4:15)
Block(-6,20,5,biomesoplenty:leaves_4:15)
Block(-5,9,-2,biomesoplenty:leaves_4:15)
Block(-5,10,-3,biomesoplenty:leaves_4:15)
Block(-5,10,-2,biomesoplenty:leaves_4:15)
Block(-5,11,-4,biomesoplenty:leaves_4:15)
Block(-5,11,-3,biomesoplenty:leaves_4:15)
Block(-5,11,-2,biomesoplenty:leaves_4:15)
Block(-5,11,-1,biomesoplenty:leaves_4:15)
Block(-5,12,-4,biomesoplenty:leaves_4:15)
Block(-5,12,-3,biomesoplenty:leaves_4:15)
Block(-5,12,-2,biomesoplenty:leaves_4:15)
Block(-5,12,-1,biomesoplenty:leaves_4:15)
Block(-5,12,5,biomesoplenty:leaves_4:15)
Block(-5,13,-4,biomesoplenty:leaves_4:15)
Block(-5,13,-3,biomesoplenty:leaves_4:15)
Block(-5,13,-2,biomesoplenty:leaves_4:15)
Block(-5,13,7,biomesoplenty:leaves_4:15)
Block(-5,13,8,biomesoplenty:leaves_4:15)
Block(-5,13,9,biomesoplenty:leaves_4:15)
Block(-5,14,-4,biomesoplenty:leaves_4:15)
Block(-5,14,-3,biomesoplenty:leaves_4:15)
Block(-5,14,-2,biomesoplenty:leaves_4:15)
Block(-5,14,-1,biomesoplenty:leaves_4:15)
Block(-5,14,6,biomesoplenty:leaves_4:15)
Block(-5,14,7,biomesoplenty:leaves_4:15)
Block(-5,14,8,biomesoplenty:leaves_4:15)
Block(-5,15,-3,biomesoplenty:leaves_4:15)
Block(-5,15,-2,biomesoplenty:leaves_4:15)
Block(-5,15,-1,biomesoplenty:leaves_4:15)
Block(-5,15,0,biomesoplenty:leaves_4:15)
Block(-5,15,2,biomesoplenty:leaves_4:15)
Block(-5,15,6,biomesoplenty:leaves_4:15)
Block(-5,15,7,biomesoplenty:leaves_4:15)
Block(-5,15,8,biomesoplenty:leaves_4:15)
Block(-5,15,9,biomesoplenty:leaves_4:15)
Block(-5,16,-2,biomesoplenty:leaves_4:15)
Block(-5,16,-1,biomesoplenty:leaves_4:15)
Block(-5,16,0,biomesoplenty:leaves_4:15)
Block(-5,16,3,biomesoplenty:leaves_4:15)
Block(-5,16,4,biomesoplenty:leaves_4:15)
Block(-5,16,5,biomesoplenty:leaves_4:15)
Block(-5,16,7,biomesoplenty:leaves_4:15)
Block(-5,16,8,biomesoplenty:leaves_4:15)
Block(-5,16,9,biomesoplenty:leaves_4:15)
Block(-5,17,-2,biomesoplenty:leaves_4:15)
Block(-5,17,-1,biomesoplenty:leaves_4:15)
Block(-5,17,0,biomesoplenty:leaves_4:15)
Block(-5,17,1,biomesoplenty:leaves_4:15)
Block(-5,17,3,biomesoplenty:leaves_4:15)
Block(-5,17,4,biomesoplenty:log_2:1)
Block(-5,17,5,biomesoplenty:leaves_4:15)
Block(-5,17,6,biomesoplenty:leaves_4:15)
Block(-5,17,7,biomesoplenty:leaves_4:15)
Block(-5,17,8,biomesoplenty:leaves_4:15)
Block(-5,17,9,biomesoplenty:leaves_4:15)
Block(-5,18,0,biomesoplenty:leaves_4:15)
Block(-5,18,3,biomesoplenty:leaves_4:15)
Block(-5,18,4,biomesoplenty:log_2:5)
Block(-5,18,5,biomesoplenty:leaves_4:15)
Block(-5,18,6,biomesoplenty:leaves_4:15)
Block(-5,18,7,biomesoplenty:leaves_4:15)
Block(-5,18,8,biomesoplenty:leaves_4:15)
Block(-5,18,9,biomesoplenty:leaves_4:15)
Block(-5,19,4,biomesoplenty:leaves_4:15)
Block(-5,19,5,biomesoplenty:leaves_4:15)
Block(-5,19,7,biomesoplenty:leaves_4:15)
Block(-4,8,-2,biomesoplenty:leaves_4:15)
Block(-4,8,3,biomesoplenty:log_2:1)
Block(-4,9,-6,biomesoplenty:leaves_4:15)
Block(-4,9,-3,biomesoplenty:leaves_4:15)
Block(-4,9,-2,biomesoplenty:leaves_4:15)
Block(-4,9,-1,biomesoplenty:leaves_4:15)
Block(-4,10,-6,biomesoplenty:leaves_4:15)
Block(-4,10,-2,biomesoplenty:leaves_4:15)
Block(-4,11,-4,biomesoplenty:leaves_4:15)
Block(-4,11,-3,biomesoplenty:leaves_4:15)
Block(-4,11,-2,biomesoplenty:leaves_4:15)
Block(-4,11,3,biomesoplenty:leaves_4:15)
Block(-4,11,4,biomesoplenty:leaves_4:15)
Block(-4,12,-5,biomesoplenty:leaves_4:15)
Block(-4,12,-4,biomesoplenty:leaves_4:15)
Block(-4,12,-3,biomesoplenty:leaves_4:15)
Block(-4,12,8,biomesoplenty:leaves_4:15)
Block(-4,12,9,biomesoplenty:leaves_4:15)
Block(-4,13,-5,biomesoplenty:leaves_4:15)
Block(-4,13,-4,biomesoplenty:leaves_4:15)
Block(-4,13,-3,biomesoplenty:leaves_4:15)
Block(-4,13,7,biomesoplenty:leaves_4:15)
Block(-4,13,8,biomesoplenty:leaves_4:15)
Block(-4,13,9,biomesoplenty:leaves_4:15)
Block(-4,13,10,biomesoplenty:leaves_4:15)
Block(-4,14,-5,biomesoplenty:leaves_4:15)
Block(-4,14,-4,biomesoplenty:leaves_4:15)
Block(-4,14,-3,biomesoplenty:leaves_4:15)
Block(-4,14,-2,biomesoplenty:leaves_4:15)
Block(-4,14,7,biomesoplenty:leaves_4:15)
Block(-4,14,8,biomesoplenty:leaves_4:15)
Block(-4,14,9,biomesoplenty:leaves_4:15)
Block(-4,15,-5,biomesoplenty:leaves_4:15)
Block(-4,15,-4,biomesoplenty:leaves_4:15)
Block(-4,15,-3,biomesoplenty:leaves_4:15)
Block(-4,15,-2,biomesoplenty:leaves_4:15)
Block(-4,15,-1,biomesoplenty:leaves_4:15)
Block(-4,15,3,biomesoplenty:leaves_4:15)
Block(-4,15,4,biomesoplenty:leaves_4:15)
Block(-4,15,5,biomesoplenty:leaves_4:15)
Block(-4,15,7,biomesoplenty:leaves_4:15)
Block(-4,15,8,biomesoplenty:leaves_4:15)
Block(-4,16,-4,biomesoplenty:leaves_4:15)
Block(-4,16,-3,biomesoplenty:leaves_4:15)
Block(-4,16,-2,biomesoplenty:leaves_4:15)
Block(-4,16,-1,biomesoplenty:leaves_4:15)
Block(-4,16,0,biomesoplenty:leaves_4:15)
Block(-4,16,2,biomesoplenty:leaves_4:15)
Block(-4,16,4,biomesoplenty:log_2:13)
Block(-4,16,6,biomesoplenty:leaves_4:15)
Block(-4,16,7,biomesoplenty:leaves_4:15)
Block(-4,16,8,biomesoplenty:leaves_4:15)
Block(-4,16,9,biomesoplenty:leaves_4:15)
Block(-4,16,10,biomesoplenty:leaves_4:15)
Block(-4,17,-3,biomesoplenty:leaves_4:15)
Block(-4,17,-2,biomesoplenty:leaves_4:15)
Block(-4,17,-1,biomesoplenty:leaves_4:15)
Block(-4,17,0,biomesoplenty:log_2:1)
Block(-4,17,1,biomesoplenty:leaves_4:15)
Block(-4,17,2,biomesoplenty:leaves_4:15)
Block(-4,17,3,biomesoplenty:leaves_4:15)
Block(-4,17,4,biomesoplenty:log_2:13)
Block(-4,17,5,biomesoplenty:leaves_4:15)
Block(-4,17,6,biomesoplenty:leaves_4:15)
Block(-4,17,7,biomesoplenty:log_2:1)
Block(-4,17,8,biomesoplenty:leaves_4:15)
Block(-4,17,9,biomesoplenty:leaves_4:15)
Block(-4,17,10,biomesoplenty:leaves_4:15)
Block(-4,18,-3,biomesoplenty:leaves_4:15)
Block(-4,18,-2,biomesoplenty:leaves_4:15)
Block(-4,18,-1,biomesoplenty:leaves_4:15)
Block(-4,18,0,biomesoplenty:leaves_4:15)
Block(-4,18,1,biomesoplenty:leaves_4:15)
Block(-4,18,2,biomesoplenty:leaves_4:15)
Block(-4,18,3,biomesoplenty:leaves_4:15)
Block(-4,18,4,biomesoplenty:leaves_4:15)
Block(-4,18,5,biomesoplenty:leaves_4:15)
Block(-4,18,6,biomesoplenty:leaves_4:15)
Block(-4,18,7,biomesoplenty:log_2:5)
Block(-4,18,8,biomesoplenty:leaves_4:15)
Block(-4,18,9,biomesoplenty:leaves_4:15)
Block(-4,19,-2,biomesoplenty:leaves_4:15)
Block(-4,19,0,biomesoplenty:leaves_4:15)
Block(-4,19,2,biomesoplenty:leaves_4:15)
Block(-4,19,3,biomesoplenty:leaves_4:15)
Block(-4,19,4,biomesoplenty:leaves_4:15)
Block(-4,19,5,biomesoplenty:leaves_4:15)
Block(-4,19,6,biomesoplenty:leaves_4:15)
Block(-4,19,7,biomesoplenty:leaves_4:15)
Block(-4,19,8,biomesoplenty:leaves_4:15)
Block(-4,20,2,biomesoplenty:leaves_4:15)
Block(-3,7,-6,biomesoplenty:leaves_4:15)
Block(-3,8,-7,biomesoplenty:leaves_4:15)
Block(-3,8,-6,biomesoplenty:leaves_4:15)
Block(-3,8,-5,biomesoplenty:leaves_4:15)
Block(-3,8,-2,biomesoplenty:leaves_4:15)
Block(-3,8,3,biomesoplenty:log_2:1)
Block(-3,9,-7,biomesoplenty:leaves_4:15)
Block(-3,9,-6,biomesoplenty:leaves_4:15)
Block(-3,9,-3,biomesoplenty:leaves_4:15)
Block(-3,9,-2,biomesoplenty:leaves_4:15)
Block(-3,9,-1,biomesoplenty:leaves_4:15)
Block(-3,9,3,biomesoplenty:leaves_4:15)
Block(-3,10,-7,biomesoplenty:leaves_4:15)
Block(-3,10,-6,biomesoplenty:leaves_4:15)
Block(-3,10,-5,biomesoplenty:leaves_4:15)
Block(-3,10,3,biomesoplenty:leaves_4:15)
Block(-3,10,4,biomesoplenty:leaves_4:15)
Block(-3,11,-6,biomesoplenty:leaves_4:15)
Block(-3,11,1,biomesoplenty:leaves_4:15)
Block(-3,11,2,biomesoplenty:leaves_4:15)
Block(-3,11,3,biomesoplenty:leaves_4:15)
Block(-3,11,4,biomesoplenty:leaves_4:15)
Block(-3,11,5,biomesoplenty:leaves_4:15)
Block(-3,12,-4,biomesoplenty:leaves_4:15)
Block(-3,12,3,biomesoplenty:leaves_4:15)
Block(-3,12,4,biomesoplenty:leaves_4:15)
Block(-3,12,9,biomesoplenty:leaves_4:15)
Block(-3,13,-4,biomesoplenty:leaves_4:15)
Block(-3,13,3,biomesoplenty:leaves_4:15)
Block(-3,13,8,biomesoplenty:leaves_4:15)
Block(-3,13,9,biomesoplenty:leaves_4:15)
Block(-3,14,-4,biomesoplenty:leaves_4:15)
Block(-3,14,-3,biomesoplenty:leaves_4:15)
Block(-3,14,2,biomesoplenty:leaves_4:15)
Block(-3,14,3,biomesoplenty:leaves_4:15)
Block(-3,14,4,biomesoplenty:log_2:13)
Block(-3,14,5,biomesoplenty:leaves_4:15)
Block(-3,14,9,biomesoplenty:leaves_4:15)
Block(-3,14,10,biomesoplenty:leaves_4:15)
Block(-3,15,-4,biomesoplenty:leaves_4:15)
Block(-3,15,-3,biomesoplenty:leaves_4:15)
Block(-3,15,-2,biomesoplenty:leaves_4:15)
Block(-3,15,3,biomesoplenty:leaves_4:15)
Block(-3,15,4,biomesoplenty:log_2:13)
Block(-3,15,5,biomesoplenty:leaves_4:15)
Block(-3,15,9,biomesoplenty:leaves_4:15)
Block(-3,15,10,biomesoplenty:leaves_4:15)
Block(-3,16,-4,biomesoplenty:leaves_4:15)
Block(-3,16,-3,biomesoplenty:leaves_4:15)
Block(-3,16,-2,biomesoplenty:leaves_4:15)
Block(-3,16,0,biomesoplenty:leaves_4:15)
Block(-3,16,2,biomesoplenty:leaves_4:15)
Block(-3,16,3,biomesoplenty:log_2:13)
Block(-3,16,4,biomesoplenty:log_2:13)
Block(-3,16,5,biomesoplenty:log_2:13)
Block(-3,16,7,biomesoplenty:leaves_4:15)
Block(-3,16,8,biomesoplenty:leaves_4:15)
Block(-3,16,9,biomesoplenty:leaves_4:15)
Block(-3,16,10,biomesoplenty:leaves_4:15)
Block(-3,16,11,biomesoplenty:leaves_4:15)
Block(-3,17,-4,biomesoplenty:leaves_4:15)
Block(-3,17,-3,biomesoplenty:leaves_4:15)
Block(-3,17,-2,biomesoplenty:leaves_4:15)
Block(-3,17,-1,biomesoplenty:leaves_4:15)
Block(-3,17,0,biomesoplenty:log_2:9)
Block(-3,17,1,biomesoplenty:log_2:9)
Block(-3,17,2,biomesoplenty:log_2:9)
Block(-3,17,3,biomesoplenty:log_2:13)
Block(-3,17,4,biomesoplenty:log_2:13)
Block(-3,17,5,biomesoplenty:log_2:13)
Block(-3,17,6,biomesoplenty:log_2:9)
Block(-3,17,7,biomesoplenty:log_2:9)
Block(-3,17,8,biomesoplenty:log_2:9)
Block(-3,17,9,biomesoplenty:leaves_4:15)
Block(-3,17,10,biomesoplenty:leaves_4:15)
Block(-3,17,11,biomesoplenty:leaves_4:15)
Block(-3,18,-3,biomesoplenty:leaves_4:15)
Block(-3,18,-2,biomesoplenty:leaves_4:15)
Block(-3,18,-1,biomesoplenty:leaves_4:15)
Block(-3,18,0,biomesoplenty:leaves_4:15)
Block(-3,18,1,biomesoplenty:leaves_4:15)
Block(-3,18,2,biomesoplenty:leaves_4:15)
Block(-3,18,3,biomesoplenty:leaves_4:15)
Block(-3,18,4,biomesoplenty:log_2:13)
Block(-3,18,5,biomesoplenty:leaves_4:15)
Block(-3,18,6,biomesoplenty:leaves_4:15)
Block(-3,18,7,biomesoplenty:leaves_4:15)
Block(-3,18,8,biomesoplenty:leaves_4:15)
Block(-3,18,9,biomesoplenty:leaves_4:15)
Block(-3,18,10,biomesoplenty:leaves_4:15)
Block(-3,18,11,biomesoplenty:leaves_4:15)
Block(-3,19,-2,biomesoplenty:leaves_4:15)
Block(-3,19,-1,biomesoplenty:leaves_4:15)
Block(-3,19,0,biomesoplenty:leaves_4:15)
Block(-3,19,1,biomesoplenty:leaves_4:15)
Block(-3,19,2,biomesoplenty:leaves_4:15)
Block(-3,19,3,biomesoplenty:leaves_4:15)
Block(-3,19,4,biomesoplenty:leaves_4:15)
Block(-3,19,7,biomesoplenty:leaves_4:15)
Block(-3,20,2,biomesoplenty:leaves_4:15)
Block(-3,20,3,biomesoplenty:leaves_4:15)
Block(-2,8,-6,biomesoplenty:leaves_4:15)
Block(-2,8,-2,biomesoplenty:leaves_4:15)
Block(-2,8,2,biomesoplenty:log_2:1)
Block(-2,8,3,biomesoplenty:log_2:9)
Block(-2,9,-6,biomesoplenty:leaves_4:15)
Block(-2,9,-3,biomesoplenty:leaves_4:15)
Block(-2,9,-2,biomesoplenty:log_2:1)
Block(-2,9,-1,biomesoplenty:leaves_4:15)
Block(-2,9,2,biomesoplenty:leaves_4:15)
Block(-2,9,3,biomesoplenty:leaves_4:15)
Block(-2,9,4,biomesoplenty:leaves_4:15)
Block(-2,10,-7,biomesoplenty:leaves_4:15)
Block(-2,10,-6,biomesoplenty:leaves_4:15)
Block(-2,10,-5,biomesoplenty:leaves_4:15)
Block(-2,10,-2,biomesoplenty:leaves_4:15)
Block(-2,10,0,biomesoplenty:leaves_4:15)
Block(-2,10,1,biomesoplenty:leaves_4:15)
Block(-2,10,3,biomesoplenty:leaves_4:15)
Block(-2,11,-7,biomesoplenty:leaves_4:15)
Block(-2,11,-6,biomesoplenty:leaves_4:15)
Block(-2,11,-5,biomesoplenty:leaves_4:15)
Block(-2,11,0,biomesoplenty:leaves_4:15)
Block(-2,11,1,biomesoplenty:leaves_4:15)
Block(-2,11,2,biomesoplenty:leaves_4:15)
Block(-2,11,3,biomesoplenty:leaves_4:15)
Block(-2,11,4,biomesoplenty:leaves_4:15)
Block(-2,12,-7,biomesoplenty:leaves_4:15)
Block(-2,12,-6,biomesoplenty:leaves_4:15)
Block(-2,12,-5,biomesoplenty:leaves_4:15)
Block(-2,12,1,biomesoplenty:leaves_4:15)
Block(-2,12,3,biomesoplenty:leaves_4:15)
Block(-2,12,9,biomesoplenty:leaves_4:15)
Block(-2,12,10,biomesoplenty:leaves_4:15)
Block(-2,13,-6,biomesoplenty:leaves_4:15)
Block(-2,13,3,biomesoplenty:leaves_4:15)
Block(-2,13,4,biomesoplenty:log_2:13)
Block(-2,13,5,biomesoplenty:leaves_4:15)
Block(-2,13,8,biomesoplenty:leaves_4:15)
Block(-2,13,9,biomesoplenty:leaves_4:15)
Block(-2,13,10,biomesoplenty:leaves_4:15)
Block(-2,14,-6,biomesoplenty:leaves_4:15)
Block(-2,14,2,biomesoplenty:leaves_4:15)
Block(-2,14,3,biomesoplenty:log_2:13)
Block(-2,14,4,biomesoplenty:log_2:13)
Block(-2,14,5,biomesoplenty:log_2:13)
Block(-2,14,6,biomesoplenty:leaves_4:15)
Block(-2,14,7,biomesoplenty:leaves_4:15)
Block(-2,14,9,biomesoplenty:leaves_4:15)
Block(-2,14,10,biomesoplenty:leaves_4:15)
Block(-2,14,11,biomesoplenty:leaves_4:15)
Block(-2,15,-3,biomesoplenty:leaves_4:15)
Block(-2,15,3,biomesoplenty:log_2:13)
Block(-2,15,4,biomesoplenty:log_2:13)
Block(-2,15,5,biomesoplenty:log_2:13)
Block(-2,15,6,biomesoplenty:log_2:9)
Block(-2,15,7,biomesoplenty:leaves_4:15)
Block(-2,15,8,biomesoplenty:leaves_4:15)
Block(-2,15,9,biomesoplenty:leaves_4:15)
Block(-2,15,10,biomesoplenty:leaves_4:15)
Block(-2,15,11,biomesoplenty:leaves_4:15)
Block(-2,16,-5,biomesoplenty:leaves_4:15)
Block(-2,16,-4,biomesoplenty:leaves_4:15)
Block(-2,16,-3,biomesoplenty:leaves_4:15)
Block(-2,16,2,biomesoplenty:leaves_4:15)
Block(-2,16,3,biomesoplenty:log_2:13)
Block(-2,16,4,biomesoplenty:log_2:13)
Block(-2,16,5,biomesoplenty:log_2:13)
Block(-2,16,7,biomesoplenty:leaves_4:15)
Block(-2,16,8,biomesoplenty:leaves_4:15)
Block(-2,16,9,biomesoplenty:leaves_4:15)
Block(-2,16,10,biomesoplenty:leaves_4:15)
Block(-2,16,11,biomesoplenty:leaves_4:15)
Block(-2,17,-4,biomesoplenty:leaves_4:15)
Block(-2,17,-3,biomesoplenty:leaves_4:15)
Block(-2,17,-2,biomesoplenty:leaves_4:15)
Block(-2,17,-1,biomesoplenty:leaves_4:15)
Block(-2,17,0,biomesoplenty:leaves_4:15)
Block(-2,17,1,biomesoplenty:leaves_4:15)
Block(-2,17,2,biomesoplenty:leaves_4:15)
Block(-2,17,3,biomesoplenty:leaves_4:15)
Block(-2,17,4,biomesoplenty:log_2:13)
Block(-2,17,5,biomesoplenty:leaves_4:15)
Block(-2,17,7,biomesoplenty:leaves_4:15)
Block(-2,17,8,biomesoplenty:leaves_4:15)
Block(-2,17,9,biomesoplenty:leaves_4:15)
Block(-2,17,10,biomesoplenty:leaves_4:15)
Block(-2,17,11,biomesoplenty:leaves_4:15)
Block(-2,18,-3,biomesoplenty:leaves_4:15)
Block(-2,18,-2,biomesoplenty:leaves_4:15)
Block(-2,18,-1,biomesoplenty:leaves_4:15)
Block(-2,18,0,biomesoplenty:leaves_4:15)
Block(-2,18,1,biomesoplenty:leaves_4:15)
Block(-2,18,2,biomesoplenty:leaves_4:15)
Block(-2,18,3,biomesoplenty:leaves_4:15)
Block(-2,18,4,biomesoplenty:log_2:5)
Block(-2,18,8,biomesoplenty:leaves_4:15)
Block(-2,18,9,biomesoplenty:leaves_4:15)
Block(-2,18,10,biomesoplenty:leaves_4:15)
Block(-2,19,-2,biomesoplenty:leaves_4:15)
Block(-2,19,-1,biomesoplenty:leaves_4:15)
Block(-2,19,0,biomesoplenty:leaves_4:15)
Block(-2,19,1,biomesoplenty:leaves_4:15)
Block(-2,19,2,biomesoplenty:leaves_4:15)
Block(-2,19,3,biomesoplenty:leaves_4:15)
Block(-2,19,4,biomesoplenty:leaves_4:15)
Block(-2,19,5,biomesoplenty:leaves_4:15)
Block(-2,20,2,biomesoplenty:leaves_4:15)
Block(-1,0,4,biomesoplenty:log_2:5)
Block(-1,2,3,biomesoplenty:log_2:13)
Block(-1,3,2,biomesoplenty:log_2:13)
Block(-1,3,3,biomesoplenty:log_2:13)
Block(-1,3,4,biomesoplenty:log_2:13)
Block(-1,4,2,biomesoplenty:log_2:13)
Block(-1,4,3,biomesoplenty:log_2:13)
Block(-1,4,4,biomesoplenty:log_2:13)
Block(-1,5,2,biomesoplenty:log_2:13)
Block(-1,5,3,biomesoplenty:log_2:13)
Block(-1,5,4,biomesoplenty:log_2:13)
Block(-1,6,2,biomesoplenty:log_2:13)
Block(-1,6,3,biomesoplenty:log_2:13)
Block(-1,6,4,biomesoplenty:log_2:13)
Block(-1,7,-6,biomesoplenty:leaves_4:15)
Block(-1,7,1,biomesoplenty:log_2:13)
Block(-1,7,2,biomesoplenty:log_2:13)
Block(-1,7,3,biomesoplenty:log_2:13)
Block(-1,7,8,biomesoplenty:leaves_4:15)
Block(-1,7,9,biomesoplenty:leaves_4:15)
Block(-1,8,-6,biomesoplenty:leaves_4:15)
Block(-1,8,2,biomesoplenty:log_2:13)
Block(-1,8,3,biomesoplenty:log_2:9)
Block(-1,8,9,biomesoplenty:leaves_4:15)
Block(-1,9,-6,biomesoplenty:leaves_4:15)
Block(-1,9,-2,biomesoplenty:log_2:9)
Block(-1,9,-1,biomesoplenty:log_2:1)
Block(-1,9,0,biomesoplenty:leaves_4:15)
Block(-1,9,2,biomesoplenty:leaves_4:15)
Block(-1,9,3,biomesoplenty:leaves_4:15)
Block(-1,9,4,biomesoplenty:leaves_4:15)
Block(-1,9,9,biomesoplenty:leaves_4:15)
Block(-1,10,-6,biomesoplenty:leaves_4:15)
Block(-1,10,-1,biomesoplenty:leaves_4:15)
Block(-1,10,0,biomesoplenty:leaves_4:15)
Block(-1,10,1,biomesoplenty:leaves_4:15)
Block(-1,10,2,biomesoplenty:leaves_4:15)
Block(-1,10,3,biomesoplenty:leaves_4:15)
Block(-1,10,4,biomesoplenty:leaves_4:15)
Block(-1,10,9,biomesoplenty:leaves_4:15)
Block(-1,11,-6,biomesoplenty:leaves_4:15)
Block(-1,11,0,biomesoplenty:leaves_4:15)
Block(-1,11,1,biomesoplenty:leaves_4:15)
Block(-1,11,2,biomesoplenty:leaves_4:15)
Block(-1,11,3,biomesoplenty:leaves_4:15)
Block(-1,11,6,biomesoplenty:leaves_4:15)
Block(-1,11,7,biomesoplenty:leaves_4:15)
Block(-1,11,9,biomesoplenty:leaves_4:15)
Block(-1,12,-7,biomesoplenty:leaves_4:15)
Block(-1,12,-6,biomesoplenty:leaves_4:15)
Block(-1,12,-5,biomesoplenty:leaves_4:15)
Block(-1,12,1,biomesoplenty:leaves_4:15)
Block(-1,12,2,biomesoplenty:leaves_4:15)
Block(-1,12,3,biomesoplenty:leaves_4:15)
Block(-1,12,4,biomesoplenty:leaves_4:15)
Block(-1,12,6,biomesoplenty:leaves_4:15)
Block(-1,12,8,biomesoplenty:leaves_4:15)
Block(-1,12,9,biomesoplenty:leaves_4:15)
Block(-1,12,10,biomesoplenty:leaves_4:15)
Block(-1,13,-7,biomesoplenty:leaves_4:15)
Block(-1,13,-6,biomesoplenty:leaves_4:15)
Block(-1,13,-5,biomesoplenty:leaves_4:15)
Block(-1,13,3,biomesoplenty:leaves_4:15)
Block(-1,13,4,biomesoplenty:log_2:13)
Block(-1,13,5,biomesoplenty:leaves_4:15)
Block(-1,13,8,biomesoplenty:leaves_4:15)
Block(-1,13,9,biomesoplenty:leaves_4:15)
Block(-1,13,10,biomesoplenty:leaves_4:15)
Block(-1,13,11,biomesoplenty:leaves_4:15)
Block(-1,14,-7,biomesoplenty:leaves_4:15)
Block(-1,14,-6,biomesoplenty:leaves_4:15)
Block(-1,14,-5,biomesoplenty:leaves_4:15)
Block(-1,14,2,biomesoplenty:leaves_4:15)
Block(-1,14,3,biomesoplenty:log_2:13)
Block(-1,14,4,biomesoplenty:log_2:13)
Block(-1,14,5,biomesoplenty:log_2:13)
Block(-1,14,6,biomesoplenty:leaves_4:15)
Block(-1,14,7,biomesoplenty:leaves_4:15)
Block(-1,14,8,biomesoplenty:leaves_4:15)
Block(-1,14,9,biomesoplenty:leaves_4:15)
Block(-1,14,10,biomesoplenty:leaves_4:15)
Block(-1,14,11,biomesoplenty:leaves_4:15)
Block(-1,15,-6,biomesoplenty:leaves_4:15)
Block(-1,15,-5,biomesoplenty:leaves_4:15)
Block(-1,15,-4,biomesoplenty:leaves_4:15)
Block(-1,15,3,biomesoplenty:leaves_4:15)
Block(-1,15,4,biomesoplenty:log_2:13)
Block(-1,15,5,biomesoplenty:leaves_4:15)
Block(-1,15,6,biomesoplenty:log_2:13)
Block(-1,15,7,biomesoplenty:log_2:9)
Block(-1,15,8,biomesoplenty:leaves_4:15)
Block(-1,15,9,biomesoplenty:leaves_4:15)
Block(-1,15,10,biomesoplenty:leaves_4:15)
Block(-1,16,-6,biomesoplenty:leaves_4:15)
Block(-1,16,-5,biomesoplenty:leaves_4:15)
Block(-1,16,-4,biomesoplenty:leaves_4:15)
Block(-1,16,-3,biomesoplenty:leaves_4:15)
Block(-1,16,4,biomesoplenty:log_2:13)
Block(-1,16,6,biomesoplenty:leaves_4:15)
Block(-1,16,7,biomesoplenty:leaves_4:15)
Block(-1,16,8,biomesoplenty:leaves_4:15)
Block(-1,16,9,biomesoplenty:leaves_4:15)
Block(-1,16,10,biomesoplenty:leaves_4:15)
Block(-1,17,-5,biomesoplenty:leaves_4:15)
Block(-1,17,-4,biomesoplenty:leaves_4:15)
Block(-1,17,-3,biomesoplenty:leaves_4:15)
Block(-1,17,-2,biomesoplenty:leaves_4:15)
Block(-1,17,-1,biomesoplenty:leaves_4:15)
Block(-1,17,6,biomesoplenty:leaves_4:15)
Block(-1,18,-4,biomesoplenty:leaves_4:15)
Block(-1,18,-3,biomesoplenty:leaves_4:15)
Block(-1,18,-2,biomesoplenty:leaves_4:15)
Block(-1,18,-1,biomesoplenty:leaves_4:15)
Block(-1,18,3,biomesoplenty:leaves_4:15)
Block(-1,18,4,biomesoplenty:log_2:13)
Block(-1,18,5,biomesoplenty:leaves_4:15)
Block(-1,18,6,biomesoplenty:leaves_4:15)
Block(-1,18,7,biomesoplenty:leaves_4:15)
Block(-1,19,-4,biomesoplenty:leaves_4:15)
Block(-1,19,-3,biomesoplenty:leaves_4:15)
Block(-1,19,-2,biomesoplenty:leaves_4:15)
Block(-1,19,-1,biomesoplenty:leaves_4:15)
Block(-1,19,2,biomesoplenty:leaves_4:15)
Block(-1,19,3,biomesoplenty:leaves_4:15)
Block(-1,19,4,biomesoplenty:log_2:5)
Block(-1,19,5,biomesoplenty:leaves_4:15)
Block(-1,20,1,biomesoplenty:leaves_4:15)
Block(-1,20,2,biomesoplenty:leaves_4:15)
Block(-1,20,3,biomesoplenty:leaves_4:15)
Block(-1,20,4,biomesoplenty:leaves_4:15)
Block(-1,20,5,biomesoplenty:leaves_4:15)
Block(-1,21,2,biomesoplenty:leaves_4:15)
Block(-1,21,3,biomesoplenty:leaves_4:15)
Block(0,0,2,biomesoplenty:log_2:13)
Block(0,0,3,biomesoplenty:log_2:13)
Block(0,0,4,biomesoplenty:log_2:13)
Block(0,0,5,biomesoplenty:log_2:9)
Block(0,1,2,biomesoplenty:log_2:13)
Block(0,1,3,biomesoplenty:log_2:13)
Block(0,1,4,biomesoplenty:log_2:13)
Block(0,2,2,biomesoplenty:log_2:13)
Block(0,2,3,biomesoplenty:log_2:13)
Block(0,2,4,biomesoplenty:log_2:13)
Block(0,3,2,biomesoplenty:log_2:13)
Block(0,3,3,biomesoplenty:log_2:13)
Block(0,3,4,biomesoplenty:log_2:13)
Block(0,4,2,biomesoplenty:log_2:13)
Block(0,4,3,biomesoplenty:log_2:13)
Block(0,4,4,biomesoplenty:log_2:13)
Block(0,5,2,biomesoplenty:log_2:13)
Block(0,5,3,biomesoplenty:log_2:13)
Block(0,5,4,biomesoplenty:log_2:13)
Block(0,6,-6,biomesoplenty:leaves_4:15)
Block(0,6,1,biomesoplenty:log_2:13)
Block(0,6,2,biomesoplenty:log_2:13)
Block(0,6,3,biomesoplenty:log_2:13)
Block(0,6,4,biomesoplenty:log_2:13)
Block(0,6,8,biomesoplenty:leaves_4:15)
Block(0,6,9,biomesoplenty:leaves_4:15)
Block(0,7,-7,biomesoplenty:leaves_4:15)
Block(0,7,-6,biomesoplenty:leaves_4:15)
Block(0,7,-5,biomesoplenty:leaves_4:15)
Block(0,7,1,biomesoplenty:log_2:13)
Block(0,7,2,biomesoplenty:log_2:13)
Block(0,7,3,biomesoplenty:log_2:13)
Block(0,7,4,biomesoplenty:log_2:13)
Block(0,7,7,biomesoplenty:leaves_4:15)
Block(0,7,8,biomesoplenty:leaves_4:15)
Block(0,7,9,biomesoplenty:leaves_4:15)
Block(0,7,10,biomesoplenty:leaves_4:15)
Block(0,8,-7,biomesoplenty:leaves_4:15)
Block(0,8,-6,biomesoplenty:leaves_4:15)
Block(0,8,-5,biomesoplenty:leaves_4:15)
Block(0,8,-2,biomesoplenty:leaves_4:15)
Block(0,8,-1,biomesoplenty:leaves_4:15)
Block(0,8,1,biomesoplenty:log_2:13)
Block(0,8,2,biomesoplenty:log_2:13)
Block(0,8,3,biomesoplenty:log_2:13)
Block(0,8,8,biomesoplenty:leaves_4:15)
Block(0,8,9,biomesoplenty:leaves_4:15)
Block(0,8,10,biomesoplenty:leaves_4:15)
Block(0,9,-7,biomesoplenty:leaves_4:15)
Block(0,9,-6,biomesoplenty:leaves_4:15)
Block(0,9,-5,biomesoplenty:leaves_4:15)
Block(0,9,-3,biomesoplenty:leaves_4:15)
Block(0,9,-2,biomesoplenty:leaves_4:15)
Block(0,9,-1,biomesoplenty:log_2:9)
Block(0,9,0,biomesoplenty:log_2:13)
Block(0,9,1,biomesoplenty:log_2:13)
Block(0,9,2,biomesoplenty:log_2:13)
Block(0,9,3,biomesoplenty:leaves_4:15)
Block(0,9,8,biomesoplenty:leaves_4:15)
Block(0,9,9,biomesoplenty:leaves_4:15)
Block(0,10,-7,biomesoplenty:leaves_4:15)
Block(0,10,-6,biomesoplenty:leaves_4:15)
Block(0,10,-5,biomesoplenty:leaves_4:15)
Block(0,10,-2,biomesoplenty:leaves_4:15)
Block(0,10,-1,biomesoplenty:leaves_4:15)
Block(0,10,0,biomesoplenty:leaves_4:15)
Block(0,10,1,biomesoplenty:log_2:13)
Block(0,10,2,biomesoplenty:leaves_4:15)
Block(0,10,3,biomesoplenty:leaves_4:15)
Block(0,10,6,biomesoplenty:leaves_4:15)
Block(0,10,7,biomesoplenty:leaves_4:15)
Block(0,10,8,biomesoplenty:leaves_4:15)
Block(0,10,9,biomesoplenty:leaves_4:15)
Block(0,10,10,biomesoplenty:leaves_4:15)
Block(0,11,-7,biomesoplenty:leaves_4:15)
Block(0,11,-6,biomesoplenty:leaves_4:15)
Block(0,11,-5,biomesoplenty:leaves_4:15)
Block(0,11,0,biomesoplenty:leaves_4:15)
Block(0,11,1,biomesoplenty:leaves_4:15)
Block(0,11,2,biomesoplenty:leaves_4:15)
Block(0,11,3,biomesoplenty:log_2:13)
Block(0,11,4,biomesoplenty:leaves_4:15)
Block(0,11,5,biomesoplenty:leaves_4:15)
Block(0,11,6,biomesoplenty:leaves_4:15)
Block(0,11,7,biomesoplenty:leaves_4:15)
Block(0,11,8,biomesoplenty:leaves_4:15)
Block(0,11,9,biomesoplenty:leaves_4:15)
Block(0,11,10,biomesoplenty:leaves_4:15)
Block(0,12,-7,biomesoplenty:leaves_4:15)
Block(0,12,-6,biomesoplenty:leaves_4:15)
Block(0,12,-5,biomesoplenty:leaves_4:15)
Block(0,12,3,biomesoplenty:log_2:13)
Block(0,12,4,biomesoplenty:log_2:13)
Block(0,12,5,biomesoplenty:leaves_4:15)
Block(0,12,6,biomesoplenty:leaves_4:15)
Block(0,12,7,biomesoplenty:leaves_4:15)
Block(0,12,9,biomesoplenty:leaves_4:15)
Block(0,12,10,biomesoplenty:leaves_4:15)
Block(0,12,11,biomesoplenty:leaves_4:15)
Block(0,13,-6,biomesoplenty:leaves_4:15)
Block(0,13,2,biomesoplenty:leaves_4:15)
Block(0,13,3,biomesoplenty:log_2:13)
Block(0,13,4,biomesoplenty:log_2:13)
Block(0,13,5,biomesoplenty:log_2:13)
Block(0,13,6,biomesoplenty:leaves_4:15)
Block(0,13,9,biomesoplenty:leaves_4:15)
Block(0,13,10,biomesoplenty:leaves_4:15)
Block(0,13,11,biomesoplenty:leaves_4:15)
Block(0,14,-7,biomesoplenty:leaves_4:15)
Block(0,14,-6,biomesoplenty:leaves_4:15)
Block(0,14,1,biomesoplenty:leaves_4:15)
Block(0,14,2,biomesoplenty:leaves_4:15)
Block(0,14,3,biomesoplenty:log_2:13)
Block(0,14,4,biomesoplenty:log_2:13)
Block(0,14,5,biomesoplenty:log_2:13)
Block(0,14,7,biomesoplenty:leaves_4:15)
Block(0,14,8,biomesoplenty:leaves_4:15)
Block(0,14,9,biomesoplenty:leaves_4:15)
Block(0,14,10,biomesoplenty:leaves_4:15)
Block(0,14,11,biomesoplenty:leaves_4:15)
Block(0,15,-7,biomesoplenty:leaves_4:15)
Block(0,15,-6,biomesoplenty:leaves_4:15)
Block(0,15,-5,biomesoplenty:leaves_4:15)
Block(0,15,-2,biomesoplenty:leaves_4:15)
Block(0,15,2,biomesoplenty:leaves_4:15)
Block(0,15,3,biomesoplenty:leaves_4:15)
Block(0,15,4,biomesoplenty:log_2:13)
Block(0,15,6,biomesoplenty:leaves_4:15)
Block(0,15,7,biomesoplenty:log_2:13)
Block(0,15,8,biomesoplenty:leaves_4:15)
Block(0,15,9,biomesoplenty:leaves_4:15)
Block(0,15,10,biomesoplenty:leaves_4:15)
Block(0,16,-7,biomesoplenty:leaves_4:15)
Block(0,16,-6,biomesoplenty:leaves_4:15)
Block(0,16,-5,biomesoplenty:leaves_4:15)
Block(0,16,-4,biomesoplenty:leaves_4:15)
Block(0,16,-2,biomesoplenty:leaves_4:15)
Block(0,16,-1,biomesoplenty:leaves_4:15)
Block(0,16,0,biomesoplenty:leaves_4:15)
Block(0,16,1,biomesoplenty:leaves_4:15)
Block(0,16,2,biomesoplenty:leaves_4:15)
Block(0,16,3,biomesoplenty:leaves_4:15)
Block(0,16,4,biomesoplenty:leaves_4:15)
Block(0,16,7,biomesoplenty:leaves_4:15)
Block(0,16,9,biomesoplenty:leaves_4:15)
Block(0,16,10,biomesoplenty:leaves_4:15)
Block(0,17,-6,biomesoplenty:leaves_4:15)
Block(0,17,-5,biomesoplenty:leaves_4:15)
Block(0,17,-4,biomesoplenty:leaves_4:15)
Block(0,17,-3,biomesoplenty:leaves_4:15)
Block(0,17,-2,biomesoplenty:leaves_4:15)
Block(0,17,2,biomesoplenty:leaves_4:15)
Block(0,17,6,biomesoplenty:leaves_4:15)
Block(0,17,7,biomesoplenty:leaves_4:15)
Block(0,17,9,biomesoplenty:leaves_4:15)
Block(0,18,-4,biomesoplenty:leaves_4:15)
Block(0,18,-3,biomesoplenty:leaves_4:15)
Block(0,18,-2,biomesoplenty:leaves_4:15)
Block(0,18,-1,biomesoplenty:leaves_4:15)
Block(0,18,4,biomesoplenty:log_2:13)
Block(0,18,5,biomesoplenty:log_2:9)
Block(0,18,6,biomesoplenty:log_2:9)
Block(0,18,7,biomesoplenty:leaves_4:15)
Block(0,18,8,biomesoplenty:leaves_4:15)
Block(0,19,-5,biomesoplenty:leaves_4:15)
Block(0,19,-4,biomesoplenty:leaves_4:15)
Block(0,19,-3,biomesoplenty:leaves_4:15)
Block(0,19,-2,biomesoplenty:leaves_4:15)
Block(0,19,1,biomesoplenty:leaves_4:15)
Block(0,19,2,biomesoplenty:leaves_4:15)
Block(0,19,3,biomesoplenty:log_2:9)
Block(0,19,4,biomesoplenty:log_2:13)
Block(0,19,5,biomesoplenty:leaves_4:15)
Block(0,19,6,biomesoplenty:leaves_4:15)
Block(0,20,-4,biomesoplenty:leaves_4:15)
Block(0,20,1,biomesoplenty:leaves_4:15)
Block(0,20,2,biomesoplenty:leaves_4:15)
Block(0,20,3,biomesoplenty:log_2:5)
Block(0,20,4,biomesoplenty:leaves_4:15)
Block(0,21,2,biomesoplenty:leaves_4:15)
Block(0,21,3,biomesoplenty:leaves_4:15)
Block(0,21,4,biomesoplenty:leaves_4:15)
Block(1,0,1,biomesoplenty:log_2:5)
Block(1,0,2,biomesoplenty:log_2:13)
Block(1,0,3,biomesoplenty:log_2:13)
Block(1,0,4,biomesoplenty:log_2:13)
Block(1,0,5,biomesoplenty:log_2:5)
Block(1,0,6,biomesoplenty:log_2:5)
Block(1,1,1,biomesoplenty:log_2:5)
Block(1,1,2,biomesoplenty:log_2:13)
Block(1,1,3,biomesoplenty:log_2:13)
Block(1,1,4,biomesoplenty:log_2:13)
Block(1,1,5,biomesoplenty:log_2:5)
Block(1,2,1,biomesoplenty:log_2:5)
Block(1,2,2,biomesoplenty:log_2:13)
Block(1,2,3,biomesoplenty:log_2:13)
Block(1,2,4,biomesoplenty:log_2:13)
Block(1,2,5,biomesoplenty:log_2:9)
Block(1,3,2,biomesoplenty:log_2:13)
Block(1,3,3,biomesoplenty:log_2:13)
Block(1,3,4,biomesoplenty:log_2:13)
Block(1,4,2,biomesoplenty:log_2:13)
Block(1,4,3,biomesoplenty:log_2:13)
Block(1,4,4,biomesoplenty:log_2:13)
Block(1,5,2,biomesoplenty:log_2:13)
Block(1,5,3,biomesoplenty:log_2:13)
Block(1,5,4,biomesoplenty:log_2:13)
Block(1,6,2,biomesoplenty:log_2:13)
Block(1,6,3,biomesoplenty:log_2:13)
Block(1,6,4,biomesoplenty:log_2:13)
Block(1,7,-6,biomesoplenty:leaves_4:15)
Block(1,7,1,biomesoplenty:log_2:13)
Block(1,7,2,biomesoplenty:log_2:13)
Block(1,7,3,biomesoplenty:log_2:13)
Block(1,7,8,biomesoplenty:leaves_4:15)
Block(1,7,9,biomesoplenty:leaves_4:15)
Block(1,8,-6,biomesoplenty:leaves_4:15)
Block(1,8,-2,biomesoplenty:leaves_4:15)
Block(1,8,0,biomesoplenty:log_2:13)
Block(1,8,1,biomesoplenty:log_2:13)
Block(1,8,2,biomesoplenty:log_2:13)
Block(1,8,3,biomesoplenty:log_2:13)
Block(1,8,9,biomesoplenty:leaves_4:15)
Block(1,9,-6,biomesoplenty:leaves_4:15)
Block(1,9,-3,biomesoplenty:leaves_4:15)
Block(1,9,-2,biomesoplenty:leaves_4:15)
Block(1,9,-1,biomesoplenty:leaves_4:15)
Block(1,9,0,biomesoplenty:log_2:13)
Block(1,9,1,biomesoplenty:log_2:13)
Block(1,9,2,biomesoplenty:log_2:13)
Block(1,9,3,biomesoplenty:log_2:13)
Block(1,9,5,biomesoplenty:leaves_4:15)
Block(1,9,9,biomesoplenty:leaves_4:15)
Block(1,10,-2,biomesoplenty:leaves_4:15)
Block(1,10,0,biomesoplenty:log_2:13)
Block(1,10,1,biomesoplenty:log_2:13)
Block(1,10,2,biomesoplenty:log_2:13)
Block(1,10,3,biomesoplenty:log_2:13)
Block(1,10,5,biomesoplenty:leaves_4:15)
Block(1,10,8,biomesoplenty:leaves_4:15)
Block(1,10,9,biomesoplenty:leaves_4:15)
Block(1,10,10,biomesoplenty:leaves_4:15)
Block(1,11,-6,biomesoplenty:leaves_4:15)
Block(1,11,-1,biomesoplenty:leaves_4:15)
Block(1,11,0,biomesoplenty:leaves_4:15)
Block(1,11,1,biomesoplenty:log_2:13)
Block(1,11,2,biomesoplenty:log_2:13)
Block(1,11,3,biomesoplenty:log_2:13)
Block(1,11,4,biomesoplenty:log_2:13)
Block(1,11,6,biomesoplenty:leaves_4:15)
Block(1,11,7,biomesoplenty:leaves_4:15)
Block(1,11,8,biomesoplenty:leaves_4:15)
Block(1,11,9,biomesoplenty:leaves_4:15)
Block(1,11,10,biomesoplenty:leaves_4:15)
Block(1,11,11,biomesoplenty:leaves_4:15)
Block(1,12,-7,biomesoplenty:leaves_4:15)
Block(1,12,-6,biomesoplenty:leaves_4:15)
Block(1,12,0,biomesoplenty:leaves_4:15)
Block(1,12,1,biomesoplenty:leaves_4:15)
Block(1,12,2,biomesoplenty:log_2:13)
Block(1,12,3,biomesoplenty:log_2:13)
Block(1,12,4,biomesoplenty:log_2:13)
Block(1,12,5,biomesoplenty:leaves_4:15)
Block(1,12,9,biomesoplenty:leaves_4:15)
Block(1,12,10,biomesoplenty:leaves_4:15)
Block(1,12,11,biomesoplenty:leaves_4:15)
Block(1,13,-7,biomesoplenty:leaves_4:15)
Block(1,13,-6,biomesoplenty:leaves_4:15)
Block(1,13,-5,biomesoplenty:leaves_4:15)
Block(1,13,0,biomesoplenty:leaves_4:15)
Block(1,13,1,biomesoplenty:leaves_4:15)
Block(1,13,2,biomesoplenty:log_2:13)
Block(1,13,3,biomesoplenty:log_2:13)
Block(1,13,4,biomesoplenty:log_2:13)
Block(1,13,5,biomesoplenty:log_2:13)
Block(1,13,10,biomesoplenty:leaves_4:15)
Block(1,14,-8,biomesoplenty:leaves_4:7)
Block(1,14,-7,biomesoplenty:leaves_4:15)
Block(1,14,-6,biomesoplenty:leaves_4:15)
Block(1,14,-5,biomesoplenty:leaves_4:15)
Block(1,14,1,biomesoplenty:leaves_4:15)
Block(1,14,2,biomesoplenty:leaves_4:15)
Block(1,14,3,biomesoplenty:log_2:13)
Block(1,14,4,biomesoplenty:log_2:13)
Block(1,14,8,biomesoplenty:leaves_4:15)
Block(1,14,9,biomesoplenty:leaves_4:15)
Block(1,14,10,biomesoplenty:leaves_4:15)
Block(1,15,-7,biomesoplenty:leaves_4:15)
Block(1,15,-6,biomesoplenty:leaves_4:15)
Block(1,15,-3,biomesoplenty:leaves_4:15)
Block(1,15,-2,biomesoplenty:leaves_4:15)
Block(1,15,-1,biomesoplenty:leaves_4:15)
Block(1,15,0,biomesoplenty:leaves_4:15)
Block(1,15,1,biomesoplenty:leaves_4:15)
Block(1,15,2,biomesoplenty:leaves_4:15)
Block(1,15,3,biomesoplenty:leaves_4:15)
Block(1,15,4,biomesoplenty:leaves_4:15)
Block(1,15,7,biomesoplenty:log_2:13)
Block(1,15,8,biomesoplenty:log_2:9)
Block(1,15,9,biomesoplenty:leaves_4:15)
Block(1,15,10,biomesoplenty:leaves_4:15)
Block(1,16,-8,biomesoplenty:leaves_4:15)
Block(1,16,-7,biomesoplenty:leaves_4:15)
Block(1,16,-6,biomesoplenty:leaves_4:15)
Block(1,16,-5,biomesoplenty:leaves_4:15)
Block(1,16,-3,biomesoplenty:leaves_4:15)
Block(1,16,-2,biomesoplenty:log_2:9)
Block(1,16,-1,biomesoplenty:log_2:13)
Block(1,16,0,biomesoplenty:leaves_4:15)
Block(1,16,1,biomesoplenty:leaves_4:15)
Block(1,16,2,biomesoplenty:leaves_4:15)
Block(1,16,3,biomesoplenty:leaves_4:15)
Block(1,16,8,biomesoplenty:log_2:5)
Block(1,16,9,biomesoplenty:log_2:9)
Block(1,16,10,biomesoplenty:leaves_4:15)
Block(1,17,-7,biomesoplenty:leaves_4:15)
Block(1,17,-6,biomesoplenty:leaves_4:15)
Block(1,17,-5,biomesoplenty:leaves_4:15)
Block(1,17,-4,biomesoplenty:leaves_4:15)
Block(1,17,-3,biomesoplenty:leaves_4:15)
Block(1,17,-2,biomesoplenty:leaves_4:15)
Block(1,17,-1,biomesoplenty:leaves_4:15)
Block(1,17,0,biomesoplenty:leaves_4:15)
Block(1,17,1,biomesoplenty:leaves_4:15)
Block(1,17,2,biomesoplenty:leaves_4:15)
Block(1,17,3,biomesoplenty:leaves_4:15)
Block(1,17,6,biomesoplenty:leaves_4:15)
Block(1,17,7,biomesoplenty:leaves_4:15)
Block(1,17,8,biomesoplenty:leaves_4:15)
Block(1,17,9,biomesoplenty:leaves_4:15)
Block(1,17,10,biomesoplenty:leaves_4:15)
Block(1,18,-6,biomesoplenty:leaves_4:15)
Block(1,18,-5,biomesoplenty:leaves_4:15)
Block(1,18,-4,biomesoplenty:log_2:13)
Block(1,18,-3,biomesoplenty:leaves_4:15)
Block(1,18,-1,biomesoplenty:leaves_4:15)
Block(1,18,0,biomesoplenty:leaves_4:15)
Block(1,18,1,biomesoplenty:leaves_4:15)
Block(1,18,5,biomesoplenty:leaves_4:15)
Block(1,18,6,biomesoplenty:log_2:13)
Block(1,18,7,biomesoplenty:log_2:9)
Block(1,18,8,biomesoplenty:leaves_4:15)
Block(1,19,-4,biomesoplenty:leaves_4:15)
Block(1,19,-3,biomesoplenty:leaves_4:15)
Block(1,19,-2,biomesoplenty:leaves_4:15)
Block(1,19,-1,biomesoplenty:leaves_4:15)
Block(1,19,0,biomesoplenty:leaves_4:15)
Block(1,19,2,biomesoplenty:leaves_4:15)
Block(1,19,6,biomesoplenty:leaves_4:15)
Block(1,19,7,biomesoplenty:leaves_4:15)
Block(1,19,8,biomesoplenty:leaves_4:15)
Block(1,20,-1,biomesoplenty:leaves_4:15)
Block(1,20,1,biomesoplenty:leaves_4:15)
Block(1,20,2,biomesoplenty:leaves_4:15)
Block(1,20,3,biomesoplenty:leaves_4:15)
Block(1,20,4,biomesoplenty:leaves_4:15)
Block(1,21,2,biomesoplenty:leaves_4:15)
Block(1,21,3,biomesoplenty:leaves_4:15)
Block(2,0,1,biomesoplenty:log_2:5)
Block(2,0,2,biomesoplenty:log_2:13)
Block(2,0,3,biomesoplenty:log_2:13)
Block(2,0,4,biomesoplenty:log_2:13)
Block(2,0,5,biomesoplenty:log_2:5)
Block(2,1,2,biomesoplenty:log_2:13)
Block(2,1,3,biomesoplenty:log_2:13)
Block(2,1,4,biomesoplenty:log_2:13)
Block(2,1,5,biomesoplenty:log_2:1)
Block(2,2,2,biomesoplenty:log_2:13)
Block(2,2,3,biomesoplenty:log_2:13)
Block(2,2,4,biomesoplenty:log_2:13)
Block(2,3,3,biomesoplenty:log_2:13)
Block(2,7,2,biomesoplenty:log_2:13)
Block(2,8,1,biomesoplenty:log_2:13)
Block(2,8,2,biomesoplenty:log_2:13)
Block(2,8,3,biomesoplenty:log_2:13)
Block(2,8,5,biomesoplenty:leaves_4:15)
Block(2,9,-2,biomesoplenty:leaves_4:15)
Block(2,9,0,biomesoplenty:log_2:13)
Block(2,9,1,biomesoplenty:log_2:13)
Block(2,9,2,biomesoplenty:log_2:13)
Block(2,9,4,biomesoplenty:leaves_4:15)
Block(2,9,5,biomesoplenty:log_2:5)
Block(2,9,6,biomesoplenty:leaves_4:15)
Block(2,10,-1,biomesoplenty:leaves_4:15)
Block(2,10,0,biomesoplenty:log_2:13)
Block(2,10,1,biomesoplenty:log_2:13)
Block(2,10,2,biomesoplenty:log_2:13)
Block(2,10,3,biomesoplenty:log_2:13)
Block(2,10,4,biomesoplenty:log_2:9)
Block(2,10,5,biomesoplenty:log_2:9)
Block(2,11,-7,biomesoplenty:leaves_4:15)
Block(2,11,-1,biomesoplenty:leaves_4:15)
Block(2,11,0,biomesoplenty:log_2:13)
Block(2,11,1,biomesoplenty:log_2:13)
Block(2,11,2,biomesoplenty:log_2:13)
Block(2,11,3,biomesoplenty:log_2:13)
Block(2,11,5,biomesoplenty:leaves_4:15)
Block(2,11,9,biomesoplenty:leaves_4:15)
Block(2,11,10,biomesoplenty:leaves_4:15)
Block(2,12,-8,biomesoplenty:leaves_4:15)
Block(2,12,-7,biomesoplenty:leaves_4:15)
Block(2,12,-6,biomesoplenty:leaves_4:15)
Block(2,12,-5,biomesoplenty:leaves_4:15)
Block(2,12,0,biomesoplenty:leaves_4:15)
Block(2,12,1,biomesoplenty:log_2:13)
Block(2,12,2,biomesoplenty:log_2:13)
Block(2,12,3,biomesoplenty:log_2:13)
Block(2,12,4,biomesoplenty:leaves_4:15)
Block(2,12,10,biomesoplenty:leaves_4:15)
Block(2,13,-8,biomesoplenty:leaves_4:15)
Block(2,13,-7,biomesoplenty:leaves_4:15)
Block(2,13,-6,biomesoplenty:leaves_4:15)
Block(2,13,-5,biomesoplenty:leaves_4:15)
Block(2,13,-4,biomesoplenty:leaves_4:15)
Block(2,13,-3,biomesoplenty:leaves_4:15)
Block(2,13,0,biomesoplenty:leaves_4:15)
Block(2,13,1,biomesoplenty:leaves_4:15)
Block(2,13,2,biomesoplenty:log_2:13)
Block(2,13,3,biomesoplenty:log_2:13)
Block(2,13,4,biomesoplenty:log_2:13)
Block(2,13,5,biomesoplenty:leaves_4:15)
Block(2,14,-8,biomesoplenty:leaves_4:7)
Block(2,14,-7,biomesoplenty:leaves_4:15)
Block(2,14,-6,biomesoplenty:leaves_4:15)
Block(2,14,-5,biomesoplenty:leaves_4:15)
Block(2,14,-4,biomesoplenty:leaves_4:15)
Block(2,14,-3,biomesoplenty:leaves_4:15)
Block(2,14,-2,biomesoplenty:leaves_4:15)
Block(2,14,-1,biomesoplenty:leaves_4:15)
Block(2,14,0,biomesoplenty:leaves_4:15)
Block(2,14,1,biomesoplenty:log_2:13)
Block(2,14,2,biomesoplenty:log_2:13)
Block(2,14,3,biomesoplenty:leaves_4:15)
Block(2,14,4,biomesoplenty:leaves_4:15)
Block(2,14,5,biomesoplenty:leaves_4:15)
Block(2,14,7,biomesoplenty:leaves_4:15)
Block(2,14,8,biomesoplenty:leaves_4:15)
Block(2,15,-8,biomesoplenty:leaves_4:15)
Block(2,15,-7,biomesoplenty:leaves_4:15)
Block(2,15,-6,biomesoplenty:leaves_4:15)
Block(2,15,-5,biomesoplenty:leaves_4:15)
Block(2,15,-2,biomesoplenty:leaves_4:15)
Block(2,15,-1,biomesoplenty:leaves_4:15)
Block(2,15,0,biomesoplenty:log_2:13)
Block(2,15,1,biomesoplenty:log_2:13)
Block(2,15,2,biomesoplenty:leaves_4:15)
Block(2,15,3,biomesoplenty:leaves_4:15)
Block(2,15,4,biomesoplenty:leaves_4:15)
Block(2,15,7,biomesoplenty:leaves_4:15)
Block(2,15,8,biomesoplenty:log_2:13)
Block(2,15,9,biomesoplenty:leaves_4:15)
Block(2,16,-8,biomesoplenty:leaves_4:15)
Block(2,16,-7,biomesoplenty:leaves_4:15)
Block(2,16,-6,biomesoplenty:leaves_4:15)
Block(2,16,-5,biomesoplenty:leaves_4:15)
Block(2,16,-4,biomesoplenty:leaves_4:15)
Block(2,16,-3,biomesoplenty:leaves_4:15)
Block(2,16,-2,biomesoplenty:leaves_4:15)
Block(2,16,-1,biomesoplenty:log_2:9)
Block(2,16,0,biomesoplenty:log_2:5)
Block(2,16,1,biomesoplenty:log_2:13)
Block(2,16,2,biomesoplenty:leaves_4:15)
Block(2,16,3,biomesoplenty:leaves_4:15)
Block(2,16,7,biomesoplenty:leaves_4:15)
Block(2,16,8,biomesoplenty:leaves_4:15)
Block(2,16,9,biomesoplenty:leaves_4:15)
Block(2,17,-7,biomesoplenty:leaves_4:15)
Block(2,17,-6,biomesoplenty:leaves_4:15)
Block(2,17,-5,biomesoplenty:leaves_4:15)
Block(2,17,-4,biomesoplenty:leaves_4:15)
Block(2,17,-3,biomesoplenty:leaves_4:15)
Block(2,17,-2,biomesoplenty:leaves_4:15)
Block(2,17,-1,biomesoplenty:leaves_4:15)
Block(2,17,0,biomesoplenty:log_2:13)
Block(2,17,1,biomesoplenty:log_2:13)
Block(2,17,2,biomesoplenty:leaves_4:15)
Block(2,17,7,biomesoplenty:leaves_4:15)
Block(2,17,9,biomesoplenty:leaves_4:15)
Block(2,18,-5,biomesoplenty:leaves_4:15)
Block(2,18,-4,biomesoplenty:log_2:9)
Block(2,18,-3,biomesoplenty:log_2:13)
Block(2,18,-2,biomesoplenty:leaves_4:15)
Block(2,18,-1,biomesoplenty:leaves_4:15)
Block(2,18,0,biomesoplenty:log_2:13)
Block(2,18,4,biomesoplenty:leaves_4:15)
Block(2,18,6,biomesoplenty:leaves_4:15)
Block(2,18,7,biomesoplenty:leaves_4:15)
Block(2,18,8,biomesoplenty:leaves_4:15)
Block(2,19,-5,biomesoplenty:leaves_4:15)
Block(2,19,-4,biomesoplenty:leaves_4:15)
Block(2,19,-3,biomesoplenty:leaves_4:15)
Block(2,19,-2,biomesoplenty:leaves_4:15)
Block(2,19,-1,biomesoplenty:leaves_4:15)
Block(2,19,0,biomesoplenty:leaves_4:15)
Block(2,19,1,biomesoplenty:leaves_4:15)
Block(2,19,2,biomesoplenty:leaves_4:15)
Block(2,19,3,biomesoplenty:leaves_4:15)
Block(2,19,4,biomesoplenty:leaves_4:15)
Block(2,19,5,biomesoplenty:leaves_4:15)
Block(2,19,6,biomesoplenty:leaves_4:15)
Block(2,19,7,biomesoplenty:leaves_4:15)
Block(2,19,8,biomesoplenty:leaves_4:15)
Block(2,20,-2,biomesoplenty:leaves_4:15)
Block(2,20,-1,biomesoplenty:leaves_4:15)
Block(2,20,0,biomesoplenty:leaves_4:15)
Block(2,20,1,biomesoplenty:leaves_4:15)
Block(2,20,2,biomesoplenty:log_2:13)
Block(2,20,3,biomesoplenty:leaves_4:15)
Block(2,20,4,biomesoplenty:leaves_4:15)
Block(2,20,7,biomesoplenty:leaves_4:15)
Block(2,20,8,biomesoplenty:leaves_4:15)
Block(2,20,9,biomesoplenty:leaves_4:15)
Block(2,21,2,biomesoplenty:leaves_4:15)
Block(2,21,3,biomesoplenty:leaves_4:15)
Block(3,0,3,biomesoplenty:log_2:5)
Block(3,0,4,biomesoplenty:log_2:1)
Block(3,1,2,biomesoplenty:log_2:9)
Block(3,1,3,biomesoplenty:log_2:5)
Block(3,2,2,biomesoplenty:log_2:5)
Block(3,8,2,biomesoplenty:log_2:5)
Block(3,8,3,biomesoplenty:log_2:9)
Block(3,8,4,biomesoplenty:log_2:9)
Block(3,9,-1,biomesoplenty:leaves_4:15)
Block(3,9,1,biomesoplenty:log_2:13)
Block(3,9,2,biomesoplenty:log_2:9)
Block(3,9,3,biomesoplenty:leaves_4:15)
Block(3,9,5,biomesoplenty:leaves_4:15)
Block(3,10,-2,biomesoplenty:leaves_4:15)
Block(3,10,-1,biomesoplenty:leaves_4:15)
Block(3,10,0,biomesoplenty:log_2:13)
Block(3,10,1,biomesoplenty:log_2:13)
Block(3,10,2,biomesoplenty:log_2:13)
Block(3,10,3,biomesoplenty:leaves_4:15)
Block(3,10,5,biomesoplenty:leaves_4:15)
Block(3,11,-6,biomesoplenty:leaves_4:15)
Block(3,11,-2,biomesoplenty:leaves_4:15)
Block(3,11,-1,biomesoplenty:leaves_4:15)
Block(3,11,0,biomesoplenty:leaves_4:15)
Block(3,11,1,biomesoplenty:log_2:13)
Block(3,11,2,biomesoplenty:log_2:13)
Block(3,11,3,biomesoplenty:log_2:13)
Block(3,11,4,biomesoplenty:leaves_4:15)
Block(3,12,-7,biomesoplenty:leaves_4:15)
Block(3,12,-6,biomesoplenty:leaves_4:15)
Block(3,12,-4,biomesoplenty:leaves_4:15)
Block(3,12,-1,biomesoplenty:leaves_4:15)
Block(3,12,0,biomesoplenty:leaves_4:15)
Block(3,12,1,biomesoplenty:log_2:13)
Block(3,12,2,biomesoplenty:log_2:13)
Block(3,12,3,biomesoplenty:log_2:13)
Block(3,12,4,biomesoplenty:leaves_4:15)
Block(3,12,6,biomesoplenty:leaves_4:15)
Block(3,12,8,biomesoplenty:leaves_4:15)
Block(3,13,-7,biomesoplenty:leaves_4:15)
Block(3,13,-6,biomesoplenty:leaves_4:15)
Block(3,13,-5,biomesoplenty:leaves_4:15)
Block(3,13,-4,biomesoplenty:leaves_4:15)
Block(3,13,-3,biomesoplenty:leaves_4:15)
Block(3,13,-2,biomesoplenty:leaves_4:15)
Block(3,13,-1,biomesoplenty:leaves_4:15)
Block(3,13,0,biomesoplenty:leaves_4:15)
Block(3,13,1,biomesoplenty:log_2:13)
Block(3,13,2,biomesoplenty:log_2:13)
Block(3,13,3,biomesoplenty:log_2:13)
Block(3,13,4,biomesoplenty:leaves_4:15)
Block(3,13,6,biomesoplenty:leaves_4:15)
Block(3,13,8,biomesoplenty:leaves_4:15)
Block(3,13,9,biomesoplenty:leaves_4:15)
Block(3,14,-7,biomesoplenty:leaves_4:15)
Block(3,14,-6,biomesoplenty:leaves_4:15)
Block(3,14,-5,biomesoplenty:leaves_4:15)
Block(3,14,-4,biomesoplenty:leaves_4:15)
Block(3,14,-3,biomesoplenty:leaves_4:15)
Block(3,14,-2,biomesoplenty:log_2:9)
Block(3,14,-1,biomesoplenty:log_2:9)
Block(3,14,0,biomesoplenty:log_2:13)
Block(3,14,1,biomesoplenty:log_2:13)
Block(3,14,2,biomesoplenty:log_2:13)
Block(3,14,3,biomesoplenty:log_2:13)
Block(3,14,4,biomesoplenty:leaves_4:15)
Block(3,14,7,biomesoplenty:leaves_4:15)
Block(3,14,8,biomesoplenty:leaves_4:15)
Block(3,14,9,biomesoplenty:leaves_4:15)
Block(3,15,-7,biomesoplenty:leaves_4:15)
Block(3,15,-6,biomesoplenty:leaves_4:15)
Block(3,15,-5,biomesoplenty:leaves_4:15)
Block(3,15,-4,biomesoplenty:leaves_4:15)
Block(3,15,-3,biomesoplenty:leaves_4:15)
Block(3,15,-2,biomesoplenty:leaves_4:15)
Block(3,15,-1,biomesoplenty:leaves_4:15)
Block(3,15,0,biomesoplenty:log_2:13)
Block(3,15,1,biomesoplenty:log_2:13)
Block(3,15,2,biomesoplenty:log_2:13)
Block(3,15,7,biomesoplenty:leaves_4:15)
Block(3,15,8,biomesoplenty:leaves_4:15)
Block(3,15,9,biomesoplenty:leaves_4:15)
Block(3,16,-7,biomesoplenty:leaves_4:15)
Block(3,16,-6,biomesoplenty:leaves_4:15)
Block(3,16,-5,biomesoplenty:leaves_4:15)
Block(3,16,-4,biomesoplenty:leaves_4:15)
Block(3,16,-2,biomesoplenty:leaves_4:15)
Block(3,16,-1,biomesoplenty:leaves_4:15)
Block(3,16,0,biomesoplenty:log_2:13)
Block(3,16,1,biomesoplenty:log_2:13)
Block(3,16,2,biomesoplenty:log_2:13)
Block(3,16,6,biomesoplenty:leaves_4:15)
Block(3,16,7,biomesoplenty:leaves_4:15)
Block(3,16,8,biomesoplenty:leaves_4:15)
Block(3,16,9,biomesoplenty:leaves_4:15)
Block(3,17,-5,biomesoplenty:leaves_4:15)
Block(3,17,-4,biomesoplenty:leaves_4:15)
Block(3,17,-3,biomesoplenty:leaves_4:15)
Block(3,17,-2,biomesoplenty:leaves_4:15)
Block(3,17,-1,biomesoplenty:log_2:13)
Block(3,17,0,biomesoplenty:log_2:13)
Block(3,17,1,biomesoplenty:log_2:13)
Block(3,17,5,biomesoplenty:leaves_4:15)
Block(3,17,6,biomesoplenty:leaves_4:15)
Block(3,17,7,biomesoplenty:leaves_4:15)
Block(3,17,8,biomesoplenty:leaves_4:15)
Block(3,18,-5,biomesoplenty:leaves_4:15)
Block(3,18,-4,biomesoplenty:leaves_4:15)
Block(3,18,-3,biomesoplenty:log_2:9)
Block(3,18,-2,biomesoplenty:log_2:9)
Block(3,18,-1,biomesoplenty:log_2:13)
Block(3,18,0,biomesoplenty:log_2:13)
Block(3,18,1,biomesoplenty:log_2:13)
Block(3,18,2,biomesoplenty:leaves_4:15)
Block(3,18,3,biomesoplenty:leaves_4:15)
Block(3,18,4,biomesoplenty:leaves_4:15)
Block(3,18,5,biomesoplenty:leaves_4:15)
Block(3,18,6,biomesoplenty:leaves_4:15)
Block(3,18,7,biomesoplenty:leaves_4:15)
Block(3,19,-4,biomesoplenty:leaves_4:15)
Block(3,19,-3,biomesoplenty:leaves_4:15)
Block(3,19,-2,biomesoplenty:leaves_4:15)
Block(3,19,-1,biomesoplenty:leaves_4:15)
Block(3,19,0,biomesoplenty:log_2:13)
Block(3,19,1,biomesoplenty:log_2:9)
Block(3,19,2,biomesoplenty:log_2:9)
Block(3,19,3,biomesoplenty:leaves_4:15)
Block(3,19,4,biomesoplenty:leaves_4:15)
Block(3,19,5,biomesoplenty:leaves_4:15)
Block(3,19,6,biomesoplenty:leaves_4:15)
Block(3,19,7,biomesoplenty:log_2:13)
Block(3,19,8,biomesoplenty:leaves_4:15)
Block(3,19,9,biomesoplenty:leaves_4:15)
Block(3,20,-1,biomesoplenty:leaves_4:15)
Block(3,20,0,biomesoplenty:leaves_4:15)
Block(3,20,1,biomesoplenty:leaves_4:15)
Block(3,20,2,biomesoplenty:log_2:5)
Block(3,20,3,biomesoplenty:log_2:9)
Block(3,20,4,biomesoplenty:leaves_4:15)
Block(3,20,5,biomesoplenty:leaves_4:15)
Block(3,20,6,biomesoplenty:leaves_4:15)
Block(3,20,7,biomesoplenty:leaves_4:15)
Block(3,20,8,biomesoplenty:leaves_4:15)
Block(3,20,9,biomesoplenty:leaves_4:15)
Block(3,21,2,biomesoplenty:leaves_4:15)
Block(3,21,3,biomesoplenty:leaves_4:15)
Block(3,21,4,biomesoplenty:leaves_4:15)
Block(3,21,7,biomesoplenty:leaves_4:15)
Block(3,21,8,biomesoplenty:leaves_4:15)
Block(3,21,9,biomesoplenty:leaves_4:15)
Block(4,8,-1,biomesoplenty:leaves_4:15)
Block(4,8,3,biomesoplenty:leaves_4:15)
Block(4,9,-6,biomesoplenty:leaves_4:15)
Block(4,9,-1,biomesoplenty:leaves_4:15)
Block(4,9,0,biomesoplenty:leaves_4:15)
Block(4,9,2,biomesoplenty:leaves_4:15)
Block(4,9,3,biomesoplenty:leaves_4:15)
Block(4,9,4,biomesoplenty:leaves_4:15)
Block(4,10,-6,biomesoplenty:leaves_4:15)
Block(4,10,-2,biomesoplenty:leaves_4:15)
Block(4,10,-1,biomesoplenty:leaves_4:15)
Block(4,10,0,biomesoplenty:leaves_4:15)
Block(4,10,1,biomesoplenty:log_2:1)
Block(4,10,2,biomesoplenty:log_2:9)
Block(4,10,3,biomesoplenty:leaves_4:15)
Block(4,10,4,biomesoplenty:leaves_4:15)
Block(4,11,-7,biomesoplenty:leaves_4:15)
Block(4,11,-6,biomesoplenty:leaves_4:15)
Block(4,11,-1,biomesoplenty:leaves_4:15)
Block(4,11,0,biomesoplenty:leaves_4:15)
Block(4,11,1,biomesoplenty:log_2:5)
Block(4,11,2,biomesoplenty:log_2:13)
Block(4,11,3,biomesoplenty:leaves_4:15)
Block(4,11,4,biomesoplenty:leaves_4:15)
Block(4,11,5,biomesoplenty:leaves_4:15)
Block(4,11,6,biomesoplenty:leaves_4:15)
Block(4,11,8,biomesoplenty:leaves_4:15)
Block(4,12,-7,biomesoplenty:leaves_4:15)
Block(4,12,-6,biomesoplenty:leaves_4:15)
Block(4,12,-5,biomesoplenty:leaves_4:15)
Block(4,12,0,biomesoplenty:leaves_4:15)
Block(4,12,1,biomesoplenty:log_2:13)
Block(4,12,2,biomesoplenty:log_2:13)
Block(4,12,3,biomesoplenty:log_2:13)
Block(4,12,4,biomesoplenty:leaves_4:15)
Block(4,12,5,biomesoplenty:leaves_4:15)
Block(4,12,6,biomesoplenty:leaves_4:15)
Block(4,12,7,biomesoplenty:leaves_4:15)
Block(4,12,8,biomesoplenty:leaves_4:15)
Block(4,12,9,biomesoplenty:leaves_4:15)
Block(4,13,-7,biomesoplenty:leaves_4:15)
Block(4,13,-6,biomesoplenty:leaves_4:15)
Block(4,13,-5,biomesoplenty:leaves_4:15)
Block(4,13,-4,biomesoplenty:leaves_4:15)
Block(4,13,-3,biomesoplenty:leaves_4:15)
Block(4,13,-2,biomesoplenty:leaves_4:15)
Block(4,13,0,biomesoplenty:leaves_4:15)
Block(4,13,1,biomesoplenty:leaves_4:15)
Block(4,13,2,biomesoplenty:log_2:13)
Block(4,13,3,biomesoplenty:leaves_4:15)
Block(4,13,4,biomesoplenty:leaves_4:15)
Block(4,13,5,biomesoplenty:leaves_4:15)
Block(4,13,6,biomesoplenty:leaves_4:15)
Block(4,13,7,biomesoplenty:leaves_4:15)
Block(4,13,8,biomesoplenty:leaves_4:15)
Block(4,13,9,biomesoplenty:leaves_4:15)
Block(4,13,10,biomesoplenty:leaves_4:15)
Block(4,14,-6,biomesoplenty:leaves_4:15)
Block(4,14,-5,biomesoplenty:leaves_4:15)
Block(4,14,-4,biomesoplenty:leaves_4:15)
Block(4,14,-3,biomesoplenty:log_2:9)
Block(4,14,-2,biomesoplenty:log_2:13)
Block(4,14,-1,biomesoplenty:leaves_4:15)
Block(4,14,0,biomesoplenty:leaves_4:15)
Block(4,14,1,biomesoplenty:log_2:13)
Block(4,14,2,biomesoplenty:log_2:13)
Block(4,14,3,biomesoplenty:leaves_4:15)
Block(4,14,4,biomesoplenty:leaves_4:15)
Block(4,14,5,biomesoplenty:log_2:13)
Block(4,14,6,biomesoplenty:log_2:9)
Block(4,14,7,biomesoplenty:log_2:9)
Block(4,14,8,biomesoplenty:log_2:9)
Block(4,14,9,biomesoplenty:leaves_4:15)
Block(4,15,-5,biomesoplenty:leaves_4:15)
Block(4,15,-4,biomesoplenty:leaves_4:15)
Block(4,15,-3,biomesoplenty:leaves_4:15)
Block(4,15,-2,biomesoplenty:leaves_4:15)
Block(4,15,-1,biomesoplenty:leaves_4:15)
Block(4,15,0,biomesoplenty:leaves_4:15)
Block(4,15,1,biomesoplenty:log_2:13)
Block(4,15,2,biomesoplenty:log_2:13)
Block(4,15,7,biomesoplenty:leaves_4:15)
Block(4,15,8,biomesoplenty:leaves_4:15)
Block(4,15,9,biomesoplenty:leaves_4:15)
Block(4,16,-5,biomesoplenty:leaves_4:15)
Block(4,16,-2,biomesoplenty:leaves_4:15)
Block(4,16,-1,biomesoplenty:leaves_4:15)
Block(4,16,0,biomesoplenty:log_2:13)
Block(4,16,1,biomesoplenty:log_2:13)
Block(4,16,2,biomesoplenty:log_2:13)
Block(4,16,3,biomesoplenty:log_2:13)
Block(4,16,5,biomesoplenty:leaves_4:15)
Block(4,16,6,biomesoplenty:leaves_4:15)
Block(4,16,7,biomesoplenty:leaves_4:15)
Block(4,16,8,biomesoplenty:leaves_4:15)
Block(4,16,9,biomesoplenty:leaves_4:15)
Block(4,17,-4,biomesoplenty:leaves_4:15)
Block(4,17,-3,biomesoplenty:leaves_4:15)
Block(4,17,-2,biomesoplenty:leaves_4:15)
Block(4,17,-1,biomesoplenty:leaves_4:15)
Block(4,17,0,biomesoplenty:log_2:13)
Block(4,17,1,biomesoplenty:log_2:13)
Block(4,17,2,biomesoplenty:log_2:13)
Block(4,17,5,biomesoplenty:leaves_4:15)
Block(4,17,6,biomesoplenty:leaves_4:15)
Block(4,17,7,biomesoplenty:leaves_4:15)
Block(4,17,8,biomesoplenty:leaves_4:15)
Block(4,18,-4,biomesoplenty:leaves_4:15)
Block(4,18,-3,biomesoplenty:leaves_4:15)
Block(4,18,-1,biomesoplenty:leaves_4:15)
Block(4,18,0,biomesoplenty:log_2:13)
Block(4,18,1,biomesoplenty:leaves_4:15)
Block(4,18,2,biomesoplenty:leaves_4:15)
Block(4,18,3,biomesoplenty:leaves_4:15)
Block(4,18,4,biomesoplenty:leaves_4:15)
Block(4,18,5,biomesoplenty:leaves_4:15)
Block(4,18,6,biomesoplenty:leaves_4:15)
Block(4,18,7,biomesoplenty:leaves_4:15)
Block(4,18,8,biomesoplenty:leaves_4:15)
Block(4,19,-4,biomesoplenty:leaves_4:15)
Block(4,19,-3,biomesoplenty:leaves_4:15)
Block(4,19,-2,biomesoplenty:leaves_4:15)
Block(4,19,-1,biomesoplenty:leaves_4:15)
Block(4,19,0,biomesoplenty:leaves_4:15)
Block(4,19,1,biomesoplenty:leaves_4:15)
Block(4,19,2,biomesoplenty:log_2:13)
Block(4,19,3,biomesoplenty:leaves_4:15)
Block(4,19,4,biomesoplenty:leaves_4:15)
Block(4,19,5,biomesoplenty:log_2:13)
Block(4,19,6,biomesoplenty:log_2:9)
Block(4,19,7,biomesoplenty:log_2:9)
Block(4,19,8,biomesoplenty:log_2:9)
Block(4,19,9,biomesoplenty:leaves_4:15)
Block(4,20,-2,biomesoplenty:leaves_4:15)
Block(4,20,-1,biomesoplenty:leaves_4:15)
Block(4,20,0,biomesoplenty:leaves_4:15)
Block(4,20,1,biomesoplenty:leaves_4:15)
Block(4,20,2,biomesoplenty:leaves_4:15)
Block(4,20,3,biomesoplenty:leaves_4:15)
Block(4,20,4,biomesoplenty:leaves_4:15)
Block(4,20,5,biomesoplenty:leaves_4:15)
Block(4,20,7,biomesoplenty:leaves_4:15)
Block(4,20,8,biomesoplenty:leaves_4:15)
Block(4,21,3,biomesoplenty:leaves_4:15)
Block(4,21,5,biomesoplenty:leaves_4:15)
Block(4,21,7,biomesoplenty:leaves_4:15)
Block(4,21,8,biomesoplenty:leaves_4:15)
Block(4,21,9,biomesoplenty:leaves_4:15)
Block(5,7,8,biomesoplenty:leaves_4:15)
Block(5,8,-6,biomesoplenty:leaves_4:15)
Block(5,8,8,biomesoplenty:leaves_4:15)
Block(5,9,-6,biomesoplenty:leaves_4:15)
Block(5,9,-5,biomesoplenty:leaves_4:15)
Block(5,9,-4,biomesoplenty:leaves_4:15)
Block(5,9,-1,biomesoplenty:leaves_4:15)
Block(5,9,2,biomesoplenty:log_2:5)
Block(5,9,3,biomesoplenty:leaves_4:15)
Block(5,9,8,biomesoplenty:leaves_4:15)
Block(5,10,-7,biomesoplenty:leaves_4:15)
Block(5,10,-6,biomesoplenty:leaves_4:15)
Block(5,10,-4,biomesoplenty:leaves_4:15)
Block(5,10,-1,biomesoplenty:leaves_4:15)
Block(5,10,1,biomesoplenty:log_2:1)
Block(5,10,2,biomesoplenty:log_2:9)
Block(5,10,3,biomesoplenty:leaves_4:15)
Block(5,10,8,biomesoplenty:leaves_4:15)
Block(5,11,-7,biomesoplenty:leaves_4:15)
Block(5,11,-6,biomesoplenty:leaves_4:15)
Block(5,11,-5,biomesoplenty:leaves_4:15)
Block(5,11,-4,biomesoplenty:leaves_4:15)
Block(5,11,3,biomesoplenty:leaves_4:15)
Block(5,11,4,biomesoplenty:leaves_4:15)
Block(5,11,6,biomesoplenty:leaves_4:15)
Block(5,11,8,biomesoplenty:leaves_4:15)
Block(5,11,9,biomesoplenty:leaves_4:15)
Block(5,12,-6,biomesoplenty:leaves_4:15)
Block(5,12,-4,biomesoplenty:leaves_4:15)
Block(5,12,3,biomesoplenty:leaves_4:15)
Block(5,12,4,biomesoplenty:leaves_4:15)
Block(5,12,5,biomesoplenty:leaves_4:15)
Block(5,12,6,biomesoplenty:leaves_4:15)
Block(5,12,7,biomesoplenty:leaves_4:15)
Block(5,12,8,biomesoplenty:leaves_4:15)
Block(5,12,9,biomesoplenty:leaves_4:15)
Block(5,12,10,biomesoplenty:leaves_4:15)
Block(5,13,-6,biomesoplenty:leaves_4:15)
Block(5,13,-5,biomesoplenty:leaves_4:15)
Block(5,13,-4,biomesoplenty:leaves_4:15)
Block(5,13,-3,biomesoplenty:leaves_4:15)
Block(5,13,0,biomesoplenty:leaves_4:15)
Block(5,13,1,biomesoplenty:leaves_4:15)
Block(5,13,2,biomesoplenty:leaves_4:15)
Block(5,13,3,biomesoplenty:leaves_4:15)
Block(5,13,4,biomesoplenty:leaves_4:15)
Block(5,13,5,biomesoplenty:leaves_4:15)
Block(5,13,6,biomesoplenty:leaves_4:15)
Block(5,13,7,biomesoplenty:leaves_4:15)
Block(5,13,8,biomesoplenty:leaves_4:15)
Block(5,13,9,biomesoplenty:leaves_4:15)
Block(5,14,-5,biomesoplenty:leaves_4:15)
Block(5,14,-4,biomesoplenty:leaves_4:15)
Block(5,14,-3,biomesoplenty:leaves_4:15)
Block(5,14,-1,biomesoplenty:leaves_4:15)
Block(5,14,0,biomesoplenty:leaves_4:15)
Block(5,14,1,biomesoplenty:leaves_4:15)
Block(5,14,2,biomesoplenty:log_2:13)
Block(5,14,3,biomesoplenty:log_2:9)
Block(5,14,4,biomesoplenty:log_2:9)
Block(5,14,5,biomesoplenty:log_2:9)
Block(5,14,6,biomesoplenty:leaves_4:15)
Block(5,14,7,biomesoplenty:leaves_4:15)
Block(5,14,8,biomesoplenty:log_2:13)
Block(5,14,9,biomesoplenty:leaves_4:15)
Block(5,15,-4,biomesoplenty:leaves_4:15)
Block(5,15,-3,biomesoplenty:leaves_4:15)
Block(5,15,-2,biomesoplenty:leaves_4:15)
Block(5,15,-1,biomesoplenty:leaves_4:15)
Block(5,15,0,biomesoplenty:log_2:13)
Block(5,15,1,biomesoplenty:log_2:13)
Block(5,15,2,biomesoplenty:leaves_4:15)
Block(5,15,3,biomesoplenty:leaves_4:15)
Block(5,15,4,biomesoplenty:leaves_4:15)
Block(5,15,5,biomesoplenty:leaves_4:15)
Block(5,15,6,biomesoplenty:leaves_4:15)
Block(5,15,7,biomesoplenty:leaves_4:15)
Block(5,15,8,biomesoplenty:leaves_4:15)
Block(5,15,9,biomesoplenty:leaves_4:15)
Block(5,16,-4,biomesoplenty:leaves_4:15)
Block(5,16,-3,biomesoplenty:leaves_4:15)
Block(5,16,-2,biomesoplenty:leaves_4:15)
Block(5,16,-1,biomesoplenty:log_2:13)
Block(5,16,0,biomesoplenty:log_2:13)
Block(5,16,1,biomesoplenty:log_2:13)
Block(5,16,2,biomesoplenty:log_2:13)
Block(5,16,4,biomesoplenty:log_2:13)
Block(5,16,6,biomesoplenty:leaves_4:15)
Block(5,16,7,biomesoplenty:leaves_4:15)
Block(5,16,8,biomesoplenty:leaves_4:15)
Block(5,17,-4,biomesoplenty:leaves_4:15)
Block(5,17,-3,biomesoplenty:leaves_4:15)
Block(5,17,-2,biomesoplenty:leaves_4:15)
Block(5,17,-1,biomesoplenty:leaves_4:15)
Block(5,17,0,biomesoplenty:log_2:13)
Block(5,17,1,biomesoplenty:leaves_4:15)
Block(5,17,2,biomesoplenty:log_2:13)
Block(5,17,3,biomesoplenty:log_2:13)
Block(5,17,4,biomesoplenty:log_2:13)
Block(5,17,5,biomesoplenty:leaves_4:15)
Block(5,17,6,biomesoplenty:leaves_4:15)
Block(5,17,7,biomesoplenty:leaves_4:15)
Block(5,17,8,biomesoplenty:leaves_4:15)
Block(5,18,-4,biomesoplenty:leaves_4:15)
Block(5,18,-3,biomesoplenty:leaves_4:15)
Block(5,18,-2,biomesoplenty:leaves_4:15)
Block(5,18,-1,biomesoplenty:leaves_4:15)
Block(5,18,0,biomesoplenty:leaves_4:15)
Block(5,18,1,biomesoplenty:leaves_4:15)
Block(5,18,2,biomesoplenty:leaves_4:15)
Block(5,18,5,biomesoplenty:log_2:13)
Block(5,18,6,biomesoplenty:leaves_4:15)
Block(5,18,7,biomesoplenty:leaves_4:15)
Block(5,19,-4,biomesoplenty:leaves_4:15)
Block(5,19,-3,biomesoplenty:leaves_4:15)
Block(5,19,-2,biomesoplenty:leaves_4:15)
Block(5,19,-1,biomesoplenty:leaves_4:15)
Block(5,19,0,biomesoplenty:leaves_4:15)
Block(5,19,1,biomesoplenty:leaves_4:15)
Block(5,19,2,biomesoplenty:leaves_4:15)
Block(5,19,3,biomesoplenty:leaves_4:15)
Block(5,19,4,biomesoplenty:leaves_4:15)
Block(5,19,5,biomesoplenty:log_2:5)
Block(5,19,6,biomesoplenty:leaves_4:15)
Block(5,19,7,biomesoplenty:leaves_4:15)
Block(5,19,8,biomesoplenty:leaves_4:15)
Block(5,20,-1,biomesoplenty:leaves_4:15)
Block(5,20,2,biomesoplenty:leaves_4:15)
Block(5,20,4,biomesoplenty:leaves_4:15)
Block(5,20,5,biomesoplenty:log_2:5)
Block(5,20,6,biomesoplenty:leaves_4:15)
Block(5,20,7,biomesoplenty:leaves_4:15)
Block(5,20,8,biomesoplenty:leaves_4:15)
Block(5,21,4,biomesoplenty:leaves_4:15)
Block(5,21,5,biomesoplenty:log_2:5)
Block(5,21,6,biomesoplenty:leaves_4:15)
Block(5,21,8,biomesoplenty:leaves_4:15)
Block(5,22,5,biomesoplenty:leaves_4:15)
Block(6,6,8,biomesoplenty:leaves_4:15)
Block(6,7,7,biomesoplenty:leaves_4:15)
Block(6,7,8,biomesoplenty:leaves_4:15)
Block(6,7,9,biomesoplenty:leaves_4:15)
Block(6,8,-4,biomesoplenty:leaves_4:15)
Block(6,8,7,biomesoplenty:leaves_4:15)
Block(6,8,8,biomesoplenty:leaves_4:15)
Block(6,8,9,biomesoplenty:leaves_4:15)
Block(6,9,-6,biomesoplenty:leaves_4:15)
Block(6,9,-5,biomesoplenty:leaves_4:15)
Block(6,9,-4,biomesoplenty:leaves_4:15)
Block(6,9,-3,biomesoplenty:leaves_4:15)
Block(6,9,2,biomesoplenty:leaves_4:15)
Block(6,9,8,biomesoplenty:leaves_4:15)
Block(6,9,9,biomesoplenty:leaves_4:15)
Block(6,10,-6,biomesoplenty:leaves_4:15)
Block(6,10,-5,biomesoplenty:leaves_4:15)
Block(6,10,-4,biomesoplenty:leaves_4:15)
Block(6,10,-3,biomesoplenty:leaves_4:15)
Block(6,10,1,biomesoplenty:leaves_4:15)
Block(6,10,2,biomesoplenty:log_2:1)
Block(6,10,3,biomesoplenty:leaves_4:15)
Block(6,10,7,biomesoplenty:leaves_4:15)
Block(6,10,8,biomesoplenty:leaves_4:15)
Block(6,10,9,biomesoplenty:leaves_4:15)
Block(6,11,-6,biomesoplenty:leaves_4:15)
Block(6,11,-5,biomesoplenty:leaves_4:15)
Block(6,11,-4,biomesoplenty:leaves_4:15)
Block(6,11,-3,biomesoplenty:leaves_4:15)
Block(6,11,2,biomesoplenty:leaves_4:15)
Block(6,11,7,biomesoplenty:leaves_4:15)
Block(6,11,8,biomesoplenty:leaves_4:15)
Block(6,11,9,biomesoplenty:leaves_4:15)
Block(6,12,-5,biomesoplenty:leaves_4:15)
Block(6,12,-4,biomesoplenty:leaves_4:15)
Block(6,12,-3,biomesoplenty:leaves_4:15)
Block(6,12,4,biomesoplenty:leaves_4:15)
Block(6,12,6,biomesoplenty:leaves_4:15)
Block(6,12,7,biomesoplenty:leaves_4:15)
Block(6,12,8,biomesoplenty:leaves_4:15)
Block(6,12,9,biomesoplenty:leaves_4:15)
Block(6,13,-6,biomesoplenty:leaves_4:15)
Block(6,13,-5,biomesoplenty:leaves_4:15)
Block(6,13,-4,biomesoplenty:leaves_4:15)
Block(6,13,-3,biomesoplenty:leaves_4:15)
Block(6,13,3,biomesoplenty:leaves_4:15)
Block(6,13,5,biomesoplenty:leaves_4:15)
Block(6,13,6,biomesoplenty:leaves_4:15)
Block(6,13,8,biomesoplenty:leaves_4:15)
Block(6,14,-5,biomesoplenty:leaves_4:15)
Block(6,14,-4,biomesoplenty:leaves_4:15)
Block(6,14,-3,biomesoplenty:leaves_4:15)
Block(6,14,-2,biomesoplenty:leaves_4:15)
Block(6,14,2,biomesoplenty:leaves_4:15)
Block(6,14,3,biomesoplenty:leaves_4:15)
Block(6,14,4,biomesoplenty:log_2:13)
Block(6,14,5,biomesoplenty:leaves_4:15)
Block(6,14,6,biomesoplenty:leaves_4:15)
Block(6,14,7,biomesoplenty:leaves_4:15)
Block(6,14,8,biomesoplenty:leaves_4:15)
Block(6,14,9,biomesoplenty:leaves_4:15)
Block(6,15,-5,biomesoplenty:leaves_4:15)
Block(6,15,-4,biomesoplenty:leaves_4:15)
Block(6,15,-3,biomesoplenty:leaves_4:15)
Block(6,15,-2,biomesoplenty:leaves_4:15)
Block(6,15,-1,biomesoplenty:leaves_4:15)
Block(6,15,0,biomesoplenty:log_2:13)
Block(6,15,1,biomesoplenty:leaves_4:15)
Block(6,15,2,biomesoplenty:leaves_4:15)
Block(6,15,5,biomesoplenty:leaves_4:15)
Block(6,15,6,biomesoplenty:leaves_4:15)
Block(6,15,8,biomesoplenty:leaves_4:15)
Block(6,16,-5,biomesoplenty:leaves_4:15)
Block(6,16,-4,biomesoplenty:leaves_4:15)
Block(6,16,-3,biomesoplenty:leaves_4:15)
Block(6,16,-2,biomesoplenty:leaves_4:15)
Block(6,16,-1,biomesoplenty:log_2:13)
Block(6,16,0,biomesoplenty:log_2:13)
Block(6,16,1,biomesoplenty:log_2:13)
Block(6,16,2,biomesoplenty:leaves_4:15)
Block(6,16,3,biomesoplenty:leaves_4:15)
Block(6,16,4,biomesoplenty:log_2:13)
Block(6,16,6,biomesoplenty:leaves_4:15)
Block(6,17,-4,biomesoplenty:leaves_4:15)
Block(6,17,-3,biomesoplenty:leaves_4:15)
Block(6,17,-2,biomesoplenty:leaves_4:15)
Block(6,17,-1,biomesoplenty:log_2:13)
Block(6,17,0,biomesoplenty:log_2:13)
Block(6,17,1,biomesoplenty:leaves_4:15)
Block(6,17,2,biomesoplenty:leaves_4:15)
Block(6,17,3,biomesoplenty:log_2:13)
Block(6,17,4,biomesoplenty:log_2:13)
Block(6,17,5,biomesoplenty:log_2:13)
Block(6,17,6,biomesoplenty:leaves_4:15)
Block(6,17,7,biomesoplenty:leaves_4:15)
Block(6,18,-4,biomesoplenty:leaves_4:15)
Block(6,18,-3,biomesoplenty:leaves_4:15)
Block(6,18,-2,biomesoplenty:leaves_4:15)
Block(6,18,-1,biomesoplenty:leaves_4:15)
Block(6,18,0,biomesoplenty:leaves_4:15)
Block(6,18,1,biomesoplenty:leaves_4:15)
Block(6,18,4,biomesoplenty:log_2:13)
Block(6,18,5,biomesoplenty:log_2:9)
Block(6,18,6,biomesoplenty:leaves_4:15)
Block(6,18,7,biomesoplenty:leaves_4:15)
Block(6,19,-3,biomesoplenty:leaves_4:15)
Block(6,19,0,biomesoplenty:leaves_4:15)
Block(6,19,4,biomesoplenty:leaves_4:15)
Block(6,19,5,biomesoplenty:leaves_4:15)
Block(6,19,6,biomesoplenty:leaves_4:15)
Block(6,19,7,biomesoplenty:leaves_4:15)
Block(6,20,5,biomesoplenty:leaves_4:15)
Block(6,20,6,biomesoplenty:leaves_4:15)
Block(6,20,7,biomesoplenty:leaves_4:15)
Block(6,21,4,biomesoplenty:leaves_4:15)
Block(6,21,5,biomesoplenty:leaves_4:15)
Block(6,21,6,biomesoplenty:leaves_4:15)
Block(7,7,8,biomesoplenty:leaves_4:15)
Block(7,8,8,biomesoplenty:leaves_4:15)
Block(7,9,-4,biomesoplenty:leaves_4:15)
Block(7,9,8,biomesoplenty:leaves_4:15)
Block(7,10,-4,biomesoplenty:leaves_4:15)
Block(7,10,2,biomesoplenty:leaves_4:15)
Block(7,10,8,biomesoplenty:leaves_4:15)
Block(7,10,9,biomesoplenty:leaves_4:15)
Block(7,11,-4,biomesoplenty:leaves_4:15)
Block(7,11,7,biomesoplenty:leaves_4:15)
Block(7,11,8,biomesoplenty:leaves_4:15)
Block(7,11,9,biomesoplenty:leaves_4:15)
Block(7,11,10,biomesoplenty:leaves_4:15)
Block(7,12,-4,biomesoplenty:leaves_4:15)
Block(7,12,7,biomesoplenty:leaves_4:15)
Block(7,12,8,biomesoplenty:leaves_4:15)
Block(7,12,9,biomesoplenty:leaves_4:15)
Block(7,13,-5,biomesoplenty:leaves_4:15)
Block(7,13,-4,biomesoplenty:leaves_4:15)
Block(7,13,8,biomesoplenty:leaves_4:15)
Block(7,15,-4,biomesoplenty:leaves_4:15)
Block(7,15,-2,biomesoplenty:leaves_4:15)
Block(7,15,0,biomesoplenty:leaves_4:15)
Block(7,15,1,biomesoplenty:leaves_4:15)
Block(7,16,-4,biomesoplenty:leaves_4:15)
Block(7,16,-3,biomesoplenty:leaves_4:15)
Block(7,16,-2,biomesoplenty:leaves_4:15)
Block(7,16,-1,biomesoplenty:log_2:9)
Block(7,16,0,biomesoplenty:log_2:13)
Block(7,16,1,biomesoplenty:leaves_4:15)
Block(7,16,2,biomesoplenty:leaves_4:15)
Block(7,16,3,biomesoplenty:leaves_4:15)
Block(7,16,4,biomesoplenty:leaves_4:15)
Block(7,16,5,biomesoplenty:leaves_4:15)
Block(7,16,6,biomesoplenty:leaves_4:15)
Block(7,16,7,biomesoplenty:leaves_4:15)
Block(7,17,-4,biomesoplenty:leaves_4:15)
Block(7,17,-3,biomesoplenty:leaves_4:15)
Block(7,17,-2,biomesoplenty:leaves_4)
Block(7,17,-1,biomesoplenty:log_2:9)
Block(7,17,0,biomesoplenty:log_2:5)
Block(7,17,1,biomesoplenty:leaves_4:15)
Block(7,17,2,biomesoplenty:leaves_4:15)
Block(7,17,3,biomesoplenty:log_2:13)
Block(7,17,4,biomesoplenty:log_2:13)
Block(7,17,5,biomesoplenty:log_2:13)
Block(7,17,6,biomesoplenty:log_2:13)
Block(7,17,7,biomesoplenty:leaves_4:15)
Block(7,18,-4,biomesoplenty:leaves_4:15)
Block(7,18,-3,biomesoplenty:leaves_4:15)
Block(7,18,-2,biomesoplenty:leaves_4:15)
Block(7,18,-1,biomesoplenty:leaves_4:15)
Block(7,18,0,biomesoplenty:log_2:5)
Block(7,18,1,biomesoplenty:leaves_4:15)
Block(7,18,2,biomesoplenty:leaves_4:15)
Block(7,18,3,biomesoplenty:leaves_4:15)
Block(7,18,4,biomesoplenty:log_2:13)
Block(7,18,5,biomesoplenty:log_2:13)
Block(7,18,6,biomesoplenty:log_2:13)
Block(7,18,7,biomesoplenty:leaves_4:15)
Block(7,19,-3,biomesoplenty:leaves_4:15)
Block(7,19,-2,biomesoplenty:leaves_4:15)
Block(7,19,-1,biomesoplenty:leaves_4:15)
Block(7,19,0,biomesoplenty:leaves_4:15)
Block(7,19,1,biomesoplenty:leaves_4:15)
Block(7,19,5,biomesoplenty:leaves_4:15)
Block(7,19,6,biomesoplenty:leaves_4:15)
Block(7,19,7,biomesoplenty:leaves_4:15)
Block(7,20,6,biomesoplenty:leaves_4:15)
Block(8,9,8,biomesoplenty:leaves_4:15)
Block(8,10,-1,biomesoplenty:leaves_4:15)
Block(8,10,3,biomesoplenty:leaves_4:15)
Block(8,10,7,biomesoplenty:leaves_4:15)
Block(8,10,8,biomesoplenty:leaves_4:15)
Block(8,11,-2,biomesoplenty:leaves_4:15)
Block(8,11,-1,biomesoplenty:leaves_4:15)
Block(8,11,0,biomesoplenty:leaves_4:15)
Block(8,11,7,biomesoplenty:leaves_4:15)
Block(8,11,8,biomesoplenty:leaves_4:15)
Block(8,11,9,biomesoplenty:leaves_4:15)
Block(8,12,-1,biomesoplenty:leaves_4:15)
Block(8,12,5,biomesoplenty:leaves_4:15)
Block(8,12,6,biomesoplenty:leaves_4:15)
Block(8,12,8,biomesoplenty:leaves_4:15)
Block(8,13,-1,biomesoplenty:leaves_4:15)
Block(8,13,5,biomesoplenty:leaves_4:15)
Block(8,14,-1,biomesoplenty:leaves_4:15)
Block(8,14,0,biomesoplenty:leaves_4:15)
Block(8,14,5,biomesoplenty:leaves_4:15)
Block(8,14,7,biomesoplenty:leaves_4:15)
Block(8,15,-1,biomesoplenty:leaves_4:15)
Block(8,15,0,biomesoplenty:leaves_4:15)
Block(8,15,2,biomesoplenty:leaves_4:15)
Block(8,15,4,biomesoplenty:leaves_4:15)
Block(8,15,5,biomesoplenty:leaves_4:15)
Block(8,15,6,biomesoplenty:leaves_4:15)
Block(8,15,7,biomesoplenty:leaves_4:15)
Block(8,15,8,biomesoplenty:leaves_4:15)
Block(8,16,-2,biomesoplenty:leaves_4)
Block(8,16,-1,biomesoplenty:log_2:13)
Block(8,16,0,biomesoplenty:leaves_4:15)
Block(8,16,1,biomesoplenty:leaves_4:15)
Block(8,16,2,biomesoplenty:leaves_4:15)
Block(8,16,3,biomesoplenty:leaves_4:15)
Block(8,16,6,biomesoplenty:leaves_4:15)
Block(8,16,7,biomesoplenty:leaves_4:15)
Block(8,16,8,biomesoplenty:leaves_4:15)
Block(8,17,-3,biomesoplenty:leaves_4:15)
Block(8,17,-2,biomesoplenty:log_2:9)
Block(8,17,-1,biomesoplenty:log_2:13)
Block(8,17,0,biomesoplenty:log_2:13)
Block(8,17,1,biomesoplenty:leaves_4:15)
Block(8,17,2,biomesoplenty:leaves_4:15)
Block(8,17,4,biomesoplenty:leaves_4:15)
Block(8,17,6,biomesoplenty:leaves_4:15)
Block(8,17,7,biomesoplenty:leaves_4:15)
Block(8,17,8,biomesoplenty:leaves_4:15)
Block(8,18,-4,biomesoplenty:leaves_4:15)
Block(8,18,-3,biomesoplenty:leaves_4:15)
Block(8,18,-2,biomesoplenty:leaves_4)
Block(8,18,-1,biomesoplenty:leaves_4:15)
Block(8,18,0,biomesoplenty:leaves_4:15)
Block(8,18,1,biomesoplenty:leaves_4:15)
Block(8,18,3,biomesoplenty:leaves_4:15)
Block(8,18,4,biomesoplenty:leaves_4:15)
Block(8,18,5,biomesoplenty:leaves_4:15)
Block(8,18,6,biomesoplenty:log_2:13)
Block(8,18,7,biomesoplenty:log_2:13)
Block(8,18,8,biomesoplenty:leaves_4:15)
Block(8,19,-2,biomesoplenty:leaves_4:15)
Block(8,19,0,biomesoplenty:leaves_4:15)
Block(8,19,4,biomesoplenty:leaves_4:15)
Block(8,19,5,biomesoplenty:leaves_4:15)
Block(8,19,6,biomesoplenty:log_2:13)
Block(8,19,7,biomesoplenty:leaves_4:15)
Block(8,20,6,biomesoplenty:leaves_4:15)
Block(8,20,7,biomesoplenty:leaves_4:15)
Block(9,9,-1,biomesoplenty:leaves_4:15)
Block(9,9,3,biomesoplenty:leaves_4:15)
Block(9,10,-2,biomesoplenty:leaves_4:15)
Block(9,10,-1,biomesoplenty:leaves_4:15)
Block(9,10,0,biomesoplenty:leaves_4:15)
Block(9,10,2,biomesoplenty:leaves_4:15)
Block(9,10,3,biomesoplenty:leaves_4:15)
Block(9,10,4,biomesoplenty:leaves_4:15)
Block(9,10,8,biomesoplenty:leaves_4:15)
Block(9,11,-2,biomesoplenty:leaves_4:15)
Block(9,11,-1,biomesoplenty:leaves_4:15)
Block(9,11,0,biomesoplenty:leaves_4:15)
Block(9,11,1,biomesoplenty:leaves_4:15)
Block(9,11,3,biomesoplenty:leaves_4:15)
Block(9,11,5,biomesoplenty:leaves_4:15)
Block(9,11,6,biomesoplenty:leaves_4:15)
Block(9,11,8,biomesoplenty:leaves_4:15)
Block(9,12,-2,biomesoplenty:leaves_4:15)
Block(9,12,-1,biomesoplenty:leaves_4:15)
Block(9,12,0,biomesoplenty:leaves_4:15)
Block(9,12,1,biomesoplenty:leaves_4:15)
Block(9,12,3,biomesoplenty:leaves_4:15)
Block(9,12,5,biomesoplenty:leaves_4:15)
Block(9,12,6,biomesoplenty:leaves_4:15)
Block(9,12,7,biomesoplenty:leaves_4:15)
Block(9,13,-1,biomesoplenty:leaves_4:15)
Block(9,13,0,biomesoplenty:leaves_4:15)
Block(9,13,1,biomesoplenty:leaves_4:15)
Block(9,13,3,biomesoplenty:leaves_4:15)
Block(9,13,4,biomesoplenty:leaves_4:15)
Block(9,13,5,biomesoplenty:leaves_4:15)
Block(9,13,6,biomesoplenty:leaves_4:15)
Block(9,14,-2,biomesoplenty:leaves_4:15)
Block(9,14,-1,biomesoplenty:leaves_4:15)
Block(9,14,0,biomesoplenty:leaves_4:15)
Block(9,14,1,biomesoplenty:leaves_4:15)
Block(9,14,2,biomesoplenty:leaves_4:15)
Block(9,14,3,biomesoplenty:leaves_4:15)
Block(9,14,4,biomesoplenty:leaves_4:15)
Block(9,14,5,biomesoplenty:leaves_4:15)
Block(9,14,6,biomesoplenty:leaves_4:15)
Block(9,15,-2,biomesoplenty:leaves_4:15)
Block(9,15,-1,biomesoplenty:leaves_4:15)
Block(9,15,0,biomesoplenty:leaves_4:15)
Block(9,15,1,biomesoplenty:leaves_4:15)
Block(9,15,2,biomesoplenty:leaves_4:15)
Block(9,15,3,biomesoplenty:leaves_4:15)
Block(9,15,4,biomesoplenty:leaves_4:15)
Block(9,15,5,biomesoplenty:leaves_4:15)
Block(9,15,6,biomesoplenty:leaves_4:15)
Block(9,16,-2,biomesoplenty:leaves_4:15)
Block(9,16,-1,biomesoplenty:leaves_4:15)
Block(9,16,0,biomesoplenty:leaves_4:15)
Block(9,16,1,biomesoplenty:leaves_4:15)
Block(9,16,2,biomesoplenty:leaves_4:15)
Block(9,16,3,biomesoplenty:leaves_4:15)
Block(9,16,4,biomesoplenty:leaves_4:15)
Block(9,16,5,biomesoplenty:leaves_4:15)
Block(9,16,7,biomesoplenty:leaves_4:15)
Block(9,17,-3,biomesoplenty:leaves_4:15)
Block(9,17,-2,biomesoplenty:log_2:13)
Block(9,17,-1,biomesoplenty:leaves_4:15)
Block(9,17,0,biomesoplenty:leaves_4:15)
Block(9,17,1,biomesoplenty:leaves_4:15)
Block(9,17,2,biomesoplenty:leaves_4:15)
Block(9,17,3,biomesoplenty:leaves_4:15)
Block(9,17,4,biomesoplenty:leaves_4:15)
Block(9,17,5,biomesoplenty:leaves_4:15)
Block(9,17,6,biomesoplenty:leaves_4:15)
Block(9,17,7,biomesoplenty:leaves_4:15)
Block(9,17,8,biomesoplenty:leaves_4:15)
Block(9,18,-3,biomesoplenty:leaves_4:15)
Block(9,18,-2,biomesoplenty:leaves_4:15)
Block(9,18,-1,biomesoplenty:leaves_4:15)
Block(9,18,1,biomesoplenty:leaves_4:15)
Block(9,18,2,biomesoplenty:leaves_4:15)
Block(9,18,3,biomesoplenty:leaves_4:15)
Block(9,18,4,biomesoplenty:leaves_4:15)
Block(9,18,5,biomesoplenty:leaves_4:15)
Block(9,18,6,biomesoplenty:log_2:13)
Block(9,18,7,biomesoplenty:leaves_4:15)
Block(9,18,8,biomesoplenty:leaves_4:15)
Block(9,19,-3,biomesoplenty:leaves_4:15)
Block(9,19,-1,biomesoplenty:leaves_4:15)
Block(9,19,5,biomesoplenty:leaves_4:15)
Block(9,19,6,biomesoplenty:leaves_4:15)
Block(9,19,7,biomesoplenty:leaves_4:15)
Block(9,19,8,biomesoplenty:leaves_4:15)
Block(9,20,6,biomesoplenty:leaves_4:15)
Block(10,9,3,biomesoplenty:leaves_4:15)
Block(10,10,-1,biomesoplenty:leaves_4:15)
Block(10,10,1,biomesoplenty:leaves_4:15)
Block(10,10,2,biomesoplenty:leaves_4:15)
Block(10,10,3,biomesoplenty:leaves_4:15)
Block(10,11,-1,biomesoplenty:leaves_4:15)
Block(10,11,0,biomesoplenty:leaves_4:15)
Block(10,11,1,biomesoplenty:leaves_4:15)
Block(10,11,2,biomesoplenty:leaves_4:15)
Block(10,11,3,biomesoplenty:leaves_4:15)
Block(10,11,4,biomesoplenty:leaves_4:15)
Block(10,12,-1,biomesoplenty:leaves_4:15)
Block(10,12,0,biomesoplenty:leaves_4:15)
Block(10,12,1,biomesoplenty:leaves_4:15)
Block(10,12,2,biomesoplenty:leaves_4:15)
Block(10,12,3,biomesoplenty:leaves_4:15)
Block(10,12,4,biomesoplenty:leaves_4:15)
Block(10,12,5,biomesoplenty:leaves_4:15)
Block(10,12,6,biomesoplenty:leaves_4:15)
Block(10,13,-1,biomesoplenty:leaves_4:15)
Block(10,13,0,biomesoplenty:leaves_4:15)
Block(10,13,1,biomesoplenty:leaves_4:15)
Block(10,13,2,biomesoplenty:leaves_4:15)
Block(10,13,3,biomesoplenty:leaves_4:15)
Block(10,13,4,biomesoplenty:leaves_4:15)
Block(10,13,5,biomesoplenty:leaves_4:15)
Block(10,14,-1,biomesoplenty:leaves_4:15)
Block(10,14,0,biomesoplenty:leaves_4:15)
Block(10,14,1,biomesoplenty:leaves_4:15)
Block(10,14,2,biomesoplenty:leaves_4:15)
Block(10,14,3,biomesoplenty:leaves_4:15)
Block(10,14,4,biomesoplenty:leaves_4:15)
Block(10,14,5,biomesoplenty:leaves_4:15)
Block(10,15,-1,biomesoplenty:leaves_4:15)
Block(10,15,0,biomesoplenty:leaves_4:15)
Block(10,15,1,biomesoplenty:leaves_4:15)
Block(10,15,2,biomesoplenty:leaves_4:15)
Block(10,15,3,biomesoplenty:leaves_4:15)
Block(10,15,4,biomesoplenty:leaves_4:15)
Block(10,15,5,biomesoplenty:leaves_4:15)
Block(10,16,-1,biomesoplenty:leaves_4:15)
Block(10,16,2,biomesoplenty:leaves_4:15)
Block(10,16,3,biomesoplenty:leaves_4:15)
Block(10,16,4,biomesoplenty:leaves_4:15)
Block(10,16,5,biomesoplenty:leaves_4:15)
Block(10,16,7,biomesoplenty:leaves_4:15)
Block(10,17,-2,biomesoplenty:leaves_4:15)
Block(10,17,-1,biomesoplenty:leaves_4:15)
Block(10,17,1,biomesoplenty:leaves_4:15)
Block(10,17,2,biomesoplenty:leaves_4:15)
Block(10,17,3,biomesoplenty:leaves_4:15)
Block(10,17,4,biomesoplenty:leaves_4:15)
Block(10,17,5,biomesoplenty:leaves_4:15)
Block(10,17,6,biomesoplenty:leaves_4:15)
Block(10,17,7,biomesoplenty:leaves_4:15)
Block(10,17,8,biomesoplenty:leaves_4:15)
Block(10,18,-2,biomesoplenty:leaves_4:15)
Block(10,18,-1,biomesoplenty:leaves_4:15)
Block(10,18,1,biomesoplenty:leaves_4:15)
Block(10,18,2,biomesoplenty:leaves_4:15)
Block(10,18,3,biomesoplenty:leaves_4:15)
Block(10,18,4,biomesoplenty:leaves_4:15)
Block(10,18,5,biomesoplenty:leaves_4:15)
Block(10,18,6,biomesoplenty:leaves_4:15)
Block(10,18,7,biomesoplenty:leaves_4:15)
Block(10,18,8,biomesoplenty:leaves_4:15)
Block(10,19,-1,biomesoplenty:leaves_4:15)
Block(10,19,2,biomesoplenty:leaves_4:15)
Block(10,19,4,biomesoplenty:leaves_4:15)
Block(10,19,5,biomesoplenty:leaves_4:15)
Block(10,19,6,biomesoplenty:leaves_4:15)
Block(10,19,7,biomesoplenty:leaves_4:15)
Block(11,10,3,biomesoplenty:leaves_4:15)
Block(11,11,1,biomesoplenty:leaves_4:15)
Block(11,11,3,biomesoplenty:leaves_4:15)
Block(11,12,1,biomesoplenty:leaves_4:15)
Block(11,12,3,biomesoplenty:leaves_4:15)
Block(11,13,1,biomesoplenty:leaves_4:15)
Block(11,13,3,biomesoplenty:leaves_4:15)
Block(11,14,0,biomesoplenty:leaves_4:15)
Block(11,14,1,biomesoplenty:leaves_4:15)
Block(11,14,3,biomesoplenty:leaves_4:15)
Block(11,15,2,biomesoplenty:leaves_4:15)
Block(11,15,3,biomesoplenty:leaves_4:15)
Block(11,16,4,biomesoplenty:leaves_4:15)
Block(11,17,3,biomesoplenty:leaves_4:15)
Block(11,17,4,biomesoplenty:leaves_4:15)
Block(11,17,5,biomesoplenty:leaves_4:15)
Block(11,17,7,biomesoplenty:leaves_4:15)
Block(11,18,-1,biomesoplenty:leaves_4:15)
Block(11,18,2,biomesoplenty:leaves_4:15)
Block(11,18,3,biomesoplenty:leaves_4:15)
Block(11,18,4,biomesoplenty:leaves_4:15)
Block(11,18,5,biomesoplenty:leaves_4:15)
Block(11,18,6,biomesoplenty:leaves_4:15)
Block(11,18,7,biomesoplenty:leaves_4:15)
Block(11,19,5,biomesoplenty:leaves_4:15)
Block(12,18,5,biomesoplenty:leaves_4:15)

#######################################################################
# +-----------------------------------------------------------------+ #
# |                            BO3 checks                           | #
# +-----------------------------------------------------------------+ #
#######################################################################

# Require a condition at a certain location in order for the BO3 to be spawned.
# BlockCheck(x,y,z,BlockName[,BlockName[,...]]) - one of the blocks must be at the location
# BlockCheckNot(x,y,z,BlockName[,BlockName[,...]]) - all the blocks must not be at the location
# LightCheck(x,y,z,minLightLevel,maxLightLevel) - light must be between min and max (inclusive)

# You can use "Solid" as a BlockName for matching all solid blocks or "All" to match all blocks that aren't air.

# Examples:
#   BlockCheck(0,-1,0,GRASS,DIRT)  Require grass or dirt just below the object
#   BlockCheck(0,-1,0,Solid)       Require any solid block just below the object
#   BlockCheck(0,-1,0,WOOL)        Require any type of wool just below the object
#   BlockCheck(0,-1,0,WOOL:0)      Require white wool just below the object
#   BlockCheckNot(0,-1,0,WOOL:0)   Require that there is no white wool below the object
#   LightCheck(0,0,0,0,1)          Require almost complete darkness just below the object
BlockCheck(0,2,0,AIR)
BlockCheck(2,2,0,AIR)
BlockCheck(-2,2,0,AIR)
BlockCheck(0,2,2,AIR)
BlockCheck(0,2,-2,AIR)
BlockCheck(5,2,0,AIR)
BlockCheck(-5,2,0,AIR)
BlockCheck(0,2,5,AIR)
BlockCheck(0,2,-5,AIR)
BlockCheck(-4,0,-4,Solid)
BlockCheck(-3,0,-4,Solid)
BlockCheck(-2,0,-4,Solid)
BlockCheck(-1,0,-4,Solid)
BlockCheck(0,0,-4,Solid)
BlockCheck(1,0,-4,Solid)
BlockCheck(2,0,-4,Solid)
BlockCheck(3,0,-4,Solid)
BlockCheck(4,0,-4,Solid)
BlockCheck(-4,0,-3,Solid)
BlockCheck(-3,0,-3,Solid)
BlockCheck(-2,0,-3,Solid)
BlockCheck(-1,0,-3,Solid)
BlockCheck(0,0,-3,Solid)
BlockCheck(1,0,-3,Solid)
BlockCheck(2,0,-3,Solid)
BlockCheck(3,0,-3,Solid)
BlockCheck(4,0,-3,Solid)
BlockCheck(-4,0,-2,Solid)
BlockCheck(-3,0,-2,Solid)
BlockCheck(-2,0,-2,Solid)
BlockCheck(-1,0,-2,Solid)
BlockCheck(0,0,-2,Solid)
BlockCheck(1,0,-2,Solid)
BlockCheck(2,0,-2,Solid)
BlockCheck(3,0,-2,Solid)
BlockCheck(4,0,-2,Solid)
BlockCheck(-4,0,-1,Solid)
BlockCheck(-3,0,-1,Solid)
BlockCheck(-2,0,-1,Solid)
BlockCheck(-1,0,-1,Solid)
BlockCheck(0,0,-1,Solid)
BlockCheck(1,0,-1,Solid)
BlockCheck(2,0,-1,Solid)
BlockCheck(3,0,-1,Solid)
BlockCheck(4,0,-1,Solid)
BlockCheck(-4,0,0,Solid)
BlockCheck(-3,0,0,Solid)
BlockCheck(-2,0,0,Solid)
BlockCheck(-1,0,0,Solid)
BlockCheck(0,0,0,Solid)
BlockCheck(1,0,0,Solid)
BlockCheck(2,0,0,Solid)
BlockCheck(3,0,0,Solid)
BlockCheck(4,0,0,Solid)
BlockCheck(-4,0,1,Solid)
BlockCheck(-3,0,1,Solid)
BlockCheck(-2,0,1,Solid)
BlockCheck(-1,0,1,Solid)
BlockCheck(0,0,1,Solid)
BlockCheck(1,0,1,Solid)
BlockCheck(2,0,1,Solid)
BlockCheck(3,0,1,Solid)
BlockCheck(4,0,1,Solid)
BlockCheck(-4,0,2,Solid)
BlockCheck(-3,0,2,Solid)
BlockCheck(-2,0,2,Solid)
BlockCheck(-1,0,2,Solid)
BlockCheck(0,0,2,Solid)
BlockCheck(1,0,2,Solid)
BlockCheck(2,0,2,Solid)
BlockCheck(3,0,2,Solid)
BlockCheck(4,0,2,Solid)
BlockCheck(-4,0,3,Solid)
BlockCheck(-3,0,3,Solid)
BlockCheck(-2,0,3,Solid)
BlockCheck(-1,0,3,Solid)
BlockCheck(0,0,3,Solid)
BlockCheck(1,0,3,Solid)
BlockCheck(2,0,3,Solid)
BlockCheck(3,0,3,Solid)
BlockCheck(4,0,3,Solid)
BlockCheck(-4,0,4,Solid)
BlockCheck(-3,0,4,Solid)
BlockCheck(-2,0,4,Solid)
BlockCheck(-1,0,4,Solid)
BlockCheck(0,0,4,Solid)
BlockCheck(1,0,4,Solid)
BlockCheck(2,0,4,Solid)
BlockCheck(3,0,4,Solid)
BlockCheck(4,0,4,Solid)

#######################################################################
# +-----------------------------------------------------------------+ #
# |                             Branches                            | #
# +-----------------------------------------------------------------+ #
#######################################################################

# Branches are child-BO3's that spawn if this BO3 is configured to spawn as a
# CustomStructure resource in a biome config. Branches can have branches,
# making complex structures possible. See the wiki for more details.

# Regular Branches spawn each branch with an independent chance of spawning.
# Branch(x,y,z,branchName,rotation,chance[,anotherBranchName,rotation,chance[,...]][IndividualChance])
# branchName - name of the object to spawn.
# rotation - NORTH, SOUTH, EAST or WEST.
# IndividualChance - The chance each branch has to spawn, assumed to be 100 when left blank
# isRequiredBranch - If this is set to true then at least one of the branches in this BO3 must spawn at these x,y,z coordinates. If no branch can spawn there then this BO3 fails to spawn and its branch is rolled back.
# isRequiredBranch:true branches must spawn or the current branch is rolled back entirely. This is useful for grouping BO3's that must spawn together, for instance a single room made of multiple BO3's/branches.
# If all parts of the room are connected together via isRequiredBranch:true branches then either the entire room will spawns or no part of it will spawn.
# *Note: When isRequiredBranch:true only one BO3 can be added per Branch() and it will automatically have a rarity of 100.0.
# isRequiredBranch:false branches are used to make optional parts of structures, for instance the middle section of a tunnel that has a beginning, middle and end BO3/branch and can have a variable length by repeating the middle BO3/branch.
# By making the start and end branches isRequiredBranch:true and the middle branch isRequiredbranch:false you can make it so that either:
# A. A tunnel spawns with at least a beginning and end branch
# B. A tunnel spawns with a beginning and end branch and as many middle branches as will fit in the available space.
# C. No tunnel spawns at all because there wasn't enough space to spawn at least a beginning and end branch.
# branchDepth - When creating a chain of branches that contains optional (isRequiredBranch:false) branches branch depth is configured for the first BO3 in the chain to determine the maximum length of the chain.
# branchDepth - 1 is inherited by each isRequiredBranch:false branch in the chain. When branchDepth is zero isRequiredBranch:false branches cannot spawn and the chain ends. In the case of the tunnel this means the last middle branch would be
# rolled back and an IsRequiredBranch:true end branch could be spawned in its place to make sure the tunnel has a proper ending.
# Instead of inheriting branchDepth - 1 from the parent branchDepth can be overridden by child branches if it is set higher than 0 (the default value).
# isRequiredBranch:true branches do inherit branchDepth and pass it on to their own branches, however they cannot be prevented from spawning by it and also don't subtract 1 from branchDepth when inheriting it.

# Weighted Branches spawn branches with a dependent chance of spawning.
# WeightedBranch(x,y,z,branchName,rotation,chance[,anotherBranchName,rotation,chance[,...]][MaxChanceOutOf])
# *Note: isRequiredBranch must be set to false. It is not possible to use isRequiredBranch:true with WeightedBranch() since isRequired:true branches must spawn and automatically have a rarity of 100.0.
# MaxChanceOutOf - The chance all branches have to spawn out of, assumed to be 100 when left blank

#######################################################################
# +-----------------------------------------------------------------+ #
# |                             Entities                            | #
# +-----------------------------------------------------------------+ #
#######################################################################

# Forge only (this may have changed, check for updates).
# An EntityFunction spawns an entity instead of a block. The entity is spawned only once when the BO3 is spawned.
# Entities are persistent by default so they don't de-spawn when no player is near, they are only unloaded.
# Usage: Entity(x,y,z,entityName,groupSize,NameTagOrNBTFileName) or Entity(x,y,z,mobName,groupSize)
# Use /otg entities to get a list of entities that can be used as entityName, this includes entities added by other mods and non-living entities.
# NameTagOrNBTFileName can be either a nametag for the mob or an .txt file with nbt data (such as myentityinfo.txt).
# In the text file you can use the same mob spawning parameters used with the /summon command to equip the
# entity and give it custom attributes etc. You can copy the DATA part of a summon command including surrounding 
# curly braces to a .txt file, for instance for: "/summon Skeleton x y z {DATA}"
# *Note: Unlike Block(), for Entity() .nbt files don't work, only .txt files work.

#######################################################################
# +-----------------------------------------------------------------+ #
# |                            Particles                            | #
# +-----------------------------------------------------------------+ #
#######################################################################

# Forge only (this may have changed, check for updates).
# Creates an invisible particle spawner at the given location that spawns particles every x milliseconds.
# Usage: Particle(x,y,z,particleName,interval,velocityX,velocityY,velocityZ)
# velocityX, velocityY and velocityZ are optional.
# Only vanilla particle names can be used, for 1.11.2 these are;
# explode, largeexplode, hugeexplosion, fireworksSpark, bubble, splash, wake, suspended
# depthsuspend, crit, magicCrit, smoke, largesmoke, spell, instantSpell, mobSpell
# mobSpellAmbient, witchMagic, dripWater, dripLava, angryVillager, happyVillager
