
#######################################################################
# +-----------------------------------------------------------------+ #
# |                            BO3 object                           | #
# +-----------------------------------------------------------------+ #
#######################################################################

# This is the config file of a custom object.
# If you add this object correctly to your BiomeConfigs, it will spawn in the world.

# This is the creator of this BO3 object
Author: Unknown

# A short description of this BO3 object
Description: This BO3 was converted from a schematic using OTGEdit. The author and description information of the schematic could not be found. If you know who the author of the schematic is then please add this information.

# The BO3 version, don't change this! It can be used by external applications to do a version check.
Version: 3

# The settings mode, WriteAll, WriteWithoutComments or WriteDisable. See WorldConfig.
SettingsMode: WriteAll


#######################################################################
# +-----------------------------------------------------------------+ #
# |                          Main settings                          | #
# +-----------------------------------------------------------------+ #
#######################################################################

# This needs to be set to true to spawn the object in the Tree and Sapling resources.
Tree: true

# The frequency of the BO3 from 1 to 200. Tries this many times to spawn this BO3 when using the CustomObject(...) resource.
# Ignored by Tree(..), Sapling(..) and CustomStructure(..)
Frequency: 40

# The rarity of the BO3 from 0 to 100. Each spawn attempt has rarity% chance to succeed when using the CustomObject(...) resource.
# Ignored by Tree(..), Sapling(..) and CustomStructure(..)
Rarity: 100.0

# If you set this to true, the BO3 will be placed with a random rotation.
RotateRandomly: true

# The spawn height of the BO3: randomY, highestBlock or highestSolidBlock.
SpawnHeight: randomY

# The offset from the spawn height to spawn this BO3
# Ex. SpawnHeight = highestSolidBlock, SpawnHeightOffset = 3; This object will spawn 3 blocks above the highest solid block
SpawnHeightOffset: 0

# A random amount to offset the spawn location from the spawn offset height
# Ex. SpawnHeightOffset = 3, SpawnHeightVariance = 3; This object will spawn 3 to 6 blocks above the original spot it would have spawned
SpawnHeightVariance: 0

##############################
# Height Limits for the BO3. #
##############################

# When in randomY mode used as the minimum Y or in atMinY mode as the actual Y to spawn this BO3 at.
MinHeight: 0

# When in randomY mode used as the maximum Y to spawn this BO3 at.
MaxHeight: 256

######################
# Extrusion settings #
######################

# The style of extrusion you wish to use - BottomDown, TopUp, None (Default)
ExtrudeMode: None

# The blocks to extrude your BO3 through
ExtrudeThroughBlocks: AIR

# Objects can have other objects attacthed to it: branches. Branches can also
# have branches attached to it, which can also have branches, etc. This is the
# maximum branch depth for this objects.
MaxBranchDepth: 10

# When spawned with the UseWorld keyword, this BO3 should NOT spawn in the following biomes.
# If you write the BO3 name directly in the BiomeConfigs, this will be ignored.
ExcludedBiomes: All


#######################################################################
# +-----------------------------------------------------------------+ #
# |                      Source block settings                      | #
# +-----------------------------------------------------------------+ #
#######################################################################

# The block(s) the BO3 should spawn in.
SourceBlocks: AIR

# The maximum percentage of the BO3 that can be outside the SourceBlock.
# The BO3 won't be placed on a location with more blocks outside the SourceBlock than this percentage.
MaxPercentageOutsideSourceBlock: 100

# What to do when a block is about to be placed outside the SourceBlock? (dontPlace, placeAnyway)
OutsideSourceBlock: placeAnyway

# OTG+ settings #
# Legacy setting, rename this file to .BO4 instead. Set this to true to enable the advanced customstructure features of OTG+.
IsOTGPlus: false


#######################################################################
# +-----------------------------------------------------------------+ #
# |                              Blocks                             | #
# +-----------------------------------------------------------------+ #
#######################################################################

# All the blocks used in the BO3 are listed here. Possible blocks:
# Block(x,y,z,id[.data][,nbtfile.nbt)
# RandomBlock(x,y,z,id[:data][,nbtfile.nbt],chance[,id[:data][,nbtfile.nbt],chance[,...]])
#  So RandomBlock(0,0,0,CHEST,chest.nbt,50,CHEST,anotherchest.nbt,100) will spawn a chest at
#  the BO3 origin, and give it a 50% chance to have the contents of chest.nbt, or, if that
#  fails, a 100% percent chance to have the contents of anotherchest.nbt.
# *Note: Unlike Entity() and Spawner(), for Block() .txt files don't work, only .nbt files work.
# MinecraftObject(x,y,z,name) (TODO: This may not work anymore and needs to be tested.
#  Spawns an object in the Mojang NBT structure format. For example, 
#  MinecraftObject(0,0,0,minecraft:igloo/igloo_bottom)
#  spawns the bottom part of an igloo.
Block(-7,16,-2,SANDSTONE)
Block(-7,17,-2,SANDSTONE)
Block(-7,18,-1,SANDSTONE)
Block(-6,12,1,SANDSTONE)
Block(-6,12,2,SANDSTONE)
Block(-6,12,3,SANDSTONE)
Block(-6,12,4,SANDSTONE)
Block(-6,13,0,SANDSTONE)
Block(-6,13,1,SANDSTONE)
Block(-6,13,2,SANDSTONE)
Block(-6,13,3,SANDSTONE)
Block(-6,14,-1,SANDSTONE)
Block(-6,14,0,SANDSTONE)
Block(-6,14,1,SANDSTONE)
Block(-6,14,2,SANDSTONE)
Block(-6,14,3,SANDSTONE)
Block(-6,15,-1,SANDSTONE)
Block(-6,15,0,SANDSTONE)
Block(-6,15,1,SANDSTONE)
Block(-6,15,2,SANDSTONE)
Block(-6,16,-2,SANDSTONE)
Block(-6,16,-1,SANDSTONE)
Block(-6,16,0,SANDSTONE)
Block(-6,16,1,SANDSTONE)
Block(-6,16,2,SANDSTONE)
Block(-6,17,-3,SANDSTONE)
Block(-6,17,-2,SANDSTONE)
Block(-6,17,-1,SANDSTONE)
Block(-6,17,0,SANDSTONE)
Block(-6,17,1,SANDSTONE)
Block(-6,17,2,SANDSTONE)
Block(-6,18,-3,SANDSTONE)
Block(-6,18,-2,SANDSTONE)
Block(-6,18,-1,SANDSTONE)
Block(-6,18,0,SANDSTONE)
Block(-6,18,1,SANDSTONE)
Block(-6,18,2,SANDSTONE)
Block(-6,19,-2,SANDSTONE)
Block(-6,19,-1,SANDSTONE)
Block(-6,19,0,SANDSTONE)
Block(-6,19,1,SANDSTONE)
Block(-6,19,2,SANDSTONE)
Block(-6,20,-1,SANDSTONE)
Block(-6,20,0,SANDSTONE)
Block(-6,20,1,SANDSTONE)
Block(-6,20,2,SANDSTONE)
Block(-6,21,0,SANDSTONE)
Block(-6,21,1,SANDSTONE)
Block(-6,21,2,SANDSTONE)
Block(-6,22,1,SANDSTONE)
Block(-6,22,2,SANDSTONE)
Block(-6,22,3,SANDSTONE)
Block(-5,11,2,SANDSTONE)
Block(-5,11,3,SANDSTONE)
Block(-5,11,4,SANDSTONE)
Block(-5,12,1,SANDSTONE)
Block(-5,12,2,SANDSTONE)
Block(-5,12,3,SANDSTONE)
Block(-5,12,4,SANDSTONE)
Block(-5,12,5,SANDSTONE)
Block(-5,12,6,SANDSTONE)
Block(-5,12,7,SANDSTONE)
Block(-5,12,8,SANDSTONE)
Block(-5,13,0,SANDSTONE)
Block(-5,13,1,SANDSTONE)
Block(-5,13,2,SANDSTONE)
Block(-5,13,3,SANDSTONE)
Block(-5,13,4,SANDSTONE)
Block(-5,13,5,SANDSTONE)
Block(-5,13,6,SANDSTONE)
Block(-5,13,7,SANDSTONE)
Block(-5,13,8,SANDSTONE)
Block(-5,14,-1,SANDSTONE)
Block(-5,14,0,SANDSTONE)
Block(-5,14,1,SANDSTONE)
Block(-5,14,2,SANDSTONE)
Block(-5,14,3,SANDSTONE)
Block(-5,14,4,SANDSTONE)
Block(-5,14,5,SANDSTONE)
Block(-5,14,6,SANDSTONE)
Block(-5,14,7,SANDSTONE)
Block(-5,15,-2,SANDSTONE)
Block(-5,15,-1,SANDSTONE)
Block(-5,15,0,SANDSTONE)
Block(-5,15,1,SANDSTONE)
Block(-5,15,2,SANDSTONE)
Block(-5,15,3,SANDSTONE)
Block(-5,15,4,SANDSTONE)
Block(-5,15,5,SANDSTONE)
Block(-5,15,6,SANDSTONE)
Block(-5,16,-3,SANDSTONE)
Block(-5,16,-2,SANDSTONE)
Block(-5,16,-1,SANDSTONE)
Block(-5,16,0,SANDSTONE)
Block(-5,16,1,SANDSTONE)
Block(-5,16,2,SANDSTONE)
Block(-5,16,3,SANDSTONE)
Block(-5,16,4,SANDSTONE)
Block(-5,16,5,SANDSTONE)
Block(-5,17,-3,SANDSTONE)
Block(-5,17,-2,SANDSTONE)
Block(-5,17,-1,SANDSTONE)
Block(-5,17,0,SANDSTONE)
Block(-5,17,1,SANDSTONE)
Block(-5,17,2,SANDSTONE)
Block(-5,17,3,SANDSTONE)
Block(-5,17,4,SANDSTONE)
Block(-5,17,5,SANDSTONE)
Block(-5,18,-4,SANDSTONE)
Block(-5,18,-3,SANDSTONE)
Block(-5,18,-2,SANDSTONE)
Block(-5,18,-1,SANDSTONE)
Block(-5,18,0,SANDSTONE)
Block(-5,18,1,SANDSTONE)
Block(-5,18,2,SANDSTONE)
Block(-5,18,3,SANDSTONE)
Block(-5,18,4,SANDSTONE)
Block(-5,18,5,SANDSTONE)
Block(-5,19,-3,SANDSTONE)
Block(-5,19,-2,SANDSTONE)
Block(-5,19,-1,SANDSTONE)
Block(-5,19,0,SANDSTONE)
Block(-5,19,1,SANDSTONE)
Block(-5,19,2,SANDSTONE)
Block(-5,19,3,SANDSTONE)
Block(-5,19,4,SANDSTONE)
Block(-5,19,5,SANDSTONE)
Block(-5,20,-2,SANDSTONE)
Block(-5,20,-1,SANDSTONE)
Block(-5,20,0,SANDSTONE)
Block(-5,20,1,SANDSTONE)
Block(-5,20,2,SANDSTONE)
Block(-5,20,3,SANDSTONE)
Block(-5,20,4,SANDSTONE)
Block(-5,20,5,SANDSTONE)
Block(-5,20,6,SANDSTONE)
Block(-5,21,-1,SANDSTONE)
Block(-5,21,0,SANDSTONE)
Block(-5,21,1,SANDSTONE)
Block(-5,21,2,SANDSTONE)
Block(-5,21,3,SANDSTONE)
Block(-5,21,4,SANDSTONE)
Block(-5,21,5,SANDSTONE)
Block(-5,21,6,SANDSTONE)
Block(-5,22,0,SANDSTONE)
Block(-5,22,1,SANDSTONE)
Block(-5,22,2,SANDSTONE)
Block(-5,22,3,SANDSTONE)
Block(-5,22,4,SANDSTONE)
Block(-5,22,5,SANDSTONE)
Block(-5,22,6,SANDSTONE)
Block(-5,22,7,SANDSTONE)
Block(-5,22,8,SANDSTONE)
Block(-5,22,9,SANDSTONE)
Block(-5,22,10,SANDSTONE)
Block(-5,22,11,SANDSTONE)
Block(-5,23,1,SANDSTONE)
Block(-5,23,2,SANDSTONE)
Block(-5,23,3,SANDSTONE)
Block(-5,23,4,SANDSTONE)
Block(-5,23,5,SANDSTONE)
Block(-5,23,6,SANDSTONE)
Block(-5,23,7,SANDSTONE)
Block(-5,23,8,SANDSTONE)
Block(-5,23,9,SANDSTONE)
Block(-5,23,10,SANDSTONE)
Block(-5,23,11,SANDSTONE)
Block(-5,24,3,SANDSTONE)
Block(-5,24,4,SANDSTONE)
Block(-5,24,5,SANDSTONE)
Block(-5,24,6,SANDSTONE)
Block(-5,24,7,SANDSTONE)
Block(-5,24,8,SANDSTONE)
Block(-5,24,9,SANDSTONE)
Block(-5,24,10,SANDSTONE)
Block(-5,24,11,SANDSTONE)
Block(-5,24,12,SANDSTONE)
Block(-5,25,4,SANDSTONE)
Block(-5,25,5,SANDSTONE)
Block(-5,25,6,SANDSTONE)
Block(-5,25,7,SANDSTONE)
Block(-5,25,8,SANDSTONE)
Block(-5,25,9,SANDSTONE)
Block(-5,25,10,SANDSTONE)
Block(-5,25,11,SANDSTONE)
Block(-5,25,12,SANDSTONE)
Block(-5,26,5,SANDSTONE)
Block(-5,26,6,SANDSTONE)
Block(-5,26,7,SANDSTONE)
Block(-5,26,8,SANDSTONE)
Block(-5,26,9,SANDSTONE)
Block(-5,26,10,SANDSTONE)
Block(-5,26,11,SANDSTONE)
Block(-5,26,12,SANDSTONE)
Block(-5,27,7,SANDSTONE)
Block(-5,27,8,SANDSTONE)
Block(-5,27,9,SANDSTONE)
Block(-4,10,2,SANDSTONE)
Block(-4,11,1,SANDSTONE)
Block(-4,11,2,SANDSTONE)
Block(-4,11,3,SANDSTONE)
Block(-4,11,4,SANDSTONE)
Block(-4,11,5,SANDSTONE)
Block(-4,11,6,SANDSTONE)
Block(-4,11,7,SANDSTONE)
Block(-4,11,8,SANDSTONE)
Block(-4,12,0,SANDSTONE)
Block(-4,12,1,SANDSTONE)
Block(-4,12,2,SANDSTONE)
Block(-4,12,3,SANDSTONE)
Block(-4,12,4,SANDSTONE)
Block(-4,12,5,SANDSTONE)
Block(-4,12,6,SANDSTONE)
Block(-4,12,7,SANDSTONE)
Block(-4,12,8,SANDSTONE)
Block(-4,12,9,SANDSTONE)
Block(-4,13,0,SANDSTONE)
Block(-4,13,1,SANDSTONE)
Block(-4,13,2,SANDSTONE)
Block(-4,13,3,SANDSTONE)
Block(-4,13,4,SANDSTONE)
Block(-4,13,5,SANDSTONE)
Block(-4,13,6,SANDSTONE)
Block(-4,13,7,SANDSTONE)
Block(-4,13,8,SANDSTONE)
Block(-4,13,9,SANDSTONE)
Block(-4,13,10,SANDSTONE)
Block(-4,14,-1,SANDSTONE)
Block(-4,14,0,SANDSTONE)
Block(-4,14,1,SANDSTONE)
Block(-4,14,2,SANDSTONE)
Block(-4,14,3,SANDSTONE)
Block(-4,14,4,SANDSTONE)
Block(-4,14,5,SANDSTONE)
Block(-4,14,6,SANDSTONE)
Block(-4,14,7,SANDSTONE)
Block(-4,14,8,SANDSTONE)
Block(-4,14,9,SANDSTONE)
Block(-4,14,10,SANDSTONE)
Block(-4,15,-2,SANDSTONE)
Block(-4,15,-1,SANDSTONE)
Block(-4,15,0,SANDSTONE)
Block(-4,15,1,SANDSTONE)
Block(-4,15,2,SANDSTONE)
Block(-4,15,3,SANDSTONE)
Block(-4,15,4,SANDSTONE)
Block(-4,15,5,SANDSTONE)
Block(-4,15,6,SANDSTONE)
Block(-4,15,7,SANDSTONE)
Block(-4,15,8,SANDSTONE)
Block(-4,15,9,SANDSTONE)
Block(-4,15,10,SANDSTONE)
Block(-4,16,-3,SANDSTONE)
Block(-4,16,-2,SANDSTONE)
Block(-4,16,-1,SANDSTONE)
Block(-4,16,0,SANDSTONE)
Block(-4,16,1,SANDSTONE)
Block(-4,16,2,SANDSTONE)
Block(-4,16,3,SANDSTONE)
Block(-4,16,4,SANDSTONE)
Block(-4,16,5,SANDSTONE)
Block(-4,16,6,SANDSTONE)
Block(-4,16,7,SANDSTONE)
Block(-4,16,8,SANDSTONE)
Block(-4,16,9,SANDSTONE)
Block(-4,16,10,SANDSTONE)
Block(-4,17,-4,SANDSTONE)
Block(-4,17,-3,SANDSTONE)
Block(-4,17,-2,SANDSTONE)
Block(-4,17,-1,SANDSTONE)
Block(-4,17,0,SANDSTONE)
Block(-4,17,1,SANDSTONE)
Block(-4,17,2,SANDSTONE)
Block(-4,17,3,SANDSTONE)
Block(-4,17,4,SANDSTONE)
Block(-4,17,5,SANDSTONE)
Block(-4,17,6,SANDSTONE)
Block(-4,17,7,SANDSTONE)
Block(-4,17,8,SANDSTONE)
Block(-4,17,9,SANDSTONE)
Block(-4,17,10,SANDSTONE)
Block(-4,18,-4,SANDSTONE)
Block(-4,18,-3,SANDSTONE)
Block(-4,18,-2,SANDSTONE)
Block(-4,18,-1,SANDSTONE)
Block(-4,18,0,SANDSTONE)
Block(-4,18,1,SANDSTONE)
Block(-4,18,2,SANDSTONE)
Block(-4,18,3,SANDSTONE)
Block(-4,18,4,SANDSTONE)
Block(-4,18,5,SANDSTONE)
Block(-4,18,6,SANDSTONE)
Block(-4,18,7,SANDSTONE)
Block(-4,18,8,SANDSTONE)
Block(-4,18,9,SANDSTONE)
Block(-4,18,10,SANDSTONE)
Block(-4,19,-4,SANDSTONE)
Block(-4,19,-3,SANDSTONE)
Block(-4,19,-2,SANDSTONE)
Block(-4,19,-1,SANDSTONE)
Block(-4,19,0,SANDSTONE)
Block(-4,19,1,SANDSTONE)
Block(-4,19,2,SANDSTONE)
Block(-4,19,3,SANDSTONE)
Block(-4,19,4,SANDSTONE)
Block(-4,19,5,SANDSTONE)
Block(-4,19,6,SANDSTONE)
Block(-4,19,7,SANDSTONE)
Block(-4,19,8,SANDSTONE)
Block(-4,19,9,SANDSTONE)
Block(-4,19,10,SANDSTONE)
Block(-4,19,11,SANDSTONE)
Block(-4,20,-3,SANDSTONE)
Block(-4,20,-2,SANDSTONE)
Block(-4,20,-1,SANDSTONE)
Block(-4,20,0,SANDSTONE)
Block(-4,20,1,SANDSTONE)
Block(-4,20,2,SANDSTONE)
Block(-4,20,3,SANDSTONE)
Block(-4,20,4,SANDSTONE)
Block(-4,20,5,SANDSTONE)
Block(-4,20,6,SANDSTONE)
Block(-4,20,7,SANDSTONE)
Block(-4,20,8,SANDSTONE)
Block(-4,20,9,SANDSTONE)
Block(-4,20,10,SANDSTONE)
Block(-4,20,11,SANDSTONE)
Block(-4,21,-2,SANDSTONE)
Block(-4,21,-1,SANDSTONE)
Block(-4,21,0,SANDSTONE)
Block(-4,21,1,SANDSTONE)
Block(-4,21,2,SANDSTONE)
Block(-4,21,3,SANDSTONE)
Block(-4,21,4,SANDSTONE)
Block(-4,21,5,SANDSTONE)
Block(-4,21,6,SANDSTONE)
Block(-4,21,7,SANDSTONE)
Block(-4,21,8,SANDSTONE)
Block(-4,21,9,SANDSTONE)
Block(-4,21,10,SANDSTONE)
Block(-4,21,11,SANDSTONE)
Block(-4,21,12,SANDSTONE)
Block(-4,22,-1,SANDSTONE)
Block(-4,22,0,SANDSTONE)
Block(-4,22,1,SANDSTONE)
Block(-4,22,2,SANDSTONE)
Block(-4,22,3,SANDSTONE)
Block(-4,22,4,SANDSTONE)
Block(-4,22,5,SANDSTONE)
Block(-4,22,6,SANDSTONE)
Block(-4,22,7,SANDSTONE)
Block(-4,22,8,SANDSTONE)
Block(-4,22,9,SANDSTONE)
Block(-4,22,10,SANDSTONE)
Block(-4,22,11,SANDSTONE)
Block(-4,22,12,SANDSTONE)
Block(-4,23,0,SANDSTONE)
Block(-4,23,1,SANDSTONE)
Block(-4,23,2,SANDSTONE)
Block(-4,23,3,SANDSTONE)
Block(-4,23,4,SANDSTONE)
Block(-4,23,5,SANDSTONE)
Block(-4,23,6,SANDSTONE)
Block(-4,23,7,SANDSTONE)
Block(-4,23,8,SANDSTONE)
Block(-4,23,9,SANDSTONE)
Block(-4,23,10,SANDSTONE)
Block(-4,23,11,SANDSTONE)
Block(-4,23,12,SANDSTONE)
Block(-4,23,13,SANDSTONE)
Block(-4,24,1,SANDSTONE)
Block(-4,24,2,SANDSTONE)
Block(-4,24,3,SANDSTONE)
Block(-4,24,4,SANDSTONE)
Block(-4,24,5,SANDSTONE)
Block(-4,24,6,SANDSTONE)
Block(-4,24,7,SANDSTONE)
Block(-4,24,8,SANDSTONE)
Block(-4,24,9,SANDSTONE)
Block(-4,24,10,SANDSTONE)
Block(-4,24,11,SANDSTONE)
Block(-4,24,12,SANDSTONE)
Block(-4,24,13,SANDSTONE)
Block(-4,25,3,SANDSTONE)
Block(-4,25,4,SANDSTONE)
Block(-4,25,5,SANDSTONE)
Block(-4,25,6,SANDSTONE)
Block(-4,25,7,SANDSTONE)
Block(-4,25,8,SANDSTONE)
Block(-4,25,9,SANDSTONE)
Block(-4,25,10,SANDSTONE)
Block(-4,25,11,SANDSTONE)
Block(-4,25,12,SANDSTONE)
Block(-4,25,13,SANDSTONE)
Block(-4,26,4,SANDSTONE)
Block(-4,26,5,SANDSTONE)
Block(-4,26,6,SANDSTONE)
Block(-4,26,7,SANDSTONE)
Block(-4,26,8,SANDSTONE)
Block(-4,26,9,SANDSTONE)
Block(-4,26,10,SANDSTONE)
Block(-4,26,11,SANDSTONE)
Block(-4,26,12,SANDSTONE)
Block(-4,26,13,SANDSTONE)
Block(-4,26,14,SANDSTONE)
Block(-4,27,5,SANDSTONE)
Block(-4,27,6,SANDSTONE)
Block(-4,27,7,SANDSTONE)
Block(-4,27,8,SANDSTONE)
Block(-4,27,9,SANDSTONE)
Block(-4,27,10,SANDSTONE)
Block(-4,27,11,SANDSTONE)
Block(-4,27,12,SANDSTONE)
Block(-4,27,13,SANDSTONE)
Block(-4,27,14,SANDSTONE)
Block(-4,28,7,SANDSTONE)
Block(-4,28,8,SANDSTONE)
Block(-4,28,9,SANDSTONE)
Block(-4,28,10,SANDSTONE)
Block(-3,10,2,SANDSTONE)
Block(-3,10,3,SANDSTONE)
Block(-3,10,4,SANDSTONE)
Block(-3,11,1,SANDSTONE)
Block(-3,11,2,SANDSTONE)
Block(-3,11,3,SANDSTONE)
Block(-3,11,4,SANDSTONE)
Block(-3,11,5,SANDSTONE)
Block(-3,11,6,SANDSTONE)
Block(-3,11,7,SANDSTONE)
Block(-3,11,8,SANDSTONE)
Block(-3,11,9,SANDSTONE)
Block(-3,11,10,SANDSTONE)
Block(-3,12,0,SANDSTONE)
Block(-3,12,1,SANDSTONE)
Block(-3,12,2,SANDSTONE)
Block(-3,12,3,SANDSTONE)
Block(-3,12,4,SANDSTONE)
Block(-3,12,5,SANDSTONE)
Block(-3,12,6,SANDSTONE)
Block(-3,12,7,SANDSTONE)
Block(-3,12,8,SANDSTONE)
Block(-3,12,9,SANDSTONE)
Block(-3,12,10,SANDSTONE)
Block(-3,13,-1,SANDSTONE)
Block(-3,13,0,SANDSTONE)
Block(-3,13,1,SANDSTONE)
Block(-3,13,2,SANDSTONE)
Block(-3,13,3,SANDSTONE)
Block(-3,13,4,SANDSTONE)
Block(-3,13,5,SANDSTONE)
Block(-3,13,6,SANDSTONE)
Block(-3,13,7,SANDSTONE)
Block(-3,13,8,SANDSTONE)
Block(-3,13,9,SANDSTONE)
Block(-3,13,10,SANDSTONE)
Block(-3,14,-2,SANDSTONE)
Block(-3,14,-1,SANDSTONE)
Block(-3,14,0,SANDSTONE)
Block(-3,14,1,SANDSTONE)
Block(-3,14,2,SANDSTONE)
Block(-3,14,3,SANDSTONE)
Block(-3,14,4,SANDSTONE)
Block(-3,14,5,SANDSTONE)
Block(-3,14,6,SANDSTONE)
Block(-3,14,7,SANDSTONE)
Block(-3,14,8,SANDSTONE)
Block(-3,14,9,SANDSTONE)
Block(-3,14,10,SANDSTONE)
Block(-3,14,11,SANDSTONE)
Block(-3,15,-2,SANDSTONE)
Block(-3,15,-1,SANDSTONE)
Block(-3,15,0,SANDSTONE)
Block(-3,15,1,SANDSTONE)
Block(-3,15,2,SANDSTONE)
Block(-3,15,3,SANDSTONE)
Block(-3,15,4,SANDSTONE)
Block(-3,15,5,SANDSTONE)
Block(-3,15,6,SANDSTONE)
Block(-3,15,7,SANDSTONE)
Block(-3,15,8,SANDSTONE)
Block(-3,15,9,SANDSTONE)
Block(-3,15,10,SANDSTONE)
Block(-3,15,11,SANDSTONE)
Block(-3,16,-3,SANDSTONE)
Block(-3,16,-2,SANDSTONE)
Block(-3,16,-1,SANDSTONE)
Block(-3,16,0,SANDSTONE)
Block(-3,16,1,SANDSTONE)
Block(-3,16,2,SANDSTONE)
Block(-3,16,3,SANDSTONE)
Block(-3,16,4,SANDSTONE)
Block(-3,16,5,SANDSTONE)
Block(-3,16,6,SANDSTONE)
Block(-3,16,7,SANDSTONE)
Block(-3,16,8,SANDSTONE)
Block(-3,16,9,SANDSTONE)
Block(-3,16,10,SANDSTONE)
Block(-3,16,11,SANDSTONE)
Block(-3,17,-4,SANDSTONE)
Block(-3,17,-3,SANDSTONE)
Block(-3,17,-2,SANDSTONE)
Block(-3,17,-1,SANDSTONE)
Block(-3,17,0,SANDSTONE)
Block(-3,17,1,SANDSTONE)
Block(-3,17,2,SANDSTONE)
Block(-3,17,3,SANDSTONE)
Block(-3,17,4,SANDSTONE)
Block(-3,17,5,SANDSTONE)
Block(-3,17,6,SANDSTONE)
Block(-3,17,7,SANDSTONE)
Block(-3,17,8,SANDSTONE)
Block(-3,17,9,SANDSTONE)
Block(-3,17,10,SANDSTONE)
Block(-3,17,11,SANDSTONE)
Block(-3,18,-5,SANDSTONE)
Block(-3,18,-4,SANDSTONE)
Block(-3,18,-3,SANDSTONE)
Block(-3,18,-2,SANDSTONE)
Block(-3,18,-1,SANDSTONE)
Block(-3,18,0,SANDSTONE)
Block(-3,18,1,SANDSTONE)
Block(-3,18,2,SANDSTONE)
Block(-3,18,3,SANDSTONE)
Block(-3,18,4,SANDSTONE)
Block(-3,18,5,SANDSTONE)
Block(-3,18,6,SANDSTONE)
Block(-3,18,7,SANDSTONE)
Block(-3,18,8,SANDSTONE)
Block(-3,18,9,SANDSTONE)
Block(-3,18,10,SANDSTONE)
Block(-3,18,11,SANDSTONE)
Block(-3,19,-5,SANDSTONE)
Block(-3,19,-4,SANDSTONE)
Block(-3,19,-3,SANDSTONE)
Block(-3,19,-2,SANDSTONE)
Block(-3,19,-1,SANDSTONE)
Block(-3,19,0,SANDSTONE)
Block(-3,19,1,SANDSTONE)
Block(-3,19,2,SANDSTONE)
Block(-3,19,3,SANDSTONE)
Block(-3,19,4,SANDSTONE)
Block(-3,19,5,SANDSTONE)
Block(-3,19,6,SANDSTONE)
Block(-3,19,7,SANDSTONE)
Block(-3,19,8,SANDSTONE)
Block(-3,19,9,SANDSTONE)
Block(-3,19,10,SANDSTONE)
Block(-3,19,11,SANDSTONE)
Block(-3,19,12,SANDSTONE)
Block(-3,20,-5,SANDSTONE)
Block(-3,20,-4,SANDSTONE)
Block(-3,20,-3,SANDSTONE)
Block(-3,20,-2,SANDSTONE)
Block(-3,20,-1,SANDSTONE)
Block(-3,20,0,SANDSTONE)
Block(-3,20,1,SANDSTONE)
Block(-3,20,2,SANDSTONE)
Block(-3,20,3,SANDSTONE)
Block(-3,20,4,SANDSTONE)
Block(-3,20,5,SANDSTONE)
Block(-3,20,6,SANDSTONE)
Block(-3,20,7,SANDSTONE)
Block(-3,20,8,SANDSTONE)
Block(-3,20,9,SANDSTONE)
Block(-3,20,10,SANDSTONE)
Block(-3,20,11,SANDSTONE)
Block(-3,20,12,SANDSTONE)
Block(-3,21,-4,SANDSTONE)
Block(-3,21,-3,SANDSTONE)
Block(-3,21,-2,SANDSTONE)
Block(-3,21,-1,SANDSTONE)
Block(-3,21,0,SANDSTONE)
Block(-3,21,1,SANDSTONE)
Block(-3,21,2,SANDSTONE)
Block(-3,21,3,SANDSTONE)
Block(-3,21,4,SANDSTONE)
Block(-3,21,5,SANDSTONE)
Block(-3,21,6,SANDSTONE)
Block(-3,21,7,SANDSTONE)
Block(-3,21,8,SANDSTONE)
Block(-3,21,9,SANDSTONE)
Block(-3,21,10,SANDSTONE)
Block(-3,21,11,SANDSTONE)
Block(-3,21,12,SANDSTONE)
Block(-3,21,13,SANDSTONE)
Block(-3,22,-3,SANDSTONE)
Block(-3,22,-2,SANDSTONE)
Block(-3,22,-1,SANDSTONE)
Block(-3,22,0,SANDSTONE)
Block(-3,22,1,SANDSTONE)
Block(-3,22,2,SANDSTONE)
Block(-3,22,3,SANDSTONE)
Block(-3,22,4,SANDSTONE)
Block(-3,22,5,SANDSTONE)
Block(-3,22,6,SANDSTONE)
Block(-3,22,7,SANDSTONE)
Block(-3,22,8,SANDSTONE)
Block(-3,22,9,SANDSTONE)
Block(-3,22,10,SANDSTONE)
Block(-3,22,11,SANDSTONE)
Block(-3,22,12,SANDSTONE)
Block(-3,22,13,SANDSTONE)
Block(-3,23,-2,SANDSTONE)
Block(-3,23,-1,SANDSTONE)
Block(-3,23,0,SANDSTONE)
Block(-3,23,1,SANDSTONE)
Block(-3,23,2,SANDSTONE)
Block(-3,23,3,SANDSTONE)
Block(-3,23,4,SANDSTONE)
Block(-3,23,5,SANDSTONE)
Block(-3,23,6,SANDSTONE)
Block(-3,23,7,SANDSTONE)
Block(-3,23,8,SANDSTONE)
Block(-3,23,9,SANDSTONE)
Block(-3,23,10,SANDSTONE)
Block(-3,23,11,SANDSTONE)
Block(-3,23,12,SANDSTONE)
Block(-3,23,13,SANDSTONE)
Block(-3,23,14,SANDSTONE)
Block(-3,24,-1,SANDSTONE)
Block(-3,24,0,SANDSTONE)
Block(-3,24,1,SANDSTONE)
Block(-3,24,2,SANDSTONE)
Block(-3,24,3,SANDSTONE)
Block(-3,24,4,SANDSTONE)
Block(-3,24,5,SANDSTONE)
Block(-3,24,6,SANDSTONE)
Block(-3,24,7,SANDSTONE)
Block(-3,24,8,SANDSTONE)
Block(-3,24,9,SANDSTONE)
Block(-3,24,10,SANDSTONE)
Block(-3,24,11,SANDSTONE)
Block(-3,24,12,SANDSTONE)
Block(-3,24,13,SANDSTONE)
Block(-3,24,14,SANDSTONE)
Block(-3,25,1,SANDSTONE)
Block(-3,25,2,SANDSTONE)
Block(-3,25,3,SANDSTONE)
Block(-3,25,4,SANDSTONE)
Block(-3,25,5,SANDSTONE)
Block(-3,25,6,SANDSTONE)
Block(-3,25,7,SANDSTONE)
Block(-3,25,8,SANDSTONE)
Block(-3,25,9,SANDSTONE)
Block(-3,25,10,SANDSTONE)
Block(-3,25,11,SANDSTONE)
Block(-3,25,12,SANDSTONE)
Block(-3,25,13,SANDSTONE)
Block(-3,25,14,SANDSTONE)
Block(-3,26,3,SANDSTONE)
Block(-3,26,4,SANDSTONE)
Block(-3,26,5,SANDSTONE)
Block(-3,26,6,SANDSTONE)
Block(-3,26,7,SANDSTONE)
Block(-3,26,8,SANDSTONE)
Block(-3,26,9,SANDSTONE)
Block(-3,26,10,SANDSTONE)
Block(-3,26,11,SANDSTONE)
Block(-3,26,12,SANDSTONE)
Block(-3,26,13,SANDSTONE)
Block(-3,26,14,SANDSTONE)
Block(-3,26,15,SANDSTONE)
Block(-3,27,4,SANDSTONE)
Block(-3,27,5,SANDSTONE)
Block(-3,27,6,SANDSTONE)
Block(-3,27,7,SANDSTONE)
Block(-3,27,8,SANDSTONE)
Block(-3,27,9,SANDSTONE)
Block(-3,27,10,SANDSTONE)
Block(-3,27,11,SANDSTONE)
Block(-3,27,12,SANDSTONE)
Block(-3,27,13,SANDSTONE)
Block(-3,27,14,SANDSTONE)
Block(-3,27,15,SANDSTONE)
Block(-3,28,6,SANDSTONE)
Block(-3,28,7,SANDSTONE)
Block(-3,28,8,SANDSTONE)
Block(-3,28,9,SANDSTONE)
Block(-3,28,10,SANDSTONE)
Block(-3,28,11,SANDSTONE)
Block(-3,28,12,SANDSTONE)
Block(-3,28,13,SANDSTONE)
Block(-3,28,14,SANDSTONE)
Block(-3,29,8,SANDSTONE)
Block(-3,29,9,SANDSTONE)
Block(-3,29,10,SANDSTONE)
Block(-2,10,1,SANDSTONE)
Block(-2,10,2,SANDSTONE)
Block(-2,10,3,SANDSTONE)
Block(-2,10,4,SANDSTONE)
Block(-2,10,5,SANDSTONE)
Block(-2,10,6,SANDSTONE)
Block(-2,11,1,SANDSTONE)
Block(-2,11,2,SANDSTONE)
Block(-2,11,3,SANDSTONE)
Block(-2,11,4,SANDSTONE)
Block(-2,11,5,SANDSTONE)
Block(-2,11,6,SANDSTONE)
Block(-2,11,7,SANDSTONE)
Block(-2,11,8,SANDSTONE)
Block(-2,11,9,SANDSTONE)
Block(-2,11,10,SANDSTONE)
Block(-2,11,11,SANDSTONE)
Block(-2,12,0,SANDSTONE)
Block(-2,12,1,SANDSTONE)
Block(-2,12,2,SANDSTONE)
Block(-2,12,3,SANDSTONE)
Block(-2,12,4,SANDSTONE)
Block(-2,12,5,SANDSTONE)
Block(-2,12,6,SANDSTONE)
Block(-2,12,7,SANDSTONE)
Block(-2,12,8,SANDSTONE)
Block(-2,12,9,SANDSTONE)
Block(-2,12,10,SANDSTONE)
Block(-2,12,11,SANDSTONE)
Block(-2,13,-1,SANDSTONE)
Block(-2,13,0,SANDSTONE)
Block(-2,13,1,SANDSTONE)
Block(-2,13,2,SANDSTONE)
Block(-2,13,3,SANDSTONE)
Block(-2,13,4,SANDSTONE)
Block(-2,13,5,SANDSTONE)
Block(-2,13,6,SANDSTONE)
Block(-2,13,7,SANDSTONE)
Block(-2,13,8,SANDSTONE)
Block(-2,13,9,SANDSTONE)
Block(-2,13,10,SANDSTONE)
Block(-2,13,11,SANDSTONE)
Block(-2,14,-2,SANDSTONE)
Block(-2,14,-1,SANDSTONE)
Block(-2,14,0,SANDSTONE)
Block(-2,14,1,SANDSTONE)
Block(-2,14,2,SANDSTONE)
Block(-2,14,3,SANDSTONE)
Block(-2,14,4,SANDSTONE)
Block(-2,14,5,SANDSTONE)
Block(-2,14,6,SANDSTONE)
Block(-2,14,7,SANDSTONE)
Block(-2,14,8,SANDSTONE)
Block(-2,14,9,SANDSTONE)
Block(-2,14,10,SANDSTONE)
Block(-2,14,11,SANDSTONE)
Block(-2,14,12,SANDSTONE)
Block(-2,15,-3,SANDSTONE)
Block(-2,15,-2,SANDSTONE)
Block(-2,15,-1,SANDSTONE)
Block(-2,15,0,SANDSTONE)
Block(-2,15,1,SANDSTONE)
Block(-2,15,2,SANDSTONE)
Block(-2,15,3,SANDSTONE)
Block(-2,15,4,SANDSTONE)
Block(-2,15,5,SANDSTONE)
Block(-2,15,6,SANDSTONE)
Block(-2,15,7,SANDSTONE)
Block(-2,15,8,SANDSTONE)
Block(-2,15,9,SANDSTONE)
Block(-2,15,10,SANDSTONE)
Block(-2,15,11,SANDSTONE)
Block(-2,15,12,SANDSTONE)
Block(-2,16,-4,SANDSTONE)
Block(-2,16,-3,SANDSTONE)
Block(-2,16,-2,SANDSTONE)
Block(-2,16,-1,SANDSTONE)
Block(-2,16,0,SANDSTONE)
Block(-2,16,1,SANDSTONE)
Block(-2,16,2,SANDSTONE)
Block(-2,16,3,SANDSTONE)
Block(-2,16,4,SANDSTONE)
Block(-2,16,5,SANDSTONE)
Block(-2,16,6,SANDSTONE)
Block(-2,16,7,SANDSTONE)
Block(-2,16,8,SANDSTONE)
Block(-2,16,9,SANDSTONE)
Block(-2,16,10,SANDSTONE)
Block(-2,16,11,SANDSTONE)
Block(-2,16,12,SANDSTONE)
Block(-2,17,-5,SANDSTONE)
Block(-2,17,-4,SANDSTONE)
Block(-2,17,-3,SANDSTONE)
Block(-2,17,-2,SANDSTONE)
Block(-2,17,-1,SANDSTONE)
Block(-2,17,0,SANDSTONE)
Block(-2,17,1,SANDSTONE)
Block(-2,17,2,SANDSTONE)
Block(-2,17,3,SANDSTONE)
Block(-2,17,4,SANDSTONE)
Block(-2,17,5,SANDSTONE)
Block(-2,17,6,SANDSTONE)
Block(-2,17,7,SANDSTONE)
Block(-2,17,8,SANDSTONE)
Block(-2,17,9,SANDSTONE)
Block(-2,17,10,SANDSTONE)
Block(-2,17,11,SANDSTONE)
Block(-2,17,12,SANDSTONE)
Block(-2,18,-5,SANDSTONE)
Block(-2,18,-4,SANDSTONE)
Block(-2,18,-3,SANDSTONE)
Block(-2,18,-2,SANDSTONE)
Block(-2,18,-1,SANDSTONE)
Block(-2,18,0,SANDSTONE)
Block(-2,18,1,SANDSTONE)
Block(-2,18,2,SANDSTONE)
Block(-2,18,3,SANDSTONE)
Block(-2,18,4,SANDSTONE)
Block(-2,18,5,SANDSTONE)
Block(-2,18,6,SANDSTONE)
Block(-2,18,7,SANDSTONE)
Block(-2,18,8,SANDSTONE)
Block(-2,18,9,SANDSTONE)
Block(-2,18,10,SANDSTONE)
Block(-2,18,11,SANDSTONE)
Block(-2,18,12,SANDSTONE)
Block(-2,18,13,SANDSTONE)
Block(-2,19,-5,SANDSTONE)
Block(-2,19,-4,SANDSTONE)
Block(-2,19,-3,SANDSTONE)
Block(-2,19,-2,SANDSTONE)
Block(-2,19,-1,SANDSTONE)
Block(-2,19,0,SANDSTONE)
Block(-2,19,1,SANDSTONE)
Block(-2,19,2,SANDSTONE)
Block(-2,19,3,SANDSTONE)
Block(-2,19,4,SANDSTONE)
Block(-2,19,5,SANDSTONE)
Block(-2,19,6,SANDSTONE)
Block(-2,19,7,SANDSTONE)
Block(-2,19,8,SANDSTONE)
Block(-2,19,9,SANDSTONE)
Block(-2,19,10,SANDSTONE)
Block(-2,19,11,SANDSTONE)
Block(-2,19,12,SANDSTONE)
Block(-2,19,13,SANDSTONE)
Block(-2,20,-5,SANDSTONE)
Block(-2,20,-4,SANDSTONE)
Block(-2,20,-3,SANDSTONE)
Block(-2,20,-2,SANDSTONE)
Block(-2,20,-1,SANDSTONE)
Block(-2,20,0,SANDSTONE)
Block(-2,20,1,SANDSTONE)
Block(-2,20,2,SANDSTONE)
Block(-2,20,3,SANDSTONE)
Block(-2,20,4,SANDSTONE)
Block(-2,20,5,SANDSTONE)
Block(-2,20,6,SANDSTONE)
Block(-2,20,7,SANDSTONE)
Block(-2,20,8,SANDSTONE)
Block(-2,20,9,SANDSTONE)
Block(-2,20,10,SANDSTONE)
Block(-2,20,11,SANDSTONE)
Block(-2,20,12,SANDSTONE)
Block(-2,20,13,SANDSTONE)
Block(-2,21,-5,SANDSTONE)
Block(-2,21,-4,SANDSTONE)
Block(-2,21,-3,SANDSTONE)
Block(-2,21,-2,SANDSTONE)
Block(-2,21,-1,SANDSTONE)
Block(-2,21,0,SANDSTONE)
Block(-2,21,1,SANDSTONE)
Block(-2,21,2,SANDSTONE)
Block(-2,21,3,SANDSTONE)
Block(-2,21,4,SANDSTONE)
Block(-2,21,5,SANDSTONE)
Block(-2,21,6,SANDSTONE)
Block(-2,21,7,SANDSTONE)
Block(-2,21,8,SANDSTONE)
Block(-2,21,9,SANDSTONE)
Block(-2,21,10,SANDSTONE)
Block(-2,21,11,SANDSTONE)
Block(-2,21,12,SANDSTONE)
Block(-2,21,13,SANDSTONE)
Block(-2,21,14,SANDSTONE)
Block(-2,22,-4,SANDSTONE)
Block(-2,22,-3,SANDSTONE)
Block(-2,22,-2,SANDSTONE)
Block(-2,22,-1,SANDSTONE)
Block(-2,22,0,SANDSTONE)
Block(-2,22,1,SANDSTONE)
Block(-2,22,2,SANDSTONE)
Block(-2,22,3,SANDSTONE)
Block(-2,22,4,SANDSTONE)
Block(-2,22,5,SANDSTONE)
Block(-2,22,6,SANDSTONE)
Block(-2,22,7,SANDSTONE)
Block(-2,22,8,SANDSTONE)
Block(-2,22,9,SANDSTONE)
Block(-2,22,10,SANDSTONE)
Block(-2,22,11,SANDSTONE)
Block(-2,22,12,SANDSTONE)
Block(-2,22,13,SANDSTONE)
Block(-2,22,14,SANDSTONE)
Block(-2,23,-3,SANDSTONE)
Block(-2,23,-2,SANDSTONE)
Block(-2,23,-1,SANDSTONE)
Block(-2,23,0,SANDSTONE)
Block(-2,23,1,SANDSTONE)
Block(-2,23,2,SANDSTONE)
Block(-2,23,3,SANDSTONE)
Block(-2,23,4,SANDSTONE)
Block(-2,23,5,SANDSTONE)
Block(-2,23,6,SANDSTONE)
Block(-2,23,7,SANDSTONE)
Block(-2,23,8,SANDSTONE)
Block(-2,23,9,SANDSTONE)
Block(-2,23,10,SANDSTONE)
Block(-2,23,11,SANDSTONE)
Block(-2,23,12,SANDSTONE)
Block(-2,23,13,SANDSTONE)
Block(-2,23,14,SANDSTONE)
Block(-2,23,15,SANDSTONE)
Block(-2,24,-2,SANDSTONE)
Block(-2,24,-1,SANDSTONE)
Block(-2,24,0,SANDSTONE)
Block(-2,24,1,SANDSTONE)
Block(-2,24,2,SANDSTONE)
Block(-2,24,3,SANDSTONE)
Block(-2,24,4,SANDSTONE)
Block(-2,24,5,SANDSTONE)
Block(-2,24,6,SANDSTONE)
Block(-2,24,7,SANDSTONE)
Block(-2,24,8,SANDSTONE)
Block(-2,24,9,SANDSTONE)
Block(-2,24,10,SANDSTONE)
Block(-2,24,11,SANDSTONE)
Block(-2,24,12,SANDSTONE)
Block(-2,24,13,SANDSTONE)
Block(-2,24,14,SANDSTONE)
Block(-2,24,15,SANDSTONE)
Block(-2,25,0,SANDSTONE)
Block(-2,25,1,SANDSTONE)
Block(-2,25,2,SANDSTONE)
Block(-2,25,3,SANDSTONE)
Block(-2,25,4,SANDSTONE)
Block(-2,25,5,SANDSTONE)
Block(-2,25,6,SANDSTONE)
Block(-2,25,7,SANDSTONE)
Block(-2,25,8,SANDSTONE)
Block(-2,25,9,SANDSTONE)
Block(-2,25,10,SANDSTONE)
Block(-2,25,11,SANDSTONE)
Block(-2,25,12,SANDSTONE)
Block(-2,25,13,SANDSTONE)
Block(-2,25,14,SANDSTONE)
Block(-2,25,15,SANDSTONE)
Block(-2,26,1,SANDSTONE)
Block(-2,26,2,SANDSTONE)
Block(-2,26,3,SANDSTONE)
Block(-2,26,4,SANDSTONE)
Block(-2,26,5,SANDSTONE)
Block(-2,26,6,SANDSTONE)
Block(-2,26,7,SANDSTONE)
Block(-2,26,8,SANDSTONE)
Block(-2,26,9,SANDSTONE)
Block(-2,26,10,SANDSTONE)
Block(-2,26,11,SANDSTONE)
Block(-2,26,12,SANDSTONE)
Block(-2,26,13,SANDSTONE)
Block(-2,26,14,SANDSTONE)
Block(-2,26,15,SANDSTONE)
Block(-2,27,3,SANDSTONE)
Block(-2,27,4,SANDSTONE)
Block(-2,27,5,SANDSTONE)
Block(-2,27,6,SANDSTONE)
Block(-2,27,7,SANDSTONE)
Block(-2,27,8,SANDSTONE)
Block(-2,27,9,SANDSTONE)
Block(-2,27,10,SANDSTONE)
Block(-2,27,11,SANDSTONE)
Block(-2,27,12,SANDSTONE)
Block(-2,27,13,SANDSTONE)
Block(-2,27,14,SANDSTONE)
Block(-2,27,15,SANDSTONE)
Block(-2,28,4,SANDSTONE)
Block(-2,28,5,SANDSTONE)
Block(-2,28,6,SANDSTONE)
Block(-2,28,7,SANDSTONE)
Block(-2,28,8,SANDSTONE)
Block(-2,28,9,SANDSTONE)
Block(-2,28,10,SANDSTONE)
Block(-2,28,11,SANDSTONE)
Block(-2,28,12,SANDSTONE)
Block(-2,28,13,SANDSTONE)
Block(-2,28,14,SANDSTONE)
Block(-2,29,6,SANDSTONE)
Block(-2,29,7,SANDSTONE)
Block(-2,29,8,SANDSTONE)
Block(-2,29,9,SANDSTONE)
Block(-2,29,10,SANDSTONE)
Block(-2,29,11,SANDSTONE)
Block(-2,29,12,SANDSTONE)
Block(-2,29,13,SANDSTONE)
Block(-2,29,14,SANDSTONE)
Block(-2,30,9,SANDSTONE)
Block(-2,30,10,SANDSTONE)
Block(-2,30,11,SANDSTONE)
Block(-1,9,2,SANDSTONE)
Block(-1,10,1,SANDSTONE)
Block(-1,10,2,SANDSTONE)
Block(-1,10,3,SANDSTONE)
Block(-1,10,4,SANDSTONE)
Block(-1,10,5,SANDSTONE)
Block(-1,10,6,SANDSTONE)
Block(-1,10,7,SANDSTONE)
Block(-1,10,8,SANDSTONE)
Block(-1,10,9,SANDSTONE)
Block(-1,10,10,SANDSTONE)
Block(-1,11,1,SANDSTONE)
Block(-1,11,2,SANDSTONE)
Block(-1,11,3,SANDSTONE)
Block(-1,11,4,SANDSTONE)
Block(-1,11,5,SANDSTONE)
Block(-1,11,6,SANDSTONE)
Block(-1,11,7,SANDSTONE)
Block(-1,11,8,SANDSTONE)
Block(-1,11,9,SANDSTONE)
Block(-1,11,10,SANDSTONE)
Block(-1,11,11,SANDSTONE)
Block(-1,11,12,SANDSTONE)
Block(-1,12,0,SANDSTONE)
Block(-1,12,1,SANDSTONE)
Block(-1,12,2,SANDSTONE)
Block(-1,12,3,SANDSTONE)
Block(-1,12,4,SANDSTONE)
Block(-1,12,5,SANDSTONE)
Block(-1,12,6,SANDSTONE)
Block(-1,12,7,SANDSTONE)
Block(-1,12,8,SANDSTONE)
Block(-1,12,9,SANDSTONE)
Block(-1,12,10,SANDSTONE)
Block(-1,12,11,SANDSTONE)
Block(-1,12,12,SANDSTONE)
Block(-1,13,-1,SANDSTONE)
Block(-1,13,0,SANDSTONE)
Block(-1,13,1,SANDSTONE)
Block(-1,13,2,SANDSTONE)
Block(-1,13,3,SANDSTONE)
Block(-1,13,4,SANDSTONE)
Block(-1,13,5,SANDSTONE)
Block(-1,13,6,SANDSTONE)
Block(-1,13,7,SANDSTONE)
Block(-1,13,8,SANDSTONE)
Block(-1,13,9,SANDSTONE)
Block(-1,13,10,SANDSTONE)
Block(-1,13,11,SANDSTONE)
Block(-1,13,12,SANDSTONE)
Block(-1,14,-2,SANDSTONE)
Block(-1,14,-1,SANDSTONE)
Block(-1,14,0,SANDSTONE)
Block(-1,14,1,SANDSTONE)
Block(-1,14,2,SANDSTONE)
Block(-1,14,3,SANDSTONE)
Block(-1,14,4,SANDSTONE)
Block(-1,14,5,SANDSTONE)
Block(-1,14,6,SANDSTONE)
Block(-1,14,7,SANDSTONE)
Block(-1,14,8,SANDSTONE)
Block(-1,14,9,SANDSTONE)
Block(-1,14,10,SANDSTONE)
Block(-1,14,11,SANDSTONE)
Block(-1,14,12,SANDSTONE)
Block(-1,15,-3,SANDSTONE)
Block(-1,15,-2,SANDSTONE)
Block(-1,15,-1,SANDSTONE)
Block(-1,15,0,SANDSTONE)
Block(-1,15,1,SANDSTONE)
Block(-1,15,2,SANDSTONE)
Block(-1,15,3,SANDSTONE)
Block(-1,15,4,SANDSTONE)
Block(-1,15,5,SANDSTONE)
Block(-1,15,6,SANDSTONE)
Block(-1,15,7,SANDSTONE)
Block(-1,15,8,SANDSTONE)
Block(-1,15,9,SANDSTONE)
Block(-1,15,10,SANDSTONE)
Block(-1,15,11,SANDSTONE)
Block(-1,15,12,SANDSTONE)
Block(-1,15,13,SANDSTONE)
Block(-1,16,-4,SANDSTONE)
Block(-1,16,-3,SANDSTONE)
Block(-1,16,-2,SANDSTONE)
Block(-1,16,-1,SANDSTONE)
Block(-1,16,0,SANDSTONE)
Block(-1,16,1,SANDSTONE)
Block(-1,16,2,SANDSTONE)
Block(-1,16,3,SANDSTONE)
Block(-1,16,4,SANDSTONE)
Block(-1,16,5,SANDSTONE)
Block(-1,16,6,SANDSTONE)
Block(-1,16,7,SANDSTONE)
Block(-1,16,8,SANDSTONE)
Block(-1,16,9,SANDSTONE)
Block(-1,16,10,SANDSTONE)
Block(-1,16,11,SANDSTONE)
Block(-1,16,12,SANDSTONE)
Block(-1,16,13,SANDSTONE)
Block(-1,17,-5,SANDSTONE)
Block(-1,17,-4,SANDSTONE)
Block(-1,17,-3,SANDSTONE)
Block(-1,17,-2,SANDSTONE)
Block(-1,17,-1,SANDSTONE)
Block(-1,17,0,SANDSTONE)
Block(-1,17,1,SANDSTONE)
Block(-1,17,2,SANDSTONE)
Block(-1,17,3,SANDSTONE)
Block(-1,17,4,SANDSTONE)
Block(-1,17,5,SANDSTONE)
Block(-1,17,6,SANDSTONE)
Block(-1,17,7,SANDSTONE)
Block(-1,17,8,SANDSTONE)
Block(-1,17,9,SANDSTONE)
Block(-1,17,10,SANDSTONE)
Block(-1,17,11,SANDSTONE)
Block(-1,17,12,SANDSTONE)
Block(-1,17,13,SANDSTONE)
Block(-1,18,-6,SANDSTONE)
Block(-1,18,-5,SANDSTONE)
Block(-1,18,-4,SANDSTONE)
Block(-1,18,-3,SANDSTONE)
Block(-1,18,-2,SANDSTONE)
Block(-1,18,-1,SANDSTONE)
Block(-1,18,0,SANDSTONE)
Block(-1,18,1,SANDSTONE)
Block(-1,18,2,SANDSTONE)
Block(-1,18,3,SANDSTONE)
Block(-1,18,4,SANDSTONE)
Block(-1,18,5,SANDSTONE)
Block(-1,18,6,SANDSTONE)
Block(-1,18,7,SANDSTONE)
Block(-1,18,8,SANDSTONE)
Block(-1,18,9,SANDSTONE)
Block(-1,18,10,SANDSTONE)
Block(-1,18,11,SANDSTONE)
Block(-1,18,12,SANDSTONE)
Block(-1,18,13,SANDSTONE)
Block(-1,18,14,SANDSTONE)
Block(-1,19,-6,SANDSTONE)
Block(-1,19,-5,SANDSTONE)
Block(-1,19,-4,SANDSTONE)
Block(-1,19,-3,SANDSTONE)
Block(-1,19,-2,SANDSTONE)
Block(-1,19,-1,SANDSTONE)
Block(-1,19,0,SANDSTONE)
Block(-1,19,1,SANDSTONE)
Block(-1,19,2,SANDSTONE)
Block(-1,19,3,SANDSTONE)
Block(-1,19,4,SANDSTONE)
Block(-1,19,5,SANDSTONE)
Block(-1,19,6,SANDSTONE)
Block(-1,19,7,SANDSTONE)
Block(-1,19,8,SANDSTONE)
Block(-1,19,9,SANDSTONE)
Block(-1,19,10,SANDSTONE)
Block(-1,19,11,SANDSTONE)
Block(-1,19,12,SANDSTONE)
Block(-1,19,13,SANDSTONE)
Block(-1,19,14,SANDSTONE)
Block(-1,20,-6,SANDSTONE)
Block(-1,20,-5,SANDSTONE)
Block(-1,20,-4,SANDSTONE)
Block(-1,20,-3,SANDSTONE)
Block(-1,20,-2,SANDSTONE)
Block(-1,20,-1,SANDSTONE)
Block(-1,20,0,SANDSTONE)
Block(-1,20,1,SANDSTONE)
Block(-1,20,2,SANDSTONE)
Block(-1,20,3,SANDSTONE)
Block(-1,20,4,SANDSTONE)
Block(-1,20,5,SANDSTONE)
Block(-1,20,6,SANDSTONE)
Block(-1,20,7,SANDSTONE)
Block(-1,20,8,SANDSTONE)
Block(-1,20,9,SANDSTONE)
Block(-1,20,10,SANDSTONE)
Block(-1,20,11,SANDSTONE)
Block(-1,20,12,SANDSTONE)
Block(-1,20,13,SANDSTONE)
Block(-1,20,14,SANDSTONE)
Block(-1,20,15,SANDSTONE)
Block(-1,21,-6,SANDSTONE)
Block(-1,21,-5,SANDSTONE)
Block(-1,21,-4,SANDSTONE)
Block(-1,21,-3,SANDSTONE)
Block(-1,21,-2,SANDSTONE)
Block(-1,21,-1,SANDSTONE)
Block(-1,21,0,SANDSTONE)
Block(-1,21,1,SANDSTONE)
Block(-1,21,2,SANDSTONE)
Block(-1,21,3,SANDSTONE)
Block(-1,21,4,SANDSTONE)
Block(-1,21,5,SANDSTONE)
Block(-1,21,6,SANDSTONE)
Block(-1,21,7,SANDSTONE)
Block(-1,21,8,SANDSTONE)
Block(-1,21,9,SANDSTONE)
Block(-1,21,10,SANDSTONE)
Block(-1,21,11,SANDSTONE)
Block(-1,21,12,SANDSTONE)
Block(-1,21,13,SANDSTONE)
Block(-1,21,14,SANDSTONE)
Block(-1,21,15,SANDSTONE)
Block(-1,22,-5,SANDSTONE)
Block(-1,22,-4,SANDSTONE)
Block(-1,22,-3,SANDSTONE)
Block(-1,22,-2,SANDSTONE)
Block(-1,22,-1,SANDSTONE)
Block(-1,22,0,SANDSTONE)
Block(-1,22,1,SANDSTONE)
Block(-1,22,2,SANDSTONE)
Block(-1,22,3,SANDSTONE)
Block(-1,22,4,SANDSTONE)
Block(-1,22,5,SANDSTONE)
Block(-1,22,6,SANDSTONE)
Block(-1,22,7,SANDSTONE)
Block(-1,22,8,SANDSTONE)
Block(-1,22,9,SANDSTONE)
Block(-1,22,10,SANDSTONE)
Block(-1,22,11,SANDSTONE)
Block(-1,22,12,SANDSTONE)
Block(-1,22,13,SANDSTONE)
Block(-1,22,14,SANDSTONE)
Block(-1,22,15,SANDSTONE)
Block(-1,22,16,SANDSTONE)
Block(-1,23,-4,SANDSTONE)
Block(-1,23,-3,SANDSTONE)
Block(-1,23,-2,SANDSTONE)
Block(-1,23,-1,SANDSTONE)
Block(-1,23,0,SANDSTONE)
Block(-1,23,1,SANDSTONE)
Block(-1,23,2,SANDSTONE)
Block(-1,23,3,SANDSTONE)
Block(-1,23,4,SANDSTONE)
Block(-1,23,5,SANDSTONE)
Block(-1,23,6,SANDSTONE)
Block(-1,23,7,SANDSTONE)
Block(-1,23,8,SANDSTONE)
Block(-1,23,9,SANDSTONE)
Block(-1,23,10,SANDSTONE)
Block(-1,23,11,SANDSTONE)
Block(-1,23,12,SANDSTONE)
Block(-1,23,13,SANDSTONE)
Block(-1,23,14,SANDSTONE)
Block(-1,23,15,SANDSTONE)
Block(-1,23,16,SANDSTONE)
Block(-1,24,-3,SANDSTONE)
Block(-1,24,-2,SANDSTONE)
Block(-1,24,-1,SANDSTONE)
Block(-1,24,0,SANDSTONE)
Block(-1,24,1,SANDSTONE)
Block(-1,24,2,SANDSTONE)
Block(-1,24,3,SANDSTONE)
Block(-1,24,4,SANDSTONE)
Block(-1,24,5,SANDSTONE)
Block(-1,24,6,SANDSTONE)
Block(-1,24,7,SANDSTONE)
Block(-1,24,8,SANDSTONE)
Block(-1,24,9,SANDSTONE)
Block(-1,24,10,SANDSTONE)
Block(-1,24,11,SANDSTONE)
Block(-1,24,12,SANDSTONE)
Block(-1,24,13,SANDSTONE)
Block(-1,24,14,SANDSTONE)
Block(-1,24,15,SANDSTONE)
Block(-1,24,16,SANDSTONE)
Block(-1,25,-2,SANDSTONE)
Block(-1,25,-1,SANDSTONE)
Block(-1,25,0,SANDSTONE)
Block(-1,25,1,SANDSTONE)
Block(-1,25,2,SANDSTONE)
Block(-1,25,3,SANDSTONE)
Block(-1,25,4,SANDSTONE)
Block(-1,25,5,SANDSTONE)
Block(-1,25,6,SANDSTONE)
Block(-1,25,7,SANDSTONE)
Block(-1,25,8,SANDSTONE)
Block(-1,25,9,SANDSTONE)
Block(-1,25,10,SANDSTONE)
Block(-1,25,11,SANDSTONE)
Block(-1,25,12,SANDSTONE)
Block(-1,25,13,SANDSTONE)
Block(-1,25,14,SANDSTONE)
Block(-1,25,15,SANDSTONE)
Block(-1,25,16,SANDSTONE)
Block(-1,26,0,SANDSTONE)
Block(-1,26,1,SANDSTONE)
Block(-1,26,2,SANDSTONE)
Block(-1,26,3,SANDSTONE)
Block(-1,26,4,SANDSTONE)
Block(-1,26,5,SANDSTONE)
Block(-1,26,6,SANDSTONE)
Block(-1,26,7,SANDSTONE)
Block(-1,26,8,SANDSTONE)
Block(-1,26,9,SANDSTONE)
Block(-1,26,10,SANDSTONE)
Block(-1,26,11,SANDSTONE)
Block(-1,26,12,SANDSTONE)
Block(-1,26,13,SANDSTONE)
Block(-1,26,14,SANDSTONE)
Block(-1,26,15,SANDSTONE)
Block(-1,26,16,SANDSTONE)
Block(-1,27,1,SANDSTONE)
Block(-1,27,2,SANDSTONE)
Block(-1,27,3,SANDSTONE)
Block(-1,27,4,SANDSTONE)
Block(-1,27,5,SANDSTONE)
Block(-1,27,6,SANDSTONE)
Block(-1,27,7,SANDSTONE)
Block(-1,27,8,SANDSTONE)
Block(-1,27,9,SANDSTONE)
Block(-1,27,10,SANDSTONE)
Block(-1,27,11,SANDSTONE)
Block(-1,27,12,SANDSTONE)
Block(-1,27,13,SANDSTONE)
Block(-1,27,14,SANDSTONE)
Block(-1,27,15,SANDSTONE)
Block(-1,28,3,SANDSTONE)
Block(-1,28,4,SANDSTONE)
Block(-1,28,5,SANDSTONE)
Block(-1,28,6,SANDSTONE)
Block(-1,28,7,SANDSTONE)
Block(-1,28,8,SANDSTONE)
Block(-1,28,9,SANDSTONE)
Block(-1,28,10,SANDSTONE)
Block(-1,28,11,SANDSTONE)
Block(-1,28,12,SANDSTONE)
Block(-1,28,13,SANDSTONE)
Block(-1,28,14,SANDSTONE)
Block(-1,28,15,SANDSTONE)
Block(-1,29,5,SANDSTONE)
Block(-1,29,6,SANDSTONE)
Block(-1,29,7,SANDSTONE)
Block(-1,29,8,SANDSTONE)
Block(-1,29,9,SANDSTONE)
Block(-1,29,10,SANDSTONE)
Block(-1,29,11,SANDSTONE)
Block(-1,29,12,SANDSTONE)
Block(-1,29,13,SANDSTONE)
Block(-1,29,14,SANDSTONE)
Block(-1,30,7,SANDSTONE)
Block(-1,30,8,SANDSTONE)
Block(-1,30,9,SANDSTONE)
Block(-1,30,10,SANDSTONE)
Block(-1,30,11,SANDSTONE)
Block(-1,30,12,SANDSTONE)
Block(-1,30,13,SANDSTONE)
Block(-1,30,14,SANDSTONE)
Block(0,9,2,SANDSTONE)
Block(0,9,3,SANDSTONE)
Block(0,9,4,SANDSTONE)
Block(0,9,5,SANDSTONE)
Block(0,9,6,SANDSTONE)
Block(0,10,1,SANDSTONE)
Block(0,10,2,SANDSTONE)
Block(0,10,3,SANDSTONE)
Block(0,10,4,SANDSTONE)
Block(0,10,5,SANDSTONE)
Block(0,10,6,SANDSTONE)
Block(0,10,7,SANDSTONE)
Block(0,10,8,SANDSTONE)
Block(0,10,9,SANDSTONE)
Block(0,10,10,SANDSTONE)
Block(0,10,11,SANDSTONE)
Block(0,10,12,SANDSTONE)
Block(0,10,13,SANDSTONE)
Block(0,11,1,SANDSTONE)
Block(0,11,2,SANDSTONE)
Block(0,11,3,SANDSTONE)
Block(0,11,4,SANDSTONE)
Block(0,11,5,SANDSTONE)
Block(0,11,6,SANDSTONE)
Block(0,11,7,SANDSTONE)
Block(0,11,8,SANDSTONE)
Block(0,11,9,SANDSTONE)
Block(0,11,10,SANDSTONE)
Block(0,11,11,SANDSTONE)
Block(0,11,12,SANDSTONE)
Block(0,11,13,SANDSTONE)
Block(0,12,-1,SANDSTONE)
Block(0,12,0,SANDSTONE)
Block(0,12,1,SANDSTONE)
Block(0,12,2,SANDSTONE)
Block(0,12,3,SANDSTONE)
Block(0,12,4,SANDSTONE)
Block(0,12,5,SANDSTONE)
Block(0,12,6,SANDSTONE)
Block(0,12,7,SANDSTONE)
Block(0,12,8,SANDSTONE)
Block(0,12,9,SANDSTONE)
Block(0,12,10,SANDSTONE)
Block(0,12,11,SANDSTONE)
Block(0,12,12,SANDSTONE)
Block(0,12,13,SANDSTONE)
Block(0,13,-2,SANDSTONE)
Block(0,13,-1,SANDSTONE)
Block(0,13,0,SANDSTONE)
Block(0,13,1,SANDSTONE)
Block(0,13,2,SANDSTONE)
Block(0,13,3,SANDSTONE)
Block(0,13,4,SANDSTONE)
Block(0,13,5,SANDSTONE)
Block(0,13,6,SANDSTONE)
Block(0,13,7,SANDSTONE)
Block(0,13,8,SANDSTONE)
Block(0,13,9,SANDSTONE)
Block(0,13,10,SANDSTONE)
Block(0,13,11,SANDSTONE)
Block(0,13,12,SANDSTONE)
Block(0,13,13,SANDSTONE)
Block(0,13,14,SANDSTONE)
Block(0,14,-3,SANDSTONE)
Block(0,14,-2,SANDSTONE)
Block(0,14,-1,SANDSTONE)
Block(0,14,0,SANDSTONE)
Block(0,14,1,SANDSTONE)
Block(0,14,2,SANDSTONE)
Block(0,14,3,SANDSTONE)
Block(0,14,4,SANDSTONE)
Block(0,14,5,SANDSTONE)
Block(0,14,6,SANDSTONE)
Block(0,14,7,SANDSTONE)
Block(0,14,8,SANDSTONE)
Block(0,14,9,SANDSTONE)
Block(0,14,10,SANDSTONE)
Block(0,14,11,SANDSTONE)
Block(0,14,12,SANDSTONE)
Block(0,14,13,SANDSTONE)
Block(0,14,14,SANDSTONE)
Block(0,15,-3,SANDSTONE)
Block(0,15,-2,SANDSTONE)
Block(0,15,-1,SANDSTONE)
Block(0,15,0,SANDSTONE)
Block(0,15,1,SANDSTONE)
Block(0,15,2,SANDSTONE)
Block(0,15,3,SANDSTONE)
Block(0,15,4,SANDSTONE)
Block(0,15,5,SANDSTONE)
Block(0,15,6,SANDSTONE)
Block(0,15,7,SANDSTONE)
Block(0,15,8,SANDSTONE)
Block(0,15,9,SANDSTONE)
Block(0,15,10,SANDSTONE)
Block(0,15,11,SANDSTONE)
Block(0,15,12,SANDSTONE)
Block(0,15,13,SANDSTONE)
Block(0,15,14,SANDSTONE)
Block(0,16,-4,SANDSTONE)
Block(0,16,-3,SANDSTONE)
Block(0,16,-2,SANDSTONE)
Block(0,16,-1,SANDSTONE)
Block(0,16,0,SANDSTONE)
Block(0,16,1,SANDSTONE)
Block(0,16,2,SANDSTONE)
Block(0,16,3,SANDSTONE)
Block(0,16,4,SANDSTONE)
Block(0,16,5,SANDSTONE)
Block(0,16,6,SANDSTONE)
Block(0,16,7,SANDSTONE)
Block(0,16,8,SANDSTONE)
Block(0,16,9,SANDSTONE)
Block(0,16,10,SANDSTONE)
Block(0,16,11,SANDSTONE)
Block(0,16,12,SANDSTONE)
Block(0,16,13,SANDSTONE)
Block(0,16,14,SANDSTONE)
Block(0,17,-5,SANDSTONE)
Block(0,17,-4,SANDSTONE)
Block(0,17,-3,SANDSTONE)
Block(0,17,-2,SANDSTONE)
Block(0,17,-1,SANDSTONE)
Block(0,17,0,SANDSTONE)
Block(0,17,1,SANDSTONE)
Block(0,17,2,SANDSTONE)
Block(0,17,3,SANDSTONE)
Block(0,17,4,SANDSTONE)
Block(0,17,5,SANDSTONE)
Block(0,17,6,SANDSTONE)
Block(0,17,7,SANDSTONE)
Block(0,17,8,SANDSTONE)
Block(0,17,9,SANDSTONE)
Block(0,17,10,SANDSTONE)
Block(0,17,11,SANDSTONE)
Block(0,17,12,SANDSTONE)
Block(0,17,13,SANDSTONE)
Block(0,17,14,SANDSTONE)
Block(0,17,15,SANDSTONE)
Block(0,18,-6,SANDSTONE)
Block(0,18,-5,SANDSTONE)
Block(0,18,-4,SANDSTONE)
Block(0,18,-3,SANDSTONE)
Block(0,18,-2,SANDSTONE)
Block(0,18,-1,SANDSTONE)
Block(0,18,0,SANDSTONE)
Block(0,18,1,SANDSTONE)
Block(0,18,2,SANDSTONE)
Block(0,18,3,SANDSTONE)
Block(0,18,4,SANDSTONE)
Block(0,18,5,SANDSTONE)
Block(0,18,6,SANDSTONE)
Block(0,18,7,SANDSTONE)
Block(0,18,8,SANDSTONE)
Block(0,18,9,SANDSTONE)
Block(0,18,10,SANDSTONE)
Block(0,18,11,SANDSTONE)
Block(0,18,12,SANDSTONE)
Block(0,18,13,SANDSTONE)
Block(0,18,14,SANDSTONE)
Block(0,18,15,SANDSTONE)
Block(0,19,-6,SANDSTONE)
Block(0,19,-5,SANDSTONE)
Block(0,19,-4,SANDSTONE)
Block(0,19,-3,SANDSTONE)
Block(0,19,-2,SANDSTONE)
Block(0,19,-1,SANDSTONE)
Block(0,19,0,SANDSTONE)
Block(0,19,1,SANDSTONE)
Block(0,19,2,SANDSTONE)
Block(0,19,3,SANDSTONE)
Block(0,19,4,SANDSTONE)
Block(0,19,5,SANDSTONE)
Block(0,19,6,SANDSTONE)
Block(0,19,7,SANDSTONE)
Block(0,19,8,SANDSTONE)
Block(0,19,9,SANDSTONE)
Block(0,19,10,SANDSTONE)
Block(0,19,11,SANDSTONE)
Block(0,19,12,SANDSTONE)
Block(0,19,13,SANDSTONE)
Block(0,19,14,SANDSTONE)
Block(0,19,15,SANDSTONE)
Block(0,20,-6,SANDSTONE)
Block(0,20,-5,SANDSTONE)
Block(0,20,-4,SANDSTONE)
Block(0,20,-3,SANDSTONE)
Block(0,20,-2,SANDSTONE)
Block(0,20,-1,SANDSTONE)
Block(0,20,0,SANDSTONE)
Block(0,20,1,SANDSTONE)
Block(0,20,2,SANDSTONE)
Block(0,20,3,SANDSTONE)
Block(0,20,4,SANDSTONE)
Block(0,20,5,SANDSTONE)
Block(0,20,6,SANDSTONE)
Block(0,20,7,SANDSTONE)
Block(0,20,8,SANDSTONE)
Block(0,20,9,SANDSTONE)
Block(0,20,10,SANDSTONE)
Block(0,20,11,SANDSTONE)
Block(0,20,12,SANDSTONE)
Block(0,20,13,SANDSTONE)
Block(0,20,14,SANDSTONE)
Block(0,20,15,SANDSTONE)
Block(0,20,16,SANDSTONE)
Block(0,21,-6,SANDSTONE)
Block(0,21,-5,SANDSTONE)
Block(0,21,-4,SANDSTONE)
Block(0,21,-3,SANDSTONE)
Block(0,21,-2,SANDSTONE)
Block(0,21,-1,SANDSTONE)
Block(0,21,0,SANDSTONE)
Block(0,21,1,SANDSTONE)
Block(0,21,2,SANDSTONE)
Block(0,21,3,SANDSTONE)
Block(0,21,4,SANDSTONE)
Block(0,21,5,SANDSTONE)
Block(0,21,6,SANDSTONE)
Block(0,21,7,SANDSTONE)
Block(0,21,8,SANDSTONE)
Block(0,21,9,SANDSTONE)
Block(0,21,10,SANDSTONE)
Block(0,21,11,SANDSTONE)
Block(0,21,12,SANDSTONE)
Block(0,21,13,SANDSTONE)
Block(0,21,14,SANDSTONE)
Block(0,21,15,SANDSTONE)
Block(0,21,16,SANDSTONE)
Block(0,22,-6,SANDSTONE)
Block(0,22,-5,SANDSTONE)
Block(0,22,-4,SANDSTONE)
Block(0,22,-3,SANDSTONE)
Block(0,22,-2,SANDSTONE)
Block(0,22,-1,SANDSTONE)
Block(0,22,0,SANDSTONE)
Block(0,22,1,SANDSTONE)
Block(0,22,2,SANDSTONE)
Block(0,22,3,SANDSTONE)
Block(0,22,4,SANDSTONE)
Block(0,22,5,SANDSTONE)
Block(0,22,6,SANDSTONE)
Block(0,22,7,SANDSTONE)
Block(0,22,8,SANDSTONE)
Block(0,22,9,SANDSTONE)
Block(0,22,10,SANDSTONE)
Block(0,22,11,SANDSTONE)
Block(0,22,12,SANDSTONE)
Block(0,22,13,SANDSTONE)
Block(0,22,14,SANDSTONE)
Block(0,22,15,SANDSTONE)
Block(0,22,16,SANDSTONE)
Block(0,23,-5,SANDSTONE)
Block(0,23,-4,SANDSTONE)
Block(0,23,-3,SANDSTONE)
Block(0,23,-2,SANDSTONE)
Block(0,23,-1,SANDSTONE)
Block(0,23,0,SANDSTONE)
Block(0,23,1,SANDSTONE)
Block(0,23,2,SANDSTONE)
Block(0,23,3,SANDSTONE)
Block(0,23,4,SANDSTONE)
Block(0,23,5,SANDSTONE)
Block(0,23,6,SANDSTONE)
Block(0,23,7,SANDSTONE)
Block(0,23,8,SANDSTONE)
Block(0,23,9,SANDSTONE)
Block(0,23,10,SANDSTONE)
Block(0,23,11,SANDSTONE)
Block(0,23,12,SANDSTONE)
Block(0,23,13,SANDSTONE)
Block(0,23,14,SANDSTONE)
Block(0,23,15,SANDSTONE)
Block(0,23,16,SANDSTONE)
Block(0,24,-4,SANDSTONE)
Block(0,24,-3,SANDSTONE)
Block(0,24,-2,SANDSTONE)
Block(0,24,-1,SANDSTONE)
Block(0,24,0,SANDSTONE)
Block(0,24,1,SANDSTONE)
Block(0,24,2,SANDSTONE)
Block(0,24,3,SANDSTONE)
Block(0,24,4,SANDSTONE)
Block(0,24,5,SANDSTONE)
Block(0,24,6,SANDSTONE)
Block(0,24,7,SANDSTONE)
Block(0,24,8,SANDSTONE)
Block(0,24,9,SANDSTONE)
Block(0,24,10,SANDSTONE)
Block(0,24,11,SANDSTONE)
Block(0,24,12,SANDSTONE)
Block(0,24,13,SANDSTONE)
Block(0,24,14,SANDSTONE)
Block(0,24,15,SANDSTONE)
Block(0,24,16,SANDSTONE)
Block(0,25,-3,SANDSTONE)
Block(0,25,-2,SANDSTONE)
Block(0,25,-1,SANDSTONE)
Block(0,25,0,SANDSTONE)
Block(0,25,1,SANDSTONE)
Block(0,25,2,SANDSTONE)
Block(0,25,3,SANDSTONE)
Block(0,25,4,SANDSTONE)
Block(0,25,5,SANDSTONE)
Block(0,25,6,SANDSTONE)
Block(0,25,7,SANDSTONE)
Block(0,25,8,SANDSTONE)
Block(0,25,9,SANDSTONE)
Block(0,25,10,SANDSTONE)
Block(0,25,11,SANDSTONE)
Block(0,25,12,SANDSTONE)
Block(0,25,13,SANDSTONE)
Block(0,25,14,SANDSTONE)
Block(0,25,15,SANDSTONE)
Block(0,25,16,SANDSTONE)
Block(0,26,-2,SANDSTONE)
Block(0,26,-1,SANDSTONE)
Block(0,26,0,SANDSTONE)
Block(0,26,1,SANDSTONE)
Block(0,26,2,SANDSTONE)
Block(0,26,3,SANDSTONE)
Block(0,26,4,SANDSTONE)
Block(0,26,5,SANDSTONE)
Block(0,26,6,SANDSTONE)
Block(0,26,7,SANDSTONE)
Block(0,26,8,SANDSTONE)
Block(0,26,9,SANDSTONE)
Block(0,26,10,SANDSTONE)
Block(0,26,11,SANDSTONE)
Block(0,26,12,SANDSTONE)
Block(0,26,13,SANDSTONE)
Block(0,26,14,SANDSTONE)
Block(0,26,15,SANDSTONE)
Block(0,26,16,SANDSTONE)
Block(0,27,0,SANDSTONE)
Block(0,27,1,SANDSTONE)
Block(0,27,2,SANDSTONE)
Block(0,27,3,SANDSTONE)
Block(0,27,4,SANDSTONE)
Block(0,27,5,SANDSTONE)
Block(0,27,6,SANDSTONE)
Block(0,27,7,SANDSTONE)
Block(0,27,8,SANDSTONE)
Block(0,27,9,SANDSTONE)
Block(0,27,10,SANDSTONE)
Block(0,27,11,SANDSTONE)
Block(0,27,12,SANDSTONE)
Block(0,27,13,SANDSTONE)
Block(0,27,14,SANDSTONE)
Block(0,27,15,SANDSTONE)
Block(0,27,16,SANDSTONE)
Block(0,28,2,SANDSTONE)
Block(0,28,3,SANDSTONE)
Block(0,28,4,SANDSTONE)
Block(0,28,5,SANDSTONE)
Block(0,28,6,SANDSTONE)
Block(0,28,7,SANDSTONE)
Block(0,28,8,SANDSTONE)
Block(0,28,9,SANDSTONE)
Block(0,28,10,SANDSTONE)
Block(0,28,11,SANDSTONE)
Block(0,28,12,SANDSTONE)
Block(0,28,13,SANDSTONE)
Block(0,28,14,SANDSTONE)
Block(0,28,15,SANDSTONE)
Block(0,29,3,SANDSTONE)
Block(0,29,4,SANDSTONE)
Block(0,29,5,SANDSTONE)
Block(0,29,6,SANDSTONE)
Block(0,29,7,SANDSTONE)
Block(0,29,8,SANDSTONE)
Block(0,29,9,SANDSTONE)
Block(0,29,10,SANDSTONE)
Block(0,29,11,SANDSTONE)
Block(0,29,12,SANDSTONE)
Block(0,29,13,SANDSTONE)
Block(0,29,14,SANDSTONE)
Block(0,29,15,SANDSTONE)
Block(0,30,6,SANDSTONE)
Block(0,30,7,SANDSTONE)
Block(0,30,8,SANDSTONE)
Block(0,30,9,SANDSTONE)
Block(0,30,10,SANDSTONE)
Block(0,30,11,SANDSTONE)
Block(0,30,12,SANDSTONE)
Block(0,30,13,SANDSTONE)
Block(0,30,14,SANDSTONE)
Block(0,31,9,SANDSTONE)
Block(0,31,10,SANDSTONE)
Block(0,31,11,SANDSTONE)
Block(0,31,12,SANDSTONE)
Block(0,31,13,SANDSTONE)
Block(0,31,14,SANDSTONE)
Block(1,9,2,SANDSTONE)
Block(1,9,3,SANDSTONE)
Block(1,9,4,SANDSTONE)
Block(1,9,5,SANDSTONE)
Block(1,9,6,SANDSTONE)
Block(1,9,7,SANDSTONE)
Block(1,9,8,SANDSTONE)
Block(1,9,9,SANDSTONE)
Block(1,10,1,SANDSTONE)
Block(1,10,2,SANDSTONE)
Block(1,10,3,SANDSTONE)
Block(1,10,4,SANDSTONE)
Block(1,10,5,SANDSTONE)
Block(1,10,6,SANDSTONE)
Block(1,10,7,SANDSTONE)
Block(1,10,8,SANDSTONE)
Block(1,10,9,SANDSTONE)
Block(1,10,10,SANDSTONE)
Block(1,10,11,SANDSTONE)
Block(1,10,12,SANDSTONE)
Block(1,10,13,SANDSTONE)
Block(1,10,14,SANDSTONE)
Block(1,11,0,SANDSTONE)
Block(1,11,1,SANDSTONE)
Block(1,11,2,SANDSTONE)
Block(1,11,3,SANDSTONE)
Block(1,11,4,SANDSTONE)
Block(1,11,5,SANDSTONE)
Block(1,11,6,SANDSTONE)
Block(1,11,7,SANDSTONE)
Block(1,11,8,SANDSTONE)
Block(1,11,9,SANDSTONE)
Block(1,11,10,SANDSTONE)
Block(1,11,11,SANDSTONE)
Block(1,11,12,SANDSTONE)
Block(1,11,13,SANDSTONE)
Block(1,11,14,SANDSTONE)
Block(1,11,15,SANDSTONE)
Block(1,12,-1,SANDSTONE)
Block(1,12,0,SANDSTONE)
Block(1,12,1,SANDSTONE)
Block(1,12,2,SANDSTONE)
Block(1,12,3,SANDSTONE)
Block(1,12,4,SANDSTONE)
Block(1,12,5,SANDSTONE)
Block(1,12,6,SANDSTONE)
Block(1,12,7,SANDSTONE)
Block(1,12,8,SANDSTONE)
Block(1,12,9,SANDSTONE)
Block(1,12,10,SANDSTONE)
Block(1,12,11,SANDSTONE)
Block(1,12,12,SANDSTONE)
Block(1,12,13,SANDSTONE)
Block(1,12,14,SANDSTONE)
Block(1,12,15,SANDSTONE)
Block(1,13,-2,SANDSTONE)
Block(1,13,-1,SANDSTONE)
Block(1,13,0,SANDSTONE)
Block(1,13,1,SANDSTONE)
Block(1,13,2,SANDSTONE)
Block(1,13,3,SANDSTONE)
Block(1,13,4,SANDSTONE)
Block(1,13,5,SANDSTONE)
Block(1,13,6,SANDSTONE)
Block(1,13,7,SANDSTONE)
Block(1,13,8,SANDSTONE)
Block(1,13,9,SANDSTONE)
Block(1,13,10,SANDSTONE)
Block(1,13,11,SANDSTONE)
Block(1,13,12,SANDSTONE)
Block(1,13,13,SANDSTONE)
Block(1,13,14,SANDSTONE)
Block(1,13,15,SANDSTONE)
Block(1,14,-3,SANDSTONE)
Block(1,14,-2,SANDSTONE)
Block(1,14,-1,SANDSTONE)
Block(1,14,0,SANDSTONE)
Block(1,14,1,SANDSTONE)
Block(1,14,2,SANDSTONE)
Block(1,14,3,SANDSTONE)
Block(1,14,4,SANDSTONE)
Block(1,14,5,SANDSTONE)
Block(1,14,6,SANDSTONE)
Block(1,14,7,SANDSTONE)
Block(1,14,8,SANDSTONE)
Block(1,14,9,SANDSTONE)
Block(1,14,10,SANDSTONE)
Block(1,14,11,SANDSTONE)
Block(1,14,12,SANDSTONE)
Block(1,14,13,SANDSTONE)
Block(1,14,14,SANDSTONE)
Block(1,14,15,SANDSTONE)
Block(1,15,-4,SANDSTONE)
Block(1,15,-3,SANDSTONE)
Block(1,15,-2,SANDSTONE)
Block(1,15,-1,SANDSTONE)
Block(1,15,0,SANDSTONE)
Block(1,15,1,SANDSTONE)
Block(1,15,2,SANDSTONE)
Block(1,15,3,SANDSTONE)
Block(1,15,4,SANDSTONE)
Block(1,15,5,SANDSTONE)
Block(1,15,6,SANDSTONE)
Block(1,15,7,SANDSTONE)
Block(1,15,8,SANDSTONE)
Block(1,15,9,SANDSTONE)
Block(1,15,10,SANDSTONE)
Block(1,15,11,SANDSTONE)
Block(1,15,12,SANDSTONE)
Block(1,15,13,SANDSTONE)
Block(1,15,14,SANDSTONE)
Block(1,15,15,SANDSTONE)
Block(1,15,16,SANDSTONE)
Block(1,16,-5,SANDSTONE)
Block(1,16,-4,SANDSTONE)
Block(1,16,-3,SANDSTONE)
Block(1,16,-2,SANDSTONE)
Block(1,16,-1,SANDSTONE)
Block(1,16,0,SANDSTONE)
Block(1,16,1,SANDSTONE)
Block(1,16,2,SANDSTONE)
Block(1,16,3,SANDSTONE)
Block(1,16,4,SANDSTONE)
Block(1,16,5,SANDSTONE)
Block(1,16,6,SANDSTONE)
Block(1,16,7,SANDSTONE)
Block(1,16,8,SANDSTONE)
Block(1,16,9,SANDSTONE)
Block(1,16,10,SANDSTONE)
Block(1,16,11,SANDSTONE)
Block(1,16,12,SANDSTONE)
Block(1,16,13,SANDSTONE)
Block(1,16,14,SANDSTONE)
Block(1,16,15,SANDSTONE)
Block(1,16,16,SANDSTONE)
Block(1,17,-5,SANDSTONE)
Block(1,17,-4,SANDSTONE)
Block(1,17,-3,SANDSTONE)
Block(1,17,-2,SANDSTONE)
Block(1,17,-1,SANDSTONE)
Block(1,17,0,SANDSTONE)
Block(1,17,1,SANDSTONE)
Block(1,17,2,SANDSTONE)
Block(1,17,3,SANDSTONE)
Block(1,17,4,SANDSTONE)
Block(1,17,5,SANDSTONE)
Block(1,17,6,SANDSTONE)
Block(1,17,7,SANDSTONE)
Block(1,17,8,SANDSTONE)
Block(1,17,9,SANDSTONE)
Block(1,17,10,SANDSTONE)
Block(1,17,11,SANDSTONE)
Block(1,17,12,SANDSTONE)
Block(1,17,13,SANDSTONE)
Block(1,17,14,SANDSTONE)
Block(1,17,15,SANDSTONE)
Block(1,17,16,SANDSTONE)
Block(1,18,-6,SANDSTONE)
Block(1,18,-5,SANDSTONE)
Block(1,18,-4,SANDSTONE)
Block(1,18,-3,SANDSTONE)
Block(1,18,-2,SANDSTONE)
Block(1,18,-1,SANDSTONE)
Block(1,18,0,SANDSTONE)
Block(1,18,1,SANDSTONE)
Block(1,18,2,SANDSTONE)
Block(1,18,3,SANDSTONE)
Block(1,18,4,SANDSTONE)
Block(1,18,5,SANDSTONE)
Block(1,18,6,SANDSTONE)
Block(1,18,7,SANDSTONE)
Block(1,18,8,SANDSTONE)
Block(1,18,9,SANDSTONE)
Block(1,18,10,SANDSTONE)
Block(1,18,11,SANDSTONE)
Block(1,18,12,SANDSTONE)
Block(1,18,13,SANDSTONE)
Block(1,18,14,SANDSTONE)
Block(1,18,15,SANDSTONE)
Block(1,18,16,SANDSTONE)
Block(1,18,17,SANDSTONE)
Block(1,19,-6,SANDSTONE)
Block(1,19,-5,SANDSTONE)
Block(1,19,-4,SANDSTONE)
Block(1,19,-3,SANDSTONE)
Block(1,19,-2,SANDSTONE)
Block(1,19,-1,SANDSTONE)
Block(1,19,0,SANDSTONE)
Block(1,19,1,SANDSTONE)
Block(1,19,2,SANDSTONE)
Block(1,19,3,SANDSTONE)
Block(1,19,4,SANDSTONE)
Block(1,19,5,SANDSTONE)
Block(1,19,6,SANDSTONE)
Block(1,19,7,SANDSTONE)
Block(1,19,8,SANDSTONE)
Block(1,19,9,SANDSTONE)
Block(1,19,10,SANDSTONE)
Block(1,19,11,SANDSTONE)
Block(1,19,12,SANDSTONE)
Block(1,19,13,SANDSTONE)
Block(1,19,14,SANDSTONE)
Block(1,19,15,SANDSTONE)
Block(1,19,16,SANDSTONE)
Block(1,19,17,SANDSTONE)
Block(1,20,-6,SANDSTONE)
Block(1,20,-5,SANDSTONE)
Block(1,20,-4,SANDSTONE)
Block(1,20,-3,SANDSTONE)
Block(1,20,-2,SANDSTONE)
Block(1,20,-1,SANDSTONE)
Block(1,20,0,SANDSTONE)
Block(1,20,1,SANDSTONE)
Block(1,20,2,SANDSTONE)
Block(1,20,3,SANDSTONE)
Block(1,20,4,SANDSTONE)
Block(1,20,5,SANDSTONE)
Block(1,20,6,SANDSTONE)
Block(1,20,7,SANDSTONE)
Block(1,20,8,SANDSTONE)
Block(1,20,9,SANDSTONE)
Block(1,20,10,SANDSTONE)
Block(1,20,11,SANDSTONE)
Block(1,20,12,SANDSTONE)
Block(1,20,13,SANDSTONE)
Block(1,20,14,SANDSTONE)
Block(1,20,15,SANDSTONE)
Block(1,20,16,SANDSTONE)
Block(1,20,17,SANDSTONE)
Block(1,21,-6,SANDSTONE)
Block(1,21,-5,SANDSTONE)
Block(1,21,-4,SANDSTONE)
Block(1,21,-3,SANDSTONE)
Block(1,21,-2,SANDSTONE)
Block(1,21,-1,SANDSTONE)
Block(1,21,0,SANDSTONE)
Block(1,21,1,SANDSTONE)
Block(1,21,2,SANDSTONE)
Block(1,21,3,SANDSTONE)
Block(1,21,4,SANDSTONE)
Block(1,21,5,SANDSTONE)
Block(1,21,6,SANDSTONE)
Block(1,21,7,SANDSTONE)
Block(1,21,8,SANDSTONE)
Block(1,21,9,SANDSTONE)
Block(1,21,10,SANDSTONE)
Block(1,21,11,SANDSTONE)
Block(1,21,12,SANDSTONE)
Block(1,21,13,SANDSTONE)
Block(1,21,14,SANDSTONE)
Block(1,21,15,SANDSTONE)
Block(1,21,16,SANDSTONE)
Block(1,21,17,SANDSTONE)
Block(1,22,-6,SANDSTONE)
Block(1,22,-5,SANDSTONE)
Block(1,22,-4,SANDSTONE)
Block(1,22,-3,SANDSTONE)
Block(1,22,-2,SANDSTONE)
Block(1,22,-1,SANDSTONE)
Block(1,22,0,SANDSTONE)
Block(1,22,1,SANDSTONE)
Block(1,22,2,SANDSTONE)
Block(1,22,3,SANDSTONE)
Block(1,22,4,SANDSTONE)
Block(1,22,5,SANDSTONE)
Block(1,22,6,SANDSTONE)
Block(1,22,7,SANDSTONE)
Block(1,22,8,SANDSTONE)
Block(1,22,9,SANDSTONE)
Block(1,22,10,SANDSTONE)
Block(1,22,11,SANDSTONE)
Block(1,22,12,SANDSTONE)
Block(1,22,13,SANDSTONE)
Block(1,22,14,SANDSTONE)
Block(1,22,15,SANDSTONE)
Block(1,22,16,SANDSTONE)
Block(1,23,-5,SANDSTONE)
Block(1,23,-4,SANDSTONE)
Block(1,23,-3,SANDSTONE)
Block(1,23,-2,SANDSTONE)
Block(1,23,-1,SANDSTONE)
Block(1,23,0,SANDSTONE)
Block(1,23,1,SANDSTONE)
Block(1,23,2,SANDSTONE)
Block(1,23,3,SANDSTONE)
Block(1,23,4,SANDSTONE)
Block(1,23,5,SANDSTONE)
Block(1,23,6,SANDSTONE)
Block(1,23,7,SANDSTONE)
Block(1,23,8,SANDSTONE)
Block(1,23,9,SANDSTONE)
Block(1,23,10,SANDSTONE)
Block(1,23,11,SANDSTONE)
Block(1,23,12,SANDSTONE)
Block(1,23,13,SANDSTONE)
Block(1,23,14,SANDSTONE)
Block(1,23,15,SANDSTONE)
Block(1,23,16,SANDSTONE)
Block(1,24,-4,SANDSTONE)
Block(1,24,-3,SANDSTONE)
Block(1,24,-2,SANDSTONE)
Block(1,24,-1,SANDSTONE)
Block(1,24,0,SANDSTONE)
Block(1,24,1,SANDSTONE)
Block(1,24,2,SANDSTONE)
Block(1,24,3,SANDSTONE)
Block(1,24,4,SANDSTONE)
Block(1,24,5,SANDSTONE)
Block(1,24,6,SANDSTONE)
Block(1,24,7,SANDSTONE)
Block(1,24,8,SANDSTONE)
Block(1,24,9,SANDSTONE)
Block(1,24,10,SANDSTONE)
Block(1,24,11,SANDSTONE)
Block(1,24,12,SANDSTONE)
Block(1,24,13,SANDSTONE)
Block(1,24,14,SANDSTONE)
Block(1,24,15,SANDSTONE)
Block(1,24,16,SANDSTONE)
Block(1,25,-4,SANDSTONE)
Block(1,25,-3,SANDSTONE)
Block(1,25,-2,SANDSTONE)
Block(1,25,-1,SANDSTONE)
Block(1,25,0,SANDSTONE)
Block(1,25,1,SANDSTONE)
Block(1,25,2,SANDSTONE)
Block(1,25,3,SANDSTONE)
Block(1,25,4,SANDSTONE)
Block(1,25,5,SANDSTONE)
Block(1,25,6,SANDSTONE)
Block(1,25,7,SANDSTONE)
Block(1,25,8,SANDSTONE)
Block(1,25,9,SANDSTONE)
Block(1,25,10,SANDSTONE)
Block(1,25,11,SANDSTONE)
Block(1,25,12,SANDSTONE)
Block(1,25,13,SANDSTONE)
Block(1,25,14,SANDSTONE)
Block(1,25,15,SANDSTONE)
Block(1,25,16,SANDSTONE)
Block(1,26,-3,SANDSTONE)
Block(1,26,-2,SANDSTONE)
Block(1,26,-1,SANDSTONE)
Block(1,26,0,SANDSTONE)
Block(1,26,1,SANDSTONE)
Block(1,26,2,SANDSTONE)
Block(1,26,3,SANDSTONE)
Block(1,26,4,SANDSTONE)
Block(1,26,5,SANDSTONE)
Block(1,26,6,SANDSTONE)
Block(1,26,7,SANDSTONE)
Block(1,26,8,SANDSTONE)
Block(1,26,9,SANDSTONE)
Block(1,26,10,SANDSTONE)
Block(1,26,11,SANDSTONE)
Block(1,26,12,SANDSTONE)
Block(1,26,13,SANDSTONE)
Block(1,26,14,SANDSTONE)
Block(1,26,15,SANDSTONE)
Block(1,26,16,SANDSTONE)
Block(1,27,-2,SANDSTONE)
Block(1,27,-1,SANDSTONE)
Block(1,27,0,SANDSTONE)
Block(1,27,1,SANDSTONE)
Block(1,27,2,SANDSTONE)
Block(1,27,3,SANDSTONE)
Block(1,27,4,SANDSTONE)
Block(1,27,5,SANDSTONE)
Block(1,27,6,SANDSTONE)
Block(1,27,7,SANDSTONE)
Block(1,27,8,SANDSTONE)
Block(1,27,9,SANDSTONE)
Block(1,27,10,SANDSTONE)
Block(1,27,11,SANDSTONE)
Block(1,27,12,SANDSTONE)
Block(1,27,13,SANDSTONE)
Block(1,27,14,SANDSTONE)
Block(1,27,15,SANDSTONE)
Block(1,27,16,SANDSTONE)
Block(1,28,0,SANDSTONE)
Block(1,28,1,SANDSTONE)
Block(1,28,2,SANDSTONE)
Block(1,28,3,SANDSTONE)
Block(1,28,4,SANDSTONE)
Block(1,28,5,SANDSTONE)
Block(1,28,6,SANDSTONE)
Block(1,28,7,SANDSTONE)
Block(1,28,8,SANDSTONE)
Block(1,28,9,SANDSTONE)
Block(1,28,10,SANDSTONE)
Block(1,28,11,SANDSTONE)
Block(1,28,12,SANDSTONE)
Block(1,28,13,SANDSTONE)
Block(1,28,14,SANDSTONE)
Block(1,28,15,SANDSTONE)
Block(1,28,16,SANDSTONE)
Block(1,29,2,SANDSTONE)
Block(1,29,3,SANDSTONE)
Block(1,29,4,SANDSTONE)
Block(1,29,5,SANDSTONE)
Block(1,29,6,SANDSTONE)
Block(1,29,7,SANDSTONE)
Block(1,29,8,SANDSTONE)
Block(1,29,9,SANDSTONE)
Block(1,29,10,SANDSTONE)
Block(1,29,11,SANDSTONE)
Block(1,29,12,SANDSTONE)
Block(1,29,13,SANDSTONE)
Block(1,29,14,SANDSTONE)
Block(1,29,15,SANDSTONE)
Block(1,30,4,SANDSTONE)
Block(1,30,5,SANDSTONE)
Block(1,30,6,SANDSTONE)
Block(1,30,7,SANDSTONE)
Block(1,30,8,SANDSTONE)
Block(1,30,9,SANDSTONE)
Block(1,30,10,SANDSTONE)
Block(1,30,11,SANDSTONE)
Block(1,30,12,SANDSTONE)
Block(1,30,13,SANDSTONE)
Block(1,30,14,SANDSTONE)
Block(1,30,15,SANDSTONE)
Block(1,31,7,SANDSTONE)
Block(1,31,8,SANDSTONE)
Block(1,31,9,SANDSTONE)
Block(1,31,10,SANDSTONE)
Block(1,31,11,SANDSTONE)
Block(1,31,12,SANDSTONE)
Block(1,31,13,SANDSTONE)
Block(1,31,14,SANDSTONE)
Block(1,32,11,SANDSTONE)
Block(1,32,12,SANDSTONE)
Block(1,32,13,SANDSTONE)
Block(2,8,2,SANDSTONE)
Block(2,8,3,SANDSTONE)
Block(2,8,4,SANDSTONE)
Block(2,8,5,SANDSTONE)
Block(2,8,6,SANDSTONE)
Block(2,9,1,SANDSTONE)
Block(2,9,2,SANDSTONE)
Block(2,9,3,SANDSTONE)
Block(2,9,4,SANDSTONE)
Block(2,9,5,SANDSTONE)
Block(2,9,6,SANDSTONE)
Block(2,9,7,SANDSTONE)
Block(2,9,8,SANDSTONE)
Block(2,9,9,SANDSTONE)
Block(2,9,10,SANDSTONE)
Block(2,9,11,SANDSTONE)
Block(2,9,12,SANDSTONE)
Block(2,9,13,SANDSTONE)
Block(2,9,14,SANDSTONE)
Block(2,9,15,SANDSTONE)
Block(2,10,0,SANDSTONE)
Block(2,10,1,SANDSTONE)
Block(2,10,2,SANDSTONE)
Block(2,10,3,SANDSTONE)
Block(2,10,4,SANDSTONE)
Block(2,10,5,SANDSTONE)
Block(2,10,6,SANDSTONE)
Block(2,10,7,SANDSTONE)
Block(2,10,8,SANDSTONE)
Block(2,10,9,SANDSTONE)
Block(2,10,10,SANDSTONE)
Block(2,10,11,SANDSTONE)
Block(2,10,12,SANDSTONE)
Block(2,10,13,SANDSTONE)
Block(2,10,14,SANDSTONE)
Block(2,10,15,SANDSTONE)
Block(2,10,16,SANDSTONE)
Block(2,11,0,SANDSTONE)
Block(2,11,1,SANDSTONE)
Block(2,11,2,SANDSTONE)
Block(2,11,3,SANDSTONE)
Block(2,11,4,SANDSTONE)
Block(2,11,5,SANDSTONE)
Block(2,11,6,SANDSTONE)
Block(2,11,7,SANDSTONE)
Block(2,11,8,SANDSTONE)
Block(2,11,9,SANDSTONE)
Block(2,11,10,SANDSTONE)
Block(2,11,11,SANDSTONE)
Block(2,11,12,SANDSTONE)
Block(2,11,13,SANDSTONE)
Block(2,11,14,SANDSTONE)
Block(2,11,15,SANDSTONE)
Block(2,11,16,SANDSTONE)
Block(2,12,-2,SANDSTONE)
Block(2,12,-1,SANDSTONE)
Block(2,12,0,SANDSTONE)
Block(2,12,1,SANDSTONE)
Block(2,12,2,SANDSTONE)
Block(2,12,3,SANDSTONE)
Block(2,12,4,SANDSTONE)
Block(2,12,5,SANDSTONE)
Block(2,12,6,SANDSTONE)
Block(2,12,7,SANDSTONE)
Block(2,12,8,SANDSTONE)
Block(2,12,9,SANDSTONE)
Block(2,12,10,SANDSTONE)
Block(2,12,11,SANDSTONE)
Block(2,12,12,SANDSTONE)
Block(2,12,13,SANDSTONE)
Block(2,12,14,SANDSTONE)
Block(2,12,15,SANDSTONE)
Block(2,12,16,SANDSTONE)
Block(2,13,-3,SANDSTONE)
Block(2,13,-2,SANDSTONE)
Block(2,13,-1,SANDSTONE)
Block(2,13,0,SANDSTONE)
Block(2,13,1,SANDSTONE)
Block(2,13,2,SANDSTONE)
Block(2,13,3,SANDSTONE)
Block(2,13,4,SANDSTONE)
Block(2,13,5,SANDSTONE)
Block(2,13,6,SANDSTONE)
Block(2,13,7,SANDSTONE)
Block(2,13,8,SANDSTONE)
Block(2,13,9,SANDSTONE)
Block(2,13,10,SANDSTONE)
Block(2,13,11,SANDSTONE)
Block(2,13,12,SANDSTONE)
Block(2,13,13,SANDSTONE)
Block(2,13,14,SANDSTONE)
Block(2,13,15,SANDSTONE)
Block(2,13,16,SANDSTONE)
Block(2,13,17,SANDSTONE)
Block(2,14,-3,SANDSTONE)
Block(2,14,-2,SANDSTONE)
Block(2,14,-1,SANDSTONE)
Block(2,14,0,SANDSTONE)
Block(2,14,1,SANDSTONE)
Block(2,14,2,SANDSTONE)
Block(2,14,3,SANDSTONE)
Block(2,14,4,SANDSTONE)
Block(2,14,5,SANDSTONE)
Block(2,14,6,SANDSTONE)
Block(2,14,7,SANDSTONE)
Block(2,14,8,SANDSTONE)
Block(2,14,9,SANDSTONE)
Block(2,14,10,SANDSTONE)
Block(2,14,11,SANDSTONE)
Block(2,14,12,SANDSTONE)
Block(2,14,13,SANDSTONE)
Block(2,14,14,SANDSTONE)
Block(2,14,15,SANDSTONE)
Block(2,14,16,SANDSTONE)
Block(2,14,17,SANDSTONE)
Block(2,15,-4,SANDSTONE)
Block(2,15,-3,SANDSTONE)
Block(2,15,-2,SANDSTONE)
Block(2,15,-1,SANDSTONE)
Block(2,15,0,SANDSTONE)
Block(2,15,1,SANDSTONE)
Block(2,15,2,SANDSTONE)
Block(2,15,3,SANDSTONE)
Block(2,15,4,SANDSTONE)
Block(2,15,5,SANDSTONE)
Block(2,15,6,SANDSTONE)
Block(2,15,7,SANDSTONE)
Block(2,15,8,SANDSTONE)
Block(2,15,9,SANDSTONE)
Block(2,15,10,SANDSTONE)
Block(2,15,11,SANDSTONE)
Block(2,15,12,SANDSTONE)
Block(2,15,13,SANDSTONE)
Block(2,15,14,SANDSTONE)
Block(2,15,15,SANDSTONE)
Block(2,15,16,SANDSTONE)
Block(2,15,17,SANDSTONE)
Block(2,16,-5,SANDSTONE)
Block(2,16,-4,SANDSTONE)
Block(2,16,-3,SANDSTONE)
Block(2,16,-2,SANDSTONE)
Block(2,16,-1,SANDSTONE)
Block(2,16,0,SANDSTONE)
Block(2,16,1,SANDSTONE)
Block(2,16,2,SANDSTONE)
Block(2,16,3,SANDSTONE)
Block(2,16,4,SANDSTONE)
Block(2,16,5,SANDSTONE)
Block(2,16,6,SANDSTONE)
Block(2,16,7,SANDSTONE)
Block(2,16,8,SANDSTONE)
Block(2,16,9,SANDSTONE)
Block(2,16,10,SANDSTONE)
Block(2,16,11,SANDSTONE)
Block(2,16,12,SANDSTONE)
Block(2,16,13,SANDSTONE)
Block(2,16,14,SANDSTONE)
Block(2,16,15,SANDSTONE)
Block(2,16,16,SANDSTONE)
Block(2,16,17,SANDSTONE)
Block(2,17,-5,SANDSTONE)
Block(2,17,-4,SANDSTONE)
Block(2,17,-3,SANDSTONE)
Block(2,17,-2,SANDSTONE)
Block(2,17,-1,SANDSTONE)
Block(2,17,0,SANDSTONE)
Block(2,17,1,SANDSTONE)
Block(2,17,2,SANDSTONE)
Block(2,17,3,SANDSTONE)
Block(2,17,4,SANDSTONE)
Block(2,17,5,SANDSTONE)
Block(2,17,6,SANDSTONE)
Block(2,17,7,SANDSTONE)
Block(2,17,8,SANDSTONE)
Block(2,17,9,SANDSTONE)
Block(2,17,10,SANDSTONE)
Block(2,17,11,SANDSTONE)
Block(2,17,12,SANDSTONE)
Block(2,17,13,SANDSTONE)
Block(2,17,14,SANDSTONE)
Block(2,17,15,SANDSTONE)
Block(2,17,16,SANDSTONE)
Block(2,17,17,SANDSTONE)
Block(2,17,18,SANDSTONE)
Block(2,18,-6,SANDSTONE)
Block(2,18,-5,SANDSTONE)
Block(2,18,-4,SANDSTONE)
Block(2,18,-3,SANDSTONE)
Block(2,18,-2,SANDSTONE)
Block(2,18,-1,SANDSTONE)
Block(2,18,0,SANDSTONE)
Block(2,18,1,SANDSTONE)
Block(2,18,2,SANDSTONE)
Block(2,18,3,SANDSTONE)
Block(2,18,4,SANDSTONE)
Block(2,18,5,SANDSTONE)
Block(2,18,6,SANDSTONE)
Block(2,18,7,SANDSTONE)
Block(2,18,8,SANDSTONE)
Block(2,18,9,SANDSTONE)
Block(2,18,10,SANDSTONE)
Block(2,18,11,SANDSTONE)
Block(2,18,12,SANDSTONE)
Block(2,18,13,SANDSTONE)
Block(2,18,14,SANDSTONE)
Block(2,18,15,SANDSTONE)
Block(2,18,16,SANDSTONE)
Block(2,18,17,SANDSTONE)
Block(2,19,-6,SANDSTONE)
Block(2,19,-5,SANDSTONE)
Block(2,19,-4,SANDSTONE)
Block(2,19,-3,SANDSTONE)
Block(2,19,-2,SANDSTONE)
Block(2,19,-1,SANDSTONE)
Block(2,19,0,SANDSTONE)
Block(2,19,1,SANDSTONE)
Block(2,19,2,SANDSTONE)
Block(2,19,3,SANDSTONE)
Block(2,19,4,SANDSTONE)
Block(2,19,5,SANDSTONE)
Block(2,19,6,SANDSTONE)
Block(2,19,7,SANDSTONE)
Block(2,19,8,SANDSTONE)
Block(2,19,9,SANDSTONE)
Block(2,19,10,SANDSTONE)
Block(2,19,11,SANDSTONE)
Block(2,19,12,SANDSTONE)
Block(2,19,13,SANDSTONE)
Block(2,19,14,SANDSTONE)
Block(2,19,15,SANDSTONE)
Block(2,19,16,SANDSTONE)
Block(2,19,17,SANDSTONE)
Block(2,20,-6,SANDSTONE)
Block(2,20,-5,SANDSTONE)
Block(2,20,-4,SANDSTONE)
Block(2,20,-3,SANDSTONE)
Block(2,20,-2,SANDSTONE)
Block(2,20,-1,SANDSTONE)
Block(2,20,0,SANDSTONE)
Block(2,20,1,SANDSTONE)
Block(2,20,2,SANDSTONE)
Block(2,20,3,SANDSTONE)
Block(2,20,4,SANDSTONE)
Block(2,20,5,SANDSTONE)
Block(2,20,6,SANDSTONE)
Block(2,20,7,SANDSTONE)
Block(2,20,8,SANDSTONE)
Block(2,20,9,SANDSTONE)
Block(2,20,10,SANDSTONE)
Block(2,20,11,SANDSTONE)
Block(2,20,12,SANDSTONE)
Block(2,20,13,SANDSTONE)
Block(2,20,14,SANDSTONE)
Block(2,20,15,SANDSTONE)
Block(2,20,16,SANDSTONE)
Block(2,20,17,SANDSTONE)
Block(2,21,-6,SANDSTONE)
Block(2,21,-5,SANDSTONE)
Block(2,21,-4,SANDSTONE)
Block(2,21,-3,SANDSTONE)
Block(2,21,-2,SANDSTONE)
Block(2,21,-1,SANDSTONE)
Block(2,21,0,SANDSTONE)
Block(2,21,1,SANDSTONE)
Block(2,21,2,SANDSTONE)
Block(2,21,3,SANDSTONE)
Block(2,21,4,SANDSTONE)
Block(2,21,5,SANDSTONE)
Block(2,21,6,SANDSTONE)
Block(2,21,7,SANDSTONE)
Block(2,21,8,SANDSTONE)
Block(2,21,9,SANDSTONE)
Block(2,21,10,SANDSTONE)
Block(2,21,11,SANDSTONE)
Block(2,21,12,SANDSTONE)
Block(2,21,13,SANDSTONE)
Block(2,21,14,SANDSTONE)
Block(2,21,15,SANDSTONE)
Block(2,21,16,SANDSTONE)
Block(2,21,17,SANDSTONE)
Block(2,22,-6,SANDSTONE)
Block(2,22,-5,SANDSTONE)
Block(2,22,-4,SANDSTONE)
Block(2,22,-3,SANDSTONE)
Block(2,22,-2,SANDSTONE)
Block(2,22,-1,SANDSTONE)
Block(2,22,0,SANDSTONE)
Block(2,22,1,SANDSTONE)
Block(2,22,2,SANDSTONE)
Block(2,22,3,SANDSTONE)
Block(2,22,4,SANDSTONE)
Block(2,22,5,SANDSTONE)
Block(2,22,6,SANDSTONE)
Block(2,22,7,SANDSTONE)
Block(2,22,8,SANDSTONE)
Block(2,22,9,SANDSTONE)
Block(2,22,10,SANDSTONE)
Block(2,22,11,SANDSTONE)
Block(2,22,12,SANDSTONE)
Block(2,22,13,SANDSTONE)
Block(2,22,14,SANDSTONE)
Block(2,22,15,SANDSTONE)
Block(2,22,16,SANDSTONE)
Block(2,23,-6,SANDSTONE)
Block(2,23,-5,SANDSTONE)
Block(2,23,-4,SANDSTONE)
Block(2,23,-3,SANDSTONE)
Block(2,23,-2,SANDSTONE)
Block(2,23,-1,SANDSTONE)
Block(2,23,0,SANDSTONE)
Block(2,23,1,SANDSTONE)
Block(2,23,2,SANDSTONE)
Block(2,23,3,SANDSTONE)
Block(2,23,4,SANDSTONE)
Block(2,23,5,SANDSTONE)
Block(2,23,6,SANDSTONE)
Block(2,23,7,SANDSTONE)
Block(2,23,8,SANDSTONE)
Block(2,23,9,SANDSTONE)
Block(2,23,10,SANDSTONE)
Block(2,23,11,SANDSTONE)
Block(2,23,12,SANDSTONE)
Block(2,23,13,SANDSTONE)
Block(2,23,14,SANDSTONE)
Block(2,23,15,SANDSTONE)
Block(2,23,16,SANDSTONE)
Block(2,24,-6,SANDSTONE)
Block(2,24,-5,SANDSTONE)
Block(2,24,-4,SANDSTONE)
Block(2,24,-3,SANDSTONE)
Block(2,24,-2,SANDSTONE)
Block(2,24,-1,SANDSTONE)
Block(2,24,0,SANDSTONE)
Block(2,24,1,SANDSTONE)
Block(2,24,2,SANDSTONE)
Block(2,24,3,SANDSTONE)
Block(2,24,4,SANDSTONE)
Block(2,24,5,SANDSTONE)
Block(2,24,6,SANDSTONE)
Block(2,24,7,SANDSTONE)
Block(2,24,8,SANDSTONE)
Block(2,24,9,SANDSTONE)
Block(2,24,10,SANDSTONE)
Block(2,24,11,SANDSTONE)
Block(2,24,12,SANDSTONE)
Block(2,24,13,SANDSTONE)
Block(2,24,14,SANDSTONE)
Block(2,24,15,SANDSTONE)
Block(2,24,16,SANDSTONE)
Block(2,25,-4,SANDSTONE)
Block(2,25,-3,SANDSTONE)
Block(2,25,-2,SANDSTONE)
Block(2,25,-1,SANDSTONE)
Block(2,25,0,SANDSTONE)
Block(2,25,1,SANDSTONE)
Block(2,25,2,SANDSTONE)
Block(2,25,3,SANDSTONE)
Block(2,25,4,SANDSTONE)
Block(2,25,5,SANDSTONE)
Block(2,25,6,SANDSTONE)
Block(2,25,7,SANDSTONE)
Block(2,25,8,SANDSTONE)
Block(2,25,9,SANDSTONE)
Block(2,25,10,SANDSTONE)
Block(2,25,11,SANDSTONE)
Block(2,25,12,SANDSTONE)
Block(2,25,13,SANDSTONE)
Block(2,25,14,SANDSTONE)
Block(2,25,15,SANDSTONE)
Block(2,25,16,SANDSTONE)
Block(2,26,-3,SANDSTONE)
Block(2,26,-2,SANDSTONE)
Block(2,26,-1,SANDSTONE)
Block(2,26,0,SANDSTONE)
Block(2,26,1,SANDSTONE)
Block(2,26,2,SANDSTONE)
Block(2,26,3,SANDSTONE)
Block(2,26,4,SANDSTONE)
Block(2,26,5,SANDSTONE)
Block(2,26,6,SANDSTONE)
Block(2,26,7,SANDSTONE)
Block(2,26,8,SANDSTONE)
Block(2,26,9,SANDSTONE)
Block(2,26,10,SANDSTONE)
Block(2,26,11,SANDSTONE)
Block(2,26,12,SANDSTONE)
Block(2,26,13,SANDSTONE)
Block(2,26,14,SANDSTONE)
Block(2,26,15,SANDSTONE)
Block(2,26,16,SANDSTONE)
Block(2,27,-3,SANDSTONE)
Block(2,27,-2,SANDSTONE)
Block(2,27,-1,SANDSTONE)
Block(2,27,0,SANDSTONE)
Block(2,27,1,SANDSTONE)
Block(2,27,2,SANDSTONE)
Block(2,27,3,SANDSTONE)
Block(2,27,4,SANDSTONE)
Block(2,27,5,SANDSTONE)
Block(2,27,6,SANDSTONE)
Block(2,27,7,SANDSTONE)
Block(2,27,8,SANDSTONE)
Block(2,27,9,SANDSTONE)
Block(2,27,10,SANDSTONE)
Block(2,27,11,SANDSTONE)
Block(2,27,12,SANDSTONE)
Block(2,27,13,SANDSTONE)
Block(2,27,14,SANDSTONE)
Block(2,27,15,SANDSTONE)
Block(2,27,16,SANDSTONE)
Block(2,28,-1,SANDSTONE)
Block(2,28,0,SANDSTONE)
Block(2,28,1,SANDSTONE)
Block(2,28,2,SANDSTONE)
Block(2,28,3,SANDSTONE)
Block(2,28,4,SANDSTONE)
Block(2,28,5,SANDSTONE)
Block(2,28,6,SANDSTONE)
Block(2,28,7,SANDSTONE)
Block(2,28,8,SANDSTONE)
Block(2,28,9,SANDSTONE)
Block(2,28,10,SANDSTONE)
Block(2,28,11,SANDSTONE)
Block(2,28,12,SANDSTONE)
Block(2,28,13,SANDSTONE)
Block(2,28,14,SANDSTONE)
Block(2,28,15,SANDSTONE)
Block(2,28,16,SANDSTONE)
Block(2,29,0,SANDSTONE)
Block(2,29,1,SANDSTONE)
Block(2,29,2,SANDSTONE)
Block(2,29,3,SANDSTONE)
Block(2,29,4,SANDSTONE)
Block(2,29,5,SANDSTONE)
Block(2,29,6,SANDSTONE)
Block(2,29,7,SANDSTONE)
Block(2,29,8,SANDSTONE)
Block(2,29,9,SANDSTONE)
Block(2,29,10,SANDSTONE)
Block(2,29,11,SANDSTONE)
Block(2,29,12,SANDSTONE)
Block(2,29,13,SANDSTONE)
Block(2,29,14,SANDSTONE)
Block(2,29,15,SANDSTONE)
Block(2,30,3,SANDSTONE)
Block(2,30,4,SANDSTONE)
Block(2,30,5,SANDSTONE)
Block(2,30,6,SANDSTONE)
Block(2,30,7,SANDSTONE)
Block(2,30,8,SANDSTONE)
Block(2,30,9,SANDSTONE)
Block(2,30,10,SANDSTONE)
Block(2,30,11,SANDSTONE)
Block(2,30,12,SANDSTONE)
Block(2,30,13,SANDSTONE)
Block(2,30,14,SANDSTONE)
Block(2,30,15,SANDSTONE)
Block(2,31,6,SANDSTONE)
Block(2,31,7,SANDSTONE)
Block(2,31,8,SANDSTONE)
Block(2,31,9,SANDSTONE)
Block(2,31,10,SANDSTONE)
Block(2,31,11,SANDSTONE)
Block(2,31,12,SANDSTONE)
Block(2,31,13,SANDSTONE)
Block(2,31,14,SANDSTONE)
Block(2,32,9,SANDSTONE)
Block(2,32,10,SANDSTONE)
Block(2,32,11,SANDSTONE)
Block(2,32,12,SANDSTONE)
Block(3,8,1,SANDSTONE)
Block(3,8,2,SANDSTONE)
Block(3,8,3,SANDSTONE)
Block(3,8,4,SANDSTONE)
Block(3,8,5,SANDSTONE)
Block(3,8,6,SANDSTONE)
Block(3,8,7,SANDSTONE)
Block(3,8,8,SANDSTONE)
Block(3,8,9,SANDSTONE)
Block(3,8,10,SANDSTONE)
Block(3,8,11,SANDSTONE)
Block(3,8,12,SANDSTONE)
Block(3,8,13,SANDSTONE)
Block(3,9,0,SANDSTONE)
Block(3,9,1,SANDSTONE)
Block(3,9,2,SANDSTONE)
Block(3,9,3,SANDSTONE)
Block(3,9,4,SANDSTONE)
Block(3,9,5,SANDSTONE)
Block(3,9,6,SANDSTONE)
Block(3,9,7,SANDSTONE)
Block(3,9,8,SANDSTONE)
Block(3,9,9,SANDSTONE)
Block(3,9,10,SANDSTONE)
Block(3,9,11,SANDSTONE)
Block(3,9,12,SANDSTONE)
Block(3,9,13,SANDSTONE)
Block(3,9,14,SANDSTONE)
Block(3,9,15,SANDSTONE)
Block(3,9,16,SANDSTONE)
Block(3,9,17,SANDSTONE)
Block(3,10,0,SANDSTONE)
Block(3,10,1,SANDSTONE)
Block(3,10,2,SANDSTONE)
Block(3,10,3,SANDSTONE)
Block(3,10,4,SANDSTONE)
Block(3,10,5,SANDSTONE)
Block(3,10,6,SANDSTONE)
Block(3,10,7,SANDSTONE)
Block(3,10,8,SANDSTONE)
Block(3,10,9,SANDSTONE)
Block(3,10,10,SANDSTONE)
Block(3,10,11,SANDSTONE)
Block(3,10,12,SANDSTONE)
Block(3,10,13,SANDSTONE)
Block(3,10,14,SANDSTONE)
Block(3,10,15,SANDSTONE)
Block(3,10,16,SANDSTONE)
Block(3,10,17,SANDSTONE)
Block(3,11,-1,SANDSTONE)
Block(3,11,0,SANDSTONE)
Block(3,11,1,SANDSTONE)
Block(3,11,2,SANDSTONE)
Block(3,11,3,SANDSTONE)
Block(3,11,4,SANDSTONE)
Block(3,11,5,SANDSTONE)
Block(3,11,6,SANDSTONE)
Block(3,11,7,SANDSTONE)
Block(3,11,8,SANDSTONE)
Block(3,11,9,SANDSTONE)
Block(3,11,10,SANDSTONE)
Block(3,11,11,SANDSTONE)
Block(3,11,12,SANDSTONE)
Block(3,11,13,SANDSTONE)
Block(3,11,14,SANDSTONE)
Block(3,11,15,SANDSTONE)
Block(3,11,16,SANDSTONE)
Block(3,11,17,SANDSTONE)
Block(3,12,-2,SANDSTONE)
Block(3,12,-1,SANDSTONE)
Block(3,12,0,SANDSTONE)
Block(3,12,1,SANDSTONE)
Block(3,12,2,SANDSTONE)
Block(3,12,3,SANDSTONE)
Block(3,12,4,SANDSTONE)
Block(3,12,5,SANDSTONE)
Block(3,12,6,SANDSTONE)
Block(3,12,7,SANDSTONE)
Block(3,12,8,SANDSTONE)
Block(3,12,9,SANDSTONE)
Block(3,12,10,SANDSTONE)
Block(3,12,11,SANDSTONE)
Block(3,12,12,SANDSTONE)
Block(3,12,13,SANDSTONE)
Block(3,12,14,SANDSTONE)
Block(3,12,15,SANDSTONE)
Block(3,12,16,SANDSTONE)
Block(3,12,17,SANDSTONE)
Block(3,12,18,SANDSTONE)
Block(3,13,-3,SANDSTONE)
Block(3,13,-2,SANDSTONE)
Block(3,13,-1,SANDSTONE)
Block(3,13,0,SANDSTONE)
Block(3,13,1,SANDSTONE)
Block(3,13,2,SANDSTONE)
Block(3,13,3,SANDSTONE)
Block(3,13,4,SANDSTONE)
Block(3,13,5,SANDSTONE)
Block(3,13,6,SANDSTONE)
Block(3,13,7,SANDSTONE)
Block(3,13,8,SANDSTONE)
Block(3,13,9,SANDSTONE)
Block(3,13,10,SANDSTONE)
Block(3,13,11,SANDSTONE)
Block(3,13,12,SANDSTONE)
Block(3,13,13,SANDSTONE)
Block(3,13,14,SANDSTONE)
Block(3,13,15,SANDSTONE)
Block(3,13,16,SANDSTONE)
Block(3,13,17,SANDSTONE)
Block(3,13,18,SANDSTONE)
Block(3,14,-4,SANDSTONE)
Block(3,14,-3,SANDSTONE)
Block(3,14,-2,SANDSTONE)
Block(3,14,-1,SANDSTONE)
Block(3,14,0,SANDSTONE)
Block(3,14,1,SANDSTONE)
Block(3,14,2,SANDSTONE)
Block(3,14,3,SANDSTONE)
Block(3,14,4,SANDSTONE)
Block(3,14,5,SANDSTONE)
Block(3,14,6,SANDSTONE)
Block(3,14,7,SANDSTONE)
Block(3,14,8,SANDSTONE)
Block(3,14,9,SANDSTONE)
Block(3,14,10,SANDSTONE)
Block(3,14,11,SANDSTONE)
Block(3,14,12,SANDSTONE)
Block(3,14,13,SANDSTONE)
Block(3,14,14,SANDSTONE)
Block(3,14,15,SANDSTONE)
Block(3,14,16,SANDSTONE)
Block(3,14,17,SANDSTONE)
Block(3,14,18,SANDSTONE)
Block(3,15,-5,SANDSTONE)
Block(3,15,-4,SANDSTONE)
Block(3,15,-3,SANDSTONE)
Block(3,15,-2,SANDSTONE)
Block(3,15,-1,SANDSTONE)
Block(3,15,0,SANDSTONE)
Block(3,15,1,SANDSTONE)
Block(3,15,2,SANDSTONE)
Block(3,15,3,SANDSTONE)
Block(3,15,4,SANDSTONE)
Block(3,15,5,SANDSTONE)
Block(3,15,6,SANDSTONE)
Block(3,15,7,SANDSTONE)
Block(3,15,8,SANDSTONE)
Block(3,15,9,SANDSTONE)
Block(3,15,10,SANDSTONE)
Block(3,15,11,SANDSTONE)
Block(3,15,12,SANDSTONE)
Block(3,15,13,SANDSTONE)
Block(3,15,14,SANDSTONE)
Block(3,15,15,SANDSTONE)
Block(3,15,16,SANDSTONE)
Block(3,15,17,SANDSTONE)
Block(3,15,18,SANDSTONE)
Block(3,16,-5,SANDSTONE)
Block(3,16,-4,SANDSTONE)
Block(3,16,-3,SANDSTONE)
Block(3,16,-2,SANDSTONE)
Block(3,16,-1,SANDSTONE)
Block(3,16,0,SANDSTONE)
Block(3,16,1,SANDSTONE)
Block(3,16,2,SANDSTONE)
Block(3,16,3,SANDSTONE)
Block(3,16,4,SANDSTONE)
Block(3,16,5,SANDSTONE)
Block(3,16,6,SANDSTONE)
Block(3,16,7,SANDSTONE)
Block(3,16,8,SANDSTONE)
Block(3,16,9,SANDSTONE)
Block(3,16,10,SANDSTONE)
Block(3,16,11,SANDSTONE)
Block(3,16,12,SANDSTONE)
Block(3,16,13,SANDSTONE)
Block(3,16,14,SANDSTONE)
Block(3,16,15,SANDSTONE)
Block(3,16,16,SANDSTONE)
Block(3,16,17,SANDSTONE)
Block(3,16,18,SANDSTONE)
Block(3,17,-5,SANDSTONE)
Block(3,17,-4,SANDSTONE)
Block(3,17,-3,SANDSTONE)
Block(3,17,-2,SANDSTONE)
Block(3,17,-1,SANDSTONE)
Block(3,17,0,SANDSTONE)
Block(3,17,1,SANDSTONE)
Block(3,17,2,SANDSTONE)
Block(3,17,3,SANDSTONE)
Block(3,17,4,SANDSTONE)
Block(3,17,5,SANDSTONE)
Block(3,17,6,SANDSTONE)
Block(3,17,7,SANDSTONE)
Block(3,17,8,SANDSTONE)
Block(3,17,9,SANDSTONE)
Block(3,17,10,SANDSTONE)
Block(3,17,11,SANDSTONE)
Block(3,17,12,SANDSTONE)
Block(3,17,13,SANDSTONE)
Block(3,17,14,SANDSTONE)
Block(3,17,15,SANDSTONE)
Block(3,17,16,SANDSTONE)
Block(3,17,17,SANDSTONE)
Block(3,18,-5,SANDSTONE)
Block(3,18,-4,SANDSTONE)
Block(3,18,-3,SANDSTONE)
Block(3,18,-2,SANDSTONE)
Block(3,18,-1,SANDSTONE)
Block(3,18,0,SANDSTONE)
Block(3,18,1,SANDSTONE)
Block(3,18,2,SANDSTONE)
Block(3,18,3,SANDSTONE)
Block(3,18,4,SANDSTONE)
Block(3,18,5,SANDSTONE)
Block(3,18,6,SANDSTONE)
Block(3,18,7,SANDSTONE)
Block(3,18,8,SANDSTONE)
Block(3,18,9,SANDSTONE)
Block(3,18,10,SANDSTONE)
Block(3,18,11,SANDSTONE)
Block(3,18,12,SANDSTONE)
Block(3,18,13,SANDSTONE)
Block(3,18,14,SANDSTONE)
Block(3,18,15,SANDSTONE)
Block(3,18,16,SANDSTONE)
Block(3,18,17,SANDSTONE)
Block(3,19,-5,SANDSTONE)
Block(3,19,-4,SANDSTONE)
Block(3,19,-3,SANDSTONE)
Block(3,19,-2,SANDSTONE)
Block(3,19,-1,SANDSTONE)
Block(3,19,0,SANDSTONE)
Block(3,19,1,SANDSTONE)
Block(3,19,2,SANDSTONE)
Block(3,19,3,SANDSTONE)
Block(3,19,4,SANDSTONE)
Block(3,19,5,SANDSTONE)
Block(3,19,6,SANDSTONE)
Block(3,19,7,SANDSTONE)
Block(3,19,8,SANDSTONE)
Block(3,19,9,SANDSTONE)
Block(3,19,10,SANDSTONE)
Block(3,19,11,SANDSTONE)
Block(3,19,12,SANDSTONE)
Block(3,19,13,SANDSTONE)
Block(3,19,14,SANDSTONE)
Block(3,19,15,SANDSTONE)
Block(3,19,16,SANDSTONE)
Block(3,19,17,SANDSTONE)
Block(3,20,-5,SANDSTONE)
Block(3,20,-4,SANDSTONE)
Block(3,20,-3,SANDSTONE)
Block(3,20,-2,SANDSTONE)
Block(3,20,-1,SANDSTONE)
Block(3,20,0,SANDSTONE)
Block(3,20,1,SANDSTONE)
Block(3,20,2,SANDSTONE)
Block(3,20,3,SANDSTONE)
Block(3,20,4,SANDSTONE)
Block(3,20,5,SANDSTONE)
Block(3,20,6,SANDSTONE)
Block(3,20,7,SANDSTONE)
Block(3,20,8,SANDSTONE)
Block(3,20,9,SANDSTONE)
Block(3,20,10,SANDSTONE)
Block(3,20,11,SANDSTONE)
Block(3,20,12,SANDSTONE)
Block(3,20,13,SANDSTONE)
Block(3,20,14,SANDSTONE)
Block(3,20,15,SANDSTONE)
Block(3,20,16,SANDSTONE)
Block(3,20,17,SANDSTONE)
Block(3,21,-6,SANDSTONE)
Block(3,21,-5,SANDSTONE)
Block(3,21,-4,SANDSTONE)
Block(3,21,-3,SANDSTONE)
Block(3,21,-2,SANDSTONE)
Block(3,21,-1,SANDSTONE)
Block(3,21,0,SANDSTONE)
Block(3,21,1,SANDSTONE)
Block(3,21,2,SANDSTONE)
Block(3,21,3,SANDSTONE)
Block(3,21,4,SANDSTONE)
Block(3,21,5,SANDSTONE)
Block(3,21,6,SANDSTONE)
Block(3,21,7,SANDSTONE)
Block(3,21,8,SANDSTONE)
Block(3,21,9,SANDSTONE)
Block(3,21,10,SANDSTONE)
Block(3,21,11,SANDSTONE)
Block(3,21,12,SANDSTONE)
Block(3,21,13,SANDSTONE)
Block(3,21,14,SANDSTONE)
Block(3,21,15,SANDSTONE)
Block(3,21,16,SANDSTONE)
Block(3,22,-6,SANDSTONE)
Block(3,22,-5,SANDSTONE)
Block(3,22,-4,SANDSTONE)
Block(3,22,-3,SANDSTONE)
Block(3,22,-2,SANDSTONE)
Block(3,22,-1,SANDSTONE)
Block(3,22,0,SANDSTONE)
Block(3,22,1,SANDSTONE)
Block(3,22,2,SANDSTONE)
Block(3,22,3,SANDSTONE)
Block(3,22,4,SANDSTONE)
Block(3,22,5,SANDSTONE)
Block(3,22,6,SANDSTONE)
Block(3,22,7,SANDSTONE)
Block(3,22,8,SANDSTONE)
Block(3,22,9,SANDSTONE)
Block(3,22,10,SANDSTONE)
Block(3,22,11,SANDSTONE)
Block(3,22,12,SANDSTONE)
Block(3,22,13,SANDSTONE)
Block(3,22,14,SANDSTONE)
Block(3,22,15,SANDSTONE)
Block(3,22,16,SANDSTONE)
Block(3,23,-6,SANDSTONE)
Block(3,23,-5,SANDSTONE)
Block(3,23,-4,SANDSTONE)
Block(3,23,-3,SANDSTONE)
Block(3,23,-2,SANDSTONE)
Block(3,23,-1,SANDSTONE)
Block(3,23,0,SANDSTONE)
Block(3,23,1,SANDSTONE)
Block(3,23,2,SANDSTONE)
Block(3,23,3,SANDSTONE)
Block(3,23,4,SANDSTONE)
Block(3,23,5,SANDSTONE)
Block(3,23,6,SANDSTONE)
Block(3,23,7,SANDSTONE)
Block(3,23,8,SANDSTONE)
Block(3,23,9,SANDSTONE)
Block(3,23,10,SANDSTONE)
Block(3,23,11,SANDSTONE)
Block(3,23,12,SANDSTONE)
Block(3,23,13,SANDSTONE)
Block(3,23,14,SANDSTONE)
Block(3,23,15,SANDSTONE)
Block(3,23,16,SANDSTONE)
Block(3,24,-6,SANDSTONE)
Block(3,24,-5,SANDSTONE)
Block(3,24,-4,SANDSTONE)
Block(3,24,-3,SANDSTONE)
Block(3,24,-2,SANDSTONE)
Block(3,24,-1,SANDSTONE)
Block(3,24,0,SANDSTONE)
Block(3,24,1,SANDSTONE)
Block(3,24,2,SANDSTONE)
Block(3,24,3,SANDSTONE)
Block(3,24,4,SANDSTONE)
Block(3,24,5,SANDSTONE)
Block(3,24,6,SANDSTONE)
Block(3,24,7,SANDSTONE)
Block(3,24,8,SANDSTONE)
Block(3,24,9,SANDSTONE)
Block(3,24,10,SANDSTONE)
Block(3,24,11,SANDSTONE)
Block(3,24,12,SANDSTONE)
Block(3,24,13,SANDSTONE)
Block(3,24,14,SANDSTONE)
Block(3,24,15,SANDSTONE)
Block(3,24,16,SANDSTONE)
Block(3,25,-6,SANDSTONE)
Block(3,25,-5,SANDSTONE)
Block(3,25,-4,SANDSTONE)
Block(3,25,-3,SANDSTONE)
Block(3,25,-2,SANDSTONE)
Block(3,25,-1,SANDSTONE)
Block(3,25,0,SANDSTONE)
Block(3,25,1,SANDSTONE)
Block(3,25,2,SANDSTONE)
Block(3,25,3,SANDSTONE)
Block(3,25,4,SANDSTONE)
Block(3,25,5,SANDSTONE)
Block(3,25,6,SANDSTONE)
Block(3,25,7,SANDSTONE)
Block(3,25,8,SANDSTONE)
Block(3,25,9,SANDSTONE)
Block(3,25,10,SANDSTONE)
Block(3,25,11,SANDSTONE)
Block(3,25,12,SANDSTONE)
Block(3,25,13,SANDSTONE)
Block(3,25,14,SANDSTONE)
Block(3,25,15,SANDSTONE)
Block(3,25,16,SANDSTONE)
Block(3,26,-5,SANDSTONE)
Block(3,26,-4,SANDSTONE)
Block(3,26,-3,SANDSTONE)
Block(3,26,-2,SANDSTONE)
Block(3,26,-1,SANDSTONE)
Block(3,26,0,SANDSTONE)
Block(3,26,1,SANDSTONE)
Block(3,26,2,SANDSTONE)
Block(3,26,3,SANDSTONE)
Block(3,26,4,SANDSTONE)
Block(3,26,5,SANDSTONE)
Block(3,26,6,SANDSTONE)
Block(3,26,7,SANDSTONE)
Block(3,26,8,SANDSTONE)
Block(3,26,9,SANDSTONE)
Block(3,26,10,SANDSTONE)
Block(3,26,11,SANDSTONE)
Block(3,26,12,SANDSTONE)
Block(3,26,13,SANDSTONE)
Block(3,26,14,SANDSTONE)
Block(3,26,15,SANDSTONE)
Block(3,26,16,SANDSTONE)
Block(3,27,-4,SANDSTONE)
Block(3,27,-3,SANDSTONE)
Block(3,27,-2,SANDSTONE)
Block(3,27,-1,SANDSTONE)
Block(3,27,0,SANDSTONE)
Block(3,27,1,SANDSTONE)
Block(3,27,2,SANDSTONE)
Block(3,27,3,SANDSTONE)
Block(3,27,4,SANDSTONE)
Block(3,27,5,SANDSTONE)
Block(3,27,6,SANDSTONE)
Block(3,27,7,SANDSTONE)
Block(3,27,8,SANDSTONE)
Block(3,27,9,SANDSTONE)
Block(3,27,10,SANDSTONE)
Block(3,27,11,SANDSTONE)
Block(3,27,12,SANDSTONE)
Block(3,27,13,SANDSTONE)
Block(3,27,14,SANDSTONE)
Block(3,27,15,SANDSTONE)
Block(3,27,16,SANDSTONE)
Block(3,28,-3,SANDSTONE)
Block(3,28,-2,SANDSTONE)
Block(3,28,-1,SANDSTONE)
Block(3,28,0,SANDSTONE)
Block(3,28,1,SANDSTONE)
Block(3,28,2,SANDSTONE)
Block(3,28,3,SANDSTONE)
Block(3,28,4,SANDSTONE)
Block(3,28,5,SANDSTONE)
Block(3,28,6,SANDSTONE)
Block(3,28,7,SANDSTONE)
Block(3,28,8,SANDSTONE)
Block(3,28,9,SANDSTONE)
Block(3,28,10,SANDSTONE)
Block(3,28,11,SANDSTONE)
Block(3,28,12,SANDSTONE)
Block(3,28,13,SANDSTONE)
Block(3,28,14,SANDSTONE)
Block(3,28,15,SANDSTONE)
Block(3,28,16,SANDSTONE)
Block(3,29,-1,SANDSTONE)
Block(3,29,0,SANDSTONE)
Block(3,29,1,SANDSTONE)
Block(3,29,2,SANDSTONE)
Block(3,29,3,SANDSTONE)
Block(3,29,4,SANDSTONE)
Block(3,29,5,SANDSTONE)
Block(3,29,6,SANDSTONE)
Block(3,29,7,SANDSTONE)
Block(3,29,8,SANDSTONE)
Block(3,29,9,SANDSTONE)
Block(3,29,10,SANDSTONE)
Block(3,29,11,SANDSTONE)
Block(3,29,12,SANDSTONE)
Block(3,29,13,SANDSTONE)
Block(3,29,14,SANDSTONE)
Block(3,29,15,SANDSTONE)
Block(3,30,3,SANDSTONE)
Block(3,30,4,SANDSTONE)
Block(3,30,5,SANDSTONE)
Block(3,30,6,SANDSTONE)
Block(3,30,7,SANDSTONE)
Block(3,30,8,SANDSTONE)
Block(3,30,9,SANDSTONE)
Block(3,30,10,SANDSTONE)
Block(3,30,11,SANDSTONE)
Block(3,30,12,SANDSTONE)
Block(3,30,13,SANDSTONE)
Block(3,30,14,SANDSTONE)
Block(3,31,6,SANDSTONE)
Block(3,31,7,SANDSTONE)
Block(3,31,8,SANDSTONE)
Block(3,31,9,SANDSTONE)
Block(3,31,10,SANDSTONE)
Block(3,31,11,SANDSTONE)
Block(3,31,12,SANDSTONE)
Block(3,31,13,SANDSTONE)
Block(3,32,9,SANDSTONE)
Block(3,32,10,SANDSTONE)
Block(4,7,5,SANDSTONE)
Block(4,7,6,SANDSTONE)
Block(4,7,7,SANDSTONE)
Block(4,8,1,SANDSTONE)
Block(4,8,2,SANDSTONE)
Block(4,8,3,SANDSTONE)
Block(4,8,4,SANDSTONE)
Block(4,8,5,SANDSTONE)
Block(4,8,6,SANDSTONE)
Block(4,8,7,SANDSTONE)
Block(4,8,8,SANDSTONE)
Block(4,8,9,SANDSTONE)
Block(4,8,10,SANDSTONE)
Block(4,8,11,SANDSTONE)
Block(4,8,12,SANDSTONE)
Block(4,8,13,SANDSTONE)
Block(4,8,14,SANDSTONE)
Block(4,8,15,SANDSTONE)
Block(4,8,16,SANDSTONE)
Block(4,8,17,SANDSTONE)
Block(4,9,0,SANDSTONE)
Block(4,9,1,SANDSTONE)
Block(4,9,2,SANDSTONE)
Block(4,9,3,SANDSTONE)
Block(4,9,4,SANDSTONE)
Block(4,9,5,SANDSTONE)
Block(4,9,6,SANDSTONE)
Block(4,9,7,SANDSTONE)
Block(4,9,8,SANDSTONE)
Block(4,9,9,SANDSTONE)
Block(4,9,10,SANDSTONE)
Block(4,9,11,SANDSTONE)
Block(4,9,12,SANDSTONE)
Block(4,9,13,SANDSTONE)
Block(4,9,14,SANDSTONE)
Block(4,9,15,SANDSTONE)
Block(4,9,16,SANDSTONE)
Block(4,9,17,SANDSTONE)
Block(4,10,-1,SANDSTONE)
Block(4,10,0,SANDSTONE)
Block(4,10,1,SANDSTONE)
Block(4,10,2,SANDSTONE)
Block(4,10,3,SANDSTONE)
Block(4,10,4,SANDSTONE)
Block(4,10,5,SANDSTONE)
Block(4,10,6,SANDSTONE)
Block(4,10,7,SANDSTONE)
Block(4,10,8,SANDSTONE)
Block(4,10,9,SANDSTONE)
Block(4,10,10,SANDSTONE)
Block(4,10,11,SANDSTONE)
Block(4,10,12,SANDSTONE)
Block(4,10,13,SANDSTONE)
Block(4,10,14,SANDSTONE)
Block(4,10,15,SANDSTONE)
Block(4,10,16,SANDSTONE)
Block(4,10,17,SANDSTONE)
Block(4,10,18,SANDSTONE)
Block(4,11,-2,SANDSTONE)
Block(4,11,-1,SANDSTONE)
Block(4,11,0,SANDSTONE)
Block(4,11,1,SANDSTONE)
Block(4,11,2,SANDSTONE)
Block(4,11,3,SANDSTONE)
Block(4,11,4,SANDSTONE)
Block(4,11,5,SANDSTONE)
Block(4,11,6,SANDSTONE)
Block(4,11,7,SANDSTONE)
Block(4,11,8,SANDSTONE)
Block(4,11,9,SANDSTONE)
Block(4,11,10,SANDSTONE)
Block(4,11,11,SANDSTONE)
Block(4,11,12,SANDSTONE)
Block(4,11,13,SANDSTONE)
Block(4,11,14,SANDSTONE)
Block(4,11,15,SANDSTONE)
Block(4,11,16,SANDSTONE)
Block(4,11,17,SANDSTONE)
Block(4,11,18,SANDSTONE)
Block(4,12,-2,SANDSTONE)
Block(4,12,-1,SANDSTONE)
Block(4,12,0,SANDSTONE)
Block(4,12,1,SANDSTONE)
Block(4,12,2,SANDSTONE)
Block(4,12,3,SANDSTONE)
Block(4,12,4,SANDSTONE)
Block(4,12,5,SANDSTONE)
Block(4,12,6,SANDSTONE)
Block(4,12,7,SANDSTONE)
Block(4,12,8,SANDSTONE)
Block(4,12,9,SANDSTONE)
Block(4,12,10,SANDSTONE)
Block(4,12,11,SANDSTONE)
Block(4,12,12,SANDSTONE)
Block(4,12,13,SANDSTONE)
Block(4,12,14,SANDSTONE)
Block(4,12,15,SANDSTONE)
Block(4,12,16,SANDSTONE)
Block(4,12,17,SANDSTONE)
Block(4,12,18,SANDSTONE)
Block(4,13,-3,SANDSTONE)
Block(4,13,-2,SANDSTONE)
Block(4,13,-1,SANDSTONE)
Block(4,13,0,SANDSTONE)
Block(4,13,1,SANDSTONE)
Block(4,13,2,SANDSTONE)
Block(4,13,3,SANDSTONE)
Block(4,13,4,SANDSTONE)
Block(4,13,5,SANDSTONE)
Block(4,13,6,SANDSTONE)
Block(4,13,7,SANDSTONE)
Block(4,13,8,SANDSTONE)
Block(4,13,9,SANDSTONE)
Block(4,13,10,SANDSTONE)
Block(4,13,11,SANDSTONE)
Block(4,13,12,SANDSTONE)
Block(4,13,13,SANDSTONE)
Block(4,13,14,SANDSTONE)
Block(4,13,15,SANDSTONE)
Block(4,13,16,SANDSTONE)
Block(4,13,17,SANDSTONE)
Block(4,13,18,SANDSTONE)
Block(4,14,-4,SANDSTONE)
Block(4,14,-3,SANDSTONE)
Block(4,14,-2,SANDSTONE)
Block(4,14,-1,SANDSTONE)
Block(4,14,0,SANDSTONE)
Block(4,14,1,SANDSTONE)
Block(4,14,2,SANDSTONE)
Block(4,14,3,SANDSTONE)
Block(4,14,4,SANDSTONE)
Block(4,14,5,SANDSTONE)
Block(4,14,6,SANDSTONE)
Block(4,14,7,SANDSTONE)
Block(4,14,8,SANDSTONE)
Block(4,14,9,SANDSTONE)
Block(4,14,10,SANDSTONE)
Block(4,14,11,SANDSTONE)
Block(4,14,12,SANDSTONE)
Block(4,14,13,SANDSTONE)
Block(4,14,14,SANDSTONE)
Block(4,14,15,SANDSTONE)
Block(4,14,16,SANDSTONE)
Block(4,14,17,SANDSTONE)
Block(4,14,18,SANDSTONE)
Block(4,15,-5,SANDSTONE)
Block(4,15,-4,SANDSTONE)
Block(4,15,-3,SANDSTONE)
Block(4,15,-2,SANDSTONE)
Block(4,15,-1,SANDSTONE)
Block(4,15,0,SANDSTONE)
Block(4,15,1,SANDSTONE)
Block(4,15,2,SANDSTONE)
Block(4,15,3,SANDSTONE)
Block(4,15,4,SANDSTONE)
Block(4,15,5,SANDSTONE)
Block(4,15,6,SANDSTONE)
Block(4,15,7,SANDSTONE)
Block(4,15,8,SANDSTONE)
Block(4,15,9,SANDSTONE)
Block(4,15,10,SANDSTONE)
Block(4,15,11,SANDSTONE)
Block(4,15,12,SANDSTONE)
Block(4,15,13,SANDSTONE)
Block(4,15,14,SANDSTONE)
Block(4,15,15,SANDSTONE)
Block(4,15,16,SANDSTONE)
Block(4,15,17,SANDSTONE)
Block(4,15,18,SANDSTONE)
Block(4,16,-5,SANDSTONE)
Block(4,16,-4,SANDSTONE)
Block(4,16,-3,SANDSTONE)
Block(4,16,-2,SANDSTONE)
Block(4,16,-1,SANDSTONE)
Block(4,16,0,SANDSTONE)
Block(4,16,1,SANDSTONE)
Block(4,16,2,SANDSTONE)
Block(4,16,3,SANDSTONE)
Block(4,16,4,SANDSTONE)
Block(4,16,5,SANDSTONE)
Block(4,16,6,SANDSTONE)
Block(4,16,7,SANDSTONE)
Block(4,16,8,SANDSTONE)
Block(4,16,9,SANDSTONE)
Block(4,16,10,SANDSTONE)
Block(4,16,11,SANDSTONE)
Block(4,16,12,SANDSTONE)
Block(4,16,13,SANDSTONE)
Block(4,16,14,SANDSTONE)
Block(4,16,15,SANDSTONE)
Block(4,16,16,SANDSTONE)
Block(4,16,17,SANDSTONE)
Block(4,16,18,SANDSTONE)
Block(4,17,-5,SANDSTONE)
Block(4,17,-4,SANDSTONE)
Block(4,17,-3,SANDSTONE)
Block(4,17,-2,SANDSTONE)
Block(4,17,-1,SANDSTONE)
Block(4,17,0,SANDSTONE)
Block(4,17,1,SANDSTONE)
Block(4,17,2,SANDSTONE)
Block(4,17,3,SANDSTONE)
Block(4,17,4,SANDSTONE)
Block(4,17,5,SANDSTONE)
Block(4,17,6,SANDSTONE)
Block(4,17,7,SANDSTONE)
Block(4,17,8,SANDSTONE)
Block(4,17,9,SANDSTONE)
Block(4,17,10,SANDSTONE)
Block(4,17,11,SANDSTONE)
Block(4,17,12,SANDSTONE)
Block(4,17,13,SANDSTONE)
Block(4,17,14,SANDSTONE)
Block(4,17,15,SANDSTONE)
Block(4,17,16,SANDSTONE)
Block(4,17,17,SANDSTONE)
Block(4,17,18,SANDSTONE)
Block(4,18,-5,SANDSTONE)
Block(4,18,-4,SANDSTONE)
Block(4,18,-3,SANDSTONE)
Block(4,18,-2,SANDSTONE)
Block(4,18,-1,SANDSTONE)
Block(4,18,0,SANDSTONE)
Block(4,18,1,SANDSTONE)
Block(4,18,2,SANDSTONE)
Block(4,18,3,SANDSTONE)
Block(4,18,4,SANDSTONE)
Block(4,18,5,SANDSTONE)
Block(4,18,6,SANDSTONE)
Block(4,18,7,SANDSTONE)
Block(4,18,8,SANDSTONE)
Block(4,18,9,SANDSTONE)
Block(4,18,10,SANDSTONE)
Block(4,18,11,SANDSTONE)
Block(4,18,12,SANDSTONE)
Block(4,18,13,SANDSTONE)
Block(4,18,14,SANDSTONE)
Block(4,18,15,SANDSTONE)
Block(4,18,16,SANDSTONE)
Block(4,18,17,SANDSTONE)
Block(4,19,-5,SANDSTONE)
Block(4,19,-4,SANDSTONE)
Block(4,19,-3,SANDSTONE)
Block(4,19,-2,SANDSTONE)
Block(4,19,-1,SANDSTONE)
Block(4,19,0,SANDSTONE)
Block(4,19,1,SANDSTONE)
Block(4,19,2,SANDSTONE)
Block(4,19,3,SANDSTONE)
Block(4,19,4,SANDSTONE)
Block(4,19,5,SANDSTONE)
Block(4,19,6,SANDSTONE)
Block(4,19,7,SANDSTONE)
Block(4,19,8,SANDSTONE)
Block(4,19,9,SANDSTONE)
Block(4,19,10,SANDSTONE)
Block(4,19,11,SANDSTONE)
Block(4,19,12,SANDSTONE)
Block(4,19,13,SANDSTONE)
Block(4,19,14,SANDSTONE)
Block(4,19,15,SANDSTONE)
Block(4,19,16,SANDSTONE)
Block(4,19,17,SANDSTONE)
Block(4,20,-5,SANDSTONE)
Block(4,20,-4,SANDSTONE)
Block(4,20,-3,SANDSTONE)
Block(4,20,-2,SANDSTONE)
Block(4,20,-1,SANDSTONE)
Block(4,20,0,SANDSTONE)
Block(4,20,1,SANDSTONE)
Block(4,20,2,SANDSTONE)
Block(4,20,3,SANDSTONE)
Block(4,20,4,SANDSTONE)
Block(4,20,5,SANDSTONE)
Block(4,20,6,SANDSTONE)
Block(4,20,7,SANDSTONE)
Block(4,20,8,SANDSTONE)
Block(4,20,9,SANDSTONE)
Block(4,20,10,SANDSTONE)
Block(4,20,11,SANDSTONE)
Block(4,20,12,SANDSTONE)
Block(4,20,13,SANDSTONE)
Block(4,20,14,SANDSTONE)
Block(4,20,15,SANDSTONE)
Block(4,20,16,SANDSTONE)
Block(4,20,17,SANDSTONE)
Block(4,21,-5,SANDSTONE)
Block(4,21,-4,SANDSTONE)
Block(4,21,-3,SANDSTONE)
Block(4,21,-2,SANDSTONE)
Block(4,21,-1,SANDSTONE)
Block(4,21,0,SANDSTONE)
Block(4,21,1,SANDSTONE)
Block(4,21,2,SANDSTONE)
Block(4,21,3,SANDSTONE)
Block(4,21,4,SANDSTONE)
Block(4,21,5,SANDSTONE)
Block(4,21,6,SANDSTONE)
Block(4,21,7,SANDSTONE)
Block(4,21,8,SANDSTONE)
Block(4,21,9,SANDSTONE)
Block(4,21,10,SANDSTONE)
Block(4,21,11,SANDSTONE)
Block(4,21,12,SANDSTONE)
Block(4,21,13,SANDSTONE)
Block(4,21,14,SANDSTONE)
Block(4,21,15,SANDSTONE)
Block(4,21,16,SANDSTONE)
Block(4,22,-6,SANDSTONE)
Block(4,22,-5,SANDSTONE)
Block(4,22,-4,SANDSTONE)
Block(4,22,-3,SANDSTONE)
Block(4,22,-2,SANDSTONE)
Block(4,22,-1,SANDSTONE)
Block(4,22,0,SANDSTONE)
Block(4,22,1,SANDSTONE)
Block(4,22,2,SANDSTONE)
Block(4,22,3,SANDSTONE)
Block(4,22,4,SANDSTONE)
Block(4,22,5,SANDSTONE)
Block(4,22,6,SANDSTONE)
Block(4,22,7,SANDSTONE)
Block(4,22,8,SANDSTONE)
Block(4,22,9,SANDSTONE)
Block(4,22,10,SANDSTONE)
Block(4,22,11,SANDSTONE)
Block(4,22,12,SANDSTONE)
Block(4,22,13,SANDSTONE)
Block(4,22,14,SANDSTONE)
Block(4,22,15,SANDSTONE)
Block(4,22,16,SANDSTONE)
Block(4,23,-6,SANDSTONE)
Block(4,23,-5,SANDSTONE)
Block(4,23,-4,SANDSTONE)
Block(4,23,-3,SANDSTONE)
Block(4,23,-2,SANDSTONE)
Block(4,23,-1,SANDSTONE)
Block(4,23,0,SANDSTONE)
Block(4,23,1,SANDSTONE)
Block(4,23,2,SANDSTONE)
Block(4,23,3,SANDSTONE)
Block(4,23,4,SANDSTONE)
Block(4,23,5,SANDSTONE)
Block(4,23,6,SANDSTONE)
Block(4,23,7,SANDSTONE)
Block(4,23,8,SANDSTONE)
Block(4,23,9,SANDSTONE)
Block(4,23,10,SANDSTONE)
Block(4,23,11,SANDSTONE)
Block(4,23,12,SANDSTONE)
Block(4,23,13,SANDSTONE)
Block(4,23,14,SANDSTONE)
Block(4,23,15,SANDSTONE)
Block(4,23,16,SANDSTONE)
Block(4,24,-6,SANDSTONE)
Block(4,24,-5,SANDSTONE)
Block(4,24,-4,SANDSTONE)
Block(4,24,-3,SANDSTONE)
Block(4,24,-2,SANDSTONE)
Block(4,24,-1,SANDSTONE)
Block(4,24,0,SANDSTONE)
Block(4,24,1,SANDSTONE)
Block(4,24,2,SANDSTONE)
Block(4,24,3,SANDSTONE)
Block(4,24,4,SANDSTONE)
Block(4,24,5,SANDSTONE)
Block(4,24,6,SANDSTONE)
Block(4,24,7,SANDSTONE)
Block(4,24,8,SANDSTONE)
Block(4,24,9,SANDSTONE)
Block(4,24,10,SANDSTONE)
Block(4,24,11,SANDSTONE)
Block(4,24,12,SANDSTONE)
Block(4,24,13,SANDSTONE)
Block(4,24,14,SANDSTONE)
Block(4,24,15,SANDSTONE)
Block(4,24,16,SANDSTONE)
Block(4,25,-6,SANDSTONE)
Block(4,25,-5,SANDSTONE)
Block(4,25,-4,SANDSTONE)
Block(4,25,-3,SANDSTONE)
Block(4,25,-2,SANDSTONE)
Block(4,25,-1,SANDSTONE)
Block(4,25,0,SANDSTONE)
Block(4,25,1,SANDSTONE)
Block(4,25,2,SANDSTONE)
Block(4,25,3,SANDSTONE)
Block(4,25,4,SANDSTONE)
Block(4,25,5,SANDSTONE)
Block(4,25,6,SANDSTONE)
Block(4,25,7,SANDSTONE)
Block(4,25,8,SANDSTONE)
Block(4,25,9,SANDSTONE)
Block(4,25,10,SANDSTONE)
Block(4,25,11,SANDSTONE)
Block(4,25,12,SANDSTONE)
Block(4,25,13,SANDSTONE)
Block(4,25,14,SANDSTONE)
Block(4,25,15,SANDSTONE)
Block(4,25,16,SANDSTONE)
Block(4,26,-6,SANDSTONE)
Block(4,26,-5,SANDSTONE)
Block(4,26,-4,SANDSTONE)
Block(4,26,-3,SANDSTONE)
Block(4,26,-2,SANDSTONE)
Block(4,26,-1,SANDSTONE)
Block(4,26,0,SANDSTONE)
Block(4,26,1,SANDSTONE)
Block(4,26,2,SANDSTONE)
Block(4,26,3,SANDSTONE)
Block(4,26,4,SANDSTONE)
Block(4,26,5,SANDSTONE)
Block(4,26,6,SANDSTONE)
Block(4,26,7,SANDSTONE)
Block(4,26,8,SANDSTONE)
Block(4,26,9,SANDSTONE)
Block(4,26,10,SANDSTONE)
Block(4,26,11,SANDSTONE)
Block(4,26,12,SANDSTONE)
Block(4,26,13,SANDSTONE)
Block(4,26,14,SANDSTONE)
Block(4,26,15,SANDSTONE)
Block(4,26,16,SANDSTONE)
Block(4,27,-5,SANDSTONE)
Block(4,27,-4,SANDSTONE)
Block(4,27,-3,SANDSTONE)
Block(4,27,-2,SANDSTONE)
Block(4,27,-1,SANDSTONE)
Block(4,27,0,SANDSTONE)
Block(4,27,1,SANDSTONE)
Block(4,27,2,SANDSTONE)
Block(4,27,3,SANDSTONE)
Block(4,27,4,SANDSTONE)
Block(4,27,5,SANDSTONE)
Block(4,27,6,SANDSTONE)
Block(4,27,7,SANDSTONE)
Block(4,27,8,SANDSTONE)
Block(4,27,9,SANDSTONE)
Block(4,27,10,SANDSTONE)
Block(4,27,11,SANDSTONE)
Block(4,27,12,SANDSTONE)
Block(4,27,13,SANDSTONE)
Block(4,27,14,SANDSTONE)
Block(4,27,15,SANDSTONE)
Block(4,27,16,SANDSTONE)
Block(4,28,-4,SANDSTONE)
Block(4,28,-3,SANDSTONE)
Block(4,28,-2,SANDSTONE)
Block(4,28,-1,SANDSTONE)
Block(4,28,0,SANDSTONE)
Block(4,28,1,SANDSTONE)
Block(4,28,2,SANDSTONE)
Block(4,28,3,SANDSTONE)
Block(4,28,4,SANDSTONE)
Block(4,28,5,SANDSTONE)
Block(4,28,6,SANDSTONE)
Block(4,28,7,SANDSTONE)
Block(4,28,8,SANDSTONE)
Block(4,28,9,SANDSTONE)
Block(4,28,10,SANDSTONE)
Block(4,28,11,SANDSTONE)
Block(4,28,12,SANDSTONE)
Block(4,28,13,SANDSTONE)
Block(4,28,14,SANDSTONE)
Block(4,28,15,SANDSTONE)
Block(4,28,16,SANDSTONE)
Block(4,29,-1,SANDSTONE)
Block(4,29,0,SANDSTONE)
Block(4,29,1,SANDSTONE)
Block(4,29,2,SANDSTONE)
Block(4,29,3,SANDSTONE)
Block(4,29,4,SANDSTONE)
Block(4,29,5,SANDSTONE)
Block(4,29,6,SANDSTONE)
Block(4,29,7,SANDSTONE)
Block(4,29,8,SANDSTONE)
Block(4,29,9,SANDSTONE)
Block(4,29,10,SANDSTONE)
Block(4,29,11,SANDSTONE)
Block(4,29,12,SANDSTONE)
Block(4,29,13,SANDSTONE)
Block(4,29,14,SANDSTONE)
Block(4,29,15,SANDSTONE)
Block(4,30,2,SANDSTONE)
Block(4,30,3,SANDSTONE)
Block(4,30,4,SANDSTONE)
Block(4,30,5,SANDSTONE)
Block(4,30,6,SANDSTONE)
Block(4,30,7,SANDSTONE)
Block(4,30,8,SANDSTONE)
Block(4,30,9,SANDSTONE)
Block(4,30,10,SANDSTONE)
Block(4,30,11,SANDSTONE)
Block(4,30,12,SANDSTONE)
Block(4,30,13,SANDSTONE)
Block(4,30,14,SANDSTONE)
Block(4,31,6,SANDSTONE)
Block(4,31,7,SANDSTONE)
Block(4,31,8,SANDSTONE)
Block(4,31,9,SANDSTONE)
Block(4,31,10,SANDSTONE)
Block(4,31,11,SANDSTONE)
Block(4,31,12,SANDSTONE)
Block(4,32,9,SANDSTONE)
Block(5,7,2,SANDSTONE)
Block(5,7,3,SANDSTONE)
Block(5,7,4,SANDSTONE)
Block(5,7,5,SANDSTONE)
Block(5,7,6,SANDSTONE)
Block(5,7,7,SANDSTONE)
Block(5,7,8,SANDSTONE)
Block(5,7,9,SANDSTONE)
Block(5,7,10,SANDSTONE)
Block(5,7,11,SANDSTONE)
Block(5,7,12,SANDSTONE)
Block(5,7,13,SANDSTONE)
Block(5,8,0,SANDSTONE)
Block(5,8,1,SANDSTONE)
Block(5,8,2,SANDSTONE)
Block(5,8,3,SANDSTONE)
Block(5,8,4,SANDSTONE)
Block(5,8,5,SANDSTONE)
Block(5,8,6,SANDSTONE)
Block(5,8,7,SANDSTONE)
Block(5,8,8,SANDSTONE)
