
#######################################################################
# +-----------------------------------------------------------------+ #
# |                            BO3 object                           | #
# +-----------------------------------------------------------------+ #
#######################################################################

# This is the config file of a custom object.
# If you add this object correctly to your BiomeConfigs, it will spawn in the world.

# This is the creator of this BO3 object
Author: Unknown

# A short description of this BO3 object
Description: This BO3 was converted from a schematic using OTGEdit. The author and description information of the schematic could not be found. If you know who the author of the schematic is then please add this information.

# The BO3 version, don't change this! It can be used by external applications to do a version check.
Version: 3

# The settings mode, WriteAll, WriteWithoutComments or WriteDisable. See WorldConfig.
SettingsMode: WriteAll


#######################################################################
# +-----------------------------------------------------------------+ #
# |                          Main settings                          | #
# +-----------------------------------------------------------------+ #
#######################################################################

# This needs to be set to true to spawn the object in the Tree and Sapling resources.
Tree: true

# The frequency of the BO3 from 1 to 200. Tries this many times to spawn this BO3 when using the CustomObject(...) resource.
# Ignored by Tree(..), Sapling(..) and CustomStructure(..)
Frequency: 40

# The rarity of the BO3 from 0 to 100. Each spawn attempt has rarity% chance to succeed when using the CustomObject(...) resource.
# Ignored by Tree(..), Sapling(..) and CustomStructure(..)
Rarity: 100.0

# If you set this to true, the BO3 will be placed with a random rotation.
RotateRandomly: true

# The spawn height of the BO3: randomY, highestBlock or highestSolidBlock.
SpawnHeight: randomY

# The offset from the spawn height to spawn this BO3
# Ex. SpawnHeight = highestSolidBlock, SpawnHeightOffset = 3; This object will spawn 3 blocks above the highest solid block
SpawnHeightOffset: 0

# A random amount to offset the spawn location from the spawn offset height
# Ex. SpawnHeightOffset = 3, SpawnHeightVariance = 3; This object will spawn 3 to 6 blocks above the original spot it would have spawned
SpawnHeightVariance: 0

##############################
# Height Limits for the BO3. #
##############################

# When in randomY mode used as the minimum Y or in atMinY mode as the actual Y to spawn this BO3 at.
MinHeight: 0

# When in randomY mode used as the maximum Y to spawn this BO3 at.
MaxHeight: 256

######################
# Extrusion settings #
######################

# The style of extrusion you wish to use - BottomDown, TopUp, None (Default)
ExtrudeMode: None

# The blocks to extrude your BO3 through
ExtrudeThroughBlocks: AIR

# Objects can have other objects attacthed to it: branches. Branches can also
# have branches attached to it, which can also have branches, etc. This is the
# maximum branch depth for this objects.
MaxBranchDepth: 10

# When spawned with the UseWorld keyword, this BO3 should NOT spawn in the following biomes.
# If you write the BO3 name directly in the BiomeConfigs, this will be ignored.
ExcludedBiomes: All


#######################################################################
# +-----------------------------------------------------------------+ #
# |                      Source block settings                      | #
# +-----------------------------------------------------------------+ #
#######################################################################

# The block(s) the BO3 should spawn in.
SourceBlocks: AIR

# The maximum percentage of the BO3 that can be outside the SourceBlock.
# The BO3 won't be placed on a location with more blocks outside the SourceBlock than this percentage.
MaxPercentageOutsideSourceBlock: 100

# What to do when a block is about to be placed outside the SourceBlock? (dontPlace, placeAnyway)
OutsideSourceBlock: placeAnyway

# OTG+ settings #
# Legacy setting, rename this file to .BO4 instead. Set this to true to enable the advanced customstructure features of OTG+.
IsOTGPlus: false


#######################################################################
# +-----------------------------------------------------------------+ #
# |                              Blocks                             | #
# +-----------------------------------------------------------------+ #
#######################################################################

# All the blocks used in the BO3 are listed here. Possible blocks:
# Block(x,y,z,id[.data][,nbtfile.nbt)
# RandomBlock(x,y,z,id[:data][,nbtfile.nbt],chance[,id[:data][,nbtfile.nbt],chance[,...]])
#  So RandomBlock(0,0,0,CHEST,chest.nbt,50,CHEST,anotherchest.nbt,100) will spawn a chest at
#  the BO3 origin, and give it a 50% chance to have the contents of chest.nbt, or, if that
#  fails, a 100% percent chance to have the contents of anotherchest.nbt.
# *Note: Unlike Entity() and Spawner(), for Block() .txt files don't work, only .nbt files work.
# MinecraftObject(x,y,z,name) (TODO: This may not work anymore and needs to be tested.
#  Spawns an object in the Mojang NBT structure format. For example, 
#  MinecraftObject(0,0,0,minecraft:igloo/igloo_bottom)
#  spawns the bottom part of an igloo.
Block(-9,14,2,biomesoplenty:hard_ice)
Block(-9,14,3,biomesoplenty:hard_ice)
Block(-9,14,4,biomesoplenty:hard_ice)
Block(-9,15,3,biomesoplenty:hard_ice)
Block(-9,15,4,biomesoplenty:hard_ice)
Block(-9,15,5,biomesoplenty:hard_ice)
Block(-9,15,6,biomesoplenty:hard_ice)
Block(-9,16,4,biomesoplenty:hard_ice)
Block(-9,16,5,biomesoplenty:hard_ice)
Block(-9,16,6,biomesoplenty:hard_ice)
Block(-9,17,5,biomesoplenty:hard_ice)
Block(-9,17,6,biomesoplenty:hard_ice)
Block(-8,5,0,biomesoplenty:hard_ice)
Block(-8,5,1,biomesoplenty:hard_ice)
Block(-8,5,2,biomesoplenty:hard_ice)
Block(-8,6,-1,biomesoplenty:hard_ice)
Block(-8,6,0,biomesoplenty:hard_ice)
Block(-8,6,1,biomesoplenty:hard_ice)
Block(-8,6,2,biomesoplenty:hard_ice)
Block(-8,6,3,biomesoplenty:hard_ice)
Block(-8,6,4,biomesoplenty:hard_ice)
Block(-8,7,-1,biomesoplenty:hard_ice)
Block(-8,7,0,biomesoplenty:hard_ice)
Block(-8,7,1,biomesoplenty:hard_ice)
Block(-8,7,2,biomesoplenty:hard_ice)
Block(-8,7,3,biomesoplenty:hard_ice)
Block(-8,7,4,biomesoplenty:hard_ice)
Block(-8,7,5,biomesoplenty:hard_ice)
Block(-8,8,-1,biomesoplenty:hard_ice)
Block(-8,8,0,biomesoplenty:hard_ice)
Block(-8,8,1,biomesoplenty:hard_ice)
Block(-8,8,2,biomesoplenty:hard_ice)
Block(-8,8,3,biomesoplenty:hard_ice)
Block(-8,8,4,biomesoplenty:hard_ice)
Block(-8,8,5,biomesoplenty:hard_ice)
Block(-8,8,6,biomesoplenty:hard_ice)
Block(-8,9,-1,biomesoplenty:hard_ice)
Block(-8,9,0,biomesoplenty:hard_ice)
Block(-8,9,1,biomesoplenty:hard_ice)
Block(-8,9,2,biomesoplenty:hard_ice)
Block(-8,9,3,biomesoplenty:hard_ice)
Block(-8,9,4,biomesoplenty:hard_ice)
Block(-8,9,5,biomesoplenty:hard_ice)
Block(-8,9,6,biomesoplenty:hard_ice)
Block(-8,10,-1,biomesoplenty:hard_ice)
Block(-8,10,0,biomesoplenty:hard_ice)
Block(-8,10,1,biomesoplenty:hard_ice)
Block(-8,10,2,biomesoplenty:hard_ice)
Block(-8,10,3,biomesoplenty:hard_ice)
Block(-8,10,4,biomesoplenty:hard_ice)
Block(-8,10,5,biomesoplenty:hard_ice)
Block(-8,10,6,biomesoplenty:hard_ice)
Block(-8,10,7,biomesoplenty:hard_ice)
Block(-8,11,-1,biomesoplenty:hard_ice)
Block(-8,11,0,biomesoplenty:hard_ice)
Block(-8,11,1,biomesoplenty:hard_ice)
Block(-8,11,2,biomesoplenty:hard_ice)
Block(-8,11,3,biomesoplenty:hard_ice)
Block(-8,11,4,biomesoplenty:hard_ice)
Block(-8,11,5,biomesoplenty:hard_ice)
Block(-8,11,6,biomesoplenty:hard_ice)
Block(-8,11,7,biomesoplenty:hard_ice)
Block(-8,12,-1,biomesoplenty:hard_ice)
Block(-8,12,0,biomesoplenty:hard_ice)
Block(-8,12,1,biomesoplenty:hard_ice)
Block(-8,12,2,biomesoplenty:hard_ice)
Block(-8,12,3,biomesoplenty:hard_ice)
Block(-8,12,4,biomesoplenty:hard_ice)
Block(-8,12,5,biomesoplenty:hard_ice)
Block(-8,12,6,biomesoplenty:hard_ice)
Block(-8,12,7,biomesoplenty:hard_ice)
Block(-8,12,8,biomesoplenty:hard_ice)
Block(-8,13,-1,biomesoplenty:hard_ice)
Block(-8,13,0,biomesoplenty:hard_ice)
Block(-8,13,1,biomesoplenty:hard_ice)
Block(-8,13,2,biomesoplenty:hard_ice)
Block(-8,13,3,biomesoplenty:hard_ice)
Block(-8,13,4,biomesoplenty:hard_ice)
Block(-8,13,5,biomesoplenty:hard_ice)
Block(-8,13,6,biomesoplenty:hard_ice)
Block(-8,13,7,biomesoplenty:hard_ice)
Block(-8,13,8,biomesoplenty:hard_ice)
Block(-8,14,-2,biomesoplenty:hard_ice)
Block(-8,14,-1,biomesoplenty:hard_ice)
Block(-8,14,0,biomesoplenty:hard_ice)
Block(-8,14,1,biomesoplenty:hard_ice)
Block(-8,14,2,biomesoplenty:hard_ice)
Block(-8,14,3,biomesoplenty:hard_ice)
Block(-8,14,4,biomesoplenty:hard_ice)
Block(-8,14,5,biomesoplenty:hard_ice)
Block(-8,14,6,biomesoplenty:hard_ice)
Block(-8,14,7,biomesoplenty:hard_ice)
Block(-8,14,8,biomesoplenty:hard_ice)
Block(-8,14,9,biomesoplenty:hard_ice)
Block(-8,15,-2,biomesoplenty:hard_ice)
Block(-8,15,-1,biomesoplenty:hard_ice)
Block(-8,15,0,biomesoplenty:hard_ice)
Block(-8,15,1,biomesoplenty:hard_ice)
Block(-8,15,2,biomesoplenty:hard_ice)
Block(-8,15,3,biomesoplenty:hard_ice)
Block(-8,15,4,biomesoplenty:hard_ice)
Block(-8,15,5,biomesoplenty:hard_ice)
Block(-8,15,6,biomesoplenty:hard_ice)
Block(-8,15,7,biomesoplenty:hard_ice)
Block(-8,15,8,biomesoplenty:hard_ice)
Block(-8,15,9,biomesoplenty:hard_ice)
Block(-8,16,-2,biomesoplenty:hard_ice)
Block(-8,16,-1,biomesoplenty:hard_ice)
Block(-8,16,0,biomesoplenty:hard_ice)
Block(-8,16,1,biomesoplenty:hard_ice)
Block(-8,16,2,biomesoplenty:hard_ice)
Block(-8,16,3,biomesoplenty:hard_ice)
Block(-8,16,4,biomesoplenty:hard_ice)
Block(-8,16,5,biomesoplenty:hard_ice)
Block(-8,16,6,biomesoplenty:hard_ice)
Block(-8,16,7,biomesoplenty:hard_ice)
Block(-8,16,8,biomesoplenty:hard_ice)
Block(-8,16,9,biomesoplenty:hard_ice)
Block(-8,17,0,biomesoplenty:hard_ice)
Block(-8,17,1,biomesoplenty:hard_ice)
Block(-8,17,2,biomesoplenty:hard_ice)
Block(-8,17,3,biomesoplenty:hard_ice)
Block(-8,17,4,biomesoplenty:hard_ice)
Block(-8,17,5,biomesoplenty:hard_ice)
Block(-8,17,6,biomesoplenty:hard_ice)
Block(-8,17,7,biomesoplenty:hard_ice)
Block(-8,17,8,biomesoplenty:hard_ice)
Block(-8,18,1,biomesoplenty:hard_ice)
Block(-8,18,2,biomesoplenty:hard_ice)
Block(-8,18,3,biomesoplenty:hard_ice)
Block(-8,18,4,biomesoplenty:hard_ice)
Block(-8,18,5,biomesoplenty:hard_ice)
Block(-8,18,6,biomesoplenty:hard_ice)
Block(-8,18,7,biomesoplenty:hard_ice)
Block(-8,18,8,biomesoplenty:hard_ice)
Block(-7,4,0,biomesoplenty:hard_ice)
Block(-7,4,1,biomesoplenty:hard_ice)
Block(-7,4,2,biomesoplenty:hard_ice)
Block(-7,4,3,biomesoplenty:hard_ice)
Block(-7,4,4,biomesoplenty:hard_ice)
Block(-7,5,-3,biomesoplenty:hard_ice)
Block(-7,5,-2,biomesoplenty:hard_ice)
Block(-7,5,-1,biomesoplenty:hard_ice)
Block(-7,5,0,biomesoplenty:hard_ice)
Block(-7,5,1,biomesoplenty:hard_ice)
Block(-7,5,2,biomesoplenty:hard_ice)
Block(-7,5,3,biomesoplenty:hard_ice)
Block(-7,5,4,biomesoplenty:hard_ice)
Block(-7,5,5,biomesoplenty:hard_ice)
Block(-7,6,-3,biomesoplenty:hard_ice)
Block(-7,6,-2,biomesoplenty:hard_ice)
Block(-7,6,-1,biomesoplenty:hard_ice)
Block(-7,6,0,biomesoplenty:hard_ice)
Block(-7,6,1,biomesoplenty:hard_ice)
Block(-7,6,2,biomesoplenty:hard_ice)
Block(-7,6,3,biomesoplenty:hard_ice)
Block(-7,6,4,biomesoplenty:hard_ice)
Block(-7,6,5,biomesoplenty:hard_ice)
Block(-7,6,6,biomesoplenty:hard_ice)
Block(-7,6,7,biomesoplenty:hard_ice)
Block(-7,7,-3,biomesoplenty:hard_ice)
Block(-7,7,-2,biomesoplenty:hard_ice)
Block(-7,7,-1,biomesoplenty:hard_ice)
Block(-7,7,0,biomesoplenty:hard_ice)
Block(-7,7,1,biomesoplenty:hard_ice)
Block(-7,7,2,biomesoplenty:hard_ice)
Block(-7,7,3,biomesoplenty:hard_ice)
Block(-7,7,4,biomesoplenty:hard_ice)
Block(-7,7,5,biomesoplenty:hard_ice)
Block(-7,7,6,biomesoplenty:hard_ice)
Block(-7,7,7,biomesoplenty:hard_ice)
Block(-7,8,-3,biomesoplenty:hard_ice)
Block(-7,8,-2,biomesoplenty:hard_ice)
Block(-7,8,-1,biomesoplenty:hard_ice)
Block(-7,8,0,biomesoplenty:hard_ice)
Block(-7,8,1,biomesoplenty:hard_ice)
Block(-7,8,2,biomesoplenty:hard_ice)
Block(-7,8,3,biomesoplenty:hard_ice)
Block(-7,8,4,biomesoplenty:hard_ice)
Block(-7,8,5,biomesoplenty:hard_ice)
Block(-7,8,6,biomesoplenty:hard_ice)
Block(-7,8,7,biomesoplenty:hard_ice)
Block(-7,8,8,biomesoplenty:hard_ice)
Block(-7,9,-3,biomesoplenty:hard_ice)
Block(-7,9,-2,biomesoplenty:hard_ice)
Block(-7,9,-1,biomesoplenty:hard_ice)
Block(-7,9,0,biomesoplenty:hard_ice)
Block(-7,9,1,biomesoplenty:hard_ice)
Block(-7,9,2,biomesoplenty:hard_ice)
Block(-7,9,3,biomesoplenty:hard_ice)
Block(-7,9,4,biomesoplenty:hard_ice)
Block(-7,9,5,biomesoplenty:hard_ice)
Block(-7,9,6,biomesoplenty:hard_ice)
Block(-7,9,7,biomesoplenty:hard_ice)
Block(-7,9,8,biomesoplenty:hard_ice)
Block(-7,10,-3,biomesoplenty:hard_ice)
Block(-7,10,-2,biomesoplenty:hard_ice)
Block(-7,10,-1,biomesoplenty:hard_ice)
Block(-7,10,0,biomesoplenty:hard_ice)
Block(-7,10,1,biomesoplenty:hard_ice)
Block(-7,10,2,biomesoplenty:hard_ice)
Block(-7,10,3,biomesoplenty:hard_ice)
Block(-7,10,4,biomesoplenty:hard_ice)
Block(-7,10,5,biomesoplenty:hard_ice)
Block(-7,10,6,biomesoplenty:hard_ice)
Block(-7,10,7,biomesoplenty:hard_ice)
Block(-7,10,8,biomesoplenty:hard_ice)
Block(-7,10,9,biomesoplenty:hard_ice)
Block(-7,11,-3,biomesoplenty:hard_ice)
Block(-7,11,-2,biomesoplenty:hard_ice)
Block(-7,11,-1,biomesoplenty:hard_ice)
Block(-7,11,0,biomesoplenty:hard_ice)
Block(-7,11,1,biomesoplenty:hard_ice)
Block(-7,11,2,biomesoplenty:hard_ice)
Block(-7,11,3,biomesoplenty:hard_ice)
Block(-7,11,4,biomesoplenty:hard_ice)
Block(-7,11,5,biomesoplenty:hard_ice)
Block(-7,11,6,biomesoplenty:hard_ice)
Block(-7,11,7,biomesoplenty:hard_ice)
Block(-7,11,8,biomesoplenty:hard_ice)
Block(-7,11,9,biomesoplenty:hard_ice)
Block(-7,11,10,biomesoplenty:hard_ice)
Block(-7,12,-3,biomesoplenty:hard_ice)
Block(-7,12,-2,biomesoplenty:hard_ice)
Block(-7,12,-1,biomesoplenty:hard_ice)
Block(-7,12,0,biomesoplenty:hard_ice)
Block(-7,12,1,biomesoplenty:hard_ice)
Block(-7,12,2,biomesoplenty:hard_ice)
Block(-7,12,3,biomesoplenty:hard_ice)
Block(-7,12,4,biomesoplenty:hard_ice)
Block(-7,12,5,biomesoplenty:hard_ice)
Block(-7,12,6,biomesoplenty:hard_ice)
Block(-7,12,7,biomesoplenty:hard_ice)
Block(-7,12,8,biomesoplenty:hard_ice)
Block(-7,12,9,biomesoplenty:hard_ice)
Block(-7,12,10,biomesoplenty:hard_ice)
Block(-7,13,-3,biomesoplenty:hard_ice)
Block(-7,13,-2,biomesoplenty:hard_ice)
Block(-7,13,-1,biomesoplenty:hard_ice)
Block(-7,13,0,biomesoplenty:hard_ice)
Block(-7,13,1,biomesoplenty:hard_ice)
Block(-7,13,2,biomesoplenty:hard_ice)
Block(-7,13,3,biomesoplenty:hard_ice)
Block(-7,13,4,biomesoplenty:hard_ice)
Block(-7,13,5,biomesoplenty:hard_ice)
Block(-7,13,6,biomesoplenty:hard_ice)
Block(-7,13,7,biomesoplenty:hard_ice)
Block(-7,13,8,biomesoplenty:hard_ice)
Block(-7,13,9,biomesoplenty:hard_ice)
Block(-7,13,10,biomesoplenty:hard_ice)
Block(-7,14,-3,biomesoplenty:hard_ice)
Block(-7,14,-2,biomesoplenty:hard_ice)
Block(-7,14,-1,biomesoplenty:hard_ice)
Block(-7,14,0,biomesoplenty:hard_ice)
Block(-7,14,1,biomesoplenty:hard_ice)
Block(-7,14,2,biomesoplenty:hard_ice)
Block(-7,14,3,biomesoplenty:hard_ice)
Block(-7,14,4,biomesoplenty:hard_ice)
Block(-7,14,5,biomesoplenty:hard_ice)
Block(-7,14,6,biomesoplenty:hard_ice)
Block(-7,14,7,biomesoplenty:hard_ice)
Block(-7,14,8,biomesoplenty:hard_ice)
Block(-7,14,9,biomesoplenty:hard_ice)
Block(-7,14,10,biomesoplenty:hard_ice)
Block(-7,14,11,biomesoplenty:hard_ice)
Block(-7,15,-4,biomesoplenty:hard_ice)
Block(-7,15,-3,biomesoplenty:hard_ice)
Block(-7,15,-2,biomesoplenty:hard_ice)
Block(-7,15,-1,biomesoplenty:hard_ice)
Block(-7,15,0,biomesoplenty:hard_ice)
Block(-7,15,1,biomesoplenty:hard_ice)
Block(-7,15,2,biomesoplenty:hard_ice)
Block(-7,15,3,biomesoplenty:hard_ice)
Block(-7,15,4,biomesoplenty:hard_ice)
Block(-7,15,5,biomesoplenty:hard_ice)
Block(-7,15,6,biomesoplenty:hard_ice)
Block(-7,15,7,biomesoplenty:hard_ice)
Block(-7,15,8,biomesoplenty:hard_ice)
Block(-7,15,9,biomesoplenty:hard_ice)
Block(-7,15,10,biomesoplenty:hard_ice)
Block(-7,15,11,biomesoplenty:hard_ice)
Block(-7,16,-4,biomesoplenty:hard_ice)
Block(-7,16,-3,biomesoplenty:hard_ice)
Block(-7,16,-2,biomesoplenty:hard_ice)
Block(-7,16,-1,biomesoplenty:hard_ice)
Block(-7,16,0,biomesoplenty:hard_ice)
Block(-7,16,1,biomesoplenty:hard_ice)
Block(-7,16,2,biomesoplenty:hard_ice)
Block(-7,16,3,biomesoplenty:hard_ice)
Block(-7,16,4,biomesoplenty:hard_ice)
Block(-7,16,5,biomesoplenty:hard_ice)
Block(-7,16,6,biomesoplenty:hard_ice)
Block(-7,16,7,biomesoplenty:hard_ice)
Block(-7,16,8,biomesoplenty:hard_ice)
Block(-7,16,9,biomesoplenty:hard_ice)
Block(-7,16,10,biomesoplenty:hard_ice)
Block(-7,16,11,biomesoplenty:hard_ice)
Block(-7,17,-4,biomesoplenty:hard_ice)
Block(-7,17,-3,biomesoplenty:hard_ice)
Block(-7,17,-2,biomesoplenty:hard_ice)
Block(-7,17,-1,biomesoplenty:hard_ice)
Block(-7,17,0,biomesoplenty:hard_ice)
Block(-7,17,1,biomesoplenty:hard_ice)
Block(-7,17,2,biomesoplenty:hard_ice)
Block(-7,17,3,biomesoplenty:hard_ice)
Block(-7,17,4,biomesoplenty:hard_ice)
Block(-7,17,5,biomesoplenty:hard_ice)
Block(-7,17,6,biomesoplenty:hard_ice)
Block(-7,17,7,biomesoplenty:hard_ice)
Block(-7,17,8,biomesoplenty:hard_ice)
Block(-7,17,9,biomesoplenty:hard_ice)
Block(-7,17,10,biomesoplenty:hard_ice)
Block(-7,17,11,biomesoplenty:hard_ice)
Block(-7,18,-4,biomesoplenty:hard_ice)
Block(-7,18,-3,biomesoplenty:hard_ice)
Block(-7,18,-2,biomesoplenty:hard_ice)
Block(-7,18,-1,biomesoplenty:hard_ice)
Block(-7,18,0,biomesoplenty:hard_ice)
Block(-7,18,1,biomesoplenty:hard_ice)
Block(-7,18,2,biomesoplenty:hard_ice)
Block(-7,18,3,biomesoplenty:hard_ice)
Block(-7,18,4,biomesoplenty:hard_ice)
Block(-7,18,5,biomesoplenty:hard_ice)
Block(-7,18,6,biomesoplenty:hard_ice)
Block(-7,18,7,biomesoplenty:hard_ice)
Block(-7,18,8,biomesoplenty:hard_ice)
Block(-7,18,9,biomesoplenty:hard_ice)
Block(-7,18,10,biomesoplenty:hard_ice)
Block(-7,19,-4,biomesoplenty:hard_ice)
Block(-7,19,-3,biomesoplenty:hard_ice)
Block(-7,19,-2,biomesoplenty:hard_ice)
Block(-7,19,-1,biomesoplenty:hard_ice)
Block(-7,19,0,biomesoplenty:hard_ice)
Block(-7,19,1,biomesoplenty:hard_ice)
Block(-7,19,2,biomesoplenty:hard_ice)
Block(-7,19,3,biomesoplenty:hard_ice)
Block(-7,19,4,biomesoplenty:hard_ice)
Block(-7,19,5,biomesoplenty:hard_ice)
Block(-7,19,6,biomesoplenty:hard_ice)
Block(-6,3,5,biomesoplenty:hard_ice)
Block(-6,3,6,biomesoplenty:hard_ice)
Block(-6,4,-1,biomesoplenty:hard_ice)
Block(-6,4,0,biomesoplenty:hard_ice)
Block(-6,4,1,biomesoplenty:hard_ice)
Block(-6,4,2,biomesoplenty:hard_ice)
Block(-6,4,3,biomesoplenty:hard_ice)
Block(-6,4,4,biomesoplenty:hard_ice)
Block(-6,4,5,biomesoplenty:hard_ice)
Block(-6,4,6,biomesoplenty:hard_ice)
Block(-6,4,7,biomesoplenty:hard_ice)
Block(-6,5,-4,biomesoplenty:hard_ice)
Block(-6,5,-3,biomesoplenty:hard_ice)
Block(-6,5,-2,biomesoplenty:hard_ice)
Block(-6,5,-1,biomesoplenty:hard_ice)
Block(-6,5,0,biomesoplenty:hard_ice)
Block(-6,5,1,biomesoplenty:hard_ice)
Block(-6,5,2,biomesoplenty:hard_ice)
Block(-6,5,3,biomesoplenty:hard_ice)
Block(-6,5,4,biomesoplenty:hard_ice)
Block(-6,5,5,biomesoplenty:hard_ice)
Block(-6,5,6,biomesoplenty:hard_ice)
Block(-6,5,7,biomesoplenty:hard_ice)
Block(-6,5,8,biomesoplenty:hard_ice)
Block(-6,6,-4,biomesoplenty:hard_ice)
Block(-6,6,-3,biomesoplenty:hard_ice)
Block(-6,6,-2,biomesoplenty:hard_ice)
Block(-6,6,-1,biomesoplenty:hard_ice)
Block(-6,6,0,biomesoplenty:hard_ice)
Block(-6,6,1,biomesoplenty:hard_ice)
Block(-6,6,2,biomesoplenty:hard_ice)
Block(-6,6,3,biomesoplenty:hard_ice)
Block(-6,6,4,biomesoplenty:hard_ice)
Block(-6,6,5,biomesoplenty:hard_ice)
Block(-6,6,6,biomesoplenty:hard_ice)
Block(-6,6,7,biomesoplenty:hard_ice)
Block(-6,6,8,biomesoplenty:hard_ice)
Block(-6,7,-5,biomesoplenty:hard_ice)
Block(-6,7,-4,biomesoplenty:hard_ice)
Block(-6,7,-3,biomesoplenty:hard_ice)
Block(-6,7,-2,biomesoplenty:hard_ice)
Block(-6,7,-1,biomesoplenty:hard_ice)
Block(-6,7,0,biomesoplenty:hard_ice)
Block(-6,7,1,biomesoplenty:hard_ice)
Block(-6,7,2,biomesoplenty:hard_ice)
Block(-6,7,3,biomesoplenty:hard_ice)
Block(-6,7,4,biomesoplenty:hard_ice)
Block(-6,7,5,biomesoplenty:hard_ice)
Block(-6,7,6,biomesoplenty:hard_ice)
Block(-6,7,7,biomesoplenty:hard_ice)
Block(-6,7,8,biomesoplenty:hard_ice)
Block(-6,7,9,biomesoplenty:hard_ice)
Block(-6,8,-5,biomesoplenty:hard_ice)
Block(-6,8,-4,biomesoplenty:hard_ice)
Block(-6,8,-3,biomesoplenty:hard_ice)
Block(-6,8,-2,biomesoplenty:hard_ice)
Block(-6,8,-1,biomesoplenty:hard_ice)
Block(-6,8,0,biomesoplenty:hard_ice)
Block(-6,8,1,biomesoplenty:hard_ice)
Block(-6,8,2,biomesoplenty:hard_ice)
Block(-6,8,3,biomesoplenty:hard_ice)
Block(-6,8,4,biomesoplenty:hard_ice)
Block(-6,8,5,biomesoplenty:hard_ice)
Block(-6,8,6,biomesoplenty:hard_ice)
Block(-6,8,7,biomesoplenty:hard_ice)
Block(-6,8,8,biomesoplenty:hard_ice)
Block(-6,8,9,biomesoplenty:hard_ice)
Block(-6,8,10,biomesoplenty:hard_ice)
Block(-6,9,-5,biomesoplenty:hard_ice)
Block(-6,9,-4,biomesoplenty:hard_ice)
Block(-6,9,-3,biomesoplenty:hard_ice)
Block(-6,9,-2,biomesoplenty:hard_ice)
Block(-6,9,-1,biomesoplenty:hard_ice)
Block(-6,9,0,biomesoplenty:hard_ice)
Block(-6,9,1,biomesoplenty:hard_ice)
Block(-6,9,2,biomesoplenty:hard_ice)
Block(-6,9,3,biomesoplenty:hard_ice)
Block(-6,9,4,biomesoplenty:hard_ice)
Block(-6,9,5,biomesoplenty:hard_ice)
Block(-6,9,6,biomesoplenty:hard_ice)
Block(-6,9,7,biomesoplenty:hard_ice)
Block(-6,9,8,biomesoplenty:hard_ice)
Block(-6,9,9,biomesoplenty:hard_ice)
Block(-6,9,10,biomesoplenty:hard_ice)
Block(-6,9,11,biomesoplenty:hard_ice)
Block(-6,10,-5,biomesoplenty:hard_ice)
Block(-6,10,-4,biomesoplenty:hard_ice)
Block(-6,10,-3,biomesoplenty:hard_ice)
Block(-6,10,-2,biomesoplenty:hard_ice)
Block(-6,10,-1,biomesoplenty:hard_ice)
Block(-6,10,0,biomesoplenty:hard_ice)
Block(-6,10,1,biomesoplenty:hard_ice)
Block(-6,10,2,biomesoplenty:hard_ice)
Block(-6,10,3,biomesoplenty:hard_ice)
Block(-6,10,4,biomesoplenty:hard_ice)
Block(-6,10,5,biomesoplenty:hard_ice)
Block(-6,10,6,biomesoplenty:hard_ice)
Block(-6,10,7,biomesoplenty:hard_ice)
Block(-6,10,8,biomesoplenty:hard_ice)
Block(-6,10,9,biomesoplenty:hard_ice)
Block(-6,10,10,biomesoplenty:hard_ice)
Block(-6,10,11,biomesoplenty:hard_ice)
Block(-6,11,-5,biomesoplenty:hard_ice)
Block(-6,11,-4,biomesoplenty:hard_ice)
Block(-6,11,-3,biomesoplenty:hard_ice)
Block(-6,11,-2,biomesoplenty:hard_ice)
Block(-6,11,-1,biomesoplenty:hard_ice)
Block(-6,11,0,biomesoplenty:hard_ice)
Block(-6,11,1,biomesoplenty:hard_ice)
Block(-6,11,2,biomesoplenty:hard_ice)
Block(-6,11,3,biomesoplenty:hard_ice)
Block(-6,11,4,biomesoplenty:hard_ice)
Block(-6,11,5,biomesoplenty:hard_ice)
Block(-6,11,6,biomesoplenty:hard_ice)
Block(-6,11,7,biomesoplenty:hard_ice)
Block(-6,11,8,biomesoplenty:hard_ice)
Block(-6,11,9,biomesoplenty:hard_ice)
Block(-6,11,10,biomesoplenty:hard_ice)
Block(-6,11,11,biomesoplenty:hard_ice)
Block(-6,12,-5,biomesoplenty:hard_ice)
Block(-6,12,-4,biomesoplenty:hard_ice)
Block(-6,12,-3,biomesoplenty:hard_ice)
Block(-6,12,-2,biomesoplenty:hard_ice)
Block(-6,12,-1,biomesoplenty:hard_ice)
Block(-6,12,0,biomesoplenty:hard_ice)
Block(-6,12,1,biomesoplenty:hard_ice)
Block(-6,12,2,biomesoplenty:hard_ice)
Block(-6,12,3,biomesoplenty:hard_ice)
Block(-6,12,4,biomesoplenty:hard_ice)
Block(-6,12,5,biomesoplenty:hard_ice)
Block(-6,12,6,biomesoplenty:hard_ice)
Block(-6,12,7,biomesoplenty:hard_ice)
Block(-6,12,8,biomesoplenty:hard_ice)
Block(-6,12,9,biomesoplenty:hard_ice)
Block(-6,12,10,biomesoplenty:hard_ice)
Block(-6,12,11,biomesoplenty:hard_ice)
Block(-6,12,12,biomesoplenty:hard_ice)
Block(-6,13,-5,biomesoplenty:hard_ice)
Block(-6,13,-4,biomesoplenty:hard_ice)
Block(-6,13,-3,biomesoplenty:hard_ice)
Block(-6,13,-2,biomesoplenty:hard_ice)
Block(-6,13,-1,biomesoplenty:hard_ice)
Block(-6,13,0,biomesoplenty:hard_ice)
Block(-6,13,1,biomesoplenty:hard_ice)
Block(-6,13,2,biomesoplenty:hard_ice)
Block(-6,13,3,biomesoplenty:hard_ice)
Block(-6,13,4,biomesoplenty:hard_ice)
Block(-6,13,5,biomesoplenty:hard_ice)
Block(-6,13,6,biomesoplenty:hard_ice)
Block(-6,13,7,biomesoplenty:hard_ice)
Block(-6,13,8,biomesoplenty:hard_ice)
Block(-6,13,9,biomesoplenty:hard_ice)
Block(-6,13,10,biomesoplenty:hard_ice)
Block(-6,13,11,biomesoplenty:hard_ice)
Block(-6,13,12,biomesoplenty:hard_ice)
Block(-6,14,-5,biomesoplenty:hard_ice)
Block(-6,14,-4,biomesoplenty:hard_ice)
Block(-6,14,-3,biomesoplenty:hard_ice)
Block(-6,14,-2,biomesoplenty:hard_ice)
Block(-6,14,-1,biomesoplenty:hard_ice)
Block(-6,14,0,biomesoplenty:hard_ice)
Block(-6,14,1,biomesoplenty:hard_ice)
Block(-6,14,2,biomesoplenty:hard_ice)
Block(-6,14,3,biomesoplenty:hard_ice)
Block(-6,14,4,biomesoplenty:hard_ice)
Block(-6,14,5,biomesoplenty:hard_ice)
Block(-6,14,6,biomesoplenty:hard_ice)
Block(-6,14,7,biomesoplenty:hard_ice)
Block(-6,14,8,biomesoplenty:hard_ice)
Block(-6,14,9,biomesoplenty:hard_ice)
Block(-6,14,10,biomesoplenty:hard_ice)
Block(-6,14,11,biomesoplenty:hard_ice)
Block(-6,14,12,biomesoplenty:hard_ice)
Block(-6,15,-5,biomesoplenty:hard_ice)
Block(-6,15,-4,biomesoplenty:hard_ice)
Block(-6,15,-3,biomesoplenty:hard_ice)
Block(-6,15,-2,biomesoplenty:hard_ice)
Block(-6,15,-1,biomesoplenty:hard_ice)
Block(-6,15,0,biomesoplenty:hard_ice)
Block(-6,15,1,biomesoplenty:hard_ice)
Block(-6,15,2,biomesoplenty:hard_ice)
Block(-6,15,3,biomesoplenty:hard_ice)
Block(-6,15,4,biomesoplenty:hard_ice)
Block(-6,15,5,biomesoplenty:hard_ice)
Block(-6,15,6,biomesoplenty:hard_ice)
Block(-6,15,7,biomesoplenty:hard_ice)
Block(-6,15,8,biomesoplenty:hard_ice)
Block(-6,15,9,biomesoplenty:hard_ice)
Block(-6,15,10,biomesoplenty:hard_ice)
Block(-6,15,11,biomesoplenty:hard_ice)
Block(-6,15,12,biomesoplenty:hard_ice)
Block(-6,16,-5,biomesoplenty:hard_ice)
Block(-6,16,-4,biomesoplenty:hard_ice)
Block(-6,16,-3,biomesoplenty:hard_ice)
Block(-6,16,-2,biomesoplenty:hard_ice)
Block(-6,16,-1,biomesoplenty:hard_ice)
Block(-6,16,0,biomesoplenty:hard_ice)
Block(-6,16,1,biomesoplenty:hard_ice)
Block(-6,16,2,biomesoplenty:hard_ice)
Block(-6,16,3,biomesoplenty:hard_ice)
Block(-6,16,4,biomesoplenty:hard_ice)
Block(-6,16,5,biomesoplenty:hard_ice)
Block(-6,16,6,biomesoplenty:hard_ice)
Block(-6,16,7,biomesoplenty:hard_ice)
Block(-6,16,8,biomesoplenty:hard_ice)
Block(-6,16,9,biomesoplenty:hard_ice)
Block(-6,16,10,biomesoplenty:hard_ice)
Block(-6,16,11,biomesoplenty:hard_ice)
Block(-6,16,12,biomesoplenty:hard_ice)
Block(-6,17,-5,biomesoplenty:hard_ice)
Block(-6,17,-4,biomesoplenty:hard_ice)
Block(-6,17,-3,biomesoplenty:hard_ice)
Block(-6,17,-2,biomesoplenty:hard_ice)
Block(-6,17,-1,biomesoplenty:hard_ice)
Block(-6,17,0,biomesoplenty:hard_ice)
Block(-6,17,1,biomesoplenty:hard_ice)
Block(-6,17,2,biomesoplenty:hard_ice)
Block(-6,17,3,biomesoplenty:hard_ice)
Block(-6,17,4,biomesoplenty:hard_ice)
Block(-6,17,5,biomesoplenty:hard_ice)
Block(-6,17,6,biomesoplenty:hard_ice)
Block(-6,17,7,biomesoplenty:hard_ice)
Block(-6,17,8,biomesoplenty:hard_ice)
Block(-6,17,9,biomesoplenty:hard_ice)
Block(-6,17,10,biomesoplenty:hard_ice)
Block(-6,17,11,biomesoplenty:hard_ice)
Block(-6,17,12,biomesoplenty:hard_ice)
Block(-6,18,-6,biomesoplenty:hard_ice)
Block(-6,18,-5,biomesoplenty:hard_ice)
Block(-6,18,-4,biomesoplenty:hard_ice)
Block(-6,18,-3,biomesoplenty:hard_ice)
Block(-6,18,-2,biomesoplenty:hard_ice)
Block(-6,18,-1,biomesoplenty:hard_ice)
Block(-6,18,0,biomesoplenty:hard_ice)
Block(-6,18,1,biomesoplenty:hard_ice)
Block(-6,18,2,biomesoplenty:hard_ice)
Block(-6,18,3,biomesoplenty:hard_ice)
Block(-6,18,4,biomesoplenty:hard_ice)
Block(-6,18,5,biomesoplenty:hard_ice)
Block(-6,18,6,biomesoplenty:hard_ice)
Block(-6,18,7,biomesoplenty:hard_ice)
Block(-6,18,8,biomesoplenty:hard_ice)
Block(-6,18,9,biomesoplenty:hard_ice)
Block(-6,18,10,biomesoplenty:hard_ice)
Block(-6,18,11,biomesoplenty:hard_ice)
Block(-6,19,-6,biomesoplenty:hard_ice)
Block(-6,19,-5,biomesoplenty:hard_ice)
Block(-6,19,-4,biomesoplenty:hard_ice)
Block(-6,19,-3,biomesoplenty:hard_ice)
Block(-6,19,-2,biomesoplenty:hard_ice)
Block(-6,19,-1,biomesoplenty:hard_ice)
Block(-6,19,0,biomesoplenty:hard_ice)
Block(-6,19,1,biomesoplenty:hard_ice)
Block(-6,19,2,biomesoplenty:hard_ice)
Block(-6,19,3,biomesoplenty:hard_ice)
Block(-6,19,4,biomesoplenty:hard_ice)
Block(-6,19,5,biomesoplenty:hard_ice)
Block(-6,19,6,biomesoplenty:hard_ice)
Block(-6,19,7,biomesoplenty:hard_ice)
Block(-6,19,8,biomesoplenty:hard_ice)
Block(-5,3,5,biomesoplenty:hard_ice)
Block(-5,3,6,biomesoplenty:hard_ice)
Block(-5,3,7,biomesoplenty:hard_ice)
Block(-5,3,8,biomesoplenty:hard_ice)
Block(-5,4,-2,biomesoplenty:hard_ice)
Block(-5,4,-1,biomesoplenty:hard_ice)
Block(-5,4,0,biomesoplenty:hard_ice)
Block(-5,4,1,biomesoplenty:hard_ice)
Block(-5,4,2,biomesoplenty:hard_ice)
Block(-5,4,3,biomesoplenty:hard_ice)
Block(-5,4,4,biomesoplenty:hard_ice)
Block(-5,4,5,biomesoplenty:hard_ice)
Block(-5,4,6,biomesoplenty:hard_ice)
Block(-5,4,7,biomesoplenty:hard_ice)
Block(-5,4,8,biomesoplenty:hard_ice)
Block(-5,4,9,biomesoplenty:hard_ice)
Block(-5,5,-6,biomesoplenty:hard_ice)
Block(-5,5,-5,biomesoplenty:hard_ice)
Block(-5,5,-4,biomesoplenty:hard_ice)
Block(-5,5,-3,biomesoplenty:hard_ice)
Block(-5,5,-2,biomesoplenty:hard_ice)
Block(-5,5,-1,biomesoplenty:hard_ice)
Block(-5,5,0,biomesoplenty:hard_ice)
Block(-5,5,1,biomesoplenty:hard_ice)
Block(-5,5,2,biomesoplenty:hard_ice)
Block(-5,5,3,biomesoplenty:hard_ice)
Block(-5,5,4,biomesoplenty:hard_ice)
Block(-5,5,5,biomesoplenty:hard_ice)
Block(-5,5,6,biomesoplenty:hard_ice)
Block(-5,5,7,biomesoplenty:hard_ice)
Block(-5,5,8,biomesoplenty:hard_ice)
Block(-5,5,9,biomesoplenty:hard_ice)
Block(-5,5,10,biomesoplenty:hard_ice)
Block(-5,6,-6,biomesoplenty:hard_ice)
Block(-5,6,-5,biomesoplenty:hard_ice)
Block(-5,6,-4,biomesoplenty:hard_ice)
Block(-5,6,-3,biomesoplenty:hard_ice)
Block(-5,6,-2,biomesoplenty:hard_ice)
Block(-5,6,-1,biomesoplenty:hard_ice)
Block(-5,6,0,biomesoplenty:hard_ice)
Block(-5,6,1,biomesoplenty:hard_ice)
Block(-5,6,2,biomesoplenty:hard_ice)
Block(-5,6,3,biomesoplenty:hard_ice)
Block(-5,6,4,biomesoplenty:hard_ice)
Block(-5,6,5,biomesoplenty:hard_ice)
Block(-5,6,6,biomesoplenty:hard_ice)
Block(-5,6,7,biomesoplenty:hard_ice)
Block(-5,6,8,biomesoplenty:hard_ice)
Block(-5,6,9,biomesoplenty:hard_ice)
Block(-5,6,10,biomesoplenty:hard_ice)
Block(-5,7,-6,biomesoplenty:hard_ice)
Block(-5,7,-5,biomesoplenty:hard_ice)
Block(-5,7,-4,biomesoplenty:hard_ice)
Block(-5,7,-3,biomesoplenty:hard_ice)
Block(-5,7,-2,biomesoplenty:hard_ice)
Block(-5,7,-1,biomesoplenty:hard_ice)
Block(-5,7,0,biomesoplenty:hard_ice)
Block(-5,7,1,biomesoplenty:hard_ice)
Block(-5,7,2,biomesoplenty:hard_ice)
Block(-5,7,3,biomesoplenty:hard_ice)
Block(-5,7,4,biomesoplenty:hard_ice)
Block(-5,7,5,biomesoplenty:hard_ice)
Block(-5,7,6,biomesoplenty:hard_ice)
Block(-5,7,7,biomesoplenty:hard_ice)
Block(-5,7,8,biomesoplenty:hard_ice)
Block(-5,7,9,biomesoplenty:hard_ice)
Block(-5,7,10,biomesoplenty:hard_ice)
Block(-5,7,11,biomesoplenty:hard_ice)
Block(-5,8,-6,biomesoplenty:hard_ice)
Block(-5,8,-5,biomesoplenty:hard_ice)
Block(-5,8,-4,biomesoplenty:hard_ice)
Block(-5,8,-3,biomesoplenty:hard_ice)
Block(-5,8,-2,biomesoplenty:hard_ice)
Block(-5,8,-1,biomesoplenty:hard_ice)
Block(-5,8,0,biomesoplenty:hard_ice)
Block(-5,8,1,biomesoplenty:hard_ice)
Block(-5,8,2,biomesoplenty:hard_ice)
Block(-5,8,3,biomesoplenty:hard_ice)
Block(-5,8,4,biomesoplenty:hard_ice)
Block(-5,8,5,biomesoplenty:hard_ice)
Block(-5,8,6,biomesoplenty:hard_ice)
Block(-5,8,7,biomesoplenty:hard_ice)
Block(-5,8,8,biomesoplenty:hard_ice)
Block(-5,8,9,biomesoplenty:hard_ice)
Block(-5,8,10,biomesoplenty:hard_ice)
Block(-5,8,11,biomesoplenty:hard_ice)
Block(-5,8,12,biomesoplenty:hard_ice)
Block(-5,9,-6,biomesoplenty:hard_ice)
Block(-5,9,-5,biomesoplenty:hard_ice)
Block(-5,9,-4,biomesoplenty:hard_ice)
Block(-5,9,-3,biomesoplenty:hard_ice)
Block(-5,9,-2,biomesoplenty:hard_ice)
Block(-5,9,-1,biomesoplenty:hard_ice)
Block(-5,9,0,biomesoplenty:hard_ice)
Block(-5,9,1,biomesoplenty:hard_ice)
Block(-5,9,2,biomesoplenty:hard_ice)
Block(-5,9,3,biomesoplenty:hard_ice)
Block(-5,9,4,biomesoplenty:hard_ice)
Block(-5,9,5,biomesoplenty:hard_ice)
Block(-5,9,6,biomesoplenty:hard_ice)
Block(-5,9,7,biomesoplenty:hard_ice)
Block(-5,9,8,biomesoplenty:hard_ice)
Block(-5,9,9,biomesoplenty:hard_ice)
Block(-5,9,10,biomesoplenty:hard_ice)
Block(-5,9,11,biomesoplenty:hard_ice)
Block(-5,9,12,biomesoplenty:hard_ice)
Block(-5,10,-6,biomesoplenty:hard_ice)
Block(-5,10,-5,biomesoplenty:hard_ice)
Block(-5,10,-4,biomesoplenty:hard_ice)
Block(-5,10,-3,biomesoplenty:hard_ice)
Block(-5,10,-2,biomesoplenty:hard_ice)
Block(-5,10,-1,biomesoplenty:hard_ice)
Block(-5,10,0,biomesoplenty:hard_ice)
Block(-5,10,1,biomesoplenty:hard_ice)
Block(-5,10,2,biomesoplenty:hard_ice)
Block(-5,10,3,biomesoplenty:hard_ice)
Block(-5,10,4,biomesoplenty:hard_ice)
Block(-5,10,5,biomesoplenty:hard_ice)
Block(-5,10,6,biomesoplenty:hard_ice)
Block(-5,10,7,biomesoplenty:hard_ice)
Block(-5,10,8,biomesoplenty:hard_ice)
Block(-5,10,9,biomesoplenty:hard_ice)
Block(-5,10,10,biomesoplenty:hard_ice)
Block(-5,10,11,biomesoplenty:hard_ice)
Block(-5,10,12,biomesoplenty:hard_ice)
Block(-5,11,-7,biomesoplenty:hard_ice)
Block(-5,11,-6,biomesoplenty:hard_ice)
Block(-5,11,-5,biomesoplenty:hard_ice)
Block(-5,11,-4,biomesoplenty:hard_ice)
Block(-5,11,-3,biomesoplenty:hard_ice)
Block(-5,11,-2,biomesoplenty:hard_ice)
Block(-5,11,-1,biomesoplenty:hard_ice)
Block(-5,11,0,biomesoplenty:hard_ice)
Block(-5,11,1,biomesoplenty:hard_ice)
Block(-5,11,2,biomesoplenty:hard_ice)
Block(-5,11,3,biomesoplenty:hard_ice)
Block(-5,11,4,biomesoplenty:hard_ice)
Block(-5,11,5,biomesoplenty:hard_ice)
Block(-5,11,6,biomesoplenty:hard_ice)
Block(-5,11,7,biomesoplenty:hard_ice)
Block(-5,11,8,biomesoplenty:hard_ice)
Block(-5,11,9,biomesoplenty:hard_ice)
Block(-5,11,10,biomesoplenty:hard_ice)
Block(-5,11,11,biomesoplenty:hard_ice)
Block(-5,11,12,biomesoplenty:hard_ice)
Block(-5,12,-7,biomesoplenty:hard_ice)
Block(-5,12,-6,biomesoplenty:hard_ice)
Block(-5,12,-5,biomesoplenty:hard_ice)
Block(-5,12,-4,biomesoplenty:hard_ice)
Block(-5,12,-3,biomesoplenty:hard_ice)
Block(-5,12,-2,biomesoplenty:hard_ice)
Block(-5,12,-1,biomesoplenty:hard_ice)
Block(-5,12,0,biomesoplenty:hard_ice)
Block(-5,12,1,biomesoplenty:hard_ice)
Block(-5,12,2,biomesoplenty:hard_ice)
Block(-5,12,3,biomesoplenty:hard_ice)
Block(-5,12,4,biomesoplenty:hard_ice)
Block(-5,12,5,biomesoplenty:hard_ice)
Block(-5,12,6,biomesoplenty:hard_ice)
Block(-5,12,7,biomesoplenty:hard_ice)
Block(-5,12,8,biomesoplenty:hard_ice)
Block(-5,12,9,biomesoplenty:hard_ice)
Block(-5,12,10,biomesoplenty:hard_ice)
Block(-5,12,11,biomesoplenty:hard_ice)
Block(-5,12,12,biomesoplenty:hard_ice)
Block(-5,12,13,biomesoplenty:hard_ice)
Block(-5,13,-7,biomesoplenty:hard_ice)
Block(-5,13,-6,biomesoplenty:hard_ice)
Block(-5,13,-5,biomesoplenty:hard_ice)
Block(-5,13,-4,biomesoplenty:hard_ice)
Block(-5,13,-3,biomesoplenty:hard_ice)
Block(-5,13,-2,biomesoplenty:hard_ice)
Block(-5,13,-1,biomesoplenty:hard_ice)
Block(-5,13,0,biomesoplenty:hard_ice)
Block(-5,13,1,biomesoplenty:hard_ice)
Block(-5,13,2,biomesoplenty:hard_ice)
Block(-5,13,3,biomesoplenty:hard_ice)
Block(-5,13,4,biomesoplenty:hard_ice)
Block(-5,13,5,biomesoplenty:hard_ice)
Block(-5,13,6,biomesoplenty:hard_ice)
Block(-5,13,7,biomesoplenty:hard_ice)
Block(-5,13,8,biomesoplenty:hard_ice)
Block(-5,13,9,biomesoplenty:hard_ice)
Block(-5,13,10,biomesoplenty:hard_ice)
Block(-5,13,11,biomesoplenty:hard_ice)
Block(-5,13,12,biomesoplenty:hard_ice)
Block(-5,13,13,biomesoplenty:hard_ice)
Block(-5,14,-7,biomesoplenty:hard_ice)
Block(-5,14,-6,biomesoplenty:hard_ice)
Block(-5,14,-5,biomesoplenty:hard_ice)
Block(-5,14,-4,biomesoplenty:hard_ice)
Block(-5,14,-3,biomesoplenty:hard_ice)
Block(-5,14,-2,biomesoplenty:hard_ice)
Block(-5,14,-1,biomesoplenty:hard_ice)
Block(-5,14,0,biomesoplenty:hard_ice)
Block(-5,14,1,biomesoplenty:hard_ice)
Block(-5,14,2,biomesoplenty:hard_ice)
Block(-5,14,3,biomesoplenty:hard_ice)
Block(-5,14,4,biomesoplenty:hard_ice)
Block(-5,14,5,biomesoplenty:hard_ice)
Block(-5,14,6,biomesoplenty:hard_ice)
Block(-5,14,7,biomesoplenty:hard_ice)
Block(-5,14,8,biomesoplenty:hard_ice)
Block(-5,14,9,biomesoplenty:hard_ice)
Block(-5,14,10,biomesoplenty:hard_ice)
Block(-5,14,11,biomesoplenty:hard_ice)
Block(-5,14,12,biomesoplenty:hard_ice)
Block(-5,14,13,biomesoplenty:hard_ice)
Block(-5,15,-7,biomesoplenty:hard_ice)
Block(-5,15,-6,biomesoplenty:hard_ice)
Block(-5,15,-5,biomesoplenty:hard_ice)
Block(-5,15,-4,biomesoplenty:hard_ice)
Block(-5,15,-3,biomesoplenty:hard_ice)
Block(-5,15,-2,biomesoplenty:hard_ice)
Block(-5,15,-1,biomesoplenty:hard_ice)
Block(-5,15,0,biomesoplenty:hard_ice)
Block(-5,15,1,biomesoplenty:hard_ice)
Block(-5,15,2,biomesoplenty:hard_ice)
Block(-5,15,3,biomesoplenty:hard_ice)
Block(-5,15,4,biomesoplenty:hard_ice)
Block(-5,15,5,biomesoplenty:hard_ice)
Block(-5,15,6,biomesoplenty:hard_ice)
Block(-5,15,7,biomesoplenty:hard_ice)
Block(-5,15,8,biomesoplenty:hard_ice)
Block(-5,15,9,biomesoplenty:hard_ice)
Block(-5,15,10,biomesoplenty:hard_ice)
Block(-5,15,11,biomesoplenty:hard_ice)
Block(-5,15,12,biomesoplenty:hard_ice)
Block(-5,15,13,biomesoplenty:hard_ice)
Block(-5,16,-7,biomesoplenty:hard_ice)
Block(-5,16,-6,biomesoplenty:hard_ice)
Block(-5,16,-5,biomesoplenty:hard_ice)
Block(-5,16,-4,biomesoplenty:hard_ice)
Block(-5,16,-3,biomesoplenty:hard_ice)
Block(-5,16,-2,biomesoplenty:hard_ice)
Block(-5,16,-1,biomesoplenty:hard_ice)
Block(-5,16,0,biomesoplenty:hard_ice)
Block(-5,16,1,biomesoplenty:hard_ice)
Block(-5,16,2,biomesoplenty:hard_ice)
Block(-5,16,3,biomesoplenty:hard_ice)
Block(-5,16,4,biomesoplenty:hard_ice)
Block(-5,16,5,biomesoplenty:hard_ice)
Block(-5,16,6,biomesoplenty:hard_ice)
Block(-5,16,7,biomesoplenty:hard_ice)
Block(-5,16,8,biomesoplenty:hard_ice)
Block(-5,16,9,biomesoplenty:hard_ice)
Block(-5,16,10,biomesoplenty:hard_ice)
Block(-5,16,11,biomesoplenty:hard_ice)
Block(-5,16,12,biomesoplenty:hard_ice)
Block(-5,16,13,biomesoplenty:hard_ice)
Block(-5,17,-7,biomesoplenty:hard_ice)
Block(-5,17,-6,biomesoplenty:hard_ice)
Block(-5,17,-5,biomesoplenty:hard_ice)
Block(-5,17,-4,biomesoplenty:hard_ice)
Block(-5,17,-3,biomesoplenty:hard_ice)
Block(-5,17,-2,biomesoplenty:hard_ice)
Block(-5,17,-1,biomesoplenty:hard_ice)
Block(-5,17,0,biomesoplenty:hard_ice)
Block(-5,17,1,biomesoplenty:hard_ice)
Block(-5,17,2,biomesoplenty:hard_ice)
Block(-5,17,3,biomesoplenty:hard_ice)
Block(-5,17,4,biomesoplenty:hard_ice)
Block(-5,17,5,biomesoplenty:hard_ice)
Block(-5,17,6,biomesoplenty:hard_ice)
Block(-5,17,7,biomesoplenty:hard_ice)
Block(-5,17,8,biomesoplenty:hard_ice)
Block(-5,17,9,biomesoplenty:hard_ice)
Block(-5,17,10,biomesoplenty:hard_ice)
Block(-5,17,11,biomesoplenty:hard_ice)
Block(-5,17,12,biomesoplenty:hard_ice)
Block(-5,18,-7,biomesoplenty:hard_ice)
Block(-5,18,-6,biomesoplenty:hard_ice)
Block(-5,18,-5,biomesoplenty:hard_ice)
Block(-5,18,-4,biomesoplenty:hard_ice)
Block(-5,18,-3,biomesoplenty:hard_ice)
Block(-5,18,-2,biomesoplenty:hard_ice)
Block(-5,18,-1,biomesoplenty:hard_ice)
Block(-5,18,0,biomesoplenty:hard_ice)
Block(-5,18,1,biomesoplenty:hard_ice)
Block(-5,18,2,biomesoplenty:hard_ice)
Block(-5,18,3,biomesoplenty:hard_ice)
Block(-5,18,4,biomesoplenty:hard_ice)
Block(-5,18,5,biomesoplenty:hard_ice)
Block(-5,18,6,biomesoplenty:hard_ice)
Block(-5,18,7,biomesoplenty:hard_ice)
Block(-5,18,8,biomesoplenty:hard_ice)
Block(-5,18,9,biomesoplenty:hard_ice)
Block(-5,18,10,biomesoplenty:hard_ice)
Block(-5,18,11,biomesoplenty:hard_ice)
Block(-5,19,-7,biomesoplenty:hard_ice)
Block(-5,19,-6,biomesoplenty:hard_ice)
Block(-5,19,-5,biomesoplenty:hard_ice)
Block(-5,19,-4,biomesoplenty:hard_ice)
Block(-5,19,-3,biomesoplenty:hard_ice)
Block(-5,19,-2,biomesoplenty:hard_ice)
Block(-5,19,-1,biomesoplenty:hard_ice)
Block(-5,19,0,biomesoplenty:hard_ice)
Block(-5,19,1,biomesoplenty:hard_ice)
Block(-5,19,2,biomesoplenty:hard_ice)
Block(-5,19,3,biomesoplenty:hard_ice)
Block(-5,19,4,biomesoplenty:hard_ice)
Block(-5,19,5,biomesoplenty:hard_ice)
Block(-5,19,6,biomesoplenty:hard_ice)
Block(-5,19,7,biomesoplenty:hard_ice)
Block(-5,19,8,biomesoplenty:hard_ice)
Block(-5,19,9,biomesoplenty:hard_ice)
Block(-5,19,10,biomesoplenty:hard_ice)
Block(-5,20,-6,biomesoplenty:hard_ice)
Block(-5,20,-5,biomesoplenty:hard_ice)
Block(-5,20,-4,biomesoplenty:hard_ice)
Block(-5,20,-3,biomesoplenty:hard_ice)
Block(-5,20,-2,biomesoplenty:hard_ice)
Block(-5,20,-1,biomesoplenty:hard_ice)
Block(-5,20,0,biomesoplenty:hard_ice)
Block(-5,20,1,biomesoplenty:hard_ice)
Block(-5,20,2,biomesoplenty:hard_ice)
Block(-5,20,3,biomesoplenty:hard_ice)
Block(-5,20,4,biomesoplenty:hard_ice)
Block(-5,20,5,biomesoplenty:hard_ice)
Block(-4,3,4,biomesoplenty:hard_ice)
Block(-4,3,5,biomesoplenty:hard_ice)
Block(-4,3,6,biomesoplenty:hard_ice)
Block(-4,3,7,biomesoplenty:hard_ice)
Block(-4,3,8,biomesoplenty:hard_ice)
Block(-4,3,9,biomesoplenty:hard_ice)
Block(-4,3,10,biomesoplenty:hard_ice)
Block(-4,4,-4,biomesoplenty:hard_ice)
Block(-4,4,-3,biomesoplenty:hard_ice)
Block(-4,4,-2,biomesoplenty:hard_ice)
Block(-4,4,-1,biomesoplenty:hard_ice)
Block(-4,4,0,biomesoplenty:hard_ice)
Block(-4,4,1,biomesoplenty:hard_ice)
Block(-4,4,2,biomesoplenty:hard_ice)
Block(-4,4,3,biomesoplenty:hard_ice)
Block(-4,4,4,biomesoplenty:hard_ice)
Block(-4,4,5,biomesoplenty:hard_ice)
Block(-4,4,6,biomesoplenty:hard_ice)
Block(-4,4,7,biomesoplenty:hard_ice)
Block(-4,4,8,biomesoplenty:hard_ice)
Block(-4,4,9,biomesoplenty:hard_ice)
Block(-4,4,10,biomesoplenty:hard_ice)
Block(-4,5,-7,biomesoplenty:hard_ice)
Block(-4,5,-6,biomesoplenty:hard_ice)
Block(-4,5,-5,biomesoplenty:hard_ice)
Block(-4,5,-4,biomesoplenty:hard_ice)
Block(-4,5,-3,biomesoplenty:hard_ice)
Block(-4,5,-2,biomesoplenty:hard_ice)
Block(-4,5,-1,biomesoplenty:hard_ice)
Block(-4,5,0,biomesoplenty:hard_ice)
Block(-4,5,1,biomesoplenty:hard_ice)
Block(-4,5,2,biomesoplenty:hard_ice)
Block(-4,5,3,biomesoplenty:hard_ice)
Block(-4,5,4,biomesoplenty:hard_ice)
Block(-4,5,5,biomesoplenty:hard_ice)
Block(-4,5,6,biomesoplenty:hard_ice)
Block(-4,5,7,biomesoplenty:hard_ice)
Block(-4,5,8,biomesoplenty:hard_ice)
Block(-4,5,9,biomesoplenty:hard_ice)
Block(-4,5,10,biomesoplenty:hard_ice)
Block(-4,5,11,biomesoplenty:hard_ice)
Block(-4,6,-7,biomesoplenty:hard_ice)
Block(-4,6,-6,biomesoplenty:hard_ice)
Block(-4,6,-5,biomesoplenty:hard_ice)
Block(-4,6,-4,biomesoplenty:hard_ice)
Block(-4,6,-3,biomesoplenty:hard_ice)
Block(-4,6,-2,biomesoplenty:hard_ice)
Block(-4,6,-1,biomesoplenty:hard_ice)
Block(-4,6,0,biomesoplenty:hard_ice)
Block(-4,6,1,biomesoplenty:hard_ice)
Block(-4,6,2,biomesoplenty:hard_ice)
Block(-4,6,3,biomesoplenty:hard_ice)
Block(-4,6,4,biomesoplenty:hard_ice)
Block(-4,6,5,biomesoplenty:hard_ice)
Block(-4,6,6,biomesoplenty:hard_ice)
Block(-4,6,7,biomesoplenty:hard_ice)
Block(-4,6,8,biomesoplenty:hard_ice)
Block(-4,6,9,biomesoplenty:hard_ice)
Block(-4,6,10,biomesoplenty:hard_ice)
Block(-4,6,11,biomesoplenty:hard_ice)
Block(-4,6,12,biomesoplenty:hard_ice)
Block(-4,7,-7,biomesoplenty:hard_ice)
Block(-4,7,-6,biomesoplenty:hard_ice)
Block(-4,7,-5,biomesoplenty:hard_ice)
Block(-4,7,-4,biomesoplenty:hard_ice)
Block(-4,7,-3,biomesoplenty:hard_ice)
Block(-4,7,-2,biomesoplenty:hard_ice)
Block(-4,7,-1,biomesoplenty:hard_ice)
Block(-4,7,0,biomesoplenty:hard_ice)
Block(-4,7,1,biomesoplenty:hard_ice)
Block(-4,7,2,biomesoplenty:hard_ice)
Block(-4,7,3,biomesoplenty:hard_ice)
Block(-4,7,4,biomesoplenty:hard_ice)
Block(-4,7,5,biomesoplenty:hard_ice)
Block(-4,7,6,biomesoplenty:hard_ice)
Block(-4,7,7,biomesoplenty:hard_ice)
Block(-4,7,8,biomesoplenty:hard_ice)
Block(-4,7,9,biomesoplenty:hard_ice)
Block(-4,7,10,biomesoplenty:hard_ice)
Block(-4,7,11,biomesoplenty:hard_ice)
Block(-4,7,12,biomesoplenty:hard_ice)
Block(-4,7,13,biomesoplenty:hard_ice)
Block(-4,8,-7,biomesoplenty:hard_ice)
Block(-4,8,-6,biomesoplenty:hard_ice)
Block(-4,8,-5,biomesoplenty:hard_ice)
Block(-4,8,-4,biomesoplenty:hard_ice)
Block(-4,8,-3,biomesoplenty:hard_ice)
Block(-4,8,-2,biomesoplenty:hard_ice)
Block(-4,8,-1,biomesoplenty:hard_ice)
Block(-4,8,0,biomesoplenty:hard_ice)
Block(-4,8,1,biomesoplenty:hard_ice)
Block(-4,8,2,biomesoplenty:hard_ice)
Block(-4,8,3,biomesoplenty:hard_ice)
Block(-4,8,4,biomesoplenty:hard_ice)
Block(-4,8,5,biomesoplenty:hard_ice)
Block(-4,8,6,biomesoplenty:hard_ice)
Block(-4,8,7,biomesoplenty:hard_ice)
Block(-4,8,8,biomesoplenty:hard_ice)
Block(-4,8,9,biomesoplenty:hard_ice)
Block(-4,8,10,biomesoplenty:hard_ice)
Block(-4,8,11,biomesoplenty:hard_ice)
Block(-4,8,12,biomesoplenty:hard_ice)
Block(-4,8,13,biomesoplenty:hard_ice)
Block(-4,9,-7,biomesoplenty:hard_ice)
Block(-4,9,-6,biomesoplenty:hard_ice)
Block(-4,9,-5,biomesoplenty:hard_ice)
Block(-4,9,-4,biomesoplenty:hard_ice)
Block(-4,9,-3,biomesoplenty:hard_ice)
Block(-4,9,-2,biomesoplenty:hard_ice)
Block(-4,9,-1,biomesoplenty:hard_ice)
Block(-4,9,0,biomesoplenty:hard_ice)
Block(-4,9,1,biomesoplenty:hard_ice)
Block(-4,9,2,biomesoplenty:hard_ice)
Block(-4,9,3,biomesoplenty:hard_ice)
Block(-4,9,4,biomesoplenty:hard_ice)
Block(-4,9,5,biomesoplenty:hard_ice)
Block(-4,9,6,biomesoplenty:hard_ice)
Block(-4,9,7,biomesoplenty:hard_ice)
Block(-4,9,8,biomesoplenty:hard_ice)
Block(-4,9,9,biomesoplenty:hard_ice)
Block(-4,9,10,biomesoplenty:hard_ice)
Block(-4,9,11,biomesoplenty:hard_ice)
Block(-4,9,12,biomesoplenty:hard_ice)
Block(-4,9,13,biomesoplenty:hard_ice)
Block(-4,10,-8,biomesoplenty:hard_ice)
Block(-4,10,-7,biomesoplenty:hard_ice)
Block(-4,10,-6,biomesoplenty:hard_ice)
Block(-4,10,-5,biomesoplenty:hard_ice)
Block(-4,10,-4,biomesoplenty:hard_ice)
Block(-4,10,-3,biomesoplenty:hard_ice)
Block(-4,10,-2,biomesoplenty:hard_ice)
Block(-4,10,-1,biomesoplenty:hard_ice)
Block(-4,10,0,biomesoplenty:hard_ice)
Block(-4,10,1,biomesoplenty:hard_ice)
Block(-4,10,2,biomesoplenty:hard_ice)
Block(-4,10,3,biomesoplenty:hard_ice)
Block(-4,10,4,biomesoplenty:hard_ice)
Block(-4,10,5,biomesoplenty:hard_ice)
Block(-4,10,6,biomesoplenty:hard_ice)
Block(-4,10,7,biomesoplenty:hard_ice)
Block(-4,10,8,biomesoplenty:hard_ice)
Block(-4,10,9,biomesoplenty:hard_ice)
Block(-4,10,10,biomesoplenty:hard_ice)
Block(-4,10,11,biomesoplenty:hard_ice)
Block(-4,10,12,biomesoplenty:hard_ice)
Block(-4,10,13,biomesoplenty:hard_ice)
Block(-4,11,-8,biomesoplenty:hard_ice)
Block(-4,11,-7,biomesoplenty:hard_ice)
Block(-4,11,-6,biomesoplenty:hard_ice)
Block(-4,11,-5,biomesoplenty:hard_ice)
Block(-4,11,-4,biomesoplenty:hard_ice)
Block(-4,11,-3,biomesoplenty:hard_ice)
Block(-4,11,-2,biomesoplenty:hard_ice)
Block(-4,11,-1,biomesoplenty:hard_ice)
Block(-4,11,0,biomesoplenty:hard_ice)
Block(-4,11,1,biomesoplenty:hard_ice)
Block(-4,11,2,biomesoplenty:hard_ice)
Block(-4,11,3,biomesoplenty:hard_ice)
Block(-4,11,4,biomesoplenty:hard_ice)
Block(-4,11,5,biomesoplenty:hard_ice)
Block(-4,11,6,biomesoplenty:hard_ice)
Block(-4,11,7,biomesoplenty:hard_ice)
Block(-4,11,8,biomesoplenty:hard_ice)
Block(-4,11,9,biomesoplenty:hard_ice)
Block(-4,11,10,biomesoplenty:hard_ice)
Block(-4,11,11,biomesoplenty:hard_ice)
Block(-4,11,12,biomesoplenty:hard_ice)
Block(-4,11,13,biomesoplenty:hard_ice)
Block(-4,11,14,biomesoplenty:hard_ice)
Block(-4,12,-8,biomesoplenty:hard_ice)
Block(-4,12,-7,biomesoplenty:hard_ice)
Block(-4,12,-6,biomesoplenty:hard_ice)
Block(-4,12,-5,biomesoplenty:hard_ice)
Block(-4,12,-4,biomesoplenty:hard_ice)
Block(-4,12,-3,biomesoplenty:hard_ice)
Block(-4,12,-2,biomesoplenty:hard_ice)
Block(-4,12,-1,biomesoplenty:hard_ice)
Block(-4,12,0,biomesoplenty:hard_ice)
Block(-4,12,1,biomesoplenty:hard_ice)
Block(-4,12,2,biomesoplenty:hard_ice)
Block(-4,12,3,biomesoplenty:hard_ice)
Block(-4,12,4,biomesoplenty:hard_ice)
Block(-4,12,5,biomesoplenty:hard_ice)
Block(-4,12,6,biomesoplenty:hard_ice)
Block(-4,12,7,biomesoplenty:hard_ice)
Block(-4,12,8,biomesoplenty:hard_ice)
Block(-4,12,9,biomesoplenty:hard_ice)
Block(-4,12,10,biomesoplenty:hard_ice)
Block(-4,12,11,biomesoplenty:hard_ice)
Block(-4,12,12,biomesoplenty:hard_ice)
Block(-4,12,13,biomesoplenty:hard_ice)
Block(-4,12,14,biomesoplenty:hard_ice)
Block(-4,13,-8,biomesoplenty:hard_ice)
Block(-4,13,-7,biomesoplenty:hard_ice)
Block(-4,13,-6,biomesoplenty:hard_ice)
Block(-4,13,-5,biomesoplenty:hard_ice)
Block(-4,13,-4,biomesoplenty:hard_ice)
Block(-4,13,-3,biomesoplenty:hard_ice)
Block(-4,13,-2,biomesoplenty:hard_ice)
Block(-4,13,-1,biomesoplenty:hard_ice)
Block(-4,13,0,biomesoplenty:hard_ice)
Block(-4,13,1,biomesoplenty:hard_ice)
Block(-4,13,2,biomesoplenty:hard_ice)
Block(-4,13,3,biomesoplenty:hard_ice)
Block(-4,13,4,biomesoplenty:hard_ice)
Block(-4,13,5,biomesoplenty:hard_ice)
Block(-4,13,6,biomesoplenty:hard_ice)
Block(-4,13,7,biomesoplenty:hard_ice)
Block(-4,13,8,biomesoplenty:hard_ice)
Block(-4,13,9,biomesoplenty:hard_ice)
Block(-4,13,10,biomesoplenty:hard_ice)
Block(-4,13,11,biomesoplenty:hard_ice)
Block(-4,13,12,biomesoplenty:hard_ice)
Block(-4,13,13,biomesoplenty:hard_ice)
Block(-4,13,14,biomesoplenty:hard_ice)
Block(-4,14,-8,biomesoplenty:hard_ice)
Block(-4,14,-7,biomesoplenty:hard_ice)
Block(-4,14,-6,biomesoplenty:hard_ice)
Block(-4,14,-5,biomesoplenty:hard_ice)
Block(-4,14,-4,biomesoplenty:hard_ice)
Block(-4,14,-3,biomesoplenty:hard_ice)
Block(-4,14,-2,biomesoplenty:hard_ice)
Block(-4,14,-1,biomesoplenty:hard_ice)
Block(-4,14,0,biomesoplenty:hard_ice)
Block(-4,14,1,biomesoplenty:hard_ice)
Block(-4,14,2,biomesoplenty:hard_ice)
Block(-4,14,3,biomesoplenty:hard_ice)
Block(-4,14,4,biomesoplenty:hard_ice)
Block(-4,14,5,biomesoplenty:hard_ice)
Block(-4,14,6,biomesoplenty:hard_ice)
Block(-4,14,7,biomesoplenty:hard_ice)
Block(-4,14,8,biomesoplenty:hard_ice)
Block(-4,14,9,biomesoplenty:hard_ice)
Block(-4,14,10,biomesoplenty:hard_ice)
Block(-4,14,11,biomesoplenty:hard_ice)
Block(-4,14,12,biomesoplenty:hard_ice)
Block(-4,14,13,biomesoplenty:hard_ice)
Block(-4,14,14,biomesoplenty:hard_ice)
Block(-4,15,-8,biomesoplenty:hard_ice)
Block(-4,15,-7,biomesoplenty:hard_ice)
Block(-4,15,-6,biomesoplenty:hard_ice)
Block(-4,15,-5,biomesoplenty:hard_ice)
Block(-4,15,-4,biomesoplenty:hard_ice)
Block(-4,15,-3,biomesoplenty:hard_ice)
Block(-4,15,-2,biomesoplenty:hard_ice)
Block(-4,15,-1,biomesoplenty:hard_ice)
Block(-4,15,0,biomesoplenty:hard_ice)
Block(-4,15,1,biomesoplenty:hard_ice)
Block(-4,15,2,biomesoplenty:hard_ice)
Block(-4,15,3,biomesoplenty:hard_ice)
Block(-4,15,4,biomesoplenty:hard_ice)
Block(-4,15,5,biomesoplenty:hard_ice)
Block(-4,15,6,biomesoplenty:hard_ice)
Block(-4,15,7,biomesoplenty:hard_ice)
Block(-4,15,8,biomesoplenty:hard_ice)
Block(-4,15,9,biomesoplenty:hard_ice)
Block(-4,15,10,biomesoplenty:hard_ice)
Block(-4,15,11,biomesoplenty:hard_ice)
Block(-4,15,12,biomesoplenty:hard_ice)
Block(-4,15,13,biomesoplenty:hard_ice)
Block(-4,15,14,biomesoplenty:hard_ice)
Block(-4,16,-8,biomesoplenty:hard_ice)
Block(-4,16,-7,biomesoplenty:hard_ice)
Block(-4,16,-6,biomesoplenty:hard_ice)
Block(-4,16,-5,biomesoplenty:hard_ice)
Block(-4,16,-4,biomesoplenty:hard_ice)
Block(-4,16,-3,biomesoplenty:hard_ice)
Block(-4,16,-2,biomesoplenty:hard_ice)
Block(-4,16,-1,biomesoplenty:hard_ice)
Block(-4,16,0,biomesoplenty:hard_ice)
Block(-4,16,1,biomesoplenty:hard_ice)
Block(-4,16,2,biomesoplenty:hard_ice)
Block(-4,16,3,biomesoplenty:hard_ice)
Block(-4,16,4,biomesoplenty:hard_ice)
Block(-4,16,5,biomesoplenty:hard_ice)
Block(-4,16,6,biomesoplenty:hard_ice)
Block(-4,16,7,biomesoplenty:hard_ice)
Block(-4,16,8,biomesoplenty:hard_ice)
Block(-4,16,9,biomesoplenty:hard_ice)
Block(-4,16,10,biomesoplenty:hard_ice)
Block(-4,16,11,biomesoplenty:hard_ice)
Block(-4,16,12,biomesoplenty:hard_ice)
Block(-4,16,13,biomesoplenty:hard_ice)
Block(-4,17,-8,biomesoplenty:hard_ice)
Block(-4,17,-7,biomesoplenty:hard_ice)
Block(-4,17,-6,biomesoplenty:hard_ice)
Block(-4,17,-5,biomesoplenty:hard_ice)
Block(-4,17,-4,biomesoplenty:hard_ice)
Block(-4,17,-3,biomesoplenty:hard_ice)
Block(-4,17,-2,biomesoplenty:hard_ice)
Block(-4,17,-1,biomesoplenty:hard_ice)
Block(-4,17,0,biomesoplenty:hard_ice)
Block(-4,17,1,biomesoplenty:hard_ice)
Block(-4,17,2,biomesoplenty:hard_ice)
Block(-4,17,3,biomesoplenty:hard_ice)
Block(-4,17,4,biomesoplenty:hard_ice)
Block(-4,17,5,biomesoplenty:hard_ice)
Block(-4,17,6,biomesoplenty:hard_ice)
Block(-4,17,7,biomesoplenty:hard_ice)
Block(-4,17,8,biomesoplenty:hard_ice)
Block(-4,17,9,biomesoplenty:hard_ice)
Block(-4,17,10,biomesoplenty:hard_ice)
Block(-4,17,11,biomesoplenty:hard_ice)
Block(-4,17,12,biomesoplenty:hard_ice)
Block(-4,18,-8,biomesoplenty:hard_ice)
Block(-4,18,-7,biomesoplenty:hard_ice)
Block(-4,18,-6,biomesoplenty:hard_ice)
Block(-4,18,-5,biomesoplenty:hard_ice)
Block(-4,18,-4,biomesoplenty:hard_ice)
Block(-4,18,-3,biomesoplenty:hard_ice)
Block(-4,18,-2,biomesoplenty:hard_ice)
Block(-4,18,-1,biomesoplenty:hard_ice)
Block(-4,18,0,biomesoplenty:hard_ice)
Block(-4,18,1,biomesoplenty:hard_ice)
Block(-4,18,2,biomesoplenty:hard_ice)
Block(-4,18,3,biomesoplenty:hard_ice)
Block(-4,18,4,biomesoplenty:hard_ice)
Block(-4,18,5,biomesoplenty:hard_ice)
Block(-4,18,6,biomesoplenty:hard_ice)
Block(-4,18,7,biomesoplenty:hard_ice)
Block(-4,18,8,biomesoplenty:hard_ice)
Block(-4,18,9,biomesoplenty:hard_ice)
Block(-4,18,10,biomesoplenty:hard_ice)
Block(-4,18,11,biomesoplenty:hard_ice)
Block(-4,18,12,biomesoplenty:hard_ice)
Block(-4,19,-8,biomesoplenty:hard_ice)
Block(-4,19,-7,biomesoplenty:hard_ice)
Block(-4,19,-6,biomesoplenty:hard_ice)
Block(-4,19,-5,biomesoplenty:hard_ice)
Block(-4,19,-4,biomesoplenty:hard_ice)
Block(-4,19,-3,biomesoplenty:hard_ice)
Block(-4,19,-2,biomesoplenty:hard_ice)
Block(-4,19,-1,biomesoplenty:hard_ice)
Block(-4,19,0,biomesoplenty:hard_ice)
Block(-4,19,1,biomesoplenty:hard_ice)
Block(-4,19,2,biomesoplenty:hard_ice)
Block(-4,19,3,biomesoplenty:hard_ice)
Block(-4,19,4,biomesoplenty:hard_ice)
Block(-4,19,5,biomesoplenty:hard_ice)
Block(-4,19,6,biomesoplenty:hard_ice)
Block(-4,19,7,biomesoplenty:hard_ice)
Block(-4,19,8,biomesoplenty:hard_ice)
Block(-4,19,9,biomesoplenty:hard_ice)
Block(-4,19,10,biomesoplenty:hard_ice)
Block(-4,19,11,biomesoplenty:hard_ice)
Block(-4,20,-8,biomesoplenty:hard_ice)
Block(-4,20,-7,biomesoplenty:hard_ice)
Block(-4,20,-6,biomesoplenty:hard_ice)
Block(-4,20,-5,biomesoplenty:hard_ice)
Block(-4,20,-4,biomesoplenty:hard_ice)
Block(-4,20,-3,biomesoplenty:hard_ice)
Block(-4,20,-2,biomesoplenty:hard_ice)
Block(-4,20,-1,biomesoplenty:hard_ice)
Block(-4,20,0,biomesoplenty:hard_ice)
Block(-4,20,1,biomesoplenty:hard_ice)
Block(-4,20,2,biomesoplenty:hard_ice)
Block(-4,20,3,biomesoplenty:hard_ice)
Block(-4,20,4,biomesoplenty:hard_ice)
Block(-4,20,5,biomesoplenty:hard_ice)
Block(-4,20,6,biomesoplenty:hard_ice)
Block(-4,20,7,biomesoplenty:hard_ice)
Block(-4,20,8,biomesoplenty:hard_ice)
Block(-4,21,-5,biomesoplenty:hard_ice)
Block(-4,21,-4,biomesoplenty:hard_ice)
Block(-4,21,-3,biomesoplenty:hard_ice)
Block(-4,21,-2,biomesoplenty:hard_ice)
Block(-4,21,-1,biomesoplenty:hard_ice)
Block(-3,2,8,biomesoplenty:hard_ice)
Block(-3,2,9,biomesoplenty:hard_ice)
Block(-3,2,10,biomesoplenty:hard_ice)
Block(-3,3,3,biomesoplenty:hard_ice)
Block(-3,3,4,biomesoplenty:hard_ice)
Block(-3,3,5,biomesoplenty:hard_ice)
Block(-3,3,6,biomesoplenty:hard_ice)
Block(-3,3,7,biomesoplenty:hard_ice)
Block(-3,3,8,biomesoplenty:hard_ice)
Block(-3,3,9,biomesoplenty:hard_ice)
Block(-3,3,10,biomesoplenty:hard_ice)
Block(-3,3,11,biomesoplenty:hard_ice)
Block(-3,4,-6,biomesoplenty:hard_ice)
Block(-3,4,-5,biomesoplenty:hard_ice)
Block(-3,4,-4,biomesoplenty:hard_ice)
Block(-3,4,-3,biomesoplenty:hard_ice)
Block(-3,4,-2,biomesoplenty:hard_ice)
Block(-3,4,-1,biomesoplenty:hard_ice)
Block(-3,4,0,biomesoplenty:hard_ice)
Block(-3,4,1,biomesoplenty:hard_ice)
Block(-3,4,2,biomesoplenty:hard_ice)
Block(-3,4,3,biomesoplenty:hard_ice)
Block(-3,4,4,biomesoplenty:hard_ice)
Block(-3,4,5,biomesoplenty:hard_ice)
Block(-3,4,6,biomesoplenty:hard_ice)
Block(-3,4,7,biomesoplenty:hard_ice)
Block(-3,4,8,biomesoplenty:hard_ice)
Block(-3,4,9,biomesoplenty:hard_ice)
Block(-3,4,10,biomesoplenty:hard_ice)
Block(-3,4,11,biomesoplenty:hard_ice)
Block(-3,5,-8,biomesoplenty:hard_ice)
Block(-3,5,-7,biomesoplenty:hard_ice)
Block(-3,5,-6,biomesoplenty:hard_ice)
Block(-3,5,-5,biomesoplenty:hard_ice)
Block(-3,5,-4,biomesoplenty:hard_ice)
Block(-3,5,-3,biomesoplenty:hard_ice)
Block(-3,5,-2,biomesoplenty:hard_ice)
Block(-3,5,-1,biomesoplenty:hard_ice)
Block(-3,5,0,biomesoplenty:hard_ice)
Block(-3,5,1,biomesoplenty:hard_ice)
Block(-3,5,2,biomesoplenty:hard_ice)
Block(-3,5,3,biomesoplenty:hard_ice)
Block(-3,5,4,biomesoplenty:hard_ice)
Block(-3,5,5,biomesoplenty:hard_ice)
Block(-3,5,6,biomesoplenty:hard_ice)
Block(-3,5,7,biomesoplenty:hard_ice)
Block(-3,5,8,biomesoplenty:hard_ice)
Block(-3,5,9,biomesoplenty:hard_ice)
Block(-3,5,10,biomesoplenty:hard_ice)
Block(-3,5,11,biomesoplenty:hard_ice)
Block(-3,5,12,biomesoplenty:hard_ice)
Block(-3,6,-8,biomesoplenty:hard_ice)
Block(-3,6,-7,biomesoplenty:hard_ice)
Block(-3,6,-6,biomesoplenty:hard_ice)
Block(-3,6,-5,biomesoplenty:hard_ice)
Block(-3,6,-4,biomesoplenty:hard_ice)
Block(-3,6,-3,biomesoplenty:hard_ice)
Block(-3,6,-2,biomesoplenty:hard_ice)
Block(-3,6,-1,biomesoplenty:hard_ice)
Block(-3,6,0,biomesoplenty:hard_ice)
Block(-3,6,1,biomesoplenty:hard_ice)
Block(-3,6,2,biomesoplenty:hard_ice)
Block(-3,6,3,biomesoplenty:hard_ice)
Block(-3,6,4,biomesoplenty:hard_ice)
Block(-3,6,5,biomesoplenty:hard_ice)
Block(-3,6,6,biomesoplenty:hard_ice)
Block(-3,6,7,biomesoplenty:hard_ice)
Block(-3,6,8,biomesoplenty:hard_ice)
Block(-3,6,9,biomesoplenty:hard_ice)
Block(-3,6,10,biomesoplenty:hard_ice)
Block(-3,6,11,biomesoplenty:hard_ice)
Block(-3,6,12,biomesoplenty:hard_ice)
Block(-3,6,13,biomesoplenty:hard_ice)
Block(-3,7,-8,biomesoplenty:hard_ice)
Block(-3,7,-7,biomesoplenty:hard_ice)
Block(-3,7,-6,biomesoplenty:hard_ice)
Block(-3,7,-5,biomesoplenty:hard_ice)
Block(-3,7,-4,biomesoplenty:hard_ice)
Block(-3,7,-3,biomesoplenty:hard_ice)
Block(-3,7,-2,biomesoplenty:hard_ice)
Block(-3,7,-1,biomesoplenty:hard_ice)
Block(-3,7,0,biomesoplenty:hard_ice)
Block(-3,7,1,biomesoplenty:hard_ice)
Block(-3,7,2,biomesoplenty:hard_ice)
Block(-3,7,3,biomesoplenty:hard_ice)
Block(-3,7,4,biomesoplenty:hard_ice)
Block(-3,7,5,biomesoplenty:hard_ice)
Block(-3,7,6,biomesoplenty:hard_ice)
Block(-3,7,7,biomesoplenty:hard_ice)
Block(-3,7,8,biomesoplenty:hard_ice)
Block(-3,7,9,biomesoplenty:hard_ice)
Block(-3,7,10,biomesoplenty:hard_ice)
Block(-3,7,11,biomesoplenty:hard_ice)
Block(-3,7,12,biomesoplenty:hard_ice)
Block(-3,7,13,biomesoplenty:hard_ice)
Block(-3,8,-8,biomesoplenty:hard_ice)
Block(-3,8,-7,biomesoplenty:hard_ice)
Block(-3,8,-6,biomesoplenty:hard_ice)
Block(-3,8,-5,biomesoplenty:hard_ice)
Block(-3,8,-4,biomesoplenty:hard_ice)
Block(-3,8,-3,biomesoplenty:hard_ice)
Block(-3,8,-2,biomesoplenty:hard_ice)
Block(-3,8,-1,biomesoplenty:hard_ice)
Block(-3,8,0,biomesoplenty:hard_ice)
Block(-3,8,1,biomesoplenty:hard_ice)
Block(-3,8,2,biomesoplenty:hard_ice)
Block(-3,8,3,biomesoplenty:hard_ice)
Block(-3,8,4,biomesoplenty:hard_ice)
Block(-3,8,5,biomesoplenty:hard_ice)
Block(-3,8,6,biomesoplenty:hard_ice)
Block(-3,8,7,biomesoplenty:hard_ice)
Block(-3,8,8,biomesoplenty:hard_ice)
Block(-3,8,9,biomesoplenty:hard_ice)
Block(-3,8,10,biomesoplenty:hard_ice)
Block(-3,8,11,biomesoplenty:hard_ice)
Block(-3,8,12,biomesoplenty:hard_ice)
Block(-3,8,13,biomesoplenty:hard_ice)
Block(-3,8,14,biomesoplenty:hard_ice)
Block(-3,9,-9,biomesoplenty:hard_ice)
Block(-3,9,-8,biomesoplenty:hard_ice)
Block(-3,9,-7,biomesoplenty:hard_ice)
Block(-3,9,-6,biomesoplenty:hard_ice)
Block(-3,9,-5,biomesoplenty:hard_ice)
Block(-3,9,-4,biomesoplenty:hard_ice)
Block(-3,9,-3,biomesoplenty:hard_ice)
Block(-3,9,-2,biomesoplenty:hard_ice)
Block(-3,9,-1,biomesoplenty:hard_ice)
Block(-3,9,0,biomesoplenty:hard_ice)
Block(-3,9,1,biomesoplenty:hard_ice)
Block(-3,9,2,biomesoplenty:hard_ice)
Block(-3,9,3,biomesoplenty:hard_ice)
Block(-3,9,4,biomesoplenty:hard_ice)
Block(-3,9,5,biomesoplenty:hard_ice)
Block(-3,9,6,biomesoplenty:hard_ice)
Block(-3,9,7,biomesoplenty:hard_ice)
Block(-3,9,8,biomesoplenty:hard_ice)
Block(-3,9,9,biomesoplenty:hard_ice)
Block(-3,9,10,biomesoplenty:hard_ice)
Block(-3,9,11,biomesoplenty:hard_ice)
Block(-3,9,12,biomesoplenty:hard_ice)
Block(-3,9,13,biomesoplenty:hard_ice)
Block(-3,9,14,biomesoplenty:hard_ice)
Block(-3,10,-9,biomesoplenty:hard_ice)
Block(-3,10,-8,biomesoplenty:hard_ice)
Block(-3,10,-7,biomesoplenty:hard_ice)
Block(-3,10,-6,biomesoplenty:hard_ice)
Block(-3,10,-5,biomesoplenty:hard_ice)
Block(-3,10,-4,biomesoplenty:hard_ice)
Block(-3,10,-3,biomesoplenty:hard_ice)
Block(-3,10,-2,biomesoplenty:hard_ice)
Block(-3,10,-1,biomesoplenty:hard_ice)
Block(-3,10,0,biomesoplenty:hard_ice)
Block(-3,10,1,biomesoplenty:hard_ice)
Block(-3,10,2,biomesoplenty:hard_ice)
Block(-3,10,3,biomesoplenty:hard_ice)
Block(-3,10,4,biomesoplenty:hard_ice)
Block(-3,10,5,biomesoplenty:hard_ice)
Block(-3,10,6,biomesoplenty:hard_ice)
Block(-3,10,7,biomesoplenty:hard_ice)
Block(-3,10,8,biomesoplenty:hard_ice)
Block(-3,10,9,biomesoplenty:hard_ice)
Block(-3,10,10,biomesoplenty:hard_ice)
Block(-3,10,11,biomesoplenty:hard_ice)
Block(-3,10,12,biomesoplenty:hard_ice)
Block(-3,10,13,biomesoplenty:hard_ice)
Block(-3,10,14,biomesoplenty:hard_ice)
Block(-3,10,15,biomesoplenty:hard_ice)
Block(-3,11,-9,biomesoplenty:hard_ice)
Block(-3,11,-8,biomesoplenty:hard_ice)
Block(-3,11,-7,biomesoplenty:hard_ice)
Block(-3,11,-6,biomesoplenty:hard_ice)
Block(-3,11,-5,biomesoplenty:hard_ice)
Block(-3,11,-4,biomesoplenty:hard_ice)
Block(-3,11,-3,biomesoplenty:hard_ice)
Block(-3,11,-2,biomesoplenty:hard_ice)
Block(-3,11,-1,biomesoplenty:hard_ice)
Block(-3,11,0,biomesoplenty:hard_ice)
Block(-3,11,1,biomesoplenty:hard_ice)
Block(-3,11,2,biomesoplenty:hard_ice)
Block(-3,11,3,biomesoplenty:hard_ice)
Block(-3,11,4,biomesoplenty:hard_ice)
Block(-3,11,5,biomesoplenty:hard_ice)
Block(-3,11,6,biomesoplenty:hard_ice)
Block(-3,11,7,biomesoplenty:hard_ice)
Block(-3,11,8,biomesoplenty:hard_ice)
Block(-3,11,9,biomesoplenty:hard_ice)
Block(-3,11,10,biomesoplenty:hard_ice)
Block(-3,11,11,biomesoplenty:hard_ice)
Block(-3,11,12,biomesoplenty:hard_ice)
Block(-3,11,13,biomesoplenty:hard_ice)
Block(-3,11,14,biomesoplenty:hard_ice)
Block(-3,11,15,biomesoplenty:hard_ice)
Block(-3,12,-9,biomesoplenty:hard_ice)
Block(-3,12,-8,biomesoplenty:hard_ice)
Block(-3,12,-7,biomesoplenty:hard_ice)
Block(-3,12,-6,biomesoplenty:hard_ice)
Block(-3,12,-5,biomesoplenty:hard_ice)
Block(-3,12,-4,biomesoplenty:hard_ice)
Block(-3,12,-3,biomesoplenty:hard_ice)
Block(-3,12,-2,biomesoplenty:hard_ice)
Block(-3,12,-1,biomesoplenty:hard_ice)
Block(-3,12,0,biomesoplenty:hard_ice)
Block(-3,12,1,biomesoplenty:hard_ice)
Block(-3,12,2,biomesoplenty:hard_ice)
Block(-3,12,3,biomesoplenty:hard_ice)
Block(-3,12,4,biomesoplenty:hard_ice)
Block(-3,12,5,biomesoplenty:hard_ice)
Block(-3,12,6,biomesoplenty:hard_ice)
Block(-3,12,7,biomesoplenty:hard_ice)
Block(-3,12,8,biomesoplenty:hard_ice)
Block(-3,12,9,biomesoplenty:hard_ice)
Block(-3,12,10,biomesoplenty:hard_ice)
Block(-3,12,11,biomesoplenty:hard_ice)
Block(-3,12,12,biomesoplenty:hard_ice)
Block(-3,12,13,biomesoplenty:hard_ice)
Block(-3,12,14,biomesoplenty:hard_ice)
Block(-3,12,15,biomesoplenty:hard_ice)
Block(-3,13,-9,biomesoplenty:hard_ice)
Block(-3,13,-8,biomesoplenty:hard_ice)
Block(-3,13,-7,biomesoplenty:hard_ice)
Block(-3,13,-6,biomesoplenty:hard_ice)
Block(-3,13,-5,biomesoplenty:hard_ice)
Block(-3,13,-4,biomesoplenty:hard_ice)
Block(-3,13,-3,biomesoplenty:hard_ice)
Block(-3,13,-2,biomesoplenty:hard_ice)
Block(-3,13,-1,biomesoplenty:hard_ice)
Block(-3,13,0,biomesoplenty:hard_ice)
Block(-3,13,1,biomesoplenty:hard_ice)
Block(-3,13,2,biomesoplenty:hard_ice)
Block(-3,13,3,biomesoplenty:hard_ice)
Block(-3,13,4,biomesoplenty:hard_ice)
Block(-3,13,5,biomesoplenty:hard_ice)
Block(-3,13,6,biomesoplenty:hard_ice)
Block(-3,13,7,biomesoplenty:hard_ice)
Block(-3,13,8,biomesoplenty:hard_ice)
Block(-3,13,9,biomesoplenty:hard_ice)
Block(-3,13,10,biomesoplenty:hard_ice)
Block(-3,13,11,biomesoplenty:hard_ice)
Block(-3,13,12,biomesoplenty:hard_ice)
Block(-3,13,13,biomesoplenty:hard_ice)
Block(-3,13,14,biomesoplenty:hard_ice)
Block(-3,13,15,biomesoplenty:hard_ice)
Block(-3,14,-9,biomesoplenty:hard_ice)
Block(-3,14,-8,biomesoplenty:hard_ice)
Block(-3,14,-7,biomesoplenty:hard_ice)
Block(-3,14,-6,biomesoplenty:hard_ice)
Block(-3,14,-5,biomesoplenty:hard_ice)
Block(-3,14,-4,biomesoplenty:hard_ice)
Block(-3,14,-3,biomesoplenty:hard_ice)
Block(-3,14,-2,biomesoplenty:hard_ice)
Block(-3,14,-1,biomesoplenty:hard_ice)
Block(-3,14,0,biomesoplenty:hard_ice)
Block(-3,14,1,biomesoplenty:hard_ice)
Block(-3,14,2,biomesoplenty:hard_ice)
Block(-3,14,3,biomesoplenty:hard_ice)
Block(-3,14,4,biomesoplenty:hard_ice)
Block(-3,14,5,biomesoplenty:hard_ice)
Block(-3,14,6,biomesoplenty:hard_ice)
Block(-3,14,7,biomesoplenty:hard_ice)
Block(-3,14,8,biomesoplenty:hard_ice)
Block(-3,14,9,biomesoplenty:hard_ice)
Block(-3,14,10,biomesoplenty:hard_ice)
Block(-3,14,11,biomesoplenty:hard_ice)
Block(-3,14,12,biomesoplenty:hard_ice)
Block(-3,14,13,biomesoplenty:hard_ice)
Block(-3,14,14,biomesoplenty:hard_ice)
Block(-3,14,15,biomesoplenty:hard_ice)
Block(-3,15,-9,biomesoplenty:hard_ice)
Block(-3,15,-8,biomesoplenty:hard_ice)
Block(-3,15,-7,biomesoplenty:hard_ice)
Block(-3,15,-6,biomesoplenty:hard_ice)
Block(-3,15,-5,biomesoplenty:hard_ice)
Block(-3,15,-4,biomesoplenty:hard_ice)
Block(-3,15,-3,biomesoplenty:hard_ice)
Block(-3,15,-2,biomesoplenty:hard_ice)
Block(-3,15,-1,biomesoplenty:hard_ice)
Block(-3,15,0,biomesoplenty:hard_ice)
Block(-3,15,1,biomesoplenty:hard_ice)
Block(-3,15,2,biomesoplenty:hard_ice)
Block(-3,15,3,biomesoplenty:hard_ice)
Block(-3,15,4,biomesoplenty:hard_ice)
Block(-3,15,5,biomesoplenty:hard_ice)
Block(-3,15,6,biomesoplenty:hard_ice)
Block(-3,15,7,biomesoplenty:hard_ice)
Block(-3,15,8,biomesoplenty:hard_ice)
Block(-3,15,9,biomesoplenty:hard_ice)
Block(-3,15,10,biomesoplenty:hard_ice)
Block(-3,15,11,biomesoplenty:hard_ice)
Block(-3,15,12,biomesoplenty:hard_ice)
Block(-3,15,13,biomesoplenty:hard_ice)
Block(-3,15,14,biomesoplenty:hard_ice)
Block(-3,16,-9,biomesoplenty:hard_ice)
Block(-3,16,-8,biomesoplenty:hard_ice)
Block(-3,16,-7,biomesoplenty:hard_ice)
Block(-3,16,-6,biomesoplenty:hard_ice)
Block(-3,16,-5,biomesoplenty:hard_ice)
Block(-3,16,-4,biomesoplenty:hard_ice)
Block(-3,16,-3,biomesoplenty:hard_ice)
Block(-3,16,-2,biomesoplenty:hard_ice)
Block(-3,16,-1,biomesoplenty:hard_ice)
Block(-3,16,0,biomesoplenty:hard_ice)
Block(-3,16,1,biomesoplenty:hard_ice)
Block(-3,16,2,biomesoplenty:hard_ice)
Block(-3,16,3,biomesoplenty:hard_ice)
Block(-3,16,4,biomesoplenty:hard_ice)
Block(-3,16,5,biomesoplenty:hard_ice)
Block(-3,16,6,biomesoplenty:hard_ice)
Block(-3,16,7,biomesoplenty:hard_ice)
Block(-3,16,8,biomesoplenty:hard_ice)
Block(-3,16,9,biomesoplenty:hard_ice)
Block(-3,16,10,biomesoplenty:hard_ice)
Block(-3,16,11,biomesoplenty:hard_ice)
Block(-3,16,12,biomesoplenty:hard_ice)
Block(-3,16,13,biomesoplenty:hard_ice)
Block(-3,16,14,biomesoplenty:hard_ice)
Block(-3,17,-9,biomesoplenty:hard_ice)
Block(-3,17,-8,biomesoplenty:hard_ice)
Block(-3,17,-7,biomesoplenty:hard_ice)
Block(-3,17,-6,biomesoplenty:hard_ice)
Block(-3,17,-5,biomesoplenty:hard_ice)
Block(-3,17,-4,biomesoplenty:hard_ice)
Block(-3,17,-3,biomesoplenty:hard_ice)
Block(-3,17,-2,biomesoplenty:hard_ice)
Block(-3,17,-1,biomesoplenty:hard_ice)
Block(-3,17,0,biomesoplenty:hard_ice)
Block(-3,17,1,biomesoplenty:hard_ice)
Block(-3,17,2,biomesoplenty:hard_ice)
Block(-3,17,3,biomesoplenty:hard_ice)
Block(-3,17,4,biomesoplenty:hard_ice)
Block(-3,17,5,biomesoplenty:hard_ice)
Block(-3,17,6,biomesoplenty:hard_ice)
Block(-3,17,7,biomesoplenty:hard_ice)
Block(-3,17,8,biomesoplenty:hard_ice)
Block(-3,17,9,biomesoplenty:hard_ice)
Block(-3,17,10,biomesoplenty:hard_ice)
Block(-3,17,11,biomesoplenty:hard_ice)
Block(-3,17,12,biomesoplenty:hard_ice)
Block(-3,17,13,biomesoplenty:hard_ice)
Block(-3,18,-9,biomesoplenty:hard_ice)
Block(-3,18,-8,biomesoplenty:hard_ice)
Block(-3,18,-7,biomesoplenty:hard_ice)
Block(-3,18,-6,biomesoplenty:hard_ice)
Block(-3,18,-5,biomesoplenty:hard_ice)
Block(-3,18,-4,biomesoplenty:hard_ice)
Block(-3,18,-3,biomesoplenty:hard_ice)
Block(-3,18,-2,biomesoplenty:hard_ice)
Block(-3,18,-1,biomesoplenty:hard_ice)
Block(-3,18,0,biomesoplenty:hard_ice)
Block(-3,18,1,biomesoplenty:hard_ice)
Block(-3,18,2,biomesoplenty:hard_ice)
Block(-3,18,3,biomesoplenty:hard_ice)
Block(-3,18,4,biomesoplenty:hard_ice)
Block(-3,18,5,biomesoplenty:hard_ice)
Block(-3,18,6,biomesoplenty:hard_ice)
Block(-3,18,7,biomesoplenty:hard_ice)
Block(-3,18,8,biomesoplenty:hard_ice)
Block(-3,18,9,biomesoplenty:hard_ice)
Block(-3,18,10,biomesoplenty:hard_ice)
Block(-3,18,11,biomesoplenty:hard_ice)
Block(-3,18,12,biomesoplenty:hard_ice)
Block(-3,19,-9,biomesoplenty:hard_ice)
Block(-3,19,-8,biomesoplenty:hard_ice)
Block(-3,19,-7,biomesoplenty:hard_ice)
Block(-3,19,-6,biomesoplenty:hard_ice)
Block(-3,19,-5,biomesoplenty:hard_ice)
Block(-3,19,-4,biomesoplenty:hard_ice)
Block(-3,19,-3,biomesoplenty:hard_ice)
Block(-3,19,-2,biomesoplenty:hard_ice)
Block(-3,19,-1,biomesoplenty:hard_ice)
Block(-3,19,0,biomesoplenty:hard_ice)
Block(-3,19,1,biomesoplenty:hard_ice)
Block(-3,19,2,biomesoplenty:hard_ice)
Block(-3,19,3,biomesoplenty:hard_ice)
Block(-3,19,4,biomesoplenty:hard_ice)
Block(-3,19,5,biomesoplenty:hard_ice)
Block(-3,19,6,biomesoplenty:hard_ice)
Block(-3,19,7,biomesoplenty:hard_ice)
Block(-3,19,8,biomesoplenty:hard_ice)
Block(-3,19,9,biomesoplenty:hard_ice)
Block(-3,19,10,biomesoplenty:hard_ice)
Block(-3,19,11,biomesoplenty:hard_ice)
Block(-3,20,-9,biomesoplenty:hard_ice)
Block(-3,20,-8,biomesoplenty:hard_ice)
Block(-3,20,-7,biomesoplenty:hard_ice)
Block(-3,20,-6,biomesoplenty:hard_ice)
Block(-3,20,-5,biomesoplenty:hard_ice)
Block(-3,20,-4,biomesoplenty:hard_ice)
Block(-3,20,-3,biomesoplenty:hard_ice)
Block(-3,20,-2,biomesoplenty:hard_ice)
Block(-3,20,-1,biomesoplenty:hard_ice)
Block(-3,20,0,biomesoplenty:hard_ice)
Block(-3,20,1,biomesoplenty:hard_ice)
Block(-3,20,2,biomesoplenty:hard_ice)
Block(-3,20,3,biomesoplenty:hard_ice)
Block(-3,20,4,biomesoplenty:hard_ice)
Block(-3,20,5,biomesoplenty:hard_ice)
Block(-3,20,6,biomesoplenty:hard_ice)
Block(-3,20,7,biomesoplenty:hard_ice)
Block(-3,20,8,biomesoplenty:hard_ice)
Block(-3,20,9,biomesoplenty:hard_ice)
Block(-3,20,10,biomesoplenty:hard_ice)
Block(-3,21,-8,biomesoplenty:hard_ice)
Block(-3,21,-7,biomesoplenty:hard_ice)
Block(-3,21,-6,biomesoplenty:hard_ice)
Block(-3,21,-5,biomesoplenty:hard_ice)
Block(-3,21,-4,biomesoplenty:hard_ice)
Block(-3,21,-3,biomesoplenty:hard_ice)
Block(-3,21,-2,biomesoplenty:hard_ice)
Block(-3,21,-1,biomesoplenty:hard_ice)
Block(-3,21,0,biomesoplenty:hard_ice)
Block(-3,21,1,biomesoplenty:hard_ice)
Block(-3,21,2,biomesoplenty:hard_ice)
Block(-3,21,3,biomesoplenty:hard_ice)
Block(-3,21,4,biomesoplenty:hard_ice)
Block(-3,21,5,biomesoplenty:hard_ice)
Block(-3,21,6,biomesoplenty:hard_ice)
Block(-2,2,7,biomesoplenty:hard_ice)
Block(-2,2,8,biomesoplenty:hard_ice)
Block(-2,2,9,biomesoplenty:hard_ice)
Block(-2,2,10,biomesoplenty:hard_ice)
Block(-2,3,1,biomesoplenty:hard_ice)
Block(-2,3,2,biomesoplenty:hard_ice)
Block(-2,3,3,biomesoplenty:hard_ice)
Block(-2,3,4,biomesoplenty:hard_ice)
Block(-2,3,5,biomesoplenty:hard_ice)
Block(-2,3,6,biomesoplenty:hard_ice)
Block(-2,3,7,biomesoplenty:hard_ice)
Block(-2,3,8,biomesoplenty:hard_ice)
Block(-2,3,9,biomesoplenty:hard_ice)
Block(-2,3,10,biomesoplenty:hard_ice)
Block(-2,3,11,biomesoplenty:hard_ice)
Block(-2,4,-7,biomesoplenty:hard_ice)
Block(-2,4,-6,biomesoplenty:hard_ice)
Block(-2,4,-5,biomesoplenty:hard_ice)
Block(-2,4,-4,biomesoplenty:hard_ice)
Block(-2,4,-3,biomesoplenty:hard_ice)
Block(-2,4,-2,biomesoplenty:hard_ice)
Block(-2,4,-1,biomesoplenty:hard_ice)
Block(-2,4,0,biomesoplenty:hard_ice)
Block(-2,4,1,biomesoplenty:hard_ice)
Block(-2,4,2,biomesoplenty:hard_ice)
Block(-2,4,3,biomesoplenty:hard_ice)
Block(-2,4,4,biomesoplenty:hard_ice)
Block(-2,4,5,biomesoplenty:hard_ice)
Block(-2,4,6,biomesoplenty:hard_ice)
Block(-2,4,7,biomesoplenty:hard_ice)
Block(-2,4,8,biomesoplenty:hard_ice)
Block(-2,4,9,biomesoplenty:hard_ice)
Block(-2,4,10,biomesoplenty:hard_ice)
Block(-2,4,11,biomesoplenty:hard_ice)
Block(-2,5,-9,biomesoplenty:hard_ice)
Block(-2,5,-8,biomesoplenty:hard_ice)
Block(-2,5,-7,biomesoplenty:hard_ice)
Block(-2,5,-6,biomesoplenty:hard_ice)
Block(-2,5,-5,biomesoplenty:hard_ice)
Block(-2,5,-4,biomesoplenty:hard_ice)
Block(-2,5,-3,biomesoplenty:hard_ice)
Block(-2,5,-2,biomesoplenty:hard_ice)
Block(-2,5,-1,biomesoplenty:hard_ice)
Block(-2,5,0,biomesoplenty:hard_ice)
Block(-2,5,1,biomesoplenty:hard_ice)
Block(-2,5,2,biomesoplenty:hard_ice)
Block(-2,5,3,biomesoplenty:hard_ice)
Block(-2,5,4,biomesoplenty:hard_ice)
Block(-2,5,5,biomesoplenty:hard_ice)
Block(-2,5,6,biomesoplenty:hard_ice)
Block(-2,5,7,biomesoplenty:hard_ice)
Block(-2,5,8,biomesoplenty:hard_ice)
Block(-2,5,9,biomesoplenty:hard_ice)
Block(-2,5,10,biomesoplenty:hard_ice)
Block(-2,5,11,biomesoplenty:hard_ice)
Block(-2,5,12,biomesoplenty:hard_ice)
Block(-2,6,-9,biomesoplenty:hard_ice)
Block(-2,6,-8,biomesoplenty:hard_ice)
Block(-2,6,-7,biomesoplenty:hard_ice)
Block(-2,6,-6,biomesoplenty:hard_ice)
Block(-2,6,-5,biomesoplenty:hard_ice)
Block(-2,6,-4,biomesoplenty:hard_ice)
Block(-2,6,-3,biomesoplenty:hard_ice)
Block(-2,6,-2,biomesoplenty:hard_ice)
Block(-2,6,-1,biomesoplenty:hard_ice)
Block(-2,6,0,biomesoplenty:hard_ice)
Block(-2,6,1,biomesoplenty:hard_ice)
Block(-2,6,2,biomesoplenty:hard_ice)
Block(-2,6,3,biomesoplenty:hard_ice)
Block(-2,6,4,biomesoplenty:hard_ice)
Block(-2,6,5,biomesoplenty:hard_ice)
Block(-2,6,6,biomesoplenty:hard_ice)
Block(-2,6,7,biomesoplenty:hard_ice)
Block(-2,6,8,biomesoplenty:hard_ice)
Block(-2,6,9,biomesoplenty:hard_ice)
Block(-2,6,10,biomesoplenty:hard_ice)
Block(-2,6,11,biomesoplenty:hard_ice)
Block(-2,6,12,biomesoplenty:hard_ice)
Block(-2,7,-9,biomesoplenty:hard_ice)
Block(-2,7,-8,biomesoplenty:hard_ice)
Block(-2,7,-7,biomesoplenty:hard_ice)
Block(-2,7,-6,biomesoplenty:hard_ice)
Block(-2,7,-5,biomesoplenty:hard_ice)
Block(-2,7,-4,biomesoplenty:hard_ice)
Block(-2,7,-3,biomesoplenty:hard_ice)
Block(-2,7,-2,biomesoplenty:hard_ice)
Block(-2,7,-1,biomesoplenty:hard_ice)
Block(-2,7,0,biomesoplenty:hard_ice)
Block(-2,7,1,biomesoplenty:hard_ice)
Block(-2,7,2,biomesoplenty:hard_ice)
Block(-2,7,3,biomesoplenty:hard_ice)
Block(-2,7,4,biomesoplenty:hard_ice)
Block(-2,7,5,biomesoplenty:hard_ice)
Block(-2,7,6,biomesoplenty:hard_ice)
Block(-2,7,7,biomesoplenty:hard_ice)
Block(-2,7,8,biomesoplenty:hard_ice)
Block(-2,7,9,biomesoplenty:hard_ice)
Block(-2,7,10,biomesoplenty:hard_ice)
Block(-2,7,11,biomesoplenty:hard_ice)
Block(-2,7,12,biomesoplenty:hard_ice)
Block(-2,7,13,biomesoplenty:hard_ice)
Block(-2,8,-9,biomesoplenty:hard_ice)
Block(-2,8,-8,biomesoplenty:hard_ice)
Block(-2,8,-7,biomesoplenty:hard_ice)
Block(-2,8,-6,biomesoplenty:hard_ice)
Block(-2,8,-5,biomesoplenty:hard_ice)
Block(-2,8,-4,biomesoplenty:hard_ice)
Block(-2,8,-3,biomesoplenty:hard_ice)
Block(-2,8,-2,biomesoplenty:hard_ice)
Block(-2,8,-1,biomesoplenty:hard_ice)
Block(-2,8,0,biomesoplenty:hard_ice)
Block(-2,8,1,biomesoplenty:hard_ice)
Block(-2,8,2,biomesoplenty:hard_ice)
Block(-2,8,3,biomesoplenty:hard_ice)
Block(-2,8,4,biomesoplenty:hard_ice)
Block(-2,8,5,biomesoplenty:hard_ice)
Block(-2,8,6,biomesoplenty:hard_ice)
Block(-2,8,7,biomesoplenty:hard_ice)
Block(-2,8,8,biomesoplenty:hard_ice)
Block(-2,8,9,biomesoplenty:hard_ice)
Block(-2,8,10,biomesoplenty:hard_ice)
Block(-2,8,11,biomesoplenty:hard_ice)
Block(-2,8,12,biomesoplenty:hard_ice)
Block(-2,8,13,biomesoplenty:hard_ice)
Block(-2,8,14,biomesoplenty:hard_ice)
Block(-2,9,-10,biomesoplenty:hard_ice)
Block(-2,9,-9,biomesoplenty:hard_ice)
Block(-2,9,-8,biomesoplenty:hard_ice)
Block(-2,9,-7,biomesoplenty:hard_ice)
Block(-2,9,-6,biomesoplenty:hard_ice)
Block(-2,9,-5,biomesoplenty:hard_ice)
Block(-2,9,-4,biomesoplenty:hard_ice)
Block(-2,9,-3,biomesoplenty:hard_ice)
Block(-2,9,-2,biomesoplenty:hard_ice)
Block(-2,9,-1,biomesoplenty:hard_ice)
Block(-2,9,0,biomesoplenty:hard_ice)
Block(-2,9,1,biomesoplenty:hard_ice)
Block(-2,9,2,biomesoplenty:hard_ice)
Block(-2,9,3,biomesoplenty:hard_ice)
Block(-2,9,4,biomesoplenty:hard_ice)
Block(-2,9,5,biomesoplenty:hard_ice)
Block(-2,9,6,biomesoplenty:hard_ice)
Block(-2,9,7,biomesoplenty:hard_ice)
Block(-2,9,8,biomesoplenty:hard_ice)
Block(-2,9,9,biomesoplenty:hard_ice)
Block(-2,9,10,biomesoplenty:hard_ice)
Block(-2,9,11,biomesoplenty:hard_ice)
Block(-2,9,12,biomesoplenty:hard_ice)
Block(-2,9,13,biomesoplenty:hard_ice)
Block(-2,9,14,biomesoplenty:hard_ice)
Block(-2,10,-10,biomesoplenty:hard_ice)
Block(-2,10,-9,biomesoplenty:hard_ice)
Block(-2,10,-8,biomesoplenty:hard_ice)
Block(-2,10,-7,biomesoplenty:hard_ice)
Block(-2,10,-6,biomesoplenty:hard_ice)
Block(-2,10,-5,biomesoplenty:hard_ice)
Block(-2,10,-4,biomesoplenty:hard_ice)
Block(-2,10,-3,biomesoplenty:hard_ice)
Block(-2,10,-2,biomesoplenty:hard_ice)
Block(-2,10,-1,biomesoplenty:hard_ice)
Block(-2,10,0,biomesoplenty:hard_ice)
Block(-2,10,1,biomesoplenty:hard_ice)
Block(-2,10,2,biomesoplenty:hard_ice)
Block(-2,10,3,biomesoplenty:hard_ice)
Block(-2,10,4,biomesoplenty:hard_ice)
Block(-2,10,5,biomesoplenty:hard_ice)
Block(-2,10,6,biomesoplenty:hard_ice)
Block(-2,10,7,biomesoplenty:hard_ice)
Block(-2,10,8,biomesoplenty:hard_ice)
Block(-2,10,9,biomesoplenty:hard_ice)
Block(-2,10,10,biomesoplenty:hard_ice)
Block(-2,10,11,biomesoplenty:hard_ice)
Block(-2,10,12,biomesoplenty:hard_ice)
Block(-2,10,13,biomesoplenty:hard_ice)
Block(-2,10,14,biomesoplenty:hard_ice)
Block(-2,10,15,biomesoplenty:hard_ice)
Block(-2,11,-10,biomesoplenty:hard_ice)
Block(-2,11,-9,biomesoplenty:hard_ice)
Block(-2,11,-8,biomesoplenty:hard_ice)
Block(-2,11,-7,biomesoplenty:hard_ice)
Block(-2,11,-6,biomesoplenty:hard_ice)
Block(-2,11,-5,biomesoplenty:hard_ice)
Block(-2,11,-4,biomesoplenty:hard_ice)
Block(-2,11,-3,biomesoplenty:hard_ice)
Block(-2,11,-2,biomesoplenty:hard_ice)
Block(-2,11,-1,biomesoplenty:hard_ice)
Block(-2,11,0,biomesoplenty:hard_ice)
Block(-2,11,1,biomesoplenty:hard_ice)
Block(-2,11,2,biomesoplenty:hard_ice)
Block(-2,11,3,biomesoplenty:hard_ice)
Block(-2,11,4,biomesoplenty:hard_ice)
Block(-2,11,5,biomesoplenty:hard_ice)
Block(-2,11,6,biomesoplenty:hard_ice)
Block(-2,11,7,biomesoplenty:hard_ice)
Block(-2,11,8,biomesoplenty:hard_ice)
Block(-2,11,9,biomesoplenty:hard_ice)
Block(-2,11,10,biomesoplenty:hard_ice)
Block(-2,11,11,biomesoplenty:hard_ice)
Block(-2,11,12,biomesoplenty:hard_ice)
Block(-2,11,13,biomesoplenty:hard_ice)
Block(-2,11,14,biomesoplenty:hard_ice)
Block(-2,11,15,biomesoplenty:hard_ice)
Block(-2,11,16,biomesoplenty:hard_ice)
Block(-2,12,-10,biomesoplenty:hard_ice)
Block(-2,12,-9,biomesoplenty:hard_ice)
Block(-2,12,-8,biomesoplenty:hard_ice)
Block(-2,12,-7,biomesoplenty:hard_ice)
Block(-2,12,-6,biomesoplenty:hard_ice)
Block(-2,12,-5,biomesoplenty:hard_ice)
Block(-2,12,-4,biomesoplenty:hard_ice)
Block(-2,12,-3,biomesoplenty:hard_ice)
Block(-2,12,-2,biomesoplenty:hard_ice)
Block(-2,12,-1,biomesoplenty:hard_ice)
Block(-2,12,0,biomesoplenty:hard_ice)
Block(-2,12,1,biomesoplenty:hard_ice)
Block(-2,12,2,biomesoplenty:hard_ice)
Block(-2,12,3,biomesoplenty:hard_ice)
Block(-2,12,4,biomesoplenty:hard_ice)
Block(-2,12,5,biomesoplenty:hard_ice)
Block(-2,12,6,biomesoplenty:hard_ice)
Block(-2,12,7,biomesoplenty:hard_ice)
Block(-2,12,8,biomesoplenty:hard_ice)
Block(-2,12,9,biomesoplenty:hard_ice)
Block(-2,12,10,biomesoplenty:hard_ice)
Block(-2,12,11,biomesoplenty:hard_ice)
Block(-2,12,12,biomesoplenty:hard_ice)
Block(-2,12,13,biomesoplenty:hard_ice)
Block(-2,12,14,biomesoplenty:hard_ice)
Block(-2,12,15,biomesoplenty:hard_ice)
Block(-2,12,16,biomesoplenty:hard_ice)
Block(-2,13,-10,biomesoplenty:hard_ice)
Block(-2,13,-9,biomesoplenty:hard_ice)
Block(-2,13,-8,biomesoplenty:hard_ice)
Block(-2,13,-7,biomesoplenty:hard_ice)
Block(-2,13,-6,biomesoplenty:hard_ice)
Block(-2,13,-5,biomesoplenty:hard_ice)
Block(-2,13,-4,biomesoplenty:hard_ice)
Block(-2,13,-3,biomesoplenty:hard_ice)
Block(-2,13,-2,biomesoplenty:hard_ice)
Block(-2,13,-1,biomesoplenty:hard_ice)
Block(-2,13,0,biomesoplenty:hard_ice)
Block(-2,13,1,biomesoplenty:hard_ice)
Block(-2,13,2,biomesoplenty:hard_ice)
Block(-2,13,3,biomesoplenty:hard_ice)
Block(-2,13,4,biomesoplenty:hard_ice)
Block(-2,13,5,biomesoplenty:hard_ice)
Block(-2,13,6,biomesoplenty:hard_ice)
Block(-2,13,7,biomesoplenty:hard_ice)
Block(-2,13,8,biomesoplenty:hard_ice)
Block(-2,13,9,biomesoplenty:hard_ice)
Block(-2,13,10,biomesoplenty:hard_ice)
Block(-2,13,11,biomesoplenty:hard_ice)
Block(-2,13,12,biomesoplenty:hard_ice)
Block(-2,13,13,biomesoplenty:hard_ice)
Block(-2,13,14,biomesoplenty:hard_ice)
Block(-2,13,15,biomesoplenty:hard_ice)
Block(-2,13,16,biomesoplenty:hard_ice)
Block(-2,14,-10,biomesoplenty:hard_ice)
Block(-2,14,-9,biomesoplenty:hard_ice)
Block(-2,14,-8,biomesoplenty:hard_ice)
Block(-2,14,-7,biomesoplenty:hard_ice)
Block(-2,14,-6,biomesoplenty:hard_ice)
Block(-2,14,-5,biomesoplenty:hard_ice)
Block(-2,14,-4,biomesoplenty:hard_ice)
Block(-2,14,-3,biomesoplenty:hard_ice)
Block(-2,14,-2,biomesoplenty:hard_ice)
Block(-2,14,-1,biomesoplenty:hard_ice)
Block(-2,14,0,biomesoplenty:hard_ice)
Block(-2,14,1,biomesoplenty:hard_ice)
Block(-2,14,2,biomesoplenty:hard_ice)
Block(-2,14,3,biomesoplenty:hard_ice)
Block(-2,14,4,biomesoplenty:hard_ice)
Block(-2,14,5,biomesoplenty:hard_ice)
Block(-2,14,6,biomesoplenty:hard_ice)
Block(-2,14,7,biomesoplenty:hard_ice)
Block(-2,14,8,biomesoplenty:hard_ice)
Block(-2,14,9,biomesoplenty:hard_ice)
Block(-2,14,10,biomesoplenty:hard_ice)
Block(-2,14,11,biomesoplenty:hard_ice)
Block(-2,14,12,biomesoplenty:hard_ice)
Block(-2,14,13,biomesoplenty:hard_ice)
Block(-2,14,14,biomesoplenty:hard_ice)
Block(-2,14,15,biomesoplenty:hard_ice)
Block(-2,14,16,biomesoplenty:hard_ice)
Block(-2,15,-10,biomesoplenty:hard_ice)
Block(-2,15,-9,biomesoplenty:hard_ice)
Block(-2,15,-8,biomesoplenty:hard_ice)
Block(-2,15,-7,biomesoplenty:hard_ice)
Block(-2,15,-6,biomesoplenty:hard_ice)
Block(-2,15,-5,biomesoplenty:hard_ice)
Block(-2,15,-4,biomesoplenty:hard_ice)
Block(-2,15,-3,biomesoplenty:hard_ice)
Block(-2,15,-2,biomesoplenty:hard_ice)
Block(-2,15,-1,biomesoplenty:hard_ice)
Block(-2,15,0,biomesoplenty:hard_ice)
Block(-2,15,1,biomesoplenty:hard_ice)
Block(-2,15,2,biomesoplenty:hard_ice)
Block(-2,15,3,biomesoplenty:hard_ice)
Block(-2,15,4,biomesoplenty:hard_ice)
Block(-2,15,5,biomesoplenty:hard_ice)
Block(-2,15,6,biomesoplenty:hard_ice)
Block(-2,15,7,biomesoplenty:hard_ice)
Block(-2,15,8,biomesoplenty:hard_ice)
Block(-2,15,9,biomesoplenty:hard_ice)
Block(-2,15,10,biomesoplenty:hard_ice)
Block(-2,15,11,biomesoplenty:hard_ice)
Block(-2,15,12,biomesoplenty:hard_ice)
Block(-2,15,13,biomesoplenty:hard_ice)
Block(-2,15,14,biomesoplenty:hard_ice)
Block(-2,15,15,biomesoplenty:hard_ice)
Block(-2,16,-10,biomesoplenty:hard_ice)
Block(-2,16,-9,biomesoplenty:hard_ice)
Block(-2,16,-8,biomesoplenty:hard_ice)
Block(-2,16,-7,biomesoplenty:hard_ice)
Block(-2,16,-6,biomesoplenty:hard_ice)
Block(-2,16,-5,biomesoplenty:hard_ice)
Block(-2,16,-4,biomesoplenty:hard_ice)
Block(-2,16,-3,biomesoplenty:hard_ice)
Block(-2,16,-2,biomesoplenty:hard_ice)
Block(-2,16,-1,biomesoplenty:hard_ice)
Block(-2,16,0,biomesoplenty:hard_ice)
Block(-2,16,1,biomesoplenty:hard_ice)
Block(-2,16,2,biomesoplenty:hard_ice)
Block(-2,16,3,biomesoplenty:hard_ice)
Block(-2,16,4,biomesoplenty:hard_ice)
Block(-2,16,5,biomesoplenty:hard_ice)
Block(-2,16,6,biomesoplenty:hard_ice)
Block(-2,16,7,biomesoplenty:hard_ice)
Block(-2,16,8,biomesoplenty:hard_ice)
Block(-2,16,9,biomesoplenty:hard_ice)
Block(-2,16,10,biomesoplenty:hard_ice)
Block(-2,16,11,biomesoplenty:hard_ice)
Block(-2,16,12,biomesoplenty:hard_ice)
Block(-2,16,13,biomesoplenty:hard_ice)
Block(-2,16,14,biomesoplenty:hard_ice)
Block(-2,17,-10,biomesoplenty:hard_ice)
Block(-2,17,-9,biomesoplenty:hard_ice)
Block(-2,17,-8,biomesoplenty:hard_ice)
Block(-2,17,-7,biomesoplenty:hard_ice)
Block(-2,17,-6,biomesoplenty:hard_ice)
Block(-2,17,-5,biomesoplenty:hard_ice)
Block(-2,17,-4,biomesoplenty:hard_ice)
Block(-2,17,-3,biomesoplenty:hard_ice)
Block(-2,17,-2,biomesoplenty:hard_ice)
Block(-2,17,-1,biomesoplenty:hard_ice)
Block(-2,17,0,biomesoplenty:hard_ice)
Block(-2,17,1,biomesoplenty:hard_ice)
Block(-2,17,2,biomesoplenty:hard_ice)
Block(-2,17,3,biomesoplenty:hard_ice)
Block(-2,17,4,biomesoplenty:hard_ice)
Block(-2,17,5,biomesoplenty:hard_ice)
Block(-2,17,6,biomesoplenty:hard_ice)
Block(-2,17,7,biomesoplenty:hard_ice)
Block(-2,17,8,biomesoplenty:hard_ice)
Block(-2,17,9,biomesoplenty:hard_ice)
Block(-2,17,10,biomesoplenty:hard_ice)
Block(-2,17,11,biomesoplenty:hard_ice)
Block(-2,17,12,biomesoplenty:hard_ice)
Block(-2,17,13,biomesoplenty:hard_ice)
Block(-2,18,-10,biomesoplenty:hard_ice)
Block(-2,18,-9,biomesoplenty:hard_ice)
Block(-2,18,-8,biomesoplenty:hard_ice)
Block(-2,18,-7,biomesoplenty:hard_ice)
Block(-2,18,-6,biomesoplenty:hard_ice)
Block(-2,18,-5,biomesoplenty:hard_ice)
Block(-2,18,-4,biomesoplenty:hard_ice)
Block(-2,18,-3,biomesoplenty:hard_ice)
Block(-2,18,-2,biomesoplenty:hard_ice)
Block(-2,18,-1,biomesoplenty:hard_ice)
Block(-2,18,0,biomesoplenty:hard_ice)
Block(-2,18,1,biomesoplenty:hard_ice)
Block(-2,18,2,biomesoplenty:hard_ice)
Block(-2,18,3,biomesoplenty:hard_ice)
Block(-2,18,4,biomesoplenty:hard_ice)
Block(-2,18,5,biomesoplenty:hard_ice)
Block(-2,18,6,biomesoplenty:hard_ice)
Block(-2,18,7,biomesoplenty:hard_ice)
Block(-2,18,8,biomesoplenty:hard_ice)
Block(-2,18,9,biomesoplenty:hard_ice)
Block(-2,18,10,biomesoplenty:hard_ice)
Block(-2,18,11,biomesoplenty:hard_ice)
Block(-2,18,12,biomesoplenty:hard_ice)
Block(-2,19,-9,biomesoplenty:hard_ice)
Block(-2,19,-8,biomesoplenty:hard_ice)
Block(-2,19,-7,biomesoplenty:hard_ice)
Block(-2,19,-6,biomesoplenty:hard_ice)
Block(-2,19,-5,biomesoplenty:hard_ice)
Block(-2,19,-4,biomesoplenty:hard_ice)
Block(-2,19,-3,biomesoplenty:hard_ice)
Block(-2,19,-2,biomesoplenty:hard_ice)
Block(-2,19,-1,biomesoplenty:hard_ice)
Block(-2,19,0,biomesoplenty:hard_ice)
Block(-2,19,1,biomesoplenty:hard_ice)
Block(-2,19,2,biomesoplenty:hard_ice)
Block(-2,19,3,biomesoplenty:hard_ice)
Block(-2,19,4,biomesoplenty:hard_ice)
Block(-2,19,5,biomesoplenty:hard_ice)
Block(-2,19,6,biomesoplenty:hard_ice)
Block(-2,19,7,biomesoplenty:hard_ice)
Block(-2,19,8,biomesoplenty:hard_ice)
Block(-2,19,9,biomesoplenty:hard_ice)
Block(-2,19,10,biomesoplenty:hard_ice)
Block(-2,19,11,biomesoplenty:hard_ice)
Block(-2,20,-9,biomesoplenty:hard_ice)
Block(-2,20,-8,biomesoplenty:hard_ice)
Block(-2,20,-7,biomesoplenty:hard_ice)
Block(-2,20,-6,biomesoplenty:hard_ice)
Block(-2,20,-5,biomesoplenty:hard_ice)
Block(-2,20,-4,biomesoplenty:hard_ice)
Block(-2,20,-3,biomesoplenty:hard_ice)
Block(-2,20,-2,biomesoplenty:hard_ice)
Block(-2,20,-1,biomesoplenty:hard_ice)
Block(-2,20,0,biomesoplenty:hard_ice)
Block(-2,20,1,biomesoplenty:hard_ice)
Block(-2,20,2,biomesoplenty:hard_ice)
Block(-2,20,3,biomesoplenty:hard_ice)
Block(-2,20,4,biomesoplenty:hard_ice)
Block(-2,20,5,biomesoplenty:hard_ice)
Block(-2,20,6,biomesoplenty:hard_ice)
Block(-2,20,7,biomesoplenty:hard_ice)
Block(-2,20,8,biomesoplenty:hard_ice)
Block(-2,20,9,biomesoplenty:hard_ice)
Block(-2,20,10,biomesoplenty:hard_ice)
Block(-2,20,11,biomesoplenty:hard_ice)
Block(-2,21,-9,biomesoplenty:hard_ice)
Block(-2,21,-8,biomesoplenty:hard_ice)
Block(-2,21,-7,biomesoplenty:hard_ice)
Block(-2,21,-6,biomesoplenty:hard_ice)
Block(-2,21,-5,biomesoplenty:hard_ice)
Block(-2,21,-4,biomesoplenty:hard_ice)
Block(-2,21,-3,biomesoplenty:hard_ice)
Block(-2,21,-2,biomesoplenty:hard_ice)
Block(-2,21,-1,biomesoplenty:hard_ice)
Block(-2,21,0,biomesoplenty:hard_ice)
Block(-2,21,1,biomesoplenty:hard_ice)
Block(-2,21,2,biomesoplenty:hard_ice)
Block(-2,21,3,biomesoplenty:hard_ice)
Block(-2,21,4,biomesoplenty:hard_ice)
Block(-2,21,5,biomesoplenty:hard_ice)
Block(-2,21,6,biomesoplenty:hard_ice)
Block(-2,21,7,biomesoplenty:hard_ice)
Block(-2,21,8,biomesoplenty:hard_ice)
Block(-2,22,-7,biomesoplenty:hard_ice)
Block(-2,22,-6,biomesoplenty:hard_ice)
Block(-2,22,-5,biomesoplenty:hard_ice)
Block(-2,22,-4,biomesoplenty:hard_ice)
Block(-2,22,-3,biomesoplenty:hard_ice)
Block(-2,22,-2,biomesoplenty:hard_ice)
Block(-2,22,-1,biomesoplenty:hard_ice)
Block(-2,22,0,biomesoplenty:hard_ice)
Block(-2,22,1,biomesoplenty:hard_ice)
Block(-2,22,2,biomesoplenty:hard_ice)
Block(-2,22,3,biomesoplenty:hard_ice)
Block(-2,22,4,biomesoplenty:hard_ice)
Block(-1,2,6,biomesoplenty:hard_ice)
Block(-1,2,7,biomesoplenty:hard_ice)
Block(-1,2,8,biomesoplenty:hard_ice)
Block(-1,2,9,biomesoplenty:hard_ice)
Block(-1,2,10,biomesoplenty:hard_ice)
Block(-1,3,-2,biomesoplenty:hard_ice)
Block(-1,3,-1,biomesoplenty:hard_ice)
Block(-1,3,0,biomesoplenty:hard_ice)
Block(-1,3,1,biomesoplenty:hard_ice)
Block(-1,3,2,biomesoplenty:hard_ice)
Block(-1,3,3,biomesoplenty:hard_ice)
Block(-1,3,4,biomesoplenty:hard_ice)
Block(-1,3,5,biomesoplenty:hard_ice)
Block(-1,3,6,biomesoplenty:hard_ice)
Block(-1,3,7,biomesoplenty:hard_ice)
Block(-1,3,8,biomesoplenty:hard_ice)
Block(-1,3,9,biomesoplenty:hard_ice)
Block(-1,3,10,biomesoplenty:hard_ice)
Block(-1,3,11,biomesoplenty:hard_ice)
Block(-1,4,-9,biomesoplenty:hard_ice)
Block(-1,4,-8,biomesoplenty:hard_ice)
Block(-1,4,-7,biomesoplenty:hard_ice)
Block(-1,4,-6,biomesoplenty:hard_ice)
Block(-1,4,-5,biomesoplenty:hard_ice)
Block(-1,4,-4,biomesoplenty:hard_ice)
Block(-1,4,-3,biomesoplenty:hard_ice)
Block(-1,4,-2,biomesoplenty:hard_ice)
Block(-1,4,-1,biomesoplenty:hard_ice)
Block(-1,4,0,biomesoplenty:hard_ice)
Block(-1,4,1,biomesoplenty:hard_ice)
Block(-1,4,2,biomesoplenty:hard_ice)
Block(-1,4,3,biomesoplenty:hard_ice)
Block(-1,4,4,biomesoplenty:hard_ice)
Block(-1,4,5,biomesoplenty:hard_ice)
Block(-1,4,6,biomesoplenty:hard_ice)
Block(-1,4,7,biomesoplenty:hard_ice)
Block(-1,4,8,biomesoplenty:hard_ice)
Block(-1,4,9,biomesoplenty:hard_ice)
Block(-1,4,10,biomesoplenty:hard_ice)
Block(-1,4,11,biomesoplenty:hard_ice)
Block(-1,5,-9,biomesoplenty:hard_ice)
Block(-1,5,-8,biomesoplenty:hard_ice)
Block(-1,5,-7,biomesoplenty:hard_ice)
Block(-1,5,-6,biomesoplenty:hard_ice)
Block(-1,5,-5,biomesoplenty:hard_ice)
Block(-1,5,-4,biomesoplenty:hard_ice)
Block(-1,5,-3,biomesoplenty:hard_ice)
Block(-1,5,-2,biomesoplenty:hard_ice)
Block(-1,5,-1,biomesoplenty:hard_ice)
Block(-1,5,0,biomesoplenty:hard_ice)
Block(-1,5,1,biomesoplenty:hard_ice)
Block(-1,5,2,biomesoplenty:hard_ice)
Block(-1,5,3,biomesoplenty:hard_ice)
Block(-1,5,4,biomesoplenty:hard_ice)
Block(-1,5,5,biomesoplenty:hard_ice)
Block(-1,5,6,biomesoplenty:hard_ice)
Block(-1,5,7,biomesoplenty:hard_ice)
Block(-1,5,8,biomesoplenty:hard_ice)
Block(-1,5,9,biomesoplenty:hard_ice)
Block(-1,5,10,biomesoplenty:hard_ice)
Block(-1,5,11,biomesoplenty:hard_ice)
Block(-1,5,12,biomesoplenty:hard_ice)
Block(-1,6,-10,biomesoplenty:hard_ice)
Block(-1,6,-9,biomesoplenty:hard_ice)
Block(-1,6,-8,biomesoplenty:hard_ice)
Block(-1,6,-7,biomesoplenty:hard_ice)
Block(-1,6,-6,biomesoplenty:hard_ice)
Block(-1,6,-5,biomesoplenty:hard_ice)
Block(-1,6,-4,biomesoplenty:hard_ice)
Block(-1,6,-3,biomesoplenty:hard_ice)
Block(-1,6,-2,biomesoplenty:hard_ice)
Block(-1,6,-1,biomesoplenty:hard_ice)
Block(-1,6,0,biomesoplenty:hard_ice)
Block(-1,6,1,biomesoplenty:hard_ice)
Block(-1,6,2,biomesoplenty:hard_ice)
Block(-1,6,3,biomesoplenty:hard_ice)
Block(-1,6,4,biomesoplenty:hard_ice)
Block(-1,6,5,biomesoplenty:hard_ice)
Block(-1,6,6,biomesoplenty:hard_ice)
Block(-1,6,7,biomesoplenty:hard_ice)
Block(-1,6,8,biomesoplenty:hard_ice)
Block(-1,6,9,biomesoplenty:hard_ice)
Block(-1,6,10,biomesoplenty:hard_ice)
Block(-1,6,11,biomesoplenty:hard_ice)
Block(-1,6,12,biomesoplenty:hard_ice)
Block(-1,7,-10,biomesoplenty:hard_ice)
Block(-1,7,-9,biomesoplenty:hard_ice)
Block(-1,7,-8,biomesoplenty:hard_ice)
Block(-1,7,-7,biomesoplenty:hard_ice)
Block(-1,7,-6,biomesoplenty:hard_ice)
Block(-1,7,-5,biomesoplenty:hard_ice)
Block(-1,7,-4,biomesoplenty:hard_ice)
Block(-1,7,-3,biomesoplenty:hard_ice)
Block(-1,7,-2,biomesoplenty:hard_ice)
Block(-1,7,-1,biomesoplenty:hard_ice)
Block(-1,7,0,biomesoplenty:hard_ice)
Block(-1,7,1,biomesoplenty:hard_ice)
Block(-1,7,2,biomesoplenty:hard_ice)
Block(-1,7,3,biomesoplenty:hard_ice)
Block(-1,7,4,biomesoplenty:hard_ice)
Block(-1,7,5,biomesoplenty:hard_ice)
Block(-1,7,6,biomesoplenty:hard_ice)
Block(-1,7,7,biomesoplenty:hard_ice)
Block(-1,7,8,biomesoplenty:hard_ice)
Block(-1,7,9,biomesoplenty:hard_ice)
Block(-1,7,10,biomesoplenty:hard_ice)
Block(-1,7,11,biomesoplenty:hard_ice)
Block(-1,7,12,biomesoplenty:hard_ice)
Block(-1,7,13,biomesoplenty:hard_ice)
Block(-1,8,-10,biomesoplenty:hard_ice)
Block(-1,8,-9,biomesoplenty:hard_ice)
Block(-1,8,-8,biomesoplenty:hard_ice)
Block(-1,8,-7,biomesoplenty:hard_ice)
Block(-1,8,-6,biomesoplenty:hard_ice)
Block(-1,8,-5,biomesoplenty:hard_ice)
Block(-1,8,-4,biomesoplenty:hard_ice)
Block(-1,8,-3,biomesoplenty:hard_ice)
Block(-1,8,-2,biomesoplenty:hard_ice)
Block(-1,8,-1,biomesoplenty:hard_ice)
Block(-1,8,0,biomesoplenty:hard_ice)
Block(-1,8,1,biomesoplenty:hard_ice)
Block(-1,8,2,biomesoplenty:hard_ice)
Block(-1,8,3,biomesoplenty:hard_ice)
Block(-1,8,4,biomesoplenty:hard_ice)
Block(-1,8,5,biomesoplenty:hard_ice)
Block(-1,8,6,biomesoplenty:hard_ice)
Block(-1,8,7,biomesoplenty:hard_ice)
Block(-1,8,8,biomesoplenty:hard_ice)
Block(-1,8,9,biomesoplenty:hard_ice)
Block(-1,8,10,biomesoplenty:hard_ice)
Block(-1,8,11,biomesoplenty:hard_ice)
Block(-1,8,12,biomesoplenty:hard_ice)
Block(-1,8,13,biomesoplenty:hard_ice)
Block(-1,8,14,biomesoplenty:hard_ice)
Block(-1,9,-11,biomesoplenty:hard_ice)
Block(-1,9,-10,biomesoplenty:hard_ice)
Block(-1,9,-9,biomesoplenty:hard_ice)
Block(-1,9,-8,biomesoplenty:hard_ice)
Block(-1,9,-7,biomesoplenty:hard_ice)
Block(-1,9,-6,biomesoplenty:hard_ice)
Block(-1,9,-5,biomesoplenty:hard_ice)
Block(-1,9,-4,biomesoplenty:hard_ice)
Block(-1,9,-3,biomesoplenty:hard_ice)
Block(-1,9,-2,biomesoplenty:hard_ice)
Block(-1,9,-1,biomesoplenty:hard_ice)
Block(-1,9,0,biomesoplenty:hard_ice)
Block(-1,9,1,biomesoplenty:hard_ice)
Block(-1,9,2,biomesoplenty:hard_ice)
Block(-1,9,3,biomesoplenty:hard_ice)
Block(-1,9,4,biomesoplenty:hard_ice)
Block(-1,9,5,biomesoplenty:hard_ice)
Block(-1,9,6,biomesoplenty:hard_ice)
Block(-1,9,7,biomesoplenty:hard_ice)
Block(-1,9,8,biomesoplenty:hard_ice)
Block(-1,9,9,biomesoplenty:hard_ice)
Block(-1,9,10,biomesoplenty:hard_ice)
Block(-1,9,11,biomesoplenty:hard_ice)
Block(-1,9,12,biomesoplenty:hard_ice)
Block(-1,9,13,biomesoplenty:hard_ice)
Block(-1,9,14,biomesoplenty:hard_ice)
Block(-1,10,-11,biomesoplenty:hard_ice)
Block(-1,10,-10,biomesoplenty:hard_ice)
Block(-1,10,-9,biomesoplenty:hard_ice)
Block(-1,10,-8,biomesoplenty:hard_ice)
Block(-1,10,-7,biomesoplenty:hard_ice)
Block(-1,10,-6,biomesoplenty:hard_ice)
Block(-1,10,-5,biomesoplenty:hard_ice)
Block(-1,10,-4,biomesoplenty:hard_ice)
Block(-1,10,-3,biomesoplenty:hard_ice)
Block(-1,10,-2,biomesoplenty:hard_ice)
Block(-1,10,-1,biomesoplenty:hard_ice)
Block(-1,10,0,biomesoplenty:hard_ice)
Block(-1,10,1,biomesoplenty:hard_ice)
Block(-1,10,2,biomesoplenty:hard_ice)
Block(-1,10,3,biomesoplenty:hard_ice)
Block(-1,10,4,biomesoplenty:hard_ice)
Block(-1,10,5,biomesoplenty:hard_ice)
Block(-1,10,6,biomesoplenty:hard_ice)
Block(-1,10,7,biomesoplenty:hard_ice)
Block(-1,10,8,biomesoplenty:hard_ice)
Block(-1,10,9,biomesoplenty:hard_ice)
Block(-1,10,10,biomesoplenty:hard_ice)
Block(-1,10,11,biomesoplenty:hard_ice)
Block(-1,10,12,biomesoplenty:hard_ice)
Block(-1,10,13,biomesoplenty:hard_ice)
Block(-1,10,14,biomesoplenty:hard_ice)
Block(-1,10,15,biomesoplenty:hard_ice)
Block(-1,11,-11,biomesoplenty:hard_ice)
Block(-1,11,-10,biomesoplenty:hard_ice)
Block(-1,11,-9,biomesoplenty:hard_ice)
Block(-1,11,-8,biomesoplenty:hard_ice)
Block(-1,11,-7,biomesoplenty:hard_ice)
Block(-1,11,-6,biomesoplenty:hard_ice)
Block(-1,11,-5,biomesoplenty:hard_ice)
Block(-1,11,-4,biomesoplenty:hard_ice)
Block(-1,11,-3,biomesoplenty:hard_ice)
Block(-1,11,-2,biomesoplenty:hard_ice)
Block(-1,11,-1,biomesoplenty:hard_ice)
Block(-1,11,0,biomesoplenty:hard_ice)
Block(-1,11,1,biomesoplenty:hard_ice)
Block(-1,11,2,biomesoplenty:hard_ice)
Block(-1,11,3,biomesoplenty:hard_ice)
Block(-1,11,4,biomesoplenty:hard_ice)
Block(-1,11,5,biomesoplenty:hard_ice)
Block(-1,11,6,biomesoplenty:hard_ice)
Block(-1,11,7,biomesoplenty:hard_ice)
Block(-1,11,8,biomesoplenty:hard_ice)
Block(-1,11,9,biomesoplenty:hard_ice)
Block(-1,11,10,biomesoplenty:hard_ice)
Block(-1,11,11,biomesoplenty:hard_ice)
Block(-1,11,12,biomesoplenty:hard_ice)
Block(-1,11,13,biomesoplenty:hard_ice)
Block(-1,11,14,biomesoplenty:hard_ice)
Block(-1,11,15,biomesoplenty:hard_ice)
Block(-1,11,16,biomesoplenty:hard_ice)
Block(-1,12,-11,biomesoplenty:hard_ice)
Block(-1,12,-10,biomesoplenty:hard_ice)
Block(-1,12,-9,biomesoplenty:hard_ice)
Block(-1,12,-8,biomesoplenty:hard_ice)
Block(-1,12,-7,biomesoplenty:hard_ice)
Block(-1,12,-6,biomesoplenty:hard_ice)
Block(-1,12,-5,biomesoplenty:hard_ice)
Block(-1,12,-4,biomesoplenty:hard_ice)
Block(-1,12,-3,biomesoplenty:hard_ice)
Block(-1,12,-2,biomesoplenty:hard_ice)
Block(-1,12,-1,biomesoplenty:hard_ice)
Block(-1,12,0,biomesoplenty:hard_ice)
Block(-1,12,1,biomesoplenty:hard_ice)
Block(-1,12,2,biomesoplenty:hard_ice)
Block(-1,12,3,biomesoplenty:hard_ice)
Block(-1,12,4,biomesoplenty:hard_ice)
Block(-1,12,5,biomesoplenty:hard_ice)
Block(-1,12,6,biomesoplenty:hard_ice)
Block(-1,12,7,biomesoplenty:hard_ice)
Block(-1,12,8,biomesoplenty:hard_ice)
Block(-1,12,9,biomesoplenty:hard_ice)
Block(-1,12,10,biomesoplenty:hard_ice)
Block(-1,12,11,biomesoplenty:hard_ice)
Block(-1,12,12,biomesoplenty:hard_ice)
Block(-1,12,13,biomesoplenty:hard_ice)
Block(-1,12,14,biomesoplenty:hard_ice)
Block(-1,12,15,biomesoplenty:hard_ice)
Block(-1,12,16,biomesoplenty:hard_ice)
Block(-1,13,-11,biomesoplenty:hard_ice)
Block(-1,13,-10,biomesoplenty:hard_ice)
Block(-1,13,-9,biomesoplenty:hard_ice)
Block(-1,13,-8,biomesoplenty:hard_ice)
Block(-1,13,-7,biomesoplenty:hard_ice)
Block(-1,13,-6,biomesoplenty:hard_ice)
Block(-1,13,-5,biomesoplenty:hard_ice)
Block(-1,13,-4,biomesoplenty:hard_ice)
Block(-1,13,-3,biomesoplenty:hard_ice)
Block(-1,13,-2,biomesoplenty:hard_ice)
Block(-1,13,-1,biomesoplenty:hard_ice)
Block(-1,13,0,biomesoplenty:hard_ice)
